File: materials_lab1/ENGR314_FA19_0002_pollypropelyne_A_20190903_AmericanIdiots_1.is_tens_RawData/Specimen_RawData_1.csv
Material,Acrylic
Geometry,Circular
Length,"2.00000",in
Diameter,"0.11700",in

Time,Extension,Load
(s),(in),(lbf)
"0.00000","0.00000","-2.29783"
"0.50000","0.00067","-1.55287"
"1.00000","0.00134","-0.75070"
"1.50000","0.00200","0.01381"
"2.00000","0.00267","0.78221"
"2.50000","0.00333","1.50606"
"3.00000","0.00399","2.23465"
"3.50000","0.00466","2.98503"
"4.00000","0.00532","3.69710"
"4.50000","0.00599","4.38665"
"5.00000","0.00665","5.08187"
"5.50000","0.00733","5.77829"
"6.00000","0.00800","6.47105"
"6.50000","0.00868","7.15915"
"7.00000","0.00935","7.83290"
"7.50000","0.01001","8.50565"
"8.00000","0.01069","9.15057"
"8.50000","0.01134","9.80032"
"9.00000","0.01201","10.43659"
"9.50000","0.01267","11.05584"
"10.00000","0.01333","11.66612"
"10.50000","0.01400","12.25285"
"11.00000","0.01466","12.86461"
"11.50000","0.01533","13.45816"
"12.00000","0.01600","14.03270"
"12.50000","0.01668","14.62712"
"13.00000","0.01734","15.18638"
"13.50000","0.01801","15.75065"
"14.00000","0.01867","16.28431"
"14.50000","0.01933","16.83350"
"15.00000","0.01999","17.35455"
"15.50000","0.02066","17.85404"
"16.00000","0.02132","18.35839"
"16.50000","0.02199","18.84781"
"17.00000","0.02266","19.35198"
"17.50000","0.02332","19.83590"
"18.00000","0.02400","20.33651"
"18.50000","0.02467","20.79901"
"19.00000","0.02534","21.26609"
"19.50000","0.02602","21.70188"
"20.00000","0.02668","22.15149"
"20.50000","0.02735","22.56701"
"21.00000","0.02800","22.97125"
"21.50000","0.02867","23.39791"
"22.00000","0.02933","23.79429"
"22.50000","0.03000","24.18737"
"23.00000","0.03067","24.55818"
"23.50000","0.03133","24.93067"
"24.00000","0.03201","25.30230"
"24.50000","0.03267","25.65740"
"25.00000","0.03335","25.99242"
"25.50000","0.03400","26.34362"
"26.00000","0.03468","26.69189"
"26.50000","0.03533","27.01195"
"27.00000","0.03600","27.34109"
"27.50000","0.03666","27.65222"
"28.00000","0.03732","27.94932"
"28.50000","0.03799","28.22196"
"29.00000","0.03865","28.51920"
"29.50000","0.03933","28.80805"
"30.00000","0.04000","29.08943"
"30.50000","0.04068","29.36531"
"31.00000","0.04135","29.61823"
"31.50000","0.04201","29.87747"
"32.00000","0.04268","30.13459"
"32.50000","0.04334","30.37067"
"33.00000","0.04401","30.63540"
"33.50000","0.04467","30.87234"
"34.00000","0.04534","31.10869"
"34.50000","0.04600","31.33870"
"35.00000","0.04667","31.57045"
"35.50000","0.04734","31.79280"
"36.00000","0.04800","32.00124"
"36.50000","0.04868","32.23621"
"37.00000","0.04934","32.44929"
"37.50000","0.05001","32.65362"
"38.00000","0.05067","32.85056"
"38.50000","0.05134","33.06134"
"39.00000","0.05200","33.25116"
"39.50000","0.05266","33.44651"
"40.00000","0.05333","33.65108"
"40.50000","0.05399","33.84194"
"41.00000","0.05466","34.04081"
"41.50000","0.05532","34.22683"
"42.00000","0.05600","34.42548"
"42.50000","0.05667","34.60337"
"43.00000","0.05734","34.78953"
"43.50000","0.05802","34.97592"
"44.00000","0.05868","35.16199"
"44.50000","0.05935","35.33690"
"45.00000","0.06000","35.49629"
"45.50000","0.06068","35.68246"
"46.00000","0.06133","35.84537"
"46.50000","0.06200","36.02019"
"47.00000","0.06267","36.17579"
"47.50000","0.06333","36.32841"
"48.00000","0.06400","36.49475"
"48.50000","0.06467","36.66873"
"49.00000","0.06535","36.82079"
"49.50000","0.06600","36.97793"
"50.00000","0.06668","37.15440"
"50.50000","0.06734","37.30454"
"51.00000","0.06800","37.47518"
"51.50000","0.06866","37.64338"
"52.00000","0.06932","37.79092"
"52.50000","0.06999","37.94007"
"53.00000","0.07065","38.07462"
"53.50000","0.07133","38.24332"
"54.00000","0.07199","38.38532"
"54.50000","0.07267","38.53936"
"55.00000","0.07334","38.69366"
"55.50000","0.07401","38.83929"
"56.00000","0.07468","38.98013"
"56.50000","0.07534","39.12599"
"57.00000","0.07601","39.28470"
"57.50000","0.07667","39.40781"
"58.00000","0.07734","39.55994"
"58.50000","0.07799","39.69586"
"59.00000","0.07867","39.82506"
"59.50000","0.07934","39.95352"
"60.00000","0.08000","40.08757"
"60.50000","0.08068","40.22573"
"61.00000","0.08134","40.36251"
"61.50000","0.08201","40.50083"
"62.00000","0.08267","40.62719"
"62.50000","0.08334","40.76434"
"63.00000","0.08400","40.89797"
"63.50000","0.08466","41.02069"
"64.00000","0.08533","41.15188"
"64.50000","0.08599","41.28422"
"65.00000","0.08666","41.40764"
"65.50000","0.08732","41.51334"
"66.00000","0.08800","41.65258"
"66.50000","0.08867","41.77289"
"67.00000","0.08934","41.89823"
"67.50000","0.09001","42.01506"
"68.00000","0.09068","42.13495"
"68.50000","0.09135","42.25529"
"69.00000","0.09200","42.36295"
"69.50000","0.09268","42.47191"
"70.00000","0.09333","42.58946"
"70.50000","0.09400","42.71227"
"71.00000","0.09467","42.81796"
"71.50000","0.09533","42.93176"
"72.00000","0.09600","43.02951"
"72.50000","0.09667","43.13508"
"73.00000","0.09734","43.24699"
"73.50000","0.09800","43.35824"
"74.00000","0.09868","43.47575"
"74.50000","0.09934","43.57935"
"75.00000","0.10000","43.67254"
"75.50000","0.10066","43.77025"
"76.00000","0.10132","43.88681"
"76.50000","0.10199","43.98473"
"77.00000","0.10265","44.08052"
"77.50000","0.10333","44.18496"
"78.00000","0.10399","44.29398"
"78.50000","0.10467","44.40915"
"79.00000","0.10534","44.50490"
"79.50000","0.10601","44.61135"
"80.00000","0.10668","44.70546"
"80.50000","0.10734","44.79764"
"81.00000","0.10802","44.89994"
"81.50000","0.10867","44.99355"
"82.00000","0.10934","45.06655"
"82.50000","0.10999","45.15605"
"83.00000","0.11067","45.25689"
"83.50000","0.11133","45.34142"
"84.00000","0.11200","45.42278"
"84.50000","0.11267","45.50945"
"85.00000","0.11334","45.59351"
"85.50000","0.11401","45.69824"
"86.00000","0.11467","45.77076"
"86.50000","0.11534","45.85086"
"87.00000","0.11600","45.92044"
"87.50000","0.11666","46.00123"
"88.00000","0.11733","46.08578"
"88.50000","0.11799","46.15246"
"89.00000","0.11866","46.22676"
"89.50000","0.11932","46.28645"
"90.00000","0.12000","46.37824"
"90.50000","0.12066","46.44816"
"91.00000","0.12134","46.51191"
"91.50000","0.12201","46.58374"
"92.00000","0.12268","46.65262"
"92.50000","0.12335","46.71767"
"93.00000","0.12401","46.78074"
"93.50000","0.12468","46.85711"
"94.00000","0.12534","46.91126"
"94.50000","0.12600","46.98461"
"95.00000","0.12667","47.04180"
"95.50000","0.12733","47.09845"
"96.00000","0.12801","47.15478"
"96.50000","0.12866","47.21055"
"97.00000","0.12934","47.28056"
"97.50000","0.13001","47.33709"
"98.00000","0.13068","47.41069"
"98.50000","0.13134","47.45513"
"99.00000","0.13201","47.52457"
"99.50000","0.13266","47.56067"
"100.00000","0.13333","47.61533"
"100.50000","0.13399","47.65260"
"101.00000","0.13465","47.70459"
"101.50000","0.13533","47.75776"
"102.00000","0.13599","47.79946"
"102.50000","0.13667","47.85700"
"103.00000","0.13734","47.91061"
"103.50000","0.13801","47.96688"
"104.00000","0.13868","48.01350"
"104.50000","0.13934","48.06093"
"105.00000","0.14002","48.11008"
"105.50000","0.14067","48.15157"
"106.00000","0.14134","48.19061"
"106.50000","0.14200","48.22672"
"107.00000","0.14267","48.27446"
"107.50000","0.14333","48.30338"
"108.00000","0.14400","48.34304"
"108.50000","0.14467","48.38069"
"109.00000","0.14533","48.41760"
"109.50000","0.14601","48.46087"
"110.00000","0.14667","48.48936"
"110.50000","0.14735","48.53254"
"111.00000","0.14800","48.56183"
"111.50000","0.14867","48.59825"
"112.00000","0.14933","48.62813"
"112.50000","0.14999","48.64877"
"113.00000","0.15066","48.67858"
"113.50000","0.15132","48.69381"
"114.00000","0.15200","48.72759"
"114.50000","0.15266","48.75275"
"115.00000","0.15334","48.77926"
"115.50000","0.15401","48.80460"
"116.00000","0.15468","48.83163"
"116.50000","0.15535","48.85159"
"117.00000","0.15601","48.88576"
"117.50000","0.15668","48.90659"
"118.00000","0.15734","48.92054"
"118.50000","0.15801","48.93975"
"119.00000","0.15866","48.95850"
"119.50000","0.15933","48.97729"
"120.00000","0.16000","48.99354"
"120.50000","0.16066","49.01487"
"121.00000","0.16134","49.03048"
"121.50000","0.16200","49.05225"
"122.00000","0.16268","49.08026"
"122.50000","0.16333","49.07660"
"123.00000","0.16401","49.10528"
"123.50000","0.16466","49.10446"
"124.00000","0.16533","49.12176"
"124.50000","0.16600","49.13381"
"125.00000","0.16665","49.14415"
"125.50000","0.16733","49.15271"
"126.00000","0.16799","49.15494"
"126.50000","0.16866","49.15946"
"127.00000","0.16933","49.16572"
"127.50000","0.17001","49.18680"
"128.00000","0.17068","49.20160"
"128.50000","0.17134","49.20878"
"129.00000","0.17202","49.21694"
"129.50000","0.17267","49.21382"
"130.00000","0.17334","49.23165"
"130.50000","0.17400","49.22077"
"131.00000","0.17467","49.22994"
"131.50000","0.17533","49.23168"
"132.00000","0.17600","49.23809"
"132.50000","0.17667","49.24435"
"133.00000","0.17733","49.25277"
"133.50000","0.17801","49.24752"
"134.00000","0.17867","49.25760"
"134.50000","0.17935","49.26558"
"135.00000","0.18000","49.25845"
"135.50000","0.18067","49.25822"
"136.00000","0.18133","49.24920"
"136.50000","0.18199","49.25767"
"137.00000","0.18266","49.25338"
"137.50000","0.18332","49.25313"
"138.00000","0.18400","49.24898"
"138.50000","0.18466","49.25014"
"139.00000","0.18533","49.24635"
"139.50000","0.18600","49.24665"
"140.00000","0.18668","49.25813"
"140.50000","0.18735","49.23677"
"141.00000","0.18801","49.21820"
"141.50000","0.18869","49.20536"
"142.00000","0.18934","49.16045"
"142.50000","0.19001","49.14138"
"143.00000","0.19066","49.11321"
"143.50000","0.19133","49.10328"
"144.00000","0.19200","49.09133"
"144.50000","0.19267","49.07530"
"145.00000","0.19334","49.07744"
"145.50000","0.19400","49.06145"
"146.00000","0.19468","49.06391"
"146.50000","0.19534","49.03828"
"147.00000","0.19601","49.04483"
"147.50000","0.19667","49.02206"
"148.00000","0.19733","49.02009"
"148.50000","0.19800","49.01002"
"149.00000","0.19866","48.99203"
"149.50000","0.19932","48.99117"
"150.00000","0.19999","48.97483"
"150.50000","0.20066","48.97320"
"151.00000","0.20133","48.96179"
"151.50000","0.20201","48.96350"
"152.00000","0.20268","48.95222"
"152.50000","0.20335","48.94826"
"153.00000","0.20402","48.94364"
"153.50000","0.20468","48.93571"
"154.00000","0.20535","48.92712"
"154.50000","0.20600","48.91453"
"155.00000","0.20667","48.90030"
"155.50000","0.20733","48.88535"
"156.00000","0.20800","48.87257"
"156.50000","0.20867","48.87315"
"157.00000","0.20933","48.87276"
"157.50000","0.21001","48.86028"
"158.00000","0.21067","48.85110"
"158.50000","0.21135","48.85146"
"159.00000","0.21200","48.83263"
"159.50000","0.21267","48.82744"
"160.00000","0.21333","48.81652"
"160.50000","0.21400","48.79944"
"161.00000","0.21466","48.79521"
"161.50000","0.21532","48.77441"
"162.00000","0.21599","48.76196"
"162.50000","0.21666","48.75061"
"163.00000","0.21733","48.74557"
"163.50000","0.21800","48.74866"
"164.00000","0.21868","48.73470"
"164.50000","0.21935","48.72899"
"165.00000","0.22001","48.72301"
"165.50000","0.22068","48.71374"
"166.00000","0.22134","48.69481"
"166.50000","0.22201","48.69917"
"167.00000","0.22266","48.67908"
"167.50000","0.22334","48.66047"
"168.00000","0.22400","48.65144"
"168.50000","0.22467","48.63661"
"169.00000","0.22533","48.62849"
"169.50000","0.22600","48.61232"
"170.00000","0.22668","48.59942"
"170.50000","0.22734","48.58801"
"171.00000","0.22801","48.58347"
"171.50000","0.22867","48.56320"
"172.00000","0.22933","48.54277"
"172.50000","0.23000","48.53673"
"173.00000","0.23066","48.52037"
"173.50000","0.23133","48.50412"
"174.00000","0.23198","48.48524"
"174.50000","0.23266","48.47437"
"175.00000","0.23333","48.45965"
"175.50000","0.23401","48.44642"
"176.00000","0.23467","48.41753"
"176.50000","0.23534","48.42111"
"177.00000","0.23602","48.40671"
"177.50000","0.23668","48.38500"
"178.00000","0.23735","48.37665"
"178.50000","0.23800","48.35049"
"179.00000","0.23867","48.33545"
"179.50000","0.23933","48.31283"
"180.00000","0.24000","48.30556"
"180.50000","0.24067","48.27660"
"181.00000","0.24133","48.27475"
"181.50000","0.24201","48.24992"
"182.00000","0.24267","48.23516"
"182.50000","0.24335","48.22533"
"183.00000","0.24400","48.19535"
"183.50000","0.24468","48.18112"
"184.00000","0.24533","48.16671"
"184.50000","0.24600","48.15904"
"185.00000","0.24666","48.12634"
"185.50000","0.24732","48.09986"
"186.00000","0.24799","48.07191"
"186.50000","0.24865","48.05991"
"187.00000","0.24933","48.04273"
"187.50000","0.24999","48.01369"
"188.00000","0.25067","48.00792"
"188.50000","0.25135","47.97961"
"189.00000","0.25201","47.95912"
"189.50000","0.25269","47.93584"
"190.00000","0.25334","47.91873"
"190.50000","0.25401","47.90149"
"191.00000","0.25467","47.87295"
"191.50000","0.25534","47.84471"
"192.00000","0.25600","47.81699"
"192.50000","0.25666","47.79748"
"193.00000","0.25734","47.77164"
"193.50000","0.25800","47.74816"
"194.00000","0.25868","47.72814"
"194.50000","0.25934","47.70067"
"195.00000","0.26001","47.67800"
"195.50000","0.26067","47.64788"
"196.00000","0.26134","47.63477"
"196.50000","0.26200","47.61474"
"197.00000","0.26266","47.58369"
"197.50000","0.26333","47.55710"
"198.00000","0.26399","47.52584"
"198.50000","0.26466","47.49210"
"199.00000","0.26532","47.46728"
"199.50000","0.26600","47.44417"
"200.00000","0.26667","47.41078"
"200.50000","0.26734","47.38715"
"201.00000","0.26801","47.35435"
"201.50000","0.26868","47.32921"
"202.00000","0.26935","47.30789"
"202.50000","0.27000","47.27134"
"203.00000","0.27068","47.25292"
"203.50000","0.27133","47.20924"
"204.00000","0.27200","47.19454"
"204.50000","0.27266","47.16485"
"205.00000","0.27333","47.14795"
"205.50000","0.27400","47.11541"
"206.00000","0.27467","47.08322"
"206.50000","0.27535","47.07305"
"207.00000","0.27600","47.03120"
"207.50000","0.27668","47.01616"
"208.00000","0.27734","46.98477"
"208.50000","0.27800","46.96186"
"209.00000","0.27866","46.92152"
"209.50000","0.27933","46.89962"
"210.00000","0.27999","46.85406"
"210.50000","0.28065","46.82694"
"211.00000","0.28133","46.79475"
"211.50000","0.28199","46.76512"
"212.00000","0.28267","46.74029"
"212.50000","0.28334","46.71081"
"213.00000","0.28401","46.68647"
"213.50000","0.28469","46.66334"
"214.00000","0.28534","46.63956"
"214.50000","0.28601","46.61566"
"215.00000","0.28667","46.57478"
"215.50000","0.28734","46.54725"
"216.00000","0.28800","46.51873"
"216.50000","0.28867","46.47971"
"217.00000","0.28934","46.45224"
"217.50000","0.29000","46.41258"
"218.00000","0.29067","46.38307"
"218.50000","0.29134","46.35384"
"219.00000","0.29201","46.33284"
"219.50000","0.29267","46.29387"
"220.00000","0.29334","46.26864"
"220.50000","0.29400","46.22617"
"221.00000","0.29467","46.17747"
"221.50000","0.29533","46.14654"
"222.00000","0.29599","46.10406"
"222.50000","0.29666","46.07063"
"223.00000","0.29732","46.01892"
"223.50000","0.29800","45.99672"
"224.00000","0.29866","45.95269"
"224.50000","0.29934","45.91945"
"225.00000","0.30001","45.88867"
"225.50000","0.30068","45.85183"
"226.00000","0.30135","45.82260"
"226.50000","0.30200","45.79002"
"227.00000","0.30268","45.75970"
"227.50000","0.30333","45.70672"
"228.00000","0.30400","45.68272"
"228.50000","0.30467","45.62562"
"229.00000","0.30534","45.59610"
"229.50000","0.30600","45.54098"
"230.00000","0.30666","45.50239"
"230.50000","0.30734","45.47052"
"231.00000","0.30800","45.42208"
"231.50000","0.30868","45.39365"
"232.00000","0.30934","45.33846"
"232.50000","0.31000","45.30806"
"233.00000","0.31066","45.24806"
"233.50000","0.31133","45.21634"
"234.00000","0.31199","45.15860"
"234.50000","0.31265","45.11492"
"235.00000","0.31333","45.07099"
"235.50000","0.31399","45.02302"
"236.00000","0.31467","44.99191"
"236.50000","0.31534","44.93907"
"237.00000","0.31601","44.89732"
"237.50000","0.31668","44.85380"
"238.00000","0.31735","44.80161"
"238.50000","0.31801","44.75286"
"239.00000","0.31867","44.69685"
"239.50000","0.31934","44.64796"
"240.00000","0.32000","44.60761"
"240.50000","0.32067","44.55534"
"241.00000","0.32133","44.50543"
"241.50000","0.32200","44.44596"
"242.00000","0.32267","44.39741"
"242.50000","0.32333","44.33782"
"243.00000","0.32402","44.29903"
"243.50000","0.32467","44.23463"
"244.00000","0.32535","44.19566"
"244.50000","0.32600","44.14133"
"245.00000","0.32667","44.08837"
"245.50000","0.32733","44.03421"
"246.00000","0.32799","43.97262"
"246.50000","0.32866","43.91700"
"247.00000","0.32932","43.85743"
"247.50000","0.32999","43.79795"
"248.00000","0.33066","43.74409"
"248.50000","0.33134","43.70050"
"249.00000","0.33201","43.65647"
"249.50000","0.33268","43.61654"
"250.00000","0.33335","43.57562"
"250.50000","0.33401","43.52020"
"251.00000","0.33468","43.48229"
"251.50000","0.33533","43.41865"
"252.00000","0.33600","43.36113"
"252.50000","0.33667","43.30234"
"253.00000","0.33733","43.24781"
"253.50000","0.33800","43.20628"
"254.00000","0.33866","43.16186"
"254.50000","0.33934","43.11296"
"255.00000","0.34000","43.06482"
"255.50000","0.34068","43.03200"
"256.00000","0.34134","42.97273"
"256.50000","0.34201","42.93517"
"257.00000","0.34266","42.88360"
"257.50000","0.34333","42.84638"
"258.00000","0.34400","42.79483"
"258.50000","0.34465","42.74575"
"259.00000","0.34533","42.68906"
"259.50000","0.34599","42.65235"
"260.00000","0.34667","42.61880"
"260.50000","0.34733","42.56850"
"261.00000","0.34801","42.53507"
"261.50000","0.34868","42.49355"
"262.00000","0.34934","42.46279"
"262.50000","0.35002","42.42715"
"263.00000","0.35067","42.38747"
"263.50000","0.35135","42.34991"
"264.00000","0.35200","42.30800"
"264.50000","0.35267","42.26921"
"265.00000","0.35333","42.23550"
"265.50000","0.35400","42.20777"
"266.00000","0.35467","42.16221"
"266.50000","0.35533","42.12535"
"267.00000","0.35601","42.09430"
"267.50000","0.35667","42.07884"
"268.00000","0.35735","42.03740"
"268.50000","0.35800","42.01336"
"269.00000","0.35867","41.99129"
"269.50000","0.35933","41.95021"
"270.00000","0.35999","41.92020"
"270.50000","0.36066","41.88636"
"271.00000","0.36132","41.86439"
"271.50000","0.36200","41.84387"
"272.00000","0.36265","41.81173"
"272.50000","0.36334","41.79424"
"273.00000","0.36401","41.76819"
"273.50000","0.36468","41.73771"
"274.00000","0.36535","41.72400"
"274.50000","0.36601","41.70033"
"275.00000","0.36668","41.68472"
"275.50000","0.36734","41.64532"
"276.00000","0.36801","41.62849"
"276.50000","0.36867","41.60461"
"277.00000","0.36933","41.58751"
"277.50000","0.37000","41.56059"
"278.00000","0.37066","41.54604"
"278.50000","0.37134","41.53289"
"279.00000","0.37200","41.51860"
"279.50000","0.37268","41.51141"
"280.00000","0.37334","41.48898"
"280.50000","0.37401","41.48344"
"281.00000","0.37466","41.46106"
"281.50000","0.37533","41.44383"
"282.00000","0.37600","41.42663"
"282.50000","0.37666","41.41587"
"283.00000","0.37732","41.39629"
"283.50000","0.37799","41.38703"
"284.00000","0.37866","41.38193"
"284.50000","0.37933","41.35938"
"285.00000","0.38001","41.35102"
"285.50000","0.38068","41.34048"
"286.00000","0.38134","41.33755"
"286.50000","0.38202","41.31782"
"287.00000","0.38267","41.31279"
"287.50000","0.38335","41.30916"
"288.00000","0.38400","41.29479"
"288.50000","0.38467","41.28369"
"289.00000","0.38533","41.26215"
"289.50000","0.38600","41.25629"
"290.00000","0.38667","41.24496"
"290.50000","0.38733","41.23683"
"291.00000","0.38801","41.23017"
"291.50000","0.38867","41.22367"
"292.00000","0.38935","41.22932"
"292.50000","0.39000","41.20923"
"293.00000","0.39067","41.19700"
"293.50000","0.39133","41.19315"
"294.00000","0.39199","41.17987"
"294.50000","0.39266","41.17704"
"295.00000","0.39332","41.17122"
"295.50000","0.39399","41.16704"
"296.00000","0.39466","41.15588"
"296.50000","0.39534","41.15191"
"297.00000","0.39600","41.15152"
"297.50000","0.39668","41.15406"
"298.00000","0.39735","41.15395"
"298.50000","0.39801","41.14668"
"299.00000","0.39868","41.14202"
"299.50000","0.39934","41.13235"
"300.00000","0.40001","41.13577"
"300.50000","0.40066","41.12567"
"301.00000","0.40134","41.12715"
"301.50000","0.40200","41.12096"
"302.00000","0.40267","41.11822"
"302.50000","0.40334","41.11433"
"303.00000","0.40400","41.11037"
"303.50000","0.40468","41.12329"
"304.00000","0.40533","41.11017"
"304.50000","0.40601","41.12609"
"305.00000","0.40667","41.11291"
"305.50000","0.40734","41.11206"
"306.00000","0.40800","41.10629"
"306.50000","0.40866","41.09818"
"307.00000","0.40932","41.09766"
"307.50000","0.40999","41.10206"
"308.00000","0.41066","41.09445"
"308.50000","0.41132","41.09239"
"309.00000","0.41200","41.10497"
"309.50000","0.41268","41.09804"
"310.00000","0.41334","41.10546"
"310.50000","0.41402","41.10663"
"311.00000","0.41468","41.09799"
"311.50000","0.41535","41.10440"
"312.00000","0.41600","41.09841"
"312.50000","0.41667","41.10106"
"313.00000","0.41733","41.10265"
"313.50000","0.41800","41.09536"
"314.00000","0.41867","41.09713"
"314.50000","0.41933","41.10230"
"315.00000","0.42001","41.08958"
"315.50000","0.42067","41.09866"
"316.00000","0.42135","41.10020"
"316.50000","0.42200","41.09882"
"317.00000","0.42268","41.10227"
"317.50000","0.42333","41.09658"
"318.00000","0.42400","41.10984"
"318.50000","0.42466","41.09871"
"319.00000","0.42532","41.09416"
"319.50000","0.42599","41.09724"
"320.00000","0.42666","41.09344"
"320.50000","0.42733","41.10441"
"321.00000","0.42800","41.08656"
"321.50000","0.42868","41.09481"
"322.00000","0.42934","41.10071"
"322.50000","0.43001","41.10478"
"323.00000","0.43069","41.11083"
"323.50000","0.43134","41.10667"
"324.00000","0.43201","41.11375"
"324.50000","0.43267","41.10382"
"325.00000","0.43334","41.10737"
"325.50000","0.43400","41.10233"
"326.00000","0.43467","41.09438"
"326.50000","0.43533","41.10523"
"327.00000","0.43600","41.10753"
"327.50000","0.43668","41.10978"
"328.00000","0.43734","41.10168"
"328.50000","0.43801","41.11238"
"329.00000","0.43867","41.10929"
"329.50000","0.43934","41.11244"
"330.00000","0.44000","41.11295"
"330.50000","0.44066","41.11917"
"331.00000","0.44132","41.11628"
"331.50000","0.44198","41.11779"
"332.00000","0.44266","41.12568"
"332.50000","0.44332","41.10641"
"333.00000","0.44400","41.11954"
"333.50000","0.44467","41.12206"
"334.00000","0.44534","41.12618"
"334.50000","0.44602","41.12333"
"335.00000","0.44668","41.13828"
"335.50000","0.44735","41.13307"
"336.00000","0.44800","41.13130"
"336.50000","0.44867","41.13075"
"337.00000","0.44933","41.13231"
"337.50000","0.45000","41.14696"
"338.00000","0.45067","41.13754"
"338.50000","0.45133","41.11316"
"339.00000","0.45201","41.13283"
"339.50000","0.45267","41.13766"
"340.00000","0.45335","41.14367"
"340.50000","0.45400","41.12944"
"341.00000","0.45468","41.14388"
"341.50000","0.45533","41.14050"
"342.00000","0.45600","41.15730"
"342.50000","0.45666","41.14691"
"343.00000","0.45732","41.14332"
"343.50000","0.45799","41.14708"
"344.00000","0.45865","41.14427"
"344.50000","0.45933","41.14188"
"345.00000","0.46000","41.14439"
"345.50000","0.46067","41.14766"
"346.00000","0.46134","41.14833"
"346.50000","0.46201","41.15551"
"347.00000","0.46269","41.17051"
"347.50000","0.46334","41.16326"
"348.00000","0.46401","41.16354"
"348.50000","0.46467","41.16221"
"349.00000","0.46534","41.16416"
"349.50000","0.46600","41.16517"
"350.00000","0.46667","41.16736"
"350.50000","0.46733","41.16169"
"351.00000","0.46800","41.16110"
"351.50000","0.46868","41.17004"
"352.00000","0.46933","41.15999"
"352.50000","0.47001","41.17383"
"353.00000","0.47067","41.17414"
"353.50000","0.47134","41.18540"
"354.00000","0.47200","41.18386"
"354.50000","0.47266","41.18086"
"355.00000","0.47332","41.17732"
"355.50000","0.47399","41.16555"
"356.00000","0.47466","41.17301"
"356.50000","0.47532","41.17031"
"357.00000","0.47600","41.16838"
"357.50000","0.47667","41.16882"
"358.00000","0.47734","41.17662"
"358.50000","0.47801","41.18695"
"359.00000","0.47868","41.18661"
"359.50000","0.47935","41.18628"
"360.00000","0.48001","41.18100"
"360.50000","0.48068","41.19582"
"361.00000","0.48133","41.18034"
"361.50000","0.48200","41.19412"
"362.00000","0.48266","41.19012"
"362.50000","0.48333","41.19379"
"363.00000","0.48400","41.19054"
"363.50000","0.48467","41.18619"
"364.00000","0.48535","41.19774"
"364.50000","0.48600","41.20054"
"365.00000","0.48668","41.20768"
"365.50000","0.48733","41.19788"
"366.00000","0.48800","41.20767"
"366.50000","0.48867","41.18987"
"367.00000","0.48933","41.19856"
"367.50000","0.48999","41.20006"
"368.00000","0.49065","41.19421"
"368.50000","0.49133","41.19676"
"369.00000","0.49199","41.19666"
"369.50000","0.49267","41.20704"
"370.00000","0.49334","41.20355"
"370.50000","0.49401","41.20408"
"371.00000","0.49469","41.21363"
"371.50000","0.49535","41.21886"
"372.00000","0.49602","41.22305"
"372.50000","0.49667","41.21956"
"373.00000","0.49734","41.22234"
"373.50000","0.49800","41.22257"
"374.00000","0.49867","41.21732"
"374.50000","0.49934","41.22343"
"375.00000","0.50000","41.22088"
"375.50000","0.50067","41.21241"
"376.00000","0.50134","41.22337"
"376.50000","0.50201","41.23040"
"377.00000","0.50267","41.22669"
"377.50000","0.50334","41.23322"
"378.00000","0.50400","41.23802"
"378.50000","0.50466","41.24519"
"379.00000","0.50533","41.23969"
"379.50000","0.50599","41.23112"
"380.00000","0.50666","41.23072"
"380.50000","0.50732","41.24101"
"381.00000","0.50800","41.23212"
"381.50000","0.50866","41.23092"
"382.00000","0.50934","41.23973"
"382.50000","0.51001","41.24261"
"383.00000","0.51068","41.24016"
"383.50000","0.51135","41.25312"
"384.00000","0.51201","41.25178"
"384.50000","0.51268","41.26696"
"385.00000","0.51333","41.23941"
"385.50000","0.51401","41.24733"
"386.00000","0.51466","41.24195"
"386.50000","0.51533","41.24708"
"387.00000","0.51600","41.24700"
"387.50000","0.51667","41.24847"
"388.00000","0.51734","41.24432"
"388.50000","0.51800","41.24405"
"389.00000","0.51868","41.25926"
"389.50000","0.51934","41.25409"
"390.00000","0.52001","41.26896"
"390.50000","0.52067","41.25240"
"391.00000","0.52133","41.25226"
"391.50000","0.52199","41.25159"
"392.00000","0.52265","41.24730"
"392.50000","0.52333","41.25597"
"393.00000","0.52399","41.25276"
"393.50000","0.52467","41.24939"
"394.00000","0.52534","41.25436"
"394.50000","0.52601","41.26811"
"395.00000","0.52668","41.25542"
"395.50000","0.52735","41.27055"
"396.00000","0.52802","41.26629"
"396.50000","0.52867","41.26161"
"397.00000","0.52934","41.26538"
"397.50000","0.53000","41.25441"
"398.00000","0.53067","41.25078"
"398.50000","0.53134","41.24774"
"399.00000","0.53199","41.24506"
"399.50000","0.53267","41.25648"
"400.00000","0.53334","41.25049"
"400.50000","0.53401","41.25720"
"401.00000","0.53467","41.24879"
"401.50000","0.53535","41.25682"
"402.00000","0.53600","41.25812"
"402.50000","0.53667","41.25669"
"403.00000","0.53733","41.24951"
"403.50000","0.53799","41.23732"
"404.00000","0.53866","41.23885"
"404.50000","0.53932","41.25113"
"405.00000","0.53999","41.23783"
"405.50000","0.54066","41.23575"
"406.00000","0.54134","41.24827"
"406.50000","0.54200","41.25614"
"407.00000","0.54268","41.25871"
"407.50000","0.54335","41.26070"
"408.00000","0.54401","41.26419"
"408.50000","0.54468","41.26152"
"409.00000","0.54533","41.24208"
"409.50000","0.54601","41.25031"
"410.00000","0.54666","41.25445"
"410.50000","0.54734","41.24414"
"411.00000","0.54800","41.24309"
"411.50000","0.54866","41.23967"
"412.00000","0.54934","41.25215"
"412.50000","0.55000","41.23998"
"413.00000","0.55068","41.24550"
"413.50000","0.55134","41.23971"
"414.00000","0.55201","41.24882"
"414.50000","0.55267","41.24130"
"415.00000","0.55333","41.23772"
"415.50000","0.55400","41.24123"
"416.00000","0.55465","41.22893"
"416.50000","0.55533","41.23239"
"417.00000","0.55599","41.23569"
"417.50000","0.55666","41.23360"
"418.00000","0.55733","41.23055"
"418.50000","0.55801","41.24387"
"419.00000","0.55868","41.23995"
"419.50000","0.55935","41.24455"
"420.00000","0.56002","41.24206"
"420.50000","0.56067","41.24178"
"421.00000","0.56134","41.25193"
"421.50000","0.56200","41.24864"
"422.00000","0.56267","41.24175"
"422.50000","0.56333","41.23365"
"423.00000","0.56400","41.23657"
"423.50000","0.56467","41.23915"
"424.00000","0.56533","41.23590"
"424.50000","0.56601","41.24458"
"425.00000","0.56667","41.24341"
"425.50000","0.56735","41.25029"
"426.00000","0.56800","41.23354"
"426.50000","0.56867","41.24314"
"427.00000","0.56933","41.24157"
"427.50000","0.57000","41.24122"
"428.00000","0.57066","41.24581"
"428.50000","0.57132","41.23952"
"429.00000","0.57199","41.23438"
"429.50000","0.57266","41.23987"
"430.00000","0.57333","41.24899"
"430.50000","0.57401","41.24448"
"431.00000","0.57468","41.24961"
"431.50000","0.57535","41.25246"
"432.00000","0.57601","41.25797"
"432.50000","0.57668","41.25350"
"433.00000","0.57734","41.24338"
"433.50000","0.57801","41.25253"
"434.00000","0.57867","41.24468"
"434.50000","0.57933","41.24518"
"435.00000","0.58000","41.24757"
"435.50000","0.58066","41.24204"
"436.00000","0.58134","41.25246"
"436.50000","0.58200","41.25195"
"437.00000","0.58268","41.25707"
"437.50000","0.58334","41.24426"
"438.00000","0.58401","41.25614"
"438.50000","0.58467","41.24133"
"439.00000","0.58533","41.23925"
"439.50000","0.58600","41.24476"
"440.00000","0.58666","41.23408"
"440.50000","0.58732","41.24392"
"441.00000","0.58799","41.22734"
"441.50000","0.58866","41.23657"
"442.00000","0.58932","41.23492"
"442.50000","0.59001","41.23660"
"443.00000","0.59067","41.23834"
"443.50000","0.59134","41.24081"
"444.00000","0.59202","41.24235"
"444.50000","0.59267","41.24189"
"445.00000","0.59335","41.23943"
"445.50000","0.59400","41.23658"
"446.00000","0.59467","41.24808"
"446.50000","0.59533","41.22146"
"447.00000","0.59600","41.22914"
"447.50000","0.59666","41.22324"
"448.00000","0.59733","41.23402"
"448.50000","0.59801","41.23155"
"449.00000","0.59867","41.22743"
"449.50000","0.59935","41.24080"
"450.00000","0.60000","41.23032"
"450.50000","0.60067","41.24703"
"451.00000","0.60133","41.24630"
"451.50000","0.60200","41.24199"
"452.00000","0.60266","41.23706"
"452.50000","0.60332","41.24264"
"453.00000","0.60399","41.24487"
"453.50000","0.60465","41.23202"
"454.00000","0.60533","41.23009"
"454.50000","0.60600","41.22960"
"455.00000","0.60668","41.23704"
"455.50000","0.60735","41.24300"
"456.00000","0.60801","41.24284"
"456.50000","0.60868","41.23482"
"457.00000","0.60934","41.23000"
"457.50000","0.61001","41.23817"
"458.00000","0.61067","41.22709"
"458.50000","0.61134","41.22991"
"459.00000","0.61200","41.23303"
"459.50000","0.61266","41.22204"
"460.00000","0.61334","41.23048"
"460.50000","0.61400","41.22028"
"461.00000","0.61468","41.21809"
"461.50000","0.61534","41.21476"
"462.00000","0.61601","41.21889"
"462.50000","0.61667","41.20938"
"463.00000","0.61734","41.22503"
"463.50000","0.61800","41.21717"
"464.00000","0.61866","41.21695"
"464.50000","0.61932","41.20454"
"465.00000","0.61999","41.21076"
"465.50000","0.62066","41.20900"
"466.00000","0.62132","41.20163"
"466.50000","0.62200","41.21139"
"467.00000","0.62267","41.19831"
"467.50000","0.62334","41.20463"
"468.00000","0.62402","41.21150"
"468.50000","0.62468","41.20989"
"469.00000","0.62535","41.20778"
"469.50000","0.62600","41.20422"
"470.00000","0.62668","41.21101"
"470.50000","0.62733","41.20387"
"471.00000","0.62800","41.20719"
"471.50000","0.62867","41.19807"
"472.00000","0.62933","41.20758"
"472.50000","0.63001","41.20386"
"473.00000","0.63067","41.19673"
"473.50000","0.63135","41.20430"
"474.00000","0.63200","41.20340"
"474.50000","0.63268","41.19639"
"475.00000","0.63333","41.20524"
"475.50000","0.63400","41.19601"
"476.00000","0.63466","41.19226"
"476.50000","0.63532","41.19544"
"477.00000","0.63599","41.21023"
"477.50000","0.63666","41.19723"
"478.00000","0.63733","41.18934"
"478.50000","0.63799","41.18452"
"479.00000","0.63868","41.18953"
"479.50000","0.63934","41.18499"
"480.00000","0.64001","41.18215"
"480.50000","0.64068","41.18727"
"481.00000","0.64134","41.18369"
"481.50000","0.64201","41.19322"
"482.00000","0.64267","41.20062"
"482.50000","0.64334","41.19077"
"483.00000","0.64400","41.18147"
"483.50000","0.64467","41.17857"
"484.00000","0.64533","41.17578"
"484.50000","0.64600","41.17682"
"485.00000","0.64668","41.17464"
"485.50000","0.64733","41.17243"
"486.00000","0.64802","41.17704"
"486.50000","0.64867","41.17941"
"487.00000","0.64934","41.17829"
"487.50000","0.65000","41.17476"
"488.00000","0.65066","41.17224"
"488.50000","0.65132","41.15999"
"489.00000","0.65199","41.15960"
"489.50000","0.65266","41.14987"
"490.00000","0.65332","41.15834"
"490.50000","0.65400","41.15949"
"491.00000","0.65467","41.15090"
"491.50000","0.65534","41.15309"
"492.00000","0.65602","41.15008"
"492.50000","0.65668","41.15886"
"493.00000","0.65735","41.16649"
"493.50000","0.65801","41.15806"
"494.00000","0.65868","41.16490"
"494.50000","0.65933","41.15802"
"495.00000","0.66000","41.16301"
"495.50000","0.66067","41.15979"
"496.00000","0.66133","41.15211"
"496.50000","0.66201","41.16262"
"497.00000","0.66267","41.15623"
"497.50000","0.66334","41.15781"
"498.00000","0.66400","41.16282"
"498.50000","0.66468","41.15886"
"499.00000","0.66533","41.14914"
"499.50000","0.66600","41.15760"
"500.00000","0.66666","41.14732"
"500.50000","0.66732","41.15077"
"501.00000","0.66799","41.15161"
"501.50000","0.66866","41.13629"
"502.00000","0.66933","41.13690"
"502.50000","0.66999","41.13466"
"503.00000","0.67067","41.13762"
"503.50000","0.67134","41.13513"
"504.00000","0.67201","41.14024"
"504.50000","0.67268","41.12662"
"505.00000","0.67334","41.12936"
"505.50000","0.67402","41.13559"
"506.00000","0.67467","41.13905"
"506.50000","0.67534","41.14200"
"507.00000","0.67600","41.12173"
"507.50000","0.67667","41.11935"
"508.00000","0.67733","41.11320"
"508.50000","0.67800","41.11512"
"509.00000","0.67867","41.11696"
"509.50000","0.67933","41.11699"
"510.00000","0.68001","41.11744"
"510.50000","0.68067","41.11952"
"511.00000","0.68134","41.12019"
"511.50000","0.68200","41.11517"
"512.00000","0.68267","41.12613"
"512.50000","0.68332","41.11816"
"513.00000","0.68399","41.10989"
"513.50000","0.68466","41.11252"
"514.00000","0.68532","41.11142"
"514.50000","0.68600","41.11519"
"515.00000","0.68667","41.10854"
"515.50000","0.68734","41.12363"
"516.00000","0.68801","41.12603"
"516.50000","0.68868","41.11297"
"517.00000","0.68935","41.12998"
"517.50000","0.69001","41.11450"
"518.00000","0.69068","41.11692"
"518.50000","0.69133","41.12811"
"519.00000","0.69200","41.11895"
"519.50000","0.69267","41.11069"
"520.00000","0.69333","41.11003"
"520.50000","0.69400","41.10417"
"521.00000","0.69467","41.11151"
"521.50000","0.69535","41.11207"
"522.00000","0.69600","41.09340"
"522.50000","0.69668","41.11072"
"523.00000","0.69734","41.09571"
"523.50000","0.69801","41.10610"
"524.00000","0.69866","41.10108"
"524.50000","0.69933","41.10636"
"525.00000","0.69999","41.08962"
"525.50000","0.70065","41.09280"
"526.00000","0.70133","41.09552"
"526.50000","0.70199","41.08887"
"527.00000","0.70267","41.09348"
"527.50000","0.70334","41.08232"
"528.00000","0.70401","41.08965"
"528.50000","0.70468","41.09010"
"529.00000","0.70534","41.09377"
"529.50000","0.70602","41.08180"
"530.00000","0.70667","41.08531"
"530.50000","0.70734","41.08636"
"531.00000","0.70800","41.07719"
"531.50000","0.70867","41.07992"
"532.00000","0.70933","41.07884"
"532.50000","0.71000","41.07067"
"533.00000","0.71067","41.08286"
"533.50000","0.71134","41.07972"
"534.00000","0.71201","41.08325"
"534.50000","0.71267","41.08928"
"535.00000","0.71335","41.09278"
"535.50000","0.71400","41.08971"
"536.00000","0.71467","41.09899"
"536.50000","0.71533","41.08583"
"537.00000","0.71599","41.08607"
"537.50000","0.71666","41.08376"
"538.00000","0.71732","41.08445"
"538.50000","0.71800","41.08668"
"539.00000","0.71866","41.09244"
"539.50000","0.71934","41.08821"
"540.00000","0.72001","41.09248"
"540.50000","0.72068","41.09709"
"541.00000","0.72135","41.10182"
"541.50000","0.72201","41.10014"
"542.00000","0.72268","41.09850"
"542.50000","0.72334","41.09977"
"543.00000","0.72401","41.10618"
"543.50000","0.72466","41.09890"
"544.00000","0.72534","41.10066"
"544.50000","0.72600","41.09817"
"545.00000","0.72667","41.09853"
"545.50000","0.72734","41.10791"
"546.00000","0.72800","41.09970"
"546.50000","0.72868","41.10648"
"547.00000","0.72933","41.09976"
"547.50000","0.73001","41.10607"
"548.00000","0.73067","41.10278"
"548.50000","0.73133","41.10961"
"549.00000","0.73199","41.10300"
"549.50000","0.73265","41.10712"
"550.00000","0.73333","41.10151"
"550.50000","0.73398","41.09649"
"551.00000","0.73466","41.11763"
"551.50000","0.73534","41.10720"
"552.00000","0.73601","41.11629"
"552.50000","0.73668","41.11103"
"553.00000","0.73735","41.11597"
"553.50000","0.73802","41.13015"
"554.00000","0.73867","41.11286"
"554.50000","0.73935","41.11749"
"555.00000","0.74000","41.10641"
"555.50000","0.74067","41.12171"
"556.00000","0.74133","41.10610"
"556.50000","0.74200","41.10940"
"557.00000","0.74267","41.11119"
"557.50000","0.74334","41.10629"
"558.00000","0.74401","41.10999"
"558.50000","0.74467","41.10771"
"559.00000","0.74535","41.10931"
"559.50000","0.74600","41.11399"
"560.00000","0.74667","41.10866"
"560.50000","0.74733","41.09757"
"561.00000","0.74799","41.09620"
"561.50000","0.74866","41.09570"
"562.00000","0.74932","41.09445"
"562.50000","0.74999","41.09559"
"563.00000","0.75065","41.09278"
"563.50000","0.75134","41.08818"
"564.00000","0.75200","41.10317"
"564.50000","0.75268","41.10397"
"565.00000","0.75335","41.09863"
"565.50000","0.75401","41.09880"
"566.00000","0.75468","41.09806"
"566.50000","0.75534","41.09728"
"567.00000","0.75601","41.10408"
"567.50000","0.75666","41.08397"
"568.00000","0.75734","41.08954"
"568.50000","0.75800","41.08865"
"569.00000","0.75867","41.09064"
"569.50000","0.75934","41.08756"
"570.00000","0.76000","41.07701"
"570.50000","0.76068","41.09689"
"571.00000","0.76134","41.08300"
"571.50000","0.76201","41.09275"
"572.00000","0.76267","41.08448"
"572.50000","0.76333","41.08314"
"573.00000","0.76399","41.07962"
"573.50000","0.76466","41.07897"
"574.00000","0.76533","41.08784"
"574.50000","0.76598","41.08552"
"575.00000","0.76666","41.08563"
"575.50000","0.76733","41.09345"
"576.00000","0.76801","41.09346"
"576.50000","0.76868","41.09236"
"577.00000","0.76935","41.09646"
"577.50000","0.77002","41.09933"
"578.00000","0.77067","41.09481"
"578.50000","0.77134","41.09827"
"579.00000","0.77200","41.09050"
"579.50000","0.77267","41.10062"
"580.00000","0.77333","41.08611"
"580.50000","0.77400","41.09402"
"581.00000","0.77467","41.09540"
"581.50000","0.77534","41.09208"
"582.00000","0.77601","41.09615"
"582.50000","0.77667","41.08867"
"583.00000","0.77735","41.09350"
"583.50000","0.77800","41.08372"
"584.00000","0.77867","41.09739"
"584.50000","0.77933","41.09135"
"585.00000","0.78000","41.08991"
"585.50000","0.78066","41.08939"
"586.00000","0.78132","41.08359"
"586.50000","0.78200","41.08684"
"587.00000","0.78265","41.07940"
"587.50000","0.78333","41.08396"
"588.00000","0.78400","41.08191"
"588.50000","0.78467","41.08970"
"589.00000","0.78535","41.08701"
"589.50000","0.78601","41.09681"
"590.00000","0.78668","41.09949"
"590.50000","0.78734","41.09057"
"591.00000","0.78801","41.09298"
"591.50000","0.78866","41.09305"
"592.00000","0.78934","41.08644"
"592.50000","0.79000","41.08554"
"593.00000","0.79066","41.08963"
"593.50000","0.79134","41.08540"
"594.00000","0.79200","41.08025"
"594.50000","0.79268","41.08601"
"595.00000","0.79334","41.08246"
"595.50000","0.79401","41.09121"
"596.00000","0.79467","41.08257"
"596.50000","0.79533","41.07555"
"597.00000","0.79600","41.06412"
"597.50000","0.79666","41.06478"
"598.00000","0.79733","41.07820"
"598.50000","0.79799","41.05763"
"599.00000","0.79866","41.06694"
"599.50000","0.79933","41.05291"
"600.00000","0.80001","41.05829"
"600.50000","0.80067","41.05289"
"601.00000","0.80135","41.06252"
"601.50000","0.80202","41.05207"
"602.00000","0.80267","41.06420"
"602.50000","0.80335","41.05376"
"603.00000","0.80400","41.04473"
"603.50000","0.80467","41.05521"
"604.00000","0.80533","41.03954"
"604.50000","0.80600","41.04770"
"605.00000","0.80667","41.03803"
"605.50000","0.80733","41.04065"
"606.00000","0.80801","41.04314"
"606.50000","0.80867","41.03099"
"607.00000","0.80935","41.04072"
"607.50000","0.81000","41.03141"
"608.00000","0.81068","41.03750"
"608.50000","0.81134","41.02814"
"609.00000","0.81200","41.03141"
"609.50000","0.81266","41.02566"
"610.00000","0.81332","41.02271"
"610.50000","0.81399","41.01708"
"611.00000","0.81465","41.01319"
"611.50000","0.81533","41.00974"
"612.00000","0.81600","41.01784"
"612.50000","0.81667","41.02407"
"613.00000","0.81734","41.02779"
"613.50000","0.81801","41.02321"
"614.00000","0.81868","41.03376"
"614.50000","0.81934","41.03254"
"615.00000","0.82001","41.02822"
"615.50000","0.82067","41.02655"
"616.00000","0.82134","41.02869"
"616.50000","0.82200","41.00903"
"617.00000","0.82266","41.01162"
"617.50000","0.82334","41.00490"
"618.00000","0.82400","40.99929"
"618.50000","0.82468","41.00544"
"619.00000","0.82534","41.00320"
"619.50000","0.82601","40.99960"
"620.00000","0.82667","40.99231"
"620.50000","0.82734","40.98980"
"621.00000","0.82800","40.99012"
"621.50000","0.82866","40.97859"
"622.00000","0.82933","40.98187"
"622.50000","0.82999","40.97125"
"623.00000","0.83066","40.97344"
"623.50000","0.83132","40.96504"
"624.00000","0.83200","40.97470"
"624.50000","0.83266","40.97575"
"625.00000","0.83334","40.97697"
"625.50000","0.83402","40.95985"
"626.00000","0.83468","40.96918"
"626.50000","0.83535","40.97298"
"627.00000","0.83600","40.97144"
"627.50000","0.83668","40.97081"
"628.00000","0.83733","40.96248"
"628.50000","0.83800","40.96691"
"629.00000","0.83866","40.95822"
"629.50000","0.83933","40.96457"
"630.00000","0.84000","40.95857"
"630.50000","0.84067","40.96116"
"631.00000","0.84135","40.96439"
"631.50000","0.84200","40.95811"
"632.00000","0.84268","40.96819"
"632.50000","0.84333","40.96440"
"633.00000","0.84400","40.96751"
"633.50000","0.84466","40.96196"
"634.00000","0.84532","40.96426"
"634.50000","0.84599","40.96380"
"635.00000","0.84665","40.95362"
"635.50000","0.84733","40.95625"
"636.00000","0.84799","40.95756"
"636.50000","0.84868","40.96219"
"636.66800","0.84889","40.97161"