File: materials_lab1/ENGR314_FA19_0002_Acrylic_B_20190903_JAM_1.is_tens_RawData/Specimen_RawData_1.csv
Material,Acrylic
Geometry,Circular
Length,"2.00000",in
Diameter,"0.12700",in

Time,Extension,Load
(s),(in),(lbf)
"0.00000","0.00000","0.31372"
"0.20000","0.00022","0.60027"
"0.40000","0.00053","1.49443"
"0.60000","0.00081","2.20059"
"0.80000","0.00108","2.82076"
"1.00000","0.00134","3.42428"
"1.20000","0.00160","4.03722"
"1.40000","0.00185","4.64917"
"1.60000","0.00213","5.30397"
"1.80000","0.00241","5.93355"
"2.00000","0.00268","6.51137"
"2.20000","0.00294","7.08947"
"2.40000","0.00319","7.65116"
"2.60000","0.00346","8.26270"
"2.80000","0.00373","8.86725"
"3.00000","0.00401","9.46062"
"3.20000","0.00427","10.01884"
"3.40000","0.00454","10.56582"
"3.60000","0.00480","11.12262"
"3.80000","0.00506","11.69986"
"4.00000","0.00533","12.28081"
"4.20000","0.00560","12.84084"
"4.40000","0.00589","13.41768"
"4.60000","0.00614","13.94405"
"4.80000","0.00640","14.45975"
"5.00000","0.00666","15.01373"
"5.20000","0.00692","15.54988"
"5.40000","0.00721","16.15136"
"5.60000","0.00748","16.66517"
"5.80000","0.00774","17.17556"
"6.00000","0.00800","17.70139"
"6.20000","0.00826","18.21821"
"6.40000","0.00853","18.80365"
"6.60000","0.00881","19.33281"
"6.80000","0.00908","19.83975"
"7.00000","0.00934","20.33629"
"7.20000","0.00959","20.82307"
"7.40000","0.00986","21.36485"
"7.60000","0.01013","21.91633"
"7.80000","0.01041","22.42878"
"8.00000","0.01067","22.93206"
"8.20000","0.01094","23.42729"
"8.40000","0.01120","23.90173"
"8.60000","0.01146","24.41212"
"8.80000","0.01173","24.92404"
"9.00000","0.01200","25.43852"
"9.20000","0.01229","25.95073"
"9.40000","0.01254","26.41621"
"9.60000","0.01280","26.90047"
"9.80000","0.01306","27.39771"
"10.00000","0.01333","27.89243"
"10.20000","0.01362","28.43269"
"10.40000","0.01389","28.90132"
"10.60000","0.01414","29.35105"
"10.80000","0.01440","29.82900"
"11.00000","0.01466","30.30212"
"11.20000","0.01494","30.83098"
"11.40000","0.01521","31.32825"
"11.60000","0.01548","31.77407"
"11.80000","0.01574","32.21938"
"12.00000","0.01600","32.67935"
"12.20000","0.01626","33.17182"
"12.40000","0.01653","33.66132"
"12.60000","0.01681","34.14652"
"12.80000","0.01707","34.59880"
"13.00000","0.01734","35.04072"
"13.20000","0.01760","35.50419"
"13.40000","0.01786","35.97979"
"13.60000","0.01813","36.45221"
"13.80000","0.01840","36.92192"
"14.00000","0.01869","37.39330"
"14.20000","0.01894","37.81380"
"14.40000","0.01920","38.25732"
"14.60000","0.01946","38.73161"
"14.80000","0.01972","39.17380"
"15.00000","0.02002","39.67130"
"15.20000","0.02028","40.10161"
"15.40000","0.02054","40.52809"
"15.60000","0.02079","40.96401"
"15.80000","0.02106","41.39690"
"16.00000","0.02134","41.89410"
"16.20000","0.02161","42.34320"
"16.40000","0.02188","42.76729"
"16.60000","0.02213","43.17894"
"16.80000","0.02239","43.58434"
"17.00000","0.02267","44.05137"
"17.20000","0.02293","44.50413"
"17.40000","0.02321","44.94236"
"17.60000","0.02348","45.36342"
"17.80000","0.02373","45.75825"
"18.00000","0.02400","46.19219"
"18.20000","0.02426","46.62586"
"18.40000","0.02453","47.07084"
"18.60000","0.02480","47.49240"
"18.80000","0.02509","47.93175"
"19.00000","0.02534","48.32192"
"19.20000","0.02559","48.72979"
"19.40000","0.02586","49.16346"
"19.60000","0.02613","49.58701"
"19.80000","0.02641","50.04627"
"20.00000","0.02668","50.43502"
"20.20000","0.02694","50.81568"
"20.40000","0.02720","51.21733"
"20.60000","0.02746","51.63026"
"20.80000","0.02774","52.08539"
"21.00000","0.02801","52.50939"
"21.20000","0.02828","52.89683"
"21.40000","0.02853","53.28684"
"21.60000","0.02879","53.65355"
"21.80000","0.02906","54.08717"
"22.00000","0.02934","54.51331"
"22.20000","0.02961","54.91694"
"22.40000","0.02987","55.29816"
"22.60000","0.03014","55.67783"
"22.80000","0.03039","56.07435"
"23.00000","0.03066","56.47649"
"23.20000","0.03093","56.89559"
"23.40000","0.03120","57.28185"
"23.60000","0.03149","57.67860"
"23.80000","0.03174","58.03309"
"24.00000","0.03199","58.40905"
"24.20000","0.03226","58.80833"
"24.40000","0.03253","59.21281"
"24.60000","0.03282","59.63995"
"24.80000","0.03308","60.00779"
"25.00000","0.03334","60.35587"
"25.20000","0.03360","60.72904"
"25.40000","0.03386","61.09309"
"25.60000","0.03414","61.52255"
"25.80000","0.03441","61.90731"
"26.00000","0.03468","62.27019"
"26.20000","0.03493","62.61928"
"26.40000","0.03519","62.97706"
"26.60000","0.03546","63.37532"
"26.80000","0.03574","63.76995"
"27.00000","0.03601","64.15109"
"27.20000","0.03627","64.49618"
"27.40000","0.03654","64.83255"
"27.60000","0.03679","65.20001"
"27.80000","0.03706","65.57871"
"28.00000","0.03734","65.95306"
"28.20000","0.03760","66.31652"
"28.40000","0.03789","66.68970"
"28.60000","0.03814","67.01001"
"28.80000","0.03839","67.35763"
"29.00000","0.03866","67.71792"
"29.20000","0.03893","68.08316"
"29.40000","0.03922","68.47672"
"29.60000","0.03948","68.81030"
"29.80000","0.03974","69.13493"
"30.00000","0.04000","69.48661"
"30.20000","0.04026","69.82221"
"30.40000","0.04054","70.22580"
"30.60000","0.04081","70.56467"
"30.80000","0.04108","70.88584"
"31.00000","0.04134","71.20569"
"31.20000","0.04159","71.52807"
"31.40000","0.04186","71.90785"
"31.60000","0.04214","72.26583"
"31.80000","0.04241","72.61245"
"32.00000","0.04268","72.93723"
"32.20000","0.04294","73.26270"
"32.40000","0.04319","73.57107"
"32.60000","0.04346","73.91855"
"32.80000","0.04374","74.25727"
"33.00000","0.04400","74.58456"
"33.20000","0.04428","74.92387"
"33.40000","0.04454","75.22635"
"33.60000","0.04479","75.55893"
"33.80000","0.04506","75.89331"
"34.00000","0.04533","76.22913"
"34.20000","0.04562","76.59329"
"34.40000","0.04588","76.87503"
"34.60000","0.04614","77.16389"
"34.80000","0.04640","77.48916"
"35.00000","0.04666","77.80583"
"35.20000","0.04694","78.17199"
"35.40000","0.04721","78.49319"
"35.60000","0.04748","78.78980"
"35.80000","0.04774","79.08369"
"36.00000","0.04799","79.38413"
"36.20000","0.04827","79.72413"
"36.40000","0.04854","80.03551"
"36.60000","0.04881","80.36595"
"36.80000","0.04907","80.64861"
"37.00000","0.04933","80.92201"
"37.20000","0.04960","81.25034"
"37.40000","0.04986","81.56120"
"37.60000","0.05014","81.87889"
"37.80000","0.05040","82.18817"
"38.00000","0.05068","82.48220"
"38.20000","0.05094","82.75926"
"38.40000","0.05119","83.03790"
"38.60000","0.05146","83.35339"
"38.80000","0.05173","83.65229"
"39.00000","0.05202","83.98938"
"39.20000","0.05228","84.26382"
"39.40000","0.05254","84.51961"
"39.60000","0.05280","84.80608"
"39.80000","0.05306","85.09071"
"40.00000","0.05334","85.43098"
"40.20000","0.05361","85.71875"
"40.40000","0.05388","85.98230"
"40.60000","0.05413","86.24385"
"40.80000","0.05439","86.51792"
"41.00000","0.05467","86.82811"
"41.20000","0.05494","87.11654"
"41.40000","0.05521","87.39696"
"41.60000","0.05547","87.65858"
"41.80000","0.05574","87.90881"
"42.00000","0.05599","88.17876"
"42.20000","0.05627","88.47734"
"42.40000","0.05654","88.75982"
"42.60000","0.05680","89.01786"
"42.80000","0.05708","89.29049"
"43.00000","0.05734","89.53227"
"43.20000","0.05759","89.80349"
"43.40000","0.05786","90.07258"
"43.60000","0.05813","90.34524"
"43.80000","0.05842","90.64630"
"44.00000","0.05868","90.88934"
"44.20000","0.05894","91.11315"
"44.40000","0.05919","91.36379"
"44.60000","0.05946","91.61687"
"44.80000","0.05974","91.91907"
"45.00000","0.06001","92.17271"
"45.20000","0.06028","92.39387"
"45.40000","0.06054","92.63350"
"45.60000","0.06079","92.85283"
"45.80000","0.06106","93.12926"
"46.00000","0.06134","93.39788"
"46.20000","0.06161","93.64785"
"46.40000","0.06187","93.87226"
"46.60000","0.06214","94.09982"
"46.80000","0.06239","94.33541"
"47.00000","0.06266","94.59735"
"47.20000","0.06294","94.84350"
"47.40000","0.06320","95.07368"
"47.60000","0.06348","95.31408"
"47.80000","0.06374","95.50998"
"48.00000","0.06399","95.74171"
"48.20000","0.06426","95.98700"
"48.40000","0.06453","96.23160"
"48.60000","0.06482","96.49871"
"48.80000","0.06508","96.69459"
"49.00000","0.06534","96.89245"
"49.20000","0.06559","97.12333"
"49.40000","0.06586","97.32386"
"49.60000","0.06614","97.60455"
"49.80000","0.06641","97.82046"
"50.00000","0.06668","98.01292"
"50.20000","0.06693","98.22023"
"50.40000","0.06719","98.42802"
"50.60000","0.06746","98.67489"
"50.80000","0.06774","98.90175"
"51.00000","0.06801","99.11742"
"51.20000","0.06827","99.30951"
"51.40000","0.06853","99.48279"
"51.60000","0.06879","99.69042"
"51.80000","0.06906","99.90939"
"52.00000","0.06934","100.13182"
"52.20000","0.06960","100.33973"
"52.40000","0.06988","100.55337"
"52.60000","0.07014","100.71978"
"52.80000","0.07039","100.91362"
"53.00000","0.07067","101.12930"
"53.20000","0.07093","101.32569"
"53.40000","0.07122","101.55004"
"53.60000","0.07148","101.72336"
"53.80000","0.07174","101.88434"
"54.00000","0.07199","102.08178"
"54.20000","0.07226","102.27330"
"54.40000","0.07254","102.51458"
"54.60000","0.07281","102.69250"
"54.80000","0.07308","102.85478"
"55.00000","0.07333","103.02600"
"55.20000","0.07359","103.20520"
"55.40000","0.07387","103.40491"
"55.60000","0.07414","103.59559"
"55.80000","0.07441","103.77101"
"56.00000","0.07467","103.93040"
"56.20000","0.07493","104.09264"
"56.40000","0.07519","104.27468"
"56.60000","0.07546","104.46481"
"56.80000","0.07574","104.64997"
"57.00000","0.07600","104.80807"
"57.20000","0.07628","104.96489"
"57.40000","0.07654","105.12730"
"57.60000","0.07679","105.27445"
"57.80000","0.07706","105.46812"
"58.00000","0.07733","105.64460"
"58.20000","0.07762","105.84154"
"58.40000","0.07788","105.97777"
"58.60000","0.07813","106.11650"
"58.80000","0.07839","106.27102"
"59.00000","0.07866","106.41250"
"59.20000","0.07894","106.61921"
"59.40000","0.07921","106.77284"
"59.60000","0.07947","106.89870"
"59.80000","0.07973","107.04303"
"60.00000","0.07999","107.18150"
"60.20000","0.08027","107.36626"
"60.40000","0.08054","107.53541"
"60.60000","0.08081","107.67893"
"60.80000","0.08107","107.80032"
"61.00000","0.08133","107.92358"
"61.20000","0.08159","108.06724"
"61.40000","0.08187","108.22253"
"61.60000","0.08214","108.38102"
"61.80000","0.08241","108.50895"
"62.00000","0.08268","108.64196"
"62.20000","0.08294","108.75789"
"62.40000","0.08320","108.90770"
"62.60000","0.08346","109.04483"
"62.80000","0.08373","109.18170"
"63.00000","0.08402","109.34753"
"63.20000","0.08428","109.44376"
"63.40000","0.08454","109.54865"
"63.60000","0.08480","109.67588"
"63.80000","0.08506","109.80894"
"64.00000","0.08534","109.98295"
"64.20000","0.08561","110.10709"
"64.40000","0.08588","110.20488"
"64.60000","0.08613","110.31122"
"64.80000","0.08639","110.41999"
"65.00000","0.08667","110.57303"
"65.20000","0.08694","110.70436"
"65.40000","0.08721","110.82248"
"65.60000","0.08747","110.91258"
"65.80000","0.08773","111.00402"
"66.00000","0.08799","111.12170"
"66.20000","0.08826","111.25334"
"66.40000","0.08854","111.37428"
"66.60000","0.08880","111.48790"
"66.80000","0.08908","111.59499"
"67.00000","0.08934","111.67289"
"67.20000","0.08959","111.77759"
"67.40000","0.08986","111.89927"
"67.60000","0.09013","112.00550"
"67.80000","0.09042","112.13311"
"68.00000","0.09068","112.20777"
"68.20000","0.09093","112.29059"
"68.40000","0.09119","112.39076"
"68.60000","0.09146","112.49620"
"68.80000","0.09175","112.63273"
"69.00000","0.09202","112.72184"
"69.20000","0.09228","112.79070"
"69.40000","0.09253","112.86558"
"69.60000","0.09279","112.93806"
"69.80000","0.09307","113.06528"
"70.00000","0.09334","113.17149"
"70.20000","0.09361","113.25217"
"70.40000","0.09387","113.31847"
"70.60000","0.09413","113.38700"
"70.80000","0.09439","113.49040"
"71.00000","0.09466","113.58567"
"71.20000","0.09494","113.67770"
"71.40000","0.09521","113.75384"
"71.60000","0.09548","113.82624"
"71.80000","0.09574","113.88346"
"72.00000","0.09599","113.95865"
"72.20000","0.09626","114.04945"
"72.40000","0.09653","114.12902"
"72.60000","0.09682","114.23518"
"72.80000","0.09708","114.28349"
"73.00000","0.09733","114.34528"
"73.20000","0.09760","114.41441"
"73.40000","0.09786","114.47925"
"73.60000","0.09815","114.60002"
"73.80000","0.09841","114.65140"
"74.00000","0.09867","114.68903"
"74.20000","0.09893","114.74239"
"74.40000","0.09919","114.80130"
"74.60000","0.09947","114.90776"
"74.80000","0.09974","114.98701"
"75.00000","0.10001","115.04007"
"75.20000","0.10027","115.08853"
"75.40000","0.10053","115.12305"
"75.60000","0.10079","115.19435"
"75.80000","0.10107","115.25806"
"76.00000","0.10134","115.33473"
"76.20000","0.10160","115.38410"
"76.40000","0.10188","115.43605"
"76.60000","0.10213","115.47370"
"76.80000","0.10239","115.51714"
"77.00000","0.10266","115.59719"
"77.20000","0.10293","115.65042"
"77.40000","0.10322","115.73358"
"77.60000","0.10348","115.74973"
"77.80000","0.10373","115.77400"
"78.00000","0.10399","115.83092"
"78.20000","0.10426","115.88001"
"78.40000","0.10455","115.97149"
"78.60000","0.10482","116.00108"
"78.80000","0.10507","116.01845"
"79.00000","0.10533","116.03867"
"79.20000","0.10559","116.08132"
"79.40000","0.10587","116.16476"
"79.60000","0.10614","116.21797"
"79.80000","0.10641","116.25227"
"80.00000","0.10667","116.28528"
"80.20000","0.10693","116.30654"
"80.40000","0.10719","116.34375"
"80.60000","0.10747","116.39253"
"80.80000","0.10774","116.44636"
"81.00000","0.10801","116.46931"
"81.20000","0.10828","116.49308"
"81.40000","0.10853","116.52613"
"81.60000","0.10879","116.56024"
"81.80000","0.10906","116.60849"
"82.00000","0.10933","116.63802"
"82.20000","0.10962","116.69400"
"82.40000","0.10988","116.69982"
"82.60000","0.11013","116.70830"
"82.80000","0.11039","116.72519"
"83.00000","0.11066","116.75426"
"83.20000","0.11095","116.83504"
"83.40000","0.11122","116.85329"
"83.60000","0.11147","116.85297"
"83.80000","0.11173","116.87125"
"84.00000","0.11199","116.87933"
"84.20000","0.11227","116.93667"
"84.40000","0.11254","116.97104"
"84.60000","0.11281","116.98214"
"84.80000","0.11307","116.98342"
"85.00000","0.11333","116.98136"
"85.20000","0.11360","117.01070"
"85.40000","0.11386","117.03961"
"85.60000","0.11414","117.07793"
"85.80000","0.11441","117.09371"
"86.00000","0.11468","117.10146"
"86.20000","0.11493","117.10157"
"86.40000","0.11519","117.11418"
"86.60000","0.11546","117.13932"
"86.80000","0.11573","117.16158"
"87.00000","0.11602","117.19492"
"87.20000","0.11628","117.18360"
"87.40000","0.11653","117.17877"
"87.60000","0.11680","117.19395"
"87.80000","0.11706","117.20767"
"88.00000","0.11735","117.25671"
"88.20000","0.11762","117.27449"
"88.40000","0.11788","117.25564"
"88.60000","0.11813","117.25310"
"88.80000","0.11839","117.25077"
"89.00000","0.11867","117.29390"
"89.20000","0.11894","117.31733"
"89.40000","0.11921","117.31255"
"89.60000","0.11947","117.29647"
"89.80000","0.11973","117.28623"
"90.00000","0.11999","117.30369"
"90.20000","0.12027","117.31808"
"90.40000","0.12054","117.33293"
"90.60000","0.12081","117.32929"
"90.80000","0.12108","117.32859"
"91.00000","0.12133","117.31195"
"91.20000","0.12159","117.31421"
"91.40000","0.12187","117.33626"
"91.60000","0.12213","117.33486"
"91.80000","0.12242","117.34399"
"92.00000","0.12268","117.32876"
"92.20000","0.12293","117.31269"
"92.40000","0.12320","117.31917"
"92.60000","0.12346","117.32063"
"92.80000","0.12375","117.37017"
"93.00000","0.12402","117.35346"
"93.20000","0.12427","117.32317"
"93.40000","0.12453","117.31903"
"93.60000","0.12479","117.29404"
"93.80000","0.12507","117.32509"
"94.00000","0.12534","117.32943"
"94.20000","0.12561","117.31575"
"94.40000","0.12587","117.29207"
"94.60000","0.12613","117.27032"
"94.80000","0.12640","117.28060"
"95.00000","0.12667","117.28754"
"95.20000","0.12694","117.29654"
"95.40000","0.12721","117.27534"
"95.60000","0.12747","117.26170"
"95.80000","0.12773","117.23449"
"96.00000","0.12800","117.22459"
"96.20000","0.12827","117.22655"
"96.40000","0.12853","117.21450"
"96.60000","0.12882","117.22996"
"96.80000","0.12907","117.19182"
"97.00000","0.12933","117.17253"
"97.20000","0.12960","117.16412"
"97.40000","0.12986","117.15583"
"97.60000","0.13015","117.17789"
"97.80000","0.13042","117.15348"
"98.00000","0.13067","117.11532"
"98.20000","0.13093","117.09293"
"98.40000","0.13119","117.07209"
"98.60000","0.13147","117.09758"
"98.80000","0.13174","117.09091"
"99.00000","0.13201","117.06483"
"99.20000","0.13227","117.02769"
"99.40000","0.13252","116.99710"
"99.60000","0.13280","116.99961"
"99.80000","0.13307","116.99791"
"100.00000","0.13334","116.98902"
"100.20000","0.13361","116.95157"
"100.40000","0.13387","116.91503"
"100.60000","0.13413","116.88979"
"100.80000","0.13440","116.87169"
"101.00000","0.13467","116.86462"
"101.20000","0.13493","116.84855"
"101.40000","0.13522","116.84640"
"101.60000","0.13547","116.80591"
"101.80000","0.13573","116.76104"
"102.00000","0.13600","116.75009"
"102.20000","0.13626","116.73715"
"102.40000","0.13655","116.74571"
"102.60000","0.13682","116.71009"
"102.80000","0.13707","116.66597"
"103.00000","0.13733","116.63183"
"103.20000","0.13759","116.59923"
"103.40000","0.13787","116.61650"
"103.60000","0.13814","116.59228"
"103.80000","0.13841","116.55694"
"104.00000","0.13867","116.52137"
"104.20000","0.13892","116.47475"
"104.40000","0.13919","116.47284"
"104.60000","0.13947","116.46388"
"104.80000","0.13974","116.44219"
"105.00000","0.14001","116.41119"
"105.20000","0.14027","116.37497"
"105.40000","0.14053","116.33693"
"105.60000","0.14079","116.31970"
"105.80000","0.14107","116.30217"
"106.00000","0.14133","116.27848"
"106.20000","0.14162","116.25978"
"106.40000","0.14187","116.20927"
"106.60000","0.14213","116.17394"
"106.80000","0.14240","116.15285"
"107.00000","0.14266","116.12931"
"107.20000","0.14295","116.13858"
"107.40000","0.14322","116.10558"
"107.60000","0.14347","116.04822"
"107.80000","0.14373","116.01465"
"108.00000","0.14399","115.96847"
"108.20000","0.14427","115.98307"
"108.40000","0.14455","115.96566"
"108.60000","0.14481","115.92267"
"108.80000","0.14507","115.87721"
"109.00000","0.14532","115.83402"
"109.20000","0.14559","115.81820"
"109.40000","0.14587","115.81482"
"109.60000","0.14614","115.78687"
"109.80000","0.14641","115.74777"
"110.00000","0.14667","115.69450"
"110.20000","0.14693","115.65435"
"110.40000","0.14720","115.63340"
"110.60000","0.14746","115.61066"
"110.80000","0.14773","115.57902"
"111.00000","0.14802","115.56515"
"111.20000","0.14827","115.51252"
"111.40000","0.14853","115.47274"
"111.60000","0.14880","115.44586"
"111.80000","0.14906","115.42559"
"112.00000","0.14935","115.43141"
"112.20000","0.14962","115.37117"
"112.40000","0.14987","115.31634"
"112.60000","0.15013","115.27293"
"112.80000","0.15039","115.24170"
"113.00000","0.15067","115.24923"
"113.20000","0.15095","115.22146"
"113.40000","0.15121","115.18094"
"113.60000","0.15147","115.12130"
"113.80000","0.15172","115.06817"
"114.00000","0.15200","115.05045"
"114.20000","0.15227","115.03084"
"114.40000","0.15254","115.00302"
"114.60000","0.15281","114.95833"
"114.80000","0.15307","114.91260"
"115.00000","0.15333","114.87710"
"115.20000","0.15360","114.84525"
"115.40000","0.15387","114.83770"
"115.60000","0.15413","114.78948"
"115.80000","0.15442","114.76378"
"116.00000","0.15467","114.69862"
"116.20000","0.15493","114.65332"
"116.40000","0.15520","114.62935"
"116.60000","0.15546","114.60761"
"116.80000","0.15575","114.60464"
"117.00000","0.15602","114.55503"
"117.20000","0.15627","114.49619"
"117.40000","0.15653","114.44917"
"117.60000","0.15679","114.41264"
"117.80000","0.15707","114.40352"
"118.00000","0.15735","114.37294"
"118.20000","0.15761","114.32519"
"118.40000","0.15787","114.26364"
"118.60000","0.15812","114.21683"
"118.80000","0.15840","114.21238"
"119.00000","0.15867","114.19037"
"119.20000","0.15894","114.16298"
"119.40000","0.15921","114.09947"
"119.60000","0.15947","114.05194"
"119.80000","0.15973","114.00653"
"120.00000","0.16000","113.97573"
"120.20000","0.16027","113.96126"
"120.40000","0.16054","113.91353"
"120.60000","0.16082","113.88938"
"120.80000","0.16107","113.82998"
"121.00000","0.16133","113.79692"
"121.20000","0.16160","113.75993"
"121.40000","0.16186","113.71818"
"121.60000","0.16215","113.71478"
"121.80000","0.16242","113.65421"
"122.00000","0.16267","113.59899"
"122.20000","0.16293","113.55052"
"122.40000","0.16319","113.50419"
"122.60000","0.16347","113.51002"
"122.80000","0.16375","113.48288"
"123.00000","0.16401","113.42634"
"123.20000","0.16427","113.37143"
"123.40000","0.16452","113.31156"
"123.60000","0.16480","113.30678"
"123.80000","0.16507","113.26775"
"124.00000","0.16534","113.23800"
"124.20000","0.16561","113.18030"
"124.40000","0.16587","113.11787"
"124.60000","0.16613","113.09566"
"124.80000","0.16640","113.06188"
"125.00000","0.16667","113.03887"
"125.20000","0.16694","113.00610"
"125.40000","0.16722","112.96825"
"125.60000","0.16747","112.90352"
"125.80000","0.16773","112.85370"
"126.00000","0.16800","112.82683"
"126.20000","0.16826","112.78740"
"126.40000","0.16855","112.77948"
"126.60000","0.16882","112.72687"
"126.80000","0.16907","112.65999"
"127.00000","0.16933","112.61520"
"127.20000","0.16959","112.57382"
"127.40000","0.16987","112.56606"
"127.60000","0.17015","112.53047"
"127.80000","0.17041","112.47411"
"128.00000","0.17067","112.41590"
"128.20000","0.17092","112.35243"
"128.40000","0.17119","112.33299"
"128.60000","0.17147","112.31719"
"128.80000","0.17174","112.28023"
"129.00000","0.17201","112.23247"
"129.20000","0.17227","112.16723"
"129.40000","0.17253","112.11107"
"129.60000","0.17279","112.09381"
"129.80000","0.17307","112.06411"
"130.00000","0.17334","112.01782"
"130.20000","0.17362","111.98423"
"130.40000","0.17387","111.92331"
"130.60000","0.17413","111.86843"
"130.80000","0.17440","111.84085"
"131.00000","0.17466","111.79655"
"131.20000","0.17495","111.78962"
"131.40000","0.17522","111.73022"
"131.60000","0.17547","111.66531"
"131.80000","0.17573","111.62292"
"132.00000","0.17599","111.57424"
"132.20000","0.17627","111.57892"
"132.40000","0.17655","111.53626"
"132.60000","0.17681","111.47978"
"132.80000","0.17707","111.41440"
"133.00000","0.17733","111.35935"
"133.20000","0.17759","111.34058"
"133.40000","0.17787","111.30879"
"133.60000","0.17814","111.27749"
"133.80000","0.17841","111.21422"
"134.00000","0.17867","111.15305"
"134.20000","0.17893","111.11276"
"134.40000","0.17919","111.08986"
"134.60000","0.17947","111.05616"
"134.80000","0.17974","111.00501"
"135.00000","0.18002","110.96904"
"135.20000","0.18027","110.90678"
"135.40000","0.18053","110.85133"
"135.60000","0.18080","110.82246"
"135.80000","0.18106","110.79683"
"136.00000","0.18135","110.78573"
"136.20000","0.18161","110.72141"
"136.40000","0.18187","110.65301"
"136.60000","0.18213","110.60926"
"136.80000","0.18239","110.55872"
"137.00000","0.18268","110.55938"
"137.20000","0.18295","110.51059"
"137.40000","0.18321","110.45539"
"137.60000","0.18347","110.39155"
"137.80000","0.18372","110.33880"
"138.00000","0.18400","110.32968"
"138.20000","0.18427","110.29544"
"138.40000","0.18454","110.25259"
"138.60000","0.18481","110.19068"
"138.80000","0.18507","110.13312"
"139.00000","0.18533","110.08367"
"139.20000","0.18560","110.04769"
"139.40000","0.18587","110.02101"
"139.60000","0.18614","109.97210"
"139.80000","0.18642","109.92327"
"140.00000","0.18667","109.85442"
"140.20000","0.18693","109.81110"
"140.40000","0.18720","109.78612"
"140.60000","0.18746","109.73761"
"140.80000","0.18775","109.72277"
"141.00000","0.18802","109.66397"
"141.20000","0.18827","109.59300"
"141.40000","0.18853","109.53606"
"141.60000","0.18879","109.49116"
"141.80000","0.18908","109.49101"
"142.00000","0.18935","109.45107"
"142.20000","0.18961","109.38900"
"142.40000","0.18987","109.32869"
"142.60000","0.19012","109.25841"
"142.80000","0.19040","109.23669"
"143.00000","0.19068","109.21304"
"143.20000","0.19094","109.16138"
"143.40000","0.19121","109.09947"
"143.60000","0.19147","109.02814"
"143.80000","0.19173","108.99033"
"144.00000","0.19200","108.95279"
"144.20000","0.19227","108.92398"
"144.40000","0.19254","108.88934"
"144.60000","0.19282","108.84570"
"144.80000","0.19307","108.77068"
"145.00000","0.19333","108.72457"
"145.20000","0.19360","108.68237"
"145.40000","0.19387","108.63704"
"145.60000","0.19415","108.62347"
"145.80000","0.19441","108.54817"
"146.00000","0.19467","108.48281"
"146.20000","0.19493","108.44391"
"146.40000","0.19519","108.40436"
"146.60000","0.19548","108.39289"
"146.80000","0.19575","108.34983"
"147.00000","0.19601","108.29476"
"147.20000","0.19627","108.20347"
"147.40000","0.19652","108.15299"
"147.60000","0.19680","108.13139"
"147.80000","0.19707","108.09876"
"148.00000","0.19735","108.06461"
"148.20000","0.19761","108.00238"
"148.40000","0.19787","107.93159"
"148.60000","0.19812","107.88984"
"148.80000","0.19840","107.86328"
"149.00000","0.19867","107.80969"
"149.20000","0.19894","107.76603"
"149.40000","0.19922","107.72325"
"149.60000","0.19947","107.65651"
"149.80000","0.19973","107.60308"
"150.00000","0.20000","107.57507"
"150.20000","0.20026","107.52887"
"150.40000","0.20055","107.52493"
"150.60000","0.20081","107.46207"
"150.80000","0.20107","107.38709"
"151.00000","0.20133","107.35294"
"151.20000","0.20159","107.28983"
"151.40000","0.20188","107.28115"
"151.60000","0.20215","107.25018"
"151.80000","0.20241","107.17361"
"152.00000","0.20267","107.10588"
"152.20000","0.20292","107.05172"
"152.40000","0.20320","107.03058"
"152.60000","0.20348","107.00426"
"152.80000","0.20374","106.95514"
"153.00000","0.20401","106.89625"
"153.20000","0.20427","106.84200"
"153.40000","0.20452","106.78590"
"153.60000","0.20479","106.75796"
"153.80000","0.20507","106.72430"
"154.00000","0.20534","106.65986"
"154.20000","0.20561","106.61759"
"154.40000","0.20587","106.55718"
"154.60000","0.20612","106.51258"
"154.80000","0.20640","106.48482"
"155.00000","0.20666","106.44766"
"155.20000","0.20695","106.42459"
"155.40000","0.20721","106.35428"
"155.60000","0.20747","106.28879"
"155.80000","0.20773","106.24058"
"156.00000","0.20799","106.20087"
"156.20000","0.20828","106.17672"
"156.40000","0.20855","106.12864"
"156.60000","0.20881","106.06636"
"156.80000","0.20907","106.00265"
"157.00000","0.20932","105.95259"
"157.20000","0.20960","105.93898"
"157.40000","0.20988","105.90988"
"157.60000","0.21015","105.85270"
"157.80000","0.21040","105.78356"
"158.00000","0.21067","105.71949"
"158.20000","0.21093","105.69109"
"158.40000","0.21120","105.65141"
"158.60000","0.21147","105.61881"
"158.80000","0.21174","105.57232"
"159.00000","0.21201","105.51613"
"159.20000","0.21227","105.45781"
"159.40000","0.21253","105.41344"
"159.60000","0.21280","105.37273"
"159.80000","0.21307","105.32865"
"160.00000","0.21335","105.31150"
"160.20000","0.21361","105.23862"
"160.40000","0.21387","105.17253"
"160.60000","0.21413","105.12684"
"160.80000","0.21439","105.08944"
"161.00000","0.21468","105.08601"
"161.20000","0.21495","105.03097"
"161.40000","0.21521","104.97032"
"161.60000","0.21547","104.90631"
"161.80000","0.21572","104.84942"
"162.00000","0.21600","104.82660"
"162.20000","0.21628","104.79297"
"162.40000","0.21654","104.74204"
"162.60000","0.21681","104.68266"
"162.80000","0.21706","104.62156"
"163.00000","0.21732","104.58487"
"163.20000","0.21760","104.55411"
"163.40000","0.21787","104.50489"
"163.60000","0.21814","104.45335"
"163.80000","0.21841","104.39620"
"164.00000","0.21867","104.32742"
"164.20000","0.21892","104.28345"
"164.40000","0.21920","104.25324"
"164.60000","0.21947","104.20927"
"164.80000","0.21975","104.18920"
"165.00000","0.22001","104.12346"
"165.20000","0.22027","104.05943"
"165.40000","0.22053","104.01255"
"165.60000","0.22079","103.96316"
"165.80000","0.22108","103.93975"
"166.00000","0.22135","103.89721"
"166.20000","0.22161","103.83907"
"166.40000","0.22187","103.76823"
"166.60000","0.22212","103.71172"
"166.80000","0.22240","103.69585"
"167.00000","0.22268","103.66180"
"167.20000","0.22295","103.61080"
"167.40000","0.22320","103.54245"
"167.60000","0.22347","103.49418"
"167.80000","0.22373","103.44233"
"168.00000","0.22400","103.40223"
"168.20000","0.22427","103.37567"
"168.40000","0.22454","103.31594"
"168.60000","0.22481","103.26089"
"168.80000","0.22507","103.19527"
"169.00000","0.22533","103.15517"
"169.20000","0.22560","103.11568"
"169.40000","0.22587","103.08815"
"169.60000","0.22615","103.06133"
"169.80000","0.22641","102.98562"
"170.00000","0.22667","102.91524"
"170.20000","0.22693","102.87874"
"170.40000","0.22719","102.82651"
"170.60000","0.22748","102.81320"
"170.80000","0.22775","102.76332"
"171.00000","0.22801","102.69975"
"171.20000","0.22827","102.64101"
"171.40000","0.22852","102.58948"
"171.60000","0.22880","102.57433"
"171.80000","0.22908","102.54368"
"172.00000","0.22934","102.47984"
"172.20000","0.22961","102.42127"
"172.40000","0.22986","102.35331"
"172.60000","0.23013","102.32369"
"172.80000","0.23040","102.28262"
"173.00000","0.23067","102.24957"
"173.20000","0.23094","102.20072"
"173.40000","0.23121","102.14842"
"173.60000","0.23146","102.07761"
"173.80000","0.23172","102.03122"
"174.00000","0.23200","102.00438"
"174.20000","0.23227","101.95653"
"174.40000","0.23255","101.93290"
"174.60000","0.23281","101.85301"
"174.80000","0.23307","101.79554"
"175.00000","0.23333","101.75824"
"175.20000","0.23359","101.70641"
"175.40000","0.23388","101.69603"
"175.60000","0.23415","101.65133"
"175.80000","0.23441","101.58400"
"176.00000","0.23467","101.52944"
"176.20000","0.23492","101.47524"
"176.40000","0.23520","101.45698"
"176.60000","0.23548","101.41709"
"176.80000","0.23574","101.36382"
"177.00000","0.23600","101.29715"
"177.20000","0.23626","101.23697"
"177.40000","0.23653","101.20129"
"177.60000","0.23680","101.17374"
"177.80000","0.23707","101.13903"
"178.00000","0.23734","101.08759"
"178.20000","0.23761","101.03712"
"178.40000","0.23787","100.98021"
"178.60000","0.23812","100.92277"
"178.80000","0.23840","100.88615"
"179.00000","0.23867","100.83951"
"179.20000","0.23895","100.79896"
"179.40000","0.23921","100.74396"
"179.60000","0.23946","100.68265"
"179.80000","0.23973","100.64578"
"180.00000","0.23999","100.59982"
"180.20000","0.24028","100.59376"
"180.40000","0.24055","100.53580"
"180.60000","0.24081","100.46561"
"180.80000","0.24106","100.40760"
"181.00000","0.24132","100.34292"
"181.20000","0.24160","100.33354"
"181.40000","0.24188","100.30125"
"181.60000","0.24214","100.24687"
"181.80000","0.24240","100.19383"
"182.00000","0.24266","100.12437"
"182.20000","0.24293","100.09125"
"182.40000","0.24320","100.04884"
"182.60000","0.24347","100.01042"
"182.80000","0.24374","99.96205"
"183.00000","0.24401","99.89141"
"183.20000","0.24426","99.84302"
"183.40000","0.24453","99.80602"
"183.60000","0.24480","99.76332"
"183.80000","0.24507","99.72870"
"184.00000","0.24536","99.70766"
"184.20000","0.24561","99.63208"
"184.40000","0.24587","99.56966"
"184.60000","0.24613","99.52878"
"184.80000","0.24639","99.48676"
"185.00000","0.24668","99.47527"
"185.20000","0.24695","99.42113"
"185.40000","0.24721","99.34405"
"185.60000","0.24747","99.29265"
"185.80000","0.24772","99.23199"
"186.00000","0.24800","99.22389"
"186.20000","0.24828","99.17926"
"186.40000","0.24854","99.12684"
"186.60000","0.24880","99.06378"
"186.80000","0.24906","99.00407"
"187.00000","0.24932","98.96963"
"187.20000","0.24960","98.93928"
"187.40000","0.24987","98.89870"
"187.60000","0.25014","98.82979"
"187.80000","0.25041","98.75639"
"188.00000","0.25067","98.71600"
"188.20000","0.25092","98.66664"
"188.40000","0.25120","98.64232"
"188.60000","0.25147","98.58663"
"188.80000","0.25175","98.56403"
"189.00000","0.25201","98.48970"
"189.20000","0.25226","98.43183"
"189.40000","0.25253","98.38726"
"189.60000","0.25279","98.34029"
"189.80000","0.25308","98.32675"
"190.00000","0.25335","98.27027"
"190.20000","0.25361","98.19546"
"190.40000","0.25387","98.14800"
"190.60000","0.25412","98.08581"
"190.80000","0.25440","98.06663"
"191.00000","0.25468","98.03093"
"191.20000","0.25495","97.98370"
"191.40000","0.25520","97.92190"
"191.60000","0.25546","97.85477"
"191.80000","0.25572","97.82433"
"192.00000","0.25600","97.78787"
"192.20000","0.25627","97.74329"
"192.40000","0.25654","97.68128"
"192.60000","0.25681","97.62638"
"192.80000","0.25706","97.57355"
"193.00000","0.25733","97.53639"
"193.20000","0.25760","97.49823"
"193.40000","0.25787","97.45896"
"193.60000","0.25815","97.43252"
"193.80000","0.25841","97.35738"
"194.00000","0.25866","97.30505"
"194.20000","0.25893","97.25906"
"194.40000","0.25919","97.21120"
"194.60000","0.25948","97.20555"
"194.80000","0.25975","97.14927"
"195.00000","0.26001","97.07854"
"195.20000","0.26026","97.01443"
"195.40000","0.26052","96.96550"
"195.60000","0.26080","96.95036"
"195.80000","0.26108","96.92137"
"196.00000","0.26135","96.86204"
"196.20000","0.26160","96.79586"
"196.40000","0.26186","96.73297"
"196.60000","0.26213","96.71572"
"196.80000","0.26240","96.68423"
"197.00000","0.26268","96.64062"
"197.20000","0.26294","96.57879"
"197.40000","0.26321","96.53409"
"197.60000","0.26346","96.47590"
"197.80000","0.26373","96.43481"
"198.00000","0.26400","96.41502"
"198.20000","0.26427","96.35921"
"198.40000","0.26456","96.33945"
"198.60000","0.26481","96.27720"
"198.80000","0.26506","96.21039"
"199.00000","0.26533","96.16676"
"199.20000","0.26559","96.12860"
"199.40000","0.26588","96.11617"
"199.60000","0.26615","96.06058"
"199.80000","0.26641","95.98958"
"200.00000","0.26666","95.94100"
"200.20000","0.26692","95.89012"
"200.40000","0.26720","95.88488"
"200.60000","0.26748","95.84458"
"200.80000","0.26775","95.78269"
"201.00000","0.26800","95.72609"
"201.20000","0.26826","95.67121"
"201.40000","0.26853","95.64620"
"201.60000","0.26880","95.60933"
"201.80000","0.26908","95.57987"
"202.00000","0.26934","95.52684"
"202.20000","0.26960","95.46846"
"202.40000","0.26986","95.41447"
"202.60000","0.27013","95.38492"
"202.80000","0.27040","95.35525"
"203.00000","0.27067","95.32158"
"203.20000","0.27095","95.28976"
"203.40000","0.27121","95.22588"
"203.60000","0.27147","95.18478"
"203.80000","0.27173","95.14167"
"204.00000","0.27199","95.09626"
"204.20000","0.27228","95.09610"
"204.40000","0.27255","95.03778"
"204.60000","0.27281","94.96729"
"204.80000","0.27306","94.91839"
"205.00000","0.27332","94.87309"
"205.20000","0.27360","94.85958"
"205.40000","0.27388","94.82766"
"205.60000","0.27415","94.77640"
"205.80000","0.27440","94.72229"
"206.00000","0.27466","94.66471"
"206.20000","0.27493","94.64850"
"206.40000","0.27520","94.60951"
"206.60000","0.27547","94.57756"
"206.80000","0.27574","94.52566"
"207.00000","0.27600","94.47109"
"207.20000","0.27626","94.42321"
"207.40000","0.27653","94.39496"
"207.60000","0.27680","94.36969"
"207.80000","0.27707","94.32489"
"208.00000","0.27735","94.29541"
"208.20000","0.27761","94.21872"
"208.40000","0.27786","94.17277"
"208.60000","0.27813","94.13876"
"208.80000","0.27839","94.10616"
"209.00000","0.27868","94.10517"
"209.20000","0.27895","94.06222"
"209.40000","0.27921","94.00174"
"209.60000","0.27946","93.94407"
"209.80000","0.27972","93.90998"
"210.00000","0.28000","93.90992"
"210.20000","0.28028","93.86201"
"210.40000","0.28055","93.81413"
"210.60000","0.28080","93.75650"
"210.80000","0.28106","93.70624"
"211.00000","0.28133","93.68572"
"211.20000","0.28160","93.65523"
"211.40000","0.28187","93.63207"
"211.60000","0.28214","93.57542"
"211.80000","0.28240","93.53100"
"212.00000","0.28266","93.48268"
"212.20000","0.28293","93.44874"
"212.40000","0.28320","93.42053"
"212.60000","0.28347","93.39279"
"212.80000","0.28375","93.35593"
"213.00000","0.28401","93.29966"
"213.20000","0.28426","93.25407"
"213.40000","0.28453","93.21750"
"213.60000","0.28479","93.18635"
"213.80000","0.28508","93.18006"
"214.00000","0.28535","93.12128"
"214.20000","0.28560","93.06828"
"214.40000","0.28586","93.02026"
"214.60000","0.28612","92.97888"
"214.80000","0.28641","92.99059"
"215.00000","0.28668","92.96631"
"215.20000","0.28695","92.91173"
"215.40000","0.28720","92.84533"
"215.60000","0.28746","92.80170"
"215.80000","0.28773","92.78101"
"216.00000","0.28800","92.76095"
"216.20000","0.28828","92.72991"
"216.40000","0.28854","92.67967"
"216.60000","0.28881","92.63175"
"216.80000","0.28906","92.59132"
"217.00000","0.28933","92.56651"
"217.20000","0.28960","92.53479"
"217.40000","0.28987","92.50158"
"217.60000","0.29015","92.46514"
"217.80000","0.29040","92.41745"
"218.00000","0.29066","92.37561"
"218.20000","0.29093","92.34017"
"218.40000","0.29119","92.30885"
"218.60000","0.29148","92.31725"
"218.80000","0.29175","92.27343"
"219.00000","0.29200","92.20359"
"219.20000","0.29226","92.17150"
"219.40000","0.29252","92.13440"
"219.60000","0.29280","92.13030"
"219.80000","0.29308","92.09793"
"220.00000","0.29335","92.04426"
"220.20000","0.29360","91.98878"
"220.40000","0.29386","91.94531"
"220.60000","0.29413","91.92927"
"220.80000","0.29440","91.91152"
"221.00000","0.29468","91.88709"
"221.20000","0.29494","91.83483"
"221.40000","0.29520","91.78665"
"221.60000","0.29546","91.75156"
"221.80000","0.29573","91.73253"
"222.00000","0.29600","91.71002"
"222.20000","0.29627","91.67902"
"222.40000","0.29655","91.64241"
"222.60000","0.29680","91.59192"
"222.80000","0.29706","91.55151"
"223.00000","0.29733","91.52539"
"223.20000","0.29759","91.49583"
"223.40000","0.29788","91.49445"
"223.60000","0.29815","91.44497"
"223.80000","0.29840","91.39408"
"224.00000","0.29866","91.35229"
"224.20000","0.29892","91.32869"
"224.40000","0.29921","91.33197"
"224.60000","0.29948","91.29206"
"224.80000","0.29975","91.24466"
"225.00000","0.30000","91.19571"
"225.20000","0.30025","91.14797"
"225.40000","0.30053","91.14001"
"225.60000","0.30080","91.12756"
"225.80000","0.30108","91.09991"
"226.00000","0.30134","91.05436"
"226.20000","0.30160","91.00156"
"226.40000","0.30186","90.96685"
"226.60000","0.30213","90.94355"
"226.80000","0.30240","90.92471"
"227.00000","0.30267","90.88999"
"227.20000","0.30295","90.86042"
"227.40000","0.30320","90.81442"
"227.60000","0.30346","90.78092"
"227.80000","0.30373","90.76041"
"228.00000","0.30399","90.73019"
"228.20000","0.30428","90.73254"
"228.40000","0.30455","90.67597"
"228.60000","0.30480","90.62252"
"228.80000","0.30506","90.59230"
"229.00000","0.30532","90.54985"
"229.20000","0.30561","90.55663"
"229.40000","0.30588","90.54129"
"229.60000","0.30615","90.48250"
"229.80000","0.30640","90.42818"
"230.00000","0.30666","90.38172"
"230.20000","0.30693","90.37206"
"230.40000","0.30720","90.36050"
"230.60000","0.30748","90.33228"
"230.80000","0.30774","90.28590"
"231.00000","0.30800","90.24187"
"231.20000","0.30826","90.20369"
"231.40000","0.30853","90.19128"
"231.60000","0.30880","90.15967"
"231.80000","0.30907","90.12918"
"232.00000","0.30935","90.09468"
"232.20000","0.30960","90.03963"
"232.40000","0.30986","90.00326"
"232.60000","0.31013","89.97603"
"232.80000","0.31039","89.95443"
"233.00000","0.31069","89.96395"
"233.20000","0.31095","89.90894"
"233.40000","0.31120","89.86388"
"233.60000","0.31146","89.81549"
"233.80000","0.31172","89.78602"
"234.00000","0.31201","89.79227"
"234.20000","0.31228","89.76016"
"234.40000","0.31255","89.71083"
"234.60000","0.31280","89.65662"
"234.80000","0.31306","89.60052"
"235.00000","0.31333","89.59976"
"235.20000","0.31360","89.57303"
"235.40000","0.31388","89.53834"
"235.60000","0.31414","89.49789"
"235.80000","0.31440","89.44349"
"236.00000","0.31466","89.41188"
"236.20000","0.31493","89.37855"
"236.40000","0.31520","89.35870"
"236.60000","0.31547","89.31579"
"236.80000","0.31575","89.28674"
"237.00000","0.31600","89.22690"
"237.20000","0.31626","89.18841"
"237.40000","0.31653","89.15401"
"237.60000","0.31680","89.11150"
"237.80000","0.31708","89.08997"
"238.00000","0.31735","89.02045"
"238.20000","0.31760","88.96017"
"238.40000","0.31786","88.91052"
"238.60000","0.31812","88.86205"
"238.80000","0.31841","88.86071"
"239.00000","0.31868","88.79805"
"239.20000","0.31894","88.73450"
"239.40000","0.31920","88.66703"
"239.60000","0.31946","88.60273"
"239.80000","0.31973","88.56598"
"240.00000","0.32000","88.52277"
"240.20000","0.32028","88.46385"
"240.40000","0.32054","88.38215"
"240.60000","0.32080","88.29083"
"240.80000","0.32106","88.22277"
"241.00000","0.32133","88.16438"
"241.20000","0.32160","88.07861"
"241.40000","0.32187","87.98673"
"241.60000","0.32215","87.90022"
"241.80000","0.32240","87.77945"
"242.00000","0.32266","87.68489"
"242.20000","0.32293","87.56167"
"242.40000","0.32319","87.44248"
"242.60000","0.32348","87.32928"
"242.80000","0.32375","87.15966"
"243.00000","0.32400","86.97146"
"243.20000","0.32426","86.76991"
"243.40000","0.32452","86.54034"
"243.60000","0.32480","86.29881"
"243.80000","0.32508","85.97994"
"244.00000","0.32534","85.55042"
"244.20000","0.32560","84.95502"
"244.40000","0.32585","83.99095"
"244.55600","0.32609","76.75981"
"244.56300","0.32611","63.00027"
"244.56900","0.32612","49.00305"
"244.57500","0.32613","35.44356"
"244.58100","0.32614","23.61584"
"244.59000","0.32614","10.23649"
"244.59100","0.32615","9.08110"