File: materials_lab1/ENGR314_FA19_0002_2024Aluminum_A_20190903_TheSeniors.is_tens_RawData/Specimen_RawData_1.csv
Material,Steel
Geometry,Circular
Length,"2.00000",in
Diameter,"0.12500",in

Time,Extension,Load
(s),(in),(lbf)
"0.00000","0.00000","0.05029"
"0.40000","0.00013","3.52040"
"0.80000","0.00027","8.08062"
"1.20000","0.00040","13.27248"
"1.60000","0.00053","18.25999"
"2.00000","0.00068","23.57380"
"2.40000","0.00080","28.30922"
"2.80000","0.00093","32.95883"
"3.20000","0.00107","37.87367"
"3.60000","0.00120","42.19622"
"4.00000","0.00134","47.11095"
"4.40000","0.00147","51.35454"
"4.80000","0.00160","55.87922"
"5.20000","0.00173","60.37608"
"5.60000","0.00187","64.64412"
"6.00000","0.00201","69.30390"
"6.40000","0.00213","73.37419"
"6.80000","0.00228","78.03754"
"7.20000","0.00240","82.13685"
"7.60000","0.00253","86.32787"
"8.00000","0.00267","90.70698"
"8.40000","0.00280","94.67256"
"8.80000","0.00294","99.07573"
"9.20000","0.00307","102.92409"
"9.60000","0.00321","107.31563"
"10.00000","0.00334","111.42931"
"10.40000","0.00347","115.20146"
"10.80000","0.00361","119.55436"
"11.20000","0.00373","123.27889"
"11.60000","0.00388","127.57856"
"12.00000","0.00400","131.41185"
"12.40000","0.00413","135.27330"
"12.80000","0.00427","139.34362"
"13.20000","0.00440","143.02937"
"13.60000","0.00454","147.26296"
"14.00000","0.00467","150.92751"
"14.40000","0.00481","154.83367"
"14.80000","0.00494","158.69418"
"15.20000","0.00507","162.34748"
"15.60000","0.00521","166.39115"
"16.00000","0.00533","169.92687"
"16.40000","0.00547","173.82462"
"16.80000","0.00560","177.54053"
"17.20000","0.00573","181.34066"
"17.60000","0.00587","185.28066"
"18.00000","0.00600","188.70558"
"18.40000","0.00614","192.77984"
"18.80000","0.00627","196.27792"
"19.20000","0.00641","200.08487"
"19.60000","0.00654","203.74094"
"20.00000","0.00667","207.22834"
"20.40000","0.00681","211.11630"
"20.80000","0.00693","214.44653"
"21.20000","0.00708","218.38175"
"21.60000","0.00720","221.88565"
"22.00000","0.00734","225.37789"
"22.40000","0.00747","229.12526"
"22.80000","0.00760","232.41747"
"23.20000","0.00774","236.35777"
"23.60000","0.00787","239.66827"
"24.00000","0.00800","243.23115"
"24.40000","0.00813","246.81018"
"24.80000","0.00827","250.25245"
"25.20000","0.00841","254.03554"
"25.60000","0.00853","257.21522"
"26.00000","0.00868","261.01872"
"26.40000","0.00880","264.35743"
"26.80000","0.00894","267.74628"
"27.20000","0.00907","271.31160"
"27.60000","0.00920","274.52583"
"28.00000","0.00934","278.17248"
"28.40000","0.00947","281.28802"
"28.80000","0.00961","284.90826"
"29.20000","0.00974","288.33067"
"29.60000","0.00987","291.50132"
"30.00000","0.01001","295.15911"
"30.40000","0.01013","298.27550"
"30.80000","0.01028","301.91344"
"31.20000","0.01040","305.09170"
"31.60000","0.01053","308.38367"
"32.00000","0.01067","311.86333"
"32.40000","0.01080","314.94910"
"32.80000","0.01094","318.66226"
"33.20000","0.01107","321.71268"
"33.60000","0.01121","325.10126"
"34.00000","0.01134","328.35972"
"34.40000","0.01147","331.41923"
"34.80000","0.01161","334.89178"
"35.20000","0.01173","337.88896"
"35.60000","0.01187","341.34148"
"36.00000","0.01200","344.34898"
"36.40000","0.01213","347.63717"
"36.80000","0.01227","351.01927"
"37.20000","0.01240","353.88341"
"37.60000","0.01254","357.47843"
"38.00000","0.01267","360.42035"
"38.40000","0.01280","363.63763"
"38.80000","0.01294","366.81690"
"39.20000","0.01307","369.82341"
"39.60000","0.01321","373.12247"
"40.00000","0.01333","375.92424"
"40.40000","0.01348","379.39645"
"40.80000","0.01361","382.39680"
"41.20000","0.01373","385.31945"
"41.60000","0.01387","388.55228"
"42.00000","0.01400","391.31160"
"42.40000","0.01414","394.77671"
"42.80000","0.01427","397.52491"
"43.20000","0.01440","400.56129"
"43.60000","0.01453","403.55145"
"44.00000","0.01467","406.48944"
"44.40000","0.01481","409.73852"
"44.80000","0.01493","412.40025"
"45.20000","0.01508","415.59160"
"45.60000","0.01520","418.46735"
"46.00000","0.01533","421.36950"
"46.40000","0.01547","424.41949"
"46.80000","0.01560","427.10106"
"47.20000","0.01574","430.20489"
"47.60000","0.01587","432.90432"
"48.00000","0.01600","435.92218"
"48.40000","0.01614","438.85693"
"48.80000","0.01627","441.50774"
"49.20000","0.01641","444.57650"
"49.60000","0.01653","447.03946"
"50.00000","0.01668","450.13783"
"50.40000","0.01680","452.83735"
"50.80000","0.01693","455.53815"
"51.20000","0.01707","458.39788"
"51.60000","0.01720","460.95281"
"52.00000","0.01734","463.98965"
"52.40000","0.01747","466.53845"
"52.80000","0.01760","469.22557"
"53.20000","0.01774","471.96120"
"53.60000","0.01787","474.42070"
"54.00000","0.01801","477.26731"
"54.40000","0.01813","479.69916"
"54.80000","0.01827","482.44829"
"55.20000","0.01840","484.92602"
"55.60000","0.01853","487.53103"
"56.00000","0.01867","490.23538"
"56.40000","0.01880","492.53868"
"56.80000","0.01894","495.28002"
"57.20000","0.01907","497.61077"
"57.60000","0.01921","500.10578"
"58.00000","0.01934","502.55931"
"58.40000","0.01947","504.83670"
"58.80000","0.01961","507.41773"
"59.20000","0.01973","509.55511"
"59.60000","0.01988","512.25128"
"60.00000","0.02001","514.42440"
"60.40000","0.02013","516.61886"
"60.80000","0.02027","519.04934"
"61.20000","0.02040","521.08069"
"61.60000","0.02054","523.64255"
"62.00000","0.02067","525.62922"
"62.40000","0.02080","527.81354"
"62.80000","0.02094","529.98155"
"63.20000","0.02107","532.01888"
"63.60000","0.02121","534.37970"
"64.00000","0.02133","536.20951"
"64.40000","0.02147","538.32407"
"64.80000","0.02160","540.28511"
"65.20000","0.02173","542.16272"
"65.60000","0.02187","544.23321"
"66.00000","0.02200","545.92751"
"66.40000","0.02214","548.00046"
"66.80000","0.02227","549.65321"
"67.20000","0.02240","551.67528"
"67.60000","0.02254","553.45597"
"68.00000","0.02267","555.07436"
"68.40000","0.02281","557.09018"
"68.80000","0.02293","558.48717"
"69.20000","0.02307","560.44744"
"69.60000","0.02320","562.05030"
"70.00000","0.02333","563.60602"
"70.40000","0.02347","565.35295"
"70.80000","0.02360","566.79752"
"71.20000","0.02374","568.71032"
"71.60000","0.02387","569.99671"
"72.00000","0.02400","571.49299"
"72.40000","0.02414","573.07856"
"72.80000","0.02427","574.35316"
"73.20000","0.02441","576.02945"
"73.60000","0.02453","577.21557"
"74.00000","0.02467","578.80965"
"74.40000","0.02480","580.08013"
"74.80000","0.02493","581.48980"
"75.20000","0.02507","582.92937"
"75.60000","0.02520","584.01977"
"76.00000","0.02534","585.61309"
"76.40000","0.02547","586.66891"
"76.80000","0.02560","587.91963"
"77.20000","0.02574","589.20514"
"77.60000","0.02587","590.28835"
"78.00000","0.02601","591.66970"
"78.40000","0.02613","592.57920"
"78.80000","0.02628","593.99018"
"79.20000","0.02641","594.97817"
"79.60000","0.02653","595.99661"
"80.00000","0.02667","597.18586"
"80.40000","0.02680","598.03987"
"80.80000","0.02694","599.38258"
"81.20000","0.02707","600.19762"
"81.60000","0.02720","601.28182"
"82.00000","0.02734","602.27299"
"82.40000","0.02747","603.18506"
"82.80000","0.02761","604.34769"
"83.20000","0.02773","605.08941"
"83.60000","0.02788","606.21505"
"84.00000","0.02801","606.96829"
"84.40000","0.02813","607.81516"
"84.80000","0.02827","608.77861"
"85.20000","0.02840","609.45392"
"85.60000","0.02854","610.52807"
"86.00000","0.02867","611.12012"
"86.40000","0.02880","612.16019"
"86.80000","0.02894","612.92298"
"87.20000","0.02907","613.48561"
"87.60000","0.02921","614.53369"
"88.00000","0.02933","615.07963"
"88.40000","0.02947","615.99692"
"88.80000","0.02960","616.67601"
"89.20000","0.02973","617.35203"
"89.60000","0.02987","618.15956"
"90.00000","0.03000","618.68261"
"90.40000","0.03014","619.62515"
"90.80000","0.03027","620.07263"
"91.20000","0.03040","620.73871"
"91.60000","0.03054","621.33120"
"92.00000","0.03067","621.81572"
"92.40000","0.03081","622.57418"
"92.80000","0.03093","622.96616"
"93.20000","0.03107","623.66710"
"93.60000","0.03120","624.15761"
"94.00000","0.03133","624.76057"
"94.40000","0.03148","625.41360"
"94.80000","0.03160","625.74318"
"95.20000","0.03175","626.63671"
"95.60000","0.03187","626.96712"
"96.00000","0.03200","627.55433"
"96.40000","0.03214","628.14330"
"96.80000","0.03227","628.58919"
"97.20000","0.03241","629.31147"
"97.60000","0.03253","629.62196"
"98.00000","0.03268","630.41554"
"98.40000","0.03281","630.78453"
"98.80000","0.03293","631.24216"
"99.20000","0.03307","631.81884"
"99.60000","0.03320","632.07543"
"100.00000","0.03334","632.91764"
"100.40000","0.03347","633.21550"
"100.80000","0.03360","633.79223"
"101.20000","0.03374","634.26358"
"101.60000","0.03387","634.67363"
"102.00000","0.03401","635.36002"
"102.40000","0.03413","635.57478"
"102.80000","0.03428","636.29800"
"103.20000","0.03440","636.60904"
"103.60000","0.03453","637.04707"
"104.00000","0.03467","637.55663"
"104.40000","0.03480","637.81821"
"104.80000","0.03494","638.47315"
"105.20000","0.03507","638.73040"
"105.60000","0.03520","639.31004"
"106.00000","0.03534","639.75493"
"106.40000","0.03547","639.99077"
"106.80000","0.03561","640.64950"
"107.20000","0.03574","640.85686"
"107.60000","0.03588","641.52393"
"108.00000","0.03600","641.77536"
"108.40000","0.03614","642.15785"
"108.80000","0.03627","642.62833"
"109.20000","0.03640","642.87805"
"109.60000","0.03654","643.57092"
"110.00000","0.03667","643.74831"
"110.40000","0.03680","644.22916"
"110.80000","0.03694","644.56412"
"111.20000","0.03707","644.78218"
"111.60000","0.03721","645.36127"
"112.00000","0.03734","645.55041"
"112.40000","0.03747","646.03981"
"112.80000","0.03760","646.31369"
"113.20000","0.03774","646.71336"
"113.60000","0.03788","647.20821"
"114.00000","0.03800","647.27577"
"114.40000","0.03814","648.00272"
"114.80000","0.03827","648.15283"
"115.20000","0.03840","648.57720"
"115.60000","0.03854","648.89905"
"116.00000","0.03867","649.10679"
"116.40000","0.03881","649.64230"
"116.80000","0.03893","649.76519"
"117.20000","0.03907","650.26590"
"117.60000","0.03921","650.54494"
"118.00000","0.03934","650.79335"
"118.40000","0.03947","651.24258"
"118.80000","0.03960","651.33644"
"119.20000","0.03974","651.98090"
"119.60000","0.03987","652.09204"
"120.00000","0.04000","652.44067"
"120.40000","0.04014","652.80565"
"120.80000","0.04027","653.04720"
"121.20000","0.04041","653.55505"
"121.60000","0.04054","653.65637"
"122.00000","0.04068","654.12684"
"122.40000","0.04080","654.30050"
"122.80000","0.04094","654.56219"
"123.20000","0.04107","654.91944"
"123.60000","0.04120","655.01291"
"124.00000","0.04134","655.52076"
"124.40000","0.04147","655.60610"
"124.80000","0.04160","656.07224"
"125.20000","0.04174","656.39014"
"125.60000","0.04187","656.44738"
"126.00000","0.04201","657.00391"
"126.40000","0.04213","657.04041"
"126.80000","0.04227","657.54003"
"127.20000","0.04240","657.71325"
"127.60000","0.04254","657.97703"
"128.00000","0.04267","658.31901"
"128.40000","0.04280","658.44443"
"128.80000","0.04294","658.97500"
"129.20000","0.04307","659.02873"
"129.60000","0.04320","659.37736"
"130.00000","0.04334","659.61743"
"130.40000","0.04347","659.74125"
"130.80000","0.04361","660.19674"
"131.20000","0.04374","660.28198"
"131.60000","0.04387","660.63220"
"132.00000","0.04400","660.80492"
"132.40000","0.04413","661.07715"
"132.80000","0.04427","661.45240"
"133.20000","0.04440","661.51156"
"133.60000","0.04454","661.99186"
"134.00000","0.04467","662.04433"
"134.40000","0.04480","662.36563"
"134.80000","0.04494","662.62858"
"135.20000","0.04507","662.77063"
"135.60000","0.04521","663.21563"
"136.00000","0.04533","663.20405"
"136.40000","0.04547","663.61141"
"136.80000","0.04561","663.80235"
"137.20000","0.04574","663.94961"
"137.60000","0.04588","664.34390"
"138.00000","0.04600","664.25998"
"138.40000","0.04614","664.80197"
"138.80000","0.04627","664.86893"
"139.20000","0.04640","665.14874"
"139.60000","0.04654","665.39753"
"140.00000","0.04667","665.52250"
"140.40000","0.04681","665.97415"
"140.80000","0.04694","666.03272"
"141.20000","0.04707","666.29501"
"141.60000","0.04720","666.49282"
"142.00000","0.04734","666.62915"
"142.40000","0.04747","666.97805"
"142.80000","0.04760","666.98327"
"143.20000","0.04774","667.45550"
"143.60000","0.04787","667.47229"
"144.00000","0.04800","667.83327"
"144.40000","0.04814","668.03174"
"144.80000","0.04827","668.09260"
"145.20000","0.04841","668.55677"
"145.60000","0.04854","668.49744"
"146.00000","0.04867","668.90051"
"146.40000","0.04881","669.04552"
"146.80000","0.04894","669.18498"
"147.20000","0.04907","669.51791"
"147.60000","0.04920","669.55721"
"148.00000","0.04935","670.07620"
"148.40000","0.04947","670.03559"
"148.80000","0.04960","670.22132"
"149.20000","0.04974","670.46781"
"149.60000","0.04987","670.50458"
"150.00000","0.05001","670.94492"
"150.40000","0.05013","670.90776"
"150.80000","0.05027","671.24931"
"151.20000","0.05040","671.36973"
"151.60000","0.05053","671.58373"
"152.00000","0.05067","671.90250"
"152.40000","0.05080","671.89158"
"152.80000","0.05094","672.33785"
"153.20000","0.05107","672.36117"
"153.60000","0.05120","672.59844"
"154.00000","0.05134","672.79444"
"154.40000","0.05147","672.86260"
"154.80000","0.05161","673.25091"
"155.20000","0.05173","673.19883"
"155.60000","0.05187","673.62699"
"156.00000","0.05201","673.68297"
"156.40000","0.05214","673.78281"
"156.80000","0.05228","674.13473"
"157.20000","0.05240","674.09417"
"157.60000","0.05254","674.51365"
"158.00000","0.05267","674.53566"
"158.40000","0.05280","674.75021"
"158.80000","0.05294","674.98973"
"159.20000","0.05307","675.07238"
"159.60000","0.05321","675.45762"
"160.00000","0.05334","675.42925"
"160.40000","0.05347","675.72958"
"160.80000","0.05360","675.82727"
"161.20000","0.05374","675.91728"
"161.60000","0.05387","676.22497"
"162.00000","0.05400","676.20982"
"162.40000","0.05414","676.57448"
"162.80000","0.05427","676.55894"
"163.20000","0.05440","676.89264"
"163.60000","0.05454","677.09138"
"164.00000","0.05467","677.08194"
"164.40000","0.05481","677.52915"
"164.80000","0.05494","677.48441"
"165.20000","0.05507","677.77508"
"165.60000","0.05520","677.86180"
"166.00000","0.05534","678.00621"
"166.40000","0.05547","678.28661"
"166.80000","0.05560","678.24347"
"167.20000","0.05574","678.72119"
"167.60000","0.05587","678.66834"
"168.00000","0.05600","678.86598"
"168.40000","0.05614","679.02547"
"168.80000","0.05627","679.05868"
"169.20000","0.05641","679.48964"
"169.60000","0.05653","679.38947"
"170.00000","0.05667","679.70791"
"170.40000","0.05680","679.78075"
"170.80000","0.05694","679.95605"
"171.20000","0.05707","680.21439"
"171.60000","0.05720","680.26736"
"172.00000","0.05734","680.61434"
"172.40000","0.05747","680.56785"
"172.80000","0.05760","680.77537"
"173.20000","0.05774","680.96796"
"173.60000","0.05787","681.00973"
"174.00000","0.05801","681.35924"
"174.40000","0.05813","681.27905"
"174.80000","0.05828","681.71583"
"175.20000","0.05841","681.74146"
"175.60000","0.05854","681.75381"
"176.00000","0.05867","682.09322"
"176.40000","0.05880","682.03855"
"176.80000","0.05894","682.46237"
"177.20000","0.05907","682.42741"
"177.60000","0.05920","682.58570"
"178.00000","0.05934","682.81380"
"178.40000","0.05947","682.85722"
"178.80000","0.05961","683.27258"
"179.20000","0.05974","683.19317"
"179.60000","0.05988","683.48719"
"180.00000","0.06001","683.52950"
"180.40000","0.06014","683.65211"
"180.80000","0.06027","683.88099"
"181.20000","0.06040","683.83927"
"181.60000","0.06054","684.16990"
"182.00000","0.06067","684.13505"
"182.40000","0.06080","684.40360"
"182.80000","0.06094","684.56941"
"183.20000","0.06106","684.46233"
"183.60000","0.06121","684.93648"
"184.00000","0.06134","684.89208"
"184.40000","0.06147","685.17660"
"184.80000","0.06160","685.25009"
"185.20000","0.06174","685.40613"
"185.60000","0.06187","685.66541"
"186.00000","0.06200","685.59389"
"186.40000","0.06214","686.00772"
"186.80000","0.06227","685.98379"
"187.20000","0.06240","686.13094"
"187.60000","0.06254","686.31003"
"188.00000","0.06267","686.24088"
"188.40000","0.06281","686.65981"
"188.80000","0.06294","686.58067"
"189.20000","0.06307","686.83758"
"189.60000","0.06320","686.88385"
"190.00000","0.06333","686.98193"
"190.40000","0.06347","687.26744"
"190.80000","0.06360","687.16415"
"191.20000","0.06374","687.62249"
"191.60000","0.06387","687.57206"
"192.00000","0.06400","687.72908"
"192.40000","0.06414","687.91135"
"192.80000","0.06427","687.94423"
"193.20000","0.06441","688.24259"
"193.60000","0.06453","688.17211"
"194.00000","0.06467","688.53809"
"194.40000","0.06481","688.59742"
"194.80000","0.06494","688.58726"
"195.20000","0.06507","688.87832"
"195.60000","0.06520","688.75263"
"196.00000","0.06534","689.21372"
"196.40000","0.06547","689.17217"
"196.80000","0.06560","689.32684"
"197.20000","0.06574","689.48013"
"197.60000","0.06587","689.53068"
"198.00000","0.06601","689.95269"
"198.40000","0.06614","689.85434"
"198.80000","0.06627","690.05159"
"199.20000","0.06641","690.11169"
"199.60000","0.06654","690.14814"
"200.00000","0.06667","690.41191"
"200.40000","0.06680","690.30758"
"200.80000","0.06694","690.63222"
"201.20000","0.06707","690.61170"
"201.60000","0.06720","690.84852"
"202.00000","0.06734","691.04660"
"202.40000","0.06747","690.93766"
"202.80000","0.06761","691.38612"
"203.20000","0.06774","691.30336"
"203.60000","0.06787","691.56944"
"204.00000","0.06800","691.65171"
"204.40000","0.06814","691.71198"
"204.80000","0.06827","691.97910"
"205.20000","0.06840","691.89568"
"205.60000","0.06854","692.30786"
"206.00000","0.06867","692.25632"
"206.40000","0.06880","692.35534"
"206.80000","0.06894","692.53525"
"207.20000","0.06907","692.45215"
"207.60000","0.06921","692.81665"
"208.00000","0.06933","692.72625"
"208.40000","0.06947","692.93553"
"208.80000","0.06960","693.07268"
"209.20000","0.06974","693.17351"
"209.60000","0.06988","693.46917"
"210.00000","0.07000","693.28948"
"210.40000","0.07014","693.72680"
"210.80000","0.07027","693.67307"
"211.20000","0.07040","693.81846"
"211.60000","0.07054","693.97060"
"212.00000","0.07067","693.92033"
"212.40000","0.07080","694.21967"
"212.80000","0.07093","694.13004"
"213.20000","0.07107","694.46303"
"213.60000","0.07121","694.53971"
"214.00000","0.07133","694.44508"
"214.40000","0.07147","694.80579"
"214.80000","0.07160","694.63241"
"215.20000","0.07174","695.07780"
"215.60000","0.07187","695.04536"
"216.00000","0.07200","695.13971"
"216.40000","0.07214","695.34542"
"216.80000","0.07227","695.35145"
"217.20000","0.07241","695.74070"
"217.60000","0.07254","695.64833"
"218.00000","0.07267","695.73697"
"218.40000","0.07281","695.90294"
"218.80000","0.07294","695.87484"
"219.20000","0.07307","696.13658"
"219.60000","0.07320","696.01337"
"220.00000","0.07334","696.29811"
"220.40000","0.07347","696.32791"
"220.80000","0.07360","696.55481"
"221.20000","0.07374","696.72330"
"221.60000","0.07387","696.67094"
"222.00000","0.07401","697.01414"
"222.40000","0.07414","696.89279"
"222.80000","0.07427","697.06628"
"223.20000","0.07440","697.17874"
"223.60000","0.07454","697.21738"
"224.00000","0.07467","697.49175"
"224.40000","0.07480","697.39581"
"224.80000","0.07494","697.84175"
"225.20000","0.07507","697.74148"
"225.60000","0.07520","697.73791"
"226.00000","0.07534","697.98286"
"226.40000","0.07547","697.86442"
"226.80000","0.07561","698.27101"
"227.20000","0.07574","698.13275"
"227.60000","0.07587","698.30855"
"228.00000","0.07600","698.43270"
"228.40000","0.07613","698.49845"
"228.80000","0.07628","698.80910"
"229.20000","0.07640","698.71695"
"229.60000","0.07654","698.90696"
"230.00000","0.07667","698.97101"
"230.40000","0.07680","699.08462"
"230.80000","0.07694","699.22848"
"231.20000","0.07707","699.16920"
"231.60000","0.07721","699.53012"
"232.00000","0.07733","699.35773"
"232.40000","0.07747","699.63874"
"232.80000","0.07761","699.72524"
"233.20000","0.07774","699.70855"
"233.60000","0.07787","700.00609"
"234.00000","0.07800","699.87206"
"234.40000","0.07814","700.20707"
"234.80000","0.07827","700.15916"
"235.20000","0.07840","700.22650"
"235.60000","0.07854","700.41295"
"236.00000","0.07867","700.37821"
"236.40000","0.07881","700.75554"
"236.80000","0.07894","700.62305"
"237.20000","0.07907","700.76525"
"237.60000","0.07921","700.90532"
"238.00000","0.07934","700.88276"
"238.40000","0.07947","701.17195"
"238.80000","0.07960","701.04473"
"239.20000","0.07974","701.28672"
"239.60000","0.07987","701.31054"
"240.00000","0.08000","701.43085"
"240.40000","0.08014","701.61691"
"240.80000","0.08027","701.52733"
"241.20000","0.08041","701.86488"
"241.60000","0.08054","701.74215"
"242.00000","0.08067","701.90648"
"242.40000","0.08080","702.00813"
"242.80000","0.08094","702.04418"
"243.20000","0.08107","702.28140"
"243.60000","0.08120","702.16372"
"244.00000","0.08134","702.55956"
"244.40000","0.08147","702.52448"
"244.80000","0.08160","702.50571"
"245.20000","0.08174","702.71246"
"245.60000","0.08187","702.59792"
"246.00000","0.08201","702.97388"
"246.40000","0.08214","702.85138"
"246.80000","0.08227","702.98810"
"247.20000","0.08240","703.07547"
"247.60000","0.08253","703.09628"
"248.00000","0.08268","703.41818"
"248.40000","0.08280","703.32729"
"248.80000","0.08295","703.66900"
"249.20000","0.08307","703.54266"
"249.60000","0.08320","703.61280"
"250.00000","0.08334","703.78848"
"250.40000","0.08347","703.72004"
"250.80000","0.08361","704.01313"
"251.20000","0.08373","703.88563"
"251.60000","0.08387","704.21187"
"252.00000","0.08401","704.25995"
"252.40000","0.08413","704.06994"
"252.80000","0.08427","704.40506"
"253.20000","0.08440","704.28805"
"253.60000","0.08454","704.65183"
"254.00000","0.08467","704.57361"
"254.40000","0.08480","704.66379"
"254.80000","0.08494","704.85600"
"255.20000","0.08506","704.75781"
"255.60000","0.08521","705.15852"
"256.00000","0.08534","705.01226"
"256.40000","0.08547","705.13712"
"256.80000","0.08560","705.17916"
"257.20000","0.08574","705.17032"
"257.60000","0.08587","705.44195"
"258.00000","0.08600","705.30710"
"258.40000","0.08614","705.55452"
"258.80000","0.08627","705.55079"
"259.20000","0.08640","705.67867"
"259.60000","0.08654","705.89700"
"260.00000","0.08666","705.71352"
"260.40000","0.08681","706.09563"
"260.80000","0.08694","706.00150"
"261.20000","0.08707","706.19580"
"261.60000","0.08720","706.18795"
"262.00000","0.08734","706.19558"
"262.40000","0.08747","706.42549"
"262.80000","0.08760","706.27154"
"263.20000","0.08774","706.61095"
"263.60000","0.08787","706.59640"
"264.00000","0.08800","706.60628"
"264.40000","0.08814","706.79871"
"264.80000","0.08827","706.67648"
"265.20000","0.08841","707.03669"
"265.60000","0.08854","706.88378"
"266.00000","0.08867","707.00469"
"266.40000","0.08880","707.14201"
"266.80000","0.08894","707.15914"
"267.20000","0.08908","707.48450"
"267.60000","0.08920","707.27648"
"268.00000","0.08934","707.59926"
"268.40000","0.08947","707.51726"
"268.80000","0.08960","707.58038"
"269.20000","0.08974","707.71776"
"269.60000","0.08987","707.64180"
"270.00000","0.09001","707.94257"
"270.40000","0.09013","707.73773"
"270.80000","0.09027","708.00695"
"271.20000","0.09041","708.08944"
"271.60000","0.09053","707.96710"
"272.00000","0.09067","708.27896"
"272.40000","0.09080","708.16908"
"272.80000","0.09094","708.45031"
"273.20000","0.09107","708.41990"
"273.60000","0.09120","708.50426"
"274.00000","0.09134","708.66924"
"274.40000","0.09147","708.56792"
"274.80000","0.09161","708.93977"
"275.20000","0.09174","708.78412"
"275.60000","0.09187","708.90799"
"276.00000","0.09201","708.95947"
"276.40000","0.09213","708.86710"
"276.80000","0.09227","709.15849"
"277.20000","0.09240","709.01205"
"277.60000","0.09254","709.29224"
"278.00000","0.09267","709.18763"
"278.40000","0.09280","709.34943"
"278.80000","0.09294","709.56173"
"279.20000","0.09307","709.37671"
"279.60000","0.09321","709.71162"
"280.00000","0.09334","709.59504"
"280.40000","0.09347","709.72232"
"280.80000","0.09360","709.80564"
"281.20000","0.09374","709.77457"
"281.60000","0.09387","710.00959"
"282.00000","0.09400","709.83500"
"282.40000","0.09414","710.18193"
"282.80000","0.09427","710.12946"
"283.20000","0.09440","710.07419"
"283.60000","0.09454","710.28412"
"284.00000","0.09466","710.11672"
"284.40000","0.09481","710.52809"
"284.80000","0.09494","710.39400"
"285.20000","0.09507","710.49099"
"285.60000","0.09520","710.58127"
"286.00000","0.09533","710.54516"
"286.40000","0.09548","710.86223"
"286.80000","0.09560","710.69955"
"287.20000","0.09574","710.95635"
"287.60000","0.09587","710.89834"
"288.00000","0.09600","710.92392"
"288.40000","0.09614","711.06580"
"288.80000","0.09627","710.98720"
"289.20000","0.09641","711.26157"
"289.60000","0.09653","711.13270"
"290.00000","0.09667","711.35817"
"290.40000","0.09681","711.42326"
"290.80000","0.09693","711.28951"
"291.20000","0.09707","711.59966"
"291.60000","0.09720","711.38424"
"292.00000","0.09734","711.74214"
"292.40000","0.09747","711.66415"
"292.80000","0.09760","711.67491"
"293.20000","0.09774","711.85318"
"293.60000","0.09787","711.74944"
"294.00000","0.09801","712.08732"
"294.40000","0.09814","711.94944"
"294.80000","0.09827","712.03803"
"295.20000","0.09840","712.11882"
"295.60000","0.09853","712.03600"
"296.00000","0.09867","712.29396"
"296.40000","0.09880","712.14182"
"296.80000","0.09894","712.35444"
"297.20000","0.09907","712.33984"
"297.60000","0.09920","712.45433"
"298.00000","0.09934","712.63732"
"298.40000","0.09947","712.47947"
"298.80000","0.09961","712.73726"
"299.20000","0.09974","712.67683"
"299.60000","0.09987","712.79171"
"300.00000","0.10000","712.83606"
"300.40000","0.10014","712.78156"
"300.80000","0.10027","712.96333"
"301.20000","0.10040","712.80856"
"301.60000","0.10054","713.16948"
"302.00000","0.10067","713.08759"
"302.40000","0.10080","713.02497"
"302.80000","0.10094","713.26416"
"303.20000","0.10107","713.10214"
"303.60000","0.10121","713.47634"
"304.00000","0.10134","713.33249"
"304.40000","0.10147","713.39983"
"304.80000","0.10160","713.48902"
"305.20000","0.10173","713.47151"
"305.60000","0.10188","713.76372"
"306.00000","0.10200","713.61422"
"306.40000","0.10214","713.70214"
"306.80000","0.10227","713.72920"
"307.20000","0.10240","713.70170"
"307.60000","0.10254","713.89808"
"308.00000","0.10267","713.75039"
"308.40000","0.10280","713.97931"
"308.80000","0.10293","713.86866"
"309.20000","0.10307","714.10291"
"309.60000","0.10321","714.17382"
"310.00000","0.10334","714.10242"
"310.40000","0.10348","714.35961"
"310.80000","0.10360","714.13760"
"311.20000","0.10374","714.42267"
"311.60000","0.10387","714.38348"
"312.00000","0.10400","714.35099"
"312.40000","0.10414","714.49342"
"312.80000","0.10427","714.38991"
"313.20000","0.10441","714.77103"
"313.60000","0.10454","714.59128"
"314.00000","0.10467","714.60868"
"314.40000","0.10481","714.75813"
"314.80000","0.10493","714.60544"
"315.20000","0.10507","714.92048"
"315.60000","0.10520","714.70610"
"316.00000","0.10534","714.95341"
"316.40000","0.10547","714.92569"
"316.80000","0.10560","714.95319"
"317.20000","0.10574","715.16203"
"317.60000","0.10587","714.99468"
"318.00000","0.10601","715.28854"
"318.40000","0.10614","715.18793"
"318.80000","0.10627","715.21406"
"319.20000","0.10640","715.34902"
"319.60000","0.10654","715.29167"
"320.00000","0.10667","715.53420"
"320.40000","0.10680","715.33294"
"320.80000","0.10694","715.61406"
"321.20000","0.10707","715.58640"
"321.60000","0.10720","715.48925"
"322.00000","0.10734","715.70028"
"322.40000","0.10747","715.54990"
"322.80000","0.10761","715.85391"
"323.20000","0.10774","715.72054"
"323.60000","0.10787","715.79644"
"324.00000","0.10801","715.86258"
"324.40000","0.10813","715.80874"
"324.80000","0.10828","716.10402"
"325.20000","0.10840","715.93135"
"325.60000","0.10854","716.10984"
"326.00000","0.10867","716.08097"
"326.40000","0.10880","716.01604"
"326.80000","0.10894","716.22251"
"327.20000","0.10907","716.06604"
"327.60000","0.10921","716.32098"
"328.00000","0.10933","716.19727"
"328.40000","0.10947","716.40479"
"328.80000","0.10961","716.45682"
"329.20000","0.10973","716.25616"
"329.60000","0.10987","716.59304"
"330.00000","0.11000","716.43179"
"330.40000","0.11014","716.59277"
"330.80000","0.11027","716.61423"
"331.20000","0.11040","716.56549"
"331.60000","0.11054","716.76242"
"332.00000","0.11066","716.59458"
"332.40000","0.11081","716.99656"
"332.80000","0.11094","716.80880"
"333.20000","0.11107","716.82049"
"333.60000","0.11121","716.92587"
"334.00000","0.11133","716.78360"
"334.40000","0.11147","717.05419"
"334.80000","0.11160","716.88778"
"335.20000","0.11174","717.01500"
"335.60000","0.11187","717.06154"
"336.00000","0.11200","717.06489"
"336.40000","0.11214","717.27998"
"336.80000","0.11227","717.08964"
"337.20000","0.11241","717.45002"
"337.60000","0.11254","717.25770"
"338.00000","0.11267","717.26670"
"338.40000","0.11281","717.37960"
"338.80000","0.11293","717.28591"
"339.20000","0.11307","717.47894"
"339.60000","0.11320","717.30787"
"340.00000","0.11334","717.59678"
"340.40000","0.11347","717.57592"
"340.80000","0.11360","717.47499"
"341.20000","0.11374","717.69162"
"341.60000","0.11386","717.47702"
"342.00000","0.11401","717.85205"
"342.40000","0.11414","717.70232"
"342.80000","0.11427","717.80178"
"343.20000","0.11441","717.87774"
"343.60000","0.11453","717.81703"
"344.00000","0.11468","718.10699"
"344.40000","0.11481","717.90090"
"344.80000","0.11494","718.04997"
"345.20000","0.11507","718.00233"
"345.60000","0.11520","717.93235"
"346.00000","0.11534","718.06972"
"346.40000","0.11547","717.90084"
"346.80000","0.11561","718.11155"
"347.20000","0.11573","718.03010"
"347.60000","0.11587","718.19107"
"348.00000","0.11601","718.30150"
"348.40000","0.11613","718.10430"
"348.80000","0.11627","718.45326"
"349.20000","0.11640","718.27027"
"349.60000","0.11654","718.48378"
"350.00000","0.11667","718.43504"
"350.40000","0.11680","718.36918"
"350.80000","0.11694","718.54657"
"351.20000","0.11706","718.35974"
"351.60000","0.11721","718.74322"
"352.00000","0.11734","718.58427"
"352.40000","0.11747","718.63208"
"352.80000","0.11761","718.67077"
"353.20000","0.11773","718.48131"
"353.60000","0.11787","718.80194"
"354.00000","0.11800","718.59338"
"354.40000","0.11814","718.74926"
"354.80000","0.11827","718.79388"
"355.20000","0.11840","718.79371"
"355.60000","0.11854","719.00035"
"356.00000","0.11866","718.77412"
"356.40000","0.11881","719.12061"
"356.80000","0.11894","718.94047"
"357.20000","0.11907","719.00255"
"357.60000","0.11921","719.05743"
"358.00000","0.11933","718.95068"
"358.40000","0.11947","719.14421"
"358.80000","0.11960","718.95474"
"359.20000","0.11974","719.15634"
"359.60000","0.11987","719.18378"
"360.00000","0.12000","719.03855"
"360.40000","0.12014","719.26589"
"360.80000","0.12027","719.08817"
"361.20000","0.12041","719.41106"
"361.60000","0.12054","719.26303"
"362.00000","0.12067","719.27725"
"362.40000","0.12081","719.39520"
"362.80000","0.12093","719.31677"
"363.20000","0.12108","719.60535"
"363.60000","0.12121","719.43921"
"364.00000","0.12134","719.54311"
"364.40000","0.12147","719.51973"
"364.80000","0.12160","719.44876"
"365.20000","0.12174","719.61715"
"365.60000","0.12187","719.42769"
"366.00000","0.12201","719.65008"
"366.40000","0.12213","719.54882"
"366.80000","0.12227","719.64767"
"367.20000","0.12241","719.72456"
"367.60000","0.12253","719.47154"
"368.00000","0.12267","719.79959"
"368.40000","0.12280","719.60864"
"368.80000","0.12294","719.79997"
"369.20000","0.12307","719.75815"
"369.60000","0.12320","719.75294"
"370.00000","0.12334","719.91040"
"370.40000","0.12347","719.74630"
"370.80000","0.12361","720.01101"
"371.20000","0.12374","719.95206"
"371.60000","0.12387","719.98993"
"372.00000","0.12401","720.04564"
"372.40000","0.12413","719.89701"
"372.80000","0.12427","720.14471"
"373.20000","0.12440","719.99267"
"373.60000","0.12454","720.07292"
"374.00000","0.12467","720.08011"
"374.40000","0.12480","720.05508"
"374.80000","0.12494","720.28285"
"375.20000","0.12507","720.10168"
"375.60000","0.12521","720.33521"
"376.00000","0.12534","720.16512"
"376.40000","0.12547","720.20409"
"376.80000","0.12561","720.27819"
"377.20000","0.12573","720.15579"
"377.60000","0.12587","720.44180"
"378.00000","0.12600","720.17193"
"378.40000","0.12614","720.36029"
"378.80000","0.12627","720.40772"
"379.20000","0.12640","720.31611"
"379.60000","0.12654","720.54070"
"380.00000","0.12666","720.27385"
"380.40000","0.12681","720.57627"
"380.80000","0.12694","720.43642"
"381.20000","0.12707","720.45574"
"381.60000","0.12721","720.55914"
"382.00000","0.12733","720.39394"
"382.40000","0.12747","720.70404"
"382.80000","0.12760","720.52605"
"383.20000","0.12774","720.55563"
"383.60000","0.12787","720.59224"
"384.00000","0.12800","720.49235"
"384.40000","0.12814","720.69822"
"384.80000","0.12827","720.49734"
"385.20000","0.12841","720.71134"
"385.60000","0.12853","720.58949"
"386.00000","0.12867","720.71271"
"386.40000","0.12881","720.81996"
"386.80000","0.12894","720.65239"
"387.20000","0.12908","720.95744"
"387.60000","0.12920","720.74460"
"388.00000","0.12934","720.86189"
"388.40000","0.12947","720.86590"
"388.80000","0.12960","720.77605"
"389.20000","0.12974","720.94290"
"389.60000","0.12987","720.75201"
"390.00000","0.13001","721.11222"
"390.40000","0.13014","720.89927"
"390.80000","0.13027","720.83412"
"391.20000","0.13041","720.97715"
"391.60000","0.13053","720.77775"
"392.00000","0.13067","721.09219"
"392.40000","0.13080","720.90640"
"392.80000","0.13094","720.99015"
"393.20000","0.13107","721.03434"
"393.60000","0.13120","721.00003"
"394.00000","0.13134","721.19603"
"394.40000","0.13147","720.98538"
"394.80000","0.13161","721.18615"
"395.20000","0.13174","721.07567"
"395.60000","0.13187","721.07045"
"396.00000","0.13201","721.12654"
"396.40000","0.13213","720.99795"
"396.80000","0.13227","721.24043"
"397.20000","0.13240","720.99290"
"397.60000","0.13254","721.24049"
"398.00000","0.13267","721.17781"
"398.40000","0.13280","721.07868"
"398.80000","0.13294","721.31617"
"399.20000","0.13307","721.09949"
"399.60000","0.13321","721.26946"
"400.00000","0.13334","721.19526"
"400.40000","0.13347","721.21666"
"400.80000","0.13361","721.32386"
"401.20000","0.13373","721.18807"
"401.60000","0.13387","721.44581"
"402.00000","0.13401","721.25371"
"402.40000","0.13414","721.31134"
"402.80000","0.13427","721.29899"
"403.20000","0.13440","721.17084"
"403.60000","0.13454","721.36705"
"404.00000","0.13466","721.15915"
"404.40000","0.13481","721.38824"
"404.80000","0.13493","721.21277"
"405.20000","0.13507","721.31831"
"405.60000","0.13521","721.41957"
"406.00000","0.13533","721.20695"
"406.40000","0.13548","721.54724"
"406.80000","0.13560","721.31881"
"407.20000","0.13574","721.39455"
"407.60000","0.13587","721.37627"
"408.00000","0.13600","721.33275"
"408.40000","0.13614","721.48385"
"408.80000","0.13626","721.23955"
"409.20000","0.13641","721.55810"
"409.60000","0.13654","721.41716"
"410.00000","0.13667","721.37874"
"410.40000","0.13681","721.46260"
"410.80000","0.13693","721.29038"
"411.20000","0.13707","721.57375"
"411.60000","0.13720","721.33341"
"412.00000","0.13734","721.42605"
"412.40000","0.13747","721.43873"
"412.80000","0.13760","721.35382"
"413.20000","0.13774","721.60273"
"413.60000","0.13787","721.39208"
"414.00000","0.13801","721.63922"
"414.40000","0.13814","721.45997"
"414.80000","0.13827","721.45190"
"415.20000","0.13841","721.52270"
"415.60000","0.13853","721.37325"
"416.00000","0.13867","721.58889"
"416.40000","0.13880","721.35547"
"416.80000","0.13894","721.62314"
"417.20000","0.13907","721.58160"
"417.60000","0.13920","721.33330"
"418.00000","0.13934","721.60651"
"418.40000","0.13947","721.39927"
"418.80000","0.13961","721.61387"
"419.20000","0.13974","721.47907"
"419.60000","0.13987","721.44565"
"420.00000","0.14001","721.54312"
"420.40000","0.14013","721.39581"
"420.80000","0.14028","721.70328"
"421.20000","0.14041","721.48549"
"421.60000","0.14054","721.58610"
"422.00000","0.14067","721.52479"
"422.40000","0.14080","721.42880"
"422.80000","0.14094","721.54164"
"423.20000","0.14106","721.31892"
"423.60000","0.14121","721.50788"
"424.00000","0.14133","721.38330"
"424.40000","0.14147","721.47891"
"424.80000","0.14161","721.56359"
"425.20000","0.14173","721.26568"
"425.60000","0.14187","721.62649"
"426.00000","0.14200","721.40893"
"426.40000","0.14214","721.49960"
"426.80000","0.14227","721.44652"
"427.20000","0.14240","721.36002"
"427.60000","0.14254","721.50212"
"428.00000","0.14266","721.27336"
"428.40000","0.14281","721.50552"
"428.80000","0.14294","721.43824"
"429.20000","0.14307","721.40695"
"429.60000","0.14321","721.45075"
"430.00000","0.14333","721.20673"
"430.40000","0.14347","721.50849"
"430.80000","0.14360","721.26798"
"431.20000","0.14374","721.35750"
"431.60000","0.14387","721.30937"
"432.00000","0.14400","721.22621"
"432.40000","0.14414","721.41474"
"432.80000","0.14427","721.19526"
"433.20000","0.14441","721.43445"
"433.60000","0.14454","721.23050"
"434.00000","0.14467","721.17621"
"434.40000","0.14481","721.24246"
"434.80000","0.14493","721.06974"
"435.20000","0.14507","721.19191"
"435.60000","0.14520","721.01299"
"436.00000","0.14534","721.17962"
"436.40000","0.14547","721.15437"
"436.80000","0.14560","720.91386"
"437.20000","0.14574","721.16623"
"437.60000","0.14586","720.88609"
"438.00000","0.14601","721.10355"
"438.40000","0.14614","720.93747"
"438.80000","0.14627","720.88126"
"439.20000","0.14641","720.91749"
"439.60000","0.14653","720.78895"
"440.00000","0.14668","720.98862"
"440.40000","0.14681","720.75810"
"440.80000","0.14694","720.77742"
"441.20000","0.14707","720.70832"
"441.60000","0.14720","720.51178"
"442.00000","0.14734","720.67232"
"442.40000","0.14746","720.42281"
"442.80000","0.14760","720.50519"
"443.20000","0.14773","720.39537"
"443.60000","0.14787","720.40503"
"444.00000","0.14801","720.49624"
"444.40000","0.14813","720.18603"
"444.80000","0.14828","720.49180"
"445.20000","0.14840","720.20041"
"445.60000","0.14854","720.22802"
"446.00000","0.14867","720.13741"
"446.40000","0.14880","719.96545"
"446.80000","0.14894","720.08949"
"447.20000","0.14906","719.78691"
"447.60000","0.14921","720.01029"
"448.00000","0.14934","719.77154"
"448.40000","0.14947","719.63411"
"448.80000","0.14961","719.62215"
"449.20000","0.14973","719.31155"
"449.60000","0.14987","719.50700"
"450.00000","0.15000","719.21194"
"450.40000","0.15014","719.15178"
"450.80000","0.15027","719.09080"
"451.20000","0.15040","718.92939"
"451.60000","0.15054","719.04146"
"452.00000","0.15066","718.64519"
"452.40000","0.15081","718.77955"
"452.80000","0.15094","718.49711"
"453.20000","0.15107","718.34294"
"453.60000","0.15121","718.26061"
"454.00000","0.15133","717.92055"
"454.40000","0.15147","717.95694"
"454.80000","0.15160","717.57510"
"455.20000","0.15174","717.54579"
"455.60000","0.15187","717.42477"
"456.00000","0.15200","716.93849"
"456.40000","0.15214","717.04513"
"456.80000","0.15226","716.54568"
"457.20000","0.15241","716.57548"
"457.60000","0.15254","716.25084"
"458.00000","0.15267","715.96478"
"458.40000","0.15281","715.83997"
"458.80000","0.15293","715.42778"
"459.20000","0.15308","715.44222"
"459.60000","0.15321","714.95720"
"460.00000","0.15334","714.60313"
"460.40000","0.15347","714.36405"
"460.80000","0.15360","713.82250"
"461.20000","0.15374","713.75768"
"461.60000","0.15387","713.20302"
"462.00000","0.15400","712.93622"
"462.40000","0.15413","712.50257"
"462.80000","0.15427","712.16948"
"463.20000","0.15441","711.91520"
"463.60000","0.15453","711.25938"
"464.00000","0.15468","711.09401"
"464.40000","0.15480","710.44636"
"464.80000","0.15494","710.05207"
"465.20000","0.15507","709.64197"
"465.60000","0.15520","709.05179"
"466.00000","0.15534","708.79811"
"466.40000","0.15546","708.08499"
"466.80000","0.15561","707.90475"
"467.20000","0.15574","707.24207"
"467.60000","0.15587","706.56363"
"468.00000","0.15601","706.19942"
"468.40000","0.15613","705.42422"
"468.80000","0.15627","705.18553"
"469.20000","0.15640","704.39271"
"469.60000","0.15654","703.80265"
"470.00000","0.15667","703.28085"
"470.40000","0.15680","702.59441"
"470.80000","0.15694","702.26383"
"471.20000","0.15707","701.40033"
"471.60000","0.15721","700.86943"
"472.00000","0.15734","700.17864"
"472.40000","0.15747","699.53803"
"472.80000","0.15761","699.02134"
"473.20000","0.15773","698.18720"
"473.60000","0.15787","697.79159"
"474.00000","0.15800","696.88933"
"474.40000","0.15814","696.34646"
"474.80000","0.15827","695.65447"
"475.20000","0.15840","694.79865"
"475.60000","0.15854","694.38433"
"476.00000","0.15867","693.42510"
"476.40000","0.15881","692.91099"
"476.80000","0.15894","692.04639"
"477.20000","0.15907","691.26807"
"477.60000","0.15921","690.70967"
"478.00000","0.15933","689.79424"
"478.40000","0.15948","689.39490"
"478.80000","0.15961","688.40126"
"479.20000","0.15974","687.64066"
"479.60000","0.15987","686.94922"
"480.00000","0.16000","686.02375"
"480.40000","0.16014","685.52819"
"480.80000","0.16026","684.49921"
"481.20000","0.16040","683.89240"
"481.60000","0.16053","683.05952"
"482.00000","0.16067","682.27110"
"482.40000","0.16081","681.61632"
"482.80000","0.16093","680.59431"
"483.20000","0.16107","680.08657"
"483.60000","0.16120","679.03607"
"484.00000","0.16134","678.29786"
"484.40000","0.16147","677.51965"
"484.80000","0.16160","676.58430"
"485.20000","0.16174","675.95471"
"485.60000","0.16186","674.89258"
"486.00000","0.16201","674.35504"
"486.40000","0.16214","673.41392"
"486.80000","0.16227","672.41716"
"487.20000","0.16241","671.76002"
"487.60000","0.16253","670.65293"
"488.00000","0.16267","670.13054"
"488.40000","0.16280","669.03717"
"488.80000","0.16294","668.27625"
"489.20000","0.16307","667.44814"
"489.60000","0.16320","666.46856"
"490.00000","0.16334","665.86608"
"490.40000","0.16347","664.75609"
"490.80000","0.16361","664.13578"
"491.20000","0.16374","663.08122"
"491.60000","0.16387","662.11826"
"492.00000","0.16401","661.39609"
"492.40000","0.16413","660.31299"
"492.80000","0.16427","659.64932"
"493.20000","0.16440","658.52846"
"493.60000","0.16454","657.86166"
"494.00000","0.16467","656.96143"
"494.40000","0.16480","655.76675"
"494.80000","0.16494","655.18629"
"495.20000","0.16507","654.05182"
"495.60000","0.16521","653.40302"
"496.00000","0.16534","652.36427"
"496.40000","0.16547","651.38611"
"496.80000","0.16561","650.62611"
"497.20000","0.16573","649.51974"
"497.60000","0.16588","648.93297"
"498.00000","0.16601","647.72391"
"498.40000","0.16614","646.79382"
"498.80000","0.16627","645.85996"
"499.20000","0.16640","644.78816"
"499.60000","0.16654","644.08712"
"500.00000","0.16667","642.88700"
"500.40000","0.16681","642.12415"
"500.80000","0.16693","641.10801"
"501.20000","0.16707","640.15752"
"501.60000","0.16721","639.38748"
"502.00000","0.16733","638.13489"
"502.40000","0.16747","637.50739"
"502.80000","0.16761","636.34471"
"503.20000","0.16774","635.46897"
"503.60000","0.16787","634.46408"
"504.00000","0.16800","633.40732"
"504.40000","0.16814","632.62603"
"504.80000","0.16826","631.38025"
"505.20000","0.16841","630.63074"
"505.60000","0.16854","629.56614"
"506.00000","0.16867","628.46504"
"506.40000","0.16881","627.62195"
"506.80000","0.16893","626.36058"
"507.20000","0.16907","625.67501"
"507.60000","0.16920","624.48500"
"508.00000","0.16933","623.61463"
"508.40000","0.16947","622.63982"
"508.80000","0.16960","621.56791"
"509.20000","0.16974","620.87137"
"509.60000","0.16987","619.56812"
"510.00000","0.17001","618.71785"
"510.40000","0.17014","617.58211"
"510.80000","0.17027","616.50214"
"511.20000","0.17041","615.59659"
"511.60000","0.17053","614.37260"
"512.00000","0.17067","613.59845"
"512.40000","0.17080","612.28456"
"512.80000","0.17094","611.44591"
"513.20000","0.17107","610.41616"
"513.60000","0.17120","609.10523"
"514.00000","0.17134","608.38580"
"514.40000","0.17147","607.07515"
"514.80000","0.17161","606.24145"
"515.20000","0.17174","605.04204"
"515.60000","0.17187","603.99325"
"516.00000","0.17201","603.04851"
"516.40000","0.17213","601.79724"
"516.80000","0.17227","601.03495"
"517.20000","0.17241","599.76271"
"517.60000","0.17254","598.71298"
"518.00000","0.17267","597.62900"
"518.40000","0.17280","596.35309"
"518.80000","0.17294","595.57877"
"519.20000","0.17307","594.22213"
"519.60000","0.17321","593.31658"
"520.00000","0.17333","592.10340"
"520.40000","0.17347","591.06761"
"520.80000","0.17361","590.12222"
"521.20000","0.17373","588.74224"
"521.60000","0.17387","587.91606"
"522.00000","0.17400","586.60184"
"522.40000","0.17414","585.53718"
"522.80000","0.17427","584.43761"
"523.20000","0.17440","583.19804"
"523.60000","0.17454","582.29798"
"524.00000","0.17466","580.94100"
"524.40000","0.17481","580.04259"
"524.80000","0.17494","578.80658"
"525.20000","0.17507","577.51530"
"525.60000","0.17521","576.56222"
"526.00000","0.17533","575.13927"
"526.40000","0.17547","574.33960"
"526.80000","0.17560","572.95106"
"527.20000","0.17574","571.82016"
"527.60000","0.17587","570.66752"
"528.00000","0.17600","569.40846"
"528.40000","0.17614","568.48244"
"528.80000","0.17627","567.05466"
"529.20000","0.17641","566.02617"
"529.60000","0.17654","564.69856"
"530.00000","0.17667","563.46189"
"530.40000","0.17681","562.36644"
"530.80000","0.17693","560.96188"
"531.20000","0.17707","559.95918"
"531.60000","0.17720","558.58294"
"532.00000","0.17734","557.51729"
"532.40000","0.17747","556.27728"
"532.80000","0.17760","554.78199"
"533.20000","0.17774","553.83846"
"533.60000","0.17786","552.30871"
"534.00000","0.17801","551.33510"
"534.40000","0.17814","549.92511"
"534.80000","0.17827","548.61934"
"535.20000","0.17841","547.47219"
"535.60000","0.17853","546.02487"
"536.00000","0.17868","545.03881"
"536.40000","0.17881","543.50664"
"536.80000","0.17894","542.20927"
"537.20000","0.17908","540.91843"
"537.60000","0.17920","539.38231"
"538.00000","0.17934","538.32495"
"538.40000","0.17946","536.73125"
"538.80000","0.17960","535.48822"
"539.20000","0.17973","534.02954"
"539.60000","0.17987","532.63628"
"540.00000","0.18001","531.31844"
"540.40000","0.18013","529.46887"
"540.80000","0.18028","527.81304"
"541.20000","0.18041","525.65749"
"541.57700","0.18054","516.39526"
"541.58200","0.18058","475.66067"
"541.58600","0.18062","421.99942"
"541.59000","0.18065","359.17918"
"541.59400","0.18068","293.24458"
"541.59800","0.18071","228.60219"
"541.60200","0.18072","168.29788"
"541.60600","0.18073","114.22333"
"541.61000","0.18074","67.36464"
"541.61400","0.18074","28.05117"
"541.61700","0.18074","3.43079"