File: materials_lab1/ENGR314_FA19_0001_polyproylene_Aredo_20190903_MELD.is_tens_RawData/Specimen_RawData_2.csv
Material,Acrylic
Geometry,Circular
Length,"2.00000",in
Diameter,"0.11800",in

Time,Extension,Load
(s),(in),(lbf)
"0.00000","0.00000","-6.66223"
"0.70000","0.00095","-5.35819"
"1.40000","0.00187","-4.07371"
"2.10000","0.00281","-2.82072"
"2.80000","0.00375","-1.59691"
"3.50000","0.00468","-0.42172"
"4.20000","0.00560","0.75889"
"4.90000","0.00653","1.89748"
"5.60000","0.00746","3.02611"
"6.30000","0.00839","4.12522"
"7.00000","0.00933","5.23337"
"7.70000","0.01027","6.31060"
"8.40000","0.01121","7.34848"
"9.10000","0.01213","8.35953"
"9.80000","0.01308","9.36579"
"10.50000","0.01401","10.34421"
"11.20000","0.01495","11.29702"
"11.90000","0.01587","12.23534"
"12.60000","0.01680","13.14394"
"13.30000","0.01773","14.04575"
"14.00000","0.01866","14.91719"
"14.70000","0.01959","15.78505"
"15.40000","0.02053","16.63754"
"16.10000","0.02147","17.46605"
"16.80000","0.02240","18.25315"
"17.50000","0.02334","19.04948"
"18.20000","0.02428","19.80053"
"18.90000","0.02522","20.53395"
"19.60000","0.02614","21.24092"
"20.30000","0.02707","21.92713"
"21.00000","0.02800","22.60266"
"21.70000","0.02892","23.24232"
"22.40000","0.02986","23.88566"
"23.10000","0.03079","24.51038"
"23.80000","0.03173","25.10581"
"24.50000","0.03266","25.66518"
"25.20000","0.03360","26.24203"
"25.90000","0.03455","26.77822"
"26.60000","0.03549","27.29660"
"27.30000","0.03641","27.77051"
"28.00000","0.03734","28.25792"
"28.70000","0.03827","28.72891"
"29.40000","0.03919","29.15888"
"30.10000","0.04013","29.59207"
"30.80000","0.04106","30.01694"
"31.50000","0.04200","30.42833"
"32.20000","0.04293","30.81909"
"32.90000","0.04387","31.21098"
"33.60000","0.04481","31.59312"
"34.30000","0.04575","31.95169"
"35.00000","0.04667","32.28967"
"35.70000","0.04761","32.63737"
"36.40000","0.04855","32.96582"
"37.10000","0.04947","33.28255"
"37.80000","0.05040","33.59285"
"38.50000","0.05133","33.90133"
"39.20000","0.05226","34.20445"
"39.90000","0.05319","34.50626"
"40.60000","0.05413","34.80130"
"41.30000","0.05507","35.09692"
"42.00000","0.05601","35.38248"
"42.70000","0.05694","35.65173"
"43.40000","0.05788","35.93742"
"44.10000","0.05882","36.19892"
"44.80000","0.05975","36.44670"
"45.50000","0.06067","36.69955"
"46.20000","0.06160","36.95000"
"46.90000","0.06253","37.20481"
"47.60000","0.06345","37.44971"
"48.30000","0.06440","37.70327"
"49.00000","0.06533","37.94731"
"49.70000","0.06628","38.20003"
"50.40000","0.06720","38.42765"
"51.10000","0.06814","38.66774"
"51.80000","0.06908","38.90117"
"52.50000","0.07001","39.12154"
"53.20000","0.07094","39.34541"
"53.90000","0.07187","39.56484"
"54.60000","0.07280","39.77235"
"55.30000","0.07372","39.99198"
"56.00000","0.07466","40.21749"
"56.70000","0.07560","40.44437"
"57.40000","0.07654","40.65030"
"58.10000","0.07746","40.84362"
"58.80000","0.07841","41.05947"
"59.50000","0.07935","41.26690"
"60.20000","0.08029","41.46547"
"60.90000","0.08120","41.66246"
"61.60000","0.08214","41.84948"
"62.30000","0.08307","42.02825"
"63.00000","0.08399","42.21056"
"63.70000","0.08493","42.39232"
"64.40000","0.08586","42.59044"
"65.10000","0.08679","42.78238"
"65.80000","0.08773","42.95360"
"66.50000","0.08867","43.13013"
"67.20000","0.08961","43.31714"
"67.90000","0.09055","43.48106"
"68.60000","0.09147","43.64360"
"69.30000","0.09241","43.80675"
"70.00000","0.09334","43.96053"
"70.70000","0.09426","44.11783"
"71.40000","0.09520","44.28571"
"72.10000","0.09613","44.43375"
"72.80000","0.09706","44.59529"
"73.50000","0.09799","44.73028"
"74.20000","0.09893","44.88640"
"74.90000","0.09987","45.04221"
"75.60000","0.10081","45.18378"
"76.30000","0.10174","45.31014"
"77.00000","0.10268","45.45365"
"77.70000","0.10361","45.58307"
"78.40000","0.10454","45.69786"
"79.10000","0.10546","45.82692"
"79.80000","0.10639","45.95085"
"80.50000","0.10733","46.07438"
"81.20000","0.10825","46.20122"
"81.90000","0.10920","46.32801"
"82.60000","0.11014","46.44765"
"83.30000","0.11108","46.57119"
"84.00000","0.11200","46.67134"
"84.70000","0.11294","46.77107"
"85.40000","0.11388","46.87964"
"86.10000","0.11481","46.97636"
"86.80000","0.11573","47.06466"
"87.50000","0.11666","47.15070"
"88.20000","0.11760","47.24947"
"88.90000","0.11852","47.33613"
"89.60000","0.11946","47.44026"
"90.30000","0.12040","47.52856"
"91.00000","0.12134","47.62950"
"91.70000","0.12227","47.70361"
"92.40000","0.12321","47.77926"
"93.10000","0.12415","47.85149"
"93.80000","0.12508","47.92924"
"94.50000","0.12601","47.99284"
"95.20000","0.12694","48.05484"
"95.90000","0.12786","48.12344"
"96.60000","0.12879","48.18956"
"97.30000","0.12973","48.26361"
"98.00000","0.13066","48.33027"
"98.70000","0.13160","48.39246"
"99.40000","0.13253","48.43971"
"100.10000","0.13347","48.51104"
"100.80000","0.13442","48.56433"
"101.50000","0.13535","48.61378"
"102.20000","0.13627","48.65362"
"102.90000","0.13721","48.69723"
"103.60000","0.13814","48.73648"
"104.30000","0.13906","48.78004"
"105.00000","0.14000","48.82391"
"105.70000","0.14093","48.86337"
"106.40000","0.14186","48.89285"
"107.10000","0.14279","48.93154"
"107.80000","0.14374","48.97861"
"108.50000","0.14468","49.01626"
"109.20000","0.14562","49.04070"
"109.90000","0.14654","49.04680"
"110.60000","0.14748","49.07479"
"111.30000","0.14841","49.10297"
"112.00000","0.14933","49.11269"
"112.70000","0.15026","49.12957"
"113.40000","0.15120","49.15052"
"114.10000","0.15213","49.16278"
"114.80000","0.15306","49.17572"
"115.50000","0.15400","49.19833"
"116.20000","0.15494","49.21742"
"116.90000","0.15588","49.24363"
"117.60000","0.15681","49.23476"
"118.30000","0.15775","49.25158"
"119.00000","0.15868","49.25648"
"119.70000","0.15961","49.24450"
"120.40000","0.16053","49.25579"
"121.10000","0.16146","49.25731"
"121.80000","0.16239","49.26295"
"122.50000","0.16332","49.26874"
"123.20000","0.16426","49.26745"
"123.90000","0.16520","49.27188"
"124.60000","0.16614","49.28504"
"125.30000","0.16707","49.26539"
"126.00000","0.16801","49.25994"
"126.70000","0.16895","49.25306"
"127.40000","0.16988","49.24354"
"128.10000","0.17080","49.23661"
"128.80000","0.17173","49.22120"
"129.50000","0.17266","49.21384"
"130.20000","0.17359","49.19223"
"130.90000","0.17453","49.19315"
"131.60000","0.17546","49.18495"
"132.30000","0.17641","49.18406"
"133.00000","0.17733","49.15471"
"133.70000","0.17828","49.14596"
"134.40000","0.17922","49.12591"
"135.10000","0.18015","49.11509"
"135.80000","0.18107","49.08007"
"136.50000","0.18200","49.06452"
"137.20000","0.18293","49.04958"
"137.90000","0.18385","49.01567"
"138.60000","0.18480","48.98756"
"139.30000","0.18573","48.96165"
"140.00000","0.18667","48.94633"
"140.70000","0.18760","48.91663"
"141.40000","0.18854","48.89301"
"142.10000","0.18948","48.87042"
"142.80000","0.19042","48.83793"
"143.50000","0.19134","48.79607"
"144.20000","0.19228","48.76549"
"144.90000","0.19320","48.72968"
"145.60000","0.19413","48.69102"
"146.30000","0.19506","48.65839"
"147.00000","0.19599","48.62758"
"147.70000","0.19693","48.59897"
"148.40000","0.19786","48.55683"
"149.10000","0.19880","48.53163"
"149.80000","0.19974","48.50541"
"150.50000","0.20069","48.48095"
"151.20000","0.20161","48.43544"
"151.90000","0.20254","48.40238"
"152.60000","0.20347","48.36619"
"153.30000","0.20440","48.32611"
"154.00000","0.20533","48.29823"
"154.70000","0.20626","48.26597"
"155.40000","0.20720","48.23353"
"156.10000","0.20812","48.19611"
"156.80000","0.20907","48.16369"
"157.50000","0.21001","48.14405"
"158.20000","0.21095","48.11273"
"158.90000","0.21187","48.06603"
"159.60000","0.21281","48.03036"
"160.30000","0.21375","47.98949"
"161.00000","0.21467","47.93696"
"161.70000","0.21560","47.89963"
"162.40000","0.21653","47.86080"
"163.10000","0.21746","47.82616"
"163.80000","0.21839","47.78536"
"164.50000","0.21933","47.74494"
"165.20000","0.22027","47.70828"
"165.90000","0.22121","47.67382"
"166.60000","0.22213","47.61903"
"167.30000","0.22308","47.57423"
"168.00000","0.22402","47.53130"
"168.70000","0.22494","47.48668"
"169.40000","0.22587","47.42931"
"170.10000","0.22680","47.38799"
"170.80000","0.22773","47.34682"
"171.50000","0.22866","47.29393"
"172.20000","0.22960","47.26255"
"172.90000","0.23053","47.22320"
"173.60000","0.23147","47.17685"
"174.30000","0.23240","47.13238"
"175.00000","0.23334","47.09833"
"175.70000","0.23428","47.04460"
"176.40000","0.23522","46.99417"
"177.10000","0.23614","46.95266"
"177.80000","0.23707","46.88935"
"178.50000","0.23800","46.83557"
"179.20000","0.23892","46.78832"
"179.90000","0.23986","46.75053"
"180.60000","0.24080","46.68920"
"181.30000","0.24173","46.64564"
"182.00000","0.24266","46.60246"
"182.70000","0.24360","46.55205"
"183.40000","0.24455","46.51152"
"184.10000","0.24549","46.46517"
"184.80000","0.24641","46.40109"
"185.50000","0.24734","46.35145"
"186.20000","0.24827","46.29405"
"186.90000","0.24920","46.23527"
"187.60000","0.25013","46.18952"
"188.30000","0.25106","46.14963"
"189.00000","0.25200","46.10239"
"189.70000","0.25292","46.04306"
"190.40000","0.25387","46.00721"
"191.10000","0.25481","45.96390"
"191.80000","0.25575","45.92090"
"192.50000","0.25667","45.85225"
"193.20000","0.25761","45.80193"
"193.90000","0.25854","45.74179"
"194.60000","0.25947","45.64461"
"195.30000","0.26039","45.64076"
"196.00000","0.26133","45.57863"
"196.70000","0.26226","45.53058"
"197.40000","0.26319","45.47316"
"198.10000","0.26413","45.41940"
"198.80000","0.26507","45.36963"
"199.50000","0.26601","45.31833"
"200.20000","0.26694","45.24934"
"200.90000","0.26788","45.19694"
"201.60000","0.26881","45.13532"
"202.30000","0.26974","45.07004"
"203.00000","0.27067","45.01392"
"203.70000","0.27160","44.94840"
"204.40000","0.27253","44.90045"
"205.10000","0.27345","44.83241"
"205.80000","0.27439","44.77886"
"206.50000","0.27534","44.71582"
"207.20000","0.27628","44.66463"
"207.90000","0.27720","44.60166"
"208.60000","0.27814","44.54136"
"209.30000","0.27909","44.48111"
"210.00000","0.28001","44.40204"
"210.70000","0.28094","44.36118"
"211.40000","0.28187","44.28728"
"212.10000","0.28280","44.22733"
"212.80000","0.28372","44.16305"
"213.50000","0.28466","44.10504"
"214.20000","0.28560","44.05191"
"214.90000","0.28654","43.99647"
"215.60000","0.28747","43.93354"
"216.30000","0.28841","43.87546"
"217.00000","0.28935","43.81788"
"217.70000","0.29028","43.75241"
"218.40000","0.29120","43.68962"
"219.10000","0.29214","43.62239"
"219.80000","0.29307","43.56835"
"220.50000","0.29399","43.50104"
"221.20000","0.29493","43.45052"
"221.90000","0.29586","43.40128"
"222.60000","0.29680","43.35314"
"223.30000","0.29773","43.28947"
"224.00000","0.29867","43.23965"
"224.70000","0.29961","43.18653"
"225.40000","0.30055","43.14513"
"226.10000","0.30147","43.07662"
"226.80000","0.30241","43.03042"
"227.50000","0.30334","42.97364"
"228.20000","0.30426","42.92370"
"228.90000","0.30519","42.87059"
"229.60000","0.30613","42.82672"
"230.30000","0.30706","42.78413"
"231.00000","0.30799","42.73735"
"231.70000","0.30894","42.70329"
"232.40000","0.30988","42.65761"
"233.10000","0.31082","42.61996"
"233.80000","0.31174","42.57352"
"234.50000","0.31268","42.52989"
"235.20000","0.31361","42.49177"
"235.90000","0.31454","42.44429"
"236.60000","0.31546","42.40970"
"237.30000","0.31639","42.37893"
"238.00000","0.31733","42.34045"
"238.70000","0.31826","42.29906"
"239.40000","0.31920","42.26907"
"240.10000","0.32014","42.24789"
"240.80000","0.32108","42.22758"
"241.50000","0.32200","42.17869"
"242.20000","0.32295","42.15105"
"242.90000","0.32388","42.11841"
"243.60000","0.32481","42.09624"
"244.30000","0.32573","42.05903"
"245.00000","0.32666","42.02602"
"245.70000","0.32759","41.99310"
"246.40000","0.32852","41.97063"
"247.10000","0.32946","41.95227"
"247.80000","0.33040","41.93535"
"248.50000","0.33134","41.91304"
"249.20000","0.33227","41.88278"
"249.90000","0.33321","41.86843"
"250.60000","0.33415","41.84010"
"251.30000","0.33508","41.81692"
"252.00000","0.33601","41.79573"
"252.70000","0.33693","41.78084"
"253.40000","0.33786","41.76363"
"254.10000","0.33879","41.73910"
"254.80000","0.33973","41.71938"
"255.50000","0.34066","41.71286"
"256.20000","0.34160","41.70783"
"256.90000","0.34253","41.68727"
"257.60000","0.34347","41.67503"
"258.30000","0.34442","41.65907"
"259.00000","0.34535","41.65108"
"259.70000","0.34627","41.63432"
"260.40000","0.34721","41.62443"
"261.10000","0.34813","41.60233"
"261.80000","0.34906","41.59265"
"262.50000","0.35000","41.58743"
"263.20000","0.35093","41.57102"
"263.90000","0.35186","41.57208"
"264.60000","0.35279","41.54202"
"265.30000","0.35374","41.55479"
"266.00000","0.35468","41.53668"
"266.70000","0.35562","41.53532"
"267.40000","0.35654","41.51551"
"268.10000","0.35747","41.51052"
"268.80000","0.35841","41.50618"
"269.50000","0.35933","41.48554"
"270.20000","0.36026","41.48525"
"270.90000","0.36119","41.47602"
"271.60000","0.36213","41.48337"
"272.30000","0.36306","41.46990"
"273.00000","0.36400","41.46944"
"273.70000","0.36494","41.46675"
"274.40000","0.36588","41.46875"
"275.10000","0.36681","41.44970"
"275.80000","0.36774","41.44606"
"276.50000","0.36868","41.44621"
"277.20000","0.36960","41.43141"
"277.90000","0.37053","41.43360"
"278.60000","0.37146","41.42083"
"279.30000","0.37240","41.41430"
"280.00000","0.37332","41.41388"
"280.70000","0.37426","41.40480"
"281.40000","0.37520","41.40502"
"282.10000","0.37614","41.40909"
"282.80000","0.37707","41.39687"
"283.50000","0.37801","41.39645"
"284.20000","0.37895","41.39025"
"284.90000","0.37988","41.38466"
"285.60000","0.38080","41.37869"
"286.30000","0.38173","41.37064"
"287.00000","0.38266","41.36479"
"287.70000","0.38359","41.36855"
"288.40000","0.38453","41.37294"
"289.10000","0.38546","41.37273"
"289.80000","0.38641","41.36400"
"290.50000","0.38733","41.36384"
"291.20000","0.38828","41.36705"
"291.90000","0.38922","41.36184"
"292.60000","0.39015","41.35647"
"293.30000","0.39107","41.34691"
"294.00000","0.39200","41.34051"
"294.70000","0.39293","41.34081"
"295.40000","0.39385","41.33094"
"296.10000","0.39479","41.33063"
"296.80000","0.39573","41.32478"
"297.50000","0.39667","41.32657"
"298.20000","0.39760","41.33009"
"298.90000","0.39854","41.34099"
"299.60000","0.39948","41.33588"
"300.30000","0.40042","41.33287"
"301.00000","0.40134","41.32242"
"301.70000","0.40227","41.32094"
"302.40000","0.40320","41.31532"
"303.10000","0.40412","41.30787"
"303.80000","0.40506","41.31235"
"304.50000","0.40599","41.30564"
"305.20000","0.40693","41.31914"
"305.90000","0.40786","41.30569"
"306.60000","0.40880","41.31051"
"307.30000","0.40975","41.32109"
"308.00000","0.41069","41.31985"
"308.70000","0.41161","41.31325"
"309.40000","0.41254","41.30721"
"310.10000","0.41348","41.30270"
"310.80000","0.41440","41.29850"
"311.50000","0.41533","41.29772"
"312.20000","0.41626","41.29157"
"312.90000","0.41720","41.29227"
"313.60000","0.41812","41.28935"
"314.30000","0.41907","41.29272"
"315.00000","0.42001","41.29285"
"315.70000","0.42095","41.29564"
"316.40000","0.42188","41.28748"
"317.10000","0.42281","41.28682"
"317.80000","0.42374","41.27235"
"318.50000","0.42467","41.27686"
"319.20000","0.42560","41.27277"
"319.90000","0.42653","41.27013"
"320.60000","0.42746","41.26724"
"321.30000","0.42839","41.26018"
"322.00000","0.42933","41.27010"
"322.70000","0.43027","41.27512"
"323.40000","0.43121","41.27748"
"324.10000","0.43214","41.27432"
"324.80000","0.43308","41.27823"
"325.50000","0.43401","41.26997"
"326.20000","0.43494","41.27360"
"326.90000","0.43587","41.25379"
"327.60000","0.43680","41.26386"
"328.30000","0.43773","41.25665"
"329.00000","0.43866","41.25977"
"329.70000","0.43960","41.26766"
"330.40000","0.44053","41.26455"
"331.10000","0.44147","41.27682"
"331.80000","0.44240","41.26248"
"332.50000","0.44334","41.26590"
"333.20000","0.44428","41.26364"
"333.90000","0.44522","41.25485"
"334.60000","0.44614","41.26083"
"335.30000","0.44707","41.25107"
"336.00000","0.44800","41.25242"
"336.70000","0.44892","41.24834"
"337.40000","0.44986","41.23827"
"338.10000","0.45080","41.25096"
"338.80000","0.45174","41.24902"
"339.50000","0.45266","41.23772"
"340.20000","0.45361","41.24158"
"340.90000","0.45455","41.24500"
"341.60000","0.45549","41.24064"
"342.30000","0.45641","41.23854"
"343.00000","0.45734","41.23280"
"343.70000","0.45827","41.23286"
"344.40000","0.45919","41.21966"
"345.10000","0.46013","41.21591"
"345.80000","0.46106","41.21314"
"346.50000","0.46199","41.22374"
"347.20000","0.46293","41.21063"
"347.90000","0.46387","41.21370"
"348.60000","0.46481","41.22168"
"349.30000","0.46576","41.22434"
"350.00000","0.46667","41.20600"
"350.70000","0.46761","41.20783"
"351.40000","0.46854","41.20536"
"352.10000","0.46946","41.19568"
"352.80000","0.47039","41.19756"
"353.50000","0.47132","41.19012"
"354.20000","0.47226","41.19653"
"354.90000","0.47319","41.19550"
"355.60000","0.47413","41.19541"
"356.30000","0.47507","41.19322"
"357.00000","0.47601","41.20211"
"357.70000","0.47694","41.18808"
"358.40000","0.47788","41.18986"
"359.10000","0.47881","41.18001"
"359.80000","0.47974","41.18225"
"360.50000","0.48067","41.17511"
"361.20000","0.48160","41.16700"
"361.90000","0.48253","41.16685"
"362.60000","0.48345","41.15670"
"363.30000","0.48440","41.16346"
"364.00000","0.48534","41.16627"
"364.70000","0.48628","41.17194"
"365.40000","0.48720","41.15978"
"366.10000","0.48815","41.16072"
"366.80000","0.48908","41.15506"
"367.50000","0.49001","41.15683"
"368.20000","0.49094","41.15047"
"368.90000","0.49187","41.14023"
"369.60000","0.49279","41.14870"
"370.30000","0.49372","41.14287"
"371.00000","0.49466","41.15302"
"371.70000","0.49560","41.14352"
"372.40000","0.49654","41.15084"
"373.10000","0.49747","41.13836"
"373.80000","0.49841","41.14472"
"374.50000","0.49935","41.14581"
"375.20000","0.50028","41.13923"
"375.90000","0.50120","41.13556"
"376.60000","0.50214","41.12449"
"377.30000","0.50307","41.12591"
"378.00000","0.50399","41.11277"
"378.70000","0.50493","41.11962"
"379.40000","0.50586","41.11775"
"380.10000","0.50680","41.12131"
"380.80000","0.50773","41.11383"
"381.50000","0.50867","41.11028"
"382.20000","0.50961","41.12065"
"382.90000","0.51056","41.11847"
"383.60000","0.51147","41.10334"
"384.30000","0.51241","41.10396"
"385.00000","0.51334","41.09166"
"385.70000","0.51426","41.08353"
"386.40000","0.51520","41.08847"
"387.10000","0.51613","41.07863"
"387.80000","0.51706","41.07604"
"388.50000","0.51799","41.07566"
"389.20000","0.51894","41.08747"
"389.90000","0.51988","41.08552"
"390.60000","0.52082","41.07960"
"391.30000","0.52174","41.07434"
"392.00000","0.52268","41.07061"
"392.70000","0.52361","41.05838"
"393.40000","0.52453","41.05832"
"394.10000","0.52546","41.05858"
"394.80000","0.52639","41.05793"
"395.50000","0.52733","41.05449"
"396.20000","0.52826","41.05387"
"396.90000","0.52920","41.05047"
"397.60000","0.53014","41.05894"
"398.30000","0.53108","41.06393"
"399.00000","0.53200","41.05137"
"399.70000","0.53295","41.05179"
"400.40000","0.53388","41.05582"
"401.10000","0.53480","41.05596"
"401.80000","0.53573","41.04228"
"402.50000","0.53666","41.04449"
"403.20000","0.53759","41.04432"
"403.90000","0.53852","41.04273"
"404.60000","0.53946","41.04111"
"405.30000","0.54040","41.04570"
"406.00000","0.54134","41.05397"
"406.70000","0.54227","41.04675"
"407.40000","0.54321","41.03780"
"408.10000","0.54415","41.03350"
"408.80000","0.54508","41.03530"
"409.50000","0.54600","41.03637"
"410.20000","0.54693","41.03089"
"410.90000","0.54786","41.01584"
"411.60000","0.54879","41.00781"
"412.30000","0.54973","41.00506"
"413.00000","0.55066","41.01841"
"413.70000","0.55161","41.02442"
"414.40000","0.55253","41.01596"
"415.10000","0.55347","41.01371"
"415.80000","0.55442","41.00870"
"416.50000","0.55535","41.00225"
"417.20000","0.55627","40.99018"
"417.90000","0.55720","40.99108"
"418.60000","0.55813","40.99443"
"419.30000","0.55906","40.99547"
"420.00000","0.56000","40.99130"
"420.70000","0.56093","40.99639"
"421.40000","0.56187","40.99270"
"422.10000","0.56280","40.98735"
"422.80000","0.56374","40.98599"
"423.50000","0.56468","40.99795"
"424.20000","0.56562","40.99672"
"424.90000","0.56654","40.98838"
"425.60000","0.56748","40.98386"
"426.30000","0.56841","40.97752"
"427.00000","0.56933","40.96595"
"427.70000","0.57026","40.97540"
"428.40000","0.57119","40.97181"
"429.10000","0.57213","40.98416"
"429.80000","0.57306","40.96947"
"430.50000","0.57400","40.97342"
"431.20000","0.57494","40.98195"
"431.90000","0.57588","40.97856"
"432.60000","0.57681","40.97769"
"433.30000","0.57774","40.97710"
"434.00000","0.57867","40.96652"
"434.70000","0.57960","40.96947"
"435.40000","0.58053","40.97291"
"436.10000","0.58146","40.97131"
"436.80000","0.58240","40.97737"
"437.50000","0.58332","40.97207"
"438.20000","0.58427","40.98116"
"438.90000","0.58521","40.98666"
"439.60000","0.58615","40.99116"
"440.30000","0.58707","40.98050"
"441.00000","0.58801","40.98083"
"441.70000","0.58895","40.97483"
"442.40000","0.58987","40.96608"
"443.10000","0.59080","40.97629"
"443.80000","0.59173","40.97603"
"444.50000","0.59266","40.96756"
"445.20000","0.59359","40.96984"
"445.90000","0.59453","40.96322"
"446.60000","0.59547","40.96908"
"447.30000","0.59641","40.97807"
"448.00000","0.59733","40.96681"
"448.70000","0.59828","40.96293"
"449.40000","0.59922","40.96166"
"450.10000","0.60015","40.95676"
"450.80000","0.60107","40.95000"
"451.50000","0.60200","40.95471"
"452.20000","0.60293","40.94527"
"452.90000","0.60385","40.94526"
"453.60000","0.60480","40.95195"
"454.30000","0.60573","40.96036"
"455.00000","0.60667","40.96384"
"455.70000","0.60760","40.95740"
"456.40000","0.60854","40.96726"
"457.10000","0.60948","40.96619"
"457.80000","0.61042","40.97526"
"458.50000","0.61134","40.96615"
"459.20000","0.61227","40.96289"
"459.90000","0.61320","40.96185"
"460.60000","0.61412","40.96128"
"461.30000","0.61506","40.96117"
"462.00000","0.61600","40.95679"
"462.70000","0.61693","40.96656"
"463.40000","0.61786","40.96133"
"464.10000","0.61880","40.96746"
"464.80000","0.61974","40.96589"
"465.50000","0.62069","40.96516"
"466.20000","0.62160","40.95282"
"466.90000","0.62254","40.95502"
"467.60000","0.62347","40.95383"
"468.30000","0.62440","40.94814"
"469.00000","0.62533","40.95851"
"469.70000","0.62626","40.95929"
"470.40000","0.62720","40.97005"
"471.10000","0.62812","40.96418"
"471.80000","0.62907","40.96388"
"472.50000","0.63001","40.97491"
"473.20000","0.63095","40.97137"
"473.90000","0.63187","40.96452"
"474.60000","0.63281","40.95778"
"475.30000","0.63374","40.96086"
"476.00000","0.63467","40.96269"
"476.70000","0.63560","40.95806"
"477.40000","0.63653","40.95747"
"478.10000","0.63746","40.95586"
"478.80000","0.63839","40.95418"
"479.50000","0.63933","40.95495"
"480.20000","0.64027","40.95900"
"480.90000","0.64121","40.96657"
"481.60000","0.64214","40.95349"
"482.30000","0.64308","40.95331"
"483.00000","0.64401","40.95353"
"483.70000","0.64494","40.94238"
"484.40000","0.64587","40.93696"
"485.10000","0.64680","40.93411"
"485.80000","0.64773","40.93380"
"486.50000","0.64866","40.92116"
"487.20000","0.64960","40.92469"
"487.90000","0.65053","40.93223"
"488.60000","0.65148","40.93130"
"489.30000","0.65240","40.92181"
"490.00000","0.65334","40.92282"
"490.70000","0.65428","40.92220"
"491.40000","0.65522","40.92656"
"492.10000","0.65614","40.91857"
"492.80000","0.65707","40.90987"
"493.50000","0.65800","40.91004"
"494.20000","0.65892","40.90981"
"494.90000","0.65986","40.90842"
"495.60000","0.66080","40.91244"
"496.30000","0.66174","40.91318"
"497.00000","0.66266","40.90515"
"497.70000","0.66361","40.89943"
"498.40000","0.66455","40.90184"
"499.10000","0.66549","40.90298"
"499.80000","0.66640","40.89890"
"500.50000","0.66734","40.88636"
"501.20000","0.66827","40.89260"
"501.90000","0.66919","40.88408"
"502.60000","0.67013","40.90007"
"503.30000","0.67106","40.89081"
"504.00000","0.67200","40.89495"
"504.70000","0.67293","40.89737"
"505.40000","0.67387","40.89914"
"506.10000","0.67481","40.90273"
"506.80000","0.67575","40.91080"
"507.50000","0.67667","40.90005"
"508.20000","0.67761","40.90111"
"508.90000","0.67854","40.89406"
"509.60000","0.67946","40.88311"
"510.30000","0.68040","40.89803"
"511.00000","0.68132","40.90167"
"511.70000","0.68226","40.90480"
"512.40000","0.68319","40.89800"
"513.10000","0.68413","40.90241"
"513.80000","0.68508","40.90036"
"514.50000","0.68602","40.91202"
"515.20000","0.68694","40.90643"
"515.90000","0.68788","40.89706"
"516.60000","0.68881","40.89740"
"517.30000","0.68974","40.88981"
"518.00000","0.69066","40.90045"
"518.70000","0.69159","40.88886"
"519.40000","0.69253","40.90319"
"520.10000","0.69346","40.89584"
"520.80000","0.69440","40.90201"
"521.50000","0.69534","40.91334"
"522.20000","0.69628","40.91488"
"522.90000","0.69720","40.90817"
"523.60000","0.69815","40.90844"
"524.30000","0.69908","40.91326"
"525.00000","0.70001","40.91279"
"525.70000","0.70094","40.91950"
"526.40000","0.70187","40.91360"
"527.10000","0.70279","40.91514"
"527.80000","0.70372","40.90707"
"528.50000","0.70466","40.91777"
"529.20000","0.70560","40.91630"
"529.90000","0.70654","40.93267"
"530.60000","0.70747","40.92778"
"531.30000","0.70841","40.92584"
"532.00000","0.70935","40.93115"
"532.70000","0.71028","40.92555"
"533.40000","0.71120","40.91494"
"534.10000","0.71214","40.90977"
"534.80000","0.71307","40.92278"
"535.50000","0.71399","40.90905"
"536.20000","0.71493","40.91146"
"536.90000","0.71586","40.91807"
"537.60000","0.71680","40.92353"
"538.30000","0.71773","40.92654"
"539.00000","0.71867","40.92171"
"539.70000","0.71961","40.92462"
"540.40000","0.72055","40.93183"
"541.10000","0.72147","40.92305"
"541.80000","0.72240","40.91779"
"542.50000","0.72334","40.91108"
"543.20000","0.72426","40.91545"
"543.90000","0.72519","40.91612"
"544.60000","0.72613","40.91114"
"545.30000","0.72707","40.91344"
"546.00000","0.72799","40.91284"
"546.70000","0.72894","40.90762"
"547.40000","0.72988","40.91190"
"548.10000","0.73082","40.91911"
"548.80000","0.73174","40.91919"
"549.50000","0.73268","40.90678"
"550.20000","0.73361","40.90822"
"550.90000","0.73453","40.90126"
"551.60000","0.73546","40.89640"
"552.30000","0.73639","40.89495"
"553.00000","0.73733","40.89326"
"553.70000","0.73825","40.89642"
"554.40000","0.73920","40.90060"
"555.10000","0.74014","40.89423"
"555.80000","0.74108","40.90501"
"556.50000","0.74200","40.89925"
"557.20000","0.74295","40.90047"
"557.90000","0.74388","40.90351"
"558.60000","0.74480","40.89796"
"559.30000","0.74573","40.89791"
"560.00000","0.74666","40.90183"
"560.70000","0.74759","40.90845"
"561.40000","0.74852","40.89896"
"562.10000","0.74946","40.90420"
"562.80000","0.75040","40.90178"
"563.50000","0.75135","40.86004"
"564.20000","0.75227","40.90573"
"564.90000","0.75321","40.91383"
"565.60000","0.75415","40.91218"
"566.30000","0.75508","40.91808"
"567.00000","0.75600","40.91130"
"567.70000","0.75693","40.91339"
"568.40000","0.75786","40.92095"
"569.10000","0.75879","40.91310"
"569.80000","0.75973","40.92001"
"570.50000","0.76067","40.91331"
"571.20000","0.76161","40.91948"
"571.90000","0.76253","40.91941"
"572.60000","0.76347","40.92390"
"573.30000","0.76442","40.94060"
"574.00000","0.76535","40.93083"
"574.70000","0.76627","40.93911"
"575.40000","0.76720","40.93938"
"576.10000","0.76813","40.93563"
"576.80000","0.76906","40.93982"
"577.50000","0.77000","40.94480"
"578.20000","0.77093","40.94571"
"578.90000","0.77187","40.95066"
"579.60000","0.77280","40.95203"
"580.30000","0.77374","40.95421"
"581.00000","0.77468","40.96418"
"581.70000","0.77562","40.95428"
"582.40000","0.77654","40.95228"
"583.10000","0.77747","40.94164"
"583.80000","0.77840","40.92984"
"584.50000","0.77932","40.93904"
"585.20000","0.78026","40.93500"
"585.90000","0.78120","40.93292"
"586.60000","0.78213","40.94449"
"587.30000","0.78306","40.92786"
"588.00000","0.78401","40.93146"
"588.70000","0.78494","40.93724"
"589.40000","0.78589","40.93550"
"590.10000","0.78681","40.91087"
"590.80000","0.78774","40.91598"
"591.50000","0.78868","40.92177"
"592.20000","0.78960","40.91187"
"592.90000","0.79053","40.91795"
"593.60000","0.79146","40.91626"
"594.30000","0.79240","40.92024"
"595.00000","0.79332","40.90661"
"595.70000","0.79427","40.90717"
"596.40000","0.79521","40.91507"
"597.10000","0.79615","40.90921"
"597.80000","0.79707","40.90102"
"598.50000","0.79801","40.89192"
"599.20000","0.79895","40.88718"
"599.90000","0.79987","40.87778"
"600.60000","0.80080","40.87639"
"601.30000","0.80173","40.87599"
"602.00000","0.80266","40.88517"
"602.70000","0.80359","40.87742"
"603.40000","0.80453","40.88046"
"604.10000","0.80547","40.88604"
"604.80000","0.80641","40.88118"
"605.50000","0.80734","40.87607"
"606.20000","0.80828","40.88063"
"606.90000","0.80922","40.87635"
"607.60000","0.81015","40.87643"
"608.30000","0.81107","40.87778"
"609.00000","0.81200","40.86496"
"609.70000","0.81293","40.86291"
"610.40000","0.81385","40.87238"
"611.10000","0.81480","40.87840"
"611.80000","0.81573","40.86486"
"612.50000","0.81667","40.87133"
"613.20000","0.81760","40.87256"
"613.90000","0.81854","40.86389"
"614.60000","0.81948","40.87711"
"615.30000","0.82042","40.87065"
"616.00000","0.82134","40.86483"
"616.70000","0.82227","40.87330"
"617.40000","0.82320","40.87814"
"618.10000","0.82412","40.87155"
"618.80000","0.82506","40.88011"
"619.50000","0.82600","40.88481"
"620.20000","0.82693","40.88034"
"620.90000","0.82786","40.88064"
"621.60000","0.82881","40.87258"
"622.30000","0.82975","40.88445"
"623.00000","0.83069","40.87468"
"623.70000","0.83161","40.87132"
"624.40000","0.83254","40.87317"
"625.10000","0.83347","40.87002"
"625.80000","0.83439","40.86869"
"626.50000","0.83533","40.87323"
"627.20000","0.83626","40.87828"
"627.90000","0.83720","40.88310"
"628.60000","0.83812","40.86862"
"629.30000","0.83907","40.87849"
"630.00000","0.84001","40.89237"
"630.70000","0.84095","40.88570"
"631.40000","0.84187","40.87634"
"632.10000","0.84281","40.87981"
"632.80000","0.84374","40.87898"
"633.50000","0.84467","40.87657"
"634.20000","0.84560","40.88106"
"634.90000","0.84652","40.88283"
"635.60000","0.84746","40.87792"
"636.30000","0.84839","40.87370"
"637.00000","0.84933","40.88439"
"637.70000","0.85027","40.89095"
"638.40000","0.85121","40.89302"
"639.10000","0.85214","40.88557"
"639.80000","0.85308","40.88172"
"640.50000","0.85401","40.87310"
"641.20000","0.85494","40.86909"
"641.90000","0.85587","40.86816"
"642.60000","0.85680","40.86456"
"643.30000","0.85773","40.87203"
"644.00000","0.85865","40.85799"
"644.70000","0.85960","40.86402"
"645.40000","0.86053","40.85634"
"646.10000","0.86148","40.85720"
"646.80000","0.86240","40.86092"
"647.50000","0.86334","40.86660"
"648.20000","0.86428","40.85394"
"648.90000","0.86521","40.84355"
"649.60000","0.86613","40.83901"
"650.30000","0.86707","40.84344"
"651.00000","0.86799","40.83562"
"651.70000","0.86892","40.83155"
"652.40000","0.86986","40.84324"
"653.10000","0.87080","40.83175"
"653.80000","0.87174","40.84403"
"654.50000","0.87266","40.83752"
"655.20000","0.87361","40.85232"
"655.90000","0.87455","40.85484"
"656.60000","0.87549","40.85209"
"657.30000","0.87640","40.84625"
"658.00000","0.87734","40.83852"
"658.70000","0.87827","40.82996"
"659.40000","0.87919","40.82925"
"660.10000","0.88013","40.83756"
"660.80000","0.88106","40.83607"
"661.50000","0.88200","40.84627"
"662.20000","0.88293","40.84632"
"662.90000","0.88387","40.85291"
"663.60000","0.88481","40.84682"
"664.30000","0.88575","40.86192"
"665.00000","0.88668","40.84767"
"665.70000","0.88761","40.83667"
"666.40000","0.88854","40.84517"
"667.10000","0.88946","40.83990"
"667.80000","0.89040","40.84105"
"668.50000","0.89133","40.84363"
"669.20000","0.89226","40.84496"
"669.90000","0.89319","40.82553"
"670.60000","0.89413","40.84494"
"671.30000","0.89508","40.84291"
"672.00000","0.89602","40.84309"
"672.70000","0.89694","40.84033"
"673.40000","0.89788","40.83344"
"674.10000","0.89881","40.83252"
"674.80000","0.89973","40.82605"
"675.50000","0.90066","40.83534"
"676.20000","0.90159","40.81532"
"676.90000","0.90253","40.81607"
"677.60000","0.90346","40.81450"
"678.30000","0.90440","40.83122"
"679.00000","0.90534","40.81768"
"679.70000","0.90628","40.82569"
"680.40000","0.90720","40.81929"
"681.10000","0.90815","40.81133"
"681.80000","0.90908","40.81436"
"682.50000","0.91001","40.81202"
"683.20000","0.91093","40.80833"
"683.90000","0.91187","40.79554"
"684.60000","0.91279","40.78741"
"685.30000","0.91372","40.79274"
"686.00000","0.91466","40.79798"
"686.70000","0.91560","40.79841"
"687.40000","0.91654","40.80099"
"688.10000","0.91747","40.78671"
"688.80000","0.91841","40.79595"
"689.50000","0.91935","40.78722"
"690.20000","0.92028","40.78667"
"690.90000","0.92120","40.77750"
"691.60000","0.92213","40.77334"
"692.30000","0.92306","40.76896"
"693.00000","0.92399","40.76972"
"693.70000","0.92493","40.77132"
"694.40000","0.92586","40.76904"
"695.10000","0.92680","40.76867"
"695.80000","0.92773","40.76869"
"696.50000","0.92868","40.77855"
"697.20000","0.92961","40.77799"
"697.90000","0.93055","40.75996"
"698.60000","0.93147","40.75886"
"699.30000","0.93240","40.76626"
"700.00000","0.93333","40.76303"
"700.70000","0.93426","40.75356"
"701.40000","0.93519","40.76309"
"702.10000","0.93613","40.76607"
"702.80000","0.93707","40.76961"
"703.50000","0.93800","40.76143"
"704.20000","0.93894","40.76617"
"704.90000","0.93988","40.76766"
"705.60000","0.94082","40.76843"
"706.30000","0.94174","40.74829"
"707.00000","0.94268","40.76085"
"707.70000","0.94361","40.75594"
"708.40000","0.94453","40.74753"
"709.10000","0.94546","40.75216"
"709.80000","0.94639","40.75275"
"710.50000","0.94733","40.75167"
"711.20000","0.94826","40.74481"
"711.90000","0.94920","40.75126"
"712.60000","0.95014","40.75655"
"713.30000","0.95108","40.74890"
"714.00000","0.95201","40.75646"
"714.70000","0.95295","40.75507"
"715.40000","0.95388","40.74218"
"716.10000","0.95480","40.74478"
"716.80000","0.95573","40.74833"
"717.50000","0.95666","40.74913"
"718.20000","0.95760","40.74319"
"718.90000","0.95852","40.75000"
"719.60000","0.95946","40.74972"
"720.30000","0.96040","40.74801"
"721.00000","0.96135","40.75242"
"721.70000","0.96227","40.74445"
"722.40000","0.96321","40.74966"
"723.10000","0.96415","40.74947"
"723.80000","0.96508","40.73922"
"724.50000","0.96600","40.73475"
"725.20000","0.96693","40.73196"
"725.90000","0.96786","40.73172"
"726.60000","0.96879","40.73240"
"727.30000","0.96973","40.73468"
"728.00000","0.97067","40.72929"
"728.70000","0.97161","40.73607"
"729.40000","0.97254","40.73422"
"730.10000","0.97348","40.73275"
"730.80000","0.97441","40.71736"
"731.50000","0.97535","40.70017"
"732.20000","0.97627","40.71167"
"732.90000","0.97720","40.70243"
"733.60000","0.97813","40.69604"
"734.30000","0.97906","40.69461"
"735.00000","0.98000","40.68378"
"735.70000","0.98093","40.68885"
"736.40000","0.98187","40.69204"
"737.10000","0.98280","40.69061"
"737.80000","0.98374","40.67588"
"738.50000","0.98468","40.67084"
"739.20000","0.98562","40.67773"
"739.90000","0.98654","40.66430"
"740.60000","0.98747","40.66628"
"741.30000","0.98840","40.65123"
"742.00000","0.98933","40.65248"
"742.70000","0.99026","40.65747"
"743.40000","0.99120","40.65340"
"744.10000","0.99213","40.65262"
"744.80000","0.99306","40.64322"
"745.50000","0.99401","40.65473"
"746.20000","0.99495","40.65456"
"746.90000","0.99589","40.65408"
"747.60000","0.99681","40.64222"
"748.30000","0.99775","40.63477"
"749.00000","0.99867","40.63561"
"749.70000","0.99960","40.63013"
"750.40000","1.00053","40.63622"
"751.10000","1.00146","40.62573"
"751.80000","1.00240","40.64364"
"752.50000","1.00333","40.63880"
"753.20000","1.00427","40.64186"
"753.90000","1.00521","40.63855"
"754.60000","1.00615","40.64015"
"755.30000","1.00707","40.63732"
"756.00000","1.00801","40.64050"
"756.70000","1.00894","40.62887"
"757.40000","1.00987","40.63109"
"758.10000","1.01080","40.63309"
"758.80000","1.01173","40.63009"
"759.50000","1.01266","40.63804"
"760.20000","1.01359","40.62742"
"760.90000","1.01453","40.63626"
"761.60000","1.01547","40.63588"
"762.30000","1.01641","40.63845"
"763.00000","1.01734","40.63322"
"763.70000","1.01828","40.63611"
"764.40000","1.01922","40.63689"
"765.10000","1.02015","40.63117"
"765.80000","1.02106","40.62869"
"766.50000","1.02200","40.63237"
"767.20000","1.02293","40.63460"
"767.90000","1.02385","40.63009"
"768.60000","1.02480","40.62342"
"769.30000","1.02573","40.62431"
"770.00000","1.02667","40.63724"
"770.70000","1.02760","40.62177"
"771.40000","1.02854","40.62651"
"772.10000","1.02948","40.62498"
"772.80000","1.03042","40.62637"
"773.50000","1.03134","40.61654"
"774.20000","1.03227","40.61249"
"774.90000","1.03320","40.61789"
"775.60000","1.03412","40.60078"
"776.30000","1.03506","40.60875"
"777.00000","1.03600","40.60132"
"777.70000","1.03694","40.60907"
"778.40000","1.03786","40.60887"
"779.10000","1.03881","40.60631"
"779.80000","1.03975","40.60556"
"780.50000","1.04068","40.60113"
"781.20000","1.04161","40.59051"
"781.90000","1.04254","40.59790"
"782.60000","1.04347","40.58535"
"783.30000","1.04439","40.57981"
"784.00000","1.04533","40.58097"
"784.70000","1.04626","40.58617"
"785.40000","1.04720","40.58230"
"786.10000","1.04812","40.57346"
"786.80000","1.04907","40.58277"
"787.50000","1.05001","40.61792"
"788.20000","1.05095","40.55942"
"788.90000","1.05187","40.56280"
"789.60000","1.05281","40.55192"
"790.30000","1.05374","40.55836"
"791.00000","1.05466","40.55478"
"791.70000","1.05560","40.54752"
"792.40000","1.05653","40.55128"
"793.10000","1.05746","40.55316"
"793.80000","1.05839","40.55143"
"794.50000","1.05933","40.55604"
"795.20000","1.06027","40.56320"
"795.90000","1.06122","40.56751"
"796.60000","1.06214","40.55528"
"797.30000","1.06308","40.55086"
"798.00000","1.06401","40.55611"
"798.70000","1.06494","40.55924"
"799.40000","1.06587","40.55543"
"800.10000","1.06679","40.55627"
"800.80000","1.06773","40.55361"
"801.50000","1.06865","40.55496"
"802.20000","1.06960","40.56385"
"802.90000","1.07054","40.55395"
"803.60000","1.07148","40.56290"
"804.30000","1.07240","40.56292"
"805.00000","1.07334","40.56087"
"805.70000","1.07428","40.55950"
"806.40000","1.07521","40.55439"
"807.10000","1.07613","40.56288"
"807.80000","1.07707","40.56382"
"808.50000","1.07799","40.55779"
"809.20000","1.07892","40.56450"
"809.90000","1.07987","40.56534"
"810.60000","1.08080","40.56621"
"811.30000","1.08174","40.57259"
"812.00000","1.08267","40.57143"
"812.70000","1.08361","40.57936"
"813.40000","1.08455","40.57660"
"814.10000","1.08548","40.56963"
"814.80000","1.08640","40.58388"
"815.50000","1.08734","40.57862"
"816.20000","1.08827","40.57503"
"816.90000","1.08919","40.57573"
"817.60000","1.09013","40.57650"
"818.30000","1.09107","40.58734"
"819.00000","1.09200","40.58662"
"819.70000","1.09293","40.57780"
"820.40000","1.09387","40.58026"
"821.10000","1.09481","40.59301"
"821.80000","1.09575","40.59071"
"822.50000","1.09667","40.57645"
"823.20000","1.09761","40.58071"
"823.90000","1.09853","40.57975"
"824.60000","1.09946","40.57470"
"825.30000","1.10039","40.57175"
"826.00000","1.10133","40.57363"
"826.70000","1.10226","40.58461"
"827.40000","1.10319","40.57517"
"828.10000","1.10413","40.56599"
"828.80000","1.10508","40.57480"
"829.50000","1.10602","40.57791"
"830.20000","1.10694","40.56082"
"830.90000","1.10788","40.57163"
"831.60000","1.10881","40.55236"
"832.30000","1.10973","40.53820"
"833.00000","1.11066","40.52723"
"833.70000","1.11159","40.53632"
"834.40000","1.11253","40.53740"
"835.10000","1.11346","40.52598"
"835.80000","1.11440","40.53196"
"836.50000","1.11534","40.52946"
"837.20000","1.11628","40.53267"
"837.90000","1.11720","40.50967"
"838.60000","1.11814","40.50875"
"839.30000","1.11908","40.50493"
"840.00000","1.12000","40.49080"
"840.70000","1.12093","40.48797"
"841.40000","1.12186","40.48555"
"842.10000","1.12280","40.48019"
"842.80000","1.12372","40.45890"
"843.50000","1.12466","40.47026"
"844.20000","1.12560","40.47508"
"844.90000","1.12654","40.47258"
"845.60000","1.12747","40.45799"
"846.30000","1.12841","40.45479"
"847.00000","1.12935","40.44993"
"847.70000","1.13028","40.44658"
"848.40000","1.13120","40.42522"
"849.10000","1.13214","40.42094"
"849.80000","1.13306","40.42600"
"850.50000","1.13399","40.41354"
"851.20000","1.13493","40.41507"
"851.90000","1.13587","40.40524"
"852.60000","1.13681","40.40621"
"853.30000","1.13773","40.39393"
"854.00000","1.13868","40.39078"
"854.70000","1.13962","40.39513"
"855.40000","1.14055","40.38801"
"856.10000","1.14147","40.37966"
"856.80000","1.14240","40.37153"
"857.50000","1.14333","40.37933"
"858.20000","1.14426","40.37311"
"858.90000","1.14519","40.36785"
"859.60000","1.14613","40.36109"
"860.30000","1.14707","40.36346"
"861.00000","1.14800","40.36005"
"861.70000","1.14894","40.35956"
"862.40000","1.14988","40.35533"
"863.10000","1.15082","40.35352"
"863.80000","1.15174","40.35283"
"864.50000","1.15267","40.34829"
"865.20000","1.15360","40.33895"
"865.90000","1.15453","40.33197"
"866.60000","1.15546","40.33379"
"867.30000","1.15639","40.33448"
"868.00000","1.15733","40.33910"
"868.70000","1.15826","40.32979"
"869.40000","1.15920","40.33354"
"870.10000","1.16014","40.33171"
"870.80000","1.16108","40.33390"
"871.50000","1.16201","40.32298"
"872.20000","1.16295","40.33207"
"872.90000","1.16387","40.31314"
"873.60000","1.16480","40.30561"
"874.30000","1.16573","40.31355"
"875.00000","1.16666","40.31178"
"875.70000","1.16759","40.31817"
"876.40000","1.16852","40.30145"
"877.10000","1.16947","40.32484"
"877.80000","1.17040","40.32939"
"878.50000","1.17135","40.31220"
"879.20000","1.17227","40.30812"
"879.90000","1.17321","40.31465"
"880.60000","1.17415","40.31400"
"881.30000","1.17507","40.30195"
"882.00000","1.17600","40.30999"
"882.70000","1.17693","40.30288"
"883.40000","1.17786","40.29801"
"884.10000","1.17879","40.29744"
"884.80000","1.17973","40.30295"
"885.50000","1.18067","40.31165"
"886.20000","1.18161","40.30243"
"886.90000","1.18254","40.28800"
"887.60000","1.18348","40.29590"
"888.30000","1.18441","40.28761"
"889.00000","1.18535","40.27528"
"889.70000","1.18627","40.27692"
"890.40000","1.18720","40.28964"
"891.10000","1.18813","40.26390"
"891.80000","1.18906","40.25915"
"892.50000","1.18999","40.27487"
"893.20000","1.19093","40.27093"
"893.90000","1.19187","40.27877"
"894.60000","1.19280","40.26914"
"895.30000","1.19374","40.27446"
"896.00000","1.19468","40.26999"
"896.70000","1.19562","40.25077"
"897.40000","1.19654","40.25022"
"898.10000","1.19747","40.25254"
"898.80000","1.19840","40.25211"
"899.50000","1.19933","40.24009"
"900.20000","1.20026","40.24336"
"900.90000","1.20119","40.24752"
"901.60000","1.20214","40.24522"
"902.30000","1.20306","40.24708"
"903.00000","1.20401","40.24420"
"903.70000","1.20495","40.23644"
"904.40000","1.20588","40.23594"
"905.10000","1.20681","40.23745"
"905.80000","1.20774","40.23436"
"906.50000","1.20867","40.21773"
"907.20000","1.20959","40.21898"
"907.90000","1.21053","40.22343"
"908.60000","1.21146","40.20944"
"909.30000","1.21240","40.21083"
"910.00000","1.21332","40.20556"
"910.70000","1.21427","40.20359"
"911.40000","1.21521","40.22252"
"912.10000","1.21615","40.21758"
"912.80000","1.21707","40.20206"
"913.50000","1.21801","40.19942"
"914.20000","1.21894","40.20098"
"914.90000","1.21987","40.19730"
"915.60000","1.22080","40.18607"
"916.30000","1.22173","40.17531"
"917.00000","1.22266","40.18889"
"917.70000","1.22359","40.18048"
"918.40000","1.22453","40.17746"
"919.10000","1.22547","40.18424"
"919.80000","1.22642","40.18451"
"920.50000","1.22734","40.17023"
"921.20000","1.22828","40.16979"
"921.90000","1.22921","40.16110"
"922.60000","1.23014","40.16226"
"923.30000","1.23106","40.16016"
"924.00000","1.23200","40.15991"
"924.70000","1.23293","40.14763"
"925.40000","1.23385","40.14470"
"926.10000","1.23480","40.14442"
"926.80000","1.23573","40.14128"
"927.50000","1.23667","40.15171"
"928.20000","1.23760","40.14171"
"928.90000","1.23854","40.14343"
"929.60000","1.23948","40.13315"
"930.30000","1.24042","40.12748"
"931.00000","1.24134","40.12572"
"931.70000","1.24227","40.11995"
"932.40000","1.24320","40.11247"
"933.10000","1.24412","40.10592"
"933.80000","1.24506","40.10818"
"934.50000","1.24600","40.11134"
"935.20000","1.24694","40.12379"
"935.90000","1.24786","40.10242"
"936.60000","1.24881","40.10388"
"937.30000","1.24975","40.10244"
"938.00000","1.25068","40.10528"
"938.70000","1.25161","40.09792"
"939.40000","1.25254","40.09492"
"940.10000","1.25347","40.09966"
"940.80000","1.25439","40.08913"
"941.50000","1.25533","40.08992"
"942.20000","1.25626","40.07987"
"942.90000","1.25720","40.09099"
"943.60000","1.25813","40.08413"
"944.30000","1.25907","40.08481"
"945.00000","1.26001","40.08923"
"945.70000","1.26095","40.07912"
"946.40000","1.26187","40.07608"
"947.10000","1.26281","40.07248"
"947.80000","1.26374","40.05995"
"948.50000","1.26466","40.05699"
"949.20000","1.26560","40.06870"
"949.90000","1.26653","40.05675"
"950.60000","1.26746","40.05432"
"951.30000","1.26839","40.05373"
"952.00000","1.26933","40.05674"
"952.70000","1.27027","40.05896"
"953.40000","1.27122","40.05906"
"954.10000","1.27214","40.04473"
"954.80000","1.27308","40.03996"
"955.50000","1.27401","40.04042"
"956.20000","1.27494","40.02950"
"956.90000","1.27586","40.03805"
"957.60000","1.27679","40.03143"
"958.30000","1.27773","40.04054"
"959.00000","1.27865","40.03582"
"959.70000","1.27960","40.03454"
"960.40000","1.28054","40.04177"
"961.10000","1.28148","40.04510"
"961.80000","1.28241","40.04265"
"962.50000","1.28335","40.03630"
"963.20000","1.28428","40.03098"
"963.90000","1.28521","40.03384"
"964.60000","1.28613","40.02248"
"965.30000","1.28706","40.02584"
"966.00000","1.28799","40.01518"
"966.70000","1.28892","40.01288"
"967.40000","1.28987","40.01485"
"968.10000","1.29080","40.01952"
"968.80000","1.29174","40.01103"
"969.50000","1.29267","40.00994"
"970.20000","1.29361","40.01691"
"970.90000","1.29455","40.00975"
"971.60000","1.29548","39.99750"
"972.30000","1.29640","40.00080"
"973.00000","1.29733","39.99235"
"973.70000","1.29826","39.98171"
"974.40000","1.29919","39.98688"
"975.10000","1.30013","39.98968"
"975.80000","1.30106","39.97560"
"976.50000","1.30200","39.98765"
"977.20000","1.30293","39.98135"
"977.90000","1.30388","39.97573"
"978.60000","1.30481","39.97709"
"979.30000","1.30575","39.96964"
"980.00000","1.30667","39.95571"
"980.70000","1.30761","39.96275"
"981.40000","1.30853","39.95130"
"982.10000","1.30946","39.94844"
"982.80000","1.31039","39.95159"
"983.50000","1.31133","39.95735"
"984.20000","1.31227","39.94554"
"984.90000","1.31319","39.94638"
"985.60000","1.31414","39.94916"
"986.30000","1.31508","39.95211"
"987.00000","1.31602","39.94755"
"987.70000","1.31694","39.94653"
"988.40000","1.31788","39.93706"
"989.10000","1.31881","39.93144"
"989.80000","1.31973","39.93158"
"990.50000","1.32066","39.93443"
"991.20000","1.32159","39.92121"
"991.90000","1.32253","39.92492"
"992.60000","1.32346","39.93343"
"993.30000","1.32440","39.92678"
"994.00000","1.32534","39.93549"
"994.70000","1.32628","39.94016"
"995.40000","1.32721","39.92440"
"996.10000","1.32814","39.93324"
"996.80000","1.32908","39.91589"
"997.50000","1.33000","39.91263"
"997.66100","1.33021","39.91344"