File: materials_lab1/ENGR314_FA19_0002_maplewood_A_20190903_NSJ.is_tens_RawData/Specimen_RawData_1.csv
Material,Acrylic
Geometry,Circular
Length,"2.00000",in
Diameter,"0.25500",in

Time,Extension,Load
(s),(in),(lbf)
"0.00000","0.00000","6.93853"
"0.19300","0.00023","12.70957"
"0.38500","0.00052","23.33798"
"0.58500","0.00077","32.04530"
"0.78500","0.00106","41.02748"
"0.98500","0.00133","49.70548"
"1.18500","0.00158","57.77952"
"1.38500","0.00185","67.02640"
"1.58500","0.00211","75.59745"
"1.78500","0.00238","84.80181"
"1.98500","0.00266","93.70512"
"2.18500","0.00293","101.86036"
"2.38500","0.00318","110.09511"
"2.58500","0.00345","118.15364"
"2.78500","0.00371","126.57942"
"2.98500","0.00398","134.94014"
"3.18500","0.00427","143.21142"
"3.38500","0.00452","150.44467"
"3.58500","0.00478","157.97513"
"3.78500","0.00505","165.40086"
"3.98500","0.00530","172.85775"
"4.18500","0.00559","180.88477"
"4.38500","0.00585","187.45685"
"4.58500","0.00613","194.53542"
"4.78500","0.00639","201.05311"
"4.98500","0.00663","207.13845"
"5.18500","0.00692","214.39215"
"5.38500","0.00718","220.41662"
"5.58500","0.00746","226.93963"
"5.78500","0.00773","232.96607"
"5.98500","0.00798","237.94408"
"6.18500","0.00825","244.06000"
"6.38500","0.00851","249.31310"
"6.58500","0.00879","255.25530"
"6.78500","0.00906","260.61512"
"6.98500","0.00933","265.36443"
"7.18500","0.00958","270.04966"
"7.38500","0.00984","274.45533"
"7.58500","0.01011","279.31793"
"7.78500","0.01038","283.82821"
"7.98500","0.01067","288.45210"
"8.18500","0.01092","291.90182"
"8.38500","0.01119","295.76383"
"8.58500","0.01145","299.54455"
"8.78500","0.01170","302.95209"
"8.98500","0.01200","307.30266"
"9.18500","0.01225","310.21842"
"9.38500","0.01253","313.65318"
"9.58500","0.01279","316.54139"
"9.78500","0.01304","319.21325"
"9.98500","0.01332","322.95808"
"10.18500","0.01358","325.79272"
"10.38500","0.01386","329.06950"
"10.58500","0.01413","331.71528"
"10.78500","0.01438","333.95651"
"10.98500","0.01465","336.89261"
"11.18500","0.01491","339.47794"
"11.38500","0.01519","342.48078"
"11.58500","0.01546","344.97056"
"11.78500","0.01573","347.26596"
"11.98500","0.01598","349.46292"
"12.18500","0.01625","351.61021"
"12.38500","0.01652","354.11854"
"12.58500","0.01678","355.81265"
"12.78500","0.01707","357.83162"
"12.98500","0.01732","358.64307"
"13.18500","0.01759","359.91758"
"13.38500","0.01785","361.27047"
"13.58500","0.01811","362.56361"
"13.78500","0.01839","364.64260"
"13.98500","0.01866","365.84853"
"14.18500","0.01893","367.58081"
"14.38500","0.01919","368.85069"
"14.58500","0.01944","369.85308"
"14.78500","0.01972","372.14469"
"14.98500","0.01998","373.41599"
"15.18500","0.02026","375.34221"
"15.38500","0.02053","376.55404"
"15.58500","0.02078","377.43651"
"15.78500","0.02105","379.15068"
"15.98500","0.02131","380.44649"
"16.18500","0.02159","382.35017"
"16.38500","0.02186","383.76310"
"16.58500","0.02212","384.39980"
"16.78500","0.02238","385.37579"
"16.98500","0.02265","386.06616"
"17.18500","0.02291","387.04898"
"17.38500","0.02319","388.18387"
"17.58500","0.02347","389.45119"
"17.78500","0.02372","390.11470"
"17.98500","0.02398","391.24785"
"18.18500","0.02425","392.26119"
"18.38500","0.02451","393.53011"
"18.58500","0.02480","395.66897"
"18.78500","0.02505","396.48890"
"18.98500","0.02533","398.15724"
"19.18500","0.02559","399.33321"
"19.38500","0.02584","400.34172"
"19.58500","0.02612","402.41055"
"19.78500","0.02638","403.25861"
"19.98500","0.02666","404.75222"
"20.18500","0.02693","405.58463"
"20.38500","0.02717","405.76114"
"20.58500","0.02745","407.16134"
"20.78500","0.02770","408.01173"
"20.98500","0.02799","409.59280"
"21.18500","0.02826","410.85919"
"21.38500","0.02853","411.59995"
"21.58500","0.02878","412.39965"
"21.78500","0.02904","413.39603"
"21.98500","0.02931","414.54535"
"22.18500","0.02958","415.91605"
"22.38500","0.02987","417.38998"
"22.58500","0.03011","417.62286"
"22.78500","0.03038","418.67369"
"22.98500","0.03065","419.52498"
"23.18500","0.03091","420.45764"
"23.38500","0.03120","422.22722"
"23.58500","0.03145","422.62368"
"23.78500","0.03172","423.72764"
"23.98500","0.03199","424.49133"
"24.18500","0.03224","425.01804"
"24.38500","0.03252","426.66901"
"24.58500","0.03278","427.33424"
"24.78500","0.03306","428.79885"
"24.98500","0.03333","429.52678"
"25.18500","0.03357","429.79457"
"25.38500","0.03385","431.13780"
"25.58500","0.03411","431.96683"
"25.78500","0.03439","433.21528"
"25.98500","0.03466","434.24324"
"26.18500","0.03492","434.78381"
"26.38500","0.03518","435.41754"
"26.58500","0.03544","436.15964"
"26.78500","0.03571","437.33483"
"26.98500","0.03598","438.38083"
"27.18500","0.03627","439.69920"
"27.38500","0.03652","439.83350"
"27.58500","0.03678","440.69563"
"27.78500","0.03705","441.52936"
"27.98500","0.03731","442.30195"
"28.18500","0.03760","443.94554"
"28.38500","0.03785","444.22938"
"28.58500","0.03813","445.20998"
"28.78500","0.03839","445.74308"
"28.98500","0.03863","446.10194"
"29.18500","0.03892","447.66773"
"29.38500","0.03918","448.31175"
"29.58500","0.03946","449.44403"
"29.78500","0.03973","450.05204"
"29.98500","0.03997","450.09469"
"30.18500","0.04025","451.17194"
"30.38500","0.04051","451.95213"
"30.58500","0.04079","453.10123"
"30.78500","0.04106","453.88450"
"30.98500","0.04133","454.38096"
"31.18500","0.04158","454.79622"
"31.38500","0.04184","455.36590"
"31.58500","0.04212","456.41695"
"31.78500","0.04238","457.24027"
"31.98500","0.04267","458.30760"
"32.18500","0.04292","458.41273"
"32.38500","0.04319","459.05060"
"32.58500","0.04345","459.70697"
"32.78500","0.04371","460.22358"
"32.98500","0.04400","461.80764"
"33.18500","0.04426","461.95610"
"33.38500","0.04453","462.73931"
"33.58500","0.04479","463.17460"
"33.78500","0.04504","463.47867"
"33.98500","0.04532","464.79788"
"34.18500","0.04558","465.28768"
"34.38500","0.04586","466.40354"
"34.58500","0.04613","466.77083"
"34.78500","0.04638","466.95799"
"34.98500","0.04665","467.97221"
"35.18500","0.04691","468.48187"
"35.38500","0.04719","469.68375"
"35.58500","0.04746","470.33029"
"35.78500","0.04772","470.65587"
"35.98500","0.04798","471.26043"
"36.18500","0.04824","471.92947"
"36.38500","0.04852","472.95890"
"36.58500","0.04879","473.86335"
"36.78500","0.04907","474.77093"
"36.98500","0.04932","475.03525"
"37.18500","0.04958","475.59640"
"37.38500","0.04985","476.17582"
"37.58500","0.05011","476.82900"
"37.78500","0.05040","478.16617"
"37.98500","0.05065","478.29635"
"38.18500","0.05093","478.97182"
"38.38500","0.05119","479.31409"
"38.58500","0.05144","479.58566"
"38.78500","0.05173","480.98918"
"38.98500","0.05198","481.20926"
"39.18500","0.05226","482.20619"
"39.38500","0.05253","482.59066"
"39.58500","0.05277","482.42508"
"39.78500","0.05305","483.52376"
"39.98500","0.05331","483.90028"
"40.18500","0.05359","485.04408"
"40.38500","0.05386","485.68031"
"40.58500","0.05412","485.59287"
"40.78500","0.05438","486.25402"
"40.98500","0.05464","486.55627"
"41.18500","0.05491","487.45924"
"41.38500","0.05519","488.30161"
"41.58500","0.05547","489.05540"
"41.78500","0.05572","488.90376"
"41.98500","0.05598","489.48071"
"42.18500","0.05625","489.86891"
"42.38500","0.05651","490.54943"
"42.58500","0.05680","491.95854"
"42.78500","0.05705","491.62336"
"42.98500","0.05733","492.41502"
"43.18500","0.05758","492.61563"
"43.38500","0.05784","492.88841"
"43.58500","0.05813","494.21783"
"43.78500","0.05838","494.37458"
"43.98500","0.05866","495.13084"
"44.18500","0.05893","495.51306"
"44.38500","0.05917","495.18968"
"44.58500","0.05945","496.11537"
"44.78500","0.05971","496.40143"
"44.98500","0.05999","497.31038"
"45.18500","0.06027","497.79908"
"45.38500","0.06052","497.64984"
"45.58500","0.06078","498.08113"
"45.78500","0.06104","498.33821"
"45.98500","0.06131","499.09947"
"46.18500","0.06159","499.71187"
"46.38500","0.06187","500.30458"
"46.58500","0.06212","500.18526"
"46.78500","0.06237","500.38350"
"46.98500","0.06265","500.98153"
"47.18500","0.06291","501.35903"
"47.38500","0.06320","502.59130"
"47.58500","0.06345","502.26342"
"47.78500","0.06373","502.79581"
"47.98500","0.06398","502.96183"
"48.18500","0.06424","503.00311"
"48.38500","0.06452","504.06579"
"48.58500","0.06478","504.09384"
"48.78500","0.06506","504.84395"
"48.98500","0.06533","504.84944"
"49.18500","0.06557","504.49658"
"49.38500","0.06585","505.44291"
"49.58500","0.06611","505.81366"
"49.78500","0.06639","506.60598"
"49.98500","0.06666","506.94407"
"50.18500","0.06692","506.72113"
"50.38500","0.06718","506.91141"
"50.58500","0.06744","507.39319"
"50.78500","0.06772","508.18985"
"50.98500","0.06799","508.78244"
"51.18500","0.06827","509.48821"
"51.38500","0.06852","509.36279"
"51.58500","0.06878","509.71576"
"51.78500","0.06905","510.15380"
"51.98500","0.06931","510.57559"
"52.18500","0.06960","511.81840"
"52.38500","0.06986","511.66143"
"52.58500","0.07013","512.18646"
"52.78500","0.07039","512.35090"
"52.98500","0.07063","512.24234"
"53.18500","0.07093","513.61402"
"53.38500","0.07119","513.68850"
"53.58500","0.07146","514.42906"
"53.78500","0.07173","514.48664"
"53.98500","0.07197","514.27264"
"54.18500","0.07225","515.10261"
"54.38500","0.07251","515.30591"
"54.58500","0.07279","516.13818"
"54.78500","0.07306","516.27512"
"54.98500","0.07332","516.17018"
"55.18500","0.07358","516.45448"
"55.38500","0.07384","516.50163"
"55.58500","0.07412","517.26261"
"55.78500","0.07438","517.59796"
"55.98500","0.07466","518.02595"
"56.18500","0.07492","517.93726"
"56.38500","0.07518","518.35032"
"56.58500","0.07545","518.78479"
"56.78500","0.07571","519.17047"
"56.98500","0.07600","520.11883"
"57.18500","0.07625","519.84566"
"57.38500","0.07653","520.37750"
"57.58500","0.07678","520.29660"
"57.78500","0.07704","520.34654"
"57.98500","0.07733","521.43738"
"58.18500","0.07758","521.35368"
"58.38500","0.07786","521.91005"
"58.58500","0.07813","521.83085"
"58.78500","0.07837","521.26071"
"58.98500","0.07865","522.01724"
"59.18500","0.07891","521.92701"
"59.38500","0.07919","522.63289"
"59.58500","0.07947","522.83327"
"59.78500","0.07972","522.24051"
"59.98500","0.07998","522.63695"
"60.18500","0.08024","522.61779"
"60.38500","0.08052","523.25210"
"60.58500","0.08079","523.62872"
"60.78500","0.08106","523.72208"
"60.98500","0.08132","523.50073"
"61.18500","0.08158","523.55847"
"61.38500","0.08184","523.73317"
"61.58500","0.08211","524.02675"
"61.78500","0.08240","524.98850"
"61.98500","0.08265","524.38910"
"62.18500","0.08293","524.75814"
"62.38500","0.08318","524.66994"
"62.58500","0.08343","524.56341"
"62.78500","0.08373","525.67917"
"62.98500","0.08398","525.20699"
"63.18500","0.08426","525.88389"
"63.38500","0.08453","525.68779"
"63.58500","0.08477","525.15935"
"63.78500","0.08505","525.97906"
"63.98500","0.08532","525.92763"
"64.18500","0.08559","526.46885"
"64.38500","0.08587","526.77303"
"64.58500","0.08612","526.13493"
"64.78500","0.08638","526.36051"
"64.98500","0.08664","526.33834"
"65.18500","0.08692","526.91172"
"65.38500","0.08719","527.29811"
"65.58500","0.08746","527.27550"
"65.78500","0.08772","526.91353"
"65.98500","0.08798","526.89147"
"66.18500","0.08825","527.12671"
"66.38500","0.08851","527.47018"
"66.58500","0.08880","528.29691"
"66.78500","0.08905","527.68999"
"66.98500","0.08932","527.82166"
"67.18500","0.08958","527.93203"
"67.38500","0.08983","527.65607"
"67.58500","0.09013","528.75410"
"67.78500","0.09038","528.45849"
"67.98500","0.09066","528.91749"
"68.18500","0.09093","528.59444"
"68.38500","0.09117","528.18626"
"68.58500","0.09145","528.80877"
"68.78500","0.09171","528.78566"
"68.98500","0.09199","529.43802"
"69.18500","0.09226","529.36497"
"69.38500","0.09252","529.02490"
"69.58500","0.09278","529.10668"
"69.78500","0.09304","529.30734"
"69.98500","0.09332","529.84494"
"70.18500","0.09359","530.20263"
"70.38500","0.09387","530.23912"
"70.58500","0.09412","529.81492"
"70.78500","0.09438","529.91053"
"70.98500","0.09465","530.21251"
"71.18500","0.09491","530.38550"
"71.38500","0.09520","531.20054"
"71.58500","0.09546","530.78786"
"71.78500","0.09573","530.98106"
"71.98500","0.09598","530.82563"
"72.18500","0.09623","530.59061"
"72.38500","0.09652","531.67431"
"72.58500","0.09679","531.54561"
"72.78500","0.09706","532.00834"
"72.98500","0.09733","531.84380"
"73.18500","0.09757","531.44017"
"73.38500","0.09785","532.47569"
"73.58500","0.09811","532.58321"
"73.78500","0.09839","533.35544"
"73.98500","0.09866","533.48458"
"74.18500","0.09892","533.23266"
"74.38500","0.09918","533.48447"
"74.58500","0.09944","533.60001"
"74.78500","0.09972","534.42323"
"74.98500","0.09999","534.69540"
"75.18500","0.10026","534.96302"
"75.38500","0.10052","534.73563"
"75.58500","0.10078","534.90885"
"75.78500","0.10105","535.33119"
"75.98500","0.10131","535.48800"
"76.18500","0.10160","536.34870"
"76.38500","0.10185","536.03460"
"76.58500","0.10213","536.38635"
"76.78500","0.10238","536.37307"
"76.98500","0.10264","536.43685"
"77.18500","0.10293","537.47769"
"77.38500","0.10319","537.30145"
"77.58500","0.10346","537.81880"
"77.78500","0.10373","537.69179"
"77.98500","0.10397","537.37181"
"78.18500","0.10425","538.15958"
"78.38500","0.10451","538.20447"
"78.58500","0.10479","538.86688"
"78.78500","0.10507","539.08916"
"78.98500","0.10532","538.55662"
"79.18500","0.10558","539.05964"
"79.38500","0.10584","538.96633"
"79.58500","0.10612","539.70574"
"79.78500","0.10639","540.07204"
"79.98500","0.10666","539.93604"
"80.18500","0.10692","539.96672"
"80.38500","0.10718","540.08631"
"80.58500","0.10744","540.56689"
"80.78500","0.10771","541.06903"
"80.98500","0.10800","541.95026"
"81.18500","0.10825","541.56964"
"81.38500","0.10852","542.02074"
"81.58500","0.10878","541.98803"
"81.78500","0.10903","541.83083"
"81.98500","0.10933","543.05351"
"82.18500","0.10958","542.77711"
"82.38500","0.10986","543.57942"
"82.58500","0.11013","543.64012"
"82.78500","0.11037","543.17897"
"82.98500","0.11065","544.28782"
"83.18500","0.11091","544.33633"
"83.38500","0.11119","545.32415"
"83.58500","0.11147","545.70517"
"83.78500","0.11171","545.34007"
"83.98500","0.11198","546.07449"
"84.18500","0.11224","546.50380"
"84.38500","0.11252","547.27987"
"84.58500","0.11280","548.08800"
"84.78500","0.11306","548.20441"
"84.98500","0.11332","548.25880"
"85.18500","0.11358","548.49294"
"85.38500","0.11384","548.92230"
"85.58500","0.11412","549.44618"
"85.78500","0.11440","550.26743"
"85.98500","0.11465","549.91353"
"86.18500","0.11492","550.33104"
"86.38500","0.11518","550.67500"
"86.58500","0.11544","550.94251"
"86.78500","0.11573","552.28599"
"86.98500","0.11598","552.17605"
"87.18500","0.11626","552.91854"
"87.38500","0.11653","553.19126"
"87.58500","0.11677","552.96102"
"87.78500","0.11705","554.10976"
"87.98500","0.11731","554.24527"
"88.18500","0.11759","555.13380"
"88.38500","0.11786","555.44808"
"88.58500","0.11812","555.34346"
"88.78500","0.11838","555.81471"
"88.98500","0.11864","556.18990"
"89.18500","0.11892","557.08958"
"89.38500","0.11919","557.56548"
"89.58500","0.11946","557.97937"
"89.78500","0.11972","557.96494"
"89.98500","0.11998","558.41582"
"90.18500","0.12025","559.03695"
"90.38500","0.12051","559.68662"
"90.58500","0.12080","560.67691"
"90.78500","0.12105","560.44058"
"90.98500","0.12132","560.89376"
"91.18500","0.12158","561.24810"
"91.38500","0.12183","561.32390"
"91.58500","0.12212","562.62368"
"91.78500","0.12239","562.80684"
"91.98500","0.12266","563.46414"
"92.18500","0.12292","563.58252"
"92.38500","0.12317","563.62978"
"92.58500","0.12345","564.75421"
"92.78500","0.12371","565.35619"
"92.98500","0.12400","566.21975"
"93.18500","0.12426","566.53259"
"93.38500","0.12452","566.53720"
"93.58500","0.12478","567.19956"
"93.78500","0.12504","567.60527"
"93.98500","0.12532","568.53771"
"94.18500","0.12559","569.12146"
"94.38500","0.12586","569.42355"
"94.58500","0.12612","569.61290"
"94.78500","0.12638","569.95352"
"94.98500","0.12665","570.60852"
"95.18500","0.12691","571.10078"
"95.38500","0.12720","572.08805"
"95.58500","0.12745","571.97224"
"95.78500","0.12772","572.52664"
"95.98500","0.12799","572.85353"
"96.18500","0.12824","572.97148"
"96.38500","0.12853","574.25305"
"96.58500","0.12879","574.33537"
"96.78500","0.12906","575.03077"
"96.98500","0.12932","575.10492"
"97.18500","0.12957","575.10343"
"97.38500","0.12985","576.21013"
"97.58500","0.13011","576.48341"
"97.78500","0.13040","577.38764"
"97.98500","0.13067","577.74428"
"98.18500","0.13091","577.41738"
"98.38500","0.13118","578.13276"
"98.58500","0.13144","578.43610"
"98.78500","0.13172","579.30658"
"98.98500","0.13199","579.95395"
"99.18500","0.13226","580.16295"
"99.38500","0.13252","580.47569"
"99.58500","0.13278","580.66251"
"99.78500","0.13305","581.48288"
"99.98500","0.13332","582.08277"
"100.18500","0.13360","582.91796"
"100.38500","0.13385","582.87959"
"100.58500","0.13412","583.29096"
"100.78500","0.13438","583.57652"
"100.98500","0.13464","583.95045"
"101.18500","0.13493","585.24525"
"101.38500","0.13518","584.95825"
"101.58500","0.13546","585.75288"
"101.78500","0.13572","585.85557"
"101.98500","0.13597","585.66380"
"102.18500","0.13625","586.84739"
"102.38500","0.13651","586.98219"
"102.58500","0.13680","587.96941"
"102.78500","0.13707","588.30690"
"102.98500","0.13732","587.98214"
"103.18500","0.13759","588.58791"
"103.38500","0.13784","588.81733"
"103.58500","0.13812","589.56217"
"103.78500","0.13840","590.11047"
"103.98500","0.13866","590.03358"
"104.18500","0.13892","590.12842"
"104.38500","0.13918","590.46437"
"104.58500","0.13944","590.84763"
"104.78500","0.13972","591.51317"
"104.98500","0.14000","592.22848"
"105.18500","0.14025","591.94819"
"105.38500","0.14052","592.29122"
"105.58500","0.14078","592.52848"
"105.78500","0.14104","592.73847"
"105.98500","0.14133","593.88387"
"106.18500","0.14159","593.77141"
"106.38500","0.14186","594.26581"
"106.58500","0.14212","594.46697"
"106.78500","0.14237","594.20797"
"106.98500","0.14266","595.26741"
"107.18500","0.14292","595.40473"
"107.38500","0.14320","596.24541"
"107.58500","0.14346","596.53031"
"107.78500","0.14372","596.28147"
"107.98500","0.14399","596.92593"
"108.18500","0.14424","597.10265"
"108.38500","0.14452","597.95079"
"108.58500","0.14479","598.42127"
"108.78500","0.14506","598.57977"
"108.98500","0.14532","598.54871"
"109.18500","0.14558","598.85865"
"109.38500","0.14585","599.50305"
"109.58500","0.14611","599.81310"
"109.78500","0.14640","600.76897"
"109.98500","0.14665","600.37056"
"110.18500","0.14692","600.72688"
"110.38500","0.14718","600.89872"
"110.58500","0.14744","601.21618"
"110.78500","0.14773","602.31338"
"110.98500","0.14799","602.15657"
"111.18500","0.14826","602.61415"
"111.38500","0.14852","602.61618"
"111.58500","0.14877","602.44351"
"111.78500","0.14905","603.37069"
"111.98500","0.14932","603.65203"
"112.18500","0.14960","604.34539"
"112.38500","0.14986","604.30132"
"112.58500","0.15011","604.10927"
"112.78500","0.15038","604.61861"
"112.98500","0.15064","604.85324"
"113.18500","0.15092","605.56065"
"113.38500","0.15119","605.80835"
"113.58500","0.15146","605.95001"
"113.78500","0.15172","605.85703"
"113.98500","0.15198","605.98832"
"114.18500","0.15225","606.43524"
"114.38500","0.15252","606.57932"
"114.58500","0.15280","607.14941"
"114.78500","0.15305","606.96329"
"114.98500","0.15332","607.07839"
"115.18500","0.15359","607.30479"
"115.38500","0.15384","607.32070"
"115.58500","0.15413","608.32647"
"115.78500","0.15439","608.16028"
"115.98500","0.15466","608.74063"
"116.18500","0.15492","608.61994"
"116.38500","0.15517","608.39810"
"116.58500","0.15545","609.31451"
"116.78500","0.15572","609.42928"
"116.98500","0.15600","609.97560"
"117.18500","0.15626","609.85990"
"117.38500","0.15651","609.49497"
"117.58500","0.15679","610.10019"
"117.78500","0.15704","609.98049"
"117.98500","0.15732","610.68049"
"118.18500","0.15760","611.01957"
"118.38500","0.15785","610.73477"
"118.58500","0.15812","610.92440"
"118.78500","0.15838","610.93806"
"118.98500","0.15864","611.40909"
"119.18500","0.15892","611.76277"
"119.38500","0.15920","612.37698"
"119.58500","0.15945","612.08302"
"119.78500","0.15972","612.16183"
"119.98500","0.15998","612.30119"
"120.18500","0.16024","612.38439"
"120.38500","0.16053","613.28879"
"120.58500","0.16079","612.59713"
"120.78500","0.16106","612.91442"
"120.98500","0.16132","612.81540"
"121.18500","0.16157","612.50640"
"121.38500","0.16186","613.42298"
"121.58500","0.16211","613.10295"
"121.78500","0.16240","613.72101"
"121.98500","0.16266","613.70306"
"122.18500","0.16291","612.99493"
"122.38500","0.16318","613.50213"
"122.58500","0.16344","613.43363"
"122.78500","0.16372","613.57392"
"122.98500","0.16400","613.90855"
"123.18500","0.16426","613.63939"
"123.38500","0.16452","613.49027"
"123.58500","0.16478","613.42880"
"123.78500","0.16505","613.79110"
"123.98500","0.16532","614.13956"
"124.18500","0.16560","614.51393"
"124.38500","0.16585","613.97748"
"124.58500","0.16612","614.06519"
"124.78500","0.16638","613.88050"
"124.98500","0.16664","614.12534"
"125.18500","0.16693","614.90674"
"125.38500","0.16719","614.31140"
"125.58500","0.16746","614.44110"
"125.78500","0.16772","614.04488"
"125.98500","0.16797","613.73522"
"126.18500","0.16826","611.24405"
"126.38500","0.16852","609.38548"
"126.58500","0.16880","611.17292"
"126.78500","0.16906","611.67665"
"126.98500","0.16931","610.97473"
"127.18500","0.16959","611.50552"
"127.38500","0.16984","611.41265"
"127.58500","0.17012","611.95909"
"127.78500","0.17040","612.04235"
"127.98500","0.17066","611.73845"
"128.18500","0.17092","611.64410"
"128.38500","0.17118","611.55722"
"128.58500","0.17145","612.06864"
"128.78500","0.17172","612.32665"
"128.98500","0.17200","612.85048"
"129.18500","0.17225","612.33456"
"129.38500","0.17252","612.51217"
"129.58500","0.17279","612.69987"
"129.78500","0.17304","612.57391"
"129.98500","0.17333","613.62353"
"130.18500","0.17359","613.20509"
"130.38500","0.17386","613.44867"
"130.58500","0.17412","613.27298"
"130.78500","0.17437","613.04493"
"130.98500","0.17465","613.82628"
"131.18500","0.17492","613.77518"
"131.38500","0.17520","614.15399"
"131.58500","0.17546","613.91964"
"131.78500","0.17571","613.51497"
"131.98500","0.17598","613.89510"
"132.18500","0.17624","614.05037"
"132.38500","0.17652","614.67337"
"132.58500","0.17680","614.81629"
"132.78500","0.17706","614.72666"
"132.98500","0.17731","614.61958"
"133.18500","0.17758","614.60899"
"133.38500","0.17785","615.13122"
"133.58500","0.17812","615.28495"
"133.78500","0.17840","615.91877"
"133.98500","0.17865","615.48210"
"134.18500","0.17892","615.55878"
"134.38500","0.17919","615.86728"
"134.58500","0.17944","615.93704"
"134.78500","0.17973","616.68908"
"134.98500","0.17999","616.53847"
"135.18500","0.18026","616.86778"
"135.38500","0.18052","616.69973"
"135.58500","0.18077","616.39369"
"135.78500","0.18105","617.26652"
"135.98500","0.18132","617.12371"
"136.18500","0.18160","617.85862"
"136.38500","0.18186","617.68206"
"136.58500","0.18211","617.27212"
"136.78500","0.18238","617.78952"
"136.98500","0.18264","617.95549"
"137.18500","0.18292","618.56592"
"137.38500","0.18320","618.77235"
"137.58500","0.18345","618.47827"
"137.78500","0.18372","618.80769"
"137.98500","0.18398","618.83870"
"138.18500","0.18425","619.46994"
"138.38500","0.18452","619.92877"
"138.58500","0.18480","620.19030"
"138.78500","0.18505","620.10550"
"138.98500","0.18531","620.21538"
"139.18500","0.18558","620.39705"
"139.38500","0.18584","620.77433"
"139.58500","0.18613","621.81649"
"139.78500","0.18639","621.55469"
"139.98500","0.18666","621.96605"
"140.18500","0.18692","621.97148"
"140.38500","0.18717","621.99794"
"140.58500","0.18746","623.15074"
"140.78500","0.18771","623.02143"
"140.98500","0.18800","623.83713"
"141.18500","0.18826","624.07061"
"141.38500","0.18850","623.71913"
"141.58500","0.18879","624.60344"
"141.78500","0.18904","624.66859"
"141.98500","0.18932","625.62161"
"142.18500","0.18960","626.04324"
"142.38500","0.18986","625.87875"
"142.58500","0.19011","626.15185"
"142.78500","0.19038","626.43923"
"142.98500","0.19064","627.01849"
"143.18500","0.19092","627.69846"
"143.38500","0.19121","628.25230"
"143.58500","0.19145","627.93490"
"143.78500","0.19172","628.24698"
"143.98500","0.19198","628.54160"
"144.18500","0.19224","628.94341"
"144.38500","0.19253","629.99797"
"144.58500","0.19279","629.53639"
"144.78500","0.19306","629.94463"
"144.98500","0.19332","630.03903"
"145.18500","0.19357","630.04479"
"145.38500","0.19386","631.20254"
"145.58500","0.19412","631.15363"
"145.78500","0.19440","631.85852"
"145.98500","0.19466","631.89057"
"146.18500","0.19490","631.54650"
"146.38500","0.19519","632.44447"
"146.58500","0.19545","632.56890"
"146.78500","0.19572","633.34673"
"146.98500","0.19600","633.83636"
"147.18500","0.19626","633.54322"
"147.38500","0.19652","633.87895"
"147.58500","0.19678","634.10886"
"147.78500","0.19705","634.87308"
"147.98500","0.19732","635.43878"
"148.18500","0.19760","636.06063"
"148.38500","0.19785","635.83055"
"148.58500","0.19811","636.11979"
"148.78500","0.19838","636.64537"
"148.98500","0.19865","637.05152"
"149.18500","0.19893","638.20778"
"149.38500","0.19919","637.90449"
"149.58500","0.19946","638.41283"
"149.78500","0.19972","638.56162"
"149.98500","0.19997","638.59659"
"150.18500","0.20026","639.87639"
"150.38500","0.20052","639.99264"
"150.58500","0.20080","640.76004"
"150.78500","0.20106","640.96844"
"150.98500","0.20130","640.75521"
"151.18500","0.20158","641.68661"
"151.38500","0.20185","642.19155"
"151.58500","0.20212","643.01774"
"151.78500","0.20239","643.34326"
"151.98500","0.20266","643.31697"
"152.18500","0.20291","643.55330"
"152.38500","0.20318","643.86566"
"152.58500","0.20345","644.55474"
"152.78500","0.20372","645.07450"
"152.98500","0.20400","645.62263"
"153.18500","0.20425","645.33257"
"153.38500","0.20452","645.60584"
"153.58500","0.20479","646.02609"
"153.78500","0.20504","646.21177"
"153.98500","0.20533","647.40859"
"154.18500","0.20559","647.06040"
"154.38500","0.20586","647.33049"
"154.58500","0.20612","647.54394"
"154.78500","0.20637","647.59827"
"154.98500","0.20666","648.61727"
"155.18500","0.20692","648.81826"
"155.38500","0.20720","649.51530"
"155.58500","0.20746","649.43720"
"155.78500","0.20771","649.36870"
"155.98500","0.20799","650.19927"
"156.18500","0.20824","650.42095"
"156.38500","0.20853","651.41827"
"156.58500","0.20879","651.66300"
"156.78500","0.20905","651.56097"
"156.98500","0.20931","651.84665"
"157.18500","0.20958","652.20955"
"157.38500","0.20985","652.86328"
"157.58500","0.21012","653.40631"
"157.78500","0.21040","653.46158"
"157.98500","0.21065","653.65483"
"158.18500","0.21091","653.96126"
"158.38500","0.21118","654.38788"
"158.58500","0.21145","654.86801"
"158.78500","0.21173","655.84019"
"158.98500","0.21199","655.80182"
"159.18500","0.21226","655.60358"
"159.38500","0.21251","655.86286"
"159.58500","0.21277","655.76071"
"159.76700","0.21304","650.28314"
"159.96700","0.21330","646.97681"
"160.16700","0.21357","648.88824"
"160.36700","0.21384","644.20797"
"160.56700","0.21408","645.41561"
"160.76700","0.21436","647.78428"
"160.96700","0.21462","648.25854"
"161.16700","0.21490","649.10476"
"161.36700","0.21517","649.57430"
"161.56700","0.21542","649.22320"
"161.76700","0.21569","650.02183"
"161.96700","0.21595","649.82891"
"162.16700","0.21623","650.79445"
"162.36700","0.21650","651.63095"
"162.56700","0.21677","651.76613"
"162.76700","0.21703","652.00526"
"162.96700","0.21728","652.31004"
"163.16700","0.21755","652.52036"
"163.36700","0.21783","653.39830"
"163.56700","0.21811","654.33864"
"163.76700","0.21836","653.98288"
"163.96700","0.21863","654.61131"
"164.16700","0.21889","655.02871"
"164.36700","0.21915","655.57970"
"164.56700","0.21944","656.97296"
"164.76700","0.21969","656.86187"
"164.96700","0.21997","657.53218"
"165.16700","0.22023","657.79294"
"165.36700","0.22048","657.81577"
"165.56700","0.22076","658.97226"
"165.76700","0.22103","659.21331"
"165.96700","0.22130","660.22028"
"166.16700","0.22157","660.58538"
"166.36700","0.22182","660.35596"
"166.56700","0.22209","661.02956"
"166.76700","0.22235","661.30596"
"166.96700","0.22263","661.67007"
"167.16700","0.22290","662.06898"
"167.36700","0.22317","662.19411"
"167.56700","0.22343","662.74049"
"167.76700","0.22368","663.05449"
"167.96700","0.22396","663.92744"
"168.16700","0.22423","664.56125"
"168.36700","0.22451","665.48101"
"168.56700","0.22476","665.20543"
"168.76700","0.22503","665.69435"
"168.96700","0.22529","666.19913"
"169.16700","0.22555","666.52849"
"169.36700","0.22584","667.65824"
"169.56700","0.22610","667.32295"
"169.76700","0.22637","667.95528"
"169.96700","0.22663","668.09474"
"170.16700","0.22688","668.00215"
"170.36700","0.22716","669.17763"
"170.56700","0.22743","669.48696"
"170.76700","0.22771","670.35601"
"170.96700","0.22797","670.59135"
"171.16700","0.22822","670.40842"
"171.36700","0.22849","671.16369"
"171.56700","0.22876","671.70870"
"171.76700","0.22903","672.31342"
"171.96700","0.22930","672.13318"
"172.16700","0.22957","671.25645"
"172.36700","0.22983","671.33691"
"172.56700","0.23009","671.35151"
"172.76700","0.23036","672.03823"
"172.96700","0.23063","672.73670"
"173.16700","0.23091","673.74708"
"173.36700","0.23116","673.75580"
"173.56700","0.23143","674.34263"
"173.76700","0.23170","674.77869"
"173.96700","0.23195","674.96860"
"174.16700","0.23224","676.43874"
"174.36700","0.23250","676.43084"
"174.56700","0.23277","677.01910"
"174.76700","0.23303","677.34506"
"174.96700","0.23328","677.52558"
"175.16700","0.23356","678.55050"
"175.36700","0.23383","678.92514"
"175.56700","0.23410","679.79008"
"175.76700","0.23437","679.91785"
"175.96700","0.23462","679.88744"
"176.16700","0.23489","680.68767"
"176.36700","0.23515","681.00529"
"176.56700","0.23543","681.96824"
"176.76700","0.23570","682.36561"
"176.96700","0.23597","682.23723"
"177.16700","0.23622","682.46067"
"177.36700","0.23649","682.89739"
"177.56700","0.23676","683.58653"
"177.76700","0.23703","684.13280"
"177.96700","0.23731","684.62632"
"178.16700","0.23756","684.33269"
"178.36700","0.23783","684.71858"
"178.56700","0.23809","684.97775"
"178.76700","0.23835","685.39307"
"178.96700","0.23864","686.48896"
"179.16700","0.23890","686.52584"
"179.36700","0.23917","687.08446"
"179.56700","0.23943","687.27968"
"179.76700","0.23968","687.53172"
"179.96700","0.23997","688.69138"
"180.16700","0.24023","688.85955"
"180.36700","0.24051","689.69528"
"180.56700","0.24078","689.94078"
"180.76700","0.24102","689.69265"
"180.96700","0.24129","690.54962"
"181.16700","0.24155","690.75758"
"181.36700","0.24183","691.58333"
"181.56700","0.24210","692.12548"
"181.76700","0.24236","691.91489"
"181.96700","0.24263","692.32702"
"182.16700","0.24288","692.40440"
"182.36700","0.24316","692.99003"
"182.56700","0.24343","693.13009"
"182.76700","0.24371","692.97032"
"182.96700","0.24396","692.26006"
"183.16700","0.24423","692.68679"
"183.36700","0.24449","692.93339"
"183.56700","0.24475","693.26818"
"183.76700","0.24505","694.42253"
"183.96700","0.24529","693.98120"
"184.16700","0.24557","694.55601"
"184.36700","0.24583","694.53559"
"184.56700","0.24608","694.76353"
"184.76700","0.24637","695.85124"
"184.96700","0.24663","695.91172"
"185.16700","0.24690","696.49164"
"185.36700","0.24717","696.80772"
"185.56700","0.24742","696.46353"
"185.76700","0.24769","697.30311"
"185.96700","0.24795","697.60761"
"186.16700","0.24823","698.44214"
"186.36700","0.24851","698.85756"
"186.56700","0.24877","698.60235"
"186.76700","0.24903","698.58605"
"186.96700","0.24928","698.57233"
"187.16700","0.24955","699.20361"
"187.36700","0.24983","699.76026"
"187.56700","0.25011","700.25450"
"187.76700","0.25036","700.10016"
"187.96700","0.25062","700.34099"
"188.16700","0.25089","700.75115"
"188.36700","0.25115","701.15697"
"188.56700","0.25145","702.32289"
"188.76700","0.25169","701.97294"
"188.96700","0.25197","702.48661"
"189.16700","0.25223","702.54786"
"189.36700","0.25248","702.60352"
"189.56700","0.25276","703.57668"
"189.76700","0.25303","703.52592"
"189.96700","0.25331","703.85473"
"190.16700","0.25357","703.82718"
"190.36700","0.25382","703.41422"
"190.46700","0.25398","704.65929"