File: materials_lab1/ENGR314_FA19_0001_acrylic_B_20190906_MA.is_tens_RawData/Specimen_RawData_1.csv
Material,Acrylic
Geometry,Circular
Length,"2.00000",in
Diameter,"0.12800",in

Time,Extension,Load
(s),(in),(lbf)
"0.00000","0.34539","-2.86032"
"0.20000","0.34561","-2.50721"
"0.40000","0.34592","-1.73272"
"0.60000","0.34620","-1.09788"
"0.80000","0.34647","-0.52216"
"1.00000","0.34672","0.05933"
"1.20000","0.34699","0.65696"
"1.40000","0.34725","1.25211"
"1.60000","0.34752","1.87810"
"1.80000","0.34781","2.49773"
"2.00000","0.34806","3.01108"
"2.20000","0.34833","3.59540"
"2.40000","0.34859","4.15949"
"2.60000","0.34885","4.73408"
"2.80000","0.34913","5.36904"
"3.00000","0.34939","5.88380"
"3.20000","0.34967","6.45752"
"3.40000","0.34993","7.00214"
"3.60000","0.35018","7.54005"
"3.80000","0.35046","8.15264"
"4.00000","0.35072","8.69872"
"4.20000","0.35100","9.27049"
"4.40000","0.35127","9.81597"
"4.60000","0.35152","10.30427"
"4.80000","0.35179","10.87274"
"5.00000","0.35205","11.41513"
"5.20000","0.35232","11.99759"
"5.40000","0.35260","12.56147"
"5.60000","0.35287","13.07596"
"5.80000","0.35312","13.61289"
"6.00000","0.35338","14.12581"
"6.20000","0.35366","14.68126"
"6.40000","0.35392","15.22651"
"6.60000","0.35421","15.79942"
"6.80000","0.35446","16.26599"
"7.00000","0.35472","16.79902"
"7.20000","0.35499","17.30393"
"7.40000","0.35525","17.84626"
"7.60000","0.35553","18.43830"
"7.80000","0.35579","18.92773"
"8.00000","0.35607","19.45785"
"8.20000","0.35633","19.96161"
"8.40000","0.35657","20.44247"
"8.60000","0.35686","21.00533"
"8.80000","0.35712","21.51086"
"9.00000","0.35740","22.03776"
"9.20000","0.35767","22.54007"
"9.40000","0.35792","22.99813"
"9.60000","0.35819","23.52668"
"9.80000","0.35845","24.01549"
"10.00000","0.35873","24.55783"
"10.20000","0.35900","25.07600"
"10.40000","0.35927","25.55266"
"10.60000","0.35952","26.04706"
"10.80000","0.35979","26.52988"
"11.00000","0.36006","27.02877"
"11.20000","0.36032","27.54022"
"11.40000","0.36061","28.04973"
"11.60000","0.36086","28.50846"
"11.80000","0.36113","28.99753"
"12.00000","0.36139","29.50110"
"12.20000","0.36165","29.96814"
"12.40000","0.36193","30.51279"
"12.60000","0.36219","30.95962"
"12.80000","0.36247","31.44767"
"13.00000","0.36273","31.91151"
"13.20000","0.36298","32.37416"
"13.40000","0.36326","32.89603"
"13.60000","0.36352","33.34963"
"13.80000","0.36380","33.85933"
"14.00000","0.36407","34.31146"
"14.20000","0.36432","34.74827"
"14.40000","0.36459","35.23359"
"14.60000","0.36485","35.69699"
"14.80000","0.36513","36.19776"
"15.00000","0.36540","36.69289"
"15.20000","0.36567","37.12830"
"15.40000","0.36592","37.58218"
"15.60000","0.36618","38.04578"
"15.80000","0.36646","38.51658"
"16.00000","0.36672","38.99494"
"16.20000","0.36701","39.45120"
"16.40000","0.36726","39.88882"
"16.60000","0.36752","40.33025"
"16.80000","0.36779","40.78470"
"17.00000","0.36805","41.23292"
"17.20000","0.36834","41.73220"
"17.40000","0.36859","42.14346"
"17.60000","0.36887","42.59541"
"17.80000","0.36913","43.03828"
"18.00000","0.36938","43.45740"
"18.20000","0.36966","43.94561"
"18.40000","0.36992","44.36705"
"18.60000","0.37020","44.84041"
"18.80000","0.37047","45.26034"
"19.00000","0.37071","45.63372"
"19.20000","0.37099","46.11622"
"19.40000","0.37125","46.53170"
"19.60000","0.37153","47.00936"
"19.80000","0.37180","47.44461"
"20.00000","0.37207","47.82993"
"20.20000","0.37233","48.26801"
"20.40000","0.37258","48.68300"
"20.60000","0.37286","49.13655"
"20.80000","0.37313","49.58604"
"21.00000","0.37341","50.03170"
"21.20000","0.37366","50.41993"
"21.40000","0.37393","50.83136"
"21.60000","0.37419","51.24231"
"21.80000","0.37445","51.66577"
"22.00000","0.37474","52.11936"
"22.20000","0.37499","52.48387"
"22.40000","0.37527","52.91229"
"22.60000","0.37553","53.31378"
"22.80000","0.37578","53.72236"
"23.00000","0.37606","54.18595"
"23.20000","0.37632","54.56525"
"23.40000","0.37660","54.99554"
"23.60000","0.37687","55.40189"
"23.80000","0.37712","55.74901"
"24.00000","0.37739","56.18684"
"24.20000","0.37765","56.58440"
"24.40000","0.37793","57.01761"
"24.60000","0.37820","57.42205"
"24.80000","0.37846","57.80093"
"25.00000","0.37872","58.18331"
"25.20000","0.37898","58.57420"
"25.40000","0.37925","58.98396"
"25.60000","0.37953","59.39077"
"25.80000","0.37981","59.80016"
"26.00000","0.38006","60.16275"
"26.20000","0.38032","60.55164"
"26.40000","0.38059","60.95314"
"26.60000","0.38085","61.33464"
"26.80000","0.38114","61.77433"
"27.00000","0.38139","62.12297"
"27.20000","0.38167","62.50580"
"27.40000","0.38193","62.87621"
"27.60000","0.38218","63.23770"
"27.80000","0.38246","63.66853"
"28.00000","0.38272","64.01565"
"28.20000","0.38300","64.42229"
"28.40000","0.38327","64.79319"
"28.60000","0.38352","65.11388"
"28.80000","0.38379","65.53074"
"29.00000","0.38405","65.88820"
"29.20000","0.38433","66.28722"
"29.40000","0.38460","66.67702"
"29.60000","0.38486","67.02137"
"29.80000","0.38512","67.39087"
"30.00000","0.38538","67.74649"
"30.20000","0.38566","68.12635"
"30.40000","0.38593","68.50139"
"30.60000","0.38621","68.87153"
"30.80000","0.38646","69.20267"
"31.00000","0.38673","69.55826"
"31.20000","0.38699","69.92654"
"31.40000","0.38725","70.28699"
"31.60000","0.38754","70.69532"
"31.80000","0.38779","71.02321"
"32.00000","0.38807","71.39334"
"32.20000","0.38833","71.73310"
"32.40000","0.38857","72.04685"
"32.60000","0.38886","72.45705"
"32.80000","0.38913","72.78848"
"33.00000","0.38940","73.15010"
"33.20000","0.38967","73.49279"
"33.40000","0.38992","73.80888"
"33.60000","0.39019","74.19066"
"33.80000","0.39045","74.52489"
"34.00000","0.39073","74.89135"
"34.20000","0.39100","75.22967"
"34.40000","0.39126","75.52783"
"34.60000","0.39152","75.87326"
"34.80000","0.39178","76.19376"
"35.00000","0.39206","76.54833"
"35.20000","0.39233","76.88983"
"35.40000","0.39261","77.22770"
"35.60000","0.39286","77.53026"
"35.80000","0.39313","77.87257"
"36.00000","0.39339","78.21165"
"36.20000","0.39365","78.53847"
"36.40000","0.39394","78.90439"
"36.60000","0.39419","79.19976"
"36.80000","0.39447","79.52670"
"37.00000","0.39473","79.83072"
"37.20000","0.39498","80.13881"
"37.40000","0.39526","80.49083"
"37.60000","0.39553","80.79579"
"37.80000","0.39580","81.14585"
"38.00000","0.39607","81.45019"
"38.20000","0.39631","81.71045"
"38.40000","0.39659","82.06591"
"38.60000","0.39685","82.36301"
"38.80000","0.39713","82.70696"
"39.00000","0.39740","83.02824"
"39.20000","0.39766","83.28987"
"39.40000","0.39793","83.60664"
"39.60000","0.39818","83.90780"
"39.80000","0.39846","84.23761"
"40.00000","0.39873","84.56247"
"40.20000","0.39901","84.87772"
"40.40000","0.39926","85.15138"
"40.60000","0.39952","85.44468"
"40.80000","0.39979","85.74417"
"41.00000","0.40005","86.04629"
"41.20000","0.40034","86.40255"
"41.40000","0.40059","86.63746"
"41.60000","0.40087","86.93188"
"41.80000","0.40113","87.21604"
"42.00000","0.40137","87.49922"
"42.20000","0.40166","87.82419"
"42.40000","0.40192","88.08787"
"42.60000","0.40220","88.40095"
"42.80000","0.40247","88.68370"
"43.00000","0.40271","88.91863"
"43.20000","0.40299","89.23148"
"43.40000","0.40325","89.51861"
"43.60000","0.40353","89.80531"
"43.80000","0.40380","90.08746"
"44.00000","0.40406","90.33071"
"44.20000","0.40432","90.61674"
"44.40000","0.40458","90.89980"
"44.60000","0.40486","91.19158"
"44.80000","0.40513","91.48901"
"45.00000","0.40541","91.76685"
"45.20000","0.40566","91.99747"
"45.40000","0.40592","92.27244"
"45.60000","0.40618","92.54290"
"45.80000","0.40645","92.80515"
"46.00000","0.40674","93.11285"
"46.20000","0.40699","93.33279"
"46.40000","0.40726","93.58617"
"46.60000","0.40753","93.84588"
"46.80000","0.40777","94.07444"
"47.00000","0.40807","94.39040"
"47.20000","0.40832","94.63291"
"47.40000","0.40860","94.90410"
"47.60000","0.40887","95.14147"
"47.80000","0.40911","95.36481"
"48.00000","0.40939","95.64283"
"48.20000","0.40965","95.88648"
"48.40000","0.40993","96.16071"
"48.60000","0.41020","96.41135"
"48.80000","0.41046","96.62463"
"49.00000","0.41072","96.87038"
"49.20000","0.41098","97.10185"
"49.40000","0.41126","97.36985"
"49.60000","0.41153","97.62260"
"49.80000","0.41181","97.86557"
"50.00000","0.41206","98.07669"
"50.20000","0.41232","98.31585"
"50.40000","0.41259","98.55612"
"50.60000","0.41285","98.80582"
"50.80000","0.41314","99.07808"
"51.00000","0.41339","99.25770"
"51.20000","0.41367","99.49707"
"51.40000","0.41393","99.69542"
"51.60000","0.41417","99.91706"
"51.80000","0.41446","100.17795"
"52.00000","0.41473","100.39121"
"52.20000","0.41500","100.61967"
"52.40000","0.41527","100.84020"
"52.60000","0.41551","101.00653"
"52.80000","0.41579","101.25871"
"53.00000","0.41605","101.47329"
"53.20000","0.41633","101.71472"
"53.40000","0.41660","101.92380"
"53.60000","0.41686","102.11285"
"53.80000","0.41712","102.32811"
"54.00000","0.41738","102.54136"
"54.20000","0.41766","102.76808"
"54.40000","0.41793","102.98137"
"54.60000","0.41820","103.18090"
"54.80000","0.41846","103.37039"
"55.00000","0.41872","103.56902"
"55.20000","0.41899","103.77865"
"55.40000","0.41925","103.98458"
"55.60000","0.41954","104.21317"
"55.80000","0.41979","104.37680"
"56.00000","0.42007","104.57925"
"56.20000","0.42033","104.78109"
"56.40000","0.42058","104.95340"
"56.60000","0.42087","105.19154"
"56.80000","0.42113","105.35687"
"57.00000","0.42140","105.56659"
"57.20000","0.42167","105.73504"
"57.40000","0.42191","105.89442"
"57.60000","0.42219","106.10871"
"57.80000","0.42245","106.27857"
"58.00000","0.42273","106.47957"
"58.20000","0.42300","106.66766"
"58.40000","0.42326","106.80037"
"58.60000","0.42352","107.00484"
"58.80000","0.42378","107.17636"
"59.00000","0.42406","107.37262"
"59.20000","0.42433","107.56396"
"59.40000","0.42460","107.71859"
"59.60000","0.42486","107.88020"
"59.80000","0.42512","108.04388"
"60.00000","0.42538","108.22616"
"60.20000","0.42565","108.38785"
"60.40000","0.42594","108.59791"
"60.60000","0.42619","108.73879"
"60.80000","0.42646","108.90945"
"61.00000","0.42673","109.06031"
"61.20000","0.42697","109.20460"
"61.40000","0.42727","109.41242"
"61.60000","0.42752","109.54709"
"61.80000","0.42780","109.71324"
"62.00000","0.42807","109.85571"
"62.20000","0.42831","109.97488"
"62.40000","0.42859","110.16697"
"62.60000","0.42885","110.31136"
"62.80000","0.42913","110.48553"
"63.00000","0.42941","110.62952"
"63.20000","0.42966","110.73870"
"63.40000","0.42992","110.89823"
"63.60000","0.43018","111.04383"
"63.80000","0.43046","111.20733"
"64.00000","0.43073","111.36624"
"64.20000","0.43101","111.50323"
"64.40000","0.43126","111.61289"
"64.60000","0.43152","111.74799"
"64.80000","0.43179","111.89853"
"65.00000","0.43205","112.04748"
"65.20000","0.43234","112.20061"
"65.40000","0.43259","112.30643"
"65.60000","0.43286","112.44523"
"65.80000","0.43312","112.56577"
"66.00000","0.43338","112.68055"
"66.20000","0.43367","112.85227"
"66.40000","0.43393","112.97043"
"66.60000","0.43420","113.09178"
"66.80000","0.43447","113.21108"
"67.00000","0.43471","113.29011"
"67.20000","0.43499","113.44728"
"67.40000","0.43525","113.55768"
"67.60000","0.43553","113.69233"
"67.80000","0.43580","113.81680"
"68.00000","0.43606","113.89361"
"68.20000","0.43632","114.02372"
"68.40000","0.43658","114.12561"
"68.60000","0.43686","114.27440"
"68.80000","0.43713","114.38431"
"69.00000","0.43741","114.49100"
"69.20000","0.43766","114.58772"
"69.40000","0.43792","114.68795"
"69.60000","0.43819","114.79900"
"69.80000","0.43845","114.91814"
"70.00000","0.43874","115.05976"
"70.20000","0.43899","115.13528"
"70.40000","0.43926","115.24379"
"70.60000","0.43953","115.34406"
"70.80000","0.43977","115.43013"
"71.00000","0.44006","115.57754"
"71.20000","0.44033","115.65601"
"71.40000","0.44061","115.75703"
"71.60000","0.44086","115.84711"
"71.80000","0.44111","115.91207"
"72.00000","0.44139","116.04069"
"72.20000","0.44165","116.12912"
"72.40000","0.44193","116.23992"
"72.60000","0.44220","116.32468"
"72.80000","0.44246","116.39776"
"73.00000","0.44272","116.48093"
"73.20000","0.44298","116.55349"
"73.40000","0.44326","116.66050"
"73.60000","0.44353","116.75106"
"73.80000","0.44380","116.82945"
"74.00000","0.44406","116.89957"
"74.20000","0.44432","116.96306"
"74.40000","0.44459","117.06169"
"74.60000","0.44485","117.15022"
"74.80000","0.44514","117.24871"
"75.00000","0.44539","117.29772"
"75.20000","0.44566","117.37132"
"75.40000","0.44593","117.45038"
"75.60000","0.44618","117.49920"
"75.80000","0.44647","117.60421"
"76.00000","0.44673","117.66513"
"76.20000","0.44701","117.74060"
"76.40000","0.44727","117.79138"
"76.60000","0.44751","117.82599"
"76.80000","0.44779","117.92489"
"77.00000","0.44805","117.98499"
"77.20000","0.44833","118.07769"
"77.40000","0.44861","118.13526"
"77.60000","0.44885","118.16293"
"77.80000","0.44912","118.24259"
"78.00000","0.44939","118.28286"
"78.20000","0.44966","118.36950"
"78.40000","0.44993","118.44751"
"78.60000","0.45021","118.49674"
"78.80000","0.45046","118.54719"
"79.00000","0.45072","118.58735"
"79.20000","0.45099","118.65417"
"79.40000","0.45125","118.72532"
"79.60000","0.45154","118.79722"
"79.80000","0.45179","118.81710"
"80.00000","0.45206","118.86659"
"80.20000","0.45232","118.92002"
"80.40000","0.45258","118.96083"
"80.60000","0.45287","119.06143"
"80.80000","0.45312","119.07870"
"81.00000","0.45340","119.13159"
"81.20000","0.45367","119.17068"
"81.40000","0.45391","119.19492"
"81.60000","0.45419","119.27708"
"81.80000","0.45445","119.31344"
"82.00000","0.45473","119.38023"
"82.20000","0.45501","119.42630"
"82.40000","0.45526","119.42395"
"82.60000","0.45552","119.47350"
"82.80000","0.45578","119.51094"
"83.00000","0.45606","119.57118"
"83.20000","0.45634","119.62504"
"83.40000","0.45661","119.64422"
"83.60000","0.45686","119.66376"
"83.80000","0.45712","119.69237"
"84.00000","0.45739","119.73192"
"84.20000","0.45765","119.78186"
"84.40000","0.45794","119.84412"
"84.60000","0.45819","119.83826"
"84.80000","0.45846","119.86145"
"85.00000","0.45872","119.89989"
"85.20000","0.45898","119.91477"
"85.40000","0.45927","119.97928"
"85.60000","0.45953","119.99154"
"85.80000","0.45980","120.02026"
"86.00000","0.46006","120.05023"
"86.20000","0.46031","120.04364"
"86.40000","0.46060","120.10330"
"86.60000","0.46085","120.12270"
"86.80000","0.46114","120.17250"
"87.00000","0.46141","120.19176"
"87.20000","0.46166","120.18175"
"87.40000","0.46192","120.21606"
"87.60000","0.46218","120.21756"
"87.80000","0.46246","120.25739"
"88.00000","0.46273","120.30520"
"88.20000","0.46301","120.30664"
"88.40000","0.46325","120.31177"
"88.60000","0.46352","120.32486"
"88.80000","0.46379","120.35439"
"89.00000","0.46405","120.37245"
"89.20000","0.46434","120.41956"
"89.40000","0.46460","120.40103"
"89.60000","0.46486","120.40512"
"89.80000","0.46512","120.41469"
"90.00000","0.46538","120.41903"
"90.20000","0.46567","120.46815"
"90.40000","0.46593","120.45849"
"90.60000","0.46620","120.47608"
"90.80000","0.46646","120.47732"
"91.00000","0.46671","120.44799"
"91.20000","0.46699","120.49481"
"91.40000","0.46725","120.50178"
"91.60000","0.46753","120.52415"
"91.80000","0.46780","120.51482"
"92.00000","0.46805","120.49340"
"92.20000","0.46832","120.50807"
"92.40000","0.46858","120.51420"
"92.60000","0.46886","120.54964"
"92.80000","0.46913","120.55354"
"93.00000","0.46941","120.54562"
"93.20000","0.46966","120.53485"
"93.40000","0.46992","120.52375"
"93.60000","0.47019","120.54794"
"93.80000","0.47045","120.55575"
"94.00000","0.47074","120.56849"
"94.20000","0.47099","120.55328"
"94.40000","0.47126","120.54975"
"94.60000","0.47153","120.54388"
"94.80000","0.47178","120.53448"
"95.00000","0.47207","120.57511"
"95.20000","0.47232","120.54112"
"95.40000","0.47260","120.55125"
"95.60000","0.47286","120.54373"
"95.80000","0.47311","120.50121"
"96.00000","0.47339","120.55012"
"96.20000","0.47365","120.53047"
"96.40000","0.47393","120.54679"
"96.60000","0.47421","120.53965"
"96.80000","0.47445","120.48665"
"97.00000","0.47472","120.50450"
"97.20000","0.47498","120.48093"
"97.40000","0.47526","120.50730"
"97.60000","0.47553","120.51169"
"97.80000","0.47580","120.47029"
"98.00000","0.47606","120.46543"
"98.20000","0.47632","120.44843"
"98.40000","0.47659","120.44655"
"98.60000","0.47685","120.45684"
"98.80000","0.47714","120.46215"
"99.00000","0.47739","120.43471"
"99.20000","0.47766","120.41277"
"99.40000","0.47792","120.39506"
"99.60000","0.47818","120.38515"
"99.80000","0.47847","120.42050"
"100.00000","0.47872","120.38743"
"100.20000","0.47900","120.37887"
"100.40000","0.47926","120.35874"
"100.60000","0.47951","120.31988"
"100.80000","0.47980","120.33825"
"101.00000","0.48005","120.31325"
"101.20000","0.48033","120.32018"
"101.40000","0.48061","120.30109"
"101.60000","0.48085","120.25332"
"101.80000","0.48112","120.25050"
"102.00000","0.48138","120.23247"
"102.20000","0.48166","120.25324"
"102.40000","0.48194","120.24246"
"102.60000","0.48221","120.20957"
"102.80000","0.48245","120.17118"
"103.00000","0.48272","120.14624"
"103.20000","0.48299","120.14854"
"103.40000","0.48326","120.14835"
"103.60000","0.48354","120.15284"
"103.80000","0.48379","120.09926"
"104.00000","0.48406","120.08208"
"104.20000","0.48432","120.05203"
"104.40000","0.48458","120.02972"
"104.60000","0.48487","120.05930"
"104.80000","0.48513","120.00655"
"105.00000","0.48540","119.99571"
"105.20000","0.48566","119.97405"
"105.40000","0.48591","119.92704"
"105.60000","0.48619","119.94145"
"105.80000","0.48645","119.91273"
"106.00000","0.48673","119.91827"
"106.20000","0.48701","119.89672"
"106.40000","0.48725","119.83159"
"106.60000","0.48752","119.83105"
"106.80000","0.48778","119.79669"
"107.00000","0.48806","119.80655"
"107.20000","0.48833","119.79415"
"107.40000","0.48860","119.74411"
"107.60000","0.48885","119.71691"
"107.80000","0.48912","119.67738"
"108.00000","0.48939","119.66286"
"108.20000","0.48966","119.65559"
"108.40000","0.48994","119.64512"
"108.60000","0.49019","119.59415"
"108.80000","0.49046","119.56188"
"109.00000","0.49073","119.55506"
"109.20000","0.49098","119.51754"
"109.40000","0.49127","119.52969"
"109.60000","0.49153","119.49326"
"109.80000","0.49180","119.46226"
"110.00000","0.49206","119.43405"
"110.20000","0.49231","119.37981"
"110.40000","0.49259","119.40323"
"110.60000","0.49285","119.36065"
"110.80000","0.49313","119.34751"
"111.00000","0.49340","119.32175"
"111.20000","0.49365","119.26159"
"111.40000","0.49392","119.23755"
"111.60000","0.49418","119.21164"
"111.80000","0.49446","119.20688"
"112.00000","0.49473","119.18661"
"112.20000","0.49500","119.14523"
"112.40000","0.49525","119.10829"
"112.60000","0.49552","119.06865"
"112.80000","0.49579","119.05958"
"113.00000","0.49605","119.03761"
"113.20000","0.49634","119.03575"
"113.40000","0.49659","118.98148"
"113.60000","0.49686","118.93837"
"113.80000","0.49712","118.90750"
"114.00000","0.49738","118.87896"
"114.20000","0.49767","118.88314"
"114.40000","0.49793","118.84000"
"114.60000","0.49820","118.81503"
"114.80000","0.49846","118.77970"
"115.00000","0.49871","118.72550"
"115.20000","0.49900","118.73624"
"115.40000","0.49925","118.68842"
"115.60000","0.49953","118.67377"
"115.80000","0.49980","118.64773"
"116.00000","0.50005","118.57721"
"116.20000","0.50032","118.55482"
"116.40000","0.50058","118.53396"
"116.60000","0.50086","118.52337"
"116.80000","0.50113","118.49613"
"117.00000","0.50140","118.43230"
"117.20000","0.50166","118.40463"
"117.40000","0.50192","118.35275"
"117.60000","0.50219","118.34487"
"117.80000","0.50246","118.32419"
"118.00000","0.50274","118.29509"
"118.20000","0.50299","118.25361"
"118.40000","0.50326","118.22466"
"118.60000","0.50352","118.18883"
"118.80000","0.50378","118.15453"
"119.00000","0.50407","118.16077"
"119.20000","0.50433","118.11217"
"119.40000","0.50460","118.08130"
"119.60000","0.50486","118.02798"
"119.80000","0.50511","117.97065"
"120.00000","0.50540","117.98657"
"120.20000","0.50565","117.93633"
"120.40000","0.50594","117.92773"
"120.60000","0.50621","117.90027"
"120.80000","0.50645","117.81428"
"121.00000","0.50672","117.81482"
"121.20000","0.50698","117.76498"
"121.40000","0.50726","117.75568"
"121.60000","0.50753","117.73430"
"121.80000","0.50780","117.67861"
"122.00000","0.50805","117.64953"
"122.20000","0.50832","117.60296"
"122.40000","0.50859","117.59259"
"122.60000","0.50886","117.57120"
"122.80000","0.50914","117.55422"
"123.00000","0.50939","117.48077"
"123.20000","0.50966","117.44798"
"123.40000","0.50992","117.42028"
"123.60000","0.51018","117.38983"
"123.80000","0.51047","117.38684"
"124.00000","0.51073","117.33600"
"124.20000","0.51100","117.30645"
"124.40000","0.51126","117.26974"
"124.60000","0.51151","117.20421"
"124.80000","0.51180","117.21383"
"125.00000","0.51205","117.15826"
"125.20000","0.51233","117.13784"
"125.40000","0.51260","117.10374"
"125.60000","0.51285","117.04222"
"125.80000","0.51312","117.02664"
"126.00000","0.51339","116.99198"
"126.20000","0.51366","116.97063"
"126.40000","0.51394","116.94373"
"126.60000","0.51420","116.87913"
"126.80000","0.51445","116.85027"
"127.00000","0.51471","116.79316"
"127.20000","0.51499","116.77873"
"127.40000","0.51526","116.76590"
"127.60000","0.51554","116.73866"
"127.80000","0.51579","116.68913"
"128.00000","0.51605","116.63362"
"128.20000","0.51632","116.61162"
"128.40000","0.51658","116.57716"
"128.60000","0.51687","116.57215"
"128.80000","0.51713","116.51396"
"129.00000","0.51740","116.48139"
"129.20000","0.51766","116.45471"
"129.40000","0.51791","116.39070"
"129.60000","0.51820","116.39876"
"129.80000","0.51846","116.35442"
"130.00000","0.51873","116.33325"
"130.20000","0.51900","116.28570"
"130.40000","0.51924","116.21680"
"130.60000","0.51952","116.20591"
"130.80000","0.51978","116.16976"
"131.00000","0.52006","116.14679"
"131.20000","0.52033","116.12800"
"131.40000","0.52060","116.06462"
"131.60000","0.52086","116.03086"
"131.80000","0.52112","115.98472"
"132.00000","0.52139","115.96550"
"132.20000","0.52166","115.94566"
"132.40000","0.52194","115.91052"
"132.60000","0.52219","115.85047"
"132.80000","0.52246","115.80818"
"133.00000","0.52273","115.77845"
"133.20000","0.52298","115.73328"
"133.40000","0.52327","115.73394"
"133.60000","0.52353","115.66991"
"133.80000","0.52380","115.64108"
"134.00000","0.52406","115.59826"
"134.20000","0.52431","115.53496"
"134.40000","0.52460","115.54707"
"134.60000","0.52486","115.49137"
"134.80000","0.52514","115.46988"
"135.00000","0.52540","115.42809"
"135.20000","0.52565","115.35963"
"135.40000","0.52592","115.34878"
"135.60000","0.52618","115.30070"
"135.80000","0.52647","115.28278"
"136.00000","0.52673","115.25519"
"136.20000","0.52699","115.18750"
"136.40000","0.52725","115.15405"
"136.60000","0.52752","115.11013"
"136.80000","0.52779","115.09532"
"137.00000","0.52806","115.06244"
"137.20000","0.52834","115.03347"
"137.40000","0.52859","114.98170"
"137.60000","0.52886","114.93058"
"137.80000","0.52912","114.89702"
"138.00000","0.52938","114.86514"
"138.20000","0.52967","114.85534"
"138.40000","0.52993","114.80617"
"138.60000","0.53020","114.76551"
"138.80000","0.53046","114.72403"
"139.00000","0.53071","114.66456"
"139.20000","0.53100","114.67426"
"139.40000","0.53126","114.61473"
"139.60000","0.53153","114.59594"
"139.80000","0.53180","114.55481"
"140.00000","0.53205","114.47413"
"140.20000","0.53232","114.46511"
"140.40000","0.53258","114.41949"
"140.60000","0.53287","114.40822"
"140.80000","0.53314","114.36788"
"141.00000","0.53339","114.30210"
"141.20000","0.53366","114.27474"
"141.40000","0.53391","114.21902"
"141.60000","0.53419","114.20742"
"141.80000","0.53446","114.17664"
"142.00000","0.53474","114.15434"
"142.20000","0.53499","114.09084"
"142.40000","0.53526","114.04259"
"142.60000","0.53552","114.01969"
"142.80000","0.53578","113.98497"
"143.00000","0.53608","113.98350"
"143.20000","0.53632","113.91584"
"143.40000","0.53660","113.87943"
"143.60000","0.53686","113.84180"
"143.80000","0.53711","113.78223"
"144.00000","0.53740","113.78416"
"144.20000","0.53766","113.72543"
"144.40000","0.53793","113.71091"
"144.60000","0.53820","113.66116"
"144.80000","0.53845","113.59334"
"145.00000","0.53872","113.58369"
"145.20000","0.53898","113.54066"
"145.40000","0.53926","113.52702"
"145.60000","0.53954","113.49566"
"145.80000","0.53979","113.43176"
"146.00000","0.54006","113.41011"
"146.20000","0.54032","113.36313"
"146.40000","0.54059","113.34628"
"146.60000","0.54086","113.31935"
"146.80000","0.54114","113.29164"
"147.00000","0.54139","113.22746"
"147.20000","0.54165","113.18076"
"147.40000","0.54192","113.15464"
"147.60000","0.54218","113.12354"
"147.80000","0.54248","113.12614"
"148.00000","0.54273","113.05595"
"148.20000","0.54300","113.02968"
"148.40000","0.54326","112.99113"
"148.60000","0.54351","112.92983"
"148.80000","0.54380","112.93075"
"149.00000","0.54406","112.87386"
"149.20000","0.54434","112.85414"
"149.40000","0.54460","112.80850"
"149.60000","0.54485","112.73258"
"149.80000","0.54512","112.73218"
"150.00000","0.54539","112.69200"
"150.20000","0.54567","112.67434"
"150.40000","0.54594","112.63676"
"150.60000","0.54619","112.56884"
"150.80000","0.54645","112.54572"
"151.00000","0.54672","112.50077"
"151.20000","0.54699","112.48616"
"151.40000","0.54726","112.44829"
"151.60000","0.54754","112.41657"
"151.80000","0.54779","112.35976"
"152.00000","0.54806","112.31534"
"152.20000","0.54832","112.28457"
"152.40000","0.54858","112.25080"
"152.60000","0.54888","112.24466"
"152.80000","0.54913","112.18060"
"153.00000","0.54940","112.14623"
"153.20000","0.54966","112.11249"
"153.40000","0.54991","112.05244"
"153.60000","0.55020","112.06750"
"153.80000","0.55046","112.01037"
"154.00000","0.55073","111.97603"
"154.20000","0.55100","111.92834"
"154.40000","0.55125","111.86031"
"154.60000","0.55152","111.86087"
"154.80000","0.55178","111.80860"
"155.00000","0.55207","111.80145"
"155.20000","0.55233","111.76230"
"155.40000","0.55259","111.69166"
"155.60000","0.55286","111.66764"
"155.80000","0.55311","111.61625"
"156.00000","0.55339","111.60763"
"156.20000","0.55366","111.56667"
"156.40000","0.55394","111.53777"
"156.60000","0.55419","111.47994"
"156.80000","0.55446","111.43028"
"157.00000","0.55472","111.41862"
"157.20000","0.55498","111.38515"
"157.40000","0.55527","111.36119"
"157.60000","0.55553","111.30973"
"157.80000","0.55580","111.27912"
"158.00000","0.55606","111.23545"
"158.20000","0.55631","111.18129"
"158.40000","0.55660","111.18315"
"158.60000","0.55686","111.11483"
"158.80000","0.55714","111.10886"
"159.00000","0.55740","111.06152"
"159.20000","0.55764","110.98221"
"159.40000","0.55793","110.98788"
"159.60000","0.55818","110.93299"
"159.80000","0.55847","110.92115"
"160.00000","0.55874","110.88915"
"160.20000","0.55899","110.81252"
"160.40000","0.55926","110.79413"
"160.60000","0.55951","110.74925"
"160.80000","0.55979","110.73376"
"161.00000","0.56006","110.69870"
"161.20000","0.56034","110.66217"
"161.40000","0.56059","110.61432"
"161.60000","0.56085","110.57376"
"161.80000","0.56112","110.54654"
"162.00000","0.56138","110.52068"
"162.20000","0.56168","110.51087"
"162.40000","0.56192","110.44161"
"162.60000","0.56220","110.41151"
"162.80000","0.56246","110.37375"
"163.00000","0.56271","110.32023"
"163.20000","0.56300","110.32881"
"163.40000","0.56325","110.26441"
"163.60000","0.56353","110.23603"
"163.80000","0.56380","110.19509"
"164.00000","0.56404","110.12277"
"164.20000","0.56432","110.11555"
"164.40000","0.56459","110.07510"
"164.60000","0.56486","110.04246"
"164.80000","0.56514","110.01642"
"165.00000","0.56539","109.95204"
"165.20000","0.56566","109.93073"
"165.40000","0.56591","109.87522"
"165.60000","0.56619","109.86301"
"165.80000","0.56647","109.83541"
"166.00000","0.56674","109.80029"
"166.20000","0.56699","109.75061"
"166.40000","0.56725","109.69412"
"166.60000","0.56752","109.66758"
"166.80000","0.56779","109.64253"
"167.00000","0.56808","109.63152"
"167.20000","0.56832","109.56550"
"167.40000","0.56859","109.52067"
"167.60000","0.56886","109.48621"
"167.80000","0.56911","109.43505"
"168.00000","0.56940","109.45328"
"168.20000","0.56966","109.38531"
"168.40000","0.56993","109.36184"
"168.60000","0.57020","109.30487"
"168.80000","0.57045","109.24294"
"169.00000","0.57072","109.23050"
"169.20000","0.57098","109.18431"
"169.40000","0.57127","109.17799"
"169.60000","0.57153","109.13249"
"169.80000","0.57179","109.06885"
"170.00000","0.57206","109.04984"
"170.20000","0.57231","109.00214"
"170.40000","0.57259","108.97666"
"170.60000","0.57287","108.95607"
"170.80000","0.57314","108.90491"
"171.00000","0.57339","108.85191"
"171.20000","0.57365","108.79802"
"171.40000","0.57392","108.78323"
"171.60000","0.57418","108.74690"
"171.80000","0.57447","108.72381"
"172.00000","0.57473","108.66148"
"172.20000","0.57500","108.62662"
"172.40000","0.57526","108.57802"
"172.60000","0.57551","108.52322"
"172.80000","0.57580","108.52787"
"173.00000","0.57606","108.46362"
"173.20000","0.57634","108.44264"
"173.40000","0.57660","108.39115"
"173.60000","0.57684","108.31938"
"173.80000","0.57713","108.32437"
"174.00000","0.57739","108.26891"
"174.20000","0.57767","108.25326"
"174.40000","0.57793","108.20140"
"174.60000","0.57819","108.13348"
"174.80000","0.57846","108.10534"
"175.00000","0.57871","108.05553"
"175.20000","0.57899","108.03111"
"175.40000","0.57926","107.99373"
"175.60000","0.57953","107.95364"
"175.80000","0.57979","107.90337"
"176.00000","0.58005","107.85778"
"176.20000","0.58032","107.82498"
"176.40000","0.58058","107.78363"
"176.60000","0.58087","107.77466"
"176.80000","0.58112","107.69631"
"177.00000","0.58140","107.66462"
"177.20000","0.58166","107.61932"
"177.40000","0.58191","107.56359"
"177.60000","0.58220","107.56027"
"177.80000","0.58246","107.49833"
"178.00000","0.58273","107.47644"
"178.20000","0.58300","107.42577"
"178.40000","0.58325","107.36401"
"178.60000","0.58352","107.35617"
"178.80000","0.58379","107.30183"
"179.00000","0.58407","107.28926"
"179.20000","0.58434","107.24969"
"179.40000","0.58459","107.16620"
"179.60000","0.58486","107.15049"
"179.80000","0.58511","107.09008"
"180.00000","0.58539","107.07638"
"180.20000","0.58567","107.03887"
"180.40000","0.58594","106.97088"
"180.60000","0.58619","106.91894"
"180.80000","0.58645","106.87910"
"181.00000","0.58672","106.84750"
"181.20000","0.58699","106.81218"
"181.40000","0.58728","106.79138"
"181.60000","0.58752","106.71714"
"181.80000","0.58779","106.67067"
"182.00000","0.58806","106.62148"
"182.20000","0.58831","106.57548"
"182.40000","0.58860","106.57844"
"182.60000","0.58886","106.50063"
"182.80000","0.58914","106.48326"
"183.00000","0.58940","106.42613"
"183.20000","0.58964","106.35038"
"183.40000","0.58993","106.36350"
"183.60000","0.59018","106.29375"
"183.80000","0.59047","106.26735"
"184.00000","0.59074","106.22557"
"184.20000","0.59099","106.14903"
"184.40000","0.59126","106.11465"
"184.60000","0.59152","106.07928"
"184.80000","0.59179","106.04501"
"185.00000","0.59207","106.00878"
"185.20000","0.59234","105.95297"
"185.40000","0.59259","105.89813"
"185.60000","0.59285","105.83817"
"185.80000","0.59312","105.82136"
"186.00000","0.59339","105.77387"
"186.20000","0.59367","105.75655"
"186.40000","0.59393","105.68620"
"186.60000","0.59419","105.63849"
"186.80000","0.59446","105.59867"
"187.00000","0.59471","105.55208"
"187.20000","0.59500","105.54226"
"187.40000","0.59526","105.45962"
"187.60000","0.59554","105.42589"
"187.80000","0.59580","105.37631"
"188.00000","0.59604","105.29726"
"188.20000","0.59633","105.30265"
"188.40000","0.59659","105.23640"
"188.60000","0.59687","105.21146"
"188.80000","0.59714","105.15970"
"189.00000","0.59739","105.07133"
"189.20000","0.59766","105.04504"
"189.40000","0.59791","104.98993"
"189.60000","0.59819","104.97299"
"189.80000","0.59846","104.91949"
"190.00000","0.59874","104.86324"
"190.20000","0.59899","104.80963"
"190.40000","0.59925","104.75047"
"190.60000","0.59952","104.72424"
"190.80000","0.59979","104.66871"
"191.00000","0.60008","104.63775"
"191.20000","0.60033","104.54423"
"191.40000","0.60059","104.50000"
"191.60000","0.60086","104.44320"
"191.80000","0.60111","104.39088"
"192.00000","0.60140","104.38697"
"192.20000","0.60166","104.32010"
"192.40000","0.60194","104.27646"
"192.60000","0.60219","104.20775"
"192.80000","0.60244","104.12339"
"193.00000","0.60273","104.10980"
"193.20000","0.60299","104.05373"
"193.40000","0.60327","104.01865"
"193.60000","0.60354","103.95969"
"193.80000","0.60379","103.87685"
"194.00000","0.60406","103.84999"
"194.20000","0.60432","103.78457"
"194.40000","0.60459","103.76235"
"194.60000","0.60487","103.71058"
"194.80000","0.60513","103.64640"
"195.00000","0.60539","103.58894"
"195.20000","0.60565","103.51548"
"195.40000","0.60593","103.48903"
"195.60000","0.60619","103.42596"
"195.80000","0.60647","103.39434"
"196.00000","0.60673","103.29689"
"196.20000","0.60699","103.24528"
"196.40000","0.60726","103.19820"
"196.60000","0.60751","103.13564"
"196.80000","0.60780","103.11305"
"197.00000","0.60806","103.03594"
"197.20000","0.60834","102.99114"
"197.40000","0.60860","102.91453"
"197.60000","0.60884","102.83461"
"197.80000","0.60913","102.81881"
"198.00000","0.60939","102.74053"
"198.20000","0.60967","102.70264"
"198.40000","0.60994","102.63187"
"198.60000","0.61018","102.53638"
"198.80000","0.61046","102.48922"
"199.00000","0.61072","102.41228"
"199.20000","0.61099","102.37935"
"199.40000","0.61127","102.32075"
"199.60000","0.61154","102.23870"
"199.80000","0.61179","102.17472"
"200.00000","0.61205","102.09007"
"200.20000","0.61232","102.04882"
"200.40000","0.61259","101.98494"
"200.60000","0.61287","101.93043"
"200.80000","0.61313","101.82830"
"201.00000","0.61339","101.75910"
"201.20000","0.61366","101.68821"
"201.40000","0.61391","101.61247"
"201.60000","0.61420","101.58966"
"201.80000","0.61446","101.48183"
"202.00000","0.61473","101.41265"
"202.20000","0.61499","101.33148"
"202.40000","0.61524","101.22668"
"202.60000","0.61553","101.20072"
"202.80000","0.61579","101.09003"
"203.00000","0.61607","101.03513"
"203.20000","0.61634","100.95120"
"203.40000","0.61659","100.83838"
"203.60000","0.61686","100.76333"
"203.80000","0.61712","100.66225"
"204.00000","0.61739","100.60793"
"204.20000","0.61767","100.51801"
"204.40000","0.61794","100.39957"
"204.60000","0.61819","100.29159"
"204.80000","0.61845","100.19143"
"205.00000","0.61872","100.10770"
"205.20000","0.61899","100.00133"
"205.40000","0.61928","99.90642"
"205.60000","0.61953","99.74030"
"205.80000","0.61979","99.62203"
"206.00000","0.62005","99.49470"
"206.20000","0.62031","99.35249"
"206.40000","0.62060","99.24199"
"206.60000","0.62086","99.04940"
"206.80000","0.62113","98.88317"
"207.00000","0.62140","98.68268"
"207.20000","0.62164","98.44829"
"207.40000","0.62193","98.27060"
"207.60000","0.62219","97.99034"
"207.80000","0.62247","97.72693"
"208.00000","0.62274","97.37426"
"208.20000","0.62298","96.92510"
"208.40000","0.62326","96.41556"
"208.60000","0.62352","95.66644"
"208.80000","0.62379","94.46781"
"208.98000","0.62405","86.89629"
"208.98700","0.62407","72.48056"
"208.99300","0.62408","57.07928"
"208.99900","0.62409","41.82954"
"209.00500","0.62410","28.33055"
"209.01200","0.62411","15.75462"
"209.01700","0.62411","8.98699"