File: materials_lab1/ENGR314_FA19_0001_polyproylene_B_20190903_CCS.is_tens_RawData/Specimen_RawData_1.csv
Material,Acrylic
Geometry,Circular
Length,"2.00000",in
Diameter,"0.12500",in

Time,Extension,Load
(s),(in),(lbf)
"0.00000","0.00000","-7.53015"
"0.80000","0.00106","-6.06040"
"1.60000","0.00215","-4.59161"
"2.40000","0.00320","-3.19163"
"3.20000","0.00427","-1.82708"
"4.00000","0.00535","-0.48221"
"4.80000","0.00641","0.83013"
"5.60000","0.00746","2.05996"
"6.40000","0.00855","3.32893"
"7.20000","0.00960","4.52200"
"8.00000","0.01067","5.69220"
"8.80000","0.01175","6.87763"
"9.60000","0.01281","8.00101"
"10.40000","0.01387","9.06553"
"11.20000","0.01495","10.15309"
"12.00000","0.01600","11.18221"
"12.80000","0.01707","12.18539"
"13.60000","0.01814","13.18611"
"14.40000","0.01921","14.14060"
"15.20000","0.02027","15.06529"
"16.00000","0.02135","15.96020"
"16.80000","0.02240","16.81539"
"17.60000","0.02347","17.65829"
"18.40000","0.02455","18.47887"
"19.20000","0.02561","19.27362"
"20.00000","0.02666","20.01014"
"20.80000","0.02775","20.75439"
"21.60000","0.02880","21.45969"
"22.40000","0.02987","22.13578"
"23.20000","0.03095","22.80832"
"24.00000","0.03201","23.46272"
"24.80000","0.03306","24.05655"
"25.60000","0.03415","24.66178"
"26.40000","0.03520","25.23865"
"27.20000","0.03627","25.77840"
"28.00000","0.03735","26.33430"
"28.80000","0.03841","26.86265"
"29.60000","0.03946","27.34418"
"30.40000","0.04055","27.84268"
"31.20000","0.04160","28.30830"
"32.00000","0.04267","28.75716"
"32.80000","0.04375","29.20302"
"33.60000","0.04481","29.63823"
"34.40000","0.04587","30.04039"
"35.20000","0.04695","30.44714"
"36.00000","0.04800","30.83329"
"36.80000","0.04906","31.20740"
"37.60000","0.05015","31.58821"
"38.40000","0.05121","31.94681"
"39.20000","0.05226","32.28774"
"40.00000","0.05335","32.62565"
"40.80000","0.05440","32.95636"
"41.60000","0.05547","33.28246"
"42.40000","0.05655","33.60303"
"43.20000","0.05761","33.92130"
"44.00000","0.05866","34.20077"
"44.80000","0.05975","34.52157"
"45.60000","0.06080","34.80775"
"46.40000","0.06187","35.08907"
"47.20000","0.06295","35.37071"
"48.00000","0.06401","35.65583"
"48.80000","0.06506","35.90584"
"49.60000","0.06615","36.18408"
"50.40000","0.06720","36.43859"
"51.20000","0.06827","36.69605"
"52.00000","0.06935","36.95226"
"52.80000","0.07041","37.20581"
"53.60000","0.07147","37.44179"
"54.40000","0.07255","37.70204"
"55.20000","0.07360","37.95215"
"56.00000","0.07466","38.15617"
"56.80000","0.07574","38.38966"
"57.60000","0.07681","38.62683"
"58.40000","0.07786","38.84075"
"59.20000","0.07895","39.06334"
"60.00000","0.08000","39.28134"
"60.80000","0.08106","39.49491"
"61.60000","0.08215","39.71723"
"62.40000","0.08321","39.91652"
"63.20000","0.08426","40.10658"
"64.00000","0.08535","40.30265"
"64.80000","0.08640","40.51103"
"65.60000","0.08746","40.69392"
"66.40000","0.08854","40.87643"
"67.20000","0.08961","41.07853"
"68.00000","0.09066","41.24444"
"68.80000","0.09175","41.42772"
"69.60000","0.09280","41.60887"
"70.40000","0.09387","41.77513"
"71.20000","0.09494","41.94183"
"72.00000","0.09601","42.12722"
"72.80000","0.09707","42.27868"
"73.60000","0.09814","42.43240"
"74.40000","0.09921","42.59274"
"75.20000","0.10026","42.74247"
"76.00000","0.10134","42.89388"
"76.80000","0.10242","43.04228"
"77.60000","0.10347","43.17821"
"78.40000","0.10454","43.30460"
"79.20000","0.10560","43.44965"
"80.00000","0.10667","43.58484"
"80.80000","0.10774","43.70388"
"81.60000","0.10882","43.84949"
"82.40000","0.10986","43.96291"
"83.20000","0.11094","44.07970"
"84.00000","0.11201","44.20622"
"84.80000","0.11306","44.30910"
"85.60000","0.11414","44.42979"
"86.40000","0.11522","44.54333"
"87.20000","0.11626","44.62907"
"88.00000","0.11734","44.73945"
"88.80000","0.11841","44.84752"
"89.60000","0.11947","44.93653"
"90.40000","0.12054","45.03093"
"91.20000","0.12162","45.13415"
"92.00000","0.12267","45.21516"
"92.80000","0.12374","45.29371"
"93.60000","0.12481","45.37844"
"94.40000","0.12586","45.45931"
"95.20000","0.12694","45.52795"
"96.00000","0.12802","45.62125"
"96.80000","0.12907","45.68094"
"97.60000","0.13014","45.74076"
"98.40000","0.13121","45.82809"
"99.20000","0.13226","45.87964"
"100.00000","0.13334","45.94383"
"100.80000","0.13442","46.01946"
"101.60000","0.13547","46.05706"
"102.40000","0.13654","46.10248"
"103.20000","0.13761","46.14777"
"104.00000","0.13867","46.18913"
"104.80000","0.13974","46.24138"
"105.60000","0.14082","46.29088"
"106.40000","0.14187","46.31329"
"107.20000","0.14294","46.34623"
"108.00000","0.14401","46.38163"
"108.80000","0.14507","46.40530"
"109.60000","0.14614","46.43642"
"110.40000","0.14722","46.46348"
"111.20000","0.14827","46.47812"
"112.00000","0.14934","46.48603"
"112.80000","0.15041","46.50784"
"113.60000","0.15147","46.51761"
"114.40000","0.15254","46.53230"
"115.20000","0.15362","46.54569"
"116.00000","0.15467","46.54354"
"116.80000","0.15573","46.54432"
"117.60000","0.15681","46.54965"
"118.40000","0.15787","46.54812"
"119.20000","0.15894","46.55022"
"120.00000","0.16002","46.55095"
"120.80000","0.16107","46.52440"
"121.60000","0.16213","46.50559"
"122.40000","0.16321","46.50200"
"123.20000","0.16427","46.47677"
"124.00000","0.16534","46.44796"
"124.80000","0.16642","46.43103"
"125.60000","0.16747","46.39009"
"126.40000","0.16853","46.34765"
"127.20000","0.16961","46.31638"
"128.00000","0.17067","46.26408"
"128.80000","0.17174","46.21678"
"129.60000","0.17282","46.17778"
"130.40000","0.17387","46.11536"
"131.20000","0.17493","46.04050"
"132.00000","0.17601","45.99263"
"132.80000","0.17707","45.92021"
"133.60000","0.17814","45.84705"
"134.40000","0.17922","45.79176"
"135.20000","0.18027","45.71683"
"136.00000","0.18133","45.61861"
"136.80000","0.18241","45.55540"
"137.60000","0.18347","45.45261"
"138.40000","0.18453","45.34417"
"139.20000","0.18562","45.26164"
"140.00000","0.18667","45.15936"
"140.80000","0.18773","45.07496"
"141.60000","0.18881","44.98653"
"142.40000","0.18987","44.92407"
"143.20000","0.19094","44.84559"
"144.00000","0.19202","44.79557"
"144.80000","0.19307","44.72531"
"145.60000","0.19413","44.65934"
"146.40000","0.19521","44.60239"
"147.20000","0.19627","44.55071"
"148.00000","0.19733","44.47836"
"148.80000","0.19842","44.44108"
"149.60000","0.19947","44.38400"
"150.40000","0.20053","44.31098"
"151.20000","0.20161","44.26454"
"152.00000","0.20267","44.21234"
"152.80000","0.20373","44.15113"
"153.60000","0.20482","44.10987"
"154.40000","0.20588","44.04944"
"155.20000","0.20693","43.98691"
"156.00000","0.20801","43.93871"
"156.80000","0.20907","43.88433"
"157.60000","0.21013","43.80450"
"158.40000","0.21122","43.77381"
"159.20000","0.21227","43.71200"
"160.00000","0.21333","43.64495"
"160.80000","0.21441","43.59990"
"161.60000","0.21547","43.53450"
"162.40000","0.21653","43.47813"
"163.20000","0.21762","43.42342"
"164.00000","0.21867","43.37208"
"164.80000","0.21973","43.28698"
"165.60000","0.22081","43.25038"
"166.40000","0.22187","43.19197"
"167.20000","0.22293","43.12120"
"168.00000","0.22402","43.07573"
"168.80000","0.22508","43.02079"
"169.60000","0.22613","42.95012"
"170.40000","0.22721","42.90634"
"171.20000","0.22827","42.84709"
"172.00000","0.22933","42.79253"
"172.80000","0.23042","42.73767"
"173.60000","0.23148","42.68048"
"174.40000","0.23253","42.61159"
"175.20000","0.23361","42.54818"
"176.00000","0.23467","42.50669"
"176.80000","0.23573","42.44347"
"177.60000","0.23682","42.39559"
"178.40000","0.23788","42.33465"
"179.20000","0.23893","42.26389"
"180.00000","0.24001","42.21571"
"180.80000","0.24107","42.16023"
"181.60000","0.24213","42.09469"
"182.40000","0.24322","42.06407"
"183.20000","0.24428","41.99334"
"184.00000","0.24533","41.92762"
"184.80000","0.24641","41.87849"
"185.60000","0.24747","41.82494"
"186.40000","0.24853","41.75829"
"187.20000","0.24962","41.72217"
"188.00000","0.25068","41.66692"
"188.80000","0.25173","41.60403"
"189.60000","0.25281","41.56512"
"190.40000","0.25387","41.51738"
"191.20000","0.25493","41.45636"
"192.00000","0.25602","41.40950"
"192.80000","0.25708","41.37656"
"193.60000","0.25813","41.31126"
"194.40000","0.25921","41.28240"
"195.20000","0.26027","41.24139"
"196.00000","0.26133","41.18913"
"196.80000","0.26242","41.15007"
"197.60000","0.26348","41.12003"
"198.40000","0.26453","41.05947"
"199.20000","0.26561","41.02769"
"200.00000","0.26667","40.99862"
"200.80000","0.26773","40.94254"
"201.60000","0.26882","40.92731"
"202.40000","0.26988","40.89015"
"203.20000","0.27093","40.83993"
"204.00000","0.27201","40.80827"
"204.80000","0.27307","40.77671"
"205.60000","0.27413","40.73240"
"206.40000","0.27522","40.71135"
"207.20000","0.27628","40.68769"
"208.00000","0.27733","40.64002"
"208.80000","0.27841","40.62743"
"209.60000","0.27947","40.59715"
"210.40000","0.28053","40.56050"
"211.20000","0.28162","40.53054"
"212.00000","0.28268","40.51718"
"212.80000","0.28373","40.47448"
"213.60000","0.28481","40.45656"
"214.40000","0.28587","40.44058"
"215.20000","0.28693","40.40059"
"216.00000","0.28801","40.37576"
"216.80000","0.28908","40.36880"
"217.60000","0.29013","40.32770"
"218.40000","0.29121","40.30571"
"219.20000","0.29227","40.29321"
"220.00000","0.29333","40.25540"
"220.80000","0.29441","40.23450"
"221.60000","0.29548","40.23509"
"222.40000","0.29653","40.19918"
"223.20000","0.29761","40.17468"
"224.00000","0.29867","40.16327"
"224.80000","0.29973","40.13655"
"225.60000","0.30082","40.12773"
"226.40000","0.30188","40.10870"
"227.20000","0.30293","40.08250"
"228.00000","0.30401","40.06821"
"228.80000","0.30507","40.05961"
"229.60000","0.30613","40.03454"
"230.40000","0.30721","40.02997"
"231.20000","0.30828","40.01945"
"232.00000","0.30933","39.98349"
"232.80000","0.31041","39.97994"
"233.60000","0.31148","39.97453"
"234.40000","0.31253","39.95825"
"235.20000","0.31361","39.94739"
"236.00000","0.31468","39.94034"
"236.80000","0.31573","39.90917"
"237.60000","0.31681","39.90979"
"238.40000","0.31788","39.90192"
"239.20000","0.31893","39.89065"
"240.00000","0.32002","39.87916"
"240.80000","0.32108","39.88495"
"241.60000","0.32212","39.85661"
"242.40000","0.32321","39.85551"
"243.20000","0.32427","39.83970"
"244.00000","0.32533","39.82937"
"244.80000","0.32641","39.82328"
"245.60000","0.32748","39.82738"
"246.40000","0.32853","39.79674"
"247.20000","0.32961","39.78848"
"248.00000","0.33067","39.79718"
"248.80000","0.33173","39.77496"
"249.60000","0.33282","39.77610"
"250.40000","0.33388","39.78048"
"251.20000","0.33493","39.75083"
"252.00000","0.33601","39.75571"
"252.80000","0.33708","39.74961"
"253.60000","0.33813","39.73829"
"254.40000","0.33921","39.73308"
"255.20000","0.34028","39.74020"
"256.00000","0.34133","39.71580"
"256.80000","0.34241","39.71645"
"257.60000","0.34348","39.71890"
"258.40000","0.34453","39.71162"
"259.20000","0.34561","39.70852"
"260.00000","0.34668","39.71358"
"260.80000","0.34772","39.68875"
"261.60000","0.34881","39.68737"
"262.40000","0.34988","39.69410"
"263.20000","0.35093","39.68156"
"264.00000","0.35201","39.68025"
"264.80000","0.35309","39.69761"
"265.60000","0.35412","39.66847"
"266.40000","0.35521","39.66488"
"267.20000","0.35628","39.67805"
"268.00000","0.35733","39.67376"
"268.80000","0.35841","39.66584"
"269.60000","0.35948","39.67615"
"270.40000","0.36053","39.65539"
"271.20000","0.36161","39.65363"
"272.00000","0.36268","39.66762"
"272.80000","0.36373","39.65530"
"273.60000","0.36481","39.65683"
"274.40000","0.36588","39.66184"
"275.20000","0.36692","39.64573"
"276.00000","0.36801","39.65031"
"276.80000","0.36908","39.65214"
"277.60000","0.37013","39.64662"
"278.40000","0.37121","39.64786"
"279.20000","0.37229","39.66084"
"280.00000","0.37332","39.64282"
"280.80000","0.37440","39.64027"
"281.60000","0.37548","39.64856"
"282.40000","0.37653","39.64083"
"283.20000","0.37761","39.64236"
"284.00000","0.37869","39.65726"
"284.80000","0.37973","39.63857"
"285.60000","0.38081","39.65073"
"286.40000","0.38188","39.64186"
"287.20000","0.38293","39.64202"
"288.00000","0.38401","39.63003"
"288.80000","0.38509","39.65612"
"289.60000","0.38613","39.62238"
"290.40000","0.38721","39.63621"
"291.20000","0.38828","39.64406"
"292.00000","0.38933","39.63600"
"292.80000","0.39041","39.63774"
"293.60000","0.39149","39.65454"
"294.40000","0.39253","39.62991"
"295.20000","0.39360","39.64181"
"296.00000","0.39468","39.64684"
"296.80000","0.39573","39.64900"
"297.60000","0.39681","39.63640"
"298.40000","0.39789","39.65581"
"299.20000","0.39893","39.63734"
"300.00000","0.40000","39.65143"
"300.80000","0.40108","39.65685"
"301.60000","0.40213","39.65045"
"302.40000","0.40321","39.64122"
"303.20000","0.40429","39.67006"
"304.00000","0.40533","39.63760"
"304.80000","0.40640","39.64615"
"305.60000","0.40748","39.66534"
"306.40000","0.40853","39.64875"
"307.20000","0.40960","39.65085"
"308.00000","0.41069","39.66291"
"308.80000","0.41173","39.64839"
"309.60000","0.41280","39.64737"
"310.40000","0.41388","39.65986"
"311.20000","0.41493","39.65462"
"312.00000","0.41600","39.65328"
"312.80000","0.41709","39.66359"
"313.60000","0.41813","39.64899"
"314.40000","0.41920","39.65073"
"315.20000","0.42028","39.66401"
"316.00000","0.42133","39.65743"
"316.80000","0.42240","39.65959"
"317.60000","0.42349","39.67790"
"318.40000","0.42453","39.65450"
"319.20000","0.42560","39.65606"
"320.00000","0.42668","39.66638"
"320.80000","0.42774","39.67053"
"321.60000","0.42880","39.65569"
"322.40000","0.42989","39.67733"
"323.20000","0.43093","39.65465"
"324.00000","0.43200","39.65577"
"324.80000","0.43308","39.66623"
"325.60000","0.43413","39.66378"
"326.40000","0.43520","39.66794"
"327.20000","0.43629","39.67045"
"328.00000","0.43733","39.66535"
"328.80000","0.43840","39.65559"
"329.60000","0.43948","39.66786"
"330.40000","0.44053","39.66655"
"331.20000","0.44160","39.66560"
"332.00000","0.44269","39.67433"
"332.80000","0.44373","39.67824"
"333.60000","0.44480","39.66915"
"334.40000","0.44588","39.68603"
"335.20000","0.44693","39.67495"
"336.00000","0.44800","39.67027"
"336.80000","0.44909","39.68555"
"337.60000","0.45013","39.67612"
"338.40000","0.45120","39.67312"
"339.20000","0.45228","39.67617"
"340.00000","0.45334","39.67699"
"340.80000","0.45440","39.66915"
"341.60000","0.45549","39.69295"
"342.40000","0.45653","39.67310"
"343.20000","0.45760","39.66982"
"344.00000","0.45868","39.67487"
"344.80000","0.45974","39.68588"
"345.60000","0.46080","39.66547"
"346.40000","0.46189","39.69220"
"347.20000","0.46293","39.67655"
"348.00000","0.46400","39.67393"
"348.80000","0.46508","39.67595"
"349.60000","0.46614","39.68645"
"350.40000","0.46720","39.66395"
"351.20000","0.46829","39.70037"
"352.00000","0.46933","39.66888"
"352.80000","0.47040","39.68211"
"353.60000","0.47148","39.68895"
"354.40000","0.47254","39.68891"
"355.20000","0.47360","39.68188"
"356.00000","0.47469","39.70164"
"356.80000","0.47573","39.69189"
"357.60000","0.47680","39.70309"
"358.40000","0.47788","39.70084"
"359.20000","0.47894","39.71210"
"360.00000","0.48000","39.69806"
"360.80000","0.48109","39.71156"
"361.60000","0.48213","39.70029"
"362.40000","0.48320","39.71585"
"363.20000","0.48428","39.70483"
"364.00000","0.48534","39.71751"
"364.80000","0.48640","39.70690"
"365.60000","0.48749","39.73168"
"366.40000","0.48853","39.72214"
"367.20000","0.48960","39.71854"
"368.00000","0.49068","39.73806"
"368.80000","0.49174","39.72845"
"369.60000","0.49280","39.72884"
"370.40000","0.49389","39.73005"
"371.20000","0.49493","39.73707"
"372.00000","0.49600","39.73522"
"372.80000","0.49708","39.74735"
"373.60000","0.49814","39.75638"
"374.40000","0.49920","39.74205"
"375.20000","0.50029","39.77002"
"376.00000","0.50133","39.75432"
"376.80000","0.50240","39.75395"
"377.60000","0.50348","39.75961"
"378.40000","0.50454","39.76893"
"379.20000","0.50560","39.75537"
"380.00000","0.50669","39.76663"
"380.80000","0.50773","39.75900"
"381.60000","0.50880","39.76336"
"382.40000","0.50988","39.77402"
"383.20000","0.51094","39.77214"
"384.00000","0.51200","39.75289"
"384.80000","0.51309","39.76077"
"385.60000","0.51413","39.75596"
"386.40000","0.51520","39.75879"
"387.20000","0.51628","39.75144"
"388.00000","0.51734","39.75905"
"388.80000","0.51839","39.74387"
"389.60000","0.51949","39.76543"
"390.40000","0.52053","39.74899"
"391.20000","0.52160","39.74141"
"392.00000","0.52268","39.74756"
"392.80000","0.52374","39.73902"
"393.60000","0.52480","39.74206"
"394.40000","0.52588","39.74060"
"395.20000","0.52693","39.73995"
"396.00000","0.52800","39.73165"
"396.80000","0.52908","39.73801"
"397.60000","0.53014","39.74950"
"398.40000","0.53120","39.72758"
"399.20000","0.53228","39.72875"
"400.00000","0.53333","39.73655"
"400.80000","0.53440","39.73307"
"401.60000","0.53548","39.74018"
"402.40000","0.53654","39.73198"
"403.20000","0.53759","39.72962"
"404.00000","0.53868","39.73294"
"404.80000","0.53973","39.72201"
"405.60000","0.54080","39.70740"
"406.40000","0.54188","39.72051"
"407.20000","0.54294","39.72521"
"408.00000","0.54399","39.70864"
"408.80000","0.54508","39.71180"
"409.60000","0.54613","39.71055"
"410.40000","0.54720","39.71009"
"411.20000","0.54828","39.71472"
"412.00000","0.54934","39.72825"
"412.80000","0.55039","39.71178"
"413.60000","0.55148","39.71567"
"414.40000","0.55253","39.70355"
"415.20000","0.55360","39.70944"
"416.00000","0.55468","39.72179"
"416.80000","0.55574","39.72584"
"417.60000","0.55680","39.71672"
"418.40000","0.55788","39.71631"
"419.20000","0.55894","39.72504"
"420.00000","0.56000","39.71771"
"420.80000","0.56108","39.74061"
"421.60000","0.56215","39.74064"
"422.40000","0.56320","39.72157"
"423.20000","0.56428","39.73430"
"424.00000","0.56534","39.73897"
"424.80000","0.56640","39.72962"
"425.60000","0.56748","39.72527"
"426.40000","0.56854","39.73268"
"427.20000","0.56960","39.71393"
"428.00000","0.57068","39.72189"
"428.80000","0.57174","39.71607"
"429.60000","0.57280","39.71942"
"430.40000","0.57388","39.72369"
"431.20000","0.57495","39.72845"
"432.00000","0.57600","39.71131"
"432.80000","0.57708","39.72359"
"433.60000","0.57814","39.70963"
"434.40000","0.57920","39.70820"
"435.20000","0.58028","39.70722"
"436.00000","0.58135","39.71368"
"436.80000","0.58240","39.70107"
"437.60000","0.58348","39.71102"
"438.40000","0.58454","39.70876"
"439.20000","0.58560","39.70491"
"440.00000","0.58668","39.71034"
"440.80000","0.58775","39.71677"
"441.60000","0.58880","39.71343"
"442.40000","0.58988","39.71511"
"443.20000","0.59094","39.71419"
"444.00000","0.59200","39.72734"
"444.80000","0.59308","39.73141"
"445.60000","0.59415","39.74073"
"446.40000","0.59520","39.72623"
"447.20000","0.59628","39.72849"
"448.00000","0.59734","39.73695"
"448.80000","0.59840","39.73673"
"449.60000","0.59947","39.72708"
"450.40000","0.60055","39.74501"
"451.20000","0.60160","39.73247"
"452.00000","0.60268","39.73550"
"452.80000","0.60374","39.74794"
"453.60000","0.60480","39.74216"
"454.40000","0.60587","39.74351"
"455.20000","0.60695","39.76729"
"456.00000","0.60800","39.76141"
"456.80000","0.60907","39.75449"
"457.60000","0.61014","39.76527"
"458.40000","0.61120","39.76098"
"459.20000","0.61227","39.76184"
"460.00000","0.61335","39.77039"
"460.80000","0.61440","39.76324"
"461.60000","0.61548","39.75292"
"462.40000","0.61654","39.77426"
"463.20000","0.61760","39.75245"
"464.00000","0.61868","39.75925"
"464.80000","0.61975","39.76675"
"465.60000","0.62080","39.75135"
"466.40000","0.62188","39.75694"
"467.20000","0.62294","39.75642"
"468.00000","0.62400","39.76152"
"468.80000","0.62508","39.75318"
"469.60000","0.62615","39.76441"
"470.40000","0.62720","39.75348"
"471.20000","0.62828","39.75149"
"472.00000","0.62934","39.75882"
"472.80000","0.63040","39.75269"
"473.60000","0.63148","39.75246"
"474.40000","0.63255","39.76570"
"475.20000","0.63360","39.75474"
"476.00000","0.63467","39.75872"
"476.80000","0.63574","39.76293"
"477.60000","0.63680","39.75541"
"478.40000","0.63787","39.75731"
"479.20000","0.63895","39.78009"
"480.00000","0.64000","39.76115"
"480.80000","0.64107","39.76262"
"481.60000","0.64214","39.78374"
"482.40000","0.64320","39.77096"
"483.20000","0.64428","39.77476"
"484.00000","0.64535","39.79893"
"484.80000","0.64640","39.78021"
"485.60000","0.64747","39.78690"
"486.40000","0.64854","39.79270"
"487.20000","0.64960","39.78557"
"488.00000","0.65068","39.78745"
"488.80000","0.65175","39.79872"
"489.60000","0.65280","39.79243"
"490.40000","0.65387","39.77917"
"491.20000","0.65494","39.79813"
"492.00000","0.65600","39.78761"
"492.80000","0.65707","39.78610"
"493.60000","0.65815","39.80355"
"494.40000","0.65920","39.79049"
"495.20000","0.66027","39.79113"
"496.00000","0.66134","39.79421"
"496.80000","0.66240","39.80098"
"497.60000","0.66347","39.79155"
"498.40000","0.66455","39.80852"
"499.20000","0.66560","39.79443"
"500.00000","0.66667","39.78043"
"500.80000","0.66774","39.79427"
"501.60000","0.66880","39.78977"
"502.40000","0.66987","39.79980"
"503.20000","0.67095","39.80738"
"504.00000","0.67200","39.79704"
"504.80000","0.67307","39.80101"
"505.60000","0.67414","39.79901"
"506.40000","0.67520","39.80621"
"507.20000","0.67627","39.80093"
"508.00000","0.67735","39.80945"
"508.80000","0.67840","39.81175"
"509.60000","0.67947","39.80509"
"510.40000","0.68054","39.81691"
"511.20000","0.68160","39.80713"
"512.00000","0.68267","39.81985"
"512.80000","0.68375","39.82960"
"513.60000","0.68480","39.81860"
"514.40000","0.68587","39.81171"
"515.20000","0.68694","39.84040"
"516.00000","0.68800","39.80605"
"516.80000","0.68907","39.80633"
"517.60000","0.69015","39.81775"
"518.40000","0.69120","39.81407"
"519.20000","0.69227","39.80672"
"520.00000","0.69335","39.81986"
"520.80000","0.69440","39.80889"
"521.60000","0.69547","39.82016"
"522.40000","0.69656","39.82074"
"523.20000","0.69760","39.81099"
"524.00000","0.69866","39.79938"
"524.80000","0.69974","39.79537"
"525.60000","0.70080","39.80121"
"526.40000","0.70187","39.79066"
"527.20000","0.70295","39.80780"
"528.00000","0.70400","39.81052"
"528.80000","0.70507","39.79855"
"529.60000","0.70614","39.80719"
"530.40000","0.70720","39.80995"
"531.20000","0.70827","39.79611"
"532.00000","0.70936","39.80993"
"532.80000","0.71040","39.80735"
"533.60000","0.71146","39.79643"
"534.40000","0.71255","39.81485"
"535.20000","0.71360","39.80746"
"536.00000","0.71467","39.80937"
"536.80000","0.71575","39.82442"
"537.60000","0.71681","39.82015"
"538.40000","0.71786","39.80828"
"539.20000","0.71895","39.82072"
"540.00000","0.72000","39.81219"
"540.80000","0.72107","39.81385"
"541.60000","0.72216","39.82460"
"542.40000","0.72321","39.82080"
"543.20000","0.72426","39.80491"
"544.00000","0.72534","39.82329"
"544.80000","0.72640","39.81827"
"545.60000","0.72747","39.82284"
"546.40000","0.72855","39.82854"
"547.20000","0.72960","39.82746"
"548.00000","0.73066","39.81569"
"548.80000","0.73174","39.83012"
"549.60000","0.73280","39.82631"
"550.40000","0.73387","39.82638"
"551.20000","0.73496","39.83392"
"552.00000","0.73601","39.83875"
"552.80000","0.73707","39.82281"
"553.60000","0.73814","39.83828"
"554.40000","0.73920","39.83643"
"555.20000","0.74027","39.83297"
"556.00000","0.74135","39.83717"
"556.80000","0.74241","39.83537"
"557.60000","0.74346","39.83073"
"558.40000","0.74455","39.83939"
"559.20000","0.74560","39.83194"
"560.00000","0.74667","39.83251"
"560.80000","0.74775","39.83922"
"561.60000","0.74881","39.84051"
"562.40000","0.74986","39.82060"
"563.20000","0.75094","39.82623"
"564.00000","0.75200","39.82811"
"564.80000","0.75307","39.82198"
"565.60000","0.75415","39.83395"
"566.40000","0.75521","39.82676"
"567.20000","0.75626","39.81717"
"568.00000","0.75734","39.81649"
"568.80000","0.75840","39.80804"
"569.60000","0.75946","39.81005"
"570.40000","0.76055","39.80968"
"571.20000","0.76161","39.81670"
"572.00000","0.76266","39.79693"
"572.80000","0.76374","39.81490"
"573.60000","0.76481","39.81433"
"574.40000","0.76586","39.79334"
"575.20000","0.76695","39.80537"
"576.00000","0.76801","39.80651"
"576.80000","0.76906","39.80005"
"577.60000","0.77014","39.80047"
"578.40000","0.77121","39.81587"
"579.20000","0.77226","39.80072"
"580.00000","0.77335","39.82181"
"580.80000","0.77441","39.81880"
"581.60000","0.77546","39.80497"
"582.40000","0.77654","39.81807"
"583.20000","0.77761","39.82973"
"584.00000","0.77866","39.81319"
"584.80000","0.77975","39.81765"
"585.60000","0.78081","39.82909"
"586.40000","0.78186","39.81470"
"587.20000","0.78294","39.82231"
"588.00000","0.78401","39.83378"
"588.80000","0.78506","39.82015"
"589.60000","0.78615","39.82391"
"590.40000","0.78721","39.83572"
"591.20000","0.78826","39.80825"
"592.00000","0.78934","39.82750"
"592.80000","0.79041","39.82399"
"593.60000","0.79146","39.81713"
"594.40000","0.79255","39.80959"
"595.20000","0.79361","39.82795"
"596.00000","0.79466","39.80977"
"596.80000","0.79574","39.81489"
"597.60000","0.79681","39.81584"
"598.40000","0.79786","39.80021"
"599.20000","0.79895","39.80327"
"600.00000","0.80001","39.81094"
"600.80000","0.80106","39.78662"
"601.60000","0.80214","39.79950"
"602.40000","0.80321","39.80625"
"603.20000","0.80427","39.78700"
"604.00000","0.80535","39.80097"
"604.80000","0.80641","39.79965"
"605.60000","0.80746","39.78794"
"606.40000","0.80854","39.78376"
"607.20000","0.80961","39.78980"
"608.00000","0.81066","39.77612"
"608.80000","0.81175","39.79870"
"609.60000","0.81281","39.79197"
"610.40000","0.81386","39.77174"
"611.20000","0.81494","39.77790"
"612.00000","0.81601","39.79378"
"612.80000","0.81706","39.77551"
"613.60000","0.81815","39.78503"
"614.40000","0.81922","39.79873"
"615.20000","0.82026","39.78710"
"616.00000","0.82134","39.78932"
"616.80000","0.82241","39.80829"
"617.60000","0.82346","39.79337"
"618.40000","0.82455","39.80481"
"619.20000","0.82561","39.81309"
"620.00000","0.82666","39.80458"
"620.80000","0.82774","39.80092"
"621.60000","0.82881","39.82725"
"622.40000","0.82986","39.82006"
"623.20000","0.83095","39.82350"
"624.00000","0.83202","39.83680"
"624.80000","0.83306","39.82714"
"625.60000","0.83414","39.82633"
"626.40000","0.83521","39.84384"
"627.20000","0.83626","39.82454"
"628.00000","0.83735","39.83756"
"628.80000","0.83842","39.84458"
"629.60000","0.83946","39.84340"
"630.40000","0.84054","39.83653"
"631.20000","0.84161","39.85501"
"632.00000","0.84266","39.83570"
"632.80000","0.84375","39.85133"
"633.60000","0.84482","39.87153"
"634.40000","0.84586","39.85389"
"635.20000","0.84694","39.85659"
"636.00000","0.84801","39.88042"
"636.80000","0.84907","39.86678"
"637.60000","0.85014","39.87296"
"638.40000","0.85122","39.89512"
"639.20000","0.85226","39.88542"
"640.00000","0.85334","39.89654"
"640.80000","0.85441","39.89441"
"641.60000","0.85547","39.90834"
"642.40000","0.85654","39.90554"
"643.20000","0.85762","39.92054"
"644.00000","0.85866","39.91479"
"644.80000","0.85974","39.92535"
"645.60000","0.86081","39.93784"
"646.40000","0.86187","39.92192"
"647.20000","0.86294","39.93256"
"648.00000","0.86402","39.94764"
"648.80000","0.86506","39.93991"
"649.60000","0.86614","39.94303"
"650.40000","0.86721","39.95944"
"651.20000","0.86827","39.93989"
"652.00000","0.86934","39.94063"
"652.80000","0.87042","39.97907"
"653.60000","0.87146","39.94099"
"654.40000","0.87254","39.95471"
"655.20000","0.87361","39.96823"
"656.00000","0.87467","39.95600"
"656.80000","0.87574","39.96317"
"657.60000","0.87682","39.97139"
"658.40000","0.87786","39.95306"
"659.20000","0.87894","39.96172"
"660.00000","0.88001","39.96769"
"660.80000","0.88107","39.95874"
"661.60000","0.88214","39.96076"
"662.40000","0.88322","39.96445"
"663.20000","0.88426","39.95634"
"664.00000","0.88534","39.96090"
"664.80000","0.88641","39.96563"
"665.60000","0.88747","39.95926"
"666.40000","0.88854","39.95392"
"667.20000","0.88962","39.97438"
"668.00000","0.89066","39.96353"
"668.80000","0.89174","39.95531"
"669.60000","0.89281","39.96428"
"670.40000","0.89387","39.96142"
"671.20000","0.89494","39.96087"
"672.00000","0.89602","39.96726"
"672.80000","0.89706","39.95237"
"673.60000","0.89814","39.96176"
"674.40000","0.89921","39.96530"
"675.20000","0.90026","39.96162"
"676.00000","0.90134","39.95273"
"676.80000","0.90242","39.97100"
"677.60000","0.90346","39.95400"
"678.40000","0.90454","39.95698"
"679.20000","0.90561","39.95705"
"680.00000","0.90667","39.95230"
"680.80000","0.90774","39.95878"
"681.60000","0.90882","39.95996"
"682.40000","0.90986","39.95625"
"683.20000","0.91094","39.94572"
"684.00000","0.91201","39.95157"
"684.80000","0.91307","39.96044"
"685.60000","0.91414","39.94789"
"686.40000","0.91522","39.96306"
"687.20000","0.91626","39.95063"
"688.00000","0.91734","39.94173"
"688.80000","0.91842","39.95958"
"689.60000","0.91947","39.94251"
"690.40000","0.92054","39.93769"
"691.20000","0.92162","39.94751"
"692.00000","0.92266","39.93134"
"692.80000","0.92374","39.92997"
"693.60000","0.92481","39.93556"
"694.40000","0.92587","39.92305"
"695.20000","0.92694","39.91115"
"696.00000","0.92802","39.92619"
"696.80000","0.92906","39.91189"
"697.60000","0.93014","39.91186"
"698.40000","0.93121","39.91900"
"699.20000","0.93227","39.90463"
"700.00000","0.93334","39.90755"
"700.80000","0.93442","39.90347"
"701.60000","0.93546","39.90340"
"702.40000","0.93654","39.89461"
"703.20000","0.93761","39.90900"
"704.00000","0.93867","39.88534"
"704.80000","0.93974","39.89337"
"705.60000","0.94082","39.90777"
"706.40000","0.94186","39.88068"
"707.20000","0.94294","39.88963"
"708.00000","0.94402","39.88551"
"708.80000","0.94507","39.88635"
"709.60000","0.94614","39.87837"
"710.40000","0.94722","39.88387"
"711.20000","0.94826","39.88043"
"712.00000","0.94934","39.86998"
"712.80000","0.95041","39.88079"
"713.60000","0.95147","39.87417"
"714.40000","0.95254","39.86544"
"715.20000","0.95362","39.87360"
"716.00000","0.95466","39.86858"
"716.80000","0.95574","39.87136"
"717.60000","0.95681","39.87350"
"718.40000","0.95787","39.87668"
"719.20000","0.95894","39.86567"
"720.00000","0.96002","39.87692"
"720.80000","0.96106","39.87083"
"721.60000","0.96214","39.86306"
"722.40000","0.96321","39.87161"
"723.20000","0.96427","39.87668"
"724.00000","0.96533","39.86770"
"724.80000","0.96642","39.88224"
"725.60000","0.96746","39.87257"
"726.40000","0.96854","39.87513"
"727.20000","0.96961","39.88035"
"728.00000","0.97067","39.87895"
"728.80000","0.97174","39.87787"
"729.60000","0.97282","39.88204"
"730.40000","0.97386","39.87717"
"731.20000","0.97494","39.87901"
"732.00000","0.97602","39.87941"
"732.80000","0.97707","39.88733"
"733.60000","0.97814","39.87408"
"734.40000","0.97922","39.88422"
"735.20000","0.98026","39.87803"
"736.00000","0.98133","39.86747"
"736.80000","0.98242","39.88086"
"737.60000","0.98347","39.87380"
"738.40000","0.98453","39.87554"
"739.20000","0.98563","39.88429"
"740.00000","0.98666","39.87085"
"740.80000","0.98773","39.87808"
"741.60000","0.98882","39.87565"
"742.40000","0.98987","39.87806"
"743.20000","0.99093","39.86472"
"744.00000","0.99202","39.86816"
"744.80000","0.99306","39.86430"
"745.60000","0.99413","39.87228"
"746.40000","0.99522","39.87523"
"747.20000","0.99627","39.87011"
"748.00000","0.99733","39.86543"
"748.80000","0.99843","39.87502"
"749.60000","0.99946","39.87666"
"750.40000","1.00053","39.85767"
"751.20000","1.00162","39.86408"
"752.00000","1.00267","39.87457"
"752.80000","1.00373","39.86022"
"753.60000","1.00482","39.87852"
"754.40000","1.00586","39.84986"
"755.20000","1.00693","39.86699"
"756.00000","1.00802","39.85828"
"756.80000","1.00907","39.86290"
"757.60000","1.01013","39.84941"
"758.40000","1.01122","39.85569"
"759.20000","1.01226","39.85323"
"760.00000","1.01333","39.83582"
"760.80000","1.01442","39.84547"
"761.60000","1.01547","39.84235"
"762.40000","1.01653","39.83484"
"763.20000","1.01762","39.83560"
"764.00000","1.01866","39.83100"
"764.80000","1.01973","39.83297"
"765.60000","1.02082","39.84680"
"766.40000","1.02187","39.83201"
"767.20000","1.02293","39.81603"
"768.00000","1.02402","39.83208"
"768.80000","1.02506","39.81821"
"769.60000","1.02613","39.81816"
"770.40000","1.02722","39.81792"
"771.20000","1.02827","39.82966"
"772.00000","1.02933","39.81167"
"772.80000","1.03042","39.82160"
"773.60000","1.03146","39.81299"
"774.40000","1.03253","39.81518"
"775.20000","1.03362","39.82300"
"776.00000","1.03467","39.81804"
"776.80000","1.03573","39.81344"
"777.60000","1.03682","39.81353"
"778.40000","1.03787","39.80750"
"779.20000","1.03893","39.80506"
"780.00000","1.04001","39.80426"
"780.80000","1.04107","39.80511"
"781.60000","1.04213","39.79561"
"782.40000","1.04322","39.80121"
"783.20000","1.04426","39.79181"
"784.00000","1.04533","39.77961"
"784.80000","1.04642","39.79091"
"785.60000","1.04747","39.78380"
"786.40000","1.04853","39.77236"
"787.20000","1.04962","39.77307"
"788.00000","1.05066","39.76058"
"788.80000","1.05173","39.77170"
"789.60000","1.05282","39.76636"
"790.40000","1.05388","39.76205"
"791.20000","1.05493","39.75644"
"792.00000","1.05602","39.75214"
"792.80000","1.05707","39.74418"
"793.60000","1.05813","39.74214"
"794.40000","1.05921","39.73728"
"795.20000","1.06028","39.74767"
"796.00000","1.06133","39.73296"
"796.80000","1.06242","39.73330"
"797.60000","1.06347","39.72361"
"798.40000","1.06453","39.72800"
"799.20000","1.06561","39.71987"
"800.00000","1.06668","39.73013"
"800.80000","1.06773","39.71656"
"801.60000","1.06882","39.72339"
"802.40000","1.06987","39.72914"
"803.20000","1.07093","39.71172"
"804.00000","1.07201","39.72136"
"804.80000","1.07308","39.72796"
"805.60000","1.07413","39.71130"
"806.40000","1.07522","39.71554"
"807.20000","1.07627","39.72289"
"808.00000","1.07733","39.71279"
"808.80000","1.07842","39.71979"
"809.60000","1.07948","39.71873"
"810.40000","1.08053","39.70789"
"811.20000","1.08162","39.70704"
"812.00000","1.08267","39.71579"
"812.80000","1.08373","39.70187"
"813.60000","1.08481","39.70270"
"814.40000","1.08588","39.71487"
"815.20000","1.08693","39.71348"
"816.00000","1.08801","39.70238"
"816.80000","1.08907","39.70428"
"817.60000","1.09013","39.69772"
"818.40000","1.09121","39.69984"
"819.20000","1.09228","39.69500"
"820.00000","1.09334","39.70159"
"820.80000","1.09441","39.68811"
"821.60000","1.09547","39.68617"
"822.40000","1.09653","39.68550"
"823.20000","1.09761","39.68578"
"824.00000","1.09868","39.69911"
"824.80000","1.09973","39.68241"
"825.60000","1.10081","39.67196"
"826.40000","1.10187","39.68550"
"827.20000","1.10293","39.67700"
"828.00000","1.10401","39.68129"
"828.80000","1.10508","39.69068"
"829.60000","1.10613","39.68624"
"830.40000","1.10721","39.68258"
"831.20000","1.10827","39.69014"
"832.00000","1.10933","39.69450"
"832.80000","1.11041","39.68804"
"833.60000","1.11148","39.69140"
"834.40000","1.11253","39.68918"
"835.20000","1.11361","39.69500"
"836.00000","1.11467","39.69052"
"836.80000","1.11573","39.68197"
"837.60000","1.11681","39.69722"
"838.40000","1.11788","39.70628"
"839.20000","1.11893","39.69620"
"840.00000","1.12001","39.69379"
"840.80000","1.12107","39.71080"
"841.60000","1.12213","39.71116"
"842.40000","1.12321","39.70398"
"843.20000","1.12428","39.71644"
"844.00000","1.12533","39.71125"
"844.80000","1.12641","39.70819"
"845.60000","1.12747","39.70391"
"846.40000","1.12853","39.70720"
"847.20000","1.12961","39.71004"
"848.00000","1.13068","39.71535"
"848.80000","1.13173","39.70388"
"849.60000","1.13281","39.70550"
"850.40000","1.13387","39.71090"
"851.20000","1.13493","39.70677"
"852.00000","1.13601","39.70885"
"852.80000","1.13708","39.71249"
"853.60000","1.13813","39.69511"
"854.40000","1.13921","39.68736"
"855.20000","1.14027","39.69938"
"856.00000","1.14133","39.69807"
"856.80000","1.14241","39.69130"
"857.60000","1.14348","39.70007"
"858.40000","1.14454","39.69820"
"859.20000","1.14561","39.68507"
"860.00000","1.14667","39.68617"
"860.80000","1.14773","39.68718"
"861.60000","1.14881","39.67915"
"862.40000","1.14989","39.69529"
"863.20000","1.15094","39.68342"
"864.00000","1.15200","39.66555"
"864.80000","1.15307","39.67831"
"865.60000","1.15413","39.68183"
"866.40000","1.15521","39.67774"
"867.20000","1.15628","39.68060"
"868.00000","1.15734","39.67647"
"868.80000","1.15840","39.67143"
"869.60000","1.15947","39.67791"
"870.40000","1.16053","39.67230"
"871.20000","1.16161","39.67956"
"872.00000","1.16269","39.67977"
"872.80000","1.16373","39.67110"
"873.60000","1.16480","39.67352"
"874.40000","1.16587","39.68512"
"875.20000","1.16693","39.68030"
"876.00000","1.16801","39.67830"
"876.80000","1.16908","39.68761"
"877.60000","1.17014","39.68390"
"878.40000","1.17120","39.68237"
"879.20000","1.17228","39.68217"
"880.00000","1.17333","39.68991"
"880.80000","1.17440","39.69223"
"881.60000","1.17548","39.70038"
"882.40000","1.17654","39.69536"
"883.20000","1.17760","39.70350"
"884.00000","1.17867","39.69713"
"884.80000","1.17973","39.69797"
"885.60000","1.18080","39.69983"
"886.40000","1.18188","39.70848"
"887.20000","1.18294","39.70105"
"888.00000","1.18400","39.70042"
"888.80000","1.18507","39.70609"
"889.60000","1.18613","39.70724"
"890.40000","1.18720","39.70426"
"891.20000","1.18829","39.71561"
"892.00000","1.18933","39.71191"
"892.80000","1.19040","39.70904"
"893.60000","1.19148","39.70336"
"894.40000","1.19253","39.71352"
"895.20000","1.19360","39.71349"
"896.00000","1.19468","39.71875"
"896.80000","1.19574","39.71616"
"897.60000","1.19680","39.71559"
"898.40000","1.19787","39.71241"
"899.20000","1.19893","39.70782"
"900.00000","1.20000","39.70969"
"900.80000","1.20109","39.72144"
"901.60000","1.20214","39.72669"
"902.40000","1.20320","39.70702"
"903.20000","1.20428","39.70988"
"904.00000","1.20533","39.71372"
"904.80000","1.20641","39.70585"
"905.60000","1.20749","39.71940"
"906.40000","1.20854","39.71226"
"907.20000","1.20960","39.70518"
"908.00000","1.21067","39.70617"
"908.80000","1.21173","39.70427"
"909.60000","1.21281","39.70659"
"910.40000","1.21388","39.71212"
"911.20000","1.21494","39.69967"
"912.00000","1.21600","39.69235"
"912.80000","1.21707","39.69299"
"913.60000","1.21813","39.69312"
"914.40000","1.21920","39.68132"
"915.20000","1.22029","39.68980"
"916.00000","1.22134","39.68863"
"916.80000","1.22240","39.67063"
"917.60000","1.22348","39.68501"
"918.40000","1.22454","39.67975"
"919.20000","1.22560","39.67871"
"920.00000","1.22668","39.68389"
"920.80000","1.22774","39.68066"
"921.60000","1.22880","39.67175"
"922.40000","1.22987","39.67194"
"923.20000","1.23094","39.66648"
"924.00000","1.23200","39.66114"
"924.80000","1.23309","39.67483"
"925.60000","1.23414","39.66213"
"926.40000","1.23520","39.64751"
"927.20000","1.23628","39.66139"
"928.00000","1.23733","39.65856"
"928.80000","1.23840","39.65694"
"929.60000","1.23949","39.65634"
"930.40000","1.24054","39.66246"
"931.20000","1.24160","39.65197"
"932.00000","1.24267","39.65112"
"932.80000","1.24374","39.64527"
"933.60000","1.24480","39.64689"
"934.40000","1.24589","39.65467"
"935.20000","1.24694","39.64820"
"936.00000","1.24800","39.64086"
"936.80000","1.24907","39.65378"
"937.60000","1.25014","39.65088"
"938.40000","1.25120","39.63566"
"939.20000","1.25228","39.65410"
"940.00000","1.25334","39.65842"
"940.80000","1.25439","39.64294"
"941.60000","1.25548","39.65857"
"942.40000","1.25654","39.65519"
"943.20000","1.25760","39.63631"
"944.00000","1.25868","39.66459"
"944.80000","1.25974","39.65814"
"945.60000","1.26080","39.64812"
"946.40000","1.26187","39.66256"
"947.20000","1.26294","39.66715"
"948.00000","1.26400","39.65983"
"948.80000","1.26509","39.66622"
"949.60000","1.26614","39.67553"
"950.40000","1.26720","39.66448"
"951.20000","1.26828","39.66775"
"952.00000","1.26934","39.67867"
"952.80000","1.27040","39.67705"
"953.60000","1.27149","39.67898"
"954.40000","1.27254","39.68612"
"955.20000","1.27359","39.68562"
"956.00000","1.27468","39.69221"
"956.80000","1.27574","39.69881"
"957.60000","1.27680","39.69049"
"958.40000","1.27788","39.71215"
"959.20000","1.27894","39.72394"
"960.00000","1.27999","39.70636"
"960.80000","1.28108","39.71381"
"961.60000","1.28214","39.71655"
"962.40000","1.28320","39.71825"
"963.20000","1.28429","39.72303"
"964.00000","1.28534","39.73596"
"964.80000","1.28639","39.73020"
"965.60000","1.28748","39.72292"
"966.40000","1.28854","39.73611"
"967.20000","1.28960","39.72320"
"968.00000","1.29069","39.71570"
"968.80000","1.29174","39.73315"
"969.60000","1.29279","39.71484"
"970.40000","1.29388","39.71673"
"971.20000","1.29494","39.72459"
"972.00000","1.29600","39.71016"
"972.80000","1.29709","39.70554"
"973.60000","1.29814","39.71857"
"974.40000","1.29919","39.69172"
"975.20000","1.30028","39.70126"
"976.00000","1.30134","39.69976"
"976.80000","1.30240","39.69136"
"977.60000","1.30349","39.69865"
"978.40000","1.30455","39.68400"
"979.20000","1.30559","39.67950"
"980.00000","1.30668","39.68891"
"980.80000","1.30774","39.68269"
"981.60000","1.30880","39.67880"
"982.40000","1.30988","39.68464"
"983.20000","1.31094","39.68176"
"984.00000","1.31199","39.67479"
"984.80000","1.31308","39.68225"
"985.60000","1.31414","39.67376"
"986.40000","1.31520","39.67928"
"987.20000","1.31628","39.68461"
"988.00000","1.31734","39.68112"
"988.80000","1.31839","39.66908"
"989.60000","1.31948","39.67795"
"990.40000","1.32054","39.67926"
"991.20000","1.32160","39.67303"
"992.00000","1.32268","39.66918"
"992.80000","1.32374","39.68236"
"993.60000","1.32479","39.66722"
"994.40000","1.32588","39.65603"
"995.20000","1.32694","39.67536"
"996.00000","1.32800","39.66957"
"996.80000","1.32908","39.66393"
"997.60000","1.33015","39.67089"
"998.40000","1.33119","39.65951"
"999.20000","1.33228","39.65970"
"1,000.00000","1.33334","39.66403"
"1,000.80000","1.33440","39.66302"
"1,001.60000","1.33548","39.65886"
"1,002.40000","1.33655","39.66446"
"1,003.20000","1.33759","39.64973"
"1,004.00000","1.33867","39.65102"
"1,004.80000","1.33974","39.65726"
"1,005.60000","1.34080","39.64311"
"1,006.40000","1.34188","39.64696"
"1,007.20000","1.34295","39.66263"
"1,008.00000","1.34399","39.64045"
"1,008.80000","1.34507","39.64441"
"1,009.60000","1.34614","39.64288"
"1,010.40000","1.34720","39.63841"
"1,011.20000","1.34828","39.62965"
"1,012.00000","1.34935","39.64572"
"1,012.80000","1.35039","39.62158"
"1,013.60000","1.35148","39.62367"
"1,014.40000","1.35254","39.63417"
"1,015.20000","1.35359","39.61737"
"1,016.00000","1.35468","39.62604"
"1,016.80000","1.35575","39.63486"
"1,017.60000","1.35679","39.61979"
"1,018.40000","1.35787","39.61916"
"1,019.20000","1.35895","39.62051"
"1,020.00000","1.36000","39.62000"
"1,020.80000","1.36108","39.61753"
"1,021.60000","1.36215","39.62387"
"1,022.40000","1.36319","39.60919"
"1,023.20000","1.36427","39.60708"
"1,024.00000","1.36535","39.61330"
"1,024.80000","1.36640","39.60511"
"1,025.60000","1.36748","39.60722"
"1,026.40000","1.36855","39.61385"
"1,027.20000","1.36959","39.59434"
"1,028.00000","1.37067","39.61049"
"1,028.80000","1.37175","39.60140"
"1,029.60000","1.37280","39.58682"
"1,030.40000","1.37388","39.58855"
"1,031.20000","1.37495","39.61289"
"1,032.00000","1.37599","39.56847"
"1,032.80000","1.37707","39.59041"
"1,033.60000","1.37815","39.59510"
"1,034.40000","1.37920","39.58227"
"1,035.20000","1.38028","39.58418"
"1,036.00000","1.38136","39.60182"
"1,036.80000","1.38239","39.57787"
"1,037.60000","1.38347","39.58154"
"1,038.40000","1.38455","39.58664"
"1,039.20000","1.38560","39.57685"
"1,040.00000","1.38668","39.57191"
"1,040.80000","1.38775","39.58971"
"1,041.60000","1.38879","39.57495"
"1,042.40000","1.38987","39.57719"
"1,043.20000","1.39095","39.58530"
"1,044.00000","1.39200","39.58607"
"1,044.80000","1.39308","39.58637"
"1,045.60000","1.39415","39.60132"
"1,046.40000","1.39519","39.59341"
"1,047.20000","1.39627","39.59135"
"1,048.00000","1.39735","39.60449"
"1,048.80000","1.39840","39.60094"
"1,049.60000","1.39948","39.61132"
"1,050.40000","1.40056","39.61396"
"1,051.20000","1.40159","39.61151"
"1,052.00000","1.40267","39.62133"
"1,052.80000","1.40374","39.62095"
"1,053.60000","1.40480","39.63275"
"1,054.40000","1.40587","39.61680"
"1,055.20000","1.40695","39.63393"
"1,056.00000","1.40799","39.61322"
"1,056.80000","1.40907","39.62173"
"1,057.60000","1.41015","39.64272"
"1,058.40000","1.41120","39.62452"
"1,058.88200","1.41184","39.62716"