File: materials_lab1/ENGR314_FA19_0002_oakwood_A_20190903_TheSeniors.is_tens_RawData/Specimen_RawData_1.csv
Material,Acrylic
Geometry,Circular
Length,"2.00000",in
Diameter,"0.25300",in

Time,Extension,Load
(s),(in),(lbf)
"0.00000","0.00000","1.09192"
"0.38700","0.00052","14.81333"
"0.78700","0.00104","29.59472"
"1.12600","0.00150","30.42645"
"1.52600","0.00203","44.51267"
"1.92600","0.00258","58.57234"
"2.32600","0.00311","70.81821"
"2.72600","0.00362","82.46355"
"3.12600","0.00417","94.12285"
"3.52600","0.00471","104.80699"
"3.92600","0.00524","114.54491"
"4.32600","0.00577","123.54768"
"4.72600","0.00631","131.50824"
"5.12600","0.00683","138.75241"
"5.52600","0.00737","145.63550"
"5.92600","0.00790","151.13492"
"6.32600","0.00843","156.21598"
"6.72600","0.00898","161.38155"
"7.12600","0.00951","165.07425"
"7.52600","0.01002","168.35400"
"7.92600","0.01057","172.40401"
"8.32600","0.01111","175.13263"
"8.72600","0.01163","176.70361"
"9.12600","0.01217","178.72504"
"9.52600","0.01271","180.21558"
"9.92600","0.01322","181.88806"
"10.32600","0.01377","184.16801"
"10.72600","0.01430","185.85294"
"11.12600","0.01484","187.71645"
"11.52600","0.01538","190.06928"
"11.92600","0.01591","191.45674"
"12.32600","0.01642","192.59984"
"12.72600","0.01697","194.59600"
"13.12600","0.01751","196.07725"
"13.52600","0.01804","197.37256"
"13.92600","0.01858","198.97002"
"14.32600","0.01910","199.91792"
"14.72600","0.01963","201.23774"
"15.12600","0.02018","202.87659"
"15.52600","0.02070","203.82657"
"15.92600","0.02123","204.97797"
"16.32600","0.02179","206.69906"
"16.72600","0.02231","207.48567"
"17.12600","0.02282","208.18471"
"17.52600","0.02337","209.38857"
"17.92600","0.02391","210.47125"
"18.32600","0.02443","211.09539"
"18.72600","0.02498","212.19373"
"19.12600","0.02551","212.64413"
"19.52600","0.02603","213.48319"
"19.92600","0.02658","214.75885"
"20.32600","0.02710","215.20557"
"20.72600","0.02763","215.94749"
"21.12600","0.02819","217.27450"
"21.52600","0.02871","217.36856"
"21.92600","0.02922","217.59794"
"22.32600","0.02977","218.53174"
"22.72600","0.03031","219.18140"
"23.12600","0.03084","219.63688"
"23.52600","0.03138","220.46925"
"23.92600","0.03191","220.61598"
"24.32600","0.03242","221.05955"
"24.72600","0.03297","221.94706"
"25.12600","0.03350","221.99880"
"25.52600","0.03404","222.39086"
"25.92600","0.03459","223.20310"
"26.32600","0.03511","223.05874"
"26.72600","0.03562","223.11837"
"27.12600","0.03617","223.91745"
"27.52600","0.03671","224.16688"
"27.92600","0.03723","224.30755"
"28.32600","0.03778","224.78969"
"28.72600","0.03830","224.45048"
"29.12600","0.03883","224.53916"
"29.52600","0.03937","225.15430"
"29.92600","0.03990","225.20843"
"30.32600","0.04043","225.52744"
"30.72600","0.04098","226.25778"
"31.12600","0.04151","226.24690"
"31.52600","0.04202","226.17847"
"31.92600","0.04257","226.80320"
"32.32600","0.04311","227.14454"
"32.72600","0.04363","227.50369"
"33.12600","0.04418","228.16978"
"33.52600","0.04470","227.89634"
"33.92600","0.04523","228.06809"
"34.32600","0.04578","228.55119"
"34.72600","0.04630","228.27881"
"35.12600","0.04683","228.37896"
"35.52600","0.04739","229.10595"
"35.92600","0.04791","228.75504"
"36.32600","0.04842","228.62613"
"36.72600","0.04897","228.94887"
"37.12600","0.04951","229.05680"
"37.52600","0.05004","229.01527"
"37.92600","0.05058","229.16685"
"38.32600","0.05110","228.77040"
"38.72600","0.05162","228.90994"
"39.12600","0.05218","229.59794"
"39.52600","0.05270","229.42494"
"39.92600","0.05323","229.53069"
"40.32600","0.05379","230.34863"
"40.72600","0.05430","230.00454"
"41.12600","0.05482","229.79355"
"41.52600","0.05537","230.19989"
"41.92600","0.05591","230.41309"
"42.32600","0.05644","230.57874"
"42.72600","0.05698","230.77964"
"43.12600","0.05750","230.37659"
"43.52600","0.05802","230.56032"
"43.92600","0.05858","231.20846"
"44.32600","0.05910","230.90544"
"44.72600","0.05963","231.14391"
"45.12600","0.06019","231.71968"
"45.52600","0.06071","231.31944"
"45.92600","0.06122","231.19789"
"46.32600","0.06177","231.82023"
"46.72600","0.06231","231.86593"
"47.12600","0.06283","231.75267"
"47.52600","0.06338","231.83791"
"47.92600","0.06390","231.20138"
"48.32600","0.06443","231.06268"
"48.72600","0.06498","231.32418"
"49.12600","0.06550","230.73019"
"49.52600","0.06603","230.59688"
"49.92600","0.06659","230.98842"
"50.32600","0.06711","230.23559"
"50.72600","0.06762","229.66184"
"51.12600","0.06817","229.66818"
"51.52600","0.06871","229.32378"
"51.92600","0.06924","229.29193"
"52.32600","0.06978","229.43662"
"52.72600","0.07029","228.78627"
"53.12600","0.07083","228.85557"
"53.52600","0.07138","229.00990"
"53.92600","0.07190","228.25180"
"54.32600","0.07243","228.02756"
"54.72600","0.07298","228.11421"
"55.12600","0.07350","227.50028"
"55.52600","0.07402","227.03377"
"55.92600","0.07457","226.74251"
"56.32600","0.07511","226.36054"
"56.72600","0.07564","226.21973"
"57.12600","0.07618","226.28577"
"57.52600","0.07670","225.39938"
"57.92600","0.07722","225.08804"
"58.32600","0.07778","225.17620"
"58.72600","0.07830","224.26641"
"59.12600","0.07883","223.99626"
"59.52600","0.07939","224.23973"
"59.92600","0.07990","223.27894"
"60.32600","0.08042","222.88920"
"60.72600","0.08097","222.98652"
"61.12600","0.08151","222.96871"
"61.52600","0.08204","223.13574"
"61.92600","0.08258","223.31521"
"62.32600","0.08310","222.63990"
"62.72600","0.08363","222.69873"
"63.12600","0.08418","223.17633"
"63.52600","0.08470","222.69910"
"63.92600","0.08523","222.91798"
"64.32600","0.08579","223.70834"
"64.72600","0.08630","223.47172"
"65.12600","0.08682","223.55281"
"65.52600","0.08737","223.99460"
"65.92600","0.08791","224.10858"
"66.32600","0.08844","224.66447"
"66.72600","0.08898","225.30632"
"67.12600","0.08949","225.06389"
"67.52600","0.09003","225.69710"
"67.92600","0.09058","226.53231"
"68.32600","0.09110","226.58497"
"68.72600","0.09164","227.04755"
"69.12600","0.09219","228.03810"
"69.52600","0.09271","228.17053"
"69.92600","0.09322","228.47731"
"70.32600","0.09377","229.31690"
"70.72600","0.09431","229.69013"
"71.12600","0.09484","229.85510"
"71.52600","0.09538","229.94191"
"71.92600","0.09589","229.85535"
"72.32600","0.09643","230.46625"
"72.72600","0.09698","231.06889"
"73.12600","0.09750","230.76861"
"73.52600","0.09804","231.27298"
"73.92600","0.09859","231.89894"
"74.32600","0.09910","231.71768"
"74.72600","0.09963","231.77103"
"75.12600","0.10017","232.21176"
"75.52600","0.10071","232.12553"
"75.92600","0.10124","232.34326"
"76.32600","0.10178","232.58969"
"76.72600","0.10229","232.09965"
"77.12600","0.10283","232.58876"
"77.52600","0.10338","233.39565"
"77.92600","0.10390","233.17348"
"78.32600","0.10443","233.64296"
"78.72600","0.10499","234.61322"
"79.12600","0.10550","234.34322"
"79.52600","0.10603","234.21937"
"79.92600","0.10657","234.31297"
"80.32600","0.10710","234.32691"
"80.72600","0.10764","234.65573"
"81.12600","0.10818","234.76012"
"81.52600","0.10869","234.27889"
"81.92600","0.10923","234.53507"
"82.32600","0.10978","234.99926"
"82.72600","0.11030","234.54086"
"83.12600","0.11083","234.62963"
"83.52600","0.11139","235.22456"
"83.92600","0.11190","234.82521"
"84.32600","0.11242","235.05617"
"84.72600","0.11297","235.57980"
"85.12600","0.11350","235.70694"
"85.52600","0.11404","235.91040"
"85.92600","0.11458","236.12036"
"86.32600","0.11509","235.47236"
"86.72600","0.11563","235.88227"
"87.12600","0.11618","236.49144"
"87.52600","0.11670","236.32635"
"87.92600","0.11724","236.89482"
"88.32600","0.11779","237.67298"
"88.72600","0.11830","237.74512"
"89.12600","0.11883","238.02158"
"89.52600","0.11937","238.52328"
"89.92600","0.11991","238.68113"
"90.32600","0.12044","239.31560"
"90.72600","0.12098","239.89623"
"91.12600","0.12149","239.77098"
"91.52600","0.12203","240.32079"
"91.92600","0.12258","240.95033"
"92.32600","0.12310","240.86528"
"92.72600","0.12364","241.35063"
"93.12600","0.12418","241.67991"
"93.52600","0.12470","241.25617"
"93.92600","0.12523","241.40271"
"94.32600","0.12577","242.02547"
"94.72600","0.12630","242.31529"
"95.12600","0.12684","243.01823"
"95.52600","0.12738","243.41719"
"95.92600","0.12789","242.86795"
"96.32600","0.12843","243.40610"
"96.72600","0.12898","244.03434"
"97.12600","0.12950","243.64861"
"97.52600","0.13003","243.95001"
"97.92600","0.13058","244.37965"
"98.32600","0.13110","244.17067"
"98.72600","0.13163","244.17668"
"99.12600","0.13217","244.22594"
"99.52600","0.13270","244.03305"
"99.92600","0.13324","244.45322"
"100.32600","0.13378","244.61242"
"100.72600","0.13429","244.02575"
"101.12600","0.13483","244.61135"
"101.52600","0.13538","245.16722"
"101.92600","0.13590","244.74477"
"102.32600","0.13644","245.08207"
"102.72600","0.13698","245.50287"
"103.12600","0.13750","245.08885"
"103.52600","0.13803","245.18193"
"103.92600","0.13857","245.20095"
"104.32600","0.13910","245.15989"
"104.72600","0.13964","245.61541"
"105.12600","0.14018","245.93836"
"105.52600","0.14069","245.31766"
"105.92600","0.14123","245.62010"
"106.32600","0.14178","245.90781"
"106.72600","0.14230","245.39584"
"107.12600","0.14284","245.55142"
"107.52600","0.14339","245.67419"
"107.92600","0.14390","245.01431"
"108.32600","0.14443","244.71881"
"108.72600","0.14497","244.62745"
"109.12600","0.14550","244.35632"
"109.52600","0.14604","244.43261"
"109.92600","0.14658","244.28750"
"110.32600","0.14709","243.44427"
"110.72600","0.14763","243.90267"
"111.12600","0.14818","244.22641"
"111.52600","0.14870","243.52539"
"111.92600","0.14924","243.39564"
"112.32600","0.14978","243.41749"
"112.72600","0.15030","242.88063"
"113.12600","0.15083","242.95744"
"113.52600","0.15137","243.27995"
"113.92600","0.15190","243.30053"
"114.32600","0.15244","243.77501"
"114.72600","0.15298","243.85086"
"115.12600","0.15349","243.29652"
"115.52600","0.15403","243.92325"
"115.92600","0.15458","244.60213"
"116.32600","0.15510","244.32979"
"116.72600","0.15564","244.53399"
"117.12600","0.15618","244.82589"
"117.52600","0.15669","244.66651"
"117.92600","0.15723","244.83047"
"118.32600","0.15777","244.94142"
"118.72600","0.15830","244.97663"
"119.12600","0.15885","245.45715"
"119.52600","0.15938","245.57257"
"119.92600","0.15989","245.03594"
"120.32600","0.16043","245.52946"
"120.72600","0.16098","246.28004"
"121.12600","0.16150","246.00597"
"121.52600","0.16203","246.54140"
"121.92600","0.16258","247.21860"
"122.32600","0.16310","247.14890"
"122.72600","0.16363","247.76630"
"123.12600","0.16417","248.27939"
"123.52600","0.16470","248.61792"
"123.92600","0.16525","249.50338"
"124.32600","0.16578","249.86557"
"124.72600","0.16629","249.63439"
"125.12600","0.16683","250.38969"
"125.52600","0.16738","251.11077"
"125.92600","0.16790","250.99464"
"126.32600","0.16844","251.60833"
"126.72600","0.16898","252.18342"
"127.12600","0.16950","251.98418"
"127.52600","0.17003","252.28899"
"127.92600","0.17057","252.45515"
"128.32600","0.17110","252.59494"
"128.72600","0.17164","253.28949"
"129.12600","0.17218","253.57053"
"129.52600","0.17269","252.99876"
"129.92600","0.17323","253.56759"
"130.32600","0.17378","253.99566"
"130.72600","0.17430","254.05486"
"131.12600","0.17484","254.55217"
"131.52600","0.17538","254.97146"
"131.92600","0.17590","254.95121"
"132.32600","0.17643","255.59699"
"132.72600","0.17697","256.19814"
"133.12600","0.17751","256.73648"
"133.52600","0.17804","257.58415"
"133.92600","0.17858","257.98416"
"134.32600","0.17909","257.75408"
"134.72600","0.17963","258.31503"
"135.12600","0.18018","258.93372"
"135.52600","0.18070","258.69313"
"135.92600","0.18124","259.16860"
"136.32600","0.18178","259.54297"
"136.72600","0.18230","259.48973"
"137.12600","0.18283","260.12868"
"137.52600","0.18337","260.50335"
"137.92600","0.18390","260.98340"
"138.32600","0.18445","262.11359"
"138.72600","0.18498","262.59990"
"139.12600","0.18549","262.32221"
"139.52600","0.18603","263.22526"
"139.92600","0.18658","264.13413"
"140.32600","0.18710","264.15559"
"140.72600","0.18764","264.74977"
"141.12600","0.18818","265.33553"
"141.52600","0.18870","265.51086"
"141.92600","0.18923","266.33236"
"142.32600","0.18977","266.82874"
"142.72600","0.19030","267.20028"
"143.12600","0.19085","268.39175"
"143.52600","0.19138","268.90053"
"143.92600","0.19189","269.04280"
"144.32600","0.19243","270.13967"
"144.72600","0.19298","271.18166"
"145.12600","0.19350","271.34426"
"145.52600","0.19404","272.07945"
"145.92600","0.19458","272.56040"
"146.32600","0.19510","272.65859"
"146.72600","0.19563","273.37262"
"147.12600","0.19617","273.99449"
"147.52600","0.19670","274.40638"
"147.92600","0.19725","275.57576"
"148.32600","0.19778","276.01758"
"148.72600","0.19829","275.95726"
"149.12600","0.19883","277.08438"
"149.52600","0.19938","277.74124"
"149.92600","0.19990","277.98068"
"150.32600","0.20044","278.79325"
"150.72600","0.20098","279.21809"
"151.12600","0.20150","279.36524"
"151.52600","0.20203","280.19499"
"151.92600","0.20257","280.75709"
"152.32600","0.20310","281.25586"
"152.72600","0.20365","282.31289"
"153.12600","0.20418","282.72974"
"153.52600","0.20469","282.58564"
"153.92600","0.20523","283.49950"
"154.32600","0.20578","284.13960"
"154.72600","0.20630","284.35675"
"155.12600","0.20684","285.02465"
"155.52600","0.20737","285.26353"
"155.92600","0.20790","285.40950"
"156.32600","0.20843","286.02600"
"156.72600","0.20897","286.17484"
"157.12600","0.20950","286.38365"
"157.52600","0.21005","287.45303"
"157.92600","0.21057","287.59170"
"158.32600","0.21109","287.50753"
"158.72600","0.21163","288.17655"
"159.12600","0.21218","288.93603"
"159.52600","0.21270","288.85458"
"159.92600","0.21324","289.49558"
"160.32600","0.21378","289.67799"
"160.72600","0.21430","289.66891"
"161.12600","0.21484","290.07816"
"161.52600","0.21537","289.99448"
"161.92600","0.21590","290.00121"
"162.32600","0.21645","290.77566"
"162.72600","0.21698","290.62297"
"163.12600","0.21749","290.15019"
"163.52600","0.21803","290.73642"
"163.92600","0.21858","291.21554"
"164.32600","0.21910","291.02124"
"164.72600","0.21964","291.46299"
"165.12600","0.22018","291.58178"
"165.52600","0.22069","291.43779"
"165.92600","0.22123","292.02748"
"166.32600","0.22177","292.10871"
"166.72600","0.22230","292.33149"
"167.12600","0.22285","293.21607"
"167.52600","0.22338","293.26061"
"167.92600","0.22389","293.02134"
"168.32600","0.22443","293.94628"
"168.72600","0.22498","294.48034"
"169.12600","0.22550","294.80886"
"169.52600","0.22604","295.62308"
"169.92600","0.22658","296.07094"
"170.32600","0.22710","296.21098"
"170.72600","0.22763","296.92489"
"171.12600","0.22817","297.31869"
"171.52600","0.22870","297.82331"
"171.92600","0.22925","298.84941"
"172.32600","0.22978","299.25921"
"172.72600","0.23029","299.18544"
"173.12600","0.23083","300.20795"
"173.52600","0.23138","301.04492"
"173.92600","0.23190","301.30301"
"174.32600","0.23244","302.07140"
"174.72600","0.23297","302.24816"
"175.12600","0.23350","302.56811"
"175.52600","0.23404","303.40042"
"175.92600","0.23457","303.60335"
"176.32600","0.23510","303.86913"
"176.72600","0.23565","305.09164"
"177.12600","0.23618","305.18231"
"177.52600","0.23669","305.05374"
"177.92600","0.23723","305.81154"
"178.32600","0.23778","306.55512"
"178.72600","0.23830","306.76358"
"179.12600","0.23884","307.50329"
"179.52600","0.23938","307.69160"
"179.92600","0.23989","307.91210"
"180.32600","0.24044","308.72646"
"180.72600","0.24097","308.84833"
"181.12600","0.24150","309.21197"
"181.52600","0.24205","310.37707"
"181.92600","0.24257","310.30385"
"182.32600","0.24309","310.31529"
"182.72600","0.24363","311.18728"
"183.12600","0.24418","311.77054"
"183.52600","0.24470","312.07299"
"183.92600","0.24524","312.87461"
"184.32600","0.24578","313.21042"
"184.72600","0.24629","313.57876"
"185.12600","0.24684","314.53891"
"185.52600","0.24737","314.78263"
"185.92600","0.24790","315.31095"
"186.32600","0.24845","316.37430"
"186.72600","0.24898","316.46178"
"187.12600","0.24949","316.22509"
"187.52600","0.25003","317.05053"
"187.92600","0.25058","317.47416"
"188.32600","0.25110","317.67282"
"188.72600","0.25164","318.42982"
"189.12600","0.25218","318.59645"
"189.52600","0.25270","318.61629"
"189.92600","0.25324","319.13872"
"190.32600","0.25377","319.12085"
"190.72600","0.25430","319.36451"
"191.12600","0.25485","320.09662"
"191.52600","0.25538","319.93960"
"191.92600","0.25589","319.55189"
"192.32600","0.25643","319.92777"
"192.72600","0.25698","319.30178"
"193.12600","0.25750","318.33298"
"193.52600","0.25804","317.16634"
"193.92600","0.25857","314.49509"
"194.32600","0.25910","309.82910"
"194.72600","0.25964","305.96044"
"195.12600","0.26017","302.67261"
"195.52600","0.26070","299.83495"
"195.92600","0.26125","297.89526"
"196.32600","0.26178","296.41240"
"196.72600","0.26229","294.42571"
"197.12600","0.26283","294.02463"
"197.52600","0.26339","293.90973"
"197.92600","0.26390","293.69820"
"198.32600","0.26444","294.12477"
"198.72600","0.26497","293.88479"
"199.12600","0.26549","293.70592"
"199.52600","0.26604","294.31086"
"199.92600","0.26657","294.52343"
"200.32600","0.26710","295.12796"
"200.72600","0.26765","296.82687"
"201.12600","0.26818","297.44518"
"201.52600","0.26869","297.89619"
"201.92600","0.26924","299.06417"
"202.32600","0.26978","299.99431"
"202.72600","0.27030","300.63174"
"203.12600","0.27084","301.58364"
"203.52600","0.27137","301.75787"
"203.92600","0.27189","302.02459"
"204.32600","0.27244","302.56858"
"204.72600","0.27297","302.52448"
"205.12600","0.27350","302.93315"
"205.52600","0.27405","304.25605"
"205.92600","0.27458","304.96810"
"206.32600","0.27509","306.24919"
"206.72600","0.27563","307.75129"
"207.12600","0.27618","308.77390"
"207.52600","0.27670","309.40160"
"207.92600","0.27724","310.50632"
"208.32600","0.27777","310.88536"
"208.72600","0.27830","311.74752"
"209.12600","0.27884","312.90309"
"209.52600","0.27937","313.43260"
"209.92600","0.27990","314.29089"
"210.32600","0.28045","315.77723"
"210.72600","0.28098","316.28217"
"211.12600","0.28149","316.66211"
"211.52600","0.28204","317.94222"
"211.92600","0.28258","318.79162"
"212.32600","0.28310","319.51328"
"212.72600","0.28364","320.65346"
"213.12600","0.28417","321.07270"
"213.52600","0.28469","321.70533"
"213.92600","0.28524","322.89795"
"214.32600","0.28577","323.43157"
"214.72600","0.28630","324.25394"
"215.12600","0.28685","325.33103"
"215.52600","0.28738","325.63874"
"215.92600","0.28789","325.88844"
"216.32600","0.28843","326.91899"
"216.72600","0.28898","327.68884"
"217.12600","0.28950","328.35374"
"217.52600","0.29004","329.32164"
"217.92600","0.29057","329.50048"
"218.32600","0.29109","330.19744"
"218.72600","0.29164","331.20378"
"219.12600","0.29217","331.55644"
"219.52600","0.29270","332.19039"
"219.92600","0.29325","333.55569"
"220.32600","0.29378","333.75700"
"220.72600","0.29429","333.97649"
"221.12600","0.29483","334.86428"
"221.52600","0.29538","335.66887"
"221.92600","0.29590","336.22406"
"222.32600","0.29644","337.03010"
"222.72600","0.29697","337.14505"
"223.12600","0.29749","337.67494"
"223.52600","0.29804","338.75167"
"223.92600","0.29857","338.92717"
"224.32600","0.29909","339.38562"
"224.72600","0.29966","340.60209"
"225.12600","0.30017","340.59957"
"225.52600","0.30069","340.72715"
"225.92600","0.30123","341.61055"
"226.32600","0.30178","342.23454"
"226.72600","0.30230","342.81819"
"227.12600","0.30285","343.57274"
"227.52600","0.30337","343.36566"
"227.92600","0.30389","343.70738"
"228.32600","0.30444","344.53202"
"228.72600","0.30497","344.54492"
"229.12600","0.30550","345.14575"
"229.52600","0.30605","346.14743"
"229.92600","0.30657","346.17405"
"230.32600","0.30709","346.29828"
"230.72600","0.30764","347.32586"
"231.12600","0.30818","347.78547"
"231.52600","0.30870","348.33668"
"231.92600","0.30925","349.08210"
"232.32600","0.30977","348.98981"
"232.72600","0.31029","349.37145"
"233.12600","0.31084","350.22159"
"233.52600","0.31137","350.34874"
"233.92600","0.31190","350.97983"
"234.32600","0.31245","351.91595"
"234.72600","0.31298","352.03263"
"235.12600","0.31349","352.14015"
"235.52600","0.31404","352.85328"
"235.92600","0.31458","353.27943"
"236.32600","0.31510","353.71747"
"236.72600","0.31565","354.30035"
"237.12600","0.31616","353.98907"
"237.52600","0.31669","354.36958"
"237.92600","0.31725","355.17711"
"238.32600","0.31777","355.05636"
"238.72600","0.31830","355.36602"
"239.12600","0.31885","356.23740"
"239.52600","0.31937","356.17884"
"239.92600","0.31989","356.24105"
"240.32600","0.32044","356.89396"
"240.72600","0.32098","357.46532"
"241.12600","0.32150","357.90374"
"241.52600","0.32205","358.58050"
"241.92600","0.32256","358.32995"
"242.32600","0.32310","358.91461"
"242.72600","0.32365","359.83086"
"243.12600","0.32417","359.75838"
"243.52600","0.32470","360.27976"
"243.92600","0.32526","361.27236"
"244.32600","0.32577","361.10381"
"244.72600","0.32629","361.31081"
"245.12600","0.32684","361.97623"
"245.52600","0.32738","362.48611"
"245.92600","0.32791","362.97942"
"246.32600","0.32845","363.56104"
"246.72600","0.32896","363.20228"
"247.12600","0.32949","363.53013"
"247.52600","0.33004","364.35303"
"247.92600","0.33057","360.43501"
"248.26000","0.33102","358.32975"
"248.66000","0.33155","360.40235"
"249.06000","0.33207","361.22587"
"249.46000","0.33262","362.37791"
"249.86000","0.33315","362.72689"
"250.26000","0.33368","363.30815"
"250.66000","0.33423","364.48958"
"251.06000","0.33476","364.65794"
"251.46000","0.33527","364.70547"
"251.86000","0.33582","365.56670"
"252.26000","0.33635","365.93303"
"252.66000","0.33688","366.20753"
"253.06000","0.33742","366.81610"
"253.46000","0.33794","366.55534"
"253.86000","0.33847","366.71550"
"254.26000","0.33902","367.32949"
"254.66000","0.33955","367.28863"
"255.06000","0.34008","364.94189"
"255.46000","0.34063","366.70430"
"255.86000","0.34115","366.63901"
"256.26000","0.34167","366.61083"
"256.66000","0.34222","367.23430"
"257.06000","0.34276","367.42576"
"257.46000","0.34328","367.57694"
"257.86000","0.34382","368.04421"
"258.26000","0.34434","367.66435"
"258.66000","0.34487","367.93586"
"259.06000","0.34542","368.51339"
"259.46000","0.34594","368.24207"
"259.86000","0.34648","368.37072"
"260.26000","0.34703","369.22851"
"260.66000","0.34755","368.85639"
"261.06000","0.34807","368.66627"
"261.46000","0.34861","369.05272"
"261.86000","0.34915","369.39553"
"262.26000","0.34968","369.70536"
"262.66000","0.35022","370.10385"
"263.06000","0.35074","369.83266"
"263.46000","0.35127","370.08532"
"263.86000","0.35182","370.82567"
"264.26000","0.35235","370.50917"
"264.66000","0.35287","370.50698"
"265.06000","0.35343","371.30119"
"265.46000","0.35395","370.77410"
"265.86000","0.35447","370.66672"
"266.26000","0.35501","371.08722"
"266.66000","0.35556","371.28599"
"267.06000","0.35608","371.52323"
"267.46000","0.35662","372.02891"
"267.86000","0.35714","371.69620"
"268.26000","0.35767","372.19189"
"268.66000","0.35822","372.93550"
"269.06000","0.35875","372.80348"
"269.46000","0.35928","373.36028"
"269.86000","0.35983","374.34780"
"270.26000","0.36036","374.31240"
"270.66000","0.36087","374.39171"
"271.06000","0.36142","375.18373"
"271.46000","0.36196","375.51477"
"271.86000","0.36248","375.91488"
"272.26000","0.36302","376.33928"
"272.66000","0.36355","376.05802"
"273.06000","0.36407","376.24597"
"273.46000","0.36462","376.82520"
"273.86000","0.36515","376.55830"
"274.26000","0.36568","376.85056"
"274.66000","0.36623","377.42433"
"275.06000","0.36676","377.18409"
"275.46000","0.36727","377.10871"
"275.86000","0.36782","377.66379"
"276.26000","0.36836","377.73108"
"276.66000","0.36888","377.77430"
"277.06000","0.36942","377.97183"
"277.46000","0.36994","377.38692"
"277.86000","0.37047","377.43604"
"278.26000","0.37102","378.16582"
"278.66000","0.37155","377.78111"
"279.06000","0.37208","377.83904"
"279.46000","0.37263","378.34326"
"279.86000","0.37315","377.84642"
"280.26000","0.37367","377.50715"
"280.66000","0.37421","377.72847"
"281.06000","0.37476","378.06692"
"281.46000","0.37528","378.57106"
"281.86000","0.37582","379.20515"
"282.26000","0.37634","379.01319"
"282.66000","0.37688","379.89865"
"283.06000","0.37742","380.95113"
"283.46000","0.37795","380.94915"
"283.86000","0.37848","381.60656"
"284.26000","0.37903","382.59216"
"284.66000","0.37955","382.61447"
"285.06000","0.38007","383.05533"
"285.46000","0.38061","383.91686"
"285.86000","0.38116","384.49708"
"286.26000","0.38169","385.31094"
"286.66000","0.38222","386.07206"
"287.06000","0.38274","386.08496"
"287.46000","0.38327","386.84459"
"287.86000","0.38382","387.85640"
"288.26000","0.38435","388.08919"
"288.66000","0.38488","388.80061"
"289.06000","0.38543","389.71604"
"289.46000","0.38595","389.73176"
"289.86000","0.38647","390.01245"
"290.26000","0.38702","390.92263"
"290.66000","0.38755","391.27968"
"291.06000","0.38808","392.04248"
"291.46000","0.38863","392.91937"
"291.86000","0.38914","392.77118"
"292.26000","0.38967","393.44772"
"292.66000","0.39022","394.39734"
"293.06000","0.39075","394.61639"
"293.46000","0.39128","395.48176"
"293.86000","0.39183","396.33747"
"294.26000","0.39235","396.47880"
"294.66000","0.39287","396.80863"
"295.06000","0.39342","397.53328"
"295.46000","0.39395","397.81802"
"295.86000","0.39448","398.39566"
"296.26000","0.39502","398.90593"
"296.66000","0.39554","398.66504"
"297.06000","0.39607","399.27327"
"297.46000","0.39662","400.28137"
"297.86000","0.39715","400.27435"
"298.26000","0.39768","400.80983"
"298.66000","0.39823","401.58925"
"299.06000","0.39875","401.53709"
"299.46000","0.39927","401.89134"
"299.86000","0.39981","402.45685"
"300.26000","0.40035","403.00350"
"300.66000","0.40089","403.74654"
"301.06000","0.40143","404.45120"
"301.46000","0.40194","404.23853"
"301.86000","0.40247","404.86106"
"302.26000","0.40303","405.81787"
"302.66000","0.40355","405.73077"
"303.06000","0.40407","406.29839"
"303.46000","0.40463","407.18168"
"303.86000","0.40515","407.08014"
"304.26000","0.40567","407.26700"
"304.66000","0.40622","408.00465"
"305.06000","0.40675","408.48144"
"305.46000","0.40729","409.14851"
"305.86000","0.40782","409.54072"
"306.26000","0.40834","409.30617"
"306.66000","0.40887","410.00414"
"307.06000","0.40942","411.00702"
"307.46000","0.40995","411.08008"
"307.86000","0.41048","411.90599"
"308.26000","0.41103","412.91612"
"308.66000","0.41155","412.82152"
"309.06000","0.41207","413.31697"
"309.46000","0.41262","414.07685"
"309.86000","0.41315","414.49464"
"310.26000","0.41368","415.23879"
"310.66000","0.41423","415.86190"
"311.06000","0.41474","415.61429"
"311.46000","0.41527","416.25395"
"311.86000","0.41582","416.92835"
"312.26000","0.41635","416.97258"
"312.66000","0.41688","417.60818"
"313.06000","0.41742","418.31666"
"313.46000","0.41795","418.39616"
"313.86000","0.41847","418.84976"
"314.26000","0.41902","419.51247"
"314.66000","0.41955","420.03489"
"315.06000","0.42008","420.89461"
"315.46000","0.42063","421.59670"
"315.86000","0.42114","421.32853"
"316.26000","0.42167","421.99824"
"316.66000","0.42223","422.98320"
"317.06000","0.42275","422.97977"
"317.46000","0.42328","423.64287"
"317.86000","0.42384","424.51889"
"318.26000","0.42435","424.46614"
"318.66000","0.42487","424.97045"
"319.06000","0.42541","425.42487"
"319.46000","0.42595","425.79521"
"319.86000","0.42649","426.65383"
"320.26000","0.42703","427.10375"
"320.66000","0.42754","426.85904"
"321.06000","0.42807","427.64354"
"321.46000","0.42863","428.56424"
"321.86000","0.42915","428.46654"
"322.26000","0.42968","429.06413"
"322.66000","0.43024","429.76386"
"323.06000","0.43075","429.65738"
"323.46000","0.43127","430.04021"
"323.86000","0.43182","430.48914"
"324.26000","0.43235","430.81612"
"324.66000","0.43289","431.70599"
"325.06000","0.43343","432.14260"
"325.46000","0.43394","432.00465"
"325.86000","0.43447","432.69420"
"326.26000","0.43503","433.57373"
"326.66000","0.43555","433.59066"
"327.06000","0.43608","434.15510"
"327.46000","0.43663","434.78781"
"327.86000","0.43715","434.77225"
"328.26000","0.43767","435.19498"
"328.66000","0.43822","435.83636"
"329.06000","0.43875","436.05184"
"329.46000","0.43928","436.82613"
"329.86000","0.43983","437.14888"
"330.26000","0.44034","436.79866"
"330.66000","0.44087","437.46862"
"331.06000","0.44143","438.06527"
"331.46000","0.44194","438.01700"
"331.86000","0.44248","438.62482"
"332.26000","0.44303","439.29000"
"332.66000","0.44355","439.16618"
"333.06000","0.44407","439.70957"
"333.46000","0.44462","440.32195"
"333.86000","0.44515","440.64440"
"334.26000","0.44569","441.45000"
"334.66000","0.44623","441.86628"
"335.06000","0.44674","441.55436"
"335.46000","0.44727","442.33497"
"335.86000","0.44783","443.04836"
"336.26000","0.44835","443.16145"
"336.66000","0.44888","443.79095"
"337.06000","0.44943","444.31832"
"337.46000","0.44994","444.46354"
"337.86000","0.45047","445.07614"
"338.26000","0.45102","445.57705"
"338.66000","0.45155","445.84522"
"339.06000","0.45209","446.73125"
"339.46000","0.45263","446.95112"
"339.86000","0.45313","446.69429"
"340.26000","0.45367","447.23567"
"340.66000","0.45423","447.95061"
"341.06000","0.45474","447.74331"
"341.46000","0.45528","448.22004"
"341.86000","0.45584","448.82341"
"342.26000","0.45634","448.61735"
"342.66000","0.45687","448.95838"
"343.06000","0.45742","449.17869"
"343.46000","0.45794","449.34930"
"343.86000","0.45849","450.20509"
"344.26000","0.45903","450.41944"
"344.66000","0.45953","450.01854"
"345.06000","0.46007","450.70978"
"345.46000","0.46063","451.45575"
"345.86000","0.46115","451.28127"
"346.26000","0.46168","451.80984"
"346.66000","0.46223","452.28767"
"347.06000","0.46274","452.03559"
"347.46000","0.46327","452.60183"
"347.86000","0.46382","452.98260"
"348.26000","0.46435","453.35650"
"348.66000","0.46489","454.22421"
"349.06000","0.46543","454.53381"
"349.46000","0.46593","454.22547"
"349.86000","0.46647","455.06595"
"350.26000","0.46703","455.76096"
"350.66000","0.46754","455.84233"
"351.06000","0.46808","456.53931"
"351.46000","0.46863","457.06678"
"351.86000","0.46914","456.94044"
"352.26000","0.46967","457.32650"
"352.66000","0.47022","457.78926"
"353.06000","0.47075","458.05620"
"353.46000","0.47129","458.73595"
"353.86000","0.47183","459.26646"
"354.26000","0.47233","458.96114"
"354.66000","0.47287","459.67034"
"355.06000","0.47343","460.32467"
"355.46000","0.47394","460.26073"
"355.86000","0.47448","460.88233"
"356.26000","0.47503","461.14073"
"356.66000","0.47554","461.16763"
"357.06000","0.47608","461.64211"
"357.46000","0.47662","461.89320"
"357.86000","0.47715","461.97762"
"358.26000","0.47769","462.91445"
"358.66000","0.47823","463.08426"
"359.06000","0.47873","462.64765"
"359.46000","0.47927","463.22093"
"359.86000","0.47983","463.84728"
"360.26000","0.48035","463.68174"
"360.66000","0.48088","464.05677"
"361.06000","0.48143","464.32648"
"361.46000","0.48194","464.11583"
"361.86000","0.48248","464.60633"
"362.26000","0.48301","464.64481"
"362.66000","0.48354","464.78520"
"363.06000","0.48409","465.67099"
"363.46000","0.48462","465.62143"
"363.86000","0.48513","465.37906"
"364.26000","0.48567","466.04547"
"364.66000","0.48623","466.59712"
"365.06000","0.48675","466.52133"
"365.46000","0.48728","467.04729"
"365.86000","0.48783","467.29614"
"366.26000","0.48834","467.02336"
"366.66000","0.48887","467.48209"
"367.06000","0.48942","467.48039"
"367.46000","0.48995","467.61123"
"367.86000","0.49049","468.31096"
"368.26000","0.49103","468.26524"
"368.66000","0.49153","467.74318"
"369.06000","0.49208","468.37490"
"369.46000","0.49263","468.81190"
"369.86000","0.49314","468.55037"
"370.26000","0.49368","469.08879"
"370.66000","0.49423","469.31322"
"371.06000","0.49474","469.18775"
"371.46000","0.49528","469.69022"
"371.86000","0.49582","469.88462"
"372.26000","0.49635","470.04450"
"372.66000","0.49689","470.77030"
"373.06000","0.49743","470.77651"
"373.46000","0.49794","470.35894"
"373.86000","0.49847","470.93408"
"374.26000","0.49903","471.28836"
"374.66000","0.49954","471.28463"
"375.06000","0.50008","471.72168"
"375.46000","0.50062","471.71575"
"375.86000","0.50114","471.62656"
"376.26000","0.50168","472.10439"
"376.66000","0.50222","472.15999"
"377.06000","0.50274","472.16987"
"377.46000","0.50329","472.88327"
"377.86000","0.50383","472.86219"
"378.26000","0.50433","472.41164"
"378.66000","0.50488","472.96236"
"379.06000","0.50543","473.42904"
"379.46000","0.50595","473.15632"
"379.86000","0.50649","473.69941"
"380.26000","0.50703","473.65440"
"380.66000","0.50754","473.69364"
"381.06000","0.50808","474.29354"
"381.46000","0.50861","474.36681"
"381.86000","0.50914","474.49392"
"382.26000","0.50970","475.42016"
"382.66000","0.51023","475.28487"
"383.06000","0.51073","474.69447"
"383.46000","0.51128","475.36374"
"383.86000","0.51183","475.89321"
"384.26000","0.51235","475.78696"
"384.66000","0.51289","476.25030"
"385.06000","0.51342","476.26380"
"385.46000","0.51394","476.18054"
"385.86000","0.51448","476.75310"
"386.26000","0.51501","476.68054"
"386.66000","0.51554","476.70216"
"387.06000","0.51610","477.45453"
"387.46000","0.51663","477.17072"
"387.86000","0.51713","476.56144"
"388.26000","0.51768","476.85699"
"388.66000","0.51822","476.99135"
"389.06000","0.51874","476.78658"
"389.46000","0.51929","477.17198"
"389.86000","0.51982","477.05496"
"390.26000","0.52034","476.94135"
"390.66000","0.52088","477.37741"
"391.06000","0.52142","477.41556"
"391.46000","0.52195","477.54624"
"391.86000","0.52249","478.26869"
"392.26000","0.52303","478.15288"
"392.66000","0.52353","477.61863"
"393.06000","0.52408","478.29756"
"393.46000","0.52463","478.65080"
"393.86000","0.52514","478.62385"
"394.26000","0.52569","479.08785"
"394.66000","0.52622","478.99175"
"395.06000","0.52674","478.89114"
"395.46000","0.52728","479.37204"
"395.86000","0.52782","479.31041"
"396.26000","0.52834","479.30717"
"396.66000","0.52890","479.86980"
"397.06000","0.52943","479.74576"
"397.46000","0.52993","479.28977"
"397.86000","0.53048","479.67561"
"398.26000","0.53103","480.00525"
"398.66000","0.53155","479.86667"
"399.06000","0.53209","480.18506"
"399.46000","0.53262","479.80328"
"399.86000","0.53314","479.59603"
"400.26000","0.53368","479.75448"
"400.66000","0.53421","479.29894"
"401.06000","0.53474","478.77237"
"401.46000","0.53530","478.91227"
"401.86000","0.53583","478.03060"
"402.26000","0.53633","476.98504"
"402.66000","0.53688","476.83866"
"403.06000","0.53743","476.60968"
"403.46000","0.53794","475.91369"
"403.86000","0.53849","475.80424"
"404.26000","0.53902","475.19766"
"404.66000","0.53954","474.59387"
"405.06000","0.54008","474.68135"
"405.46000","0.54062","473.94825"
"405.86000","0.54114","473.19803"
"406.26000","0.54170","473.51834"
"406.66000","0.54222","472.59430"
"407.06000","0.54273","471.96872"
"407.46000","0.54328","472.33930"
"407.86000","0.54383","472.57964"
"408.26000","0.54434","472.41823"
"408.66000","0.54489","472.85022"
"409.06000","0.54542","472.56943"
"409.46000","0.54594","472.54962"
"409.86000","0.54648","473.16625"
"410.26000","0.54701","473.23393"
"410.66000","0.54754","473.63096"
"411.06000","0.54810","474.57043"
"411.46000","0.54863","474.60896"
"411.86000","0.54913","474.31176"
"412.26000","0.54968","474.86829"
"412.66000","0.55022","474.72307"
"413.06000","0.55075","474.39222"
"413.46000","0.55129","474.31258"
"413.86000","0.55182","473.53667"
"414.26000","0.55234","472.88206"
"414.66000","0.55288","472.75599"
"415.06000","0.55341","471.86647"
"415.46000","0.55395","470.95658"
"415.86000","0.55450","470.05060"
"416.26000","0.55502","467.81793"
"416.66000","0.55553","465.02269"
"417.06000","0.55608","462.95995"
"417.46000","0.55663","461.09913"
"417.86000","0.55715","459.11386"
"418.26000","0.55769","457.76369"
"418.66000","0.55822","455.89897"
"419.06000","0.55874","454.69389"
"419.46000","0.55929","454.15110"
"419.86000","0.55981","452.71256"
"420.26000","0.56034","451.80334"
"420.66000","0.56090","451.53997"
"421.06000","0.56142","450.05114"
"421.46000","0.56193","448.47772"
"421.86000","0.56248","447.75393"
"422.26000","0.56303","447.08104"
"422.66000","0.56355","446.29437"
"423.06000","0.56409","445.93454"
"423.46000","0.56462","444.78385"
"423.86000","0.56514","443.92726"
"424.26000","0.56569","443.51722"
"424.66000","0.56621","442.33604"
"425.06000","0.56674","441.38982"
"425.46000","0.56730","441.09229"
"425.86000","0.56782","439.99385"
"426.26000","0.56833","439.00954"
"426.66000","0.56888","438.55561"
"427.06000","0.56943","437.88064"
"427.46000","0.56995","437.02844"
"427.86000","0.57049","436.11603"
"428.26000","0.57102","434.55620"
"428.66000","0.57154","433.29126"
"429.06000","0.57208","432.59521"
"429.46000","0.57261","431.42567"
"429.86000","0.57314","430.52265"
"430.26000","0.57370","430.21079"
"430.66000","0.57422","428.65680"
"431.06000","0.57473","427.22301"
"431.46000","0.57528","426.90858"
"431.86000","0.57582","426.01382"
"432.26000","0.57634","425.01444"
"432.66000","0.57689","424.31628"
"433.06000","0.57742","423.00958"
"433.46000","0.57793","421.95181"
"433.86000","0.57848","421.55331"
"434.26000","0.57902","420.81851"
"434.66000","0.57955","420.43542"
"435.06000","0.58010","420.27592"
"435.46000","0.58062","419.38772"
"435.86000","0.58113","418.43867"
"436.26000","0.58168","418.23346"
"436.66000","0.58222","417.39599"
"437.06000","0.58275","416.69769"
"437.46000","0.58329","416.40730"
"437.86000","0.58381","415.61237"
"438.26000","0.58434","415.15899"
"438.66000","0.58489","415.16695"
"439.06000","0.58541","414.48561"
"439.46000","0.58595","414.12392"
"439.86000","0.58650","414.19055"
"440.26000","0.58701","413.31982"
"440.66000","0.58754","412.85492"
"441.06000","0.58808","412.85176"
"441.46000","0.58862","412.80143"
"441.86000","0.58915","412.52920"
"442.26000","0.58969","412.44265"
"442.66000","0.59022","411.60379"
"443.06000","0.59074","410.84750"
"443.46000","0.59129","410.91166"
"443.86000","0.59181","410.17445"
"444.26000","0.59234","409.90101"
"444.66000","0.59290","410.36539"
"445.06000","0.59342","409.65529"
"445.46000","0.59393","409.09288"
"445.86000","0.59448","409.10208"
"446.26000","0.59502","408.88212"
"446.66000","0.59555","408.72035"
"447.06000","0.59609","408.59568"
"447.46000","0.59662","407.54439"
"447.86000","0.59714","406.79847"
"448.26000","0.59769","406.58401"
"448.66000","0.59821","405.69844"
"449.06000","0.59875","405.31476"
"449.46000","0.59930","405.19405"
"449.86000","0.59982","404.02952"
"450.26000","0.60033","403.21687"
"450.66000","0.60088","403.15669"
"451.06000","0.60142","402.81489"
"451.46000","0.60195","402.67611"
"451.86000","0.60249","402.87074"
"452.26000","0.60302","402.20471"
"452.66000","0.60354","401.75871"
"453.06000","0.60409","401.73412"
"453.46000","0.60461","401.08675"
"453.86000","0.60515","400.70267"
"454.26000","0.60570","400.69197"
"454.66000","0.60622","399.87621"
"455.06000","0.60674","399.17102"
"455.46000","0.60728","399.11136"
"455.86000","0.60782","398.80206"
"456.26000","0.60835","398.57365"
"456.66000","0.60889","398.79695"
"457.06000","0.60941","398.33831"
"457.46000","0.60994","398.57505"
"457.86000","0.61049","399.54075"
"458.26000","0.61101","399.40884"
"458.66000","0.61154","399.56416"
"459.06000","0.61210","400.20947"
"459.46000","0.61262","399.83730"
"459.86000","0.61314","399.70862"
"460.26000","0.61368","399.95711"
"460.66000","0.61422","400.09281"
"461.06000","0.61475","400.29869"
"461.46000","0.61529","400.81491"
"461.86000","0.61581","400.61290"
"462.26000","0.61634","400.96656"
"462.66000","0.61689","401.47880"
"463.06000","0.61741","401.09104"
"463.46000","0.61794","401.31702"
"463.86000","0.61850","401.87512"
"464.26000","0.61901","401.25931"
"464.66000","0.61954","401.05794"
"465.06000","0.62008","401.36820"
"465.46000","0.62062","401.57847"
"465.86000","0.62115","402.12120"
"466.26000","0.62169","402.67329"
"466.66000","0.62221","402.57532"
"467.06000","0.62274","403.05238"
"467.46000","0.62329","403.78737"
"467.86000","0.62381","403.49450"
"468.26000","0.62435","403.84549"
"468.66000","0.62490","404.54157"
"469.06000","0.62542","404.21405"
"469.46000","0.62593","402.90230"
"469.86000","0.62648","403.25353"
"470.26000","0.62702","403.21294"
"470.66000","0.62755","403.43290"
"470.82500","0.62777","403.41193"