File: materials_lab1/ENGR314_FA19_0001_acrylic_A_20190903_JJR.is_tens_RawData/Specimen_RawData_1.csv
Material,Acrylic
Geometry,Circular
Length,"2.00000",in
Diameter,"0.12800",in

Time,Extension,Load
(s),(in),(lbf)
"0.00000","0.00000","-0.51249"
"0.20000","0.00021","-0.20135"
"0.40000","0.00053","0.61311"
"0.60000","0.00079","1.18307"
"0.80000","0.00107","1.76739"
"1.00000","0.00134","2.34916"
"1.20000","0.00161","2.88030"
"1.40000","0.00187","3.41578"
"1.60000","0.00213","3.93950"
"1.80000","0.00239","4.44907"
"2.00000","0.00266","5.00925"
"2.20000","0.00295","5.57276"
"2.40000","0.00320","6.05594"
"2.60000","0.00347","6.57367"
"2.80000","0.00373","7.09255"
"3.00000","0.00399","7.60204"
"3.20000","0.00428","8.17430"
"3.40000","0.00453","8.62865"
"3.60000","0.00481","9.15021"
"3.80000","0.00508","9.62508"
"4.00000","0.00532","10.08322"
"4.20000","0.00560","10.62912"
"4.40000","0.00586","11.11033"
"4.60000","0.00614","11.62620"
"4.80000","0.00641","12.10236"
"5.00000","0.00667","12.54066"
"5.20000","0.00693","13.02331"
"5.40000","0.00719","13.47995"
"5.60000","0.00747","13.97523"
"5.80000","0.00774","14.45966"
"6.00000","0.00801","14.90453"
"6.20000","0.00827","15.34048"
"6.40000","0.00853","15.80695"
"6.60000","0.00880","16.28201"
"6.80000","0.00906","16.73347"
"7.00000","0.00935","17.20658"
"7.20000","0.00960","17.64066"
"7.40000","0.00987","18.09505"
"7.60000","0.01013","18.52311"
"7.80000","0.01039","18.93920"
"8.00000","0.01068","19.43603"
"8.20000","0.01094","19.84105"
"8.40000","0.01121","20.27639"
"8.60000","0.01148","20.70325"
"8.80000","0.01172","21.08731"
"9.00000","0.01200","21.58138"
"9.20000","0.01226","21.98007"
"9.40000","0.01254","22.43032"
"9.60000","0.01281","22.86014"
"9.80000","0.01307","23.23609"
"10.00000","0.01333","23.67498"
"10.20000","0.01359","24.07150"
"10.40000","0.01387","24.52935"
"10.60000","0.01414","24.95669"
"10.80000","0.01441","25.34318"
"11.00000","0.01467","25.74269"
"11.20000","0.01493","26.13573"
"11.40000","0.01520","26.56217"
"11.60000","0.01546","26.95891"
"11.80000","0.01575","27.40133"
"12.00000","0.01600","27.78787"
"12.20000","0.01627","28.20597"
"12.40000","0.01653","28.61575"
"12.60000","0.01679","29.00429"
"12.80000","0.01708","29.45213"
"13.00000","0.01733","29.82118"
"13.20000","0.01761","30.22455"
"13.40000","0.01788","30.59616"
"13.60000","0.01812","30.96094"
"13.80000","0.01840","31.39542"
"14.00000","0.01866","31.77486"
"14.20000","0.01894","32.19593"
"14.40000","0.01921","32.57302"
"14.60000","0.01946","32.92038"
"14.80000","0.01973","33.34382"
"15.00000","0.01999","33.69768"
"15.20000","0.02027","34.12500"
"15.40000","0.02054","34.52280"
"15.60000","0.02081","34.86811"
"15.80000","0.02107","35.25477"
"16.00000","0.02133","35.61809"
"16.20000","0.02160","36.01849"
"16.40000","0.02186","36.39667"
"16.60000","0.02215","36.80783"
"16.80000","0.02240","37.13976"
"17.00000","0.02267","37.50015"
"17.20000","0.02293","37.85715"
"17.40000","0.02319","38.23022"
"17.60000","0.02348","38.65844"
"17.80000","0.02373","38.98104"
"18.00000","0.02401","39.37437"
"18.20000","0.02428","39.71053"
"18.40000","0.02452","40.05257"
"18.60000","0.02480","40.46282"
"18.80000","0.02506","40.79891"
"19.00000","0.02534","41.18721"
"19.20000","0.02562","41.56623"
"19.40000","0.02586","41.88540"
"19.60000","0.02613","42.26141"
"19.80000","0.02639","42.60199"
"20.00000","0.02667","42.96875"
"20.20000","0.02694","43.34573"
"20.40000","0.02721","43.66542"
"20.60000","0.02747","44.01003"
"20.80000","0.02773","44.35588"
"21.00000","0.02800","44.71256"
"21.20000","0.02827","45.07438"
"21.40000","0.02855","45.45017"
"21.60000","0.02880","45.76720"
"21.80000","0.02907","46.10261"
"22.00000","0.02933","46.44189"
"22.20000","0.02959","46.77957"
"22.40000","0.02988","47.16572"
"22.60000","0.03014","47.48083"
"22.80000","0.03041","47.81172"
"23.00000","0.03068","48.14291"
"23.20000","0.03092","48.46407"
"23.40000","0.03120","48.85093"
"23.60000","0.03146","49.16932"
"23.80000","0.03174","49.52084"
"24.00000","0.03201","49.84556"
"24.20000","0.03226","50.13504"
"24.40000","0.03253","50.49258"
"24.60000","0.03279","50.80856"
"24.80000","0.03307","51.15787"
"25.00000","0.03334","51.49433"
"25.20000","0.03361","51.78902"
"25.40000","0.03387","52.11490"
"25.60000","0.03412","52.44312"
"25.80000","0.03440","52.79934"
"26.00000","0.03467","53.12471"
"26.20000","0.03495","53.45974"
"26.40000","0.03520","53.74793"
"26.60000","0.03547","54.08051"
"26.80000","0.03574","54.38808"
"27.00000","0.03599","54.69915"
"27.20000","0.03628","55.05469"
"27.40000","0.03654","55.35360"
"27.60000","0.03681","55.68319"
"27.80000","0.03707","55.99163"
"28.00000","0.03732","56.27057"
"28.20000","0.03760","56.63250"
"28.40000","0.03787","56.92514"
"28.60000","0.03815","57.26149"
"28.80000","0.03841","57.57151"
"29.00000","0.03866","57.82890"
"29.20000","0.03893","58.15242"
"29.40000","0.03919","58.45265"
"29.60000","0.03947","58.78896"
"29.80000","0.03974","59.10846"
"30.00000","0.04001","59.39404"
"30.20000","0.04027","59.68480"
"30.40000","0.04053","59.97430"
"30.60000","0.04080","60.28510"
"30.80000","0.04107","60.58658"
"31.00000","0.04135","60.90598"
"31.20000","0.04160","61.17319"
"31.40000","0.04187","61.45751"
"31.60000","0.04214","61.74822"
"31.80000","0.04239","62.02543"
"32.00000","0.04268","62.38527"
"32.20000","0.04294","62.64587"
"32.40000","0.04321","62.95739"
"32.60000","0.04347","63.23803"
"32.80000","0.04372","63.49424"
"33.00000","0.04400","63.81851"
"33.20000","0.04426","64.08777"
"33.40000","0.04455","64.40357"
"33.60000","0.04482","64.68777"
"33.80000","0.04506","64.94344"
"34.00000","0.04533","65.25021"
"34.20000","0.04559","65.52724"
"34.40000","0.04587","65.83124"
"34.60000","0.04614","66.12195"
"34.80000","0.04641","66.37126"
"35.00000","0.04667","66.65660"
"35.20000","0.04692","66.91564"
"35.40000","0.04720","67.21890"
"35.60000","0.04747","67.50339"
"35.80000","0.04775","67.77161"
"36.00000","0.04800","68.01683"
"36.20000","0.04827","68.27555"
"36.40000","0.04853","68.54721"
"36.60000","0.04879","68.81587"
"36.80000","0.04908","69.14956"
"37.00000","0.04934","69.37515"
"37.20000","0.04961","69.66973"
"37.40000","0.04987","69.92569"
"37.60000","0.05012","70.16566"
"37.80000","0.05040","70.47896"
"38.00000","0.05067","70.71699"
"38.20000","0.05095","71.00134"
"38.40000","0.05121","71.26658"
"38.60000","0.05146","71.49130"
"38.80000","0.05173","71.75738"
"39.00000","0.05199","71.99934"
"39.20000","0.05227","72.29721"
"39.40000","0.05255","72.56080"
"39.60000","0.05281","72.79030"
"39.80000","0.05307","73.05846"
"40.00000","0.05333","73.31131"
"40.20000","0.05359","73.56007"
"40.40000","0.05387","73.83076"
"40.60000","0.05415","74.07331"
"40.80000","0.05440","74.30966"
"41.00000","0.05467","74.53358"
"41.20000","0.05493","74.81457"
"41.40000","0.05519","75.05095"
"41.60000","0.05548","75.33926"
"41.80000","0.05574","75.54931"
"42.00000","0.05601","75.78265"
"42.20000","0.05627","76.03420"
"42.40000","0.05652","76.24110"
"42.60000","0.05680","76.53374"
"42.80000","0.05707","76.76712"
"43.00000","0.05735","77.02583"
"43.20000","0.05761","77.26221"
"43.40000","0.05786","77.46222"
"43.60000","0.05814","77.72724"
"43.80000","0.05839","77.94336"
"44.00000","0.05867","78.20291"
"44.20000","0.05894","78.43932"
"44.40000","0.05921","78.63637"
"44.60000","0.05947","78.85612"
"44.80000","0.05973","79.10519"
"45.00000","0.06000","79.34543"
"45.20000","0.06027","79.58141"
"45.40000","0.06055","79.80835"
"45.60000","0.06080","80.01292"
"45.80000","0.06107","80.22954"
"46.00000","0.06133","80.46826"
"46.20000","0.06159","80.67777"
"46.40000","0.06188","80.92767"
"46.60000","0.06214","81.12885"
"46.80000","0.06241","81.34862"
"47.00000","0.06267","81.55871"
"47.20000","0.06292","81.76095"
"47.40000","0.06320","82.01455"
"47.60000","0.06347","82.20464"
"47.80000","0.06375","82.43690"
"48.00000","0.06401","82.64410"
"48.20000","0.06426","82.81413"
"48.40000","0.06453","83.06656"
"48.60000","0.06479","83.26612"
"48.80000","0.06507","83.51519"
"49.00000","0.06534","83.72758"
"49.20000","0.06561","83.90459"
"49.40000","0.06587","84.10534"
"49.60000","0.06613","84.30121"
"49.80000","0.06640","84.52201"
"50.00000","0.06667","84.73072"
"50.20000","0.06695","84.93139"
"50.40000","0.06720","85.12326"
"50.60000","0.06747","85.30548"
"50.80000","0.06774","85.50209"
"51.00000","0.06799","85.66695"
"51.20000","0.06828","85.88209"
"51.40000","0.06854","86.05194"
"51.60000","0.06881","86.24101"
"51.80000","0.06907","86.42920"
"52.00000","0.06932","86.61009"
"52.20000","0.06960","86.84491"
"52.40000","0.06987","87.03814"
"52.60000","0.07015","87.25491"
"52.80000","0.07041","87.41715"
"53.00000","0.07066","87.56004"
"53.20000","0.07094","87.80236"
"53.40000","0.07119","87.96854"
"53.60000","0.07147","88.17341"
"53.80000","0.07175","88.36270"
"54.00000","0.07200","88.51667"
"54.20000","0.07227","88.71394"
"54.40000","0.07253","88.88355"
"54.60000","0.07280","89.07422"
"54.80000","0.07307","89.27393"
"55.00000","0.07335","89.45545"
"55.20000","0.07360","89.60190"
"55.40000","0.07386","89.78218"
"55.60000","0.07413","89.96198"
"55.80000","0.07439","90.16734"
"56.00000","0.07468","90.37776"
"56.20000","0.07494","90.51664"
"56.40000","0.07521","90.69418"
"56.60000","0.07547","90.86109"
"56.80000","0.07572","91.01682"
"57.00000","0.07601","91.23356"
"57.20000","0.07627","91.37999"
"57.40000","0.07654","91.56531"
"57.60000","0.07681","91.72403"
"57.80000","0.07706","91.85541"
"58.00000","0.07734","92.06106"
"58.20000","0.07759","92.22101"
"58.40000","0.07787","92.41171"
"58.60000","0.07815","92.56648"
"58.80000","0.07841","92.69249"
"59.00000","0.07867","92.87127"
"59.20000","0.07893","93.01976"
"59.40000","0.07920","93.19941"
"59.60000","0.07947","93.39026"
"59.80000","0.07976","93.53220"
"60.00000","0.08000","93.67597"
"60.20000","0.08026","93.84170"
"60.40000","0.08053","94.00823"
"60.60000","0.08079","94.16578"
"60.80000","0.08108","94.35551"
"61.00000","0.08134","94.48062"
"61.20000","0.08161","94.64421"
"61.40000","0.08187","94.78626"
"61.60000","0.08212","94.92634"
"61.80000","0.08241","95.11827"
"62.00000","0.08267","95.24805"
"62.20000","0.08295","95.41966"
"62.40000","0.08321","95.56348"
"62.60000","0.08346","95.66701"
"62.80000","0.08374","95.84410"
"63.00000","0.08399","95.98724"
"63.20000","0.08428","96.15459"
"63.40000","0.08455","96.30024"
"63.60000","0.08481","96.41872"
"63.80000","0.08507","96.56185"
"64.00000","0.08532","96.68673"
"64.20000","0.08560","96.85434"
"64.40000","0.08587","97.00912"
"64.60000","0.08615","97.15908"
"64.80000","0.08640","97.26820"
"65.00000","0.08667","97.39259"
"65.20000","0.08694","97.55435"
"65.40000","0.08719","97.68450"
"65.60000","0.08748","97.84417"
"65.80000","0.08774","97.94395"
"66.00000","0.08801","98.08532"
"66.20000","0.08827","98.19922"
"66.40000","0.08852","98.32485"
"66.60000","0.08880","98.50295"
"66.80000","0.08907","98.61286"
"67.00000","0.08935","98.74108"
"67.20000","0.08961","98.85902"
"67.40000","0.08986","98.95961"
"67.60000","0.09013","99.10828"
"67.80000","0.09039","99.22628"
"68.00000","0.09067","99.36472"
"68.20000","0.09095","99.48414"
"68.40000","0.09120","99.57191"
"68.60000","0.09146","99.69109"
"68.80000","0.09173","99.80660"
"69.00000","0.09200","99.95417"
"69.20000","0.09227","100.07200"
"69.40000","0.09255","100.21636"
"69.60000","0.09280","100.29867"
"69.80000","0.09306","100.40210"
"70.00000","0.09333","100.52262"
"70.20000","0.09359","100.64264"
"70.40000","0.09388","100.77778"
"70.60000","0.09414","100.87044"
"70.80000","0.09441","100.97706"
"71.00000","0.09467","101.08270"
"71.20000","0.09492","101.16166"
"71.40000","0.09521","101.30471"
"71.60000","0.09547","101.38548"
"71.80000","0.09575","101.51791"
"72.00000","0.09601","101.62250"
"72.20000","0.09625","101.68474"
"72.40000","0.09653","101.79743"
"72.60000","0.09679","101.90006"
"72.80000","0.09707","102.02531"
"73.00000","0.09735","102.13400"
"73.20000","0.09760","102.18755"
"73.40000","0.09787","102.29373"
"73.60000","0.09813","102.37959"
"73.80000","0.09840","102.49978"
"74.00000","0.09867","102.59905"
"74.20000","0.09895","102.68006"
"74.40000","0.09920","102.75928"
"74.60000","0.09946","102.84067"
"74.80000","0.09973","102.93033"
"75.00000","0.09999","103.02596"
"75.20000","0.10028","103.15234"
"75.40000","0.10054","103.21056"
"75.60000","0.10081","103.29392"
"75.80000","0.10107","103.36346"
"76.00000","0.10132","103.44063"
"76.20000","0.10161","103.55994"
"76.40000","0.10187","103.63207"
"76.60000","0.10215","103.71946"
"76.80000","0.10241","103.80033"
"77.00000","0.10265","103.84601"
"77.20000","0.10294","103.94126"
"77.40000","0.10319","104.01348"
"77.60000","0.10347","104.11125"
"77.80000","0.10375","104.20495"
"78.00000","0.10400","104.25785"
"78.20000","0.10426","104.33115"
"78.40000","0.10453","104.41048"
"78.60000","0.10480","104.49985"
"78.80000","0.10507","104.59115"
"79.00000","0.10535","104.64938"
"79.20000","0.10560","104.70182"
"79.40000","0.10586","104.75392"
"79.60000","0.10613","104.82615"
"79.80000","0.10639","104.90329"
"80.00000","0.10669","104.99537"
"80.20000","0.10694","105.03759"
"80.40000","0.10721","105.10142"
"80.60000","0.10747","105.14680"
"80.80000","0.10772","105.20280"
"81.00000","0.10801","105.30717"
"81.20000","0.10827","105.35558"
"81.40000","0.10854","105.42410"
"81.60000","0.10881","105.47347"
"81.80000","0.10905","105.50077"
"82.00000","0.10934","105.58333"
"82.20000","0.10959","105.64052"
"82.40000","0.10987","105.72263"
"82.60000","0.11015","105.79763"
"82.80000","0.11040","105.81077"
"83.00000","0.11067","105.87255"
"83.20000","0.11092","105.92523"
"83.40000","0.11120","106.00631"
"83.60000","0.11147","106.06756"
"83.80000","0.11175","106.11320"
"84.00000","0.11200","106.14505"
"84.20000","0.11226","106.19579"
"84.40000","0.11253","106.26250"
"84.60000","0.11280","106.31852"
"84.80000","0.11308","106.38791"
"85.00000","0.11334","106.40577"
"85.20000","0.11361","106.45399"
"85.40000","0.11387","106.49763"
"85.60000","0.11412","106.53252"
"85.80000","0.11441","106.61403"
"86.00000","0.11467","106.64993"
"86.20000","0.11495","106.69962"
"86.40000","0.11521","106.73525"
"86.60000","0.11545","106.74942"
"86.80000","0.11573","106.81191"
"87.00000","0.11600","106.85931"
"87.20000","0.11627","106.90925"
"87.40000","0.11655","106.95277"
"87.60000","0.11680","106.95781"
"87.80000","0.11706","107.00149"
"88.00000","0.11733","107.02157"
"88.20000","0.11760","107.09625"
"88.40000","0.11787","107.13856"
"88.60000","0.11815","107.16872"
"88.80000","0.11840","107.18928"
"89.00000","0.11867","107.21517"
"89.20000","0.11894","107.25640"
"89.40000","0.11920","107.29556"
"89.60000","0.11948","107.35690"
"89.80000","0.11974","107.35800"
"90.00000","0.12001","107.38961"
"90.20000","0.12027","107.41336"
"90.40000","0.12052","107.43463"
"90.60000","0.12081","107.49400"
"90.80000","0.12107","107.50282"
"91.00000","0.12135","107.55124"
"91.20000","0.12161","107.57101"
"91.40000","0.12185","107.55835"
"91.60000","0.12214","107.61400"
"91.80000","0.12240","107.63782"
"92.00000","0.12268","107.68455"
"92.20000","0.12295","107.70891"
"92.40000","0.12320","107.69195"
"92.60000","0.12346","107.73069"
"92.80000","0.12373","107.73818"
"93.00000","0.12400","107.78837"
"93.20000","0.12427","107.83210"
"93.40000","0.12455","107.82578"
"93.60000","0.12480","107.84476"
"93.80000","0.12506","107.84702"
"94.00000","0.12533","107.87185"
"94.20000","0.12560","107.89475"
"94.40000","0.12588","107.93081"
"94.60000","0.12614","107.94032"
"94.80000","0.12641","107.94311"
"95.00000","0.12667","107.95892"
"95.20000","0.12692","107.96213"
"95.40000","0.12721","108.01481"
"95.60000","0.12747","108.00679"
"95.80000","0.12775","108.02284"
"96.00000","0.12801","108.03566"
"96.20000","0.12825","108.01532"
"96.40000","0.12854","108.06529"
"96.60000","0.12880","108.05747"
"96.80000","0.12908","108.08511"
"97.00000","0.12935","108.11053"
"97.20000","0.12960","108.07760"
"97.40000","0.12986","108.10199"
"97.60000","0.13012","108.10089"
"97.80000","0.13040","108.11849"
"98.00000","0.13068","108.14681"
"98.20000","0.13095","108.13984"
"98.40000","0.13120","108.14138"
"98.60000","0.13146","108.13156"
"98.80000","0.13173","108.14696"
"99.00000","0.13200","108.16400"
"99.20000","0.13229","108.19132"
"99.40000","0.13253","108.17391"
"99.60000","0.13281","108.16528"
"99.80000","0.13307","108.16182"
"100.00000","0.13332","108.16137"
"100.20000","0.13361","108.21019"
"100.40000","0.13387","108.17845"
"100.60000","0.13414","108.18780"
"100.80000","0.13441","108.18482"
"101.00000","0.13465","108.15239"
"101.20000","0.13494","108.19300"
"101.40000","0.13520","108.17727"
"101.60000","0.13548","108.20164"
"101.80000","0.13575","108.19867"
"102.00000","0.13600","108.16015"
"102.20000","0.13627","108.17621"
"102.40000","0.13653","108.16559"
"102.60000","0.13680","108.19625"
"102.80000","0.13707","108.19211"
"103.00000","0.13735","108.16987"
"103.20000","0.13760","108.16021"
"103.40000","0.13786","108.13291"
"103.60000","0.13813","108.14674"
"103.80000","0.13840","108.14219"
"104.00000","0.13869","108.16257"
"104.20000","0.13894","108.13348"
"104.40000","0.13921","108.11331"
"104.60000","0.13946","108.10936"
"104.80000","0.13972","108.08658"
"105.00000","0.14001","108.12131"
"105.20000","0.14027","108.08955"
"105.40000","0.14054","108.08932"
"105.60000","0.14081","108.06567"
"105.80000","0.14105","108.03374"
"106.00000","0.14134","108.05615"
"106.20000","0.14160","108.03607"
"106.40000","0.14188","108.04330"
"106.60000","0.14215","108.03099"
"106.80000","0.14240","107.98687"
"107.00000","0.14266","107.98424"
"107.20000","0.14293","107.96582"
"107.40000","0.14320","107.97910"
"107.60000","0.14347","107.96488"
"107.80000","0.14375","107.93614"
"108.00000","0.14400","107.91655"
"108.20000","0.14426","107.90378"
"108.40000","0.14453","107.89227"
"108.60000","0.14480","107.88385"
"108.80000","0.14508","107.88000"
"109.00000","0.14534","107.83934"
"109.20000","0.14561","107.82024"
"109.40000","0.14587","107.80411"
"109.60000","0.14612","107.76819"
"109.80000","0.14641","107.79345"
"110.00000","0.14667","107.75900"
"110.20000","0.14694","107.73788"
"110.40000","0.14721","107.72296"
"110.60000","0.14745","107.67687"
"110.80000","0.14774","107.67494"
"111.00000","0.14800","107.65261"
"111.20000","0.14828","107.64305"
"111.40000","0.14854","107.62515"
"111.60000","0.14880","107.56582"
"111.80000","0.14907","107.55974"
"112.00000","0.14932","107.52706"
"112.20000","0.14960","107.53500"
"112.40000","0.14987","107.51836"
"112.60000","0.15014","107.48321"
"112.80000","0.15040","107.45295"
"113.00000","0.15066","107.41759"
"113.20000","0.15093","107.40957"
"113.40000","0.15120","107.38955"
"113.60000","0.15148","107.38255"
"113.80000","0.15174","107.33830"
"114.00000","0.15200","107.31474"
"114.20000","0.15226","107.28126"
"114.40000","0.15252","107.25650"
"114.60000","0.15281","107.26376"
"114.80000","0.15307","107.21822"
"115.00000","0.15334","107.19548"
"115.20000","0.15361","107.17022"
"115.40000","0.15385","107.10807"
"115.60000","0.15414","107.12212"
"115.80000","0.15440","107.07551"
"116.00000","0.15468","107.08099"
"116.20000","0.15495","107.05252"
"116.40000","0.15519","106.97732"
"116.60000","0.15547","106.97503"
"116.80000","0.15573","106.93761"
"117.00000","0.15600","106.92843"
"117.20000","0.15627","106.91092"
"117.40000","0.15654","106.87146"
"117.60000","0.15680","106.84185"
"117.80000","0.15706","106.80092"
"118.00000","0.15733","106.78723"
"118.20000","0.15760","106.76135"
"118.40000","0.15789","106.75916"
"118.60000","0.15813","106.71727"
"118.80000","0.15840","106.67539"
"119.00000","0.15866","106.62858"
"119.20000","0.15892","106.60058"
"119.40000","0.15922","106.61270"
"119.60000","0.15946","106.54279"
"119.80000","0.15974","106.53321"
"120.00000","0.16001","106.49180"
"120.20000","0.16025","106.43936"
"120.40000","0.16054","106.43939"
"120.60000","0.16080","106.41003"
"120.80000","0.16107","106.37777"
"121.00000","0.16135","106.36020"
"121.20000","0.16160","106.29397"
"121.40000","0.16186","106.27178"
"121.60000","0.16213","106.23981"
"121.80000","0.16240","106.22381"
"122.00000","0.16268","106.20255"
"122.20000","0.16294","106.14571"
"122.40000","0.16320","106.11641"
"122.60000","0.16346","106.06498"
"122.80000","0.16373","106.04837"
"123.00000","0.16400","106.02674"
"123.20000","0.16428","106.01258"
"123.40000","0.16454","105.95846"
"123.60000","0.16480","105.90489"
"123.80000","0.16506","105.88259"
"124.00000","0.16532","105.84289"
"124.20000","0.16562","105.85024"
"124.40000","0.16587","105.78118"
"124.60000","0.16614","105.75633"
"124.80000","0.16641","105.70844"
"125.00000","0.16665","105.64125"
"125.20000","0.16694","105.64614"
"125.40000","0.16720","105.60049"
"125.60000","0.16748","105.57327"
"125.80000","0.16774","105.55047"
"126.00000","0.16800","105.48059"
"126.20000","0.16826","105.47011"
"126.40000","0.16853","105.42887"
"126.60000","0.16881","105.41254"
"126.80000","0.16907","105.38549"
"127.00000","0.16934","105.32758"
"127.20000","0.16960","105.28875"
"127.40000","0.16986","105.24785"
"127.60000","0.17013","105.22297"
"127.80000","0.17040","105.18798"
"128.00000","0.17068","105.18242"
"128.20000","0.17094","105.11595"
"128.40000","0.17121","105.06739"
"128.60000","0.17147","105.02985"
"128.80000","0.17172","104.99176"
"129.00000","0.17201","104.98636"
"129.20000","0.17227","104.92253"
"129.40000","0.17255","104.89027"
"129.60000","0.17281","104.85559"
"129.80000","0.17305","104.77563"
"130.00000","0.17334","104.77745"
"130.20000","0.17360","104.73635"
"130.40000","0.17388","104.71148"
"130.60000","0.17414","104.66883"
"130.80000","0.17440","104.60451"
"131.00000","0.17466","104.58782"
"131.20000","0.17492","104.53742"
"131.40000","0.17521","104.52672"
"131.60000","0.17547","104.49195"
"131.80000","0.17574","104.42652"
"132.00000","0.17600","104.38490"
"132.20000","0.17626","104.33644"
"132.40000","0.17653","104.31799"
"132.60000","0.17680","104.27375"
"132.80000","0.17709","104.24584"
"133.00000","0.17733","104.17982"
"133.20000","0.17760","104.13766"
"133.40000","0.17787","104.10160"
"133.60000","0.17812","104.04775"
"133.80000","0.17841","104.03494"
"134.00000","0.17867","103.97483"
"134.20000","0.17894","103.94848"
"134.40000","0.17921","103.89072"
"134.60000","0.17945","103.83677"
"134.80000","0.17974","103.81500"
"135.00000","0.18000","103.76679"
"135.20000","0.18028","103.74823"
"135.40000","0.18055","103.70320"
"135.60000","0.18079","103.62593"
"135.80000","0.18107","103.60837"
"136.00000","0.18132","103.55122"
"136.20000","0.18161","103.52347"
"136.40000","0.18188","103.49221"
"136.60000","0.18214","103.42640"
"136.80000","0.18240","103.39254"
"137.00000","0.18266","103.34148"
"137.20000","0.18293","103.32215"
"137.40000","0.18320","103.28818"
"137.60000","0.18349","103.24947"
"137.80000","0.18373","103.18505"
"138.00000","0.18400","103.12526"
"138.20000","0.18426","103.09990"
"138.40000","0.18452","103.04626"
"138.60000","0.18482","103.04101"
"138.80000","0.18507","102.96342"
"139.00000","0.18534","102.94045"
"139.20000","0.18561","102.88786"
"139.40000","0.18585","102.82049"
"139.60000","0.18614","102.81556"
"139.80000","0.18640","102.75182"
"140.00000","0.18668","102.72846"
"140.20000","0.18695","102.68172"
"140.40000","0.18719","102.60390"
"140.60000","0.18747","102.58760"
"140.80000","0.18773","102.53471"
"141.00000","0.18801","102.51321"
"141.20000","0.18828","102.47642"
"141.40000","0.18854","102.40535"
"141.60000","0.18880","102.36352"
"141.80000","0.18906","102.30120"
"142.00000","0.18933","102.26808"
"142.20000","0.18960","102.22804"
"142.40000","0.18989","102.19889"
"142.60000","0.19014","102.13185"
"142.80000","0.19040","102.07932"
"143.00000","0.19067","102.03352"
"143.20000","0.19092","101.99380"
"143.40000","0.19122","101.98667"
"143.60000","0.19147","101.90162"
"143.80000","0.19174","101.85925"
"144.00000","0.19201","101.81924"
"144.20000","0.19225","101.74448"
"144.40000","0.19254","101.74807"
"144.60000","0.19280","101.69269"
"144.80000","0.19308","101.66064"
"145.00000","0.19335","101.61249"
"145.20000","0.19359","101.53105"
"145.40000","0.19387","101.51029"
"145.60000","0.19412","101.44515"
"145.80000","0.19441","101.41554"
"146.00000","0.19468","101.36647"
"146.20000","0.19494","101.30532"
"146.40000","0.19520","101.26069"
"146.60000","0.19546","101.19899"
"146.80000","0.19573","101.17000"
"147.00000","0.19600","101.13631"
"147.20000","0.19629","101.09953"
"147.40000","0.19653","101.02318"
"147.60000","0.19680","100.96991"
"147.80000","0.19707","100.92935"
"148.00000","0.19732","100.87645"
"148.20000","0.19761","100.86465"
"148.40000","0.19787","100.79531"
"148.60000","0.19814","100.75848"
"148.80000","0.19840","100.69664"
"149.00000","0.19865","100.62874"
"149.20000","0.19894","100.61276"
"149.40000","0.19920","100.54939"
"149.60000","0.19948","100.51160"
"149.80000","0.19974","100.45547"
"150.00000","0.19999","100.36936"
"150.20000","0.20027","100.35599"
"150.40000","0.20053","100.29456"
"150.60000","0.20081","100.27063"
"150.80000","0.20108","100.21835"
"151.00000","0.20134","100.14447"
"151.20000","0.20160","100.10100"
"151.40000","0.20186","100.03509"
"151.60000","0.20213","100.00087"
"151.80000","0.20240","99.96358"
"152.00000","0.20268","99.91841"
"152.20000","0.20293","99.85045"
"152.40000","0.20320","99.79893"
"152.60000","0.20347","99.75587"
"152.80000","0.20372","99.69313"
"153.00000","0.20401","99.67950"
"153.20000","0.20427","99.60800"
"153.40000","0.20454","99.55405"
"153.60000","0.20480","99.50516"
"153.80000","0.20506","99.43252"
"154.00000","0.20534","99.42441"
"154.20000","0.20560","99.35451"
"154.40000","0.20588","99.31272"
"154.60000","0.20615","99.26479"
"154.80000","0.20639","99.19491"
"155.00000","0.20667","99.16156"
"155.20000","0.20693","99.10570"
"155.40000","0.20721","99.07201"
"155.60000","0.20748","99.03062"
"155.80000","0.20774","98.93332"
"156.00000","0.20800","98.88931"
"156.20000","0.20826","98.82100"
"156.40000","0.20853","98.78955"
"156.60000","0.20880","98.74532"
"156.80000","0.20908","98.69448"
"157.00000","0.20933","98.63513"
"157.20000","0.20960","98.58160"
"157.40000","0.20986","98.52853"
"157.60000","0.21013","98.48134"
"157.80000","0.21042","98.46251"
"158.00000","0.21067","98.38605"
"158.20000","0.21094","98.32810"
"158.40000","0.21120","98.27497"
"158.60000","0.21145","98.19793"
"158.80000","0.21174","98.19168"
"159.00000","0.21200","98.11501"
"159.20000","0.21228","98.08519"
"159.40000","0.21254","98.01803"
"159.60000","0.21279","97.92429"
"159.80000","0.21307","97.90011"
"160.00000","0.21333","97.83136"
"160.20000","0.21361","97.80123"
"160.40000","0.21388","97.75796"
"160.60000","0.21414","97.67009"
"160.80000","0.21440","97.62706"
"161.00000","0.21466","97.56332"
"161.20000","0.21493","97.52373"
"161.40000","0.21521","97.47845"
"161.60000","0.21549","97.42425"
"161.80000","0.21573","97.35319"
"162.00000","0.21600","97.29169"
"162.20000","0.21626","97.24945"
"162.40000","0.21653","97.19728"
"162.60000","0.21682","97.17465"
"162.80000","0.21707","97.08417"
"163.00000","0.21734","97.03566"
"163.20000","0.21760","96.97216"
"163.40000","0.21785","96.89680"
"163.60000","0.21814","96.88054"
"163.80000","0.21840","96.80427"
"164.00000","0.21868","96.76006"
"164.20000","0.21894","96.68019"
"164.40000","0.21919","96.60759"
"164.60000","0.21947","96.57569"
"164.80000","0.21973","96.51502"
"165.00000","0.22001","96.48099"
"165.20000","0.22028","96.42448"
"165.40000","0.22054","96.35424"
"165.60000","0.22080","96.28772"
"165.80000","0.22106","96.22931"
"166.00000","0.22134","96.19364"
"166.20000","0.22160","96.13661"
"166.40000","0.22189","96.07922"
"166.60000","0.22213","96.01514"
"166.80000","0.22240","95.94913"
"167.00000","0.22266","95.90098"
"167.20000","0.22293","95.84587"
"167.40000","0.22322","95.81319"
"167.60000","0.22347","95.73000"
"167.80000","0.22374","95.67781"
"168.00000","0.22400","95.62651"
"168.20000","0.22425","95.54473"
"168.40000","0.22454","95.53278"
"168.60000","0.22480","95.46221"
"168.80000","0.22508","95.40313"
"169.00000","0.22534","95.32626"
"169.20000","0.22559","95.23657"
"169.40000","0.22587","95.20868"
"169.60000","0.22613","95.14351"
"169.80000","0.22641","95.11051"
"170.00000","0.22668","95.05742"
"170.20000","0.22694","94.96321"
"170.40000","0.22720","94.91096"
"170.60000","0.22746","94.83003"
"170.80000","0.22773","94.81151"
"171.00000","0.22800","94.74947"
"171.20000","0.22828","94.68754"
"171.40000","0.22853","94.61370"
"171.60000","0.22880","94.53854"
"171.80000","0.22907","94.49014"
"172.00000","0.22933","94.42633"
"172.20000","0.22962","94.39810"
"172.40000","0.22987","94.30899"
"172.60000","0.23014","94.25288"
"172.80000","0.23040","94.18287"
"173.00000","0.23065","94.11363"
"173.20000","0.23094","94.08779"
"173.40000","0.23120","94.00565"
"173.60000","0.23148","93.95423"
"173.80000","0.23174","93.86965"
"174.00000","0.23199","93.77371"
"174.20000","0.23227","93.74776"
"174.40000","0.23253","93.65938"
"174.60000","0.23281","93.62897"
"174.80000","0.23308","93.56119"
"175.00000","0.23333","93.46871"
"175.20000","0.23360","93.42516"
"175.40000","0.23386","93.35662"
"175.60000","0.23413","93.31531"
"175.80000","0.23441","93.25173"
"176.00000","0.23468","93.18014"
"176.20000","0.23493","93.10946"
"176.40000","0.23520","93.03213"
"176.60000","0.23546","92.99027"
"176.80000","0.23573","92.92697"
"177.00000","0.23602","92.89472"
"177.20000","0.23627","92.79085"
"177.40000","0.23654","92.72274"
"177.60000","0.23680","92.65926"
"177.80000","0.23705","92.58671"
"178.00000","0.23734","92.56706"
"178.20000","0.23760","92.48599"
"178.40000","0.23788","92.43533"
"178.60000","0.23814","92.35895"
"178.80000","0.23839","92.27075"
"179.00000","0.23867","92.24276"
"179.20000","0.23893","92.16198"
"179.40000","0.23921","92.12164"
"179.60000","0.23948","92.05103"
"179.80000","0.23974","91.95436"
"180.00000","0.24000","91.91267"
"180.20000","0.24026","91.82341"
"180.40000","0.24053","91.78965"
"180.60000","0.24081","91.73969"
"180.80000","0.24109","91.65691"
"181.00000","0.24133","91.58739"
"181.20000","0.24160","91.51748"
"181.40000","0.24186","91.46898"
"181.60000","0.24213","91.40787"
"181.80000","0.24242","91.37876"
"182.00000","0.24267","91.29093"
"182.20000","0.24294","91.22339"
"182.40000","0.24320","91.14932"
"182.60000","0.24345","91.07067"
"182.80000","0.24374","91.05190"
"183.00000","0.24400","90.96612"
"183.20000","0.24428","90.91260"
"183.40000","0.24454","90.84023"
"183.60000","0.24479","90.75206"
"183.80000","0.24507","90.72171"
"184.00000","0.24533","90.64691"
"184.20000","0.24561","90.59476"
"184.40000","0.24588","90.52518"
"184.60000","0.24613","90.43980"
"184.80000","0.24640","90.38233"
"185.00000","0.24666","90.31075"
"185.20000","0.24693","90.27522"
"185.40000","0.24721","90.20903"
"185.60000","0.24748","90.14155"
"185.80000","0.24773","90.04611"
"186.00000","0.24800","89.97999"
"186.20000","0.24827","89.93446"
"186.40000","0.24853","89.85736"
"186.60000","0.24882","89.83059"
"186.80000","0.24907","89.73614"
"187.00000","0.24934","89.66468"
"187.20000","0.24960","89.59721"
"187.40000","0.24985","89.53907"
"187.60000","0.25014","89.51537"
"187.80000","0.25040","89.42988"
"188.00000","0.25068","89.36868"
"188.20000","0.25094","89.29433"
"188.40000","0.25119","89.20554"
"188.60000","0.25147","89.17938"
"188.80000","0.25173","89.10998"
"189.00000","0.25201","89.07503"
"189.20000","0.25228","88.99787"
"189.40000","0.25253","88.92193"
"189.60000","0.25280","88.87406"
"189.80000","0.25306","88.80379"
"190.00000","0.25334","88.76588"
"190.20000","0.25360","88.70053"
"190.40000","0.25388","88.63399"
"190.60000","0.25414","88.55973"
"190.80000","0.25440","88.48369"
"191.00000","0.25467","88.43071"
"191.20000","0.25493","88.37205"
"191.40000","0.25521","88.33804"
"191.60000","0.25547","88.25341"
"191.80000","0.25574","88.20137"
"192.00000","0.25600","88.14236"
"192.20000","0.25625","88.07569"
"192.40000","0.25654","88.05468"
"192.60000","0.25680","87.97875"
"192.80000","0.25708","87.93225"
"193.00000","0.25734","87.85888"
"193.20000","0.25759","87.77993"
"193.40000","0.25787","87.74078"
"193.60000","0.25813","87.67224"
"193.80000","0.25841","87.63730"
"194.00000","0.25868","87.56908"
"194.20000","0.25893","87.48657"
"194.40000","0.25920","87.44175"
"194.60000","0.25946","87.36913"
"194.80000","0.25974","87.35111"
"195.00000","0.26001","87.30737"
"195.20000","0.26028","87.23010"
"195.40000","0.26054","87.16365"
"195.60000","0.26080","87.10365"
"195.80000","0.26106","87.05194"
"196.00000","0.26133","87.00147"
"196.20000","0.26162","86.96958"
"196.40000","0.26187","86.89452"
"196.60000","0.26214","86.82351"
"196.80000","0.26240","86.76992"
"197.00000","0.26266","86.70334"
"197.20000","0.26295","86.69056"
"197.40000","0.26320","86.61634"
"197.60000","0.26348","86.56764"
"197.80000","0.26374","86.51756"
"198.00000","0.26399","86.43787"
"198.20000","0.26427","86.41651"
"198.40000","0.26453","86.34406"
"198.60000","0.26481","86.32239"
"198.80000","0.26508","86.26543"
"199.00000","0.26533","86.17662"
"199.20000","0.26560","86.14606"
"199.40000","0.26586","86.09149"
"199.60000","0.26614","86.06956"
"199.80000","0.26641","86.03334"
"200.00000","0.26668","85.97706"
"200.20000","0.26693","85.91840"
"200.40000","0.26719","85.84883"
"200.60000","0.26746","85.80653"
"200.80000","0.26773","85.77579"
"201.00000","0.26802","85.75597"
"201.20000","0.26827","85.67948"
"201.40000","0.26854","85.62524"
"201.60000","0.26880","85.57508"
"201.80000","0.26906","85.52545"
"202.00000","0.26935","85.52656"
"202.20000","0.26960","85.45303"
"202.40000","0.26988","85.42059"
"202.60000","0.27014","85.36366"
"202.80000","0.27039","85.29995"
"203.00000","0.27067","85.29646"
"203.20000","0.27093","85.24322"
"203.40000","0.27121","85.22053"
"203.60000","0.27148","85.17642"
"203.80000","0.27173","85.09814"
"204.00000","0.27200","85.07067"
"204.20000","0.27226","85.00843"
"204.40000","0.27254","84.99641"
"204.60000","0.27281","84.95673"
"204.80000","0.27308","84.90497"
"205.00000","0.27333","84.85666"
"205.20000","0.27359","84.80808"
"205.40000","0.27387","84.78942"
"205.60000","0.27413","84.75216"
"205.80000","0.27442","84.74836"
"206.00000","0.27467","84.68104"
"206.20000","0.27494","84.63657"
"206.40000","0.27520","84.59507"
"206.60000","0.27546","84.54379"
"206.80000","0.27575","84.55257"
"207.00000","0.27600","84.48445"
"207.20000","0.27628","84.46456"
"207.40000","0.27654","84.41939"
"207.60000","0.27678","84.37054"
"207.80000","0.27707","84.35805"
"208.00000","0.27733","84.31950"
"208.20000","0.27761","84.29884"
"208.40000","0.27788","84.26403"
"208.60000","0.27813","84.20269"
"208.80000","0.27840","84.16733"
"209.00000","0.27866","84.13228"
"209.20000","0.27894","84.12882"
"209.40000","0.27921","84.09318"
"209.60000","0.27948","84.03930"
"209.80000","0.27973","84.00069"
"210.00000","0.28000","83.96372"
"210.20000","0.28027","83.95153"
"210.40000","0.28053","83.91040"
"210.60000","0.28082","83.91140"
"210.80000","0.28107","83.86189"
"211.00000","0.28134","83.82038"
"211.20000","0.28160","83.78473"
"211.40000","0.28186","83.74874"
"211.60000","0.28214","83.75381"
"211.80000","0.28240","83.71011"
"212.00000","0.28268","83.68311"
"212.20000","0.28294","83.64213"
"212.40000","0.28319","83.58182"
"212.60000","0.28347","83.58789"
"212.80000","0.28373","83.54198"
"213.00000","0.28401","83.53364"
"213.20000","0.28428","83.49167"
"213.40000","0.28453","83.43245"
"213.60000","0.28480","83.41623"
"213.80000","0.28506","83.38129"
"214.00000","0.28534","83.37733"
"214.20000","0.28561","83.34698"
"214.40000","0.28587","83.29818"
"214.60000","0.28614","83.25982"
"214.80000","0.28639","83.22962"
"215.00000","0.28667","83.21630"
"215.20000","0.28694","83.19068"
"215.40000","0.28721","83.17368"
"215.60000","0.28747","83.11824"
"215.80000","0.28774","83.08797"
"216.00000","0.28800","83.05331"
"216.20000","0.28826","83.03285"
"216.40000","0.28855","83.04094"
"216.60000","0.28880","82.98712"
"216.80000","0.28908","82.97337"
"217.00000","0.28934","82.93173"
"217.20000","0.28959","82.87166"
"217.40000","0.28987","82.88475"
"217.60000","0.29013","82.82713"
"217.80000","0.29041","82.83074"
"218.00000","0.29068","82.80431"
"218.20000","0.29093","82.74869"
"218.40000","0.29120","82.73309"
"218.60000","0.29146","82.69649"
"218.80000","0.29174","82.70076"
"219.00000","0.29201","82.67719"
"219.20000","0.29228","82.63852"
"219.40000","0.29253","82.59179"
"219.60000","0.29279","82.55290"
"219.80000","0.29306","82.53228"
"220.00000","0.29334","82.52500"
"220.20000","0.29362","82.51275"
"220.40000","0.29387","82.44895"
"220.60000","0.29414","82.40389"
"220.80000","0.29440","82.37707"
"221.00000","0.29466","82.33506"
"221.20000","0.29495","82.34430"
"221.40000","0.29520","82.28276"
"221.60000","0.29547","82.25524"
"221.80000","0.29574","82.20783"
"222.00000","0.29599","82.17710"
"222.20000","0.29627","82.16971"
"222.40000","0.29653","82.12606"
"222.60000","0.29681","82.10254"
"222.80000","0.29708","82.06398"
"223.00000","0.29733","81.99317"
"223.20000","0.29760","81.96769"
"223.40000","0.29786","81.92571"
"223.60000","0.29814","81.90700"
"223.80000","0.29841","81.86924"
"224.00000","0.29868","81.81456"
"224.20000","0.29894","81.75477"
"224.40000","0.29919","81.69240"
"224.60000","0.29947","81.66114"
"224.80000","0.29973","81.60803"
"225.00000","0.30002","81.56594"
"225.20000","0.30027","81.45945"
"225.40000","0.30053","81.38248"
"225.60000","0.30080","81.32188"
"225.80000","0.30106","81.24673"
"226.00000","0.30135","81.19912"
"226.20000","0.30160","81.07748"
"226.40000","0.30188","80.97699"
"226.60000","0.30214","80.84381"
"226.80000","0.30238","80.68076"
"227.00000","0.30267","80.55689"
"227.20000","0.30293","80.37064"
"227.40000","0.30321","80.16661"
"227.60000","0.30348","79.87784"
"227.80000","0.30373","79.48058"
"228.00000","0.30400","78.98869"
"228.20000","0.30426","78.10609"
"228.30600","0.30442","71.20911"
"228.31300","0.30444","57.84958"
"228.31900","0.30445","44.66309"
"228.32500","0.30447","32.06021"
"228.33200","0.30448","19.56762"
"228.34000","0.30449","8.98254"