File: materials_lab1/ENGR314_FA19_0002_Polypropelyne_B_redo_20190903_ACE.is_tens_RawData/Specimen_RawData_1.csv
Material,Acrylic
Geometry,Circular
Length,"2.00000",in
Diameter,"0.11700",in

Time,Extension,Load
(s),(in),(lbf)
"0.00000","0.00001","-3.87334"
"0.50000","0.00068","-3.04165"
"1.00000","0.00135","-2.15254"
"1.50000","0.00202","-1.29616"
"2.00000","0.00269","-0.47064"
"2.50000","0.00336","0.35341"
"3.00000","0.00401","1.15075"
"3.50000","0.00468","1.93244"
"4.00000","0.00534","2.70214"
"4.50000","0.00600","3.45998"
"5.00000","0.00667","4.19526"
"5.50000","0.00733","4.93269"
"6.00000","0.00800","5.66972"
"6.50000","0.00868","6.38722"
"7.00000","0.00934","7.10364"
"7.50000","0.01002","7.79766"
"8.00000","0.01068","8.47760"
"8.50000","0.01135","9.15997"
"9.00000","0.01201","9.81585"
"9.50000","0.01268","10.48034"
"10.00000","0.01333","11.11468"
"10.50000","0.01400","11.76016"
"11.00000","0.01466","12.37023"
"11.50000","0.01533","13.00755"
"12.00000","0.01600","13.61365"
"12.50000","0.01668","14.22644"
"13.00000","0.01735","14.80693"
"13.50000","0.01802","15.40694"
"14.00000","0.01869","15.98952"
"14.50000","0.01935","16.55497"
"15.00000","0.02002","17.11088"
"15.50000","0.02068","17.63831"
"16.00000","0.02134","18.18066"
"16.50000","0.02200","18.68982"
"17.00000","0.02267","19.20973"
"17.50000","0.02333","19.71117"
"18.00000","0.02400","20.19750"
"18.50000","0.02467","20.67794"
"19.00000","0.02535","21.16400"
"19.50000","0.02601","21.63793"
"20.00000","0.02669","22.09947"
"20.50000","0.02734","22.53552"
"21.00000","0.02802","22.98522"
"21.50000","0.02867","23.38974"
"22.00000","0.02934","23.81302"
"22.50000","0.03000","24.20526"
"23.00000","0.03067","24.59768"
"23.50000","0.03133","24.97737"
"24.00000","0.03200","25.36954"
"24.50000","0.03267","25.73217"
"25.00000","0.03335","26.10140"
"25.50000","0.03402","26.45807"
"26.00000","0.03469","26.79690"
"26.50000","0.03536","27.13542"
"27.00000","0.03601","27.45517"
"27.50000","0.03668","27.77187"
"28.00000","0.03734","28.07283"
"28.50000","0.03800","28.37126"
"29.00000","0.03867","28.65247"
"29.50000","0.03933","28.93056"
"30.00000","0.04000","29.21258"
"30.50000","0.04067","29.48891"
"31.00000","0.04134","29.76283"
"31.50000","0.04202","30.02163"
"32.00000","0.04268","30.27718"
"32.50000","0.04336","30.54368"
"33.00000","0.04401","30.78250"
"33.50000","0.04468","31.02601"
"34.00000","0.04534","31.25742"
"34.50000","0.04600","31.48188"
"35.00000","0.04666","31.70114"
"35.50000","0.04734","31.92544"
"36.00000","0.04800","32.14671"
"36.50000","0.04867","32.36864"
"37.00000","0.04934","32.59167"
"37.50000","0.05001","32.81689"
"38.00000","0.05069","33.03290"
"38.50000","0.05135","33.22545"
"39.00000","0.05202","33.45250"
"39.50000","0.05268","33.62386"
"40.00000","0.05335","33.82887"
"40.50000","0.05400","34.01238"
"41.00000","0.05467","34.22022"
"41.50000","0.05534","34.39538"
"42.00000","0.05600","34.58449"
"42.50000","0.05667","34.77073"
"43.00000","0.05735","34.95986"
"43.50000","0.05801","35.14879"
"44.00000","0.05869","35.33594"
"44.50000","0.05935","35.51105"
"45.00000","0.06002","35.68382"
"45.50000","0.06067","35.86148"
"46.00000","0.06135","36.04037"
"46.50000","0.06200","36.20221"
"47.00000","0.06267","36.37690"
"47.50000","0.06333","36.52902"
"48.00000","0.06400","36.71214"
"48.50000","0.06467","36.87100"
"49.00000","0.06534","37.03873"
"49.50000","0.06601","37.20986"
"50.00000","0.06668","37.36842"
"50.50000","0.06736","37.53647"
"51.00000","0.06801","37.69837"
"51.50000","0.06869","37.85778"
"52.00000","0.06934","37.99788"
"52.50000","0.07001","38.16153"
"53.00000","0.07067","38.29557"
"53.50000","0.07134","38.45255"
"54.00000","0.07200","38.60791"
"54.50000","0.07267","38.75283"
"55.00000","0.07334","38.90151"
"55.50000","0.07401","39.04879"
"56.00000","0.07468","39.19867"
"56.50000","0.07536","39.35131"
"57.00000","0.07601","39.49625"
"57.50000","0.07668","39.64433"
"58.00000","0.07734","39.77566"
"58.50000","0.07801","39.92492"
"59.00000","0.07866","40.05388"
"59.50000","0.07934","40.20206"
"60.00000","0.08000","40.32719"
"60.50000","0.08067","40.46576"
"61.00000","0.08134","40.59162"
"61.50000","0.08201","40.75627"
"62.00000","0.08269","40.87072"
"62.50000","0.08335","41.01086"
"63.00000","0.08403","41.14838"
"63.50000","0.08468","41.26425"
"64.00000","0.08535","41.40789"
"64.50000","0.08600","41.52078"
"65.00000","0.08667","41.64784"
"65.50000","0.08734","41.76433"
"66.00000","0.08800","41.87856"
"66.50000","0.08867","41.99806"
"67.00000","0.08934","42.12434"
"67.50000","0.09001","42.25165"
"68.00000","0.09069","42.36708"
"68.50000","0.09135","42.47785"
"69.00000","0.09202","42.60819"
"69.50000","0.09267","42.71636"
"70.00000","0.09335","42.83171"
"70.50000","0.09400","42.93331"
"71.00000","0.09467","43.04643"
"71.50000","0.09533","43.15048"
"72.00000","0.09600","43.25657"
"72.50000","0.09667","43.36059"
"73.00000","0.09734","43.47477"
"73.50000","0.09801","43.58022"
"74.00000","0.09868","43.69297"
"74.50000","0.09936","43.80197"
"75.00000","0.10002","43.90273"
"75.50000","0.10069","43.99939"
"76.00000","0.10134","44.09225"
"76.50000","0.10201","44.20050"
"77.00000","0.10267","44.28373"
"77.50000","0.10334","44.36993"
"78.00000","0.10400","44.46202"
"78.50000","0.10467","44.55725"
"79.00000","0.10534","44.64316"
"79.50000","0.10601","44.73741"
"80.00000","0.10668","44.83343"
"80.50000","0.10736","44.92722"
"81.00000","0.10801","45.01315"
"81.50000","0.10868","45.10192"
"82.00000","0.10934","45.17359"
"82.50000","0.11001","45.26384"
"83.00000","0.11066","45.32518"
"83.50000","0.11134","45.41469"
"84.00000","0.11199","45.48017"
"84.50000","0.11267","45.56405"
"85.00000","0.11334","45.63353"
"85.50000","0.11401","45.72421"
"86.00000","0.11469","45.79573"
"86.50000","0.11535","45.87281"
"87.00000","0.11603","45.95517"
"87.50000","0.11668","46.00362"
"88.00000","0.11735","46.07986"
"88.50000","0.11801","46.12845"
"89.00000","0.11867","46.20439"
"89.50000","0.11934","46.25891"
"90.00000","0.12000","46.31398"
"90.50000","0.12067","46.37136"
"91.00000","0.12134","46.43412"
"91.50000","0.12201","46.49172"
"92.00000","0.12268","46.54995"
"92.50000","0.12335","46.54684"
"93.00000","0.12402","46.71086"
"93.50000","0.12467","46.71653"
"94.00000","0.12535","46.77020"
"94.50000","0.12600","46.82858"
"95.00000","0.12667","46.88279"
"95.50000","0.12733","46.93029"
"96.00000","0.12800","46.97232"
"96.50000","0.12866","47.01250"
"97.00000","0.12934","47.07128"
"97.50000","0.13001","47.10035"
"98.00000","0.13068","47.15673"
"98.50000","0.13136","47.19823"
"99.00000","0.13202","47.25420"
"99.50000","0.13269","47.29862"
"100.00000","0.13335","47.32114"
"100.50000","0.13402","47.37258"
"101.00000","0.13467","47.39342"
"101.50000","0.13534","47.42664"
"102.00000","0.13600","47.45461"
"102.50000","0.13667","47.49388"
"103.00000","0.13734","47.51779"
"103.50000","0.13801","47.55032"
"104.00000","0.13868","47.59074"
"104.50000","0.13936","47.62595"
"105.00000","0.14001","47.65631"
"105.50000","0.14069","47.69629"
"106.00000","0.14134","47.71522"
"106.50000","0.14201","47.74755"
"107.00000","0.14266","47.76921"
"107.50000","0.14334","47.79964"
"108.00000","0.14400","47.81278"
"108.50000","0.14467","47.84019"
"109.00000","0.14533","47.85260"
"109.50000","0.14601","47.88892"
"110.00000","0.14668","47.91065"
"110.50000","0.14735","47.93203"
"111.00000","0.14803","47.95851"
"111.50000","0.14868","47.98018"
"112.00000","0.14935","47.99777"
"112.50000","0.15001","48.00820"
"113.00000","0.15067","48.02807"
"113.50000","0.15134","48.03901"
"114.00000","0.15200","48.05135"
"114.50000","0.15267","48.05935"
"115.00000","0.15334","48.07284"
"115.50000","0.15401","48.08810"
"116.00000","0.15468","48.10049"
"116.50000","0.15534","48.12094"
"117.00000","0.15602","48.12197"
"117.50000","0.15668","48.13935"
"118.00000","0.15735","48.15670"
"118.50000","0.15801","48.16282"
"119.00000","0.15867","48.17837"
"119.50000","0.15933","48.16987"
"120.00000","0.16000","48.18431"
"120.50000","0.16066","48.18151"
"121.00000","0.16134","48.18915"
"121.50000","0.16201","48.18369"
"122.00000","0.16268","48.19431"
"122.50000","0.16335","48.20772"
"123.00000","0.16402","48.21630"
"123.50000","0.16469","48.22045"
"124.00000","0.16535","48.21671"
"124.50000","0.16602","48.22243"
"125.00000","0.16667","48.21123"
"125.50000","0.16734","48.20486"
"126.00000","0.16800","48.20726"
"126.50000","0.16866","48.20410"
"127.00000","0.16934","48.19849"
"127.50000","0.17001","48.19928"
"128.00000","0.17068","48.19780"
"128.50000","0.17135","48.19575"
"129.00000","0.17201","48.19595"
"129.50000","0.17269","48.20227"
"130.00000","0.17334","48.19569"
"130.50000","0.17402","48.19528"
"131.00000","0.17467","48.17526"
"131.50000","0.17534","48.17718"
"132.00000","0.17600","48.16312"
"132.50000","0.17667","48.14969"
"133.00000","0.17733","48.15263"
"133.50000","0.17801","48.14154"
"134.00000","0.17868","48.14256"
"134.50000","0.17935","48.14444"
"135.00000","0.18002","48.14130"
"135.50000","0.18069","48.13281"
"136.00000","0.18136","48.13400"
"136.50000","0.18201","48.11388"
"137.00000","0.18268","48.11923"
"137.50000","0.18334","48.10569"
"138.00000","0.18401","48.09523"
"138.50000","0.18467","48.08729"
"139.00000","0.18534","48.06749"
"139.50000","0.18600","48.05474"
"140.00000","0.18668","48.05336"
"140.50000","0.18734","48.04368"
"141.00000","0.18802","48.04195"
"141.50000","0.18868","48.03393"
"142.00000","0.18935","48.03131"
"142.50000","0.19001","48.00901"
"143.00000","0.19068","48.00252"
"143.50000","0.19133","47.97641"
"144.00000","0.19200","47.96688"
"144.50000","0.19266","47.95636"
"145.00000","0.19333","47.94180"
"145.50000","0.19400","47.92750"
"146.00000","0.19468","47.92243"
"146.50000","0.19535","47.90675"
"147.00000","0.19602","47.90094"
"147.50000","0.19669","47.89042"
"148.00000","0.19735","47.89436"
"148.50000","0.19802","47.87936"
"149.00000","0.19868","47.85418"
"149.50000","0.19934","47.83983"
"150.00000","0.20000","47.81968"
"150.50000","0.20067","47.80755"
"151.00000","0.20133","47.78698"
"151.50000","0.20200","47.77082"
"152.00000","0.20268","47.76039"
"152.50000","0.20335","47.74956"
"153.00000","0.20401","47.74136"
"153.50000","0.20469","47.73319"
"154.00000","0.20534","47.71392"
"154.50000","0.20602","47.69299"
"155.00000","0.20667","47.67766"
"155.50000","0.20734","47.66904"
"156.00000","0.20800","47.64258"
"156.50000","0.20867","47.63520"
"157.00000","0.20933","47.61192"
"157.50000","0.21000","47.59266"
"158.00000","0.21067","47.57833"
"158.50000","0.21135","47.57266"
"159.00000","0.21202","47.56514"
"159.50000","0.21269","47.56435"
"160.00000","0.21336","47.54516"
"160.50000","0.21401","47.51476"
"161.00000","0.21468","47.50897"
"161.50000","0.21534","47.48623"
"162.00000","0.21601","47.48318"
"162.50000","0.21667","47.45487"
"163.00000","0.21733","47.44045"
"163.50000","0.21800","47.41196"
"164.00000","0.21867","47.40278"
"164.50000","0.21934","47.39531"
"165.00000","0.22002","47.37755"
"165.50000","0.22068","47.36710"
"166.00000","0.22135","47.35289"
"166.50000","0.22201","47.33206"
"167.00000","0.22268","47.31298"
"167.50000","0.22333","47.29938"
"168.00000","0.22400","47.28582"
"168.50000","0.22466","47.26428"
"169.00000","0.22533","47.24690"
"169.50000","0.22600","47.23301"
"170.00000","0.22667","47.22215"
"170.50000","0.22734","47.20361"
"171.00000","0.22802","47.19363"
"171.50000","0.22869","47.18248"
"172.00000","0.22935","47.16630"
"172.50000","0.23002","47.15475"
"173.00000","0.23068","47.12891"
"173.50000","0.23134","47.12673"
"174.00000","0.23201","47.09934"
"174.50000","0.23267","47.08672"
"175.00000","0.23333","47.06165"
"175.50000","0.23400","47.05134"
"176.00000","0.23467","47.03028"
"176.50000","0.23534","47.02133"
"177.00000","0.23601","47.00577"
"177.50000","0.23669","46.99120"
"178.00000","0.23734","46.97363"
"178.50000","0.23802","46.97257"
"179.00000","0.23867","46.94713"
"179.50000","0.23934","46.92746"
"180.00000","0.24000","46.89599"
"180.50000","0.24067","46.88592"
"181.00000","0.24133","46.85413"
"181.50000","0.24200","46.85356"
"182.00000","0.24267","46.82907"
"182.50000","0.24334","46.81533"
"183.00000","0.24402","46.80458"
"183.50000","0.24469","46.78533"
"184.00000","0.24536","46.77215"
"184.50000","0.24601","46.74192"
"185.00000","0.24669","46.74912"
"185.50000","0.24734","46.72144"
"186.00000","0.24801","46.70736"
"186.50000","0.24867","46.68545"
"187.00000","0.24933","46.66329"
"187.50000","0.25000","46.64881"
"188.00000","0.25067","46.63557"
"188.50000","0.25135","46.62215"
"189.00000","0.25202","46.60500"
"189.50000","0.25268","46.58552"
"190.00000","0.25336","46.57497"
"190.50000","0.25401","46.54845"
"191.00000","0.25468","46.53714"
"191.50000","0.25534","46.51101"
"192.00000","0.25600","46.50370"
"192.50000","0.25666","46.48020"
"193.00000","0.25734","46.45593"
"193.50000","0.25800","46.43354"
"194.00000","0.25867","46.41913"
"194.50000","0.25934","46.40996"
"195.00000","0.26001","46.39591"
"195.50000","0.26069","46.38146"
"196.00000","0.26135","46.37566"
"196.50000","0.26202","46.35586"
"197.00000","0.26268","46.32120"
"197.50000","0.26335","46.31419"
"198.00000","0.26401","46.29954"
"198.50000","0.26467","46.27700"
"199.00000","0.26534","46.24679"
"199.50000","0.26600","46.22854"
"200.00000","0.26667","46.22218"
"200.50000","0.26734","46.19841"
"201.00000","0.26801","46.19022"
"201.50000","0.26869","46.17212"
"202.00000","0.26935","46.15587"
"202.50000","0.27002","46.14333"
"203.00000","0.27067","46.11173"
"203.50000","0.27135","46.10752"
"204.00000","0.27200","46.09154"
"204.50000","0.27267","46.06888"
"205.00000","0.27333","46.04114"
"205.50000","0.27400","46.02074"
"206.00000","0.27467","45.99755"
"206.50000","0.27535","45.99663"
"207.00000","0.27601","45.97342"
"207.50000","0.27669","45.96899"
"208.00000","0.27736","45.94609"
"208.50000","0.27802","45.91831"
"209.00000","0.27869","45.92146"
"209.50000","0.27934","45.89167"
"210.00000","0.28001","45.87202"
"210.50000","0.28067","45.85765"
"211.00000","0.28134","45.82910"
"211.50000","0.28200","45.81616"
"212.00000","0.28267","45.79748"
"212.50000","0.28334","45.78074"
"213.00000","0.28401","45.76267"
"213.50000","0.28468","45.75552"
"214.00000","0.28536","45.74208"
"214.50000","0.28601","45.72159"
"215.00000","0.28669","45.71261"
"215.50000","0.28734","45.68117"
"216.00000","0.28801","45.66650"
"216.50000","0.28866","45.64466"
"217.00000","0.28934","45.62522"
"217.50000","0.28999","45.60273"
"218.00000","0.29067","45.58695"
"218.50000","0.29134","45.57044"
"219.00000","0.29201","45.55412"
"219.50000","0.29269","45.54023"
"220.00000","0.29335","45.51572"
"220.50000","0.29402","45.50859"
"221.00000","0.29468","45.48411"
"221.50000","0.29535","45.47148"
"222.00000","0.29601","45.45605"
"222.50000","0.29667","45.44044"
"223.00000","0.29734","45.41008"
"223.50000","0.29800","45.40049"
"224.00000","0.29867","45.37688"
"224.50000","0.29934","45.35925"
"225.00000","0.30001","45.34109"
"225.50000","0.30069","45.32137"
"226.00000","0.30135","45.30687"
"226.50000","0.30202","45.29425"
"227.00000","0.30267","45.28555"
"227.50000","0.30335","45.26284"
"228.00000","0.30400","45.23238"
"228.50000","0.30467","45.21344"
"229.00000","0.30533","45.18562"
"229.50000","0.30600","45.17023"
"230.00000","0.30666","45.14653"
"230.50000","0.30734","45.13357"
"231.00000","0.30801","45.11621"
"231.50000","0.30868","45.10767"
"232.00000","0.30936","45.07536"
"232.50000","0.31002","45.04739"
"233.00000","0.31069","45.03898"
"233.50000","0.31134","45.00929"
"234.00000","0.31201","44.97478"
"234.50000","0.31267","44.93892"
"235.00000","0.31334","44.92257"
"235.50000","0.31400","44.90199"
"236.00000","0.31467","44.86334"
"236.50000","0.31534","44.83432"
"237.00000","0.31601","44.81280"
"237.50000","0.31668","44.79423"
"238.00000","0.31736","44.77798"
"238.50000","0.31801","44.74543"
"239.00000","0.31869","44.74943"
"239.50000","0.31934","44.71873"
"240.00000","0.32001","44.69027"
"240.50000","0.32066","44.66942"
"241.00000","0.32134","44.65352"
"241.50000","0.32199","44.63014"
"242.00000","0.32267","44.60998"
"242.50000","0.32333","44.58059"
"243.00000","0.32401","44.57436"
"243.50000","0.32468","44.55947"
"244.00000","0.32535","44.54148"
"244.50000","0.32603","44.53406"
"245.00000","0.32668","44.50445"
"245.50000","0.32735","44.50115"
"246.00000","0.32801","44.48061"
"246.50000","0.32868","44.46122"
"247.00000","0.32934","44.42344"
"247.50000","0.33000","44.40650"
"248.00000","0.33067","44.38473"
"248.50000","0.33134","44.37703"
"249.00000","0.33201","44.35880"
"249.50000","0.33268","44.33391"
"250.00000","0.33335","44.32561"
"250.50000","0.33402","44.31276"
"251.00000","0.33468","44.27850"
"251.50000","0.33535","44.27136"
"252.00000","0.33600","44.23966"
"252.50000","0.33667","44.23114"
"253.00000","0.33733","44.20181"
"253.50000","0.33800","44.18860"
"254.00000","0.33867","44.15926"
"254.50000","0.33934","44.14309"
"255.00000","0.34001","44.13271"
"255.50000","0.34068","44.11565"
"256.00000","0.34135","44.08947"
"256.50000","0.34202","44.07204"
"257.00000","0.34269","44.04838"
"257.50000","0.34335","44.01537"
"258.00000","0.34402","44.00686"
"258.50000","0.34467","43.98186"
"259.00000","0.34534","43.96299"
"259.50000","0.34600","43.93464"
"260.00000","0.34667","43.90494"
"260.50000","0.34733","43.88174"
"261.00000","0.34801","43.85968"
"261.50000","0.34867","43.84935"
"262.00000","0.34935","43.81292"
"262.50000","0.35001","43.78655"
"263.00000","0.35069","43.78314"
"263.50000","0.35134","43.74803"
"264.00000","0.35201","43.72521"
"264.50000","0.35267","43.69891"
"265.00000","0.35334","43.67389"
"265.50000","0.35400","43.63707"
"266.00000","0.35467","43.61589"
"266.50000","0.35533","43.58739"
"267.00000","0.35601","43.56687"
"267.50000","0.35668","43.54728"
"268.00000","0.35735","43.52216"
"268.50000","0.35803","43.49641"
"269.00000","0.35869","43.47218"
"269.50000","0.35936","43.45338"
"270.00000","0.36001","43.41517"
"270.50000","0.36068","43.39109"
"271.00000","0.36134","43.35727"
"271.50000","0.36200","43.32948"
"272.00000","0.36267","43.29612"
"272.50000","0.36333","43.26330"
"273.00000","0.36401","43.24369"
"273.50000","0.36468","43.22342"
"274.00000","0.36535","43.19024"
"274.50000","0.36602","43.16425"
"275.00000","0.36668","43.13703"
"275.50000","0.36735","43.10559"
"276.00000","0.36801","43.07624"
"276.50000","0.36868","43.05201"
"277.00000","0.36933","43.01002"
"277.50000","0.37000","42.98355"
"278.00000","0.37066","42.94463"
"278.50000","0.37134","42.91569"
"279.00000","0.37200","42.87133"
"279.50000","0.37268","42.85303"
"280.00000","0.37335","42.81768"
"280.50000","0.37402","42.78617"
"281.00000","0.37469","42.76646"
"281.50000","0.37535","42.73361"
"282.00000","0.37602","42.71211"
"282.50000","0.37667","42.67065"
"283.00000","0.37734","42.63663"
"283.50000","0.37800","42.59103"
"284.00000","0.37867","42.56181"
"284.50000","0.37933","42.53212"
"285.00000","0.38000","42.49774"
"285.50000","0.38067","42.44860"
"286.00000","0.38135","42.42133"
"286.50000","0.38201","42.39608"
"287.00000","0.38269","42.37103"
"287.50000","0.38334","42.33256"
"288.00000","0.38402","42.30440"
"288.50000","0.38467","42.26263"
"289.00000","0.38534","42.22793"
"289.50000","0.38600","42.18646"
"290.00000","0.38667","42.15576"
"290.50000","0.38733","42.11614"
"291.00000","0.38801","42.07732"
"291.50000","0.38867","42.05172"
"292.00000","0.38935","42.02624"
"292.50000","0.39003","41.98900"
"293.00000","0.39068","41.95985"
"293.50000","0.39136","41.92974"
"294.00000","0.39201","41.88870"
"294.50000","0.39268","41.86612"
"295.00000","0.39334","41.81573"
"295.50000","0.39401","41.78609"
"296.00000","0.39467","41.74458"
"296.50000","0.39534","41.71647"
"297.00000","0.39600","41.68229"
"297.50000","0.39668","41.65528"
"298.00000","0.39734","41.61544"
"298.50000","0.39802","41.59307"
"299.00000","0.39868","41.56993"
"299.50000","0.39935","41.53457"
"300.00000","0.40001","41.50270"
"300.50000","0.40068","41.46965"
"301.00000","0.40133","41.42563"
"301.50000","0.40201","41.38953"
"302.00000","0.40266","41.37213"
"302.50000","0.40333","41.33563"
"303.00000","0.40400","41.30726"
"303.50000","0.40468","41.26855"
"304.00000","0.40535","41.24627"
"304.50000","0.40602","41.22116"
"305.00000","0.40670","41.19315"
"305.50000","0.40735","41.15412"
"306.00000","0.40802","41.13831"
"306.50000","0.40868","41.10263"
"307.00000","0.40934","41.08087"
"307.50000","0.41000","41.04019"
"308.00000","0.41067","41.02031"
"308.50000","0.41133","40.98455"
"309.00000","0.41200","40.95265"
"309.50000","0.41268","40.92694"
"310.00000","0.41335","40.91021"
"310.50000","0.41401","40.88363"
"311.00000","0.41469","40.86309"
"311.50000","0.41534","40.83619"
"312.00000","0.41602","40.82635"
"312.50000","0.41667","40.78777"
"313.00000","0.41734","40.74771"
"313.50000","0.41800","40.72947"
"314.00000","0.41867","40.71111"
"314.50000","0.41933","40.69416"
"315.00000","0.42000","40.66557"
"315.50000","0.42067","40.63789"
"316.00000","0.42134","40.63151"
"316.50000","0.42202","40.60789"
"317.00000","0.42269","40.59738"
"317.50000","0.42336","40.57830"
"318.00000","0.42402","40.55249"
"318.50000","0.42468","40.53859"
"319.00000","0.42534","40.51704"
"319.50000","0.42601","40.50866"
"320.00000","0.42667","40.48518"
"320.50000","0.42733","40.46180"
"321.00000","0.42800","40.44406"
"321.50000","0.42868","40.42953"
"322.00000","0.42934","40.41441"
"322.50000","0.43002","40.39991"
"323.00000","0.43068","40.38611"
"323.50000","0.43135","40.37148"
"324.00000","0.43201","40.35729"
"324.50000","0.43268","40.34627"
"325.00000","0.43333","40.32414"
"325.50000","0.43401","40.31567"
"326.00000","0.43466","40.29974"
"326.50000","0.43533","40.28753"
"327.00000","0.43600","40.27252"
"327.50000","0.43668","40.25330"
"328.00000","0.43734","40.24131"
"328.50000","0.43802","40.23430"
"329.00000","0.43869","40.23736"
"329.50000","0.43935","40.22302"
"330.00000","0.44002","40.21044"
"330.50000","0.44068","40.19448"
"331.00000","0.44134","40.18106"
"331.50000","0.44200","40.18200"
"332.00000","0.44267","40.16935"
"332.50000","0.44333","40.15687"
"333.00000","0.44400","40.14239"
"333.50000","0.44467","40.12983"
"334.00000","0.44534","40.11590"
"334.50000","0.44601","40.12566"
"335.00000","0.44669","40.12408"
"335.50000","0.44734","40.11512"
"336.00000","0.44802","40.09961"
"336.50000","0.44867","40.09039"
"337.00000","0.44934","40.09211"
"337.50000","0.45000","40.07414"
"338.00000","0.45067","40.07703"
"338.50000","0.45133","40.05441"
"339.00000","0.45200","40.04922"
"339.50000","0.45267","40.04343"
"340.00000","0.45334","40.03891"
"340.50000","0.45401","40.03786"
"341.00000","0.45469","40.03101"
"341.50000","0.45536","40.03153"
"342.00000","0.45602","40.01644"
"342.50000","0.45669","40.01436"
"343.00000","0.45734","39.99439"
"343.50000","0.45801","40.00145"
"344.00000","0.45867","39.99421"
"344.50000","0.45933","39.98359"
"345.00000","0.46000","39.97091"
"345.50000","0.46067","39.97156"
"346.00000","0.46134","39.96891"
"346.50000","0.46202","39.96120"
"347.00000","0.46268","39.95869"
"347.50000","0.46336","39.96740"
"348.00000","0.46401","39.95777"
"348.50000","0.46468","39.95647"
"349.00000","0.46533","39.93622"
"349.50000","0.46601","39.93509"
"350.00000","0.46666","39.92655"
"350.50000","0.46733","39.92944"
"351.00000","0.46800","39.91357"
"351.50000","0.46867","39.91602"
"352.00000","0.46934","39.91423"
"352.50000","0.47001","39.91217"
"353.00000","0.47069","39.91910"
"353.50000","0.47135","39.91480"
"354.00000","0.47203","39.90420"
"354.50000","0.47268","39.90943"
"355.00000","0.47335","39.90788"
"355.50000","0.47401","39.89371"
"356.00000","0.47467","39.89659"
"356.50000","0.47534","39.87901"
"357.00000","0.47600","39.88171"
"357.50000","0.47667","39.88572"
"358.00000","0.47734","39.87454"
"358.50000","0.47801","39.87200"
"359.00000","0.47869","39.87131"
"359.50000","0.47935","39.86022"
"360.00000","0.48002","39.87302"
"360.50000","0.48068","39.87019"
"361.00000","0.48135","39.86729"
"361.50000","0.48200","39.86113"
"362.00000","0.48267","39.86253"
"362.50000","0.48333","39.84531"
"363.00000","0.48400","39.85171"
"363.50000","0.48466","39.84380"
"364.00000","0.48534","39.85330"
"364.50000","0.48601","39.85040"
"365.00000","0.48668","39.84480"
"365.50000","0.48736","39.84909"
"366.00000","0.48802","39.84965"
"366.50000","0.48869","39.85136"
"367.00000","0.48935","39.83717"
"367.50000","0.49001","39.83747"
"368.00000","0.49067","39.83935"
"368.50000","0.49133","39.84087"
"369.00000","0.49200","39.83102"
"369.50000","0.49267","39.82857"
"370.00000","0.49334","39.82378"
"370.50000","0.49401","39.82195"
"371.00000","0.49468","39.82059"
"371.50000","0.49536","39.81583"
"372.00000","0.49601","39.81394"
"372.50000","0.49669","39.82071"
"373.00000","0.49734","39.81133"
"373.50000","0.49801","39.80894"
"374.00000","0.49866","39.80535"
"374.50000","0.49934","39.80661"
"375.00000","0.50000","39.80168"
"375.50000","0.50067","39.79714"
"376.00000","0.50134","39.78921"
"376.50000","0.50201","39.79405"
"377.00000","0.50268","39.79560"
"377.50000","0.50335","39.80605"
"378.00000","0.50402","39.81211"
"378.50000","0.50468","39.80124"
"379.00000","0.50535","39.79884"
"379.50000","0.50601","39.78853"
"380.00000","0.50668","39.79476"
"380.50000","0.50734","39.77971"
"381.00000","0.50800","39.77864"
"381.50000","0.50867","39.77941"
"382.00000","0.50934","39.78448"
"382.50000","0.51001","39.78329"
"383.00000","0.51068","39.78098"
"383.50000","0.51135","39.78308"
"384.00000","0.51202","39.78320"
"384.50000","0.51268","39.77010"
"385.00000","0.51335","39.78319"
"385.50000","0.51400","39.77753"
"386.00000","0.51467","39.77289"
"386.50000","0.51533","39.76488"
"387.00000","0.51600","39.76182"
"387.50000","0.51666","39.74672"
"388.00000","0.51734","39.75087"
"388.50000","0.51801","39.74878"
"389.00000","0.51868","39.76172"
"389.50000","0.51936","39.76184"
"390.00000","0.52002","39.75265"
"390.50000","0.52069","39.75921"
"391.00000","0.52135","39.74986"
"391.50000","0.52201","39.74764"
"392.00000","0.52267","39.74629"
"392.50000","0.52334","39.73726"
"393.00000","0.52400","39.73047"
"393.50000","0.52467","39.73566"
"394.00000","0.52534","39.72926"
"394.50000","0.52601","39.73071"
"395.00000","0.52668","39.73504"
"395.50000","0.52736","39.72756"
"396.00000","0.52801","39.73148"
"396.50000","0.52869","39.72971"
"397.00000","0.52934","39.71487"
"397.50000","0.53001","39.73111"
"398.00000","0.53067","39.71570"
"398.50000","0.53134","39.70979"
"399.00000","0.53199","39.70700"
"399.50000","0.53267","39.70415"
"400.00000","0.53333","39.69317"
"400.50000","0.53401","39.70102"
"401.00000","0.53468","39.70714"
"401.50000","0.53535","39.70831"
"402.00000","0.53603","39.70518"
"402.50000","0.53668","39.70679"
"403.00000","0.53735","39.70257"
"403.50000","0.53801","39.69828"
"404.00000","0.53868","39.70409"
"404.50000","0.53934","39.69728"
"405.00000","0.54000","39.69345"
"405.50000","0.54067","39.68689"
"406.00000","0.54134","39.68317"
"406.50000","0.54200","39.68880"
"407.00000","0.54268","39.68671"
"407.50000","0.54335","39.69368"
"408.00000","0.54402","39.69527"
"408.50000","0.54468","39.69934"
"409.00000","0.54535","39.69138"
"409.50000","0.54601","39.68039"
"410.00000","0.54667","39.68781"
"410.50000","0.54733","39.67513"
"411.00000","0.54800","39.68422"
"411.50000","0.54866","39.66980"
"412.00000","0.54934","39.67703"
"412.50000","0.55001","39.66473"
"413.00000","0.55068","39.66355"
"413.50000","0.55136","39.66891"
"414.00000","0.55202","39.66399"
"414.50000","0.55269","39.67528"
"415.00000","0.55335","39.66642"
"415.50000","0.55402","39.66928"
"416.00000","0.55468","39.65126"
"416.50000","0.55534","39.66093"
"417.00000","0.55600","39.66048"
"417.50000","0.55667","39.65321"
"418.00000","0.55734","39.64482"
"418.50000","0.55801","39.64517"
"419.00000","0.55867","39.63308"
"419.50000","0.55935","39.64583"
"420.00000","0.56001","39.64160"
"420.50000","0.56069","39.63887"
"421.00000","0.56134","39.63859"
"421.50000","0.56202","39.64437"
"422.00000","0.56267","39.63995"
"422.50000","0.56334","39.64488"
"423.00000","0.56400","39.64530"
"423.50000","0.56467","39.64381"
"424.00000","0.56533","39.63456"
"424.50000","0.56601","39.63142"
"425.00000","0.56668","39.64235"
"425.50000","0.56735","39.63877"
"426.00000","0.56803","39.63750"
"426.50000","0.56868","39.63471"
"427.00000","0.56936","39.65090"
"427.50000","0.57001","39.63874"
"428.00000","0.57068","39.64181"
"428.50000","0.57134","39.63114"
"429.00000","0.57200","39.62497"
"429.50000","0.57267","39.62980"
"430.00000","0.57333","39.62540"
"430.50000","0.57401","39.62828"
"431.00000","0.57468","39.62179"
"431.50000","0.57534","39.63363"
"432.00000","0.57602","39.63065"
"432.50000","0.57668","39.63379"
"433.00000","0.57736","39.62228"
"433.50000","0.57801","39.61887"
"434.00000","0.57868","39.62369"
"434.50000","0.57933","39.61027"
"435.00000","0.58000","39.61278"
"435.50000","0.58066","39.60554"
"436.00000","0.58133","39.60332"
"436.50000","0.58200","39.58619"
"437.00000","0.58267","39.59960"
"437.50000","0.58335","39.59574"
"438.00000","0.58402","39.59016"
"438.50000","0.58469","39.58758"
"439.00000","0.58535","39.57117"
"439.50000","0.58602","39.57401"
"440.00000","0.58667","39.56937"
"440.50000","0.58734","39.55895"
"441.00000","0.58800","39.54621"
"441.50000","0.58867","39.54546"
"442.00000","0.58933","39.54358"
"442.50000","0.59001","39.54884"
"443.00000","0.59067","39.54399"
"443.50000","0.59135","39.55009"
"444.00000","0.59201","39.53406"
"444.50000","0.59269","39.54538"
"445.00000","0.59335","39.54374"
"445.50000","0.59402","39.55134"
"446.00000","0.59467","39.53613"
"446.50000","0.59534","39.53104"
"447.00000","0.59600","39.51815"
"447.50000","0.59667","39.51846"
"448.00000","0.59733","39.51763"
"448.50000","0.59800","39.52416"
"449.00000","0.59867","39.51043"
"449.50000","0.59935","39.51183"
"450.00000","0.60002","39.51259"
"450.50000","0.60069","39.53074"
"451.00000","0.60136","39.52513"
"451.50000","0.60201","39.51389"
"452.00000","0.60268","39.51256"
"452.50000","0.60334","39.50506"
"453.00000","0.60401","39.50173"
"453.50000","0.60467","39.49028"
"454.00000","0.60533","39.48814"
"454.50000","0.60601","39.49145"
"455.00000","0.60667","39.49271"
"455.50000","0.60734","39.48468"
"456.00000","0.60802","39.49212"
"456.50000","0.60868","39.49192"
"457.00000","0.60935","39.49666"
"457.50000","0.61001","39.49317"
"458.00000","0.61068","39.48730"
"458.50000","0.61133","39.47602"
"459.00000","0.61201","39.48283"
"459.50000","0.61266","39.47275"
"460.00000","0.61333","39.47959"
"460.50000","0.61400","39.47452"
"461.00000","0.61467","39.47812"
"461.50000","0.61534","39.47960"
"462.00000","0.61602","39.47707"
"462.50000","0.61669","39.48282"
"463.00000","0.61735","39.47936"
"463.50000","0.61802","39.47826"
"464.00000","0.61868","39.47362"
"464.50000","0.61935","39.47779"
"465.00000","0.62000","39.46297"
"465.50000","0.62067","39.46043"
"466.00000","0.62133","39.45685"
"466.50000","0.62200","39.45986"
"467.00000","0.62267","39.45509"
"467.50000","0.62335","39.45460"
"468.00000","0.62401","39.45432"
"468.50000","0.62469","39.45343"
"469.00000","0.62534","39.46011"
"469.50000","0.62602","39.45802"
"470.00000","0.62667","39.44644"
"470.50000","0.62734","39.44450"
"471.00000","0.62800","39.44069"
"471.50000","0.62867","39.44604"
"472.00000","0.62933","39.42979"
"472.50000","0.63000","39.42443"
"473.00000","0.63067","39.41871"
"473.50000","0.63134","39.43056"
"474.00000","0.63202","39.43698"
"474.50000","0.63268","39.42000"
"475.00000","0.63336","39.42912"
"475.50000","0.63401","39.43392"
"476.00000","0.63469","39.43193"
"476.50000","0.63534","39.41964"
"477.00000","0.63601","39.42746"
"477.50000","0.63667","39.41250"
"478.00000","0.63733","39.41440"
"478.50000","0.63800","39.40922"
"479.00000","0.63868","39.41324"
"479.50000","0.63934","39.40988"
"480.00000","0.64002","39.41552"
"480.50000","0.64068","39.40071"
"481.00000","0.64135","39.40250"
"481.50000","0.64201","39.40131"
"482.00000","0.64268","39.40254"
"482.50000","0.64333","39.39309"
"483.00000","0.64401","39.39219"
"483.50000","0.64466","39.37762"
"484.00000","0.64533","39.37574"
"484.50000","0.64600","39.38230"
"485.00000","0.64667","39.38752"
"485.50000","0.64734","39.38368"
"486.00000","0.64802","39.37908"
"486.50000","0.64869","39.38161"
"487.00000","0.64935","39.38296"
"487.50000","0.65002","39.38688"
"488.00000","0.65068","39.37622"
"488.50000","0.65135","39.37792"
"489.00000","0.65200","39.36558"
"489.50000","0.65267","39.36332"
"490.00000","0.65333","39.35810"
"490.50000","0.65400","39.35823"
"491.00000","0.65467","39.35133"
"491.50000","0.65534","39.35608"
"492.00000","0.65601","39.35182"
"492.50000","0.65669","39.35143"
"493.00000","0.65735","39.34532"
"493.50000","0.65802","39.35128"
"494.00000","0.65868","39.34536"
"494.50000","0.65934","39.34418"
"495.00000","0.66000","39.33789"
"495.50000","0.66067","39.34346"
"496.00000","0.66133","39.33896"
"496.50000","0.66200","39.33566"
"497.00000","0.66267","39.33488"
"497.50000","0.66334","39.33831"
"498.00000","0.66401","39.34255"
"498.50000","0.66468","39.35251"
"499.00000","0.66536","39.35459"
"499.50000","0.66602","39.34679"
"500.00000","0.66669","39.35279"
"500.50000","0.66734","39.34997"
"501.00000","0.66801","39.35858"
"501.50000","0.66867","39.35166"
"502.00000","0.66934","39.34635"
"502.50000","0.67000","39.33778"
"503.00000","0.67067","39.34153"
"503.50000","0.67134","39.34873"
"504.00000","0.67201","39.34508"
"504.50000","0.67268","39.35275"
"505.00000","0.67335","39.35918"
"505.50000","0.67401","39.35848"
"506.00000","0.67469","39.36401"
"506.50000","0.67534","39.36054"
"507.00000","0.67601","39.36250"
"507.50000","0.67666","39.34476"
"508.00000","0.67734","39.35968"
"508.50000","0.67800","39.35521"
"509.00000","0.67867","39.34995"
"509.50000","0.67934","39.35597"
"510.00000","0.68001","39.35061"
"510.50000","0.68069","39.36629"
"511.00000","0.68136","39.35162"
"511.50000","0.68202","39.36495"
"512.00000","0.68268","39.35274"
"512.50000","0.68335","39.35513"
"513.00000","0.68401","39.35369"
"513.50000","0.68467","39.35479"
"514.00000","0.68533","39.34474"
"514.50000","0.68600","39.34663"
"515.00000","0.68667","39.33674"
"515.50000","0.68734","39.33672"
"516.00000","0.68801","39.34779"
"516.50000","0.68869","39.34727"
"517.00000","0.68935","39.34067"
"517.50000","0.69002","39.34911"
"518.00000","0.69068","39.34940"
"518.50000","0.69135","39.35019"
"519.00000","0.69200","39.34355"
"519.50000","0.69267","39.35051"
"520.00000","0.69333","39.33890"
"520.50000","0.69400","39.34722"
"521.00000","0.69466","39.34113"
"521.50000","0.69534","39.34768"
"522.00000","0.69601","39.34431"
"522.50000","0.69668","39.34704"
"523.00000","0.69736","39.35306"
"523.50000","0.69802","39.34416"
"524.00000","0.69869","39.36027"
"524.50000","0.69935","39.34517"
"525.00000","0.70001","39.33657"
"525.50000","0.70067","39.33434"
"526.00000","0.70134","39.32600"
"526.50000","0.70200","39.32578"
"527.00000","0.70267","39.32762"
"527.50000","0.70334","39.32582"
"528.00000","0.70401","39.32195"
"528.50000","0.70468","39.31884"
"529.00000","0.70536","39.32099"
"529.50000","0.70601","39.32473"
"530.00000","0.70669","39.31941"
"530.50000","0.70734","39.31221"
"531.00000","0.70801","39.30810"
"531.50000","0.70866","39.31361"
"532.00000","0.70934","39.30811"
"532.50000","0.70999","39.30426"
"533.00000","0.71067","39.29646"
"533.50000","0.71134","39.29487"
"534.00000","0.71201","39.30510"
"534.50000","0.71268","39.29436"
"535.00000","0.71335","39.29643"
"535.50000","0.71403","39.29375"
"536.00000","0.71468","39.28743"
"536.50000","0.71535","39.29904"
"537.00000","0.71601","39.28533"
"537.50000","0.71668","39.28117"
"538.00000","0.71734","39.27959"
"538.50000","0.71800","39.28023"
"539.00000","0.71867","39.27955"
"539.50000","0.71934","39.26574"
"540.00000","0.72001","39.26795"
"540.50000","0.72068","39.26675"
"541.00000","0.72135","39.27229"
"541.50000","0.72202","39.28233"
"542.00000","0.72268","39.26042"
"542.50000","0.72335","39.26915"
"543.00000","0.72400","39.25267"
"543.50000","0.72467","39.25817"
"544.00000","0.72533","39.23895"
"544.50000","0.72600","39.24686"
"545.00000","0.72666","39.24787"
"545.50000","0.72734","39.24969"
"546.00000","0.72801","39.24170"
"546.50000","0.72868","39.24514"
"547.00000","0.72936","39.26024"
"547.50000","0.73002","39.25597"
"548.00000","0.73069","39.25612"
"548.50000","0.73135","39.24872"
"549.00000","0.73201","39.25013"
"549.50000","0.73267","39.24314"
"550.00000","0.73334","39.24457"
"550.50000","0.73400","39.23187"
"551.00000","0.73467","39.24303"
"551.50000","0.73534","39.24379"
"552.00000","0.73601","39.24154"
"552.50000","0.73668","39.23672"
"553.00000","0.73735","39.23758"
"553.50000","0.73801","39.24376"
"554.00000","0.73869","39.25495"
"554.50000","0.73934","39.24562"
"555.00000","0.74001","39.24852"
"555.50000","0.74067","39.23861"
"556.00000","0.74134","39.25415"
"556.50000","0.74200","39.24576"
"557.00000","0.74267","39.24895"
"557.50000","0.74333","39.23935"
"558.00000","0.74401","39.25301"
"558.50000","0.74468","39.25939"
"559.00000","0.74535","39.25152"
"559.50000","0.74603","39.26529"
"560.00000","0.74668","39.27028"
"560.50000","0.74736","39.26744"
"561.00000","0.74801","39.26959"
"561.50000","0.74868","39.27816"
"562.00000","0.74934","39.26565"
"562.50000","0.75000","39.26996"
"563.00000","0.75067","39.26487"
"563.50000","0.75134","39.26237"
"564.00000","0.75200","39.26182"
"564.50000","0.75268","39.26516"
"565.00000","0.75335","39.26230"
"565.50000","0.75402","39.26415"
"566.00000","0.75468","39.25253"
"566.50000","0.75535","39.26242"
"567.00000","0.75600","39.25694"
"567.50000","0.75668","39.26235"
"568.00000","0.75733","39.25449"
"568.50000","0.75800","39.25127"
"569.00000","0.75866","39.23998"
"569.50000","0.75934","39.25228"
"570.00000","0.76000","39.24975"
"570.50000","0.76068","39.24672"
"571.00000","0.76135","39.24586"
"571.50000","0.76202","39.25639"
"572.00000","0.76269","39.25278"
"572.50000","0.76335","39.25180"
"573.00000","0.76402","39.24885"
"573.50000","0.76467","39.24828"
"574.00000","0.76534","39.24668"
"574.50000","0.76600","39.24177"
"575.00000","0.76667","39.23574"
"575.50000","0.76734","39.23116"
"576.00000","0.76801","39.22299"
"576.50000","0.76867","39.22697"
"577.00000","0.76935","39.22672"
"577.50000","0.77001","39.22649"
"578.00000","0.77069","39.23730"
"578.50000","0.77134","39.23160"
"579.00000","0.77202","39.23194"
"579.50000","0.77267","39.22251"
"580.00000","0.77334","39.22487"
"580.50000","0.77400","39.23016"
"581.00000","0.77467","39.23031"
"581.50000","0.77533","39.21938"
"582.00000","0.77601","39.21670"
"582.50000","0.77667","39.21888"
"583.00000","0.77735","39.22563"
"583.50000","0.77803","39.23024"
"584.00000","0.77868","39.23315"
"584.50000","0.77936","39.23258"
"585.00000","0.78001","39.23057"
"585.50000","0.78068","39.22842"
"586.00000","0.78134","39.22658"
"586.50000","0.78200","39.22177"
"587.00000","0.78267","39.21430"
"587.50000","0.78333","39.21942"
"588.00000","0.78401","39.21806"
"588.50000","0.78467","39.21314"
"589.00000","0.78534","39.22363"
"589.50000","0.78602","39.21597"
"590.00000","0.78668","39.22356"
"590.50000","0.78735","39.22467"
"591.00000","0.78801","39.21808"
"591.50000","0.78868","39.22311"
"592.00000","0.78933","39.20331"
"592.50000","0.79001","39.20799"
"593.00000","0.79066","39.19629"
"593.50000","0.79133","39.20048"
"594.00000","0.79200","39.19099"
"594.50000","0.79267","39.19829"
"595.00000","0.79335","39.19671"
"595.50000","0.79402","39.19716"
"596.00000","0.79469","39.19555"
"596.50000","0.79535","39.19879"
"597.00000","0.79602","39.20040"
"597.50000","0.79668","39.19678"
"598.00000","0.79734","39.19494"
"598.50000","0.79800","39.18586"
"599.00000","0.79867","39.18075"
"599.50000","0.79934","39.18042"
"600.00000","0.80001","39.17895"
"600.50000","0.80067","39.18445"
"601.00000","0.80135","39.17701"
"601.50000","0.80201","39.18306"
"602.00000","0.80269","39.18088"
"602.50000","0.80335","39.18418"
"603.00000","0.80402","39.17870"
"603.50000","0.80467","39.18013"
"604.00000","0.80534","39.18436"
"604.50000","0.80600","39.17845"
"605.00000","0.80667","39.16549"
"605.50000","0.80733","39.17158"
"606.00000","0.80800","39.17898"
"606.50000","0.80867","39.17261"
"607.00000","0.80935","39.17204"
"607.50000","0.81002","39.17967"
"608.00000","0.81068","39.17311"
"608.50000","0.81136","39.18936"
"609.00000","0.81202","39.18742"
"609.50000","0.81268","39.18423"
"610.00000","0.81334","39.17577"
"610.50000","0.81401","39.17840"
"611.00000","0.81467","39.18141"
"611.49200","0.81532","39.18975"