File: materials_lab1/ENGR314_FA19_0001_HDPE_A_20190903_JJR.is_tens_RawData/Specimen_RawData_2.csv
Material,Nylon
Geometry,Circular
Length,"2.00000",in
Diameter,"0.26400",in

Time,Extension,Load
(s),(in),(lbf)
"0.00000","0.00000","-2.19902"
"0.27400","0.00459","12.50889"
"0.57400","0.00960","25.97143"
"0.87400","0.01460","36.39485"
"1.17400","0.01960","44.88876"
"1.47400","0.02460","51.77191"
"1.77400","0.02960","57.22297"
"2.07400","0.03460","61.24497"
"2.37400","0.03959","65.05530"
"2.67400","0.04460","68.79457"
"2.97400","0.04960","72.65879"
"3.27400","0.05460","76.39201"
"3.57400","0.05959","79.90646"
"3.87400","0.06460","83.55582"
"4.17400","0.06961","87.13908"
"4.47400","0.07460","90.66776"
"4.77400","0.07959","94.21998"
"5.07400","0.08460","97.69942"
"5.37400","0.08960","101.07173"
"5.67400","0.09460","104.33185"
"5.97400","0.09960","107.53691"
"6.27400","0.10460","110.63592"
"6.57400","0.10960","113.64055"
"6.87400","0.11459","116.55408"
"7.17400","0.11960","119.42587"
"7.47400","0.12461","122.20827"
"7.77400","0.12960","124.86492"
"8.07400","0.13460","127.43448"
"8.37400","0.13960","129.93864"
"8.67400","0.14460","132.41652"
"8.97400","0.14960","134.74077"
"9.27400","0.15459","137.00272"
"9.57400","0.15960","139.21061"
"9.87400","0.16460","141.30841"
"10.17400","0.16960","143.37158"
"10.47400","0.17460","145.33686"
"10.77400","0.17960","147.24440"
"11.07400","0.18460","149.10389"
"11.37400","0.18960","150.76476"
"11.67400","0.19459","152.52123"
"11.97400","0.19960","154.21781"
"12.27400","0.20461","155.81120"
"12.57400","0.20960","157.26039"
"12.87400","0.21460","158.66606"
"13.17400","0.21960","160.09942"
"13.47400","0.22460","161.43587"
"13.77400","0.22960","162.73036"
"14.07400","0.23459","163.97481"
"14.37400","0.23960","165.16426"
"14.67400","0.24461","166.33747"
"14.97400","0.24960","167.40564"
"15.27400","0.25460","168.45054"
"15.57400","0.25960","169.44833"
"15.87400","0.26461","170.39994"
"16.17400","0.26959","171.26742"
"16.47400","0.27460","172.14542"
"16.77400","0.27961","172.99991"
"17.07400","0.28461","173.78972"
"17.37400","0.28959","174.52408"
"17.67400","0.29460","175.23644"
"17.97400","0.29960","175.92352"
"18.27400","0.30461","176.57233"
"18.57400","0.30959","177.15647"
"18.87400","0.31460","177.73847"
"19.17400","0.31960","178.28093"
"19.47400","0.32459","178.77470"
"19.77400","0.32959","179.24423"
"20.07400","0.33460","179.72325"
"20.37400","0.33960","180.17000"
"20.67400","0.34460","180.56818"
"20.97400","0.34959","180.91172"
"21.27400","0.35460","181.26176"
"21.57400","0.35960","181.58179"
"21.87400","0.36460","181.89044"
"22.17400","0.36960","182.16331"
"22.47400","0.37460","182.41104"
"22.77400","0.37960","182.67287"
"23.07400","0.38460","182.86680"
"23.37400","0.38960","183.05587"
"23.67400","0.39460","183.25222"
"23.97400","0.39960","183.43312"
"24.27400","0.40460","183.55332"
"24.57400","0.40960","183.67026"
"24.87400","0.41460","183.79849"
"25.17400","0.41961","183.91884"
"25.47400","0.42460","183.97020"
"25.77400","0.42959","184.03646"
"26.07400","0.43460","184.09451"
"26.37400","0.43961","184.15819"
"26.67400","0.44460","184.17397"
"26.97400","0.44960","184.20082"
"27.27400","0.45460","184.20232"
"27.57400","0.45961","184.18751"
"27.87400","0.46460","184.18388"
"28.17400","0.46959","184.15954"
"28.47400","0.47460","184.14072"
"28.77400","0.47960","184.10030"
"29.07400","0.48460","184.03607"
"29.37400","0.48960","183.99035"
"29.67400","0.49461","183.94002"
"29.97400","0.49960","183.87170"
"30.27400","0.50459","183.76751"
"30.57400","0.50960","183.69735"
"30.87400","0.51460","183.59286"
"31.17400","0.51960","183.52129"
"31.47400","0.52460","183.40411"
"31.77400","0.52960","183.30043"
"32.07400","0.53460","183.17659"
"32.37400","0.53960","183.05061"
"32.67400","0.54460","182.91966"
"32.97400","0.54960","182.80368"
"33.27400","0.55460","182.68316"
"33.57400","0.55961","182.54998"
"33.87400","0.56460","182.39092"
"34.17400","0.56961","182.25291"
"34.47400","0.57461","182.10948"
"34.77400","0.57960","181.93267"
"35.07400","0.58460","181.78459"
"35.37400","0.58960","181.64129"
"35.67400","0.59460","181.48922"
"35.97400","0.59960","181.32232"
"36.27400","0.60459","181.13506"
"36.57400","0.60960","180.97371"
"36.87400","0.61460","180.83213"
"37.17400","0.61960","180.62656"
"37.47400","0.62460","180.46015"
"37.77400","0.62960","180.29440"
"38.07400","0.63460","180.11381"
"38.37400","0.63960","179.91642"
"38.67400","0.64460","179.72649"
"38.97400","0.64960","179.54295"
"39.27400","0.65460","179.34620"
"39.57400","0.65960","179.16176"
"39.87400","0.66459","178.95221"
"40.17400","0.66960","178.77255"
"40.47400","0.67461","178.57215"
"40.77400","0.67960","178.37283"
"41.07400","0.68460","178.18611"
"41.37400","0.68960","178.00189"
"41.67400","0.69460","177.80406"
"41.97400","0.69960","177.60524"
"42.27400","0.70460","177.41571"
"42.57400","0.70960","177.21695"
"42.87400","0.71460","177.02033"
"43.17400","0.71959","176.81588"
"43.47400","0.72460","176.63048"
"43.77400","0.72961","176.44074"
"44.07400","0.73460","176.22081"
"44.37400","0.73960","176.02176"
"44.67400","0.74460","175.81312"
"44.97400","0.74960","175.62724"
"45.27400","0.75460","175.40147"
"45.57400","0.75959","175.20818"
"45.87400","0.76460","175.01287"
"46.17400","0.76960","174.81790"
"46.47400","0.77460","174.62656"
"46.77400","0.77960","174.41191"
"47.07400","0.78460","174.21726"
"47.37400","0.78960","174.04463"
"47.67400","0.79460","173.82384"
"47.97400","0.79960","173.61053"
"48.27400","0.80460","173.41429"
"48.57400","0.80960","173.20902"
"48.87400","0.81460","173.01220"
"49.17400","0.81959","172.78510"
"49.47400","0.82459","172.58686"
"49.77400","0.82960","172.38978"
"50.07400","0.83460","172.15572"
"50.37400","0.83960","171.95787"
"50.67400","0.84460","171.77089"
"50.97400","0.84960","171.55842"
"51.27400","0.85461","171.34866"
"51.57400","0.85960","171.14383"
"51.87400","0.86460","170.94658"
"52.17400","0.86961","170.73522"
"52.47400","0.87459","170.52089"
"52.77400","0.87960","170.34021"
"53.07400","0.88461","170.12698"
"53.37400","0.88960","169.93111"
"53.67400","0.89460","169.72359"
"53.97400","0.89960","169.51014"
"54.27400","0.90461","169.30675"
"54.57400","0.90960","169.09297"
"54.87400","0.91460","168.88753"
"55.17400","0.91960","168.69816"
"55.47400","0.92460","168.49397"
"55.77400","0.92960","168.30734"
"56.07400","0.93459","168.07563"
"56.37400","0.93960","167.87643"
"56.67400","0.94460","167.66824"
"56.97400","0.94960","167.45316"
"57.27400","0.95459","167.26357"
"57.57400","0.95960","167.05151"
"57.87400","0.96460","166.83547"
"58.17400","0.96960","166.62894"
"58.47400","0.97460","166.41345"
"58.77400","0.97959","166.21818"
"59.07400","0.98460","166.01807"
"59.37400","0.98960","165.80033"
"59.67400","0.99460","165.57242"
"59.97400","0.99960","165.37860"
"60.27400","1.00460","165.16871"
"60.57400","1.00960","164.95928"
"60.87400","1.01460","164.73548"
"61.17400","1.01960","164.54188"
"61.47400","1.02460","164.32683"
"61.77400","1.02960","164.11821"
"62.07400","1.03459","163.92223"
"62.37400","1.03961","163.71574"
"62.67400","1.04461","163.49866"
"62.97400","1.04960","163.26876"
"63.27400","1.05459","163.06896"
"63.57400","1.05960","162.85813"
"63.87400","1.06461","162.65864"
"64.17400","1.06960","162.43187"
"64.47400","1.07459","162.22482"
"64.77400","1.07960","162.00504"
"65.07400","1.08460","161.80143"
"65.37400","1.08960","161.56495"
"65.67400","1.09460","161.35776"
"65.97400","1.09960","161.11957"
"66.27400","1.10460","160.90367"
"66.57400","1.10959","160.66601"
"66.87400","1.11460","160.45741"
"67.17400","1.11960","160.23828"
"67.47400","1.12460","160.00612"
"67.77400","1.12959","159.77254"
"68.07400","1.13460","159.54290"
"68.37400","1.13960","159.32290"
"68.67400","1.14460","159.08103"
"68.97400","1.14960","158.83848"
"69.27400","1.15460","158.59260"
"69.57400","1.15960","158.35765"
"69.87400","1.16460","158.12321"
"70.17400","1.16960","157.89602"
"70.47400","1.17460","157.66703"
"70.77400","1.17960","157.42665"
"71.07400","1.18460","157.18004"
"71.37400","1.18960","156.94403"
"71.67400","1.19460","156.71424"
"71.97400","1.19961","156.48331"
"72.27400","1.20460","156.22456"
"72.57400","1.20960","155.96039"
"72.87400","1.21460","155.71661"
"73.17400","1.21961","155.46510"
"73.47400","1.22461","155.18218"
"73.77400","1.22960","154.93587"
"74.07400","1.23460","154.66162"
"74.37400","1.23960","154.41789"
"74.67400","1.24460","154.12724"
"74.97400","1.24960","153.88587"
"75.27400","1.25460","153.61372"
"75.57400","1.25960","153.33177"
"75.87400","1.26459","153.03899"
"76.17400","1.26959","152.77015"
"76.47400","1.27460","152.48633"
"76.77400","1.27961","152.20699"
"77.07400","1.28459","151.88990"
"77.37400","1.28960","151.59134"
"77.67400","1.29460","151.29299"
"77.97400","1.29960","150.98161"
"78.27400","1.30459","150.68168"
"78.57400","1.30960","150.38916"
"78.87400","1.31460","150.08678"
"79.17400","1.31960","149.76581"
"79.47400","1.32460","149.41642"
"79.77400","1.32960","149.08786"
"80.07400","1.33461","148.77970"
"80.37400","1.33960","148.42348"
"80.67400","1.34460","148.06560"
"80.97400","1.34960","147.71301"
"81.27400","1.35461","147.36530"
"81.57400","1.35961","147.00042"
"81.87400","1.36460","146.62450"
"82.17400","1.36960","146.26403"
"82.47400","1.37460","145.87893"
"82.77400","1.37960","145.49084"
"83.07400","1.38460","145.07446"
"83.37400","1.38960","144.68268"
"83.67400","1.39460","144.27384"
"83.97400","1.39960","143.84438"
"84.27400","1.40460","143.41665"
"84.57400","1.40960","142.97579"
"84.87400","1.41460","142.55330"
"85.17400","1.41960","142.08248"
"85.47400","1.42460","141.63562"
"85.77400","1.42960","141.17084"
"86.07400","1.43460","140.70384"
"86.37400","1.43960","140.21690"
"86.67400","1.44459","139.73158"
"86.97400","1.44960","139.23455"
"87.27400","1.45460","138.72855"
"87.57400","1.45960","138.21816"
"87.87400","1.46460","137.68014"
"88.17400","1.46961","137.17949"
"88.47400","1.47460","136.62264"
"88.77400","1.47959","136.08568"
"89.07400","1.48460","135.53131"
"89.37400","1.48960","134.96322"
"89.67400","1.49460","134.38939"
"89.97400","1.49959","133.79929"
"90.27400","1.50460","133.20906"
"90.57400","1.50961","132.63651"
"90.87400","1.51460","132.05418"
"91.17400","1.51960","131.44124"
"91.47400","1.52460","130.81253"
"91.77400","1.52960","130.19663"
"92.07400","1.53460","129.58711"
"92.37400","1.53960","128.96549"
"92.67400","1.54460","128.34909"
"92.97400","1.54960","127.72037"
"93.27400","1.55460","127.09405"
"93.57400","1.55960","126.45967"
"93.87400","1.56460","125.85813"
"94.17400","1.56960","125.24243"
"94.47400","1.57460","124.63539"
"94.77400","1.57959","123.99936"
"95.07400","1.58460","123.39742"
"95.37400","1.58960","122.80879"
"95.67400","1.59460","122.23312"
"95.97400","1.59959","121.67543"
"96.27400","1.60460","121.12434"
"96.57400","1.60960","120.59732"
"96.87400","1.61460","120.07335"
"97.17400","1.61960","119.57106"
"97.47400","1.62460","119.11644"
"97.77400","1.62960","118.68606"
"98.07400","1.63460","118.23702"
"98.37400","1.63960","117.79104"
"98.67400","1.64460","117.40480"
"98.97400","1.64961","116.99677"
"99.27400","1.65460","116.62320"
"99.57400","1.65959","116.28468"
"99.87400","1.66460","115.96021"
"100.17400","1.66961","115.66585"
"100.47400","1.67460","115.37447"
"100.77400","1.67960","115.10581"
"101.07400","1.68460","114.86001"
"101.37400","1.68960","114.62608"
"101.67400","1.69460","114.40374"
"101.97400","1.69960","114.19598"
"102.27400","1.70460","114.01203"
"102.57400","1.70960","113.83152"
"102.87400","1.71459","113.65144"
"103.17400","1.71960","113.49617"
"103.47400","1.72460","113.36736"
"103.77400","1.72960","113.23482"
"104.07400","1.73459","113.11772"
"104.37400","1.73960","113.00862"
"104.67400","1.74460","112.90402"
"104.97400","1.74960","112.79637"
"105.27400","1.75459","112.71685"
"105.57400","1.75960","112.65296"
"105.87400","1.76460","112.59328"
"106.17400","1.76960","112.53898"
"106.47400","1.77460","112.48076"
"106.77400","1.77960","112.44220"
"107.07400","1.78461","112.41482"
"107.37400","1.78960","112.37288"
"107.67400","1.79460","112.34397"
"107.97400","1.79960","112.30447"
"108.27400","1.80460","112.27985"
"108.57400","1.80960","112.25482"
"108.87400","1.81460","112.23409"
"109.17400","1.81960","112.21057"
"109.47400","1.82461","112.18858"
"109.77400","1.82961","112.17756"
"110.07400","1.83460","112.17542"
"110.37400","1.83960","112.18956"
"110.67400","1.84460","112.18266"
"110.97400","1.84959","112.16445"
"111.27400","1.85460","112.17446"
"111.57400","1.85960","112.17958"
"111.87400","1.86460","112.19313"
"112.17400","1.86959","112.21568"
"112.47400","1.87459","112.22932"
"112.77400","1.87960","112.25760"
"113.07400","1.88460","112.26872"
"113.37400","1.88960","112.28944"
"113.67400","1.89459","112.31438"
"113.97400","1.89961","112.35512"
"114.27400","1.90461","112.37688"
"114.57400","1.90959","112.41000"
"114.87400","1.91460","112.44209"
"115.17400","1.91960","112.46552"
"115.47400","1.92460","112.50220"
"115.77400","1.92960","112.52629"
"116.07400","1.93461","112.55798"
"116.37400","1.93960","112.57593"
"116.67400","1.94460","112.59552"
"116.97400","1.94959","112.61636"
"117.27400","1.95460","112.64789"
"117.57400","1.95961","112.69062"
"117.87400","1.96460","112.70554"
"118.17400","1.96960","112.72282"
"118.47400","1.97460","112.75621"
"118.77400","1.97961","112.78665"
"119.07400","1.98460","112.81472"
"119.37400","1.98960","112.84116"
"119.67400","1.99460","112.86705"
"119.97400","1.99960","112.90698"
"120.27400","2.00460","112.96281"
"120.57400","2.00960","112.98911"
"120.87400","2.01460","113.04501"
"121.17400","2.01960","113.07140"
"121.47400","2.02460","113.11251"
"121.77400","2.02959","113.15235"
"122.07400","2.03460","113.20547"
"122.37400","2.03960","113.23802"
"122.67400","2.04460","113.27101"
"122.97400","2.04959","113.31124"
"123.27400","2.05460","113.36041"
"123.57400","2.05960","113.38988"
"123.87400","2.06460","113.42702"
"124.17400","2.06959","113.46883"
"124.47400","2.07460","113.50246"
"124.77400","2.07960","113.55210"
"125.07400","2.08459","113.56594"
"125.37400","2.08960","113.61077"
"125.67400","2.09460","113.63212"
"125.97400","2.09960","113.66511"
"126.27400","2.10459","113.69909"
"126.57400","2.10960","113.73652"
"126.87400","2.11461","113.77518"
"127.17400","2.11960","113.80006"
"127.47400","2.12460","113.81797"
"127.77400","2.12960","113.84993"
"128.07400","2.13460","113.88682"
"128.37400","2.13960","113.91383"
"128.67400","2.14460","113.93863"
"128.97400","2.14960","113.96168"
"129.27400","2.15460","113.99829"
"129.57400","2.15960","114.01912"
"129.87400","2.16459","114.04333"
"130.17400","2.16960","114.08196"
"130.47400","2.17460","114.11463"
"130.77400","2.17960","114.14868"
"131.07400","2.18460","114.17060"
"131.37400","2.18960","114.20909"
"131.67400","2.19460","114.22957"
"131.97400","2.19960","114.25118"
"132.27400","2.20460","114.26330"
"132.57400","2.20959","114.29542"
"132.87400","2.21460","114.33388"
"133.17400","2.21960","114.33954"
"133.47400","2.22460","114.36270"
"133.77400","2.22960","114.38535"
"134.07400","2.23460","114.39228"
"134.37400","2.23960","114.40337"
"134.67400","2.24460","114.41663"
"134.97400","2.24961","114.45804"
"135.27400","2.25461","114.47221"
"135.57400","2.25960","114.48872"
"135.87400","2.26460","114.54228"
"136.17400","2.26960","114.57182"
"136.47400","2.27461","114.59498"
"136.77400","2.27959","114.60387"
"137.07400","2.28460","114.64882"
"137.37400","2.28960","114.68185"
"137.67400","2.29461","114.71292"
"137.97400","2.29960","114.74654"
"138.27400","2.30460","114.75966"
"138.57400","2.30960","114.79426"
"138.87400","2.31460","114.80803"
"139.17400","2.31960","114.83331"
"139.47400","2.32460","114.85698"
"139.77400","2.32961","114.88699"
"140.07400","2.33460","114.91005"
"140.37400","2.33960","114.91697"
"140.67400","2.34460","114.94289"
"140.97400","2.34960","114.95775"
"141.27400","2.35460","114.98549"
"141.57400","2.35960","114.98473"
"141.87400","2.36460","115.00750"
"142.17400","2.36960","115.02060"
"142.47400","2.37460","115.03986"
"142.77400","2.37960","115.05972"
"143.07400","2.38460","115.09626"
"143.37400","2.38960","115.11343"
"143.67400","2.39460","115.13521"
"143.97400","2.39959","115.16113"
"144.27400","2.40460","115.18366"
"144.57400","2.40960","115.22102"
"144.87400","2.41460","115.24336"
"145.17400","2.41959","115.24649"
"145.47400","2.42460","115.28185"
"145.77400","2.42960","115.30906"
"146.07400","2.43460","115.31835"
"146.37400","2.43959","115.34151"
"146.67400","2.44460","115.35660"
"146.97400","2.44960","115.38407"
"147.27400","2.45461","115.39096"
"147.57400","2.45960","115.40279"
"147.87400","2.46460","115.42540"
"148.17400","2.46961","115.43758"
"148.47400","2.47460","115.44075"
"148.77400","2.47960","115.45806"
"149.07400","2.48461","115.47139"
"149.37400","2.48960","115.50083"
"149.67400","2.49460","115.51479"
"149.97400","2.49960","115.53262"
"150.27400","2.50461","115.56271"
"150.57400","2.50960","115.56901"
"150.87400","2.51460","115.56725"
"151.17400","2.51960","115.59194"
"151.47400","2.52459","115.60228"
"151.77400","2.52960","115.62551"
"152.07400","2.53459","115.63259"
"152.37400","2.53960","115.65636"
"152.67400","2.54460","115.69176"
"152.97400","2.54960","115.69428"
"153.27400","2.55460","115.70972"
"153.57400","2.55960","115.72533"
"153.87400","2.56460","115.74694"
"154.17400","2.56960","115.77130"
"154.47400","2.57460","115.77738"
"154.77400","2.57960","115.79978"
"155.07400","2.58460","115.82322"
"155.37400","2.58960","115.83129"
"155.67400","2.59459","115.84143"
"155.97400","2.59960","115.85622"
"156.27400","2.60460","115.87270"
"156.57400","2.60961","115.89317"
"156.87400","2.61460","115.88097"
"157.17400","2.61960","115.91374"
"157.47400","2.62461","115.93128"
"157.77400","2.62960","115.93104"
"158.07400","2.63460","115.93246"
"158.37400","2.63960","115.94645"
"158.67400","2.64460","115.96008"
"158.97400","2.64959","115.94640"
"159.27400","2.65460","115.96971"
"159.57400","2.65960","115.96233"
"159.87400","2.66461","115.95471"
"160.17400","2.66960","115.95630"
"160.47400","2.67460","115.95814"
"160.77400","2.67960","115.98177"
"161.07400","2.68460","115.98532"
"161.37400","2.68960","115.98058"
"161.67400","2.69460","116.00250"
"161.97400","2.69960","116.02111"
"162.27400","2.70460","116.04194"
"162.57400","2.70959","116.04246"
"162.87400","2.71460","116.06828"
"163.17400","2.71960","116.09887"
"163.47400","2.72461","116.11355"
"163.77400","2.72959","116.13517"
"164.07400","2.73460","116.16119"
"164.37400","2.73960","116.18561"
"164.67400","2.74460","116.21296"
"164.97400","2.74960","116.23601"
"165.27400","2.75460","116.26336"
"165.57400","2.75960","116.28812"
"165.87400","2.76460","116.30211"
"166.17400","2.76960","116.31845"
"166.47400","2.77460","116.34289"
"166.77400","2.77960","116.34680"
"167.07400","2.78460","116.34652"
"167.37400","2.78960","116.35329"
"167.67400","2.79460","116.36181"
"167.97400","2.79961","116.37897"
"168.27400","2.80460","116.36200"
"168.57400","2.80959","116.37355"
"168.87400","2.81460","116.37339"
"169.17400","2.81960","116.37468"
"169.47400","2.82460","116.37394"
"169.77400","2.82960","116.36938"
"170.07400","2.83460","116.38062"
"170.37400","2.83960","116.39135"
"170.67400","2.84460","116.38099"
"170.97400","2.84960","116.39398"
"171.27400","2.85460","116.40152"
"171.57400","2.85960","116.40013"
"171.87400","2.86460","116.40544"
"172.17400","2.86960","116.41889"
"172.47400","2.87461","116.41472"
"172.77400","2.87961","116.41380"
"173.07400","2.88460","116.41971"
"173.37400","2.88959","116.44872"
"173.67400","2.89460","116.43991"
"173.97400","2.89960","116.45076"
"174.27400","2.90460","116.46485"
"174.57400","2.90960","116.47314"
"174.87400","2.91460","116.46983"
"175.17400","2.91960","116.48919"
"175.47400","2.92460","116.49531"
"175.77400","2.92961","116.50062"
"176.07400","2.93460","116.51087"
"176.37400","2.93959","116.50937"
"176.67400","2.94459","116.52789"
"176.97400","2.94960","116.53153"
"177.27400","2.95460","116.54527"
"177.57400","2.95960","116.54567"
"177.87400","2.96459","116.54611"
"178.17400","2.96960","116.56831"
"178.47400","2.97460","116.58537"
"178.77400","2.97960","116.59618"
"179.07400","2.98460","116.59440"
"179.37400","2.98960","116.61621"
"179.67400","2.99460","116.62413"
"179.97400","2.99960","116.62704"
"180.27400","3.00460","116.63356"
"180.57400","3.00960","116.65065"
"180.87400","3.01460","116.65669"
"181.17400","3.01960","116.66828"
"181.47400","3.02459","116.67376"
"181.77400","3.02960","116.70263"
"182.07400","3.03461","116.71421"
"182.37400","3.03960","116.71867"
"182.67400","3.04459","116.72340"
"182.97400","3.04960","116.76048"
"183.27400","3.05461","116.77939"
"183.57400","3.05960","116.78013"
"183.87400","3.06460","116.80677"
"184.17400","3.06960","116.82483"
"184.47400","3.07461","116.84732"
"184.77400","3.07959","116.86389"
"185.07400","3.08461","116.89743"
"185.37400","3.08960","116.90853"
"185.67400","3.09461","116.92991"
"185.97400","3.09960","116.94087"
"186.27400","3.10459","116.97373"
"186.57400","3.10960","116.98750"
"186.87400","3.11460","117.00455"
"187.17400","3.11959","117.02063"
"187.47400","3.12460","117.04297"
"187.77400","3.12960","117.06571"
"188.07400","3.13460","117.07786"
"188.37400","3.13959","117.09023"
"188.67400","3.14460","117.11364"
"188.97400","3.14960","117.12482"
"189.27400","3.15460","117.13095"
"189.57400","3.15960","117.15333"
"189.87400","3.16461","117.16727"
"190.17400","3.16960","117.18194"
"190.47400","3.17460","117.16984"
"190.77400","3.17960","117.17727"
"191.07400","3.18460","117.18179"
"191.37400","3.18961","117.17637"
"191.67400","3.19460","117.16858"
"191.97400","3.19960","117.16230"
"192.27400","3.20460","117.16380"
"192.57400","3.20960","117.16715"
"192.87400","3.21461","117.18081"
"193.17400","3.21960","117.18264"
"193.47400","3.22460","117.20229"
"193.77400","3.22961","117.19825"
"194.07400","3.23460","117.20855"
"194.37400","3.23960","117.23038"
"194.67400","3.24460","117.27124"
"194.97400","3.24961","117.29728"
"195.27400","3.25460","117.31901"
"195.57400","3.25960","117.36184"
"195.87400","3.26460","117.40944"
"196.17400","3.26961","117.45510"
"196.47400","3.27460","117.48448"
"196.77400","3.27960","117.52603"
"197.07400","3.28460","117.57695"
"197.37400","3.28960","117.60825"
"197.67400","3.29460","117.61881"
"197.97400","3.29960","117.65107"
"198.27400","3.30460","117.65808"
"198.57400","3.30960","117.66673"
"198.87400","3.31459","117.66911"
"199.17400","3.31960","117.68971"
"199.47400","3.32460","117.69749"
"199.77400","3.32960","117.72099"
"200.07400","3.33459","117.72054"
"200.37400","3.33960","117.72648"
"200.67400","3.34460","117.73341"
"200.97400","3.34960","117.73668"
"201.27400","3.35460","117.73190"
"201.57400","3.35959","117.71936"
"201.87400","3.36460","117.74745"
"202.17400","3.36960","117.74691"
"202.47400","3.37460","117.75877"
"202.77400","3.37961","117.78884"
"203.07400","3.38460","117.79458"
"203.37400","3.38960","117.79684"
"203.67400","3.39460","117.80069"
"203.97400","3.39961","117.81872"
"204.27400","3.40461","117.82958"
"204.57400","3.40961","117.83080"
"204.87400","3.41459","117.83550"
"205.17400","3.41960","117.84797"
"205.47400","3.42460","117.89975"
"205.77400","3.42960","117.87508"
"206.07400","3.43460","117.92189"
"206.37400","3.43960","117.90571"
"206.67400","3.44461","117.93411"
"206.97400","3.44960","117.91271"
"207.27400","3.45460","117.91475"
"207.57400","3.45960","117.92796"
"207.87400","3.46460","117.92558"
"208.17400","3.46959","117.91317"
"208.47400","3.47460","117.92440"
"208.77400","3.47960","117.93609"
"209.07400","3.48460","117.95199"
"209.37400","3.48959","117.93917"
"209.67400","3.49460","117.95760"
"209.97400","3.49960","117.96593"
"210.27400","3.50461","117.98071"
"210.57400","3.50960","117.98244"
"210.87400","3.51460","118.00445"
"211.17400","3.51960","118.00886"
"211.47400","3.52460","118.01268"
"211.77400","3.52960","118.01739"
"212.07400","3.53460","118.02340"
"212.37400","3.53960","118.04536"
"212.67400","3.54460","118.04518"
"212.97400","3.54960","118.04558"
"213.27400","3.55460","118.05917"
"213.57400","3.55960","118.07651"
"213.87400","3.56460","118.07821"
"214.17400","3.56960","118.08214"
"214.47400","3.57460","118.09823"
"214.77400","3.57960","118.11382"
"215.07400","3.58460","118.12893"
"215.37400","3.58959","118.13404"
"215.67400","3.59460","118.14233"
"215.97400","3.59960","118.15424"
"216.27400","3.60460","118.15287"
"216.57400","3.60960","118.16284"
"216.87400","3.61460","118.16386"
"217.17400","3.61960","118.18100"
"217.47400","3.62460","118.17545"
"217.77400","3.62959","118.15870"
"218.07400","3.63460","118.17459"
"218.37400","3.63960","118.17932"
"218.67400","3.64459","118.18481"
"218.97400","3.64959","118.18415"
"219.27400","3.65460","118.19180"
"219.57400","3.65961","118.19936"
"219.87400","3.66460","118.18148"
"220.17400","3.66960","118.17873"
"220.47400","3.67460","118.18255"
"220.77400","3.67960","118.17279"
"221.07400","3.68460","118.14494"
"221.37400","3.68961","118.14490"
"221.67400","3.69460","118.11494"
"221.97400","3.69961","118.12322"
"222.27400","3.70459","118.09443"
"222.57400","3.70960","118.08974"
"222.87400","3.71461","118.08504"
"223.17400","3.71960","118.08083"
"223.47400","3.72460","118.08035"
"223.77400","3.72960","118.08198"
"224.07400","3.73460","118.07770"
"224.37400","3.73960","118.06656"
"224.67400","3.74460","118.04472"
"224.97400","3.74960","118.04871"
"225.27400","3.75460","118.04512"
"225.57400","3.75960","118.04014"
"225.87400","3.76460","118.02799"
"226.17400","3.76960","118.04201"
"226.47400","3.77460","118.04089"
"226.77400","3.77960","118.04874"
"227.07400","3.78460","118.04012"
"227.37400","3.78960","118.02871"
"227.67400","3.79460","118.03631"
"227.97400","3.79959","118.02805"
"228.27400","3.80460","118.02563"
"228.57400","3.80960","118.03975"
"228.87400","3.81460","118.04262"
"229.17400","3.81961","118.05929"
"229.47400","3.82460","118.03743"
"229.77400","3.82960","118.04846"
"230.07400","3.83460","118.06658"
"230.37400","3.83961","118.06460"
"230.67400","3.84460","118.08089"
"230.97400","3.84960","118.08270"
"231.27400","3.85460","118.09363"
"231.57400","3.85960","118.08880"
"231.87400","3.86460","118.10830"
"232.17400","3.86960","118.12216"
"232.47400","3.87461","118.14403"
"232.77400","3.87960","118.17305"
"233.07400","3.88460","118.21511"
"233.37400","3.88960","118.25974"
"233.67400","3.89460","118.28924"
"233.97400","3.89960","118.31912"
"234.27400","3.90460","118.35395"
"234.57400","3.90960","118.39237"
"234.87400","3.91459","118.42802"
"235.17400","3.91959","118.45324"
"235.47400","3.92460","118.46997"
"235.77400","3.92960","118.50443"
"236.07400","3.93460","118.53977"
"236.37400","3.93959","118.56868"
"236.67400","3.94460","118.57684"
"236.97400","3.94960","118.57266"
"237.27400","3.95460","118.58953"
"237.57400","3.95959","118.58280"
"237.87400","3.96460","118.59178"
"238.17400","3.96960","118.61576"
"238.47400","3.97460","118.61232"
"238.77400","3.97960","118.61353"
"239.07400","3.98460","118.62185"
"239.37400","3.98960","118.62828"
"239.67400","3.99460","118.62681"
"239.97400","3.99960","118.62321"
"240.27400","4.00460","118.63808"
"240.57400","4.00960","118.63989"
"240.87400","4.01460","118.65986"
"241.17400","4.01959","118.68023"
"241.47400","4.02460","118.70497"
"241.77400","4.02960","118.73344"
"242.07400","4.03460","118.74202"
"242.37400","4.03959","118.76591"
"242.67400","4.04460","118.78425"
"242.97400","4.04961","118.81430"
"243.27400","4.05460","118.82092"
"243.57400","4.05960","118.83332"
"243.87400","4.06460","118.84867"
"244.17400","4.06960","118.85905"
"244.47400","4.07459","118.85391"
"244.77400","4.07960","118.86473"
"245.07400","4.08460","118.86593"
"245.37400","4.08960","118.85748"
"245.67400","4.09459","118.85828"
"245.97400","4.09960","118.86241"
"246.27400","4.10460","118.85394"
"246.57400","4.10960","118.84576"
"246.87400","4.11459","118.84456"
"247.17400","4.11960","118.85385"
"247.47400","4.12460","118.85938"
"247.77400","4.12960","118.86622"
"248.07400","4.13460","118.87812"
"248.37400","4.13960","118.88613"
"248.67400","4.14460","118.89147"
"248.97400","4.14960","118.90529"
"249.27400","4.15460","118.89310"
"249.57400","4.15960","118.90688"
"249.87400","4.16461","118.92569"
"250.17400","4.16960","118.91743"
"250.47400","4.17460","118.92893"
"250.77400","4.17960","118.94243"
"251.07400","4.18461","118.94222"
"251.37400","4.18960","118.93372"
"251.67400","4.19459","118.93041"
"251.97400","4.19960","118.93250"
"252.27400","4.20460","118.93211"
"252.57400","4.20960","118.92162"
"252.87400","4.21460","118.92205"
"253.17400","4.21959","118.91635"
"253.47400","4.22460","118.91618"
"253.77400","4.22959","118.90822"
"254.07400","4.23460","118.89111"
"254.37400","4.23960","118.87872"
"254.67400","4.24461","118.85902"
"254.97400","4.24959","118.82891"
"255.27400","4.25459","118.81558"
"255.57400","4.25960","118.80386"
"255.87400","4.26461","118.79406"
"256.17400","4.26960","118.76725"
"256.47400","4.27460","118.76554"
"256.77400","4.27960","118.76393"
"257.07400","4.28460","118.76152"
"257.37400","4.28960","118.77533"
"257.67400","4.29460","118.77404"
"257.97400","4.29960","118.78676"
"258.27400","4.30460","118.78252"
"258.57400","4.30960","118.79118"
"258.87400","4.31460","118.79924"
"259.17400","4.31961","118.81171"
"259.47400","4.32460","118.80947"
"259.77400","4.32960","118.80957"
"260.07400","4.33460","118.81740"
"260.37400","4.33961","118.82579"
"260.67400","4.34460","118.82340"
"260.97400","4.34960","118.80958"
"261.27400","4.35460","118.82562"
"261.57400","4.35960","118.81801"
"261.87400","4.36460","118.80022"
"262.17400","4.36959","118.78905"
"262.47400","4.37460","118.79286"
"262.77400","4.37960","118.78653"
"263.07400","4.38460","118.75276"
"263.37400","4.38960","118.74181"
"263.67400","4.39460","118.73621"
"263.97400","4.39960","118.71287"
"264.27400","4.40460","118.69221"
"264.57400","4.40959","118.67102"
"264.87400","4.41460","118.65710"
"265.17400","4.41961","118.64085"
"265.47400","4.42461","118.60911"
"265.77400","4.42960","118.57669"
"266.07400","4.43460","118.53901"
"266.37400","4.43960","118.49506"
"266.67400","4.44460","118.45380"
"266.97400","4.44959","118.41171"
"267.27400","4.45461","118.38506"
"267.57400","4.45960","118.33937"
"267.87400","4.46459","118.29062"
"268.17400","4.46960","118.27467"
"268.47400","4.47461","118.25006"
"268.77400","4.47961","118.22662"
"269.07400","4.48460","118.20764"
"269.37400","4.48960","118.18635"
"269.67400","4.49461","118.17560"
"269.97400","4.49961","118.16375"
"270.27400","4.50460","118.13386"
"270.57400","4.50960","118.13419"
"270.87400","4.51460","118.11622"
"271.17400","4.51960","118.10026"
"271.47400","4.52460","118.08514"
"271.77400","4.52960","118.05865"
"272.07400","4.53460","118.05339"
"272.37400","4.53960","118.02393"
"272.67400","4.54459","117.98522"
"272.97400","4.54960","117.97179"
"273.27400","4.55460","117.95360"
"273.57400","4.55960","117.93841"
"273.87400","4.56459","117.91205"
"274.17400","4.56960","117.90379"
"274.47400","4.57460","117.89126"
"274.77400","4.57960","117.87884"
"275.07400","4.58459","117.86275"
"275.37400","4.58960","117.85764"
"275.67400","4.59460","117.86260"
"275.97400","4.59960","117.84267"
"276.27400","4.60461","117.83581"
"276.57400","4.60960","117.83207"
"276.87400","4.61461","117.82784"
"277.17400","4.61960","117.81740"
"277.47400","4.62460","117.82168"
"277.77400","4.62960","117.82553"
"278.07400","4.63461","117.82946"
"278.37400","4.63960","117.81343"
"278.67400","4.64460","117.83462"
"278.97400","4.64960","117.84119"
"279.27400","4.65461","117.85959"
"279.57400","4.65960","117.85821"
"279.87400","4.66460","117.87759"
"280.17400","4.66960","117.88167"
"280.47400","4.67460","117.88978"
"280.77400","4.67959","117.89046"
"281.07400","4.68460","117.90450"
"281.37400","4.68960","117.91776"
"281.67400","4.69460","117.93190"
"281.97400","4.69959","117.92883"
"282.27400","4.70460","117.94694"
"282.57400","4.70960","117.95923"
"282.87400","4.71460","117.96826"
"283.17400","4.71959","117.97427"
"283.47400","4.72460","117.99984"
"283.77400","4.72960","118.02877"
"284.07400","4.73460","118.03054"
"284.37400","4.73960","118.05344"
"284.67400","4.74460","118.08257"
"284.97400","4.74960","118.10789"
"285.27400","4.75460","118.12914"
"285.57400","4.75960","118.14709"
"285.87400","4.76460","118.18197"
"286.17400","4.76961","118.22669"
"286.47400","4.77460","118.25679"
"286.77400","4.77960","118.29095"
"287.07400","4.78460","118.31641"
"287.37400","4.78961","118.33042"
"287.67400","4.79460","118.36521"
"287.97400","4.79959","118.39036"
"288.27400","4.80460","118.43195"
"288.57400","4.80960","118.45939"
"288.87400","4.81460","118.48579"
"289.17400","4.81960","118.50701"
"289.47400","4.82460","118.54553"
"289.77400","4.82960","118.57908"
"290.07400","4.83460","118.57927"
"290.37400","4.83960","118.59638"
"290.67400","4.84461","118.60913"
"290.97400","4.84960","118.65072"
"291.27400","4.85460","118.67753"
"291.57400","4.85959","118.70476"
"291.87400","4.86461","118.73004"
"292.17400","4.86960","118.75568"
"292.47400","4.87460","118.79203"
"292.77400","4.87959","118.82732"
"293.07400","4.88460","118.85718"
"293.37400","4.88960","118.89512"
"293.67400","4.89460","118.92688"
"293.97400","4.89960","118.95263"
"294.27400","4.90460","118.96588"
"294.57400","4.90960","118.96131"
"294.87400","4.91459","118.94191"
"295.17400","4.91960","118.92521"
"295.47400","4.92460","118.89730"
"295.77400","4.92961","118.88344"
"296.07400","4.93460","118.86618"
"296.37400","4.93960","118.84102"
"296.67400","4.94460","118.83280"
"296.97400","4.94960","118.79900"
"297.27400","4.95460","118.79276"
"297.57400","4.95960","118.76437"
"297.87400","4.96460","118.76971"
"298.17400","4.96960","118.76971"
"298.47400","4.97460","118.75707"
"298.77400","4.97960","118.75221"
"299.07400","4.98460","118.74602"
"299.37400","4.98960","118.76813"
"299.67400","4.99460","118.77695"
"299.97400","4.99960","118.79356"
"300.27400","5.00460","118.81980"
"300.57400","5.00960","118.84719"
"300.87400","5.01459","118.88600"
"301.17400","5.01960","118.92975"
"301.47400","5.02460","118.96463"
"301.77400","5.02960","118.97742"
"302.07400","5.03459","118.99351"
"302.37400","5.03960","119.01480"
"302.67400","5.04460","119.02369"
"302.97400","5.04960","119.03160"
"303.27400","5.05460","119.05298"
"303.57400","5.05960","119.03686"
"303.87400","5.06460","119.03458"
"304.17400","5.06960","119.00486"
"304.47400","5.07460","119.00043"
"304.77400","5.07960","118.94906"
"305.07400","5.08461","118.91212"
"305.37400","5.08960","118.85804"
"305.67400","5.09461","118.82671"
"305.97400","5.09961","118.78586"
"306.27400","5.10461","118.73770"
"306.57400","5.10959","118.67987"
"306.87400","5.11460","118.63395"
"307.17400","5.11960","118.60367"
"307.47400","5.12460","118.56298"
"307.77400","5.12959","118.52452"
"308.07400","5.13460","118.45891"
"308.37400","5.13960","118.42233"
"308.67400","5.14460","118.37337"
"308.97400","5.14960","118.31762"
"309.27400","5.15460","118.26859"
"309.57400","5.15960","118.21627"
"309.87400","5.16460","118.16960"
"310.17400","5.16959","118.11728"
"310.47400","5.17460","118.10162"
"310.77400","5.17960","118.06043"
"311.07400","5.18460","118.03485"
"311.37400","5.18960","117.98826"
"311.67400","5.19459","117.97028"
"311.97400","5.19960","117.95914"
"312.27400","5.20460","117.94796"
"312.57400","5.20960","117.92751"
"312.87400","5.21460","117.90926"
"313.17400","5.21960","117.90856"
"313.47400","5.22460","117.90257"
"313.77400","5.22960","117.88160"
"314.07400","5.23461","117.87879"
"314.37400","5.23960","117.87038"
"314.67400","5.24460","117.85770"
"314.97400","5.24959","117.85270"
"315.27400","5.25460","117.83683"
"315.57400","5.25961","117.84078"
"315.87400","5.26460","117.81066"
"316.17400","5.26960","117.81004"
"316.47400","5.27460","117.79911"
"316.77400","5.27961","117.78688"
"317.07400","5.28459","117.75406"
"317.37400","5.28960","117.75232"
"317.67400","5.29460","117.72947"
"317.97400","5.29960","117.70621"
"318.27400","5.30459","117.68073"
"318.57400","5.30960","117.65307"
"318.87400","5.31460","117.62798"
"319.17400","5.31959","117.59399"
"319.47400","5.32460","117.56291"
"319.77400","5.32960","117.51685"
"320.07400","5.33460","117.48383"
"320.37400","5.33960","117.43994"
"320.67400","5.34460","117.39395"
"320.97400","5.34960","117.35846"
"321.27400","5.35460","117.30345"
"321.57400","5.35959","117.24957"
"321.87400","5.36460","117.19093"
"322.17400","5.36960","117.13901"
"322.47400","5.37460","117.07188"
"322.77400","5.37960","117.01284"
"323.07400","5.38460","116.94548"
"323.37400","5.38960","116.88401"
"323.67400","5.39461","116.81667"
"323.97400","5.39960","116.72029"
"324.27400","5.40460","116.63172"
"324.57400","5.40960","116.54527"
"324.87400","5.41460","116.46817"
"325.17400","5.41961","116.36743"
"325.47400","5.42459","116.25603"
"325.77400","5.42960","116.16373"
"326.07400","5.43460","116.04294"
"326.37400","5.43961","115.92587"
"326.67400","5.44460","115.81124"
"326.97400","5.44959","115.69310"
"327.27400","5.45460","115.56215"
"327.57400","5.45959","115.38930"
"327.87400","5.46460","115.24465"
"328.17400","5.46960","115.05753"
"328.47400","5.47460","114.86034"
"328.77400","5.47959","114.64148"
"329.07400","5.48459","114.35454"
"329.37400","5.48960","113.99369"
"329.67400","5.49460","113.57523"
"329.97400","5.49960","113.13539"
"330.27400","5.50460","112.63673"
"330.57400","5.50960","112.10379"
"330.87400","5.51460","111.50431"
"331.17400","5.51959","110.81163"
"331.47400","5.52460","110.02020"
"331.77400","5.52960","108.97950"
"332.07400","5.53460","107.58150"
"332.37400","5.53960","105.84877"
"332.67400","5.54461","103.72113"
"332.97400","5.54961","101.02409"
"333.27400","5.55460","97.54326"
"333.57400","5.55960","92.58393"
"333.87400","5.56461","83.92555"
"334.01500","5.56696","66.29607"
"334.02500","5.56713","46.26889"
"334.03400","5.56729","28.11018"
"334.04700","5.56751","9.18810"