File: materials_lab1/ENGR314_FA19_0001_OakWood_A_20190903_JCM.is_tens_RawData/Specimen_RawData_1.csv
Material,Acrylic
Geometry,Circular
Length,"2.00000",in
Diameter,"0.25100",in

Time,Extension,Load
(s),(in),(lbf)
"0.00000","0.00001","-2.91801"
"0.20000","0.00025","2.35758"
"0.40000","0.00054","10.25700"
"0.60000","0.00080","16.89535"
"0.80000","0.00108","24.01818"
"1.00000","0.00135","30.77601"
"1.20000","0.00161","36.68873"
"1.40000","0.00187","43.15114"
"1.60000","0.00213","49.19381"
"1.80000","0.00240","55.35733"
"2.00000","0.00268","60.46579"
"2.20000","0.00296","66.27720"
"2.40000","0.00321","71.61706"
"2.60000","0.00347","76.93225"
"2.80000","0.00374","82.20617"
"3.00000","0.00400","87.63700"
"3.20000","0.00429","93.50820"
"3.40000","0.00454","98.30974"
"3.60000","0.00481","103.46213"
"3.80000","0.00508","108.44537"
"4.00000","0.00532","113.28192"
"4.20000","0.00561","118.69207"
"4.40000","0.00587","123.22360"
"4.60000","0.00615","128.10779"
"4.80000","0.00642","132.55498"
"5.00000","0.00666","136.48702"
"5.20000","0.00694","141.29585"
"5.40000","0.00720","145.31054"
"5.60000","0.00748","149.63095"
"5.80000","0.00775","153.64142"
"6.00000","0.00801","156.82435"
"6.20000","0.00827","160.45943"
"6.40000","0.00853","163.66263"
"6.60000","0.00881","167.16106"
"6.80000","0.00908","170.40774"
"7.00000","0.00936","173.36153"
"7.20000","0.00961","175.77009"
"7.40000","0.00987","178.22453"
"7.60000","0.01014","180.73678"
"7.80000","0.01040","182.88036"
"8.00000","0.01069","185.21802"
"8.20000","0.01094","186.54823"
"8.40000","0.01121","188.81909"
"8.60000","0.01148","190.79471"
"8.80000","0.01172","191.52347"
"9.00000","0.01201","192.51318"
"9.20000","0.01228","193.24190"
"9.40000","0.01255","194.48627"
"9.60000","0.01282","195.46310"
"9.80000","0.01306","196.22084"
"10.00000","0.01334","197.66079"
"10.20000","0.01360","199.03567"
"10.40000","0.01388","200.50249"
"10.60000","0.01415","201.78516"
"10.80000","0.01441","202.86245"
"11.00000","0.01467","203.97055"
"11.20000","0.01493","205.19526"
"11.40000","0.01521","206.66900"
"11.60000","0.01548","208.03227"
"11.80000","0.01576","209.48359"
"12.00000","0.01601","210.39042"
"12.20000","0.01628","211.59988"
"12.40000","0.01654","212.83340"
"12.60000","0.01680","213.94433"
"12.80000","0.01709","215.69231"
"13.00000","0.01734","216.53098"
"13.20000","0.01761","217.74203"
"13.40000","0.01788","218.74758"
"13.60000","0.01813","219.68393"
"13.80000","0.01841","221.28986"
"14.00000","0.01868","222.29855"
"14.20000","0.01895","223.70324"
"14.40000","0.01922","224.63914"
"14.60000","0.01946","225.39988"
"14.80000","0.01974","226.75672"
"15.00000","0.02000","227.80869"
"15.20000","0.02028","229.18291"
"15.40000","0.02055","230.26068"
"15.60000","0.02081","231.04921"
"15.80000","0.02107","232.00500"
"16.00000","0.02133","233.07680"
"16.20000","0.02161","234.29552"
"16.40000","0.02188","235.48523"
"16.60000","0.02215","236.55936"
"16.80000","0.02241","237.33036"
"17.00000","0.02267","238.27216"
"17.20000","0.02294","239.26083"
"17.40000","0.02320","240.30282"
"17.60000","0.02349","241.72892"
"17.80000","0.02374","242.39416"
"18.00000","0.02401","243.38596"
"18.20000","0.02428","244.16615"
"18.40000","0.02453","244.90045"
"18.60000","0.02482","246.33825"
"18.80000","0.02507","247.01707"
"19.00000","0.02535","248.19086"
"19.20000","0.02562","248.89989"
"19.40000","0.02586","249.36548"
"19.60000","0.02614","250.55125"
"19.80000","0.02640","251.32595"
"20.00000","0.02668","252.42505"
"20.20000","0.02696","253.27357"
"20.40000","0.02721","253.65713"
"20.60000","0.02747","254.43252"
"20.80000","0.02773","255.12067"
"21.00000","0.02801","256.10270"
"21.20000","0.02828","257.00616"
"21.40000","0.02856","257.90463"
"21.60000","0.02881","258.26116"
"21.80000","0.02907","259.05104"
"22.00000","0.02933","259.69934"
"22.20000","0.02960","260.55426"
"22.40000","0.02989","261.85168"
"22.60000","0.03014","262.03428"
"22.80000","0.03041","262.84362"
"23.00000","0.03067","263.34412"
"23.20000","0.03093","263.89749"
"23.40000","0.03122","265.13059"
"23.60000","0.03148","265.63383"
"23.80000","0.03175","266.39707"
"24.00000","0.03202","267.00623"
"24.20000","0.03226","267.19965"
"24.40000","0.03254","268.15284"
"24.60000","0.03280","268.80256"
"24.80000","0.03308","269.68791"
"25.00000","0.03336","270.35551"
"25.20000","0.03361","270.57985"
"25.40000","0.03387","271.17250"
"25.60000","0.03413","271.72900"
"25.80000","0.03440","272.48562"
"26.00000","0.03468","273.18820"
"26.20000","0.03496","273.74993"
"26.40000","0.03521","273.91993"
"26.60000","0.03547","274.35402"
"26.80000","0.03574","274.94924"
"27.00000","0.03600","275.46920"
"27.20000","0.03629","276.45702"
"27.40000","0.03654","276.47148"
"27.60000","0.03681","276.93232"
"27.80000","0.03707","277.23669"
"28.00000","0.03733","277.52431"
"28.20000","0.03762","278.50190"
"28.40000","0.03788","278.74490"
"28.60000","0.03816","279.35083"
"28.80000","0.03842","279.62627"
"29.00000","0.03866","279.66650"
"29.20000","0.03894","280.41280"
"29.40000","0.03920","280.89060"
"29.60000","0.03948","281.57672"
"29.80000","0.03976","282.04574"
"30.00000","0.04000","282.06357"
"30.20000","0.04027","282.43454"
"30.40000","0.04053","282.91300"
"30.60000","0.04081","283.49382"
"30.80000","0.04108","284.01482"
"31.00000","0.04136","284.46323"
"31.20000","0.04161","284.50099"
"31.40000","0.04187","284.74992"
"31.60000","0.04214","284.93233"
"31.80000","0.04240","282.60142"
"32.00000","0.04269","282.52702"
"32.20000","0.04295","281.85084"
"32.40000","0.04321","281.79387"
"32.60000","0.04348","281.72546"
"32.80000","0.04373","279.21773"
"33.00000","0.04402","278.91038"
"33.20000","0.04428","278.46304"
"33.40000","0.04455","278.52108"
"33.60000","0.04481","278.37212"
"33.80000","0.04506","278.09616"
"34.00000","0.04534","278.48680"
"34.20000","0.04560","278.70058"
"34.40000","0.04588","279.17945"
"34.60000","0.04615","279.37204"
"34.80000","0.04640","279.34633"
"35.00000","0.04667","279.65067"
"35.20000","0.04693","279.75410"
"35.40000","0.04721","280.23069"
"35.60000","0.04748","280.60377"
"35.80000","0.04775","281.02304"
"36.00000","0.04801","281.10858"
"36.20000","0.04827","281.34115"
"36.40000","0.04854","281.65841"
"36.60000","0.04880","281.97030"
"36.80000","0.04909","282.54884"
"37.00000","0.04934","282.36396"
"37.20000","0.04961","282.64719"
"37.40000","0.04987","282.62735"
"37.60000","0.05013","282.77494"
"37.80000","0.05042","283.56937"
"38.00000","0.05067","283.74706"
"38.20000","0.05096","284.38027"
"38.40000","0.05122","284.67465"
"38.60000","0.05146","284.72615"
"38.80000","0.05175","285.57616"
"39.00000","0.05200","285.91425"
"39.20000","0.05228","286.66615"
"39.40000","0.05256","287.06941"
"39.60000","0.05280","287.07767"
"39.80000","0.05307","287.54996"
"40.00000","0.05334","287.94373"
"40.20000","0.05361","288.59577"
"40.40000","0.05388","289.09637"
"40.60000","0.05415","289.48095"
"40.80000","0.05441","289.61863"
"41.00000","0.05467","289.99119"
"41.20000","0.05494","290.47080"
"41.40000","0.05520","290.96570"
"41.60000","0.05550","291.82836"
"41.80000","0.05574","291.69125"
"42.00000","0.05601","292.15168"
"42.20000","0.05627","292.33887"
"42.40000","0.05653","292.55207"
"42.60000","0.05682","293.44003"
"42.80000","0.05707","293.47762"
"43.00000","0.05735","294.03619"
"43.20000","0.05761","294.22151"
"43.40000","0.05786","294.14343"
"43.60000","0.05814","294.84475"
"43.80000","0.05841","295.21443"
"44.00000","0.05868","295.74550"
"44.20000","0.05896","296.15628"
"44.40000","0.05920","296.02116"
"44.60000","0.05947","296.44237"
"44.80000","0.05973","296.72621"
"45.00000","0.06001","297.26795"
"45.20000","0.06028","297.72803"
"45.40000","0.06055","297.95920"
"45.60000","0.06081","298.05297"
"45.80000","0.06107","298.26733"
"46.00000","0.06134","298.33975"
"46.20000","0.06160","298.33530"
"46.40000","0.06189","298.92644"
"46.60000","0.06214","298.65783"
"46.80000","0.06241","298.82238"
"47.00000","0.06267","299.01091"
"47.20000","0.06293","298.93223"
"47.40000","0.06322","299.59329"
"47.60000","0.06348","299.45183"
"47.80000","0.06375","299.62222"
"48.00000","0.06401","299.50237"
"48.20000","0.06426","299.34856"
"48.40000","0.06454","299.86500"
"48.60000","0.06480","300.03385"
"48.80000","0.06509","300.54365"
"49.00000","0.06535","300.67601"
"49.20000","0.06560","300.57293"
"49.40000","0.06587","300.82491"
"49.60000","0.06613","301.10277"
"49.80000","0.06641","301.57785"
"50.00000","0.06668","301.94923"
"50.20000","0.06695","302.11383"
"50.40000","0.06720","302.13233"
"50.60000","0.06747","302.38954"
"50.80000","0.06774","302.71927"
"51.00000","0.06800","302.99956"
"51.20000","0.06829","303.64186"
"51.40000","0.06855","303.49334"
"51.60000","0.06881","303.76601"
"51.80000","0.06907","303.89951"
"52.00000","0.06933","304.03574"
"52.20000","0.06962","304.80020"
"52.40000","0.06988","304.85945"
"52.60000","0.07015","305.33695"
"52.80000","0.07041","305.46225"
"53.00000","0.07066","305.41154"
"53.20000","0.07094","306.12944"
"53.40000","0.07120","306.38698"
"53.60000","0.07148","306.93476"
"53.80000","0.07175","307.12779"
"54.00000","0.07200","307.11942"
"54.20000","0.07227","307.44681"
"54.40000","0.07253","307.67634"
"54.60000","0.07281","308.29311"
"54.80000","0.07308","308.65019"
"55.00000","0.07335","308.91765"
"55.20000","0.07360","308.97440"
"55.40000","0.07387","309.22072"
"55.60000","0.07414","309.61373"
"55.80000","0.07440","309.91321"
"56.00000","0.07469","310.57732"
"56.20000","0.07494","310.46247"
"56.40000","0.07521","310.77841"
"56.60000","0.07547","310.93593"
"56.80000","0.07573","311.09655"
"57.00000","0.07602","311.86692"
"57.20000","0.07628","311.85227"
"57.40000","0.07655","312.32274"
"57.60000","0.07681","312.39308"
"57.80000","0.07706","312.42065"
"58.00000","0.07734","313.05757"
"58.20000","0.07760","313.31775"
"58.40000","0.07788","313.89893"
"58.60000","0.07816","314.20584"
"58.80000","0.07840","314.03304"
"59.00000","0.07867","314.42676"
"59.20000","0.07893","314.60911"
"59.40000","0.07921","315.19484"
"59.60000","0.07948","315.60873"
"59.80000","0.07975","315.69364"
"60.00000","0.08001","315.83782"
"60.20000","0.08027","315.98382"
"60.40000","0.08054","316.35824"
"60.60000","0.08081","316.70564"
"60.80000","0.08109","317.27090"
"61.00000","0.08134","317.12070"
"61.20000","0.08161","317.37350"
"61.40000","0.08187","317.54702"
"61.60000","0.08213","317.67441"
"61.80000","0.08242","318.47153"
"62.00000","0.08267","318.41829"
"62.20000","0.08295","318.89225"
"62.40000","0.08321","319.01259"
"62.60000","0.08346","318.94162"
"62.80000","0.08375","319.62467"
"63.00000","0.08400","319.76564"
"63.20000","0.08428","320.40439"
"63.40000","0.08456","320.66331"
"63.60000","0.08480","320.50077"
"63.80000","0.08507","321.01422"
"64.00000","0.08534","321.42009"
"64.20000","0.08561","321.88028"
"64.40000","0.08589","322.38870"
"64.60000","0.08615","322.46324"
"64.80000","0.08640","322.58854"
"65.00000","0.08667","322.84507"
"65.20000","0.08694","323.26299"
"65.40000","0.08721","323.69395"
"65.60000","0.08749","324.32315"
"65.80000","0.08774","324.16901"
"66.00000","0.08801","324.42318"
"66.20000","0.08827","324.69895"
"66.40000","0.08853","324.92851"
"66.60000","0.08882","325.79953"
"66.80000","0.08907","325.69989"
"67.00000","0.08935","326.16770"
"67.20000","0.08961","326.37198"
"67.40000","0.08986","326.29275"
"67.60000","0.09015","327.10758"
"67.80000","0.09040","327.32270"
"68.00000","0.09068","327.87094"
"68.20000","0.09095","328.04995"
"68.40000","0.09120","327.97764"
"68.60000","0.09147","328.37328"
"68.80000","0.09173","328.66557"
"69.00000","0.09201","329.31181"
"69.20000","0.09228","329.59732"
"69.40000","0.09255","329.77287"
"69.60000","0.09280","329.74285"
"69.80000","0.09307","330.01769"
"70.00000","0.09334","330.42526"
"70.20000","0.09361","330.82252"
"70.40000","0.09389","331.36813"
"70.60000","0.09414","331.20680"
"70.80000","0.09441","331.46347"
"71.00000","0.09467","331.62453"
"71.20000","0.09493","331.74031"
"71.40000","0.09522","332.53979"
"71.60000","0.09548","332.55886"
"71.80000","0.09575","332.95093"
"72.00000","0.09601","332.95719"
"72.20000","0.09626","332.90755"
"72.40000","0.09654","333.60272"
"72.60000","0.09681","333.90879"
"72.80000","0.09709","334.39353"
"73.00000","0.09735","334.50220"
"73.20000","0.09760","334.39370"
"73.40000","0.09787","334.82169"
"73.60000","0.09813","335.06958"
"73.80000","0.09841","335.63174"
"74.00000","0.09868","335.99678"
"74.20000","0.09895","336.12038"
"74.40000","0.09920","336.17439"
"74.60000","0.09947","336.37365"
"74.80000","0.09974","336.84846"
"75.00000","0.10001","337.26007"
"75.20000","0.10029","337.86385"
"75.40000","0.10054","337.74986"
"75.60000","0.10081","338.04692"
"75.80000","0.10107","338.32105"
"76.00000","0.10133","338.48938"
"76.20000","0.10162","339.35212"
"76.40000","0.10188","339.36666"
"76.60000","0.10215","339.84446"
"76.80000","0.10241","339.95879"
"77.00000","0.10266","339.98184"
"77.20000","0.10295","340.77852"
"77.40000","0.10320","340.95583"
"77.60000","0.10349","341.36911"
"77.80000","0.10376","341.55498"
"78.00000","0.10400","341.46961"
"78.20000","0.10427","342.00775"
"78.40000","0.10454","342.34999"
"78.60000","0.10481","342.96898"
"78.80000","0.10509","343.46550"
"79.00000","0.10535","343.53347"
"79.20000","0.10561","343.81855"
"79.40000","0.10586","343.90922"
"79.60000","0.10614","344.47006"
"79.80000","0.10641","344.92838"
"80.00000","0.10669","345.46249"
"80.20000","0.10694","345.39397"
"80.40000","0.10721","345.69350"
"80.60000","0.10747","345.95879"
"80.80000","0.10773","346.27424"
"81.00000","0.10802","347.19312"
"81.20000","0.10827","347.10193"
"81.40000","0.10855","347.64466"
"81.60000","0.10881","347.79079"
"81.80000","0.10906","347.88473"
"82.00000","0.10935","348.71036"
"82.20000","0.10961","348.85153"
"82.40000","0.10989","349.49824"
"82.60000","0.11016","349.72733"
"82.80000","0.11040","349.57445"
"83.00000","0.11067","350.12450"
"83.20000","0.11094","350.44308"
"83.40000","0.11121","351.01655"
"83.60000","0.11149","351.43411"
"83.80000","0.11175","351.39564"
"84.00000","0.11201","351.59682"
"84.20000","0.11227","351.97344"
"84.40000","0.11254","352.34663"
"84.60000","0.11281","352.85053"
"84.80000","0.11309","353.27671"
"85.00000","0.11334","353.09057"
"85.20000","0.11361","353.38303"
"85.40000","0.11387","353.68824"
"85.60000","0.11413","353.99296"
"85.80000","0.11442","354.86127"
"86.00000","0.11468","354.86289"
"86.20000","0.11495","355.24601"
"86.40000","0.11521","355.47148"
"86.60000","0.11546","355.53282"
"86.80000","0.11575","356.35977"
"87.00000","0.11601","356.45379"
"87.20000","0.11629","357.09624"
"87.40000","0.11655","357.33760"
"87.60000","0.11680","357.23513"
"87.80000","0.11707","357.81916"
"88.00000","0.11733","358.12383"
"88.20000","0.11762","358.80860"
"88.40000","0.11788","359.13711"
"88.60000","0.11815","359.19839"
"88.80000","0.11840","359.37573"
"89.00000","0.11866","359.65119"
"89.20000","0.11894","360.21176"
"89.40000","0.11921","360.49618"
"89.60000","0.11949","361.17348"
"89.80000","0.11974","361.08204"
"90.00000","0.12001","361.39736"
"90.20000","0.12027","361.74193"
"90.40000","0.12053","362.11001"
"90.60000","0.12082","362.95818"
"90.80000","0.12107","362.91567"
"91.00000","0.12135","363.32934"
"91.20000","0.12161","363.44438"
"91.40000","0.12186","363.41381"
"91.60000","0.12214","364.26790"
"91.80000","0.12241","364.47945"
"92.00000","0.12269","365.01557"
"92.20000","0.12295","365.14653"
"92.40000","0.12320","365.10506"
"92.60000","0.12347","365.64518"
"92.80000","0.12373","366.02128"
"93.00000","0.12402","366.61357"
"93.20000","0.12428","366.92000"
"93.40000","0.12455","367.08569"
"93.60000","0.12481","367.30233"
"93.80000","0.12506","367.57384"
"94.00000","0.12534","368.15686"
"94.20000","0.12561","368.60403"
"94.40000","0.12589","369.07805"
"94.60000","0.12614","369.07270"
"94.80000","0.12641","369.32412"
"95.00000","0.12667","369.70313"
"95.20000","0.12693","369.97437"
"95.40000","0.12722","370.76870"
"95.60000","0.12748","370.71296"
"95.80000","0.12775","371.20679"
"96.00000","0.12801","371.36870"
"96.20000","0.12826","371.45594"
"96.40000","0.12854","372.27419"
"96.60000","0.12881","372.49008"
"96.80000","0.12909","373.12260"
"97.00000","0.12935","373.26009"
"97.20000","0.12960","373.25466"
"97.40000","0.12987","373.86756"
"97.60000","0.13013","374.01111"
"97.80000","0.13042","374.48364"
"98.00000","0.13069","374.80272"
"98.20000","0.13094","374.69476"
"98.40000","0.13121","374.99857"
"98.60000","0.13147","375.20351"
"98.80000","0.13174","375.71603"
"99.00000","0.13201","376.17177"
"99.20000","0.13229","376.63379"
"99.40000","0.13254","376.60390"
"99.60000","0.13281","371.63687"
"99.80000","0.13307","372.21088"
"100.00000","0.13333","372.43243"
"100.20000","0.13363","373.17318"
"100.40000","0.13387","372.97296"
"100.60000","0.13414","373.20718"
"100.80000","0.13441","373.31306"
"101.00000","0.13466","373.33915"
"101.20000","0.13495","374.09484"
"101.40000","0.13521","374.01251"
"101.60000","0.13548","374.50535"
"101.80000","0.13575","374.65862"
"102.00000","0.13600","374.46866"
"102.20000","0.13627","375.10157"
"102.40000","0.13653","375.34479"
"102.60000","0.13681","376.05322"
"102.80000","0.13709","376.43579"
"103.00000","0.13735","376.40873"
"103.20000","0.13761","376.66249"
"103.40000","0.13786","376.98354"
"103.60000","0.13814","377.49082"
"103.80000","0.13841","378.01063"
"104.00000","0.13869","378.39527"
"104.20000","0.13894","378.34189"
"104.40000","0.13920","378.72677"
"104.60000","0.13947","379.03366"
"104.80000","0.13974","379.52466"
"105.00000","0.14003","380.36251"
"105.20000","0.14027","380.26600"
"105.40000","0.14055","380.66611"
"105.60000","0.14081","380.83137"
"105.80000","0.14106","380.86295"
"106.00000","0.14135","381.71919"
"106.20000","0.14161","381.83329"
"106.40000","0.14188","382.39287"
"106.60000","0.14215","382.62531"
"106.80000","0.14240","382.45325"
"107.00000","0.14267","383.12347"
"107.20000","0.14293","383.32789"
"107.40000","0.14322","383.91920"
"107.60000","0.14349","384.21280"
"107.80000","0.14375","384.22647"
"108.00000","0.14401","384.48514"
"108.20000","0.14426","384.67842"
"108.40000","0.14454","385.24662"
"108.60000","0.14481","385.56610"
"108.80000","0.14509","385.89989"
"109.00000","0.14534","385.76210"
"109.20000","0.14561","385.99879"
"109.40000","0.14587","386.36440"
"109.60000","0.14613","386.54547"
"109.80000","0.14643","387.38063"
"110.00000","0.14668","387.22807"
"110.20000","0.14695","387.54734"
"110.40000","0.14721","387.61921"
"110.60000","0.14746","387.77388"
"110.80000","0.14775","388.53930"
"111.00000","0.14801","388.64949"
"111.20000","0.14828","389.12021"
"111.40000","0.14855","389.18980"
"111.60000","0.14880","389.01988"
"111.80000","0.14907","389.56283"
"112.00000","0.14933","389.83572"
"112.20000","0.14962","390.39579"
"112.40000","0.14988","390.63558"
"112.60000","0.15014","390.60583"
"112.80000","0.15040","390.74445"
"113.00000","0.15066","390.97452"
"113.20000","0.15094","391.50244"
"113.40000","0.15121","391.80323"
"113.60000","0.15149","392.24333"
"113.80000","0.15174","392.17876"
"114.00000","0.15201","392.38372"
"114.20000","0.15227","392.71899"
"114.40000","0.15253","392.92980"
"114.60000","0.15282","393.62923"
"114.80000","0.15308","393.55560"
"115.00000","0.15335","393.81844"
"115.20000","0.15361","393.81581"
"115.40000","0.15386","393.80667"
"115.60000","0.15415","394.53653"
"115.80000","0.15441","394.52023"
"116.00000","0.15469","395.01422"
"116.20000","0.15495","394.97847"
"116.40000","0.15520","394.81104"
"116.60000","0.15547","395.24732"
"116.80000","0.15573","395.44277"
"117.00000","0.15602","395.92545"
"117.20000","0.15629","396.07383"
"117.40000","0.15654","395.94559"
"117.60000","0.15681","396.19826"
"117.80000","0.15706","396.30010"
"118.00000","0.15734","396.78550"
"118.20000","0.15762","397.13910"
"118.40000","0.15788","397.22329"
"118.60000","0.15814","397.14017"
"118.80000","0.15840","397.21841"
"119.00000","0.15867","397.40619"
"119.20000","0.15894","397.65825"
"119.40000","0.15923","398.32681"
"119.60000","0.15948","398.05219"
"119.80000","0.15975","398.24064"
"120.00000","0.16001","398.26997"
"120.20000","0.16026","398.25699"
"120.40000","0.16055","398.91095"
"120.60000","0.16081","398.74522"
"120.80000","0.16108","399.09717"
"121.00000","0.16135","399.07324"
"121.20000","0.16160","398.84267"
"121.40000","0.16187","399.28296"
"121.60000","0.16213","399.29105"
"121.80000","0.16242","399.79800"
"122.00000","0.16269","399.95585"
"122.20000","0.16294","399.68930"
"122.40000","0.16321","399.72934"
"122.60000","0.16346","399.73598"
"122.80000","0.16374","399.94586"
"123.00000","0.16402","400.23510"
"123.20000","0.16429","400.27457"
"123.40000","0.16454","399.83008"
"123.60000","0.16480","399.77248"
"123.80000","0.16507","399.73151"
"124.00000","0.16534","399.74712"
"124.20000","0.16563","400.09394"
"124.40000","0.16587","399.46534"
"124.60000","0.16614","399.23606"
"124.80000","0.16641","398.89278"
"125.00000","0.16666","398.47261"
"125.20000","0.16695","398.53208"
"125.40000","0.16721","397.83441"
"125.60000","0.16748","397.41327"
"125.80000","0.16775","396.66796"
"126.00000","0.16799","395.48931"
"126.20000","0.16827","394.91431"
"126.40000","0.16854","393.73834"
"126.60000","0.16882","392.76210"
"126.80000","0.16909","391.23531"
"127.00000","0.16934","388.65967"
"127.20000","0.16961","386.79185"
"127.40000","0.16986","384.99025"
"127.60000","0.17014","383.88124"
"127.80000","0.17042","382.85275"
"128.00000","0.17069","382.00769"
"128.20000","0.17094","380.94833"
"128.40000","0.17120","380.34915"
"128.60000","0.17147","380.12612"
"128.80000","0.17174","379.86959"
"129.00000","0.17203","380.11281"
"129.20000","0.17227","379.45853"
"129.40000","0.17255","379.32560"
"129.60000","0.17281","379.21017"
"129.80000","0.17306","379.01506"
"130.00000","0.17335","379.61270"
"130.20000","0.17361","379.42228"
"130.40000","0.17389","379.68155"
"130.60000","0.17415","379.55647"
"130.80000","0.17439","379.28646"
"131.00000","0.17467","379.68350"
"131.20000","0.17494","379.74511"
"131.40000","0.17522","380.08120"
"131.60000","0.17549","380.11451"
"131.80000","0.17574","379.98704"
"132.00000","0.17600","380.12255"
"132.20000","0.17626","380.26723"
"132.40000","0.17654","380.71040"
"132.60000","0.17682","380.97838"
"132.80000","0.17709","381.20796"
"133.00000","0.17734","381.09094"
"133.20000","0.17761","381.21614"
"133.40000","0.17787","381.50387"
"133.60000","0.17814","381.68480"
"133.80000","0.17843","382.35989"
"134.00000","0.17868","382.17514"
"134.20000","0.17895","382.39710"
"134.40000","0.17921","382.49394"
"134.60000","0.17946","382.53590"
"134.80000","0.17975","383.17358"
"135.00000","0.18001","383.17133"
"135.20000","0.18029","383.54238"
"135.40000","0.18055","383.49109"
"135.60000","0.18079","383.31181"
"135.80000","0.18108","383.82457"
"136.00000","0.18133","383.80078"
"136.20000","0.18162","383.80970"
"136.40000","0.18189","383.71266"
"136.60000","0.18213","383.30487"
"136.80000","0.18240","383.30597"
"137.00000","0.18266","383.20962"
"137.20000","0.18294","381.25379"
"137.40000","0.18322","380.36199"
"137.60000","0.18349","379.49832"
"137.72500","0.18365","372.71997"
"137.84100","0.18380","361.74843"
"138.04100","0.18407","358.22580"
"138.24100","0.18433","355.42906"
"138.44100","0.18459","353.30196"
"138.64100","0.18487","352.13028"
"138.84100","0.18513","350.75991"
"139.04100","0.18541","350.02310"
"139.24100","0.18567","349.21937"
"139.44100","0.18592","348.38643"
"139.64100","0.18620","348.38602"
"139.84100","0.18646","347.69883"
"140.04100","0.18674","347.58986"
"140.24100","0.18701","347.00973"
"140.44100","0.18725","346.05607"
"140.64100","0.18753","345.52489"
"140.84100","0.18779","343.21695"
"140.97600","0.18799","333.70665"
"141.17600","0.18825","329.47024"
"141.37600","0.18850","325.60584"
"141.57600","0.18878","323.28788"
"141.77600","0.18903","321.33958"
"141.97600","0.18932","320.28090"
"142.17600","0.18959","319.26328"
"142.37600","0.18985","318.18676"
"142.57600","0.19011","317.54933"
"142.77600","0.19037","317.01033"
"142.85000","0.19049","305.59346"
"142.86500","0.19051","293.27032"
"142.88600","0.19055","281.34848"
"142.93000","0.19059","269.85718"
"142.99700","0.19067","258.34206"
"143.10900","0.19084","247.01668"
"143.29200","0.19106","236.22731"
"143.49200","0.19133","229.95495"
"143.69200","0.19159","225.38896"
"143.89200","0.19187","222.15968"
"144.09200","0.19215","219.03471"
"144.29200","0.19240","215.74696"
"144.49200","0.19266","213.13050"
"144.69200","0.19292","210.66272"
"144.89200","0.19319","208.44369"
"145.09200","0.19347","206.41171"
"145.29200","0.19375","204.13701"
"145.49200","0.19400","201.62947"
"145.69200","0.19426","199.42670"
"145.89200","0.19453","197.34012"
"146.09200","0.19479","195.18884"
"146.29200","0.19508","193.36660"
"146.49200","0.19533","190.92130"
"146.69200","0.19560","188.97309"
"146.89200","0.19587","187.21614"
"147.09200","0.19611","185.38759"
"147.29200","0.19641","184.26467"
"147.49200","0.19667","182.45958"
"147.69200","0.19694","181.15608"
"147.89200","0.19721","179.76035"
"148.09200","0.19745","178.06034"
"148.29200","0.19773","177.12077"
"148.49200","0.19799","175.81033"
"148.69200","0.19827","174.75646"
"148.89200","0.19854","173.31851"
"149.09200","0.19880","171.62133"
"149.29200","0.19906","170.18030"
"149.49200","0.19932","168.73790"
"149.69200","0.19960","167.56603"
"149.89200","0.19987","166.11637"
"150.09200","0.20015","164.93693"
"150.29200","0.20040","163.39178"
"150.49200","0.20066","162.12314"
"150.69200","0.20092","161.01430"
"150.89200","0.20119","159.81578"
"151.09200","0.20148","158.84326"
"151.29200","0.20173","157.03272"
"151.49200","0.20200","155.62425"
"151.69200","0.20226","154.17763"
"151.89200","0.20251","152.63537"
"152.09200","0.20280","151.84845"
"152.29200","0.20307","150.47815"
"152.49200","0.20334","149.54522"
"152.69200","0.20360","148.23371"
"152.89200","0.20385","146.85043"
"153.09200","0.20413","146.02119"
"153.29200","0.20439","144.92013"
"153.49200","0.20467","143.97711"
"153.69200","0.20494","142.71154"
"153.89200","0.20520","141.36284"
"154.09200","0.20546","140.20179"
"154.29200","0.20572","138.98887"
"154.39200","0.20587","138.73078"