File: materials_lab1/ENGR314_FA19_0001_2024Al_A_20190903_JCM.is_tens_RawData/Specimen_RawData_1.csv
Material,Copper
Geometry,Circular
Length,"2.00000",in
Diameter,"0.12900",in

Time,Extension,Load
(s),(in),(lbf)
"0.00000","0.00000","38.05395"
"0.10000","0.00017","40.06238"
"0.14600","0.00034","45.75272"
"0.18900","0.00046","51.48301"
"0.23800","0.00060","57.15107"
"0.30100","0.00074","62.81060"
"0.36000","0.00092","68.43158"
"0.41200","0.00104","74.13810"
"0.48000","0.00122","79.80905"
"0.53900","0.00135","85.44930"
"0.60700","0.00153","91.08218"
"0.66800","0.00167","96.73321"
"0.73800","0.00185","102.35446"
"0.80700","0.00200","108.02299"
"0.87300","0.00220","113.73449"
"0.93200","0.00233","119.41765"
"1.00500","0.00253","125.06381"
"1.07400","0.00269","130.74628"
"1.14200","0.00287","136.45760"
"1.21600","0.00304","142.09892"
"1.28500","0.00321","147.75620"
"1.36200","0.00341","153.40742"
"1.41900","0.00356","159.07159"
"1.49900","0.00376","164.69485"
"1.56600","0.00392","170.37816"
"1.64300","0.00412","176.08092"
"1.71700","0.00430","181.75774"
"1.79000","0.00448","187.43771"
"1.87500","0.00469","193.12456"
"1.93300","0.00485","198.77830"
"2.01500","0.00506","204.42080"
"2.08400","0.00521","210.07458"
"2.16300","0.00542","215.71950"
"2.24400","0.00561","221.39498"
"2.31800","0.00579","227.05907"
"2.40100","0.00601","232.77024"
"2.46600","0.00617","238.44225"
"2.54700","0.00639","244.09084"
"2.63100","0.00658","249.71472"
"2.70300","0.00677","255.39411"
"2.78700","0.00697","261.05876"
"2.87200","0.00717","266.72198"
"2.94200","0.00737","272.42031"
"3.02700","0.00758","278.06218"
"3.09800","0.00775","283.70376"
"3.18400","0.00797","289.35990"
"3.26900","0.00817","295.00647"
"3.34800","0.00836","300.67595"
"3.43200","0.00860","306.37334"
"3.50700","0.00877","312.03377"
"3.58700","0.00899","317.67356"
"3.68000","0.00921","323.36856"
"3.76000","0.00940","329.02213"
"3.84300","0.00961","334.65059"
"3.93400","0.00985","340.27778"
"4.00300","0.01001","345.93406"
"4.09000","0.01025","351.56570"
"4.18400","0.01047","357.23499"
"4.26400","0.01066","362.87903"
"4.35100","0.01088","368.51449"
"4.44200","0.01112","374.14083"
"4.51800","0.01130","379.77016"
"4.60600","0.01153","385.44105"
"4.70200","0.01177","391.07922"
"4.78700","0.01197","396.70375"
"4.87600","0.01219","402.35281"
"4.96900","0.01244","408.00827"
"5.05300","0.01264","413.67273"
"5.13800","0.01285","419.33950"
"5.23500","0.01310","424.99965"
"5.33200","0.01333","430.65780"
"5.42400","0.01355","436.28766"
"5.50600","0.01379","441.97728"
"5.60400","0.01403","447.64921"
"5.70300","0.01426","453.29824"
"5.79000","0.01448","458.93463"
"5.88800","0.01472","464.56094"
"5.98800","0.01498","469.97288"
"6.06900","0.01518","475.61110"
"6.16700","0.01543","481.27716"
"6.26700","0.01568","486.76072"
"6.36700","0.01592","492.05432"
"6.46700","0.01616","497.36631"
"6.54800","0.01639","502.99306"
"6.64800","0.01664","508.17668"
"6.74800","0.01688","513.05941"
"6.84800","0.01712","518.51926"
"6.94800","0.01736","523.68745"
"7.04300","0.01763","529.32123"
"7.14300","0.01788","534.27740"
"7.24300","0.01811","538.78889"
"7.34300","0.01836","544.12612"
"7.44300","0.01861","548.98981"
"7.54300","0.01888","553.90542"
"7.64300","0.01912","558.32915"
"7.74300","0.01935","562.86117"
"7.84300","0.01961","567.60730"
"7.94300","0.01986","571.95375"
"8.04300","0.02013","576.14361"
"8.14300","0.02037","580.41262"
"8.24300","0.02061","584.48328"
"8.34300","0.02086","588.57084"
"8.44300","0.02111","592.32223"
"8.54300","0.02137","595.75413"
"8.64300","0.02161","599.63000"
"8.74300","0.02186","603.27025"
"8.84300","0.02211","606.72355"
"8.94300","0.02237","609.86374"
"9.04300","0.02261","612.65975"
"9.14300","0.02286","616.28869"
"9.24300","0.02312","619.33865"
"9.34300","0.02337","622.14042"
"9.44300","0.02362","624.66853"
"9.54300","0.02385","627.03056"
"9.64300","0.02411","630.18047"
"9.74300","0.02437","632.74014"
"9.84300","0.02462","634.85848"
"9.94300","0.02486","636.88105"
"10.04300","0.02509","638.93051"
"10.14300","0.02537","641.88079"
"10.24300","0.02563","643.67438"
"10.34300","0.02587","645.36956"
"10.44300","0.02611","647.11205"
"10.54300","0.02634","648.87567"
"10.64300","0.02663","651.35713"
"10.74300","0.02688","652.68688"
"10.84300","0.02712","653.99452"
"10.94300","0.02736","655.61280"
"11.04300","0.02760","657.17258"
"11.14300","0.02788","659.20705"
"11.24300","0.02813","660.17835"
"11.34300","0.02837","661.30437"
"11.44300","0.02861","662.75076"
"11.54300","0.02885","664.10526"
"11.64300","0.02913","665.69693"
"11.74300","0.02937","666.44946"
"11.84300","0.02961","667.59194"
"11.94300","0.02986","668.98712"
"12.04300","0.03011","670.12000"
"12.14300","0.03038","671.34421"
"12.24300","0.03062","671.98571"
"12.34300","0.03086","673.08395"
"12.44300","0.03112","674.44346"
"12.54300","0.03137","675.31651"
"12.64300","0.03162","676.10471"
"12.74300","0.03186","676.93298"
"12.84300","0.03211","678.11674"
"12.94300","0.03237","679.14995"
"13.04300","0.03262","679.89524"
"13.14300","0.03286","680.55924"
"13.24300","0.03311","681.47878"
"13.34300","0.03336","682.58098"
"13.44300","0.03362","683.43603"
"13.54300","0.03387","683.95327"
"13.64300","0.03410","684.51666"
"13.74300","0.03436","685.66886"
"13.84300","0.03462","686.55026"
"13.94300","0.03487","687.15526"
"14.04300","0.03511","687.64275"
"14.14300","0.03535","688.27156"
"14.24300","0.03562","689.50478"
"14.34300","0.03588","690.10083"
"14.44300","0.03612","690.44858"
"14.54300","0.03636","691.00143"
"14.64300","0.03660","691.63470"
"14.74300","0.03687","692.94233"
"14.84300","0.03713","693.34371"
"14.94300","0.03737","693.66133"
"15.04300","0.03761","694.19294"
"15.14300","0.03785","694.87977"
"15.24300","0.03813","695.96062"
"15.34300","0.03838","696.20069"
"15.44300","0.03862","696.49581"
"15.54300","0.03886","697.22446"
"15.64300","0.03910","697.84570"
"15.74300","0.03938","698.74949"
"15.84300","0.03962","698.87858"
"15.94300","0.03986","699.21135"
"16.04300","0.04011","700.03721"
"16.14300","0.04036","700.67074"
"16.24300","0.04063","701.23408"
"16.34300","0.04087","701.49171"
"16.44300","0.04111","701.92492"
"16.54300","0.04136","702.74468"
"16.64300","0.04161","703.16472"
"16.74300","0.04187","703.53278"
"16.84300","0.04212","704.05781"
"16.94300","0.04236","704.47751"
"17.04300","0.04262","705.23114"
"17.14300","0.04287","705.55452"
"17.24300","0.04311","705.80781"
"17.34300","0.04337","706.45101"
"17.44300","0.04361","706.92198"
"17.54300","0.04387","707.49575"
"17.64300","0.04411","707.67506"
"17.74300","0.04435","707.94986"
"17.84300","0.04463","708.93955"
"17.94300","0.04487","709.17512"
"18.04300","0.04512","709.63494"
"18.14300","0.04537","709.78033"
"18.24300","0.04560","710.10619"
"18.34300","0.04587","711.05092"
"18.44300","0.04613","711.35295"
"18.54300","0.04637","711.57447"
"18.64300","0.04661","711.76157"
"18.74300","0.04684","712.22469"
"18.84300","0.04713","713.26663"
"18.94300","0.04738","713.33913"
"19.04300","0.04762","713.40285"
"19.14300","0.04786","713.77904"
"19.24300","0.04810","714.26345"
"19.34300","0.04838","715.18705"
"19.44300","0.04863","715.18980"
"19.54300","0.04886","715.28124"
"19.64300","0.04911","715.71938"
"19.74300","0.04935","716.20720"
"19.84300","0.04963","717.00693"
"19.94300","0.04988","716.94069"
"20.04300","0.05011","717.07329"
"20.14300","0.05036","717.69118"
"20.24300","0.05061","718.16182"
"20.34300","0.05088","718.63691"
"20.44300","0.05112","718.58927"
"20.54300","0.05136","718.96841"
"20.64300","0.05161","719.45804"
"20.74300","0.05186","719.89981"
"20.84300","0.05213","720.24773"
"20.94300","0.05237","720.35508"
"21.04300","0.05261","720.77248"
"21.14300","0.05287","721.36919"
"21.24300","0.05312","721.51672"
"21.34300","0.05337","721.63143"
"21.44300","0.05361","722.05915"
"21.54300","0.05387","722.63852"
"21.64300","0.05412","722.96579"
"21.74300","0.05436","723.10120"
"21.84300","0.05461","723.27880"
"21.94300","0.05486","723.87968"
"22.04300","0.05512","724.31086"
"22.14300","0.05538","724.59571"
"22.24300","0.05561","724.61416"
"22.34300","0.05585","724.84484"
"22.44300","0.05611","725.64769"
"22.54300","0.05637","725.99523"
"22.64300","0.05663","726.04709"
"22.74300","0.05686","726.12322"
"22.84300","0.05710","726.42563"
"22.94300","0.05737","727.32086"
"23.04300","0.05763","727.44112"
"23.14300","0.05787","727.43481"
"23.24300","0.05812","727.70034"
"23.34300","0.05835","727.94106"
"23.44300","0.05862","728.87702"
"23.54300","0.05888","728.91703"
"23.64300","0.05912","728.73119"
"23.74300","0.05936","729.17192"
"23.84300","0.05960","729.60084"
"23.94300","0.05988","730.35019"
"24.04300","0.06013","730.16067"
"24.14300","0.06036","730.13723"
"24.24300","0.06061","730.71204"
"24.34300","0.06085","731.00398"
"24.44300","0.06113","731.52193"
"24.54300","0.06137","731.42610"
"24.64300","0.06161","731.66249"
"24.74300","0.06186","732.19701"
"24.84300","0.06211","732.55261"
"24.94300","0.06238","732.79954"
"25.04300","0.06262","732.73812"
"25.14300","0.06285","733.11227"
"25.24300","0.06312","733.68341"
"25.34300","0.06337","733.76529"
"25.44300","0.06362","733.90454"
"25.54300","0.06386","734.19927"
"25.64300","0.06411","734.60789"
"25.74300","0.06437","735.02513"
"25.84300","0.06462","735.10948"
"25.94300","0.06486","735.18495"
"26.04300","0.06511","735.55246"
"26.14300","0.06536","736.03441"
"26.24300","0.06562","736.28517"
"26.34300","0.06587","736.27705"
"26.44300","0.06610","736.33808"
"26.54300","0.06636","737.20252"
"26.64300","0.06662","737.38480"
"26.74300","0.06687","737.43326"
"26.84300","0.06711","737.43337"
"26.94300","0.06735","737.63150"
"27.04300","0.06762","738.55253"
"27.14300","0.06788","738.51257"
"27.24300","0.06812","738.48645"
"27.34300","0.06836","738.66312"
"27.44300","0.06860","738.91307"
"27.54300","0.06888","739.85857"
"27.64300","0.06913","739.62624"
"27.74300","0.06937","739.55116"
"27.84300","0.06961","739.88492"
"27.94300","0.06985","740.24118"
"28.04300","0.07014","741.00270"
"28.14300","0.07038","740.69123"
"28.24300","0.07061","740.72186"
"28.34300","0.07086","741.13723"
"28.44300","0.07110","741.43421"
"28.54300","0.07138","741.93399"
"28.64300","0.07162","741.81429"
"28.74300","0.07186","741.77428"
"28.84300","0.07211","742.39426"
"28.94300","0.07236","742.71193"
"29.04300","0.07263","742.85612"
"29.14300","0.07287","742.83828"
"29.24300","0.07311","743.06270"
"29.34300","0.07336","743.52796"
"29.44300","0.07361","743.70974"
"29.54300","0.07387","743.70189"
"29.64300","0.07412","744.03433"
"29.74300","0.07436","744.35151"
"29.84300","0.07462","744.61573"
"29.94300","0.07487","744.70278"
"30.04300","0.07511","744.66661"
"30.14300","0.07536","745.19065"
"30.24300","0.07562","745.46019"
"30.34300","0.07587","745.61875"
"30.44300","0.07612","745.65196"
"30.54300","0.07635","745.60338"
"30.64300","0.07662","746.46436"
"30.74300","0.07688","746.62743"
"30.84300","0.07712","746.54214"
"30.94300","0.07737","746.54214"
"31.04300","0.07759","746.60289"
"31.14300","0.07787","747.54110"
"31.24300","0.07813","747.59461"
"31.34300","0.07837","747.38517"
"31.44300","0.07861","747.46267"
"31.54300","0.07884","747.68890"
"31.64300","0.07913","748.65675"
"31.74300","0.07938","748.40148"
"31.84300","0.07962","748.24209"
"31.94300","0.07986","748.45340"
"32.04300","0.08010","748.73046"
"32.14300","0.08038","749.56032"
"32.24300","0.08063","749.18337"
"32.34300","0.08087","749.15774"
"32.44300","0.08111","749.47157"
"32.54300","0.08135","749.69841"
"32.64300","0.08163","750.24089"
"32.74300","0.08187","749.98661"
"32.84300","0.08211","750.03683"
"32.94300","0.08236","750.46372"
"33.04300","0.08261","750.65670"
"33.14300","0.08288","750.91735"
"33.24300","0.08311","750.70500"
"33.34300","0.08336","751.03552"
"33.44300","0.08361","751.41016"
"33.54300","0.08386","751.46318"
"33.64300","0.08412","751.59199"
"33.74300","0.08436","751.63623"
"33.84300","0.08461","752.01093"
"33.94300","0.08487","752.40089"
"34.04300","0.08512","752.30517"
"34.14300","0.08536","752.12142"
"34.24300","0.08561","752.53525"
"34.34300","0.08587","753.01077"
"34.44300","0.08612","753.03920"
"34.54300","0.08636","753.00775"
"34.64300","0.08660","752.99568"
"34.74300","0.08686","753.60199"
"34.84300","0.08712","753.88767"
"34.94300","0.08738","753.82011"
"35.04300","0.08761","753.74305"
"35.14300","0.08785","753.73959"
"35.24300","0.08812","754.55035"
"35.34300","0.08838","754.57027"
"35.44300","0.08862","754.38109"
"35.54300","0.08886","754.41791"
"35.64300","0.08910","754.64031"
"35.74300","0.08938","755.50508"
"35.84300","0.08963","755.28268"
"35.94300","0.08987","754.98669"
"36.04300","0.09011","755.21204"
"36.14300","0.09035","755.37116"
"36.24300","0.09063","756.09838"
"36.34300","0.09088","755.81644"
"36.44300","0.09111","755.65195"
"36.54300","0.09136","755.96457"
"36.64300","0.09161","756.27165"
"36.74300","0.09188","756.68455"
"36.84300","0.09213","756.39322"
"36.94300","0.09236","756.34602"
"37.04300","0.09261","756.77528"
"37.14300","0.09286","756.84773"
"37.24300","0.09313","757.10206"
"37.34300","0.09337","756.98790"
"37.44300","0.09360","757.04076"
"37.54300","0.09386","757.59444"
"37.64300","0.09412","757.66464"
"37.74300","0.09437","757.63121"
"37.84300","0.09462","757.78352"
"37.94300","0.09486","757.87254"
"38.04300","0.09512","758.23687"
"38.14300","0.09537","758.13994"
"38.24300","0.09561","757.99246"
"38.34300","0.09587","758.56777"
"38.44300","0.09611","758.63110"
"38.54300","0.09637","758.82073"
"38.64300","0.09662","758.70635"
"38.74300","0.09686","758.63698"
"38.84300","0.09712","759.30509"
"38.94300","0.09737","759.29571"
"39.04300","0.09763","759.32584"
"39.14300","0.09786","759.11519"
"39.24300","0.09810","759.14905"
"39.34300","0.09837","760.08759"
"39.44300","0.09862","759.85894"
"39.54300","0.09887","759.75098"
"39.64300","0.09911","759.72990"
"39.74300","0.09935","759.89324"
"39.84300","0.09963","760.59022"
"39.94300","0.09988","760.38490"
"40.04300","0.10012","760.17195"
"40.14300","0.10035","760.21871"
"40.24300","0.10060","760.52233"
"40.34300","0.10088","761.19989"
"40.44300","0.10113","760.87535"
"40.54300","0.10137","760.69143"
"40.64300","0.10161","760.84357"
"40.74300","0.10185","761.11509"
"40.84300","0.10213","761.54160"
"40.94300","0.10238","761.27343"
"41.04300","0.10261","761.13957"
"41.14300","0.10286","761.42124"
"41.24300","0.10311","761.67931"
"41.34300","0.10338","761.83688"
"41.44300","0.10362","761.68463"
"41.54300","0.10386","761.72920"
"41.64300","0.10411","762.03238"
"41.74300","0.10436","762.16213"
"41.84300","0.10462","762.05291"
"41.94300","0.10487","762.13354"
"42.04300","0.10511","762.31998"
"42.14300","0.10537","762.51680"
"42.24300","0.10562","762.50758"
"42.34300","0.10586","762.35132"
"42.44300","0.10611","762.77415"
"42.54300","0.10636","762.88041"
"42.64300","0.10662","763.07415"
"42.74300","0.10687","762.86921"
"42.84300","0.10710","762.69045"
"42.94300","0.10736","763.31719"
"43.04300","0.10762","763.48211"
"43.14300","0.10787","763.38272"
"43.24300","0.10811","763.24710"
"43.34300","0.10835","763.14583"
"43.44300","0.10862","763.93107"
"43.54300","0.10888","763.88492"
"43.64300","0.10912","763.72635"
"43.74300","0.10936","763.62125"
"43.84300","0.10960","763.65390"
"43.94300","0.10987","764.43003"
"44.04300","0.11013","764.26340"
"44.14300","0.11037","763.99562"
"44.24300","0.11061","763.93530"
"44.34300","0.11085","764.08047"
"44.44300","0.11113","764.82927"
"44.54300","0.11138","764.49809"
"44.64300","0.11162","764.19271"
"44.74300","0.11186","764.48146"
"44.84300","0.11210","764.53585"
"44.94300","0.11238","765.08015"
"45.04300","0.11263","764.70907"
"45.14300","0.11286","764.50358"
"45.24300","0.11311","764.79480"
"45.34300","0.11336","764.98080"
"45.44300","0.11363","765.25523"
"45.54300","0.11387","764.98926"
"45.64300","0.11411","764.98196"
"45.74300","0.11436","765.39123"
"45.84300","0.11461","765.38509"
"45.94300","0.11487","765.34535"
"46.04300","0.11511","765.23492"
"46.14300","0.11536","765.44645"
"46.24300","0.11561","765.66440"
"46.34300","0.11586","765.64129"
"46.44300","0.11612","765.58300"
"46.54300","0.11636","765.70699"
"46.64300","0.11661","765.91336"
"46.74300","0.11687","766.11396"
"46.84300","0.11712","765.87483"
"46.94300","0.11736","765.67993"
"47.04300","0.11761","766.13295"
"47.14300","0.11787","766.30479"
"47.24300","0.11812","766.25814"
"47.34300","0.11836","766.06928"
"47.44300","0.11861","766.07334"
"47.54300","0.11886","766.55189"
"47.64300","0.11912","766.68625"
"47.74300","0.11938","766.49579"
"47.84300","0.11962","766.29354"
"47.94300","0.11984","766.20968"
"48.04300","0.12012","767.05908"
"48.14300","0.12038","766.86742"
"48.24300","0.12062","766.50677"
"48.34300","0.12086","766.51506"
"48.44300","0.12110","766.68465"
"48.54300","0.12138","767.29662"
"48.64300","0.12163","766.96331"
"48.74300","0.12186","766.66155"
"48.84300","0.12211","766.85902"
"48.94300","0.12235","766.91901"
"49.04300","0.12263","767.47187"
"49.14300","0.12288","767.06385"
"49.24300","0.12311","766.81424"
"49.34300","0.12336","767.15913"
"49.44300","0.12361","767.29316"
"49.54300","0.12388","767.55787"
"49.64300","0.12412","767.23510"
"49.74300","0.12436","767.11012"
"49.84300","0.12461","767.47214"
"49.94300","0.12486","767.40793"
"50.04300","0.12512","767.43510"
"50.14300","0.12537","767.54053"
"50.24300","0.12560","767.30606"
"50.34300","0.12586","767.78482"
"50.44300","0.12612","767.72791"
"50.54300","0.12637","767.49349"
"50.64300","0.12662","767.71693"
"50.74300","0.12686","767.76792"
"50.84300","0.12712","767.93268"
"50.94300","0.12737","767.67577"
"51.04300","0.12761","767.52379"
"51.14300","0.12787","768.04613"
"51.24300","0.12812","768.00771"
"51.34300","0.12837","768.00519"
"51.44300","0.12861","767.83285"
"51.54300","0.12885","767.73438"
"51.64300","0.12911","768.30195"
"51.74300","0.12937","768.30634"
"51.84300","0.12962","768.05766"
"51.94300","0.12986","767.86496"
"52.04300","0.13010","767.79514"
"52.14300","0.13037","768.60903"
"52.24300","0.13063","768.42412"
"52.34300","0.13087","768.05623"
"52.44300","0.13111","768.03126"
"52.54300","0.13135","768.13433"
"52.64300","0.13163","768.75343"
"52.74300","0.13188","768.46496"
"52.84300","0.13212","768.09723"
"52.94300","0.13235","768.03839"
"53.04300","0.13260","768.22067"
"53.14300","0.13288","768.84668"
"53.24300","0.13313","768.36007"
"53.34300","0.13336","768.12709"
"53.44300","0.13361","768.43927"
"53.54300","0.13385","768.48307"
"53.64300","0.13413","768.74537"
"53.74300","0.13437","768.30821"
"53.84300","0.13461","768.28516"
"53.94300","0.13486","768.48527"
"54.04300","0.13511","768.52187"
"54.14300","0.13538","768.60179"
"54.24300","0.13562","768.38817"
"54.34300","0.13586","768.44053"
"54.44300","0.13612","768.78812"
"54.54300","0.13636","768.59816"
"54.64300","0.13662","768.54257"
"54.74300","0.13686","768.44707"
"54.84300","0.13711","768.64827"
"54.94300","0.13737","768.80936"
"55.04300","0.13762","768.52583"
"55.14300","0.13786","768.42775"
"55.24300","0.13811","768.70091"
"55.34300","0.13837","768.87495"
"55.44300","0.13863","768.92303"
"55.54300","0.13887","768.60212"
"55.64300","0.13910","768.28708"
"55.74300","0.13936","768.83280"
"55.84300","0.13963","768.99317"
"55.94300","0.13987","768.70042"
"56.04300","0.14011","768.47089"
"56.14300","0.14035","768.39180"
"56.24300","0.14061","769.10355"
"56.34300","0.14088","768.99877"
"56.44300","0.14112","768.59004"
"56.54300","0.14136","768.51046"
"56.64300","0.14160","768.48367"
"56.74300","0.14188","769.16771"
"56.84300","0.14213","768.80173"
"56.94300","0.14237","768.44449"
"57.04300","0.14261","768.44053"
"57.14300","0.14285","768.54075"
"57.24300","0.14313","769.17775"
"57.34300","0.14338","768.67912"
"57.44300","0.14361","768.29245"
"57.54300","0.14386","768.59103"
"57.64300","0.14411","768.59657"
"57.74300","0.14438","768.85947"
"57.84300","0.14462","768.43247"
"57.94300","0.14486","768.28548"
"58.04300","0.14511","768.51452"
"58.14300","0.14536","768.61501"
"58.24300","0.14563","768.68620"
"58.34300","0.14587","768.25656"
"58.44300","0.14611","768.26671"
"58.54300","0.14637","768.61661"
"58.64300","0.14661","768.40936"
"58.74300","0.14687","768.20947"
"58.84300","0.14711","768.24026"
"58.94300","0.14736","768.30590"
"59.04300","0.14762","768.50244"
"59.14300","0.14787","768.27429"
"59.24300","0.14811","768.05469"
"59.34300","0.14837","768.34185"
"59.44300","0.14861","768.30415"
"59.54300","0.14887","768.26029"
"59.64300","0.14911","767.94569"
"59.74300","0.14935","767.59821"
"59.84300","0.14962","768.29251"
"59.94300","0.14987","768.11809"
"60.04300","0.15012","767.90063"
"60.14300","0.15037","767.64970"
"60.24300","0.15060","767.51320"
"60.34300","0.15088","768.22281"
"60.44300","0.15113","767.82544"
"60.54300","0.15137","767.46309"
"60.64300","0.15161","767.26858"
"60.74300","0.15184","767.09377"
"60.84300","0.15213","767.89959"
"60.94300","0.15238","767.34509"
"61.04300","0.15262","766.84843"
"61.14300","0.15286","766.84497"
"61.24300","0.15310","766.91078"
"61.34300","0.15338","767.24701"
"61.44300","0.15363","766.67582"
"61.54300","0.15386","766.22214"
"61.64300","0.15411","766.19470"
"61.74300","0.15435","766.17752"
"61.84300","0.15463","766.36045"
"61.94300","0.15488","765.76451"
"62.04300","0.15511","765.33547"
"62.14300","0.15536","765.34842"
"62.24300","0.15561","765.18657"
"62.34300","0.15588","764.94480"
"62.44300","0.15612","764.38437"
"62.54300","0.15636","763.92613"
"62.64300","0.15661","763.79984"
"62.74300","0.15686","763.34348"
"62.84300","0.15712","762.77964"
"62.94300","0.15737","762.38573"
"63.04300","0.15761","761.79676"
"63.14300","0.15786","761.41350"
"63.24300","0.15812","760.69231"
"63.34300","0.15836","759.72019"
"63.44300","0.15861","759.32540"
"63.54300","0.15887","758.66958"
"63.64300","0.15912","757.76705"
"63.74300","0.15936","756.69010"
"63.84300","0.15960","755.66496"
"63.94300","0.15986","755.38570"
"64.04300","0.16012","754.20293"
"64.14300","0.16037","753.16472"
"64.24300","0.16061","751.86307"
"64.34300","0.16085","750.67454"
"64.44300","0.16112","750.32371"
"64.54300","0.16138","748.94341"
"64.64300","0.16162","747.43243"
"64.74300","0.16186","746.14087"
"64.84300","0.16210","745.01633"
"64.94300","0.16237","744.53433"
"65.04300","0.16263","742.83515"
"65.14300","0.16287","741.23981"
"65.24300","0.16311","739.85830"
"65.34300","0.16335","738.64753"
"65.44300","0.16363","738.01680"
"65.54300","0.16388","736.04637"
"65.64300","0.16412","734.41393"
"65.74300","0.16436","733.11535"
"65.84300","0.16460","731.91172"
"65.94300","0.16488","731.02121"
"66.04300","0.16513","728.96225"
"66.14300","0.16536","727.26115"
"66.24300","0.16561","726.11960"
"66.34300","0.16586","724.64319"
"66.44300","0.16613","723.45910"
"66.54300","0.16637","721.46859"
"66.64300","0.16661","719.83153"
"66.74300","0.16686","718.67522"
"66.84300","0.16711","717.17208"
"66.94300","0.16737","715.58184"
"67.04300","0.16762","713.81065"
"67.14300","0.16785","712.25213"
"67.24300","0.16812","711.02644"
"67.34300","0.16837","709.29433"
"67.44300","0.16862","707.54306"
"67.54300","0.16886","705.91144"
"67.64300","0.16911","704.44057"
"67.74300","0.16937","702.87213"
"67.84300","0.16962","701.04319"
"67.94300","0.16985","699.25202"
"68.04300","0.17011","697.94016"
"68.14300","0.17037","696.34268"
"68.24300","0.17063","694.58224"
"68.34300","0.17087","692.61527"
"68.44300","0.17110","690.78294"
"68.54300","0.17136","689.71153"
"68.64300","0.17162","687.82738"
"68.74300","0.17187","685.83873"
"68.84300","0.17211","683.94158"
"68.94300","0.17235","682.21523"
"69.04300","0.17262","681.12247"
"69.14300","0.17288","679.10670"
"69.24300","0.17313","677.01059"
"69.34300","0.17336","675.10729"
"69.44300","0.17360","673.35635"
"69.54300","0.17388","672.34240"
"69.64300","0.17413","669.93542"
"69.74300","0.17437","667.71708"
"69.84300","0.17461","666.11587"
"69.94300","0.17485","664.44111"
"70.04300","0.17513","663.01788"
"70.14300","0.17538","660.55991"
"70.24300","0.17561","658.38647"
"70.34300","0.17586","656.91720"
"70.44300","0.17611","655.04754"
"70.54300","0.17638","653.45319"
"70.64300","0.17662","650.98517"
"70.74300","0.17686","648.88028"
"70.84300","0.17711","647.32418"
"70.94300","0.17736","645.48849"
"71.04300","0.17763","643.51681"
"71.14300","0.17787","641.22860"
"71.24300","0.17811","639.14077"
"71.34300","0.17837","637.51865"
"71.44300","0.17861","635.29613"
"71.54300","0.17887","633.16445"
"71.64300","0.17912","631.28914"
"71.74300","0.17936","628.96279"
"71.84300","0.17962","627.28863"
"71.94300","0.17987","625.06272"
"72.04300","0.18011","622.74097"
"72.14300","0.18037","620.88010"
"72.24300","0.18062","618.65160"
"72.34300","0.18087","616.59665"
"72.44300","0.18112","614.14549"
"72.54300","0.18135","611.84855"
"72.64300","0.18162","610.25765"
"72.74300","0.18187","607.75847"
"72.84300","0.18212","605.33387"
"72.94300","0.18236","602.97727"
"73.04300","0.18260","600.67254"
"73.14300","0.18287","598.93373"
"73.24300","0.18313","596.20605"
"73.34300","0.18337","593.45396"
"73.44300","0.18361","590.89165"
"73.54300","0.18385","588.27084"
"73.64300","0.18413","586.17890"
"73.74300","0.18438","581.57426"
"73.75200","0.18442","573.42093"
"73.75300","0.18442","567.69923"
"73.75400","0.18443","560.25397"
"73.75500","0.18444","551.23132"
"73.75600","0.18446","540.82968"
"73.75700","0.18447","529.21711"
"73.75800","0.18448","516.56332"
"73.75900","0.18449","503.03137"
"73.76000","0.18450","488.74585"
"73.76100","0.18451","473.82954"
"73.76200","0.18452","458.40203"
"73.76300","0.18453","442.55489"
"73.76400","0.18454","426.38004"
"73.76500","0.18455","409.97354"
"73.76600","0.18456","393.41128"
"73.76700","0.18457","376.76705"
"73.76800","0.18457","360.11722"
"73.76900","0.18458","343.52170"
"73.77000","0.18459","327.03576"
"73.77100","0.18460","310.71538"
"73.77200","0.18461","294.60652"
"73.77300","0.18461","278.75332"
"73.77400","0.18462","263.19793"
"73.77500","0.18463","247.97017"
"73.77600","0.18463","233.09834"
"73.77700","0.18464","218.61293"
"73.77800","0.18464","204.53394"
"73.77900","0.18465","190.87725"
"73.78000","0.18465","177.66180"
"73.78100","0.18465","164.89884"
"73.78200","0.18466","152.59452"
"73.78300","0.18467","140.75794"
"73.78400","0.18467","129.39469"
"73.78500","0.18467","118.50667"
"73.78600","0.18467","108.09574"
"73.78700","0.18468","98.15926"
"73.78800","0.18468","88.69469"
"73.78900","0.18468","79.70155"
"73.79000","0.18468","71.17296"
"73.79100","0.18468","63.10061"
"73.79200","0.18469","55.47849"
"73.79300","0.18469","48.29503"
"73.79400","0.18469","41.53766"
"73.79500","0.18469","35.19765"
"73.79600","0.18469","29.26370"
"73.79800","0.18469","18.56415"
"73.80000","0.18469","9.33360"