File: materials_lab1/ENGR314_FA19_0001_HDPE_B_20190906_MA.is_tens_RawData/Specimen_RawData_1.csv
Material,Nylon
Geometry,Circular
Length,"2.00000",in
Diameter,"0.26400",in

Time,Extension,Load
(s),(in),(lbf)
"0.00000","0.00000","-5.83296"
"0.16900","0.00283","4.79604"
"0.33900","0.00568","16.09805"
"0.53300","0.00891","27.28271"
"0.73300","0.01226","37.38735"
"0.93300","0.01558","46.30537"
"1.13300","0.01893","54.51779"
"1.33300","0.02225","62.01371"
"1.53300","0.02559","68.96627"
"1.73300","0.02891","75.44038"
"1.93300","0.03225","81.49415"
"2.13300","0.03558","87.06265"
"2.33300","0.03893","92.39191"
"2.53300","0.04225","97.24143"
"2.73300","0.04559","101.82011"
"2.93300","0.04892","106.10117"
"3.13300","0.05226","110.10083"
"3.33300","0.05558","113.83334"
"3.53300","0.05893","117.39249"
"3.73300","0.06225","120.59875"
"3.93300","0.06559","123.52664"
"4.13300","0.06892","126.30184"
"4.33300","0.07225","128.89495"
"4.53300","0.07559","131.36218"
"4.73300","0.07892","133.71978"
"4.93300","0.08225","135.92003"
"5.13300","0.08559","138.07677"
"5.33300","0.08892","140.09807"
"5.53300","0.09225","142.01952"
"5.73300","0.09559","143.90576"
"5.93300","0.09892","145.66013"
"6.13300","0.10226","147.35636"
"6.33300","0.10558","148.99483"
"6.53300","0.10892","150.57770"
"6.73300","0.11225","152.05950"
"6.93300","0.11558","153.49426"
"7.13300","0.11892","154.72466"
"7.33300","0.12226","155.89733"
"7.53300","0.12559","157.26342"
"7.73300","0.12892","158.46791"
"7.93300","0.13226","159.67936"
"8.13300","0.13559","160.85684"
"8.33300","0.13891","161.99412"
"8.53300","0.14225","163.10904"
"8.73300","0.14559","164.17975"
"8.93300","0.14892","165.18634"
"9.13300","0.15225","166.20357"
"9.33300","0.15558","167.15608"
"9.53300","0.15892","168.11104"
"9.73300","0.16225","169.00488"
"9.93300","0.16559","169.87213"
"10.13300","0.16892","170.73837"
"10.33300","0.17225","171.53820"
"10.53300","0.17559","172.31103"
"10.73300","0.17892","173.05051"
"10.93300","0.18225","173.79523"
"11.13300","0.18559","174.47179"
"11.33300","0.18892","175.16928"
"11.53300","0.19225","175.80040"
"11.73300","0.19559","176.39354"
"11.93300","0.19892","176.93110"
"12.13300","0.20225","177.49595"
"12.33300","0.20559","178.06240"
"12.53300","0.20892","178.59188"
"12.73300","0.21226","179.10835"
"12.93300","0.21559","179.60301"
"13.13300","0.21892","180.05872"
"13.33300","0.22225","180.51752"
"13.53300","0.22558","180.95531"
"13.73300","0.22892","181.39490"
"13.93300","0.23225","181.74543"
"14.13300","0.23559","182.17854"
"14.33300","0.23891","182.50844"
"14.53300","0.24226","182.87250"
"14.73300","0.24559","183.18324"
"14.93300","0.24892","183.48114"
"15.13300","0.25225","183.76878"
"15.33300","0.25559","184.03156"
"15.53300","0.25891","184.28410"
"15.73300","0.26226","184.53987"
"15.93300","0.26558","184.75395"
"16.13300","0.26892","184.99789"
"16.33300","0.27225","185.19076"
"16.53300","0.27559","185.40418"
"16.73300","0.27892","185.55637"
"16.93300","0.28226","185.76042"
"17.13300","0.28558","185.91295"
"17.33300","0.28892","186.05593"
"17.53300","0.29225","186.18854"
"17.73300","0.29559","186.31475"
"17.93300","0.29892","186.42936"
"18.13300","0.30225","186.54013"
"18.33300","0.30557","186.61742"
"18.53300","0.30892","186.73246"
"18.73300","0.31225","186.79481"
"18.93300","0.31559","186.86440"
"19.13300","0.31892","186.91010"
"19.33300","0.32226","186.97955"
"19.53300","0.32558","187.00225"
"19.73300","0.32893","187.06336"
"19.93300","0.33225","187.09157"
"20.13300","0.33558","187.10407"
"20.33300","0.33892","187.10984"
"20.53300","0.34225","187.12549"
"20.73300","0.34559","187.09248"
"20.93300","0.34892","187.10560"
"21.13300","0.35225","187.07326"
"21.33300","0.35559","187.07080"
"21.53300","0.35892","187.03596"
"21.73300","0.36226","187.03842"
"21.93300","0.36559","186.99845"
"22.13300","0.36892","186.96328"
"22.33300","0.37225","186.89511"
"22.53300","0.37559","186.87932"
"22.73300","0.37892","186.82080"
"22.93300","0.38225","186.75225"
"23.13300","0.38559","186.68337"
"23.33300","0.38892","186.65251"
"23.53300","0.39225","186.54274"
"23.73300","0.39559","186.49105"
"23.93300","0.39892","186.40548"
"24.13300","0.40225","186.32462"
"24.33300","0.40559","186.24296"
"24.53300","0.40893","186.16085"
"24.73300","0.41224","186.06222"
"24.93300","0.41559","186.00224"
"25.13300","0.41891","185.85512"
"25.33300","0.42226","185.78377"
"25.53300","0.42559","185.67592"
"25.73300","0.42892","185.58178"
"25.93300","0.43225","185.46868"
"26.13300","0.43559","185.35903"
"26.33300","0.43891","185.21061"
"26.53300","0.44226","185.13141"
"26.73300","0.44558","185.01092"
"26.93300","0.44892","184.87522"
"27.13300","0.45225","184.75612"
"27.33300","0.45559","184.63989"
"27.53300","0.45892","184.49908"
"27.73300","0.46226","184.38968"
"27.93300","0.46558","184.24491"
"28.13300","0.46892","184.11935"
"28.33300","0.47226","183.98416"
"28.53300","0.47559","183.84598"
"28.73300","0.47892","183.72046"
"28.93300","0.48226","183.57817"
"29.13300","0.48558","183.45322"
"29.33300","0.48893","183.30274"
"29.53300","0.49226","183.17018"
"29.73300","0.49559","183.02718"
"29.93300","0.49892","182.89006"
"30.13300","0.50225","182.75945"
"30.33300","0.50559","182.61312"
"30.53300","0.50892","182.48923"
"30.73300","0.51225","182.34302"
"30.93300","0.51559","182.20888"
"31.13300","0.51892","182.10245"
"31.33300","0.52225","181.94704"
"31.53300","0.52559","181.81402"
"31.73300","0.52892","181.69819"
"31.93300","0.53225","181.53249"
"32.13300","0.53559","181.38938"
"32.33300","0.53892","181.25211"
"32.53300","0.54225","181.08777"
"32.73300","0.54558","180.94790"
"32.93300","0.54892","180.80739"
"33.13300","0.55226","180.64223"
"33.33300","0.55559","180.48899"
"33.53300","0.55892","180.33619"
"33.73300","0.56225","180.19327"
"33.93300","0.56559","180.03531"
"34.13300","0.56892","179.87929"
"34.33300","0.57226","179.73855"
"34.53300","0.57559","179.57911"
"34.73300","0.57892","179.42133"
"34.93300","0.58226","179.26250"
"35.13300","0.58559","179.11471"
"35.33300","0.58892","178.94010"
"35.53300","0.59225","178.78612"
"35.73300","0.59559","178.66028"
"35.93300","0.59892","178.46896"
"36.13300","0.60225","178.31620"
"36.33300","0.60559","178.17125"
"36.53300","0.60892","177.98978"
"36.73300","0.61225","177.85455"
"36.93300","0.61559","177.67545"
"37.13300","0.61892","177.52320"
"37.33300","0.62226","177.34854"
"37.53300","0.62559","177.18417"
"37.73300","0.62891","177.03516"
"37.93300","0.63226","176.88505"
"38.13300","0.63559","176.69416"
"38.33300","0.63892","176.53936"
"38.53300","0.64225","176.38414"
"38.73300","0.64559","176.23746"
"38.93300","0.64892","176.08019"
"39.13300","0.65226","175.93498"
"39.33300","0.65558","175.77071"
"39.53300","0.65892","175.63392"
"39.73300","0.66224","175.45295"
"39.93300","0.66559","175.30557"
"40.13300","0.66892","175.16043"
"40.33300","0.67226","174.98641"
"40.53300","0.67558","174.82220"
"40.73300","0.67892","174.67634"
"40.93300","0.68225","174.49639"
"41.13300","0.68559","174.34576"
"41.33300","0.68891","174.16951"
"41.53300","0.69226","174.02383"
"41.73300","0.69558","173.84221"
"41.93300","0.69893","173.68254"
"42.13300","0.70225","173.50623"
"42.33300","0.70559","173.36654"
"42.53300","0.70891","173.20297"
"42.73300","0.71226","173.02555"
"42.93300","0.71559","172.87333"
"43.13300","0.71892","172.71250"
"43.33300","0.72225","172.54775"
"43.53300","0.72559","172.42580"
"43.73300","0.72891","172.22003"
"43.93300","0.73226","172.07637"
"44.13300","0.73558","171.88602"
"44.33300","0.73892","171.75491"
"44.53300","0.74225","171.58094"
"44.73300","0.74559","171.42671"
"44.93300","0.74892","171.24003"
"45.13300","0.75226","171.09058"
"45.33300","0.75558","170.91982"
"45.53300","0.75892","170.77317"
"45.73300","0.76225","170.60355"
"45.93300","0.76559","170.42898"
"46.13300","0.76892","170.23757"
"46.33300","0.77225","170.10348"
"46.53300","0.77558","169.90461"
"46.73300","0.77893","169.73433"
"46.93300","0.78225","169.56300"
"47.13300","0.78559","169.39732"
"47.33300","0.78892","169.21240"
"47.53300","0.79226","169.07603"
"47.73300","0.79558","168.86482"
"47.93300","0.79893","168.72184"
"48.13300","0.80225","168.51081"
"48.33300","0.80559","168.35669"
"48.53300","0.80892","168.16340"
"48.73300","0.81226","168.01179"
"48.93300","0.81558","167.82103"
"49.13300","0.81892","167.66090"
"49.33300","0.82225","167.46996"
"49.53300","0.82559","167.28923"
"49.73300","0.82892","167.09908"
"49.93300","0.83226","166.91946"
"50.13300","0.83558","166.72216"
"50.33300","0.83893","166.56822"
"50.53300","0.84225","166.35384"
"50.73300","0.84560","166.18867"
"50.93300","0.84892","165.99244"
"51.13300","0.85226","165.80786"
"51.33300","0.85559","165.62162"
"51.53300","0.85892","165.44514"
"51.73300","0.86226","165.24184"
"51.93300","0.86559","165.06093"
"52.13300","0.86891","164.87778"
"52.33300","0.87225","164.69579"
"52.53300","0.87559","164.51192"
"52.73300","0.87892","164.30912"
"52.93300","0.88225","164.09180"
"53.13300","0.88559","163.91368"
"53.33300","0.88892","163.70365"
"53.53300","0.89226","163.50504"
"53.73300","0.89559","163.29838"
"53.93300","0.89892","163.09182"
"54.13300","0.90226","162.89875"
"54.33300","0.90558","162.69119"
"54.53300","0.90892","162.48005"
"54.73300","0.91225","162.28242"
"54.93300","0.91559","162.07391"
"55.13300","0.91892","161.85727"
"55.33300","0.92226","161.66885"
"55.53300","0.92559","161.45003"
"55.73300","0.92892","161.22780"
"55.93300","0.93226","161.01442"
"56.13300","0.93559","160.77798"
"56.33300","0.93892","160.55622"
"56.53300","0.94226","160.34201"
"56.73300","0.94558","160.10402"
"56.93300","0.94892","159.87730"
"57.13300","0.95225","159.64959"
"57.33300","0.95559","159.42482"
"57.53300","0.95893","159.19161"
"57.73300","0.96225","158.94486"
"57.93300","0.96558","158.71152"
"58.13300","0.96892","158.49349"
"58.33300","0.97225","158.26672"
"58.53300","0.97559","158.01069"
"58.73300","0.97892","157.76514"
"58.93300","0.98225","157.51577"
"59.13300","0.98559","157.25417"
"59.33300","0.98892","157.02925"
"59.53300","0.99225","156.73925"
"59.73300","0.99559","156.49023"
"59.93300","0.99892","156.20983"
"60.13300","1.00225","155.93998"
"60.33300","1.00559","155.67281"
"60.53300","1.00892","155.40426"
"60.73300","1.01225","155.13520"
"60.93300","1.01559","154.85620"
"61.13300","1.01892","154.57242"
"61.33300","1.02225","154.31891"
"61.53300","1.02559","154.01191"
"61.73300","1.02892","153.72604"
"61.93300","1.03225","153.40865"
"62.13300","1.03559","153.13951"
"62.33300","1.03892","152.80643"
"62.53300","1.04226","152.51863"
"62.73300","1.04558","152.20013"
"62.93300","1.04892","151.89431"
"63.13300","1.05225","151.57481"
"63.33300","1.05559","151.26122"
"63.53300","1.05892","150.92700"
"63.73300","1.06226","150.60023"
"63.93300","1.06558","150.24716"
"64.13300","1.06892","149.90775"
"64.33300","1.07225","149.54247"
"64.53300","1.07559","149.18752"
"64.73300","1.07891","148.79759"
"64.93300","1.08226","148.46043"
"65.13300","1.08559","148.08521"
"65.33300","1.08892","147.72117"
"65.53300","1.09225","147.33541"
"65.73300","1.09559","146.94260"
"65.93300","1.09891","146.56023"
"66.13300","1.10226","146.16766"
"66.33300","1.10558","145.73498"
"66.53300","1.10892","145.34823"
"66.73300","1.11225","144.92501"
"66.93300","1.11559","144.52238"
"67.13300","1.11892","144.08002"
"67.33300","1.12225","143.65056"
"67.53300","1.12558","143.19928"
"67.73300","1.12892","142.75051"
"67.93300","1.13225","142.28557"
"68.13300","1.13559","141.83591"
"68.33300","1.13892","141.36999"
"68.53300","1.14225","140.90946"
"68.73300","1.14558","140.44522"
"68.93300","1.14892","139.98516"
"69.13300","1.15225","139.47499"
"69.33300","1.15559","138.97143"
"69.53300","1.15892","138.46829"
"69.73300","1.16225","137.98395"
"69.93300","1.16558","137.48167"
"70.13300","1.16893","136.97981"
"70.33300","1.17225","136.44638"
"70.53300","1.17559","135.94769"
"70.73300","1.17892","135.38186"
"70.93300","1.18225","134.85765"
"71.13300","1.18559","134.34981"
"71.33300","1.18892","133.81554"
"71.53300","1.19225","133.28687"
"71.73300","1.19559","132.76082"
"71.93300","1.19892","132.17265"
"72.13300","1.20226","131.64393"
"72.33300","1.20558","131.09959"
"72.53300","1.20892","130.55605"
"72.73300","1.21225","130.01320"
"72.93300","1.21560","129.49750"
"73.13300","1.21891","128.92985"
"73.33300","1.22226","128.39917"
"73.53300","1.22558","127.84229"
"73.73300","1.22892","127.30678"
"73.93300","1.23225","126.77724"
"74.13300","1.23560","126.24408"
"74.33300","1.23891","125.69478"
"74.53300","1.24226","125.19844"
"74.73300","1.24559","124.66547"
"74.93300","1.24893","124.18208"
"75.13300","1.25225","123.71576"
"75.33300","1.25559","123.22788"
"75.53300","1.25892","122.75514"
"75.73300","1.26226","122.31111"
"75.93300","1.26558","121.83702"
"76.13300","1.26893","121.42732"
"76.33300","1.27225","121.00822"
"76.53300","1.27558","120.60483"
"76.73300","1.27892","120.20747"
"76.93300","1.28226","119.84010"
"77.13300","1.28559","119.47361"
"77.33300","1.28892","119.10940"
"77.53300","1.29226","118.77713"
"77.73300","1.29559","118.44488"
"77.93300","1.29892","118.12796"
"78.13300","1.30226","117.82407"
"78.33300","1.30559","117.54122"
"78.53300","1.30892","117.27711"
"78.73300","1.31225","117.00890"
"78.93300","1.31559","116.79854"
"79.13300","1.31892","116.53830"
"79.33300","1.32225","116.32111"
"79.53300","1.32559","116.11120"
"79.73300","1.32892","115.90471"
"79.93300","1.33226","115.69471"
"80.13300","1.33559","115.52821"
"80.33300","1.33892","115.36088"
"80.53300","1.34225","115.20218"
"80.73300","1.34559","115.04781"
"80.93300","1.34892","114.92668"
"81.13300","1.35225","114.79046"
"81.33300","1.35559","114.68314"
"81.53300","1.35891","114.54779"
"81.73300","1.36226","114.44856"
"81.93300","1.36559","114.36907"
"82.13300","1.36892","114.28573"
"82.33300","1.37225","114.19702"
"82.53300","1.37558","114.10909"
"82.73300","1.37892","114.03684"
"82.93300","1.38225","113.98459"
"83.13300","1.38558","113.92502"
"83.33300","1.38892","113.86195"
"83.53300","1.39225","113.81985"
"83.73300","1.39559","113.77552"
"83.93300","1.39892","113.72918"
"84.13300","1.40225","113.71453"
"84.33300","1.40558","113.67797"
"84.53300","1.40892","113.64934"
"84.73300","1.41226","113.64385"
"84.93300","1.41558","113.59265"
"85.13300","1.41892","113.59298"
"85.33300","1.42225","113.56617"
"85.53300","1.42559","113.56199"
"85.73300","1.42892","113.53482"
"85.93300","1.43225","113.53863"
"86.13300","1.43558","113.52795"
"86.33300","1.43892","113.52520"
"86.53300","1.44225","113.50294"
"86.73300","1.44559","113.49640"
"86.93300","1.44892","113.50082"
"87.13300","1.45225","113.49286"
"87.33300","1.45559","113.47974"
"87.53300","1.45893","113.50859"
"87.73300","1.46225","113.49267"
"87.93300","1.46560","113.51063"
"88.13300","1.46891","113.50940"
"88.33300","1.47225","113.52427"
"88.53300","1.47558","113.52490"
"88.73300","1.47893","113.54366"
"88.93300","1.48224","113.53578"
"89.13300","1.48559","113.56940"
"89.33300","1.48891","113.57399"
"89.53300","1.49226","113.59942"
"89.73300","1.49558","113.61732"
"89.93300","1.49892","113.62976"
"90.13300","1.50225","113.64220"
"90.33300","1.50559","113.67792"
"90.53300","1.50891","113.67375"
"90.73300","1.51226","113.70927"
"90.93300","1.51558","113.72149"
"91.13300","1.51892","113.73560"
"91.33300","1.52225","113.73815"
"91.53300","1.52559","113.75022"
"91.73300","1.52891","113.74790"
"91.93300","1.53225","113.78355"
"92.13300","1.53558","113.79069"
"92.33300","1.53892","113.82392"
"92.53300","1.54226","113.82663"
"92.73300","1.54559","113.86131"
"92.93300","1.54892","113.87043"
"93.13300","1.55226","113.90380"
"93.33300","1.55558","113.91732"
"93.53300","1.55892","113.94145"
"93.73300","1.56225","113.95751"
"93.93300","1.56559","114.00214"
"94.13300","1.56891","114.01173"
"94.33300","1.57226","114.05309"
"94.53300","1.57559","114.06672"
"94.73300","1.57892","114.11028"
"94.93300","1.58225","114.12402"
"95.13300","1.58559","114.13538"
"95.33300","1.58892","114.16267"
"95.53300","1.59226","114.19745"
"95.73300","1.59558","114.21635"
"95.93300","1.59893","114.24750"
"96.13300","1.60225","114.24581"
"96.33300","1.60559","114.27500"
"96.53300","1.60892","114.29253"
"96.73300","1.61225","114.31910"
"96.93300","1.61558","114.32104"
"97.13300","1.61893","114.36458"
"97.33300","1.62225","114.38379"
"97.53300","1.62559","114.40720"
"97.73300","1.62892","114.42801"
"97.93300","1.63225","114.43785"
"98.13300","1.63559","114.46469"
"98.33300","1.63893","114.48541"
"98.53300","1.64225","114.50407"
"98.73300","1.64559","114.52214"
"98.93300","1.64891","114.53254"
"99.13300","1.65226","114.54935"
"99.33300","1.65559","114.54043"
"99.53300","1.65892","114.57846"
"99.73300","1.66225","114.57629"
"99.93300","1.66559","114.59776"
"100.13300","1.66892","114.61606"
"100.33300","1.67226","114.62903"
"100.53300","1.67559","114.65906"
"100.73300","1.67892","114.67217"
"100.93300","1.68225","114.68160"
"101.13300","1.68559","114.72048"
"101.33300","1.68892","114.72854"
"101.53300","1.69225","114.74144"
"101.73300","1.69559","114.75407"
"101.93300","1.69892","114.78165"
"102.13300","1.70226","114.79695"
"102.33300","1.70559","114.81546"
"102.53300","1.70892","114.82157"
"102.73300","1.71225","114.83285"
"102.93300","1.71559","114.84255"
"103.13300","1.71892","114.85515"
"103.33300","1.72226","114.88108"
"103.53300","1.72558","114.88560"
"103.73300","1.72892","114.90918"
"103.93300","1.73226","114.93632"
"104.13300","1.73559","114.95086"
"104.33300","1.73892","115.00113"
"104.53300","1.74225","115.01543"
"104.73300","1.74558","115.05478"
"104.93300","1.74892","115.07845"
"105.13300","1.75225","115.13133"
"105.33300","1.75558","115.16504"
"105.53300","1.75892","115.19624"
"105.73300","1.76225","115.23447"
"105.93300","1.76559","115.25463"
"106.13300","1.76892","115.29181"
"106.33300","1.77225","115.31135"
"106.53300","1.77559","115.32952"
"106.73300","1.77892","115.36862"
"106.93300","1.78226","115.36718"
"107.13300","1.78559","115.40520"
"107.33300","1.78892","115.42349"
"107.53300","1.79225","115.41541"
"107.73300","1.79558","115.44159"
"107.93300","1.79892","115.44059"
"108.13300","1.80225","115.46349"
"108.33300","1.80559","115.46800"
"108.53300","1.80892","115.48970"
"108.73300","1.81225","115.48569"
"108.93300","1.81559","115.52312"
"109.13300","1.81892","115.53258"
"109.33300","1.82225","115.55621"
"109.53300","1.82559","115.55648"
"109.73300","1.82892","115.57006"
"109.93300","1.83226","115.57753"
"110.13300","1.83559","115.61259"
"110.33300","1.83892","115.61296"
"110.53300","1.84226","115.63619"
"110.73300","1.84558","115.62975"
"110.93300","1.84893","115.63986"
"111.13300","1.85225","115.64266"
"111.33300","1.85559","115.66320"
"111.53300","1.85892","115.66783"
"111.73300","1.86226","115.69139"
"111.93300","1.86558","115.69295"
"112.13300","1.86893","115.70848"
"112.33300","1.87225","115.71757"
"112.53300","1.87559","115.73188"
"112.73300","1.87892","115.73904"
"112.93300","1.88226","115.76108"
"113.13300","1.88558","115.76308"
"113.33300","1.88892","115.78299"
"113.53300","1.89225","115.79700"
"113.73300","1.89560","115.81464"
"113.93300","1.89892","115.81871"
"114.13300","1.90225","115.81610"
"114.33300","1.90558","115.81293"
"114.53300","1.90893","115.82876"
"114.73300","1.91225","115.81998"
"114.93300","1.91559","115.83011"
"115.13300","1.91892","115.84131"
"115.33300","1.92225","115.85280"
"115.53300","1.92558","115.84693"
"115.73300","1.92893","115.84688"
"115.93300","1.93225","115.82940"
"116.13300","1.93559","115.86370"
"116.33300","1.93891","115.86041"
"116.53300","1.94226","115.86348"
"116.73300","1.94558","115.86563"
"116.93300","1.94892","115.88295"
"117.13300","1.95225","115.86267"
"117.33300","1.95559","115.88836"
"117.53300","1.95892","115.88148"
"117.73300","1.96226","115.90475"
"117.93300","1.96559","115.91109"
"118.13300","1.96892","115.93014"
"118.33300","1.97225","115.93166"
"118.53300","1.97559","115.95901"
"118.73300","1.97891","115.95199"
"118.93300","1.98226","115.98528"
"119.13300","1.98558","115.98745"
"119.33300","1.98892","115.99176"
"119.53300","1.99225","115.98804"
"119.73300","1.99559","116.01573"
"119.93300","1.99891","116.01308"
"120.13300","2.00226","116.04485"
"120.33300","2.00558","116.05252"
"120.53300","2.00892","116.05505"
"120.73300","2.01226","116.07035"
"120.93300","2.01559","116.07746"
"121.13300","2.01892","116.08237"
"121.33300","2.02226","116.11312"
"121.53300","2.02558","116.11422"
"121.73300","2.02892","116.11259"
"121.93300","2.03225","116.12136"
"122.13300","2.03559","116.14433"
"122.33300","2.03892","116.14150"
"122.53300","2.04226","116.15088"
"122.73300","2.04558","116.15899"
"122.93300","2.04892","116.16529"
"123.13300","2.05225","116.17642"
"123.33300","2.05559","116.20503"
"123.53300","2.05893","116.22074"
"123.73300","2.06225","116.21987"
"123.93300","2.06558","116.22985"
"124.13300","2.06893","116.24722"
"124.33300","2.07225","116.26098"
"124.53300","2.07559","116.27203"
"124.73300","2.07892","116.29486"
"124.93300","2.08225","116.31222"
"125.13300","2.08558","116.31846"
"125.33300","2.08892","116.34578"
"125.53300","2.09225","116.34998"
"125.73300","2.09559","116.36258"
"125.93300","2.09892","116.39354"
"126.13300","2.10225","116.39750"
"126.33300","2.10559","116.40979"
"126.53300","2.10893","116.43522"
"126.73300","2.11225","116.43061"
"126.93300","2.11559","116.45983"
"127.13300","2.11892","116.46720"
"127.33300","2.12225","116.47766"
"127.53300","2.12559","116.48563"
"127.73300","2.12892","116.50720"
"127.93300","2.13225","116.52243"
"128.13300","2.13559","116.54361"
"128.33300","2.13892","116.55010"
"128.53300","2.14225","116.56241"
"128.73300","2.14559","116.59276"
"128.93300","2.14892","116.59485"
"129.13300","2.15226","116.60806"
"129.33300","2.15559","116.62493"
"129.53300","2.15892","116.63829"
"129.73300","2.16225","116.65927"
"129.93300","2.16559","116.67051"
"130.13300","2.16892","116.68062"
"130.33300","2.17226","116.68002"
"130.53300","2.17559","116.68622"
"130.73300","2.17892","116.70820"
"130.93300","2.18226","116.72125"
"131.13300","2.18559","116.73265"
"131.33300","2.18892","116.72443"
"131.53300","2.19226","116.75133"
"131.73300","2.19558","116.74043"
"131.93300","2.19892","116.74791"
"132.13300","2.20225","116.76753"
"132.33300","2.20559","116.76855"
"132.53300","2.20892","116.77027"
"132.73300","2.21225","116.77582"
"132.93300","2.21558","116.78607"
"133.13300","2.21893","116.81420"
"133.33300","2.22225","116.80252"
"133.53300","2.22559","116.80665"
"133.73300","2.22892","116.81211"
"133.93300","2.23226","116.81911"
"134.13300","2.23559","116.82985"
"134.33300","2.23893","116.84327"
"134.53300","2.24225","116.84603"
"134.73300","2.24559","116.87161"
"134.93300","2.24892","116.85758"
"135.13300","2.25226","116.87856"
"135.33300","2.25558","116.88616"
"135.53300","2.25892","116.89857"
"135.73300","2.26225","116.89923"
"135.93300","2.26559","116.90937"
"136.13300","2.26892","116.92221"
"136.33300","2.27226","116.94596"
"136.53300","2.27558","116.94058"
"136.73300","2.27892","116.95894"
"136.93300","2.28225","116.95388"
"137.13300","2.28559","116.97284"
"137.33300","2.28891","116.96771"
"137.53300","2.29225","116.98367"
"137.73300","2.29558","117.00273"
"137.93300","2.29893","117.01284"
"138.13300","2.30225","117.01575"
"138.33300","2.30559","117.02677"
"138.53300","2.30891","117.01922"
"138.73300","2.31226","117.02523"
"138.93300","2.31558","117.02682"
"139.13300","2.31892","117.02913"
"139.33300","2.32225","117.03968"
"139.53300","2.32559","117.05387"
"139.73300","2.32892","117.04366"
"139.93300","2.33226","117.07224"
"140.13300","2.33558","117.04770"
"140.33300","2.33892","117.06357"
"140.53300","2.34225","117.06512"
"140.73300","2.34559","117.07884"
"140.93300","2.34892","117.08055"
"141.13300","2.35225","117.09916"
"141.33300","2.35558","117.08906"
"141.53300","2.35892","117.10942"
"141.73300","2.36225","117.10846"
"141.93300","2.36559","117.14414"
"142.13300","2.36892","117.13682"
"142.33300","2.37226","117.16779"
"142.53300","2.37558","117.16912"
"142.73300","2.37893","117.22633"
"142.93300","2.38226","117.23570"
"143.13300","2.38559","117.27818"
"143.33300","2.38892","117.28167"
"143.53300","2.39226","117.30609"
"143.73300","2.39559","117.32486"
"143.93300","2.39892","117.37120"
"144.13300","2.40225","117.37593"
"144.33300","2.40559","117.40000"
"144.53300","2.40891","117.40602"
"144.73300","2.41226","117.42327"
"144.93300","2.41559","117.44543"
"145.13300","2.41893","117.46150"
"145.33300","2.42225","117.44852"
"145.53300","2.42559","117.48147"
"145.73300","2.42892","117.47342"
"145.93300","2.43226","117.48444"
"146.13300","2.43558","117.48908"
"146.33300","2.43892","117.48555"
"146.53300","2.44225","117.49288"
"146.73300","2.44560","117.50679"
"146.93300","2.44891","117.50383"
"147.13300","2.45226","117.52944"
"147.33300","2.45558","117.53475"
"147.53300","2.45892","117.55853"
"147.73300","2.46226","117.55498"
"147.93300","2.46559","117.58375"
"148.13300","2.46892","117.57024"
"148.33300","2.47226","117.58744"
"148.53300","2.47558","117.60318"
"148.73300","2.47893","117.60989"
"148.93300","2.48225","117.64311"
"149.13300","2.48558","117.64822"
"149.33300","2.48892","117.64986"
"149.53300","2.49226","117.65860"
"149.73300","2.49559","117.68456"
"149.93300","2.49892","117.67553"
"150.13300","2.50225","117.67199"
"150.33300","2.50559","117.69591"
"150.53300","2.50892","117.70210"
"150.73300","2.51226","117.72274"
"150.93300","2.51558","117.72083"
"151.13300","2.51892","117.72943"
"151.33300","2.52226","117.74669"
"151.53300","2.52558","117.74122"
"151.73300","2.52892","117.76483"
"151.93300","2.53225","117.76557"
"152.13300","2.53559","117.77656"
"152.33300","2.53893","117.79400"
"152.53300","2.54225","117.79602"
"152.73300","2.54559","117.81524"
"152.93300","2.54892","117.81443"
"153.13300","2.55225","117.81467"
"153.33300","2.55559","117.80642"
"153.53300","2.55892","117.81246"
"153.73300","2.56225","117.82600"
"153.93300","2.56559","117.82936"
"154.13300","2.56892","117.82755"
"154.33300","2.57225","117.82386"
"154.53300","2.57559","117.83187"
"154.73300","2.57892","117.83396"
"154.93300","2.58225","117.81807"
"155.13300","2.58559","117.83401"
"155.33300","2.58892","117.82566"
"155.53300","2.59226","117.83293"
"155.73300","2.59559","117.84903"
"155.93300","2.59892","117.82732"
"156.13300","2.60225","117.83832"
"156.33300","2.60559","117.82986"
"156.53300","2.60892","117.83572"
"156.73300","2.61225","117.82913"
"156.93300","2.61559","117.85140"
"157.13300","2.61891","117.84635"
"157.33300","2.62226","117.86695"
"157.53300","2.62559","117.85075"
"157.73300","2.62892","117.84614"
"157.93300","2.63225","117.85141"
"158.13300","2.63559","117.86099"
"158.33300","2.63892","117.85476"
"158.53300","2.64226","117.86390"
"158.73300","2.64558","117.85066"
"158.93300","2.64892","117.86114"
"159.13300","2.65225","117.85827"
"159.33300","2.65559","117.87452"
"159.53300","2.65892","117.86420"
"159.73300","2.66226","117.87921"
"159.93300","2.66558","117.87047"
"160.13300","2.66893","117.88507"
"160.33300","2.67225","117.88743"
"160.53300","2.67559","117.88941"
"160.73300","2.67891","117.88229"
"160.93300","2.68225","117.89977"
"161.13300","2.68558","117.88056"
"161.33300","2.68893","117.89749"
"161.53300","2.69225","117.88765"
"161.73300","2.69558","117.89704"
"161.93300","2.69892","117.89699"
"162.13300","2.70226","117.91089"
"162.33300","2.70558","117.90011"
"162.53300","2.70893","117.91537"
"162.73300","2.71225","117.89846"
"162.93300","2.71559","117.92436"
"163.13300","2.71892","117.92143"
"163.33300","2.72225","117.93740"
"163.53300","2.72558","117.92309"
"163.73300","2.72892","117.94002"
"163.93300","2.73225","117.93155"
"164.13300","2.73559","117.94432"
"164.33300","2.73892","117.92943"
"164.53300","2.74225","117.94673"
"164.73300","2.74558","117.94999"
"164.93300","2.74892","117.95152"
"165.13300","2.75225","117.94052"
"165.33300","2.75559","117.96431"
"165.53300","2.75892","117.95258"
"165.73300","2.76225","117.96353"
"165.93300","2.76559","117.95873"
"166.13300","2.76892","117.97117"
"166.33300","2.77225","117.96246"
"166.53300","2.77559","117.99358"
"166.73300","2.77891","117.97516"
"166.93300","2.78226","117.99236"
"167.13300","2.78559","117.99509"
"167.33300","2.78892","118.00541"
"167.53300","2.79225","118.01653"
"167.73300","2.79559","118.01736"
"167.93300","2.79892","118.02153"
"168.13300","2.80226","118.05641"
"168.33300","2.80558","118.04818"
"168.53300","2.80892","118.07265"
"168.73300","2.81225","118.07349"
"168.93300","2.81558","118.07160"
"169.13300","2.81892","118.08452"
"169.33300","2.82226","118.10180"
"169.53300","2.82558","118.10869"
"169.73300","2.82892","118.10162"
"169.93300","2.83225","118.11607"
"170.13300","2.83559","118.12300"
"170.33300","2.83892","118.13230"
"170.53300","2.84226","118.14088"
"170.73300","2.84558","118.13561"
"170.93300","2.84893","118.15666"
"171.13300","2.85225","118.15855"
"171.33300","2.85559","118.16035"
"171.53300","2.85892","118.17219"
"171.73300","2.86226","118.19835"
"171.93300","2.86559","118.20742"
"172.13300","2.86892","118.20222"
"172.33300","2.87225","118.21084"
"172.53300","2.87559","118.21810"
"172.73300","2.87891","118.23649"
"172.93300","2.88226","118.24192"
"173.13300","2.88558","118.24499"
"173.33300","2.88892","118.26942"
"173.53300","2.89225","118.25596"
"173.73300","2.89559","118.27792"
"173.93300","2.89893","118.28328"
"174.13300","2.90225","118.28258"
"174.33300","2.90559","118.30683"
"174.53300","2.90892","118.30080"
"174.73300","2.91225","118.31982"
"174.93300","2.91559","118.34446"
"175.13300","2.91892","118.34884"
"175.33300","2.92225","118.36559"
"175.53300","2.92559","118.36737"
"175.73300","2.92892","118.37213"
"175.93300","2.93226","118.38577"
"176.13300","2.93558","118.38503"
"176.33300","2.93892","118.39379"
"176.53300","2.94226","118.40339"
"176.73300","2.94559","118.41201"
"176.93300","2.94892","118.39281"
"177.13300","2.95225","118.40918"
"177.33300","2.95558","118.42345"
"177.53300","2.95892","118.41300"
"177.73300","2.96226","118.43116"
"177.93300","2.96559","118.43701"
"178.13300","2.96892","118.42937"
"178.33300","2.97225","118.44022"
"178.53300","2.97559","118.43422"
"178.73300","2.97892","118.44276"
"178.93300","2.98226","118.46431"
"179.13300","2.98558","118.47559"
"179.33300","2.98892","118.49578"
"179.53300","2.99225","118.50162"
"179.73300","2.99559","118.50206"
"179.93300","2.99893","118.53451"
"180.13300","3.00225","118.53863"
"180.33300","3.00558","118.54705"
"180.53300","3.00893","118.58177"
"180.73300","3.01225","118.59984"
"180.93300","3.01559","118.61117"
"181.13300","3.01892","118.64557"
"181.33300","3.02225","118.65132"
"181.53300","3.02559","118.67944"
"181.73300","3.02892","118.69410"
"181.93300","3.03225","118.70825"
"182.13300","3.03559","118.71587"
"182.33300","3.03892","118.73889"
"182.53300","3.04225","118.75070"
"182.73300","3.04559","118.78141"
"182.93300","3.04891","118.80581"
"183.13300","3.05226","118.83281"
"183.33300","3.05558","118.83206"
"183.53300","3.05892","118.84298"
"183.73300","3.06225","118.86071"
"183.93300","3.06559","118.89030"
"184.13300","3.06892","118.89406"
"184.33300","3.07226","118.92371"
"184.53300","3.07558","118.93325"
"184.73300","3.07892","118.94924"
"184.93300","3.08225","118.96067"
"185.13300","3.08558","118.96687"
"185.33300","3.08891","118.97664"
"185.53300","3.09226","118.99358"
"185.73300","3.09558","118.99139"
"185.93300","3.09892","119.01176"
"186.13300","3.10225","119.02982"
"186.33300","3.10559","119.04703"
"186.53300","3.10891","119.04369"
"186.73300","3.11225","119.04660"
"186.93300","3.11558","119.05548"
"187.13300","3.11892","119.07339"
"187.33300","3.12225","119.07252"
"187.53300","3.12559","119.09461"
"187.73300","3.12892","119.09579"
"187.93300","3.13225","119.11666"
"188.13300","3.13558","119.11618"
"188.33300","3.13893","119.14087"
"188.53300","3.14225","119.13140"
"188.73300","3.14559","119.16146"
"188.93300","3.14892","119.15388"
"189.13300","3.15226","119.17238"
"189.33300","3.15558","119.16041"
"189.53300","3.15893","119.18947"
"189.73300","3.16225","119.19050"
"189.93300","3.16559","119.20005"
"190.13300","3.16892","119.20419"
"190.33300","3.17225","119.21017"
"190.53300","3.17558","119.20650"
"190.73300","3.17892","119.22846"
"190.93300","3.18224","119.21338"
"191.13300","3.18559","119.25186"
"191.33300","3.18892","119.23917"
"191.53300","3.19226","119.24809"
"191.73300","3.19559","119.26134"
"191.93300","3.19892","119.26837"
"192.13300","3.20225","119.27262"
"192.33300","3.20559","119.29535"
"192.53300","3.20892","119.29503"
"192.73300","3.21225","119.30147"
"192.93300","3.21558","119.30953"
"193.13300","3.21892","119.32863"
"193.33300","3.22225","119.32543"
"193.53300","3.22560","119.35153"
"193.73300","3.22891","119.33693"
"193.93300","3.23226","119.35703"
"194.13300","3.23559","119.35700"
"194.33300","3.23892","119.36050"
"194.53300","3.24225","119.36056"
"194.73300","3.24559","119.36654"
"194.93300","3.24892","119.36905"
"195.13300","3.25226","119.38111"
"195.33300","3.25559","119.38943"
"195.53300","3.25892","119.38832"
"195.73300","3.26225","119.38443"
"195.93300","3.26559","119.41225"
"196.13300","3.26892","119.40165"
"196.33300","3.27226","119.40780"
"196.53300","3.27559","119.40571"
"196.73300","3.27892","119.41024"
"196.93300","3.28226","119.42014"
"197.13300","3.28559","119.41218"
"197.33300","3.28892","119.43032"
"197.53300","3.29225","119.42217"
"197.73300","3.29558","119.41953"
"197.93300","3.29892","119.42490"
"198.13300","3.30226","119.42785"
"198.33300","3.30559","119.42318"
"198.53300","3.30892","119.42663"
"198.73300","3.31226","119.43667"
"198.93300","3.31559","119.42679"
"199.13300","3.31892","119.44334"
"199.33300","3.32225","119.43088"
"199.53300","3.32558","119.43991"
"199.73300","3.32893","119.45172"
"199.93300","3.33225","119.44386"
"200.13300","3.33559","119.43318"
"200.33300","3.33892","119.43887"
"200.53300","3.34225","119.45518"
"200.73300","3.34559","119.45418"
"200.93300","3.34893","119.46299"
"201.13300","3.35225","119.45720"
"201.33300","3.35559","119.46183"
"201.53300","3.35892","119.46277"
"201.73300","3.36225","119.46310"
"201.93300","3.36558","119.45851"
"202.13300","3.36892","119.47631"
"202.33300","3.37225","119.47040"
"202.53300","3.37559","119.49430"
"202.73300","3.37892","119.48537"
"202.93300","3.38226","119.49740"
"203.13300","3.38559","119.50115"
"203.33300","3.38892","119.50307"
"203.53300","3.39225","119.50283"
"203.73300","3.39559","119.51752"
"203.93300","3.39892","119.51339"
"204.13300","3.40225","119.51639"
"204.33300","3.40559","119.52560"
"204.53300","3.40892","119.53099"
"204.73300","3.41225","119.53431"
"204.93300","3.41559","119.54977"
"205.13300","3.41892","119.53896"
"205.33300","3.42225","119.55880"
"205.53300","3.42558","119.55599"
"205.73300","3.42893","119.57132"
"205.93300","3.43225","119.57469"
"206.13300","3.43559","119.57793"
"206.33300","3.43892","119.57657"
"206.53300","3.44225","119.58637"
"206.73300","3.44559","119.58505"
"206.93300","3.44892","119.60138"
"207.13300","3.45225","119.59873"
"207.33300","3.45559","119.61879"
"207.53300","3.45891","119.60869"
"207.73300","3.46226","119.62751"
"207.93300","3.46558","119.61898"
"208.13300","3.46893","119.64102"
"208.33300","3.47224","119.63177"
"208.53300","3.47559","119.64803"
"208.73300","3.47892","119.64390"
"208.93300","3.48226","119.65941"
"209.13300","3.48558","119.65613"
"209.33300","3.48892","119.66982"
"209.53300","3.49224","119.66485"
"209.73300","3.49559","119.68629"
"209.93300","3.49892","119.68789"
"210.13300","3.50225","119.69838"
"210.33300","3.50558","119.71081"
"210.53300","3.50892","119.72727"
"210.73300","3.51225","119.73556"
"210.93300","3.51559","119.74562"
"211.13300","3.51891","119.74141"
"211.33300","3.52226","119.75668"
"211.53300","3.52558","119.75488"
"211.73300","3.52892","119.78212"
"211.93300","3.53225","119.77515"
"212.13300","3.53559","119.78711"
"212.33300","3.53891","119.78568"
"212.53300","3.54226","119.79366"
"212.73300","3.54559","119.79912"
"212.93300","3.54892","119.79135"
"213.13300","3.55225","119.79873"
"213.33300","3.55559","119.81384"
"213.53300","3.55892","119.80150"
"213.73300","3.56226","119.82089"
"213.93300","3.56558","119.81625"
"214.13300","3.56892","119.82744"
"214.33300","3.57225","119.82078"
"214.53300","3.57558","119.82191"
"214.73300","3.57892","119.81319"
"214.93300","3.58226","119.83138"
"215.13300","3.58558","119.81031"
"215.33300","3.58892","119.81993"
"215.53300","3.59225","119.82381"
"215.73300","3.59559","119.81580"
"215.93300","3.59891","119.80473"
"216.13300","3.60226","119.82026"
"216.33300","3.60558","119.81914"
"216.53300","3.60893","119.83139"
"216.73300","3.61225","119.82591"
"216.93300","3.61559","119.84079"
"217.13300","3.61892","119.82494"
"217.33300","3.62225","119.83346"
"217.53300","3.62559","119.84282"
"217.73300","3.62893","119.83055"
"217.93300","3.63225","119.83181"
"218.13300","3.63559","119.83568"
"218.33300","3.63892","119.83873"
"218.53300","3.64226","119.85257"
"218.73300","3.64558","119.85315"
"218.93300","3.64893","119.86635"
"219.13300","3.65224","119.86151"
"219.33300","3.65559","119.87505"
"219.53300","3.65892","119.88191"
"219.73300","3.66225","119.88138"
"219.93300","3.66559","119.88470"
"220.13300","3.66892","119.89585"
"220.33300","3.67225","119.89065"
"220.53300","3.67559","119.89780"
"220.73300","3.67892","119.89614"
"220.93300","3.68225","119.89136"
"221.13300","3.68559","119.90437"
"221.33300","3.68892","119.91144"
"221.53300","3.69225","119.89622"
"221.73300","3.69559","119.91883"
"221.93300","3.69892","119.90867"
"222.13300","3.70225","119.90944"
"222.33300","3.70559","119.91144"
"222.53300","3.70892","119.91189"
"222.73300","3.71226","119.91744"
"222.93300","3.71558","119.90732"
"223.13300","3.71892","119.89611"
"223.33300","3.72226","119.90050"
"223.53300","3.72559","119.89655"
"223.73300","3.72892","119.89455"
"223.93300","3.73226","119.89444"
"224.13300","3.73558","119.89618"
"224.33300","3.73892","119.86572"
"224.53300","3.74226","119.88354"
"224.73300","3.74558","119.87833"
"224.93300","3.74892","119.86958"
"225.13300","3.75226","119.88330"
"225.33300","3.75559","119.86813"
"225.53300","3.75892","119.85694"
"225.73300","3.76225","119.84898"
"225.93300","3.76559","119.84676"
"226.13300","3.76892","119.84645"
"226.33300","3.77226","119.82932"
"226.53300","3.77558","119.81656"
"226.73300","3.77892","119.81672"
"226.93300","3.78225","119.80487"
"227.13300","3.78558","119.79083"
"227.33300","3.78893","119.78950"
"227.53300","3.79225","119.78968"
"227.73300","3.79559","119.76689"
"227.93300","3.79893","119.76944"
"228.13300","3.80225","119.74740"
"228.33300","3.80559","119.74161"
"228.53300","3.80892","119.73077"
"228.73300","3.81225","119.72321"
"228.93300","3.81559","119.71366"
"229.13300","3.81892","119.71753"
"229.33300","3.82225","119.70819"
"229.53300","3.82559","119.71134"
"229.73300","3.82892","119.69618"
"229.93300","3.83225","119.69445"
"230.13300","3.83559","119.67554"
"230.33300","3.83893","119.67659"
"230.53300","3.84224","119.66994"
"230.73300","3.84559","119.67281"
"230.93300","3.84892","119.65762"
"231.13300","3.85226","119.66720"
"231.33300","3.85558","119.66569"
"231.53300","3.85892","119.66547"
"231.73300","3.86225","119.64766"
"231.93300","3.86559","119.65366"
"232.13300","3.86891","119.63056"
"232.33300","3.87226","119.64990"
"232.53300","3.87558","119.63033"
"232.73300","3.87892","119.64201"
"232.93300","3.88225","119.62995"
"233.13300","3.88559","119.63098"
"233.33300","3.88891","119.61875"
"233.53300","3.89226","119.64131"
"233.73300","3.89558","119.61856"
"233.93300","3.89892","119.61860"
"234.13300","3.90225","119.61525"
"234.33300","3.90559","119.61249"
"234.53300","3.90891","119.59905"
"234.73300","3.91225","119.62207"
"234.93300","3.91558","119.60687"
"235.13300","3.91892","119.60364"
"235.33300","3.92225","119.59553"
"235.53300","3.92558","119.59523"
"235.73300","3.92892","119.58410"
"235.93300","3.93226","119.58806"
"236.13300","3.93558","119.56736"
"236.33300","3.93893","119.58169"
"236.53300","3.94225","119.55194"
"236.73300","3.94559","119.55543"
"236.93300","3.94892","119.53925"
"237.13300","3.95226","119.54787"
"237.33300","3.95558","119.52048"
"237.53300","3.95892","119.53622"
"237.73300","3.96225","119.51745"
"237.93300","3.96559","119.51516"
"238.13300","3.96892","119.50411"
"238.33300","3.97225","119.49728"
"238.53300","3.97559","119.48128"
"238.73300","3.97892","119.47539"
"238.93300","3.98225","119.43796"
"239.13300","3.98559","119.45062"
"239.33300","3.98892","119.41716"
"239.53300","3.99226","119.42394"
"239.73300","3.99559","119.40421"
"239.93300","3.99893","119.40545"
"240.13300","4.00225","119.36949"
"240.33300","4.00559","119.38638"
"240.53300","4.00892","119.35995"
"240.73300","4.01226","119.35938"
"240.93300","4.01558","119.33546"
"241.13300","4.01892","119.32380"
"241.33300","4.02225","119.30537"
"241.53300","4.02559","119.29933"
"241.73300","4.02892","119.28162"
"241.93300","4.03226","119.28012"
"242.13300","4.03558","119.24954"
"242.33300","4.03892","119.25093"
"242.53300","4.04225","119.23574"
"242.73300","4.04559","119.23737"
"242.93300","4.04892","119.20776"
"243.13300","4.05226","119.19697"
"243.33300","4.05558","119.19205"
"243.53300","4.05892","119.15308"
"243.73300","4.06225","119.14605"
"243.93300","4.06559","119.11808"
"244.13300","4.06892","119.08863"
"244.33300","4.07225","119.07875"
"244.53300","4.07559","119.05534"
"244.73300","4.07892","119.02201"
"244.93300","4.08226","118.99196"
"245.13300","4.08558","118.96749"
"245.33300","4.08892","118.94058"
"245.53300","4.09226","118.91271"
"245.73300","4.09559","118.88075"
"245.93300","4.09892","118.85271"
"246.13300","4.10225","118.81259"
"246.33300","4.10558","118.77771"
"246.53300","4.10892","118.73388"
"246.73300","4.11225","118.70346"
"246.93300","4.11559","118.66641"
"247.13300","4.11892","118.61990"
"247.33300","4.12225","118.55976"
"247.53300","4.12559","118.51619"
"247.73300","4.12892","118.47974"
"247.93300","4.13225","118.40966"
"248.13300","4.13559","118.35926"
"248.33300","4.13891","118.28465"
"248.53300","4.14226","118.21087"
"248.73300","4.14559","118.12972"
"248.93300","4.14892","118.05575"
"249.13300","4.15226","117.95906"
"249.33300","4.15559","117.85351"
"249.53300","4.15892","117.75306"
"249.73300","4.16226","117.63655"
"249.93300","4.16559","117.51146"
"250.13300","4.16891","117.39203"
"250.33300","4.17225","117.25738"
"250.53300","4.17559","117.13343"
"250.73300","4.17892","116.96908"
"250.93300","4.18225","116.81791"
"251.13300","4.18559","116.61477"
"251.33300","4.18891","116.43919"
"251.53300","4.19226","116.22468"
"251.73300","4.19559","116.00039"
"251.93300","4.19892","115.73236"
"252.13300","4.20225","115.46562"
"252.33300","4.20559","115.14856"
"252.53300","4.20892","114.79061"
"252.73300","4.21225","114.37468"
"252.93300","4.21558","113.94569"
"253.13300","4.21892","113.46758"
"253.33300","4.22226","112.96771"
"253.53300","4.22559","112.40849"
"253.73300","4.22892","111.80458"
"253.93300","4.23225","111.14491"
"254.13300","4.23558","110.45707"
"254.33300","4.23892","109.73907"
"254.53300","4.24226","109.00800"
"254.73300","4.24558","108.19089"
"254.93300","4.24892","107.33788"
"255.13300","4.25225","106.43169"
"255.33300","4.25559","105.51602"
"255.53300","4.25892","104.53339"
"255.73300","4.26225","103.46223"
"255.93300","4.26558","102.33554"
"256.13300","4.26892","101.13364"
"256.33300","4.27225","99.88257"
"256.53300","4.27559","98.58796"
"256.73300","4.27892","97.14123"
"256.93300","4.28225","95.62580"
"257.13300","4.28558","93.98841"
"257.33300","4.28893","92.31166"
"257.53300","4.29224","90.45502"
"257.73300","4.29558","88.45505"
"257.93300","4.29892","86.29208"
"258.13300","4.30225","83.96759"
"258.33300","4.30559","81.40377"
"258.53300","4.30892","78.56091"
"258.73300","4.31225","75.30556"
"258.93300","4.31559","71.50458"
"259.13300","4.31891","66.86424"
"259.33300","4.32226","60.64508"
"259.51100","4.32522","50.34370"
"259.54200","4.32574","38.54585"
"259.55200","4.32591","24.97785"
"259.56300","4.32610","12.08703"
"259.56600","4.32615","9.33414"