File: materials_lab1/ENGR314_FA19_0001_1080 Spring Steel_B_20190903_JAZ_1.is_tens_RawData/Specimen_RawData_2.csv
Material,Acrylic
Geometry,Circular
Length,"2.00000",in
Diameter,"0.062700",in

Time,Extension,Load
(s),(in),(lbf)
"0.00000","0.24779","8.02665"
"0.10000","0.24786","8.17856"
"0.20000","0.24804","9.55771"
"0.30000","0.24820","10.82310"
"0.40000","0.24832","11.81091"
"0.50000","0.24847","12.95863"
"0.60000","0.24858","13.94611"
"0.70000","0.24872","14.88882"
"0.80000","0.24887","16.20351"
"0.90000","0.24899","17.15586"
"1.00000","0.24912","18.23105"
"1.10000","0.24925","19.25684"
"1.20000","0.24940","20.36844"
"1.30000","0.24952","21.52189"
"1.40000","0.24966","22.55810"
"1.50000","0.24980","23.80793"
"1.60000","0.24991","24.69042"
"1.70000","0.25007","25.97429"
"1.80000","0.25020","27.19875"
"1.90000","0.25032","28.19801"
"2.00000","0.25045","29.41156"
"2.10000","0.25058","30.46999"
"2.20000","0.25073","31.82603"
"2.30000","0.25085","32.94480"
"2.40000","0.25100","34.22453"
"2.50000","0.25112","35.41941"
"2.60000","0.25124","36.48338"
"2.70000","0.25141","38.04334"
"2.80000","0.25152","39.16451"
"2.90000","0.25166","40.38735"
"3.00000","0.25178","41.64516"
"3.10000","0.25192","42.93205"
"3.20000","0.25206","44.41638"
"3.30000","0.25219","45.58524"
"3.40000","0.25233","47.07938"
"3.50000","0.25244","48.23692"
"3.60000","0.25259","49.59339"
"3.70000","0.25273","51.24931"
"3.80000","0.25285","52.35901"
"3.90000","0.25299","53.82100"
"4.00000","0.25311","55.06627"
"4.10000","0.25327","56.64975"
"4.20000","0.25339","58.03871"
"4.30000","0.25353","59.38027"
"4.40000","0.25366","60.76197"
"4.50000","0.25377","61.86554"
"4.60000","0.25394","63.61856"
"4.70000","0.25406","65.06747"
"4.80000","0.25419","66.35740"
"4.90000","0.25432","67.88870"
"5.00000","0.25445","69.22030"
"5.10000","0.25460","70.95252"
"5.20000","0.25472","72.20934"
"5.30000","0.25487","73.85567"
"5.40000","0.25498","75.21284"
"5.50000","0.25512","76.51364"
"5.60000","0.25527","78.46299"
"5.70000","0.25539","79.65792"
"5.80000","0.25553","81.23089"
"5.90000","0.25565","82.63385"
"6.00000","0.25580","84.26087"
"6.10000","0.25593","85.85417"
"6.20000","0.25606","87.23622"
"6.30000","0.25620","88.94078"
"6.40000","0.25631","90.09763"
"6.50000","0.25647","91.85932"
"6.60000","0.25660","93.50016"
"6.70000","0.25672","94.77778"
"6.80000","0.25686","96.44725"
"6.90000","0.25699","97.76292"
"7.00000","0.25713","99.59492"
"7.10000","0.25725","100.91336"
"7.20000","0.25740","102.48213"
"7.30000","0.25752","103.97533"
"7.40000","0.25764","105.17817"
"7.50000","0.25781","107.18242"
"7.60000","0.25792","108.42223"
"7.70000","0.25806","109.89453"
"7.80000","0.25818","111.33832"
"7.90000","0.25833","112.79644"
"8.00000","0.25846","114.40325"
"8.10000","0.25859","115.61676"
"8.20000","0.25873","117.16230"
"8.30000","0.25884","118.21420"
"8.40000","0.25899","119.59881"
"8.50000","0.25914","121.28015"
"8.60000","0.25925","122.12916"
"8.70000","0.25939","123.34983"
"8.80000","0.25951","124.12002"
"8.90000","0.25967","125.28726"
"9.00000","0.25979","126.02465"
"9.10000","0.25993","126.60620"
"9.20000","0.26006","127.10635"
"9.30000","0.26018","126.93758"
"9.40000","0.26034","127.38336"
"9.50000","0.26046","127.60481"
"9.60000","0.26059","128.23397"
"9.70000","0.26072","129.25886"
"9.80000","0.26085","130.23721"
"9.90000","0.26100","131.63314"
"10.00000","0.26112","132.45443"
"10.10000","0.26127","133.65891"
"10.20000","0.26138","134.53618"
"10.30000","0.26152","135.48724"
"10.40000","0.26167","137.07656"
"10.50000","0.26179","138.01180"
"10.60000","0.26192","139.28966"
"10.70000","0.26204","140.47092"
"10.80000","0.26220","141.95429"
"10.90000","0.26233","143.26078"
"11.00000","0.26246","144.32808"
"11.10000","0.26260","145.78118"
"11.20000","0.26271","146.65340"
"11.30000","0.26286","148.17326"
"11.40000","0.26300","149.58307"
"11.50000","0.26312","150.52659"
"11.60000","0.26325","151.91621"
"11.70000","0.26338","152.98235"
"11.80000","0.26353","154.66145"
"11.90000","0.26365","155.79354"
"12.00000","0.26380","157.23270"
"12.10000","0.26392","158.61255"
"12.20000","0.26404","159.70627"
"12.30000","0.26421","161.64883"
"12.40000","0.26432","162.88046"
"12.50000","0.26446","164.32893"
"12.60000","0.26458","165.72840"
"12.70000","0.26473","167.26768"
"12.80000","0.26486","168.99760"
"12.90000","0.26499","170.22732"
"13.00000","0.26514","172.05103"
"13.10000","0.26525","173.19796"
"13.20000","0.26539","174.75628"
"13.30000","0.26553","176.67638"
"13.40000","0.26565","177.95827"
"13.50000","0.26579","179.62841"
"13.60000","0.26591","181.01225"
"13.70000","0.26606","182.86015"
"13.80000","0.26619","184.41640"
"13.90000","0.26633","185.95949"
"14.00000","0.26646","187.76221"
"14.10000","0.26658","188.95843"
"14.20000","0.26674","190.99361"
"14.30000","0.26686","192.70671"
"14.40000","0.26699","194.15612"
"14.50000","0.26712","195.85912"
"14.60000","0.26725","197.36776"
"14.70000","0.26740","199.46032"
"14.80000","0.26752","200.86222"
"14.90000","0.26767","202.76256"
"15.00000","0.26778","204.24818"
"15.10000","0.26791","205.65364"
"15.20000","0.26807","207.92829"
"15.30000","0.26819","209.32231"
"15.40000","0.26832","211.04860"
"15.50000","0.26845","212.66198"
"15.60000","0.26859","214.40632"
"15.70000","0.26873","216.35956"
"15.80000","0.26885","217.80521"
"15.90000","0.26900","219.88092"
"16.00000","0.26911","221.16822"
"16.10000","0.26926","223.06021"
"16.20000","0.26940","225.08312"
"16.30000","0.26952","226.48857"
"16.40000","0.26965","228.27313"
"16.50000","0.26978","229.83192"
"16.60000","0.26993","231.90986"
"16.70000","0.27005","233.50229"
"16.80000","0.27020","235.27283"
"16.90000","0.27032","237.04391"
"17.00000","0.27044","238.33879"
"17.10000","0.27061","240.70364"
"17.20000","0.27072","242.16273"
"17.30000","0.27085","243.72830"
"17.40000","0.27098","245.46596"
"17.50000","0.27112","247.16199"
"17.60000","0.27126","249.14970"
"17.70000","0.27139","250.53687"
"17.80000","0.27154","252.58383"
"17.90000","0.27164","253.93655"
"18.00000","0.27179","255.59682"
"18.10000","0.27194","257.84058"
"18.20000","0.27205","259.09805"
"18.30000","0.27219","260.80253"
"18.40000","0.27231","262.36963"
"18.50000","0.27246","264.27966"
"18.60000","0.27259","265.94811"
"18.70000","0.27273","267.45560"
"18.80000","0.27286","269.38094"
"18.90000","0.27297","270.49530"
"19.00000","0.27314","272.58195"
"19.10000","0.27326","274.20371"
"19.20000","0.27339","275.62035"
"19.30000","0.27352","277.32557"
"19.40000","0.27365","278.81905"
"19.50000","0.27380","280.69944"
"19.60000","0.27391","282.06171"
"19.70000","0.27407","283.94374"
"19.80000","0.27419","285.44004"
"19.90000","0.27432","286.73184"
"20.00000","0.27447","288.99176"
"20.10000","0.27459","290.25878"
"20.20000","0.27472","291.84869"
"20.30000","0.27485","293.38017"
"20.40000","0.27500","295.04821"
"20.50000","0.27513","296.83373"
"20.60000","0.27525","298.17800"
"20.70000","0.27540","300.12400"
"20.80000","0.27551","301.23449"
"20.90000","0.27566","303.00269"
"21.00000","0.27580","304.87743"
"21.10000","0.27592","306.15356"
"21.20000","0.27605","307.81416"
"21.30000","0.27618","309.10755"
"21.40000","0.27633","311.03788"
"21.50000","0.27645","312.44085"
"21.60000","0.27660","314.16781"
"21.70000","0.27672","315.74619"
"21.80000","0.27684","316.86434"
"21.90000","0.27701","319.07033"
"22.00000","0.27712","320.42514"
"22.10000","0.27726","321.77125"
"22.20000","0.27738","323.22035"
"22.30000","0.27752","324.57162"
"22.40000","0.27766","326.43181"
"22.50000","0.27779","327.55719"
"22.60000","0.27794","329.33201"
"22.70000","0.27804","330.39069"
"22.80000","0.27819","331.83718"
"22.90000","0.27834","333.79443"
"23.00000","0.27845","334.79521"
"23.10000","0.27859","336.24755"
"23.20000","0.27871","337.48992"
"23.30000","0.27886","339.09816"
"23.40000","0.27899","340.51131"
"23.50000","0.27913","341.73805"
"23.60000","0.27926","343.30370"
"23.70000","0.27938","344.23161"
"23.80000","0.27954","345.93738"
"23.90000","0.27966","347.36862"
"24.00000","0.27979","348.36335"
"24.10000","0.27992","349.75702"
"24.20000","0.28005","350.86496"
"24.30000","0.28020","352.52402"
"24.40000","0.28032","353.51461"
"24.50000","0.28047","354.91146"
"24.60000","0.28058","355.99893"
"24.70000","0.28071","356.90554"
"24.80000","0.28087","358.76576"
"24.90000","0.28099","359.51250"
"25.00000","0.28113","360.65666"
"25.10000","0.28124","361.66018"
"25.20000","0.28140","362.79539"
"25.30000","0.28153","363.94682"
"25.40000","0.28165","364.54040"
"25.50000","0.28180","365.71892"
"25.60000","0.28191","366.00273"
"25.70000","0.28206","366.71813"
"25.80000","0.28220","367.34503"
"25.90000","0.28232","367.06451"
"26.00000","0.28246","367.06747"
"26.10000","0.28258","365.88517"
"26.20000","0.28273","363.89943"
"26.27900","0.28283","358.26129"
"26.28900","0.28285","351.46337"
"26.29400","0.28286","344.51397"
"26.29800","0.28286","338.40554"
"26.30200","0.28287","332.31221"
"26.30600","0.28288","326.56295"
"26.31100","0.28288","320.16276"
"26.31700","0.28290","313.89163"
"26.32500","0.28291","308.01498"
"26.42500","0.28303","307.23872"
"26.52500","0.28315","309.79219"
"26.62500","0.28328","312.44708"
"26.72500","0.28344","316.08777"
"26.82500","0.28355","318.55271"
"26.92500","0.28370","321.50928"
"27.02500","0.28382","324.20896"
"27.12500","0.28396","327.16210"
"27.22500","0.28409","330.11654"
"27.32500","0.28422","332.68203"
"27.42500","0.28436","335.74077"
"27.52500","0.28447","338.00066"
"27.62500","0.28463","340.98140"
"27.72500","0.28476","343.96240"
"27.82500","0.28489","346.21787"
"27.92500","0.28503","349.04096"
"28.02500","0.28515","351.32286"
"28.12500","0.28530","354.20948"
"28.22500","0.28542","356.52536"
"28.32500","0.28556","358.93662"
"28.42500","0.28569","361.30691"
"28.52500","0.28581","363.16320"
"28.62500","0.28597","366.07378"
"28.72500","0.28609","368.09462"
"28.82500","0.28623","370.14828"
"28.92500","0.28635","372.19365"
"29.02500","0.28649","374.12475"
"29.12500","0.28663","376.43318"
"29.22500","0.28675","378.04979"
"29.32500","0.28690","380.14989"
"29.42500","0.28701","381.67786"
"29.52500","0.28716","383.46996"
"29.62500","0.28730","385.66204"
"29.72500","0.28742","387.09926"
"29.82500","0.28756","388.95089"
"29.92500","0.28768","390.45800"
"30.02500","0.28783","392.47939"
"30.12500","0.28796","394.18392"
"30.22500","0.28809","395.71900"
"30.32500","0.28823","397.64217"
"30.42500","0.28834","398.86973"
"30.52500","0.28850","400.93955"
"30.62500","0.28863","402.65841"
"30.72500","0.28875","404.08422"
"30.82500","0.28889","405.82498"
"30.92500","0.28902","407.30580"
"31.02500","0.28917","409.38081"
"31.12500","0.28929","410.78685"
"31.22500","0.28944","412.60368"
"31.32500","0.28955","414.07043"
"31.42500","0.28968","415.51813"
"31.52500","0.28984","417.73093"
"31.62500","0.28995","418.93220"
"31.72500","0.29009","420.66327"
"31.82500","0.29022","422.16920"
"31.92500","0.29036","423.91532"
"32.02500","0.29050","425.62718"
"32.12500","0.29062","427.01256"
"32.22500","0.29076","428.81482"
"32.32500","0.29088","429.97533"
"32.42500","0.29103","431.69894"
"32.52500","0.29116","433.55312"
"32.62500","0.29129","434.83913"
"32.72500","0.29142","436.44372"
"32.82500","0.29155","437.81906"
"32.92500","0.29170","439.81212"
"33.02500","0.29182","441.17969"
"33.12500","0.29197","442.80805"
"33.22500","0.29209","444.48939"
"33.32500","0.29221","445.65721"
"33.42500","0.29237","447.68716"
"33.52500","0.29249","449.11631"
"33.62500","0.29263","450.60416"
"33.72500","0.29275","452.15098"
"33.82500","0.29289","453.60670"
"33.92500","0.29303","455.47759"
"34.02500","0.29315","456.64348"
"34.12500","0.29330","458.58155"
"34.22500","0.29341","459.78441"
"34.32500","0.29355","461.22811"
"34.42500","0.29370","463.37757"
"34.52500","0.29382","464.51945"
"34.62500","0.29396","466.14103"
"34.72500","0.29408","467.46436"
"34.82500","0.29423","469.33495"
"34.92500","0.29436","470.91997"
"35.02500","0.29450","472.35050"
"35.12500","0.29463","474.19562"
"35.22500","0.29474","475.23196"
"35.32500","0.29490","477.14322"
"35.42500","0.29503","478.77791"
"35.52500","0.29516","480.10048"
"35.62500","0.29529","481.67776"
"35.72500","0.29542","483.04928"
"35.82500","0.29556","484.90604"
"35.92500","0.29568","486.17636"
"36.02500","0.29583","487.92812"
"36.12500","0.29595","489.31150"
"36.22500","0.29608","490.49668"
"36.32500","0.29624","492.68692"
"36.42500","0.29635","493.83007"
"36.52500","0.29649","495.30839"
"36.62500","0.29661","496.65088"
"36.72500","0.29676","498.32125"
"36.82500","0.29690","500.03586"
"36.92500","0.29702","501.23466"
"37.02500","0.29717","503.05870"
"37.12500","0.29728","504.06222"
"37.22500","0.29743","505.71217"
"37.32500","0.29757","507.52777"
"37.42500","0.29769","508.53667"
"37.52500","0.29782","510.04244"
"37.62500","0.29795","511.31088"
"37.72500","0.29810","513.07878"
"37.82500","0.29822","514.26446"
"37.92500","0.29836","515.79054"
"38.02500","0.29849","517.29258"
"38.12500","0.29861","518.19527"
"38.22500","0.29878","520.28820"
"38.32500","0.29889","521.44155"
"38.42500","0.29902","522.65577"
"38.52500","0.29915","524.01670"
"38.62500","0.29929","525.37840"
"38.72500","0.29943","527.12007"
"38.82500","0.29955","528.11722"
"38.92500","0.29971","529.81997"
"39.02500","0.29981","530.88424"
"39.12500","0.29995","532.04177"
"39.22500","0.30011","534.08799"
"39.32500","0.30022","534.93591"
"39.42500","0.30036","536.34497"
"39.52500","0.30048","537.56940"
"39.62500","0.30063","539.01672"
"39.72500","0.30075","540.42358"
"39.82500","0.30089","541.56969"
"39.92500","0.30103","543.30159"
"40.02500","0.30114","544.00197"
"40.12500","0.30130","545.72838"
"40.22500","0.30143","547.10314"
"40.32500","0.30155","548.14651"
"40.42500","0.30169","549.55694"
"40.52500","0.30182","550.63027"
"40.62500","0.30197","552.32956"
"40.72500","0.30209","553.33061"
"40.82500","0.30224","554.77760"
"40.92500","0.30235","556.00236"
"41.02500","0.30248","556.88288"
"41.12500","0.30264","558.85759"
"41.22500","0.30276","559.77499"
"41.32500","0.30289","561.00359"
"41.42500","0.30301","562.16600"
"41.52500","0.30316","563.44762"
"41.62500","0.30329","564.93259"
"41.72500","0.30342","565.91612"
"41.82500","0.30357","567.55186"
"41.92500","0.30368","568.23244"
"42.02500","0.30383","569.62717"
"42.12500","0.30397","571.16961"
"42.22500","0.30409","572.03251"
"42.32500","0.30422","573.32829"
"42.42500","0.30435","574.34629"
"42.52500","0.30450","575.89471"
"42.62500","0.30462","576.97210"
"42.72500","0.30476","578.23989"
"42.82500","0.30489","579.50175"
"42.92500","0.30501","580.19094"
"43.02500","0.30517","581.98497"
"43.12500","0.30529","582.94233"
"43.22500","0.30542","583.92219"
"43.32500","0.30555","585.09036"
"43.42500","0.30569","586.14734"
"43.52500","0.30583","587.65080"
"43.62500","0.30595","588.47155"
"43.72500","0.30610","589.82304"
"43.82500","0.30621","590.64686"
"43.92500","0.30635","591.66663"
"44.02500","0.30651","593.29984"
"44.12500","0.30662","593.91636"
"44.22500","0.30676","595.17702"
"44.32500","0.30688","596.04837"
"44.42500","0.30703","597.44316"
"44.52500","0.30716","598.52994"
"44.62500","0.30730","599.46666"
"44.72500","0.30743","600.69005"
"44.82500","0.30754","601.31568"
"44.92500","0.30771","602.85038"
"45.02500","0.30783","603.99039"
"45.12500","0.30795","604.73282"
"45.22500","0.30809","605.93634"
"45.32500","0.30822","606.80133"
"45.42500","0.30837","608.31319"
"45.52500","0.30849","609.03602"
"45.62500","0.30863","610.27461"
"45.72500","0.30875","611.27862"
"45.82500","0.30888","612.00053"
"45.92500","0.30904","613.73681"
"46.02500","0.30915","614.35065"
"46.12500","0.30929","615.46838"
"46.22500","0.30942","616.45829"
"46.32500","0.30956","617.51224"
"46.42500","0.30970","618.71999"
"46.52500","0.30982","619.51044"
"46.62500","0.30996","620.80232"
"46.72500","0.31007","621.37455"
"46.82500","0.31023","622.63389"
"46.92500","0.31036","623.93154"
"47.02500","0.31049","624.56881"
"47.12500","0.31063","625.77024"
"47.22500","0.31075","626.47491"
"47.32500","0.31090","627.86251"
"47.42500","0.31102","628.60247"
"47.52500","0.31116","629.50813"
"47.62500","0.31129","630.51592"
"47.72500","0.31141","630.99864"
"47.82500","0.31157","632.57965"
"47.92500","0.31169","633.21555"
"48.02500","0.31183","634.10200"
"48.12500","0.31195","635.10881"
"48.22500","0.31209","635.97951"
"48.32500","0.31223","637.23407"
"48.42500","0.31236","637.91387"
"48.52500","0.31250","639.03429"
"48.62500","0.31261","639.70005"
"48.72500","0.31275","640.56136"
"48.82500","0.31290","642.08277"
"48.92500","0.31302","642.56329"
"49.02500","0.31316","643.62970"
"49.12500","0.31328","644.30391"
"49.22500","0.31343","645.49964"
"49.32500","0.31356","646.45129"
"49.42500","0.31369","647.19300"
"49.52500","0.31383","648.37863"
"49.62500","0.31394","648.87259"
"49.72500","0.31410","650.18001"
"49.82500","0.31423","651.14291"
"49.92500","0.31436","651.86893"
"50.02500","0.31449","652.95159"
"50.12500","0.31462","653.66334"
"50.22500","0.31477","655.05846"
"50.32500","0.31489","655.69129"
"50.42500","0.31503","656.67378"
"50.52500","0.31515","657.56627"
"50.62500","0.31528","658.20096"
"50.72500","0.31544","659.70036"
"50.82500","0.31555","660.32605"
"50.92500","0.31569","661.20092"
"51.02500","0.31581","662.02024"
"51.12500","0.31596","663.03062"
"51.22500","0.31610","664.14851"
"51.32500","0.31622","664.78293"
"51.42500","0.31636","665.89161"
"51.52500","0.31648","666.42207"
"51.62500","0.31663","667.42399"
"51.72500","0.31676","668.73514"
"51.82500","0.31689","669.19343"
"51.92500","0.31703","670.29942"
"52.02500","0.31715","670.97632"
"52.12500","0.31731","672.25025"
"52.22500","0.31742","672.91699"
"52.32500","0.31756","673.79762"
"52.42500","0.31769","674.78056"
"52.52500","0.31781","675.20526"
"52.62500","0.31797","676.46273"
"52.72500","0.31809","677.23079"
"52.82500","0.31822","677.93046"
"52.92500","0.31835","678.75352"
"53.02500","0.31849","679.52504"
"53.12500","0.31863","680.71193"
"53.22500","0.31875","681.14058"
"53.32500","0.31891","682.26753"
"53.42500","0.31902","682.84849"
"53.52500","0.31915","683.51446"
"53.62500","0.31930","684.88626"
"53.72500","0.31942","685.37413"
"53.82500","0.31956","686.30624"
"53.92500","0.31968","686.99648"
"54.02500","0.31983","688.00131"
"54.12500","0.31996","688.86438"
"54.22500","0.32009","689.49539"
"54.32500","0.32023","690.60829"
"54.42500","0.32034","690.96598"
"54.52500","0.32050","692.11346"
"54.62500","0.32063","693.13454"
"54.72500","0.32076","693.70293"
"54.82500","0.32089","694.61045"
"54.92500","0.32101","695.23367"
"55.02500","0.32117","696.56584"
"55.12500","0.32129","697.16590"
"55.22500","0.32144","698.14625"
"55.32500","0.32155","698.94148"
"55.42500","0.32168","699.42173"
"55.52500","0.32184","700.92892"
"55.62500","0.32195","701.46301"
"55.72500","0.32209","702.25445"
"55.82500","0.32222","702.99408"
"55.92500","0.32235","703.81104"
"56.02500","0.32250","704.94908"
"56.12500","0.32262","705.41473"
"56.22500","0.32277","706.60765"
"56.32500","0.32288","707.02039"
"56.42500","0.32302","707.87791"
"56.52500","0.32317","709.22177"
"56.62500","0.32329","709.66798"
"56.72500","0.32342","710.55926"
"56.82500","0.32354","711.20828"
"56.92500","0.32370","712.47755"
"57.02500","0.32382","713.19764"
"57.12500","0.32396","714.01488"
"57.22500","0.32409","715.05176"
"57.32500","0.32421","715.35731"
"57.42500","0.32438","716.86972"
"57.52500","0.32449","717.54738"
"57.62500","0.32462","718.22779"
"57.72500","0.32475","719.11753"
"57.82500","0.32489","719.95228"
"57.92500","0.32503","721.23549"
"58.02500","0.32515","721.67885"
"58.12500","0.32531","722.98039"
"58.22500","0.32542","723.60680"
"58.32500","0.32555","724.28007"
"58.42500","0.32571","725.88502"
"58.52500","0.32582","726.24490"
"58.62500","0.32595","727.11170"
"58.72500","0.32608","727.94134"
"58.82500","0.32623","729.00808"
"58.92500","0.32636","730.00864"
"59.02500","0.32649","730.63970"
"59.12500","0.32663","731.95782"
"59.22500","0.32674","732.33444"
"59.32500","0.32690","733.53302"
"59.42500","0.32703","734.61744"
"59.52500","0.32715","735.22145"
"59.62500","0.32729","736.24000"
"59.72500","0.32742","737.02382"
"59.82500","0.32756","738.16817"
"59.92500","0.32768","738.86724"
"60.02500","0.32783","739.99084"
"60.12500","0.32795","740.92724"
"60.22500","0.32808","741.39727"
"60.32500","0.32824","743.01671"
"60.42500","0.32835","743.58515"
"60.52500","0.32849","744.44147"
"60.62500","0.32862","745.36601"
"60.72500","0.32876","746.27529"
"60.82500","0.32890","747.47771"
"60.92500","0.32902","748.02601"
"61.02500","0.32917","749.32859"
"61.12500","0.32928","749.76153"
"61.22500","0.32943","750.69452"
"61.32500","0.32957","752.08431"
"61.42500","0.32969","752.51137"
"61.52500","0.32982","753.48361"
"61.62500","0.32994","754.07658"
"61.72500","0.33010","755.25178"
"61.82500","0.33022","756.05903"
"61.92500","0.33036","756.93209"
"62.02500","0.33049","757.99943"
"62.12500","0.33061","758.35536"
"62.22500","0.33077","759.80471"
"62.32500","0.33089","760.65093"
"62.42500","0.33102","761.31163"
"62.52500","0.33115","762.25752"
"62.62500","0.33128","763.01115"
"62.72500","0.33144","764.35720"
"62.82500","0.33155","764.89645"
"62.92500","0.33171","766.13048"
"63.02500","0.33181","766.71550"
"63.12500","0.33195","767.46451"
"63.22500","0.33211","768.94614"
"63.32500","0.33222","769.41891"
"63.42500","0.33236","770.34153"
"63.52500","0.33248","771.13144"
"63.62500","0.33263","772.15866"
"63.72500","0.33276","773.26180"
"63.82500","0.33289","773.89138"
"63.92500","0.33303","775.12383"
"64.02500","0.33314","775.58266"
"64.12500","0.33330","776.80605"
"64.22500","0.33343","777.95342"
"64.32500","0.33355","778.44914"
"64.42500","0.33369","779.54344"
"64.52500","0.33382","780.22873"
"64.62500","0.33397","781.60437"
"64.72500","0.33409","782.30459"
"64.82500","0.33423","783.23166"
"64.92500","0.33435","784.08407"
"65.02500","0.33448","784.67420"
"65.12500","0.33464","786.30017"
"65.22500","0.33475","786.80154"
"65.32500","0.33489","787.67086"
"65.42500","0.33501","788.56598"
"65.52500","0.33516","789.50940"
"65.62500","0.33530","790.70348"
"65.72500","0.33542","791.24294"
"65.82500","0.33557","792.54482"
"65.92500","0.33568","793.07621"
"66.02500","0.33582","794.00470"
"66.12500","0.33597","795.45301"
"66.22500","0.33608","795.88451"
"66.32500","0.33623","797.04906"
"66.42500","0.33635","797.80796"
"66.52500","0.33650","798.99699"
"66.62500","0.33662","799.85308"
"66.72500","0.33676","800.70319"
"66.82500","0.33689","801.83657"
"66.92500","0.33701","802.23147"
"67.02500","0.33717","803.76462"
"67.12500","0.33729","804.49465"
"67.22500","0.33742","805.30464"
"67.32500","0.33755","806.29510"
"67.42500","0.33769","807.09806"
"67.52500","0.33783","808.39253"
"67.62500","0.33795","809.01876"
"67.72500","0.33810","810.09698"
"67.82500","0.33821","810.89874"
"67.92500","0.33835","811.64512"
"68.02500","0.33851","813.24776"
"68.12500","0.33862","813.66242"
"68.22500","0.33876","814.78526"
"68.32500","0.33888","815.55705"
"68.42500","0.33903","816.74141"
"68.52500","0.33916","817.74910"
"68.62500","0.33929","818.47249"
"68.72500","0.33943","819.61074"
"68.82500","0.33954","820.08748"
"68.92500","0.33970","821.36728"
"69.02500","0.33983","822.48979"
"69.12500","0.33995","823.03705"
"69.22500","0.34009","824.12125"
"69.32500","0.34021","824.80133"
"69.42500","0.34037","826.20726"
"69.52500","0.34049","826.89530"
"69.62500","0.34063","827.81265"
"69.72500","0.34075","828.77346"
"69.82500","0.34088","829.41655"
"69.92500","0.34104","830.87243"
"70.02500","0.34115","831.51283"
"70.12500","0.34129","832.45301"
"70.22500","0.34142","833.34566"
"70.32500","0.34156","834.26515"
"70.42500","0.34170","835.48436"
"70.52500","0.34182","836.08700"
"70.62500","0.34197","837.24908"
"70.72500","0.34208","837.85638"
"70.82500","0.34222","838.80759"
"70.92500","0.34237","840.17577"
"71.02500","0.34248","840.63746"
"71.12500","0.34262","841.68724"
"71.22500","0.34274","842.37391"
"71.32500","0.34290","843.71294"
"71.42500","0.34302","844.49582"
"71.52500","0.34316","845.32683"
"71.62500","0.34329","846.35884"
"71.72500","0.34341","846.90011"
"71.82500","0.34357","848.21153"
"71.92500","0.34369","849.07751"
"72.02500","0.34382","849.81478"
"72.12500","0.34395","850.88257"
"72.22500","0.34409","851.60579"
"72.32500","0.34423","852.90338"
"72.42500","0.34435","853.42539"
"72.52500","0.34450","854.51568"
"72.62500","0.34462","855.29647"
"72.72500","0.34475","855.93780"
"72.82500","0.34490","857.35241"
"72.92500","0.34502","857.92810"
"73.02500","0.34516","858.82206"
"73.12500","0.34528","859.52783"
"73.22500","0.34543","860.73656"
"73.32500","0.34556","861.65358"
"73.42500","0.34569","862.24036"
"73.52500","0.34583","863.52340"
"73.62500","0.34594","863.95129"
"73.72500","0.34610","864.97665"
"73.82500","0.34623","866.08862"
"73.92500","0.34636","866.68176"
"74.02500","0.34649","867.64395"
"74.12500","0.34661","868.31602"
"74.22500","0.34677","869.55433"
"74.32500","0.34689","870.15263"
"74.42500","0.34703","871.13946"
"74.52500","0.34715","871.98612"
"74.62500","0.34727","872.41181"
"74.72500","0.34744","873.88048"
"74.82500","0.34756","874.46939"
"74.92500","0.34769","875.24623"
"75.02500","0.34781","876.00848"
"75.12500","0.34795","876.78823"
"75.22500","0.34810","877.99350"
"75.32500","0.34822","878.47715"
"75.42500","0.34837","879.68017"
"75.52500","0.34848","880.10443"
"75.62500","0.34862","880.85164"
"75.72500","0.34877","882.23172"
"75.82500","0.34889","882.63710"
"75.92500","0.34902","883.50686"
"76.02500","0.34915","884.18211"
"76.12500","0.34930","885.19782"
"76.22500","0.34942","886.01050"
"76.32500","0.34956","886.67093"
"76.42500","0.34970","887.71166"
"76.52500","0.34981","888.02006"
"76.62500","0.34997","889.24289"
"76.72500","0.35009","890.07303"
"76.82500","0.35022","890.62671"
"76.92500","0.35035","891.37600"
"77.02500","0.35048","892.10575"
"77.12500","0.35063","893.28622"
"77.22500","0.35075","893.73830"
"77.32500","0.35090","894.75686"
"77.42500","0.35102","895.38304"
"77.52500","0.35115","895.85319"
"77.62500","0.35131","897.35506"
"77.72500","0.35142","897.62092"
"77.82500","0.35155","898.39069"
"77.92500","0.35168","899.05984"
"78.02500","0.35183","899.97790"
"78.12500","0.35196","900.82215"
"78.22500","0.35209","901.29454"
"78.32500","0.35223","902.45234"
"78.42500","0.35234","902.62923"
"78.52500","0.35250","903.67342"
"78.62500","0.35263","904.65773"
"78.72500","0.35276","905.00916"
"78.82500","0.35289","905.77063"
"78.92500","0.35301","906.41191"
"79.02500","0.35317","907.47047"
"79.12500","0.35329","908.01180"
"79.22500","0.35343","908.80160"
"79.32500","0.35356","909.63437"
"79.42500","0.35367","909.84156"
"79.52500","0.35384","911.25864"
"79.62500","0.35396","911.60051"
"79.72500","0.35409","912.21281"
"79.82500","0.35422","912.95903"
"79.92500","0.35436","913.58916"
"80.02500","0.35450","914.52007"
"80.12500","0.35461","914.80415"
"80.22500","0.35477","915.95619"
"80.32500","0.35488","916.24642"
"80.42500","0.35502","916.84500"
"80.52500","0.35517","918.06465"
"80.62500","0.35529","918.24868"
"80.72500","0.35542","918.97080"
"80.82500","0.35554","919.50236"
"80.92500","0.35570","920.44715"
"81.02500","0.35582","921.04458"
"81.12500","0.35596","921.53722"
"81.22500","0.35610","922.49321"
"81.32500","0.35620","922.53789"
"81.42500","0.35637","923.69113"
"81.52500","0.35650","924.28762"
"81.62500","0.35662","924.68543"
"81.72500","0.35676","925.34800"
"81.82500","0.35688","925.76326"
"81.92500","0.35703","926.78302"
"82.02500","0.35715","926.98159"
"82.12500","0.35730","927.93736"
"82.22500","0.35742","928.31508"
"82.32500","0.35755","928.65668"
"82.42500","0.35771","929.92145"
"82.52500","0.35782","930.06251"
"82.62500","0.35796","930.61937"
"82.72500","0.35808","931.13979"
"82.82500","0.35823","931.82004"
"82.92500","0.35836","932.62158"
"83.02500","0.35849","932.84990"
"83.12500","0.35863","933.78547"
"83.22500","0.35874","933.76911"
"83.32500","0.35890","934.68613"
"83.42500","0.35903","935.40370"
"83.52500","0.35915","935.54354"
"83.62500","0.35929","936.22719"
"83.72500","0.35941","936.54168"
"83.82500","0.35957","937.47132"
"83.92500","0.35969","937.75629"
"84.02500","0.35983","938.27583"
"84.12500","0.35996","938.86749"
"84.22500","0.36008","939.00942"
"84.32500","0.36024","940.10240"
"84.42500","0.36036","940.27276"
"84.52500","0.36049","940.70240"
"84.62500","0.36061","941.20427"
"84.72500","0.36076","941.70735"
"84.82500","0.36090","942.50307"
"84.92500","0.36102","942.63644"
"85.02500","0.36117","943.27409"
"85.12500","0.36128","943.44369"
"85.22500","0.36142","943.86543"
"85.32500","0.36157","944.87871"
"85.42500","0.36168","944.73393"
"85.52500","0.36183","945.41966"
"85.62500","0.36195","945.62372"
"85.72500","0.36210","946.32987"
"85.82500","0.36222","946.67466"
"85.92500","0.36236","946.94030"
"86.02500","0.36250","947.63119"
"86.12500","0.36261","947.53163"
"86.22500","0.36277","948.35096"
"86.32500","0.36289","948.70244"
"86.42500","0.36302","948.84020"
"86.52500","0.36316","949.39575"
"86.62500","0.36329","949.63011"
"86.72500","0.36343","950.32714"
"86.82500","0.36356","950.39004"
"86.92500","0.36370","950.85009"
"87.02500","0.36381","951.08533"
"87.12500","0.36395","951.19378"
"87.22500","0.36411","952.10926"
"87.32500","0.36422","951.90180"
"87.42500","0.36436","952.37425"
"87.52500","0.36448","952.48819"
"87.62500","0.36463","952.91289"
"87.72500","0.36476","953.28874"
"87.82500","0.36489","953.28962"
"87.92500","0.36503","953.78720"
"88.02500","0.36514","953.53847"
"88.12500","0.36530","954.05526"
"88.22500","0.36543","954.44890"
"88.32500","0.36556","954.20784"
"88.42500","0.36570","954.60291"
"88.52500","0.36582","954.40719"
"88.62500","0.36597","954.90894"
"88.72500","0.36609","954.68600"
"88.82500","0.36623","954.70324"
"88.92500","0.36636","954.57766"
"89.02500","0.36648","954.03100"
"89.12500","0.36664","954.45702"
"89.22500","0.36676","953.72343"
"89.32500","0.36689","953.00948"
"89.42500","0.36702","952.10531"
"89.52500","0.36716","950.68478"
"89.62500","0.36730","949.02999"
"89.72500","0.36742","945.52054"
"89.82500","0.36757","941.19132"
"89.91200","0.36767","935.52675"
"89.99000","0.36777","929.86898"
"90.07400","0.36790","924.24854"
"90.14900","0.36800","918.60708"
"90.22700","0.36809","912.95200"
"90.32700","0.36823","907.45461"
"90.42700","0.36835","902.33895"
"90.52700","0.36851","898.57757"
"90.62700","0.36863","894.51482"
"90.72700","0.36876","890.60283"
"90.82700","0.36890","887.17604"
"90.92700","0.36901","883.05148"
"91.02700","0.36917","879.84532"
"91.12700","0.36930","875.88916"
"91.22700","0.36942","871.44808"
"91.32700","0.36956","867.54247"
"91.42700","0.36969","863.37499"
"91.52700","0.36984","859.72092"
"91.62700","0.36996","855.01897"
"91.72700","0.37010","850.91555"
"91.82700","0.37022","846.56723"
"91.92700","0.37035","842.46612"
"92.02700","0.37051","839.17455"
"92.12700","0.37062","834.59561"
"92.22700","0.37076","830.62874"
"92.32700","0.37089","826.36143"
"92.42700","0.37103","822.33167"
"92.52700","0.37117","817.97160"
"92.62700","0.37129","813.03854"
"92.72700","0.37144","808.43232"
"92.82700","0.37155","802.78855"
"92.92700","0.37170","797.78908"
"93.02700","0.37183","792.47978"
"93.11700","0.37195","786.85077"
"93.21600","0.37208","781.17572"
"93.30500","0.37219","775.52723"
"93.40500","0.37234","769.88088"
"93.48800","0.37245","764.22487"
"93.55700","0.37253","758.56645"
"93.62700","0.37264","752.90287"
"93.68500","0.37272","747.28243"
"93.72800","0.37277","741.64799"
"93.76200","0.37280","736.02228"
"93.77800","0.37283","726.83294"
"93.77900","0.37284","720.97759"
"93.78000","0.37285","712.93210"
"93.78100","0.37286","702.75467"
"93.78200","0.37287","690.66686"
"93.78300","0.37288","676.94105"
"93.78400","0.37290","661.76815"
"93.78500","0.37291","645.34629"
"93.78600","0.37292","627.89511"
"93.78700","0.37293","609.55996"
"93.78800","0.37295","590.46898"
"93.78900","0.37296","570.78596"
"93.79000","0.37297","550.63115"
"93.79100","0.37298","530.09752"
"93.79200","0.37299","509.31005"
"93.79300","0.37300","488.37433"
"93.79400","0.37301","467.36414"
"93.79500","0.37302","446.37436"
"93.79600","0.37303","425.49145"
"93.79700","0.37304","404.76962"
"93.79800","0.37305","384.27589"
"93.79900","0.37306","364.08047"
"93.80000","0.37307","344.22500"
"93.80100","0.37307","324.75208"
"93.80200","0.37308","305.71231"
"93.80300","0.37309","287.13517"
"93.80400","0.37309","269.04650"
"93.80500","0.37310","251.48325"
"93.80600","0.37310","234.46533"
"93.80700","0.37311","218.00379"
"93.80800","0.37311","202.12033"
"93.80900","0.37312","186.82561"
"93.81000","0.37312","172.11983"
"93.81100","0.37313","158.01458"
"93.81200","0.37313","144.51608"
"93.81300","0.37313","131.61640"
"93.81400","0.37313","119.31495"
"93.81500","0.37313","107.61179"
"93.81600","0.37313","96.49500"
"93.81700","0.37313","85.95752"
"93.81800","0.37314","75.99533"
"93.81900","0.37314","66.59248"
"93.82000","0.37314","57.73481"
"93.82100","0.37314","49.41424"
"93.82200","0.37314","41.61440"
"93.82300","0.37314","34.31903"
"93.82400","0.37314","27.51766"
"93.82500","0.37314","21.19189"
"93.82600","0.37314","15.32137"
"93.82700","0.37314","9.89306"