File: materials_lab1/ENGR314_FA19_0002_birtchwood_A_20190903_AmericanIdiots_1.is_tens_RawData/Specimen_RawData_1.csv
Material,Steel
Geometry,Circular
Length,"2.00000",in
Diameter,"0.24400",in

Time,Extension,Load
(s),(in),(lbf)
"0.00000","0.00001","-6.11253"
"0.80000","0.00027","0.87472"
"1.60000","0.00054","8.45811"
"2.40000","0.00080","15.92695"
"3.20000","0.00107","23.42449"
"4.00000","0.00134","30.47602"
"4.80000","0.00161","37.52115"
"5.60000","0.00187","43.96396"
"6.40000","0.00214","50.44517"
"7.20000","0.00240","56.43593"
"8.00000","0.00267","62.23917"
"8.80000","0.00294","67.66244"
"9.60000","0.00321","72.15372"
"10.40000","0.00348","76.40102"
"11.20000","0.00374","79.80295"
"12.00000","0.00400","82.82835"
"12.80000","0.00428","85.76690"
"13.60000","0.00454","88.16795"
"14.40000","0.00481","90.36515"
"15.20000","0.00508","92.10687"
"16.00000","0.00533","93.51713"
"16.80000","0.00561","95.09610"
"17.60000","0.00587","96.44386"
"18.40000","0.00614","97.84248"
"19.20000","0.00641","99.09967"
"20.00000","0.00668","100.09290"
"20.80000","0.00694","100.96538"
"21.60000","0.00720","101.87484"
"22.40000","0.00748","102.91913"
"23.20000","0.00774","103.85269"
"24.00000","0.00801","104.81600"
"24.80000","0.00827","105.37079"
"25.60000","0.00854","106.17438"
"26.40000","0.00880","106.85318"
"27.20000","0.00907","107.62490"
"28.00000","0.00934","108.46509"
"28.80000","0.00961","109.00747"
"29.60000","0.00988","109.68277"
"30.40000","0.01014","110.07352"
"31.20000","0.01040","110.47451"
"32.00000","0.01068","111.19283"
"32.80000","0.01094","111.71623"
"33.60000","0.01121","112.20519"
"34.40000","0.01148","112.57430"
"35.20000","0.01173","112.87503"
"36.00000","0.01201","113.31741"
"36.80000","0.01227","113.68782"
"37.60000","0.01254","114.14370"
"38.40000","0.01281","114.58770"
"39.20000","0.01307","114.86205"
"40.00000","0.01334","115.05862"
"40.80000","0.01360","115.37854"
"41.60000","0.01388","115.81768"
"42.40000","0.01414","116.15943"
"43.20000","0.01441","116.66853"
"44.00000","0.01467","116.86409"
"44.80000","0.01494","117.31461"
"45.60000","0.01521","117.62068"
"46.40000","0.01547","118.00521"
"47.20000","0.01574","118.48970"
"48.00000","0.01601","118.75187"
"48.80000","0.01628","119.07775"
"49.60000","0.01654","119.26933"
"50.40000","0.01680","119.42418"
"51.20000","0.01708","119.85760"
"52.00000","0.01734","120.11079"
"52.80000","0.01761","120.42983"
"53.60000","0.01788","120.51666"
"54.40000","0.01814","120.65766"
"55.20000","0.01841","120.92672"
"56.00000","0.01867","121.20869"
"56.80000","0.01894","121.62876"
"57.60000","0.01921","121.94345"
"58.40000","0.01947","122.23933"
"59.20000","0.01974","122.41424"
"60.00000","0.02000","122.66321"
"60.80000","0.02028","123.04368"
"61.60000","0.02054","123.34599"
"62.40000","0.02081","123.49483"
"63.20000","0.02107","120.62231"
"64.00000","0.02134","120.76726"
"64.80000","0.02160","121.31850"
"65.60000","0.02187","121.99829"
"66.40000","0.02214","122.76020"
"67.20000","0.02241","123.23003"
"68.00000","0.02268","123.78466"
"68.80000","0.02294","124.10656"
"69.60000","0.02320","124.40904"
"70.40000","0.02348","124.97090"
"71.20000","0.02374","125.35807"
"72.00000","0.02401","125.76296"
"72.80000","0.02428","126.05108"
"73.60000","0.02453","126.19330"
"74.40000","0.02481","126.56039"
"75.20000","0.02507","126.80852"
"76.00000","0.02534","127.18259"
"76.80000","0.02561","127.51077"
"77.60000","0.02587","127.70180"
"78.40000","0.02614","127.93047"
"79.20000","0.02640","128.27000"
"80.00000","0.02668","128.68480"
"80.80000","0.02694","128.99109"
"81.60000","0.02721","129.40133"
"82.40000","0.02747","129.44459"
"83.20000","0.02774","129.75885"
"84.00000","0.02800","129.88547"
"84.80000","0.02827","130.19270"
"85.60000","0.02854","130.60350"
"86.40000","0.02881","130.81257"
"87.20000","0.02908","131.14748"
"88.00000","0.02934","131.36170"
"88.80000","0.02960","131.50053"
"89.60000","0.02988","132.00338"
"90.40000","0.03014","132.20171"
"91.20000","0.03041","132.64332"
"92.00000","0.03068","132.82537"
"92.80000","0.03093","132.91767"
"93.60000","0.03121","133.26623"
"94.40000","0.03148","133.57569"
"95.20000","0.03175","133.88009"
"96.00000","0.03201","134.19423"
"96.80000","0.03227","134.34605"
"97.60000","0.03254","134.53081"
"98.40000","0.03280","134.75567"
"99.20000","0.03308","135.13947"
"100.00000","0.03334","135.44366"
"100.80000","0.03361","135.82837"
"101.60000","0.03387","135.87934"
"102.40000","0.03414","136.15607"
"103.20000","0.03440","136.32160"
"104.00000","0.03467","136.67245"
"104.80000","0.03495","137.04220"
"105.60000","0.03521","137.15558"
"106.40000","0.03547","137.45589"
"107.20000","0.03574","137.63331"
"108.00000","0.03600","137.72254"
"108.80000","0.03628","138.14869"
"109.60000","0.03654","138.35156"
"110.40000","0.03681","138.69385"
"111.20000","0.03708","138.71852"
"112.00000","0.03734","138.74802"
"112.80000","0.03761","138.96745"
"113.60000","0.03787","139.13363"
"114.40000","0.03815","139.34333"
"115.20000","0.03841","139.53828"
"116.00000","0.03867","139.67367"
"116.80000","0.03894","139.64756"
"117.60000","0.03920","139.78184"
"118.40000","0.03948","140.01997"
"119.20000","0.03975","140.22355"
"120.00000","0.04001","140.47465"
"120.80000","0.04027","140.42233"
"121.60000","0.04054","140.60584"
"122.40000","0.04080","140.72937"
"123.20000","0.04107","140.97836"
"124.00000","0.04135","141.29849"
"124.80000","0.04161","141.44421"
"125.60000","0.04188","141.62442"
"126.40000","0.04214","141.65307"
"127.20000","0.04240","141.67725"
"128.00000","0.04268","142.02258"
"128.80000","0.04294","142.17890"
"129.60000","0.04321","142.34604"
"130.40000","0.04348","142.39525"
"131.20000","0.04374","142.42436"
"132.00000","0.04401","142.70199"
"132.80000","0.04427","142.83182"
"133.60000","0.04454","143.02392"
"134.40000","0.04481","143.20195"
"135.20000","0.04507","143.19224"
"136.00000","0.04534","143.19721"
"136.80000","0.04560","143.24640"
"137.60000","0.04588","143.54582"
"138.40000","0.04615","143.73782"
"139.20000","0.04641","144.00183"
"140.00000","0.04667","143.91505"
"140.80000","0.04694","144.11745"
"141.60000","0.04721","144.22015"
"142.40000","0.04747","144.32932"
"143.20000","0.04775","144.63827"
"144.00000","0.04801","144.62562"
"144.80000","0.04827","144.73422"
"145.60000","0.04854","144.72747"
"146.40000","0.04880","144.74590"
"147.20000","0.04908","145.04019"
"148.00000","0.04934","145.11996"
"148.80000","0.04961","145.31578"
"149.60000","0.04988","145.32276"
"150.40000","0.05014","145.27250"
"151.20000","0.05041","145.48358"
"152.00000","0.05067","145.63066"
"152.80000","0.05095","145.87605"
"153.60000","0.05121","146.08302"
"154.40000","0.05147","146.12631"
"155.20000","0.05174","146.27288"
"156.00000","0.05200","146.31622"
"156.80000","0.05228","146.53929"
"157.60000","0.05255","146.68583"
"158.40000","0.05281","146.91778"
"159.20000","0.05307","146.87209"
"160.00000","0.05334","147.05643"
"160.80000","0.05360","147.25731"
"161.60000","0.05387","147.37873"
"162.40000","0.05415","147.67630"
"163.20000","0.05441","147.64878"
"164.00000","0.05467","147.79022"
"164.80000","0.05494","147.82047"
"165.60000","0.05520","147.84340"
"166.40000","0.05548","148.14152"
"167.20000","0.05574","148.23625"
"168.00000","0.05601","148.56813"
"168.80000","0.05628","148.56962"
"169.60000","0.05654","148.49214"
"170.40000","0.05681","148.70014"
"171.20000","0.05707","148.75630"
"172.00000","0.05735","148.96517"
"172.80000","0.05761","149.10435"
"173.60000","0.05787","149.07610"
"174.40000","0.05814","149.06676"
"175.20000","0.05840","149.16688"
"176.00000","0.05868","149.33034"
"176.80000","0.05895","149.46326"
"177.60000","0.05921","149.71443"
"178.40000","0.05947","149.55374"
"179.20000","0.05974","149.67045"
"180.00000","0.06001","149.82997"
"180.80000","0.06028","149.97550"
"181.60000","0.06055","150.24016"
"182.40000","0.06081","150.29823"
"183.20000","0.06107","150.52088"
"184.00000","0.06134","150.62483"
"184.80000","0.06160","150.67275"
"185.60000","0.06188","150.99204"
"186.40000","0.06214","151.09210"
"187.20000","0.06241","151.36080"
"188.00000","0.06268","151.44211"
"188.80000","0.06294","151.39357"
"189.60000","0.06321","151.67603"
"190.40000","0.06347","151.82960"
"191.20000","0.06374","152.02869"
"192.00000","0.06401","152.19528"
"192.80000","0.06427","152.18208"
"193.60000","0.06454","152.18155"
"194.40000","0.06480","152.28483"
"195.20000","0.06508","152.52064"
"196.00000","0.06535","152.63095"
"196.80000","0.06561","152.85735"
"197.60000","0.06587","152.71097"
"198.40000","0.06614","152.86490"
"199.20000","0.06640","152.99850"
"200.00000","0.06667","153.14492"
"200.80000","0.06695","153.36295"
"201.60000","0.06721","153.36266"
"202.40000","0.06747","153.47586"
"203.20000","0.06774","153.48385"
"204.00000","0.06800","153.46048"
"204.80000","0.06828","153.75705"
"205.60000","0.06854","153.85945"
"206.40000","0.06881","154.01662"
"207.20000","0.06907","153.97865"
"208.00000","0.06934","153.98888"
"208.80000","0.06961","154.17445"
"209.60000","0.06988","154.28874"
"210.40000","0.07014","154.40329"
"211.20000","0.07041","154.48695"
"212.00000","0.07067","154.55666"
"212.80000","0.07094","154.54981"
"213.60000","0.07120","154.56110"
"214.40000","0.07148","154.73817"
"215.20000","0.07175","154.82639"
"216.00000","0.07201","154.97853"
"216.80000","0.07227","154.89126"
"217.60000","0.07254","155.01839"
"218.40000","0.07281","155.09559"
"219.20000","0.07307","155.16198"
"220.00000","0.07335","155.41090"
"220.80000","0.07361","155.32753"
"221.60000","0.07387","155.42354"
"222.40000","0.07414","155.34888"
"223.20000","0.07440","155.29332"
"224.00000","0.07468","155.50703"
"224.80000","0.07494","155.57304"
"225.60000","0.07521","155.69448"
"226.40000","0.07547","155.64795"
"227.20000","0.07574","155.61714"
"228.00000","0.07601","155.89481"
"228.80000","0.07627","156.03247"
"229.60000","0.07654","156.23187"
"230.40000","0.07681","156.45477"
"231.20000","0.07707","156.41800"
"232.00000","0.07734","156.52612"
"232.80000","0.07760","156.57479"
"233.60000","0.07788","156.75792"
"234.40000","0.07815","156.81740"
"235.20000","0.07841","156.90026"
"236.00000","0.07867","156.74644"
"236.80000","0.07894","156.78226"
"237.60000","0.07920","156.86229"
"238.40000","0.07947","156.93593"
"239.20000","0.07975","157.19550"
"240.00000","0.08001","157.05388"
"240.80000","0.08027","157.13467"
"241.60000","0.08054","157.06684"
"242.40000","0.08080","157.11047"
"243.20000","0.08108","157.35692"
"244.00000","0.08134","157.30257"
"244.80000","0.08161","157.43032"
"245.60000","0.08187","157.34085"
"246.40000","0.08213","157.24464"
"247.20000","0.08241","157.45195"
"248.00000","0.08267","157.50829"
"248.80000","0.08295","157.64552"
"249.60000","0.08321","157.73616"
"250.40000","0.08347","157.68610"
"251.20000","0.08374","157.72246"
"252.00000","0.08400","157.78138"
"252.80000","0.08428","157.92275"
"253.60000","0.08455","157.96198"
"254.40000","0.08481","158.06713"
"255.20000","0.08507","157.89947"
"256.00000","0.08534","158.00287"
"256.80000","0.08560","158.01533"
"257.60000","0.08588","158.07790"
"258.40000","0.08615","158.18302"
"259.20000","0.08641","158.14080"
"260.00000","0.08667","158.21554"
"260.80000","0.08694","158.15781"
"261.60000","0.08720","158.22569"
"262.40000","0.08748","158.43480"
"263.20000","0.08775","158.69939"
"264.00000","0.08801","158.68209"
"264.80000","0.08827","158.70916"
"265.60000","0.08854","158.66985"
"266.40000","0.08881","158.85935"
"267.20000","0.08908","158.91868"
"268.00000","0.08934","159.04902"
"268.80000","0.08961","159.14318"
"269.60000","0.08987","159.11167"
"270.40000","0.09014","159.13996"
"271.20000","0.09040","159.15246"
"272.00000","0.09068","159.35804"
"272.80000","0.09094","159.41311"
"273.60000","0.09121","159.56794"
"274.40000","0.09147","159.44843"
"275.20000","0.09174","159.59360"
"276.00000","0.09201","159.74566"
"276.80000","0.09227","159.81550"
"277.60000","0.09255","160.03072"
"278.40000","0.09281","159.91764"
"279.20000","0.09307","159.99149"
"280.00000","0.09334","159.92927"
"280.80000","0.09360","159.94596"
"281.60000","0.09388","160.18241"
"282.40000","0.09414","160.15025"
"283.20000","0.09441","160.31341"
"284.00000","0.09467","160.17934"
"284.80000","0.09494","160.09609"
"285.60000","0.09521","160.32699"
"286.40000","0.09548","160.35814"
"287.20000","0.09575","160.42459"
"288.00000","0.09601","160.43845"
"288.80000","0.09627","160.37113"
"289.60000","0.09654","160.29970"
"290.40000","0.09680","160.30741"
"291.20000","0.09708","160.42733"
"292.00000","0.09734","160.44866"
"292.80000","0.09761","160.54587"
"293.60000","0.09787","160.38828"
"294.40000","0.09814","160.37688"
"295.20000","0.09841","160.47759"
"296.00000","0.09867","160.51171"
"296.80000","0.09895","160.67268"
"297.60000","0.09920","160.48636"
"298.40000","0.09947","160.54232"
"299.20000","0.09974","160.39889"
"300.00000","0.10000","160.32385"
"300.80000","0.10028","160.58164"
"301.60000","0.10054","160.56375"
"302.40000","0.10081","160.67279"
"303.20000","0.10107","160.59712"
"304.00000","0.10134","160.51236"
"304.80000","0.10161","160.70181"
"305.60000","0.10187","160.79939"
"306.40000","0.10214","160.92981"
"307.20000","0.10241","161.03599"
"308.00000","0.10267","160.99561"
"308.80000","0.10294","161.09715"
"309.60000","0.10320","161.09763"
"310.40000","0.10348","161.27544"
"311.20000","0.10374","161.38919"
"312.00000","0.10400","161.43535"
"312.80000","0.10427","161.37988"
"313.60000","0.10454","161.42996"
"314.40000","0.10481","161.51300"
"315.20000","0.10507","161.59788"
"316.00000","0.10535","161.86669"
"316.80000","0.10560","161.72388"
"317.60000","0.10587","161.88106"
"318.40000","0.10614","161.80473"
"319.20000","0.10640","161.90739"
"320.00000","0.10668","162.21259"
"320.80000","0.10694","162.31639"
"321.60000","0.10721","162.52065"
"322.40000","0.10747","162.60716"
"323.20000","0.10774","162.51379"
"324.00000","0.10801","162.80539"
"324.80000","0.10827","162.86342"
"325.60000","0.10855","163.08722"
"326.40000","0.10881","163.19494"
"327.20000","0.10907","163.13030"
"328.00000","0.10934","163.23838"
"328.80000","0.10961","163.30222"
"329.60000","0.10988","163.51245"
"330.40000","0.11014","163.63794"
"331.20000","0.11041","163.76717"
"332.00000","0.11067","163.66685"
"332.80000","0.11094","163.81017"
"333.60000","0.11121","163.96101"
"334.40000","0.11148","164.13941"
"335.20000","0.11175","164.43976"
"336.00000","0.11201","164.34354"
"336.80000","0.11227","164.49453"
"337.60000","0.11254","164.49530"
"338.40000","0.11281","164.66955"
"339.20000","0.11308","164.90491"
"340.00000","0.11334","164.94269"
"340.80000","0.11361","165.08261"
"341.60000","0.11387","165.07620"
"342.40000","0.11413","165.05508"
"343.20000","0.11441","165.40321"
"344.00000","0.11467","165.53456"
"344.80000","0.11495","165.75186"
"345.60000","0.11521","165.83493"
"346.40000","0.11547","165.74237"
"347.20000","0.11574","165.87276"
"348.00000","0.11601","165.93097"
"348.80000","0.11628","166.13714"
"349.60000","0.11654","166.26659"
"350.40000","0.11681","166.37740"
"351.20000","0.11707","166.34797"
"352.00000","0.11734","166.46839"
"352.80000","0.11761","166.67202"
"353.60000","0.11788","166.78441"
"354.40000","0.11815","167.08849"
"355.20000","0.11841","166.96608"
"356.00000","0.11867","167.11061"
"356.80000","0.11894","167.10330"
"357.60000","0.11921","167.14218"
"358.40000","0.11948","167.41076"
"359.20000","0.11974","167.49232"
"360.00000","0.12001","167.69636"
"360.80000","0.12027","167.63882"
"361.60000","0.12054","167.64686"
"362.40000","0.12081","167.88151"
"363.20000","0.12107","167.95705"
"364.00000","0.12134","168.15337"
"364.80000","0.12161","168.12733"
"365.60000","0.12187","168.16830"
"366.40000","0.12214","168.19377"
"367.20000","0.12241","168.35384"
"368.00000","0.12268","168.50937"
"368.80000","0.12294","168.67004"
"369.60000","0.12321","168.76016"
"370.40000","0.12347","168.73584"
"371.20000","0.12374","168.80796"
"372.00000","0.12401","169.02962"
"372.80000","0.12428","169.15484"
"373.60000","0.12455","169.41680"
"374.40000","0.12481","169.31483"
"375.20000","0.12507","169.45327"
"376.00000","0.12534","169.47489"
"376.80000","0.12561","169.57458"
"377.60000","0.12588","169.83123"
"378.40000","0.12614","169.86031"
"379.20000","0.12641","169.98738"
"380.00000","0.12667","169.95619"
"380.80000","0.12693","169.92965"
"381.60000","0.12721","170.20308"
"382.40000","0.12747","170.28608"
"383.20000","0.12775","170.45995"
"384.00000","0.12801","170.49718"
"384.80000","0.12827","170.41215"
"385.60000","0.12854","170.48272"
"386.40000","0.12881","170.57864"
"387.20000","0.12908","170.70272"
"388.00000","0.12934","170.83006"
"388.80000","0.12961","170.82609"
"389.60000","0.12987","170.74018"
"390.40000","0.13014","170.81693"
"391.20000","0.13041","170.96728"
"392.00000","0.13068","171.06691"
"392.80000","0.13095","171.25845"
"393.60000","0.13121","171.11023"
"394.40000","0.13147","171.21421"
"395.20000","0.13174","171.17006"
"396.00000","0.13201","171.29467"
"396.80000","0.13228","171.50960"
"397.60000","0.13254","171.49572"
"398.40000","0.13281","171.57839"
"399.20000","0.13307","171.53478"
"400.00000","0.13333","171.47952"
"400.80000","0.13361","171.75609"
"401.60000","0.13387","171.79179"
"402.40000","0.13415","171.97981"
"403.20000","0.13441","171.99115"
"404.00000","0.13467","171.85985"
"404.80000","0.13494","171.98323"
"405.60000","0.13520","171.96778"
"406.40000","0.13548","172.17215"
"407.20000","0.13575","172.24893"
"408.00000","0.13601","172.25722"
"408.80000","0.13627","172.07363"
"409.60000","0.13654","172.17160"
"410.40000","0.13681","172.29030"
"411.20000","0.13708","172.37691"
"412.00000","0.13735","172.56092"
"412.80000","0.13761","172.39104"
"413.60000","0.13787","172.56047"
"414.40000","0.13814","172.51153"
"415.20000","0.13841","172.58826"
"416.00000","0.13868","172.79833"
"416.80000","0.13894","172.77565"
"417.60000","0.13921","172.80804"
"418.40000","0.13947","172.83458"
"419.20000","0.13974","172.73046"
"420.00000","0.14001","172.94041"
"420.80000","0.14027","173.01846"
"421.60000","0.14055","173.12831"
"422.40000","0.14081","173.05357"
"423.20000","0.14107","172.88665"
"424.00000","0.14134","172.98544"
"424.80000","0.14161","172.95275"
"425.60000","0.14188","173.09435"
"426.40000","0.14214","173.13713"
"427.20000","0.14241","173.12016"
"428.00000","0.14267","173.00728"
"428.80000","0.14294","172.92952"
"429.60000","0.14321","173.06759"
"430.40000","0.14348","173.05474"
"431.20000","0.14375","173.19268"
"432.00000","0.14401","172.88695"
"432.80000","0.14427","172.97348"
"433.60000","0.14454","172.89984"
"434.40000","0.14481","172.96481"
"435.20000","0.14508","173.12111"
"436.00000","0.14534","173.08527"
"436.80000","0.14561","173.17057"
"437.60000","0.14587","173.05433"
"438.40000","0.14613","172.98031"
"439.20000","0.14641","173.24895"
"440.00000","0.14668","173.36275"
"440.80000","0.14695","173.50001"
"441.60000","0.14721","173.48615"
"442.40000","0.14747","173.36781"
"443.20000","0.14774","173.46260"
"444.00000","0.14801","173.56493"
"444.80000","0.14828","173.66149"
"445.60000","0.14855","173.76831"
"446.40000","0.14881","173.71041"
"447.20000","0.14907","173.62925"
"448.00000","0.14934","173.65475"
"448.80000","0.14961","173.81639"
"449.60000","0.14988","173.86485"
"450.40000","0.15015","174.02620"
"451.20000","0.15041","173.81338"
"452.00000","0.15067","173.87112"
"452.80000","0.15094","173.80786"
"453.60000","0.15121","173.82165"
"454.40000","0.15148","174.05492"
"455.20000","0.15174","174.02521"
"456.00000","0.15201","174.11248"
"456.80000","0.15227","174.07997"
"457.60000","0.15254","174.03777"
"458.40000","0.15281","174.29261"
"459.20000","0.15307","174.35038"
"460.00000","0.15335","174.48972"
"460.80000","0.15361","174.42413"
"461.60000","0.15387","174.37576"
"462.40000","0.15414","174.51576"
"463.20000","0.15441","174.57563"
"464.00000","0.15468","174.74057"
"464.80000","0.15494","174.78792"
"465.60000","0.15521","174.79079"
"466.40000","0.15547","174.68855"
"467.20000","0.15574","174.75892"
"468.00000","0.15601","174.95565"
"468.80000","0.15628","175.04909"
"469.60000","0.15654","175.20882"
"470.40000","0.15681","175.11299"
"471.20000","0.15707","175.25524"
"472.00000","0.15734","175.26513"
"472.80000","0.15761","175.42456"
"473.60000","0.15788","175.67386"
"474.40000","0.15814","175.67924"
"475.20000","0.15841","175.79524"
"476.00000","0.15867","175.79944"
"476.80000","0.15893","175.77047"
"477.60000","0.15921","176.10840"
"478.40000","0.15947","176.19629"
"479.20000","0.15975","176.41554"
"480.00000","0.16001","176.45684"
"480.80000","0.16027","176.35994"
"481.60000","0.16054","176.52671"
"482.40000","0.16081","176.56460"
"483.20000","0.16108","176.77129"
"484.00000","0.16134","176.87309"
"484.80000","0.16161","176.88812"
"485.60000","0.16187","176.87401"
"486.40000","0.16214","176.93585"
"487.20000","0.16241","177.13692"
"488.00000","0.16268","177.16940"
"488.80000","0.16295","177.38976"
"489.60000","0.16321","177.17705"
"490.40000","0.16347","177.35550"
"491.20000","0.16374","177.26926"
"492.00000","0.16401","177.52844"
"492.80000","0.16428","177.74775"
"493.60000","0.16454","177.68800"
"494.40000","0.16481","177.86987"
"495.20000","0.16507","177.75085"
"496.00000","0.16533","177.73232"
"496.80000","0.16561","177.99085"
"497.60000","0.16587","178.02854"
"498.40000","0.16614","178.13655"
"499.20000","0.16641","178.08261"
"500.00000","0.16667","177.88728"
"500.80000","0.16694","178.00303"
"501.60000","0.16721","178.02046"
"502.40000","0.16748","178.09974"
"503.20000","0.16775","178.20137"
"504.00000","0.16801","178.10314"
"504.80000","0.16827","178.03639"
"505.60000","0.16854","178.04506"
"506.40000","0.16881","178.24661"
"507.20000","0.16908","178.36072"
"508.00000","0.16935","178.53015"
"508.80000","0.16961","178.30191"
"509.60000","0.16987","178.35206"
"510.40000","0.17014","178.38061"
"511.20000","0.17041","178.43521"
"512.00000","0.17068","178.57340"
"512.80000","0.17094","178.47322"
"513.60000","0.17121","178.57281"
"514.40000","0.17147","178.51821"
"515.20000","0.17173","178.45081"
"516.00000","0.17201","178.65401"
"516.80000","0.17227","178.70568"
"517.60000","0.17255","178.85185"
"518.40000","0.17281","178.75570"
"519.20000","0.17307","178.66357"
"520.00000","0.17334","178.83053"
"520.80000","0.17361","178.92971"
"521.60000","0.17388","179.03643"
"522.40000","0.17414","179.11555"
"523.20000","0.17441","179.06700"
"524.00000","0.17467","178.95111"
"524.80000","0.17494","179.02056"
"525.60000","0.17521","179.23337"
"526.40000","0.17547","179.36045"
"527.20000","0.17575","179.56216"
"528.00000","0.17601","179.37529"
"528.80000","0.17627","179.46240"
"529.60000","0.17654","179.45569"
"530.40000","0.17681","179.52945"
"531.20000","0.17708","179.66214"
"532.00000","0.17734","179.58568"
"532.80000","0.17761","179.63619"
"533.60000","0.17787","179.50966"
"534.40000","0.17813","179.40936"
"535.20000","0.17841","179.60991"
"536.00000","0.17868","179.66648"
"536.80000","0.17894","179.75399"
"537.60000","0.17921","179.63279"
"538.40000","0.17947","179.51883"
"539.20000","0.17974","179.66006"
"540.00000","0.18001","179.69699"
"540.80000","0.18028","179.84634"
"541.60000","0.18054","179.91404"
"542.40000","0.18081","179.85809"
"543.20000","0.18107","179.76860"
"544.00000","0.18133","179.77830"
"544.80000","0.18161","180.02010"
"545.60000","0.18188","180.08297"
"546.40000","0.18214","180.23877"
"547.20000","0.18241","180.08608"
"548.00000","0.18267","180.14330"
"548.80000","0.18294","180.11999"
"549.60000","0.18321","180.16019"
"550.40000","0.18348","180.30159"
"551.20000","0.18374","180.20546"
"552.00000","0.18401","180.25068"
"552.80000","0.18427","180.12233"
"553.60000","0.18454","180.08844"
"554.40000","0.18481","180.29370"
"555.20000","0.18508","180.27936"
"556.00000","0.18534","180.35714"
"556.80000","0.18561","180.30075"
"557.60000","0.18587","180.18328"
"558.40000","0.18614","180.37257"
"559.20000","0.18641","180.42836"
"560.00000","0.18668","180.59517"
"560.80000","0.18694","180.68179"
"561.60000","0.18720","180.56472"
"562.40000","0.18747","180.56313"
"563.20000","0.18774","180.56598"
"564.00000","0.18801","180.71284"
"564.80000","0.18828","180.75203"
"565.60000","0.18854","180.88012"
"566.40000","0.18881","180.67716"
"567.20000","0.18907","180.73411"
"568.00000","0.18934","180.61859"
"568.80000","0.18961","180.65399"
"569.60000","0.18988","180.75378"
"570.40000","0.19014","180.62117"
"571.20000","0.19041","180.71825"
"572.00000","0.19067","180.64438"
"572.80000","0.19093","180.52176"
"573.60000","0.19121","180.73803"
"574.40000","0.19147","180.67233"
"575.20000","0.19174","180.87780"
"576.00000","0.19201","180.78884"
"576.80000","0.19227","180.63261"
"577.60000","0.19254","180.77579"
"578.40000","0.19281","180.82282"
"579.20000","0.19308","180.88586"
"580.00000","0.19335","180.90237"
"580.80000","0.19361","180.76022"
"581.60000","0.19388","180.75347"
"582.40000","0.19414","180.70498"
"583.20000","0.19441","180.84788"
"584.00000","0.19468","180.85968"
"584.80000","0.19494","180.94001"
"585.60000","0.19520","180.74187"
"586.40000","0.19547","180.81495"
"587.20000","0.19574","180.81274"
"588.00000","0.19601","180.95765"
"588.80000","0.19628","181.17953"
"589.60000","0.19654","181.09444"
"590.40000","0.19681","181.24430"
"591.20000","0.19707","181.24060"
"592.00000","0.19733","181.28698"
"592.80000","0.19761","181.58052"
"593.60000","0.19788","181.66795"
"594.40000","0.19814","181.89258"
"595.20000","0.19841","181.88005"
"596.00000","0.19867","181.89343"
"596.80000","0.19894","182.06647"
"597.60000","0.19921","182.14051"
"598.40000","0.19948","182.29549"
"599.20000","0.19974","182.33151"
"600.00000","0.20001","182.34188"
"600.80000","0.20027","182.33745"
"601.60000","0.20054","182.41480"
"602.40000","0.20081","182.61069"
"603.20000","0.20108","182.78115"
"604.00000","0.20134","183.03689"
"604.80000","0.20160","182.92222"
"605.60000","0.20187","183.06776"
"606.40000","0.20214","183.15846"
"607.20000","0.20241","183.25864"
"608.00000","0.20268","183.49082"
"608.80000","0.20294","183.42659"
"609.60000","0.20321","183.56798"
"610.40000","0.20347","183.53422"
"611.20000","0.20373","183.53677"
"612.00000","0.20401","183.85339"
"612.80000","0.20428","183.95270"
"613.60000","0.20454","184.06430"
"614.40000","0.20481","183.98054"
"615.20000","0.20507","183.92784"
"616.00000","0.20534","184.15048"
"616.80000","0.20561","184.22769"
"617.60000","0.20588","184.43312"
"618.40000","0.20614","184.55991"
"619.20000","0.20641","184.53909"
"620.00000","0.20667","184.55435"
"620.80000","0.20693","184.58708"
"621.60000","0.20721","184.83808"
"622.40000","0.20748","184.98299"
"623.20000","0.20774","185.11091"
"624.00000","0.20800","185.00036"
"624.80000","0.20827","185.14207"
"625.60000","0.20854","185.20818"
"626.40000","0.20881","185.30787"
"627.20000","0.20908","185.59017"
"628.00000","0.20934","185.47559"
"628.80000","0.20961","185.56290"
"629.60000","0.20987","185.52875"
"630.40000","0.21014","185.57959"
"631.20000","0.21041","185.85399"
"632.00000","0.21068","185.89670"
"632.80000","0.21094","186.16022"
"633.60000","0.21121","186.09912"
"634.40000","0.21147","186.01929"
"635.20000","0.21174","186.22792"
"636.00000","0.21201","186.30334"
"636.80000","0.21228","186.51531"
"637.60000","0.21254","186.64186"
"638.40000","0.21280","186.52420"
"639.20000","0.21308","186.64204"
"640.00000","0.21333","186.59776"
"640.80000","0.21361","186.81078"
"641.60000","0.21388","186.87309"
"642.40000","0.21414","186.91557"
"643.20000","0.21440","186.83366"
"644.00000","0.21467","186.95919"
"644.80000","0.21494","187.04805"
"645.60000","0.21521","187.13272"
"646.40000","0.21548","187.37338"
"647.20000","0.21574","187.21725"
"648.00000","0.21601","187.30523"
"648.80000","0.21627","187.21545"
"649.60000","0.21653","187.22655"
"650.40000","0.21681","187.48255"
"651.20000","0.21707","187.41561"
"652.00000","0.21734","187.64907"
"652.80000","0.21761","187.53860"
"653.60000","0.21787","187.40228"
"654.40000","0.21814","187.58010"
"655.20000","0.21841","187.59601"
"656.00000","0.21868","187.75681"
"656.80000","0.21894","187.81070"
"657.60000","0.21920","187.59429"
"658.40000","0.21947","187.62658"
"659.20000","0.21974","187.65767"
"660.00000","0.22001","187.74558"
"660.80000","0.22028","187.81109"
"661.60000","0.22054","187.84427"
"662.40000","0.22080","187.64848"
"663.20000","0.22107","187.64856"
"664.00000","0.22134","187.71269"
"664.80000","0.22161","187.73620"
"665.60000","0.22188","187.84989"
"666.40000","0.22214","187.69779"
"667.20000","0.22241","187.73210"
"668.00000","0.22267","187.63452"
"668.80000","0.22294","187.57563"
"669.60000","0.22321","187.80550"
"670.40000","0.22348","187.74045"
"671.20000","0.22374","187.86936"
"672.00000","0.22401","187.83510"
"672.80000","0.22427","187.64230"
"673.60000","0.22454","187.85213"
"674.40000","0.22481","187.81914"
"675.20000","0.22508","187.90472"
"676.00000","0.22534","187.88838"
"676.80000","0.22560","187.70502"
"677.60000","0.22587","187.71312"
"678.40000","0.22614","187.67094"
"679.20000","0.22641","187.77356"
"680.00000","0.22668","187.75340"
"680.80000","0.22694","187.87057"
"681.60000","0.22720","187.63382"
"682.40000","0.22747","187.68863"
"683.20000","0.22774","187.77132"
"684.00000","0.22801","187.87768"
"684.80000","0.22828","188.08938"
"685.60000","0.22854","187.94262"
"686.40000","0.22880","187.97661"
"687.20000","0.22907","187.95968"
"688.00000","0.22933","187.94206"
"688.80000","0.22961","188.17340"
"689.60000","0.22988","188.18790"
"690.40000","0.23014","188.29225"
"691.20000","0.23041","188.18931"
"692.00000","0.23067","188.07814"
"692.80000","0.23094","188.30697"
"693.60000","0.23121","188.34395"
"694.40000","0.23148","188.43774"
"695.20000","0.23174","188.45574"
"696.00000","0.23200","188.46947"
"696.80000","0.23227","188.51895"
"697.60000","0.23254","188.53230"
"698.40000","0.23281","188.72794"
"699.20000","0.23308","188.82149"
"700.00000","0.23334","188.88012"
"700.80000","0.23360","188.80127"
"701.60000","0.23387","188.86587"
"702.40000","0.23414","188.99464"
"703.20000","0.23441","189.07912"
"704.00000","0.23468","189.33729"
"704.80000","0.23494","189.17069"
"705.60000","0.23521","189.25244"
"706.40000","0.23547","189.23799"
"707.20000","0.23574","189.30900"
"708.00000","0.23601","189.57796"
"708.80000","0.23628","189.63526"
"709.60000","0.23654","189.76401"
"710.40000","0.23681","189.67085"
"711.20000","0.23707","189.60199"
"712.00000","0.23734","189.80734"
"712.80000","0.23761","189.90634"
"713.60000","0.23788","190.06564"
"714.40000","0.23814","190.18968"
"715.20000","0.23840","190.07367"
"716.00000","0.23868","190.15807"
"716.80000","0.23894","190.15926"
"717.60000","0.23921","190.30460"
"718.40000","0.23948","190.39431"
"719.20000","0.23974","190.40310"
"720.00000","0.24001","190.32378"
"720.80000","0.24027","190.36408"
"721.60000","0.24054","190.55314"
"722.40000","0.24081","190.65342"
"723.20000","0.24108","190.89587"
"724.00000","0.24134","190.75206"
"724.80000","0.24160","190.84626"
"725.60000","0.24187","190.78734"
"726.40000","0.24214","190.86334"
"727.20000","0.24241","191.12561"
"728.00000","0.24267","191.09881"
"728.80000","0.24294","191.29678"
"729.60000","0.24321","191.24384"
"730.40000","0.24347","191.16318"
"731.20000","0.24374","191.46357"
"732.00000","0.24401","191.51854"
"732.80000","0.24428","191.76010"
"733.60000","0.24454","191.82540"
"734.40000","0.24480","191.79157"
"735.20000","0.24508","191.93468"
"736.00000","0.24534","192.04445"
"736.80000","0.24561","192.27150"
"737.60000","0.24588","192.43247"
"738.40000","0.24614","192.52560"
"739.20000","0.24640","192.44700"
"740.00000","0.24667","192.56027"
"740.80000","0.24694","192.74006"
"741.60000","0.24721","192.91055"
"742.40000","0.24748","193.11899"
"743.20000","0.24774","193.06258"
"744.00000","0.24800","193.19259"
"744.80000","0.24827","193.17557"
"745.60000","0.24854","193.26972"
"746.40000","0.24881","193.49785"
"747.20000","0.24908","193.50590"
"748.00000","0.24934","193.61073"
"748.80000","0.24961","193.61272"
"749.60000","0.24987","193.49097"
"750.40000","0.25015","193.76346"
"751.20000","0.25041","193.82271"
"752.00000","0.25068","193.97957"
"752.80000","0.25095","194.01928"
"753.60000","0.25120","193.94254"
"754.40000","0.25148","194.00615"
"755.20000","0.25174","194.01194"
"756.00000","0.25201","194.20037"
"756.80000","0.25228","194.28571"
"757.60000","0.25254","194.33402"
"758.40000","0.25280","194.21851"
"759.20000","0.25307","194.33545"
"760.00000","0.25334","194.51614"
"760.80000","0.25361","194.59843"
"761.60000","0.25388","194.83752"
"762.40000","0.25414","194.68837"
"763.20000","0.25440","194.78889"
"764.00000","0.25467","194.74953"
"764.80000","0.25494","194.88666"
"765.60000","0.25521","195.12228"
"766.40000","0.25547","195.16815"
"767.20000","0.25574","195.32970"
"768.00000","0.25600","195.24374"
"768.80000","0.25627","195.13603"
"769.60000","0.25654","195.43094"
"770.40000","0.25681","195.48791"
"771.20000","0.25708","195.51835"
"772.00000","0.25734","195.46101"
"772.80000","0.25760","195.44865"
"773.60000","0.25787","195.39765"
"774.40000","0.25814","195.52955"
"775.20000","0.25841","195.65719"
"776.00000","0.25868","195.72843"
"776.80000","0.25894","195.77464"
"777.60000","0.25920","195.60830"
"778.40000","0.25947","195.60998"
"779.20000","0.25974","195.78205"
"780.00000","0.26001","195.83581"
"780.80000","0.26028","196.01992"
"781.60000","0.26054","195.85483"
"782.40000","0.26080","195.92784"
"783.20000","0.26107","195.85768"
"784.00000","0.26134","195.85771"
"784.80000","0.26161","196.07291"
"785.60000","0.26187","196.03573"
"786.40000","0.26214","196.14000"
"787.20000","0.26241","196.07990"
"788.00000","0.26267","195.82732"
"788.80000","0.26294","196.28282"
"789.60000","0.26321","196.41423"
"790.40000","0.26348","196.59689"
"791.20000","0.26375","196.60866"
"792.00000","0.26400","196.47774"
"792.80000","0.26428","196.52210"
"793.60000","0.26454","196.52423"
"794.40000","0.26481","196.61044"
"795.20000","0.26508","196.68308"
"796.00000","0.26534","196.60447"
"796.80000","0.26560","196.60468"
"797.60000","0.26587","196.63565"
"798.40000","0.26614","196.77346"
"799.20000","0.26641","196.84321"
"800.00000","0.26668","196.98226"
"800.80000","0.26694","196.75427"
"801.60000","0.26720","196.83599"
"802.40000","0.26747","196.75111"
"803.20000","0.26774","196.78928"
"804.00000","0.26801","196.95685"
"804.80000","0.26827","196.79505"
"805.60000","0.26854","196.86614"
"806.40000","0.26880","196.77629"
"807.20000","0.26907","196.62685"
"808.00000","0.26934","196.86924"
"808.80000","0.26961","196.85476"
"809.60000","0.26988","197.04536"
"810.40000","0.27015","197.02068"
"811.20000","0.27040","196.96404"
"812.00000","0.27068","196.98916"
"812.80000","0.27094","197.10490"
"813.60000","0.27121","197.11763"
"814.40000","0.27148","197.24060"
"815.20000","0.27174","197.24848"
"816.00000","0.27201","197.16654"
"816.80000","0.27227","197.26105"
"817.60000","0.27254","197.39162"
"818.40000","0.27281","197.48403"
"819.20000","0.27308","197.69987"
"820.00000","0.27334","197.41271"
"820.80000","0.27360","197.43709"
"821.60000","0.27387","197.34571"
"822.40000","0.27414","197.48771"
"823.20000","0.27441","197.66124"
"824.00000","0.27467","197.60684"
"824.80000","0.27494","197.72861"
"825.60000","0.27520","197.63425"
"826.40000","0.27547","197.59121"
"827.20000","0.27574","197.85077"
"828.00000","0.27601","197.89050"
"828.80000","0.27628","197.99910"
"829.60000","0.27654","197.94663"
"830.40000","0.27680","197.76519"
"831.20000","0.27708","197.89286"
"832.00000","0.27734","197.91577"
"832.80000","0.27761","198.05652"
"833.60000","0.27788","198.11367"
"834.40000","0.27814","198.11030"
"835.20000","0.27841","198.07248"
"836.00000","0.27867","198.08688"
"836.80000","0.27894","198.27185"
"837.60000","0.27921","198.32321"
"838.40000","0.27948","198.50028"
"839.20000","0.27974","198.30292"
"840.00000","0.28000","198.44721"
"840.80000","0.28027","198.43545"
"841.60000","0.28054","198.51532"
"842.40000","0.28081","198.80341"
"843.20000","0.28107","198.78666"
"844.00000","0.28134","198.99231"
"844.80000","0.28160","198.94229"
"845.60000","0.28187","198.92136"
"846.40000","0.28214","199.16552"
"847.20000","0.28241","199.19934"
"848.00000","0.28268","199.32869"
"848.80000","0.28294","199.22695"
"849.60000","0.28320","199.22997"
"850.40000","0.28347","199.32478"
"851.20000","0.28374","199.48856"
"852.00000","0.28401","199.64680"
"852.80000","0.28428","199.81456"
"853.60000","0.28454","199.85166"
"854.40000","0.28480","199.85550"
"855.20000","0.28507","199.88779"
"856.00000","0.28534","200.18459"
"856.80000","0.28561","200.32216"
"857.60000","0.28588","200.54331"
"858.40000","0.28614","200.37415"
"859.20000","0.28640","200.51320"
"860.00000","0.28667","200.58073"
"860.80000","0.28694","200.66299"
"861.60000","0.28721","200.93217"
"862.40000","0.28748","200.92793"
"863.20000","0.28774","201.08571"
"864.00000","0.28800","200.99172"
"864.80000","0.28827","200.96887"
"865.60000","0.28854","201.31780"
"866.40000","0.28881","201.41137"
"867.20000","0.28908","201.67148"
"868.00000","0.28934","201.64363"
"868.80000","0.28960","201.65543"
"869.60000","0.28987","201.83283"
"870.40000","0.29014","201.98178"
"871.20000","0.29041","202.14275"
"872.00000","0.29068","202.31758"
"872.80000","0.29094","202.28006"
"873.60000","0.29120","202.27341"
"874.40000","0.29147","202.29735"
"875.20000","0.29174","202.53624"
"876.00000","0.29201","202.64973"
"876.80000","0.29228","202.78118"
"877.60000","0.29254","202.65044"
"878.40000","0.29280","202.71876"
"879.20000","0.29307","202.74636"
"880.00000","0.29334","202.87304"
"880.80000","0.29361","203.10814"
"881.60000","0.29387","203.05884"
"882.40000","0.29414","203.20910"
"883.20000","0.29440","203.18314"
"884.00000","0.29467","203.18989"
"884.80000","0.29495","203.50879"
"885.60000","0.29521","203.54619"
"886.40000","0.29548","203.72273"
"887.20000","0.29575","203.68493"
"888.00000","0.29600","203.49307"
"888.80000","0.29628","203.66379"
"889.60000","0.29654","203.60202"
"890.40000","0.29681","203.80328"
"891.20000","0.29708","203.88885"
"892.00000","0.29734","203.87538"
"892.80000","0.29760","203.82048"
"893.60000","0.29787","203.90217"
"894.40000","0.29814","204.06592"
"895.20000","0.29841","204.15939"
"896.00000","0.29868","204.34249"
"896.80000","0.29894","204.11341"
"897.60000","0.29920","204.24109"
"898.40000","0.29947","204.28482"
"899.20000","0.29974","204.39160"
"900.00000","0.30001","204.57672"
"900.80000","0.30027","204.58739"
"901.60000","0.30054","204.63389"
"902.40000","0.30080","204.61616"
"903.20000","0.30107","204.57775"
"904.00000","0.30135","204.88884"
"904.80000","0.30161","204.92367"
"905.60000","0.30188","205.13404"
"906.40000","0.30214","205.05621"
"907.20000","0.30240","204.95712"
"908.00000","0.30268","205.19683"
"908.80000","0.30294","205.26630"
"909.60000","0.30321","205.40639"
"910.40000","0.30348","205.49897"
"911.20000","0.30374","205.39883"
"912.00000","0.30400","205.39779"
"912.80000","0.30427","205.41324"
"913.60000","0.30454","205.62969"
"914.40000","0.30481","205.73585"
"915.20000","0.30508","205.94219"
"916.00000","0.30534","205.76785"
"916.80000","0.30560","205.88624"
"917.60000","0.30587","205.97300"
"918.40000","0.30614","206.09221"
"919.20000","0.30641","206.29294"
"920.00000","0.30667","206.31912"
"920.80000","0.30694","206.51161"
"921.60000","0.30720","206.51264"
"922.40000","0.30747","206.48025"
"923.20000","0.30774","206.76502"
"924.00000","0.30801","206.82096"
"924.80000","0.30828","206.94527"
"925.60000","0.30854","206.86395"
"926.40000","0.30880","206.73649"
"927.20000","0.30907","206.93996"
"928.00000","0.30934","207.03966"
"928.80000","0.30961","207.16222"
"929.60000","0.30988","207.29813"
"930.40000","0.31014","207.26160"
"931.20000","0.31040","207.17189"
"932.00000","0.31067","207.22439"
"932.80000","0.31094","207.51916"
"933.60000","0.31121","207.66772"
"934.40000","0.31148","207.86583"
"935.20000","0.31174","207.73050"
"936.00000","0.31200","207.84683"
"936.80000","0.31227","207.91144"
"937.60000","0.31254","208.02184"
"938.40000","0.31281","208.19111"
"939.20000","0.31307","208.11250"
"940.00000","0.31334","208.18426"
"940.80000","0.31360","208.15096"
"941.60000","0.31387","208.09993"
"942.40000","0.31414","208.40724"
"943.20000","0.31441","208.47481"
"944.00000","0.31468","208.58890"
"944.80000","0.31494","208.47881"
"945.60000","0.31520","208.34044"
"946.40000","0.31547","208.53809"
"947.20000","0.31574","208.58226"
"948.00000","0.31601","208.77071"
"948.80000","0.31628","208.88640"
"949.60000","0.31654","208.85917"
"950.40000","0.31680","208.85874"
"951.20000","0.31707","208.93697"
"952.00000","0.31734","209.13801"
"952.80000","0.31761","209.22135"
"953.60000","0.31788","209.38003"
"954.40000","0.31814","209.27507"
"955.20000","0.31840","209.42396"
"956.00000","0.31867","209.42959"
"956.80000","0.31894","209.52531"
"957.60000","0.31921","209.74607"
"958.40000","0.31947","209.66408"
"959.20000","0.31974","209.72473"
"960.00000","0.32000","209.61180"
"960.80000","0.32027","209.58343"
"961.60000","0.32054","209.81149"
"962.40000","0.32081","209.81374"
"963.20000","0.32108","209.99730"
"964.00000","0.32134","209.88945"
"964.80000","0.32160","209.76109"
"965.60000","0.32188","209.98420"
"966.40000","0.32214","209.99411"
"967.20000","0.32241","210.14154"
"968.00000","0.32268","210.19253"
"968.80000","0.32294","210.03369"
"969.60000","0.32320","210.02927"
"970.40000","0.32347","210.01869"
"971.20000","0.32374","210.23553"
"972.00000","0.32401","210.33741"
"972.80000","0.32428","210.47421"
"973.60000","0.32454","210.22311"
"974.40000","0.32480","210.29923"
"975.20000","0.32507","210.25635"
"976.00000","0.32534","210.42829"
"976.80000","0.32561","210.60816"
"977.60000","0.32587","210.50458"
"978.40000","0.32614","210.58390"
"979.20000","0.32640","210.46173"
"980.00000","0.32667","210.45080"
"980.80000","0.32694","210.68571"
"981.60000","0.32721","210.67417"
"982.40000","0.32747","210.79845"
"983.20000","0.32774","210.73423"
"984.00000","0.32800","210.57344"
"984.80000","0.32828","210.74448"
"985.60000","0.32854","210.75396"
"986.40000","0.32881","210.85230"
"987.20000","0.32908","210.81624"
"988.00000","0.32934","210.73036"
"988.80000","0.32961","210.81095"
"989.60000","0.32987","210.86893"
"990.40000","0.33014","211.08865"
"991.20000","0.33041","211.19510"
"992.00000","0.33068","211.30690"
"992.80000","0.33094","211.15579"
"993.60000","0.33120","211.25046"
"994.40000","0.33147","211.34859"
"995.20000","0.33174","211.42725"
"996.00000","0.33201","211.63135"
"996.80000","0.33227","211.44336"
"997.60000","0.33254","211.53153"
"998.40000","0.33281","211.37559"
"999.20000","0.33307","211.37110"
"1,000.00000","0.33334","211.56684"
"1,000.80000","0.33361","211.62050"
"1,001.60000","0.33388","211.77654"
"1,002.40000","0.33414","211.70550"
"1,003.20000","0.33440","211.62309"
"1,004.00000","0.33468","211.82591"
"1,004.80000","0.33494","211.87582"
"1,005.60000","0.33521","211.90018"
"1,006.40000","0.33548","211.97891"
"1,007.20000","0.33574","211.86371"
"1,008.00000","0.33601","211.79295"
"1,008.80000","0.33627","211.87960"
"1,009.60000","0.33654","212.00497"
"1,010.40000","0.33681","212.07061"
"1,011.20000","0.33708","212.10604"
"1,012.00000","0.33734","211.95405"
"1,012.80000","0.33761","212.02879"
"1,013.60000","0.33787","212.13520"
"1,014.40000","0.33814","212.20083"
"1,015.20000","0.33841","212.39180"
"1,016.00000","0.33867","212.34329"
"1,016.80000","0.33894","212.49236"
"1,017.60000","0.33921","212.47805"
"1,018.40000","0.33947","212.42434"
"1,019.20000","0.33975","212.73928"
"1,020.00000","0.34001","212.76990"
"1,020.80000","0.34028","212.84105"
"1,021.60000","0.34054","212.80130"
"1,022.40000","0.34080","212.73749"
"1,023.20000","0.34108","212.97481"
"1,024.00000","0.34134","213.04098"
"1,024.80000","0.34161","213.16627"
"1,025.60000","0.34188","213.23959"
"1,026.40000","0.34214","213.18590"
"1,027.20000","0.34241","213.26262"
"1,028.00000","0.34267","213.32914"
"1,028.80000","0.34294","213.61796"
"1,029.60000","0.34321","213.75561"
"1,030.40000","0.34347","213.86866"
"1,031.20000","0.34374","213.80680"
"1,032.00000","0.34401","213.91055"
"1,032.80000","0.34427","214.01810"
"1,033.60000","0.34454","214.12697"
"1,034.40000","0.34481","214.35962"
"1,035.20000","0.34507","214.19193"
"1,036.00000","0.34534","214.32493"
"1,036.80000","0.34561","214.24967"
"1,037.60000","0.34587","214.26541"
"1,038.40000","0.34614","214.51593"
"1,039.20000","0.34641","214.53945"
"1,040.00000","0.34668","214.69627"
"1,040.80000","0.34694","214.67608"
"1,041.60000","0.34720","214.59243"
"1,042.40000","0.34748","214.84431"
"1,043.20000","0.34774","214.88160"
"1,044.00000","0.34801","215.08133"
"1,044.80000","0.34828","215.14160"
"1,045.60000","0.34854","214.92385"
"1,046.40000","0.34881","214.94967"
"1,047.20000","0.34907","214.84794"
"1,048.00000","0.34934","215.02001"
"1,048.80000","0.34961","215.02654"
"1,049.60000","0.34988","215.06280"
"1,050.40000","0.35014","214.89698"
"1,051.20000","0.35040","215.01606"
"1,052.00000","0.35067","215.10668"
"1,052.80000","0.35094","215.23599"
"1,053.60000","0.35121","215.49976"
"1,054.40000","0.35147","215.37687"
"1,055.20000","0.35174","215.55767"
"1,056.00000","0.35201","215.50994"
"1,056.80000","0.35227","215.54387"
"1,057.60000","0.35255","215.81334"
"1,058.40000","0.35281","215.74531"
"1,059.20000","0.35308","215.97879"
"1,060.00000","0.35334","215.84404"
"1,060.80000","0.35360","215.71720"
"1,061.60000","0.35387","215.93174"
"1,062.40000","0.35414","216.00452"
"1,063.20000","0.35441","216.09486"
"1,064.00000","0.35468","216.15147"
"1,064.80000","0.35494","216.03309"
"1,065.60000","0.35521","216.11059"
"1,066.40000","0.35547","216.12182"
"1,067.20000","0.35574","216.26986"
"1,068.00000","0.35601","216.39134"
"1,068.80000","0.35628","216.43796"
"1,069.60000","0.35654","216.33557"
"1,070.40000","0.35680","216.36101"
"1,071.20000","0.35707","216.44359"
"1,072.00000","0.35734","216.51856"
"1,072.80000","0.35761","216.70949"
"1,073.60000","0.35787","216.48081"
"1,074.40000","0.35814","216.63262"
"1,075.20000","0.35840","216.63505"
"1,076.00000","0.35867","216.67884"
"1,076.80000","0.35895","216.96313"
"1,077.60000","0.35921","216.92028"
"1,078.40000","0.35948","217.16663"
"1,079.20000","0.35974","217.06073"
"1,080.00000","0.36000","217.04370"
"1,080.80000","0.36027","217.25691"
"1,081.60000","0.36054","217.35451"
"1,082.40000","0.36081","217.55479"
"1,083.20000","0.36108","217.64068"
"1,084.00000","0.36134","217.60217"
"1,084.80000","0.36161","217.71644"
"1,085.60000","0.36187","217.76341"
"1,086.40000","0.36214","217.91836"
"1,087.20000","0.36241","218.02729"
"1,088.00000","0.36268","218.11861"
"1,088.80000","0.36294","218.04594"
"1,089.60000","0.36320","218.17368"
"1,090.40000","0.36347","218.34132"
"1,091.20000","0.36374","218.47861"
"1,092.00000","0.36401","218.74878"
"1,092.80000","0.36427","218.66130"
"1,093.60000","0.36454","218.75821"
"1,094.40000","0.36481","218.71175"
"1,095.20000","0.36507","218.70339"
"1,096.00000","0.36534","218.94313"
"1,096.80000","0.36561","218.99139"
"1,097.60000","0.36588","219.16507"
"1,098.40000","0.36614","219.12980"
"1,099.20000","0.36640","219.04833"
"1,100.00000","0.36668","219.20156"
"1,100.80000","0.36694","219.34954"
"1,101.60000","0.36721","219.57333"
"1,102.40000","0.36748","219.70323"
"1,103.20000","0.36774","219.74456"
"1,104.00000","0.36801","219.91176"
"1,104.80000","0.36827","220.00669"
"1,105.60000","0.36854","220.23989"
"1,106.40000","0.36881","220.36349"
"1,107.20000","0.36907","220.44587"
"1,108.00000","0.36934","220.37084"
"1,108.80000","0.36960","220.43766"
"1,109.60000","0.36987","220.45904"
"1,110.40000","0.37014","220.62482"
"1,111.20000","0.37041","220.96090"
"1,112.00000","0.37067","220.86898"
"1,112.80000","0.37094","221.01265"
"1,113.60000","0.37121","220.98713"
"1,114.40000","0.37147","221.10136"
"1,115.20000","0.37174","221.36832"
"1,116.00000","0.37201","221.41121"
"1,116.80000","0.37228","221.60826"
"1,117.60000","0.37254","221.58122"
"1,118.40000","0.37280","221.54350"
"1,119.20000","0.37307","221.86385"
"1,120.00000","0.37334","221.97354"
"1,120.80000","0.37361","222.13999"
"1,121.60000","0.37388","222.25742"
"1,122.40000","0.37414","222.10497"
"1,123.20000","0.37441","222.27892"
"1,124.00000","0.37467","222.21082"
"1,124.80000","0.37494","222.43804"
"1,125.60000","0.37521","222.49918"
"1,126.40000","0.37547","222.45732"
"1,127.20000","0.37574","222.45679"
"1,128.00000","0.37600","222.53763"
"1,128.80000","0.37627","222.67372"
"1,129.60000","0.37654","222.69876"
"1,130.40000","0.37681","222.91741"
"1,131.20000","0.37707","222.75181"
"1,132.00000","0.37734","222.88732"
"1,132.80000","0.37760","222.79582"
"1,133.60000","0.37787","222.92638"
"1,134.40000","0.37814","223.20995"
"1,135.20000","0.37841","223.19417"
"1,136.00000","0.37868","223.40399"
"1,136.08500","0.37871","223.44780"