File: materials_lab1/ENGR314_FA19_0001_1080SpringSteel_A_20190903_Pasta_1.is_tens_RawData/Specimen_RawData_2.csv
Material,Steel
Geometry,Circular
Length,"2.00000",in
Diameter,"0.06200",in

Time,Extension,Load
(s),(in),(lbf)
"0.00000","0.02234","4.89625"
"0.40000","0.02248","5.80300"
"0.80000","0.02261","6.83008"
"1.20000","0.02274","7.90478"
"1.60000","0.02287","8.91747"
"2.00000","0.02301","10.03036"
"2.40000","0.02314","11.05879"
"2.80000","0.02327","12.08842"
"3.20000","0.02341","13.25008"
"3.60000","0.02354","14.33120"
"4.00000","0.02367","15.41437"
"4.40000","0.02380","16.52795"
"4.80000","0.02394","17.66500"
"5.20000","0.02408","18.85557"
"5.60000","0.02421","19.95945"
"6.00000","0.02434","21.17706"
"6.40000","0.02447","22.23173"
"6.80000","0.02461","23.48048"
"7.20000","0.02474","24.66202"
"7.60000","0.02487","25.76734"
"8.00000","0.02501","26.97971"
"8.40000","0.02514","28.07342"
"8.80000","0.02528","29.32292"
"9.20000","0.02541","30.45438"
"9.60000","0.02554","31.61539"
"10.00000","0.02567","32.74552"
"10.40000","0.02580","33.81140"
"10.80000","0.02595","35.08558"
"11.20000","0.02607","36.17960"
"11.60000","0.02621","37.33564"
"12.00000","0.02634","38.49332"
"12.40000","0.02647","39.64572"
"12.80000","0.02661","40.88821"
"13.20000","0.02674","41.98087"
"13.60000","0.02688","43.28819"
"14.00000","0.02701","44.40346"
"14.40000","0.02714","45.62020"
"14.80000","0.02728","46.90877"
"15.20000","0.02741","48.06742"
"15.60000","0.02754","49.27141"
"16.00000","0.02767","50.42044"
"16.40000","0.02781","51.71057"
"16.80000","0.02794","52.91276"
"17.20000","0.02807","54.09289"
"17.60000","0.02821","55.37113"
"18.00000","0.02833","56.44345"
"18.40000","0.02848","57.83168"
"18.80000","0.02861","59.00316"
"19.20000","0.02874","60.15211"
"19.60000","0.02887","61.42300"
"20.00000","0.02901","62.56495"
"20.40000","0.02914","63.78603"
"20.80000","0.02927","64.78358"
"21.20000","0.02941","65.93599"
"21.60000","0.02954","66.83664"
"22.00000","0.02967","67.74567"
"22.40000","0.02981","68.75634"
"22.80000","0.02994","69.53433"
"23.20000","0.03007","70.38230"
"23.60000","0.03020","71.23195"
"24.00000","0.03034","72.11156"
"24.40000","0.03048","72.95784"
"24.80000","0.03061","73.69543"
"25.20000","0.03074","74.59327"
"25.60000","0.03087","75.29314"
"26.00000","0.03101","76.21584"
"26.40000","0.03114","77.02013"
"26.80000","0.03127","77.74563"
"27.20000","0.03141","78.66207"
"27.60000","0.03154","79.36769"
"28.00000","0.03167","80.21162"
"28.40000","0.03181","80.90329"
"28.80000","0.03194","81.67194"
"29.20000","0.03207","82.38468"
"29.60000","0.03220","82.98680"
"30.00000","0.03234","83.78183"
"30.40000","0.03247","84.37417"
"30.80000","0.03261","85.03789"
"31.20000","0.03274","85.75020"
"31.60000","0.03287","86.31671"
"32.00000","0.03301","86.95000"
"32.40000","0.03314","87.38886"
"32.80000","0.03328","88.03401"
"33.20000","0.03340","88.44779"
"33.60000","0.03354","89.03928"
"34.00000","0.03368","89.56164"
"34.40000","0.03381","89.95351"
"34.80000","0.03394","90.51432"
"35.20000","0.03407","90.89226"
"35.60000","0.03421","91.39868"
"36.00000","0.03434","91.67561"
"36.40000","0.03447","91.81469"
"36.80000","0.03461","92.01520"
"37.20000","0.03474","92.03473"
"37.60000","0.03488","92.32215"
"38.00000","0.03501","92.42758"
"38.40000","0.03514","92.55930"
"38.80000","0.03527","92.81397"
"39.20000","0.03540","92.92135"
"39.60000","0.03554","93.17063"
"40.00000","0.03567","93.13924"
"40.40000","0.03581","93.34273"
"40.80000","0.03594","93.30231"
"41.20000","0.03607","93.35820"
"41.60000","0.03621","93.40690"
"42.00000","0.03634","93.33497"
"42.40000","0.03647","93.37945"
"42.80000","0.03661","93.37059"
"43.20000","0.03674","93.49216"
"43.60000","0.03688","93.50544"
"44.00000","0.03701","93.52389"
"44.40000","0.03714","93.73609"
"44.80000","0.03727","93.72567"
"45.20000","0.03741","94.01879"
"45.60000","0.03754","94.08413"
"46.00000","0.03767","94.08960"
"46.40000","0.03781","94.23310"
"46.80000","0.03794","94.11313"
"47.20000","0.03808","94.11510"
"47.60000","0.03821","93.78847"
"48.00000","0.03834","93.34508"
"48.40000","0.03847","92.99621"
"48.80000","0.03860","92.70641"
"49.20000","0.03875","92.42831"
"49.60000","0.03887","92.23186"
"50.00000","0.03901","92.33614"
"50.40000","0.03914","92.38677"
"50.80000","0.03927","92.45466"
"51.20000","0.03941","92.49215"
"51.60000","0.03954","92.40307"
"52.00000","0.03968","92.57176"
"52.40000","0.03981","92.51855"
"52.80000","0.03994","92.64560"
"53.20000","0.04008","92.76417"
"53.60000","0.04020","92.80618"
"54.00000","0.04034","92.99104"
"54.40000","0.04047","93.03571"
"54.80000","0.04061","93.27601"
"55.20000","0.04074","93.42199"
"55.60000","0.04087","93.58152"
"56.00000","0.04101","93.81736"
"56.40000","0.04113","93.82667"
"56.80000","0.04128","94.07552"
"57.20000","0.04141","94.04929"
"57.60000","0.04154","94.09905"
"58.00000","0.04167","94.18037"
"58.40000","0.04181","94.26237"
"58.80000","0.04194","94.42953"
"59.20000","0.04207","94.43726"
"59.60000","0.04221","94.59636"
"60.00000","0.04234","94.64651"
"60.40000","0.04247","94.73792"
"60.80000","0.04261","94.87783"
"61.20000","0.04274","94.90641"
"61.60000","0.04287","95.09739"
"62.00000","0.04301","95.14908"
"62.40000","0.04314","95.28539"
"62.80000","0.04328","95.32302"
"63.20000","0.04341","95.40077"
"63.60000","0.04354","95.58925"
"64.00000","0.04367","95.52784"
"64.40000","0.04381","95.73004"
"64.80000","0.04394","95.75119"
"65.20000","0.04407","95.65253"
"65.60000","0.04421","95.77909"
"66.00000","0.04434","95.77751"
"66.40000","0.04448","96.08597"
"66.80000","0.04461","96.24764"
"67.20000","0.04474","96.58185"
"67.60000","0.04487","96.86774"
"68.00000","0.04500","97.14732"
"68.40000","0.04515","97.63067"
"68.80000","0.04527","97.86718"
"69.20000","0.04541","98.18748"
"69.60000","0.04554","98.53288"
"70.00000","0.04567","98.90168"
"70.40000","0.04581","99.27980"
"70.80000","0.04594","99.57151"
"71.20000","0.04608","100.01412"
"71.60000","0.04621","100.26124"
"72.00000","0.04634","100.69843"
"72.40000","0.04648","101.13986"
"72.80000","0.04661","101.44496"
"73.20000","0.04674","101.85937"
"73.60000","0.04687","102.14172"
"74.00000","0.04701","102.61375"
"74.40000","0.04714","102.92355"
"74.80000","0.04727","103.25239"
"75.20000","0.04741","103.68224"
"75.60000","0.04754","103.85835"
"76.00000","0.04767","104.37597"
"76.40000","0.04781","104.61229"
"76.80000","0.04794","104.92850"
"77.20000","0.04807","105.26642"
"77.60000","0.04821","105.50233"
"78.00000","0.04834","105.93378"
"78.40000","0.04847","106.18052"
"78.80000","0.04861","106.62122"
"79.20000","0.04874","106.87623"
"79.60000","0.04887","107.18414"
"80.00000","0.04901","107.63783"
"80.40000","0.04914","107.84396"
"80.80000","0.04927","108.15008"
"81.20000","0.04940","108.43675"
"81.60000","0.04954","108.79565"
"82.00000","0.04967","109.07919"
"82.40000","0.04980","109.27865"
"82.80000","0.04994","109.59118"
"83.20000","0.05007","109.84128"
"83.60000","0.05021","109.52797"
"84.00000","0.05034","109.39743"
"84.40000","0.05047","110.56120"
"84.80000","0.05061","111.44262"
"85.20000","0.05074","111.87136"
"85.60000","0.05088","112.40251"
"86.00000","0.05101","112.69534"
"86.40000","0.05114","113.16306"
"86.80000","0.05127","113.54986"
"87.20000","0.05140","113.92141"
"87.60000","0.05155","114.51739"
"88.00000","0.05167","114.82727"
"88.40000","0.05181","115.21098"
"88.80000","0.05194","115.64235"
"89.20000","0.05207","116.07708"
"89.60000","0.05221","116.50555"
"90.00000","0.05234","116.79680"
"90.40000","0.05248","117.31483"
"90.80000","0.05261","118.20336"
"91.20000","0.05274","118.81991"
"91.60000","0.05288","119.07606"
"92.00000","0.05301","120.28589"
"92.40000","0.05314","121.64751"
"92.62800","0.05322","99.63637"
"93.02800","0.05335","105.96494"
"93.42800","0.05349","106.78581"
"93.82800","0.05361","108.86699"
"94.22800","0.05375","115.39818"
"94.56400","0.05386","128.04037"
"94.96400","0.05399","131.78755"
"95.36400","0.05413","135.59030"
"95.76400","0.05426","136.09875"
"96.16400","0.05439","134.57757"
"96.56400","0.05453","136.26649"
"96.96400","0.05466","138.23293"
"97.36400","0.05480","140.18305"
"97.76400","0.05493","141.95512"
"98.16400","0.05507","143.95949"
"98.56400","0.05519","145.67015"
"98.96400","0.05533","147.62452"
"99.36400","0.05547","149.55416"
"99.76400","0.05559","151.30519"
"100.16400","0.05573","153.18437"
"100.56400","0.05586","154.97826"
"100.96400","0.05600","156.98473"
"101.36400","0.05613","158.73815"
"101.76400","0.05626","160.59554"
"102.16400","0.05640","162.56327"
"102.56400","0.05652","164.30813"
"102.96400","0.05667","166.43614"
"103.36400","0.05680","168.22981"
"103.76400","0.05693","170.01020"
"104.16400","0.05706","171.83934"
"104.56400","0.05719","173.65357"
"104.96400","0.05733","175.60399"
"105.36400","0.05746","177.26287"
"105.76400","0.05760","179.23534"
"106.16400","0.05773","180.89384"
"106.56400","0.05786","182.65962"
"106.96400","0.05800","184.55167"
"107.36400","0.05813","186.21153"
"107.76400","0.05826","187.97803"
"108.16400","0.05839","189.68265"
"108.56400","0.05853","191.40205"
"108.96400","0.05866","193.18971"
"109.36400","0.05879","194.79017"
"109.76400","0.05893","196.56523"
"110.16400","0.05906","198.06798"
"110.56400","0.05920","199.91977"
"110.96400","0.05933","201.55904"
"111.36400","0.05946","203.11022"
"111.76400","0.05959","204.80964"
"112.16400","0.05973","206.37381"
"112.56400","0.05987","208.12459"
"112.96400","0.05999","209.64486"
"113.36400","0.06013","211.31965"
"113.76400","0.06026","212.89443"
"114.16400","0.06039","214.35273"
"114.56400","0.06053","216.17923"
"114.96400","0.06066","217.68636"
"115.36400","0.06079","219.23775"
"115.76400","0.06093","220.84226"
"116.16400","0.06106","222.39055"
"116.56400","0.06120","224.08778"
"116.96400","0.06133","225.55323"
"117.36400","0.06147","227.26123"
"117.76400","0.06159","228.64661"
"118.16400","0.06173","230.31241"
"118.56400","0.06187","231.92852"
"118.96400","0.06199","233.37156"
"119.36400","0.06213","234.98773"
"119.76400","0.06226","236.38351"
"120.16400","0.06240","238.04008"
"120.56400","0.06253","239.52255"
"120.96400","0.06266","241.04552"
"121.36400","0.06280","242.61962"
"121.76400","0.06292","243.94425"
"122.16400","0.06307","245.77804"
"122.56400","0.06320","247.19080"
"122.96400","0.06333","248.63442"
"123.36400","0.06346","250.21664"
"123.76400","0.06359","251.64966"
"124.16400","0.06373","253.26355"
"124.56400","0.06386","254.62415"
"124.96400","0.06400","256.26189"
"125.36400","0.06413","257.57765"
"125.76400","0.06426","259.04566"
"126.16400","0.06440","260.64344"
"126.56400","0.06453","261.96988"
"126.96400","0.06466","263.43325"
"127.36400","0.06479","264.75902"
"127.76400","0.06493","266.29270"
"128.16400","0.06506","267.69090"
"128.56400","0.06519","268.97894"
"128.96400","0.06533","270.45751"
"129.36400","0.06546","271.65708"
"129.76400","0.06560","273.24394"
"130.16400","0.06573","274.58459"
"130.56400","0.06586","275.82441"
"130.96400","0.06600","277.28438"
"131.36400","0.06612","278.48562"
"131.76400","0.06627","280.04463"
"132.16400","0.06639","281.24686"
"132.56400","0.06653","282.70202"
"132.96400","0.06666","284.02607"
"133.36400","0.06679","285.20536"
"133.76400","0.06693","286.79633"
"134.16400","0.06706","287.98020"
"134.56400","0.06719","289.29492"
"134.96400","0.06733","290.62196"
"135.36400","0.06746","291.87567"
"135.76400","0.06760","293.24008"
"136.16400","0.06773","294.37181"
"136.56400","0.06787","295.77395"
"136.96400","0.06799","296.76781"
"137.36400","0.06813","298.08255"
"137.76400","0.06827","299.36412"
"138.16400","0.06839","300.40090"
"138.56400","0.06853","301.76298"
"138.96400","0.06866","302.83137"
"139.36400","0.06880","304.25566"
"139.76400","0.06893","305.36859"
"140.16400","0.06906","306.54341"
"140.56400","0.06920","307.83013"
"140.96400","0.06932","308.84531"
"141.36400","0.06947","310.26433"
"141.76400","0.06959","311.32323"
"142.16400","0.06973","312.42612"
"142.56400","0.06986","313.63984"
"142.96400","0.06999","314.71902"
"143.36400","0.07013","315.86612"
"143.76400","0.07026","316.83176"
"144.16400","0.07040","317.94982"
"144.56400","0.07053","318.84761"
"144.96400","0.07066","319.89766"
"145.36400","0.07080","321.05780"
"145.76400","0.07093","322.03560"
"146.16400","0.07106","323.19203"
"146.56400","0.07119","324.19420"
"146.96400","0.07133","325.43175"
"147.36400","0.07146","326.55510"
"147.76400","0.07159","327.58557"
"148.16400","0.07173","328.79288"
"148.56400","0.07186","329.66052"
"148.96400","0.07200","330.91706"
"149.36400","0.07213","332.02667"
"149.76400","0.07226","332.97050"
"150.16400","0.07240","334.10514"
"150.56400","0.07253","335.07183"
"150.96400","0.07267","336.31379"
"151.36400","0.07279","337.26975"
"151.76400","0.07293","338.34253"
"152.16400","0.07306","339.36825"
"152.56400","0.07319","340.30025"
"152.96400","0.07333","341.59140"
"153.36400","0.07346","342.52870"
"153.76400","0.07359","343.52499"
"154.16400","0.07373","344.60804"
"154.56400","0.07386","345.63197"
"154.96400","0.07400","346.68596"
"155.36400","0.07413","347.63423"
"155.76400","0.07427","348.88646"
"156.16400","0.07439","349.79256"
"156.56400","0.07453","350.92593"
"156.96400","0.07467","352.10113"
"157.36400","0.07479","353.00418"
"157.76400","0.07493","354.20995"
"158.16400","0.07506","355.16078"
"158.56400","0.07520","356.43197"
"158.96400","0.07533","357.45291"
"159.36400","0.07546","358.48055"
"159.76400","0.07560","359.62268"
"160.16400","0.07572","360.50748"
"160.56400","0.07587","361.81407"
"160.96400","0.07600","362.85321"
"161.36400","0.07613","363.83439"
"161.76400","0.07626","365.00160"
"162.16400","0.07639","366.04324"
"162.56400","0.07653","367.22760"
"162.96400","0.07666","368.12755"
"163.36400","0.07680","369.42050"
"163.76400","0.07693","370.38052"
"164.16400","0.07706","371.37740"
"164.56400","0.07720","372.60858"
"164.96400","0.07733","373.52354"
"165.36400","0.07746","374.58748"
"165.76400","0.07759","375.52777"
"166.16400","0.07773","376.66186"
"166.56400","0.07786","377.74046"
"166.96400","0.07799","378.70691"
"167.36400","0.07813","379.92082"
"167.76400","0.07826","380.82003"
"168.16400","0.07840","382.02885"
"168.56400","0.07853","383.16579"
"168.96400","0.07866","384.17636"
"169.36400","0.07880","385.35694"
"169.76400","0.07893","386.38680"
"170.16400","0.07907","387.68296"
"170.56400","0.07919","388.63796"
"170.96400","0.07933","389.81766"
"171.36400","0.07946","390.92151"
"171.76400","0.07959","391.87453"
"172.16400","0.07974","393.21814"
"172.56400","0.07986","394.15744"
"172.96400","0.07999","395.17161"
"173.36400","0.08013","396.23871"
"173.76400","0.08026","397.34700"
"174.16400","0.08040","398.55883"
"174.56400","0.08053","399.46287"
"174.96400","0.08067","400.71466"
"175.36400","0.08079","401.61513"
"175.76400","0.08093","402.70756"
"176.16400","0.08107","403.90982"
"176.56400","0.08119","404.87075"
"176.96400","0.08133","405.97671"
"177.36400","0.08146","406.96760"
"177.76400","0.08160","408.19540"
"178.16400","0.08173","409.25353"
"178.56400","0.08186","410.28842"
"178.96400","0.08200","411.43713"
"179.36400","0.08212","412.26115"
"179.76400","0.08227","413.67894"
"180.16400","0.08240","414.65045"
"180.56400","0.08253","415.62711"
"180.96400","0.08266","416.74182"
"181.36400","0.08279","417.84627"
"181.76400","0.08293","419.05072"
"182.16400","0.08306","419.91955"
"182.56400","0.08320","421.22200"
"182.96400","0.08333","422.22541"
"183.36400","0.08346","423.24575"
"183.76400","0.08360","424.50237"
"184.16400","0.08373","425.47087"
"184.56400","0.08386","426.49711"
"184.96400","0.08399","427.59017"
"185.36400","0.08413","428.73076"
"185.76400","0.08426","429.85253"
"186.16400","0.08439","430.81403"
"186.56400","0.08453","432.04033"
"186.96400","0.08466","432.90051"
"187.36400","0.08480","434.14061"
"187.76400","0.08493","435.28900"
"188.16400","0.08506","436.22660"
"188.56400","0.08520","437.39120"
"188.96400","0.08533","438.37507"
"189.36400","0.08546","439.54357"
"189.76400","0.08559","440.56440"
"190.16400","0.08573","441.68757"
"190.56400","0.08586","442.77180"
"190.96400","0.08599","443.65682"
"191.36400","0.08613","444.99601"
"191.76400","0.08626","445.92886"
"192.16400","0.08639","446.94187"
"192.56400","0.08653","447.99712"
"192.96400","0.08666","449.02750"
"193.36400","0.08680","450.14897"
"193.76400","0.08692","451.01610"
"194.16400","0.08707","452.25260"
"194.56400","0.08719","453.08370"
"194.96400","0.08733","454.15066"
"195.36400","0.08747","455.26664"
"195.76400","0.08759","456.17990"
"196.16400","0.08773","457.27441"
"196.56400","0.08786","458.17716"
"196.96400","0.08800","459.36512"
"197.36400","0.08813","460.38615"
"197.76400","0.08826","461.35286"
"198.16400","0.08840","462.43722"
"198.56400","0.08852","463.26709"
"198.96400","0.08867","464.54410"
"199.36400","0.08880","465.53636"
"199.76400","0.08893","466.44987"
"200.16400","0.08906","467.55882"
"200.56400","0.08919","468.54790"
"200.96400","0.08933","469.76788"
"201.36400","0.08946","470.63342"
"201.76400","0.08960","471.84759"
"202.16400","0.08973","472.80604"
"202.56400","0.08986","473.81258"
"202.96400","0.09000","475.00380"
"203.36400","0.09013","475.93547"
"203.76400","0.09026","476.95721"
"204.16400","0.09039","477.98049"
"204.56400","0.09053","479.00849"
"204.96400","0.09066","480.22940"
"205.36400","0.09079","481.00723"
"205.76400","0.09093","482.23188"
"206.16400","0.09106","482.98682"
"206.56400","0.09120","484.22854"
"206.96400","0.09133","485.25945"
"207.36400","0.09146","486.07608"
"207.76400","0.09159","487.18591"
"208.16400","0.09173","488.08646"
"208.56400","0.09187","489.23795"
"208.96400","0.09200","490.15091"
"209.36400","0.09213","491.05865"
"209.76400","0.09226","492.05734"
"210.16400","0.09239","492.85663"
"210.56400","0.09253","494.08781"
"210.96400","0.09266","494.94259"
"211.36400","0.09279","495.81487"
"211.76400","0.09293","496.79924"
"212.16400","0.09306","497.73151"
"212.56400","0.09320","498.73920"
"212.96400","0.09333","499.50282"
"213.36400","0.09347","500.65699"
"213.76400","0.09359","501.42011"
"214.16400","0.09373","502.34289"
"214.56400","0.09387","503.37830"
"214.96400","0.09399","504.15646"
"215.36400","0.09413","505.22650"
"215.76400","0.09426","506.09203"
"216.16400","0.09440","507.17952"
"216.56400","0.09453","508.11191"
"216.96400","0.09466","508.99479"
"217.36400","0.09480","510.06790"
"217.76400","0.09492","510.76637"
"218.16400","0.09507","512.04113"
"218.56400","0.09520","512.88905"
"218.96400","0.09533","513.74328"
"219.36400","0.09546","514.76243"
"219.76400","0.09559","515.60108"
"220.16400","0.09573","516.63665"
"220.56400","0.09586","517.42985"
"220.96400","0.09600","518.43567"
"221.36400","0.09613","519.27585"
"221.76400","0.09626","520.08891"
"222.16400","0.09640","521.17053"
"222.56400","0.09653","521.86834"
"222.96400","0.09666","522.86050"
"223.36400","0.09679","523.70808"
"223.76400","0.09693","524.74327"
"224.16400","0.09706","525.66270"
"224.56400","0.09719","526.47050"
"224.96400","0.09733","527.49317"
"225.36400","0.09746","528.24416"
"225.76400","0.09760","529.43780"
"226.16400","0.09773","530.37063"
"226.56400","0.09786","531.18556"
"226.96400","0.09800","532.24314"
"227.36400","0.09812","532.97931"
"227.76400","0.09827","534.15281"
"228.16400","0.09839","534.98377"
"228.56400","0.09853","535.90715"
"228.96400","0.09866","536.84799"
"229.36400","0.09879","537.61062"
"229.76400","0.09893","538.76298"
"230.16400","0.09906","539.58329"
"230.56400","0.09919","540.44395"
"230.96400","0.09933","541.41557"
"231.36400","0.09946","542.33556"
"231.76400","0.09960","543.37958"
"232.16400","0.09973","544.19643"
"232.56400","0.09987","545.30357"
"232.96400","0.09999","546.11878"
"233.36400","0.10013","547.10671"
"233.76400","0.10026","548.17773"
"234.16400","0.10039","549.04042"
"234.56400","0.10053","550.04267"
"234.96400","0.10065","550.85365"
"235.36400","0.10080","551.99010"
"235.76400","0.10093","552.95366"
"236.16400","0.10106","553.83731"
"236.56400","0.10120","554.87387"
"236.96400","0.10132","555.63051"
"237.36400","0.10147","556.79128"
"237.76400","0.10160","557.70341"
"238.16400","0.10173","558.52718"
"238.56400","0.10186","559.60452"
"238.96400","0.10199","560.40419"
"239.36400","0.10213","561.48778"
"239.76400","0.10226","562.29904"
"240.16400","0.10240","563.36551"
"240.56400","0.10253","564.27386"
"240.96400","0.10266","565.12271"
"241.36400","0.10280","566.34544"
"241.76400","0.10293","567.17892"
"242.16400","0.10306","568.14264"
"242.56400","0.10319","569.09611"
"242.96400","0.10333","570.11774"
"243.36400","0.10346","571.13876"
"243.76400","0.10359","571.96972"
"244.16400","0.10373","573.14475"
"244.56400","0.10386","573.93427"
"244.96400","0.10399","575.00502"
"245.36400","0.10413","576.07572"
"245.76400","0.10426","576.93862"
"246.16400","0.10440","578.09812"
"246.56400","0.10452","579.10532"
"246.96400","0.10467","580.42612"
"247.36400","0.10479","581.40077"
"247.76400","0.10493","582.51916"
"248.16400","0.10506","583.56983"
"248.56400","0.10519","584.42752"
"248.96400","0.10534","585.70463"
"249.36400","0.10546","586.61238"
"249.76400","0.10559","587.52780"
"250.16400","0.10573","588.55009"
"250.56400","0.10586","589.47787"
"250.96400","0.10600","590.55372"
"251.36400","0.10613","591.36624"
"251.76400","0.10627","592.51504"
"252.16400","0.10639","593.24117"
"252.56400","0.10653","594.18546"
"252.96400","0.10667","595.26626"
"253.36400","0.10679","596.05430"
"253.76400","0.10693","596.97115"
"254.16400","0.10706","597.76243"
"254.56400","0.10719","598.75469"
"254.96400","0.10733","599.65168"
"255.36400","0.10746","600.45558"
"255.76400","0.10760","601.36832"
"256.16400","0.10772","602.00191"
"256.56400","0.10787","603.04851"
"256.96400","0.10800","603.83842"
"257.36400","0.10813","604.51224"
"257.76400","0.10826","605.32278"
"258.16400","0.10839","606.09424"
"258.56400","0.10853","606.96724"
"258.96400","0.10866","607.58893"
"259.36400","0.10880","608.38767"
"259.76400","0.10893","609.07214"
"260.16400","0.10906","609.66748"
"260.56400","0.10920","610.52813"
"260.96400","0.10933","611.10041"
"261.36400","0.10946","611.69624"
"261.76400","0.10959","612.27056"
"262.16400","0.10973","612.90053"
"262.56400","0.10986","613.46782"
"262.96400","0.10999","613.82221"
"263.36400","0.11013","614.43588"
"263.76400","0.11026","614.56832"
"264.16400","0.11039","614.98572"
"264.56400","0.11053","615.21706"
"264.96400","0.11066","615.19461"
"265.36400","0.11079","615.25427"
"265.76400","0.11092","615.21970"
"266.16400","0.11106","615.30910"
"266.56400","0.11119","615.09127"
"266.96400","0.11133","614.81240"
"267.36400","0.11146","614.32902"
"267.76400","0.11159","613.35520"
"268.16400","0.11174","612.33170"
"268.56400","0.11186","609.67999"
"268.96400","0.11199","600.09427"
"268.97500","0.11204","565.94132"
"268.97900","0.11206","534.21121"
"268.98300","0.11208","498.60111"
"268.98700","0.11210","462.01532"
"268.99100","0.11211","426.69557"
"268.99500","0.11212","394.18195"
"268.99900","0.11212","365.40402"
"269.00300","0.11212","340.75251"
"269.01100","0.11212","303.94328"
"269.02100","0.11212","278.28200"
"269.26900","0.11211","281.89650"
"269.66900","0.11222","284.02569"
"270.06900","0.11236","287.83687"
"270.46900","0.11249","290.95393"
"270.86900","0.11263","294.21599"
"271.26900","0.11276","297.36052"
"271.66900","0.11289","300.26994"
"272.06900","0.11303","303.58609"
"272.46900","0.11316","306.48816"
"272.86900","0.11330","309.44877"
"273.26900","0.11343","312.41857"
"273.66900","0.11356","315.38837"
"274.06900","0.11370","318.40666"
"274.46900","0.11383","321.14350"
"274.86900","0.11397","324.22337"
"275.26900","0.11409","326.81685"
"275.66900","0.11423","329.69724"
"276.06900","0.11437","332.62445"
"276.46900","0.11450","335.28632"
"276.86900","0.11463","338.16880"
"277.26900","0.11476","340.76288"
"277.66900","0.11490","343.68949"
"278.06900","0.11503","346.41612"
"278.46900","0.11516","349.15474"
"278.86900","0.11530","351.94290"
"279.26900","0.11542","354.44774"
"279.66900","0.11557","357.34709"
"280.06900","0.11570","359.97993"
"280.46900","0.11583","362.50689"
"280.86900","0.11596","365.17745"
"281.26900","0.11609","367.79549"
"281.66900","0.11623","370.66241"
"282.06900","0.11636","373.16668"
"282.46900","0.11650","376.04891"
"282.86900","0.11663","378.59239"
"283.26900","0.11676","381.23579"
"283.66900","0.11690","384.06014"
"284.06900","0.11703","386.65458"
"284.46900","0.11716","389.27449"
"284.86900","0.11729","391.86619"
"285.26900","0.11743","394.63085"
"285.66900","0.11756","397.34401"
"286.06900","0.11770","399.85390"
"286.46900","0.11783","402.61780"
"286.86900","0.11796","405.06202"
"287.26900","0.11810","407.86815"
"287.66900","0.11823","410.51333"
"288.06900","0.11836","412.97501"
"288.46900","0.11850","415.68731"
"288.86900","0.11863","418.20269"
"289.26900","0.11877","420.96335"
"289.66900","0.11890","423.46380"
"290.06900","0.11903","426.05267"
"290.46900","0.11916","428.65911"
"290.86900","0.11929","431.06801"
"291.26900","0.11943","433.92140"
"291.66900","0.11956","436.40445"
"292.06900","0.11970","438.94859"
"292.46900","0.11983","441.51929"
"292.86900","0.11996","444.08423"
"293.26900","0.12010","446.72813"
"293.66900","0.12023","449.10588"
"294.06900","0.12037","451.82793"
"294.46900","0.12049","454.20461"
"294.86900","0.12063","456.79082"
"295.26900","0.12077","459.40099"
"295.66900","0.12089","461.73387"
"296.06900","0.12103","464.32516"
"296.46900","0.12116","466.77281"
"296.86900","0.12130","469.43330"
"297.26900","0.12143","471.87997"
"297.66900","0.12156","474.31884"
"298.06900","0.12170","476.88158"
"298.46900","0.12182","479.10657"
"298.86900","0.12197","481.88078"
"299.26900","0.12210","484.26131"
"299.66900","0.12223","486.63366"
"300.06900","0.12236","489.14174"
"300.46900","0.12250","491.50503"
"300.86900","0.12263","494.08676"
"301.26900","0.12276","496.38079"
"301.66900","0.12290","498.92093"
"302.06900","0.12303","501.30310"
"302.46900","0.12316","503.65591"
"302.86900","0.12330","506.19714"
"303.26900","0.12343","508.44298"
"303.66900","0.12356","510.96280"
"304.06900","0.12369","513.26237"
"304.46900","0.12383","515.78609"
"304.86900","0.12396","518.17853"
"305.26900","0.12410","520.43513"
"305.66900","0.12423","522.96478"
"306.06900","0.12435","525.14322"
"306.46900","0.12450","527.69784"
"306.86900","0.12463","530.13023"
"307.26900","0.12476","532.33644"
"307.66900","0.12490","534.85797"
"308.06900","0.12503","537.01308"
"308.46900","0.12517","539.58121"
"308.86900","0.12530","541.67183"
"309.26900","0.12543","544.08414"
"309.66900","0.12556","546.48991"
"310.06900","0.12569","548.59920"
"310.46900","0.12583","551.17188"
"310.86900","0.12596","553.29872"
"311.26900","0.12610","555.59034"
"311.66900","0.12623","557.81839"
"312.06900","0.12636","560.07982"
"312.46900","0.12650","562.47884"
"312.86900","0.12663","564.53890"
"313.26900","0.12677","566.87974"
"313.66900","0.12689","568.88233"
"314.06900","0.12703","571.11154"
"314.46900","0.12717","573.37900"
"314.86900","0.12730","575.41491"
"315.26900","0.12743","577.60377"
"315.66900","0.12755","579.58468"
"316.06900","0.12770","581.91389"
"316.46900","0.12783","584.02093"
"316.86900","0.12796","586.05639"
"317.26900","0.12810","588.23330"
"317.66900","0.12822","590.09917"
"318.06900","0.12837","592.39857"
"318.46900","0.12850","594.35522"
"318.86900","0.12863","596.30726"
"319.26900","0.12877","598.43389"
"319.66900","0.12890","600.34416"
"320.06900","0.12903","602.46102"
"320.46900","0.12916","604.30044"
"320.86900","0.12930","606.39666"
"321.26900","0.12943","608.26868"
"321.66900","0.12956","610.11397"
"322.06900","0.12970","612.25722"
"322.46900","0.12983","613.96865"
"322.86900","0.12996","615.81300"
"323.26900","0.13009","617.54995"
"323.66900","0.13023","619.49491"
"324.06900","0.13037","621.30293"
"324.46900","0.13049","622.93131"
"324.86900","0.13063","624.80086"
"325.26900","0.13076","626.31031"
"325.66900","0.13090","628.10033"
"326.06900","0.13103","629.80083"
"326.46900","0.13116","631.26461"
"326.86900","0.13130","632.97653"
"327.26900","0.13143","634.35837"
"327.66900","0.13157","636.01172"
"328.06900","0.13170","637.35245"
"328.46900","0.13183","638.85301"
"328.86900","0.13197","640.24720"
"329.26900","0.13209","641.49171"
"329.66900","0.13223","643.10264"
"330.06900","0.13237","644.37104"
"330.46900","0.13250","645.67066"
"330.86900","0.13263","647.03444"
"331.26900","0.13276","648.39087"
"331.66900","0.13290","649.84296"
"332.06900","0.13303","651.02727"
"332.46900","0.13317","652.58705"
"332.86900","0.13329","653.71153"
"333.26900","0.13343","655.07443"
"333.66900","0.13357","656.54524"
"334.06900","0.13370","657.71566"
"334.46900","0.13383","659.04651"
"334.86900","0.13396","660.29246"
"335.26900","0.13410","661.68346"
"335.66900","0.13423","662.97842"
"336.06900","0.13436","664.23474"
"336.46900","0.13450","665.54797"
"336.86900","0.13462","666.65407"
"337.26900","0.13477","668.16494"
"337.66900","0.13490","669.38279"
"338.06900","0.13503","670.56440"
"338.46900","0.13516","671.83774"
"338.86900","0.13529","673.12534"
"339.26900","0.13543","674.55043"
"339.66900","0.13556","675.65175"
"340.06900","0.13570","677.06789"
"340.46900","0.13583","678.27306"
"340.86900","0.13596","679.47323"
"341.26900","0.13610","680.90331"
"341.66900","0.13623","682.08773"
"342.06900","0.13636","683.32028"
"342.46900","0.13649","684.54998"
"342.86900","0.13663","685.90811"
"343.26900","0.13677","687.21508"
"343.66900","0.13690","688.40801"
"344.06900","0.13703","689.76400"
"344.46900","0.13716","690.84370"
"344.86900","0.13730","692.29518"
"345.26900","0.13743","693.55265"
"345.66900","0.13756","694.75173"
"346.06900","0.13770","696.01276"
"346.46900","0.13783","697.25366"
"346.86900","0.13797","698.69258"
"347.26900","0.13810","699.81086"
"347.66900","0.13823","701.11784"
"348.06900","0.13837","702.40983"
"348.46900","0.13849","703.50072"
"348.86900","0.13863","705.00166"
"349.26900","0.13877","706.15315"
"349.66900","0.13890","707.34844"
"350.06900","0.13903","708.70014"
"350.46900","0.13916","709.92106"
"350.86900","0.13930","711.33687"
"351.26900","0.13943","712.43293"
"351.66900","0.13957","713.90351"
"352.06900","0.13969","714.99671"
"352.46900","0.13983","716.26736"
"352.86900","0.13997","717.62971"
"353.26900","0.14010","718.78647"
"353.66900","0.14023","720.05941"
"354.06900","0.14036","721.24702"
"354.46900","0.14050","722.65778"
"354.86900","0.14063","723.89818"
"355.26900","0.14076","725.09665"
"355.66900","0.14090","726.46823"
"356.06900","0.14102","727.50149"
"356.46900","0.14117","729.02636"
"356.86900","0.14130","730.19102"
"357.26900","0.14143","731.33910"
"357.66900","0.14157","732.67270"
"358.06900","0.14169","733.86030"
"358.46900","0.14183","735.24724"
"358.86900","0.14196","736.28463"
"359.26900","0.14210","737.74210"
"359.66900","0.14223","738.88134"
"360.06900","0.14236","740.03069"
"360.46900","0.14250","741.44744"
"360.86900","0.14263","742.58718"
"361.26900","0.14276","743.80436"
"361.66900","0.14289","744.98735"
"362.06900","0.14303","746.25042"
"362.46900","0.14317","747.52963"
"362.86900","0.14330","748.63298"
"363.26900","0.14343","749.98216"
"363.66900","0.14356","750.95593"
"364.06900","0.14370","752.36686"
"364.46900","0.14383","753.57905"
"364.86900","0.14396","754.65765"
"365.26900","0.14410","755.95475"
"365.66900","0.14422","757.02512"
"366.06900","0.14437","758.44345"
"366.46900","0.14450","759.52699"
"366.86900","0.14463","760.71289"
"367.26900","0.14477","761.93639"
"367.66900","0.14489","762.96268"
"368.06900","0.14503","764.41011"
"368.46900","0.14517","765.48059"
"368.86900","0.14530","766.59881"
"369.26900","0.14543","767.79860"
"369.66900","0.14556","768.95766"
"370.06900","0.14570","770.22408"
"370.46900","0.14583","771.26365"
"370.86900","0.14597","772.53935"
"371.26900","0.14609","773.59034"
"371.66900","0.14623","774.80648"
"372.06900","0.14637","776.06637"
"372.46900","0.14649","777.06747"
"372.86900","0.14663","778.36451"
"373.26900","0.14676","779.40672"
"373.66900","0.14690","780.75327"
"374.06900","0.14703","781.88198"
"374.46900","0.14716","782.97732"
"374.86900","0.14730","784.20477"
"375.26900","0.14742","785.18260"
"375.66900","0.14757","786.60269"
"376.06900","0.14770","787.64172"
"376.46900","0.14783","788.71736"
"376.86900","0.14796","789.92038"
"377.26900","0.14809","791.00765"
"377.66900","0.14823","792.29103"
"378.06900","0.14836","793.27737"
"378.46900","0.14850","794.51102"
"378.86900","0.14863","795.58868"
"379.26900","0.14876","796.67140"
"379.66900","0.14890","797.94802"
"380.06900","0.14903","798.88442"
"380.46900","0.14917","800.11845"
"380.86900","0.14929","801.18388"
"381.26900","0.14943","802.38800"
"381.66900","0.14957","803.52148"
"382.06900","0.14969","804.51584"
"382.46900","0.14983","805.77539"
"382.86900","0.14996","806.67984"
"383.26900","0.15010","807.98034"
"383.66900","0.15023","809.09231"
"384.06900","0.15036","810.09275"
"384.46900","0.15050","811.35033"
"384.86900","0.15062","812.23832"
"385.26900","0.15077","813.57592"
"385.66900","0.15090","814.58504"
"386.06900","0.15103","815.65233"
"386.46900","0.15117","816.78653"
"386.86900","0.15129","817.69866"
"387.26900","0.15143","819.07825"
"387.66900","0.15157","820.08341"
"388.06900","0.15170","821.12288"
"388.46900","0.15183","822.21443"
"388.86900","0.15196","823.29814"
"389.26900","0.15210","824.46324"
"389.66900","0.15223","825.41566"
"390.06900","0.15237","826.64711"
"390.46900","0.15249","827.52154"
"390.86900","0.15263","828.63795"
"391.26900","0.15277","829.78264"
"391.66900","0.15289","830.69609"
"392.06900","0.15303","831.86097"
"392.46900","0.15316","832.77897"
"392.86900","0.15330","834.03156"
"393.26900","0.15343","835.03804"
"393.66900","0.15356","835.98898"
"394.06900","0.15370","837.14930"
"394.46900","0.15382","838.00732"
"394.86900","0.15397","839.28186"
"395.26900","0.15410","840.28537"
"395.66900","0.15423","841.19092"
"396.06900","0.15437","842.34949"
"396.46900","0.15449","843.30114"
"396.86900","0.15463","844.44922"
"397.26900","0.15476","845.37113"
"397.66900","0.15490","846.47157"
"398.06900","0.15503","847.43228"
"398.46900","0.15516","848.37361"
"398.86900","0.15530","849.54469"
"399.26900","0.15542","850.35754"
"399.66900","0.15556","851.42225"
"400.06900","0.15569","852.36852"
"400.46900","0.15583","853.39965"
"400.86900","0.15597","854.41957"
"401.26900","0.15609","855.27260"
"401.66900","0.15623","856.41234"
"402.06900","0.15636","857.16783"
"402.46900","0.15650","858.24846"
"402.86900","0.15663","859.28743"
"403.26900","0.15676","860.16609"
"403.66900","0.15690","861.20116"
"404.06900","0.15702","862.02735"
"404.46900","0.15717","863.18438"
"404.86900","0.15730","864.03394"
"405.26900","0.15743","864.98192"
"405.66900","0.15757","865.95503"
"406.06900","0.15769","866.73994"
"406.46900","0.15783","867.92529"
"406.86900","0.15797","868.74741"
"407.26900","0.15810","869.61684"
"407.66900","0.15823","870.57162"
"408.06900","0.15836","871.44589"
"408.46900","0.15850","872.49776"
"408.86900","0.15862","873.22416"
"409.26900","0.15877","874.35863"
"409.66900","0.15889","875.12351"
"410.06900","0.15903","876.02187"
"410.46900","0.15917","877.06863"
"410.86900","0.15930","877.87083"
"411.26900","0.15943","878.77205"
"411.66900","0.15956","879.53099"
"412.06900","0.15970","880.58133"
"412.46900","0.15983","881.43814"
"412.86900","0.15996","882.23260"
"413.26900","0.16010","883.21147"
"413.66900","0.16022","883.89155"
"414.06900","0.16037","884.93629"
"414.46900","0.16050","885.79903"
"414.86900","0.16063","886.53767"
"415.26900","0.16076","887.45474"
"415.66900","0.16089","888.25529"
"416.06900","0.16103","889.27561"
"416.46900","0.16116","889.95678"
"416.86900","0.16130","890.93072"
"417.26900","0.16143","891.69406"
"417.66900","0.16156","892.45767"
"418.06900","0.16170","893.46349"
"418.46900","0.16183","894.20730"
"418.86900","0.16196","894.98348"
"419.26900","0.16209","895.76669"
"419.66900","0.16223","896.65023"
"420.06900","0.16237","897.50962"
"420.46900","0.16249","898.19140"
"420.86900","0.16263","899.15189"
"421.26900","0.16276","899.76616"
"421.66900","0.16290","900.69086"
"422.06900","0.16303","901.49004"
"422.46900","0.16316","902.12868"
"422.86900","0.16330","902.95805"
"423.26900","0.16342","903.67929"
"423.66900","0.16357","904.62913"
"424.06900","0.16369","905.23440"
"424.46900","0.16383","906.07349"
"424.86900","0.16397","906.85741"
"425.26900","0.16409","907.43590"
"425.66900","0.16424","908.47778"
"426.06900","0.16437","909.08267"
"426.46900","0.16449","909.75473"
"426.86900","0.16463","910.49283"
"427.26900","0.16476","911.21594"
"427.66900","0.16490","912.07039"
"428.06900","0.16502","912.58674"
"428.46900","0.16517","913.49959"
"428.86900","0.16529","914.08005"
"429.26900","0.16543","914.74334"
"429.66900","0.16557","915.57111"
"430.06900","0.16570","916.17117"
"430.46900","0.16583","916.86179"
"430.86900","0.16596","917.53227"
"431.26900","0.16609","918.20093"
"431.66900","0.16623","919.00670"
"432.06900","0.16636","919.58447"
"432.46900","0.16650","920.30357"
"432.86900","0.16662","920.86389"
"433.26900","0.16677","921.65402"
"433.66900","0.16690","922.25589"
"434.06900","0.16703","922.77257"
"434.46900","0.16716","923.44678"
"434.86900","0.16729","923.99234"
"435.26900","0.16743","924.79706"
"435.66900","0.16756","925.27434"
"436.06900","0.16770","925.96809"
"436.46900","0.16783","926.54745"
"436.86900","0.16796","927.03593"
"437.26900","0.16810","927.84483"
"437.66900","0.16823","928.35844"
"438.06900","0.16836","928.89313"
"438.46900","0.16849","929.47579"
"438.86900","0.16863","930.10246"
"439.26900","0.16877","930.73112"
"439.66900","0.16889","931.21784"
"440.06900","0.16903","931.93518"
"440.46900","0.16916","932.27887"
"440.86900","0.16930","932.97471"
"441.26900","0.16943","933.54375"
"441.66900","0.16956","933.98207"
"442.06900","0.16970","934.58317"
"442.46900","0.16982","935.02257"
"442.86900","0.16997","935.72335"
"443.26900","0.17010","936.16385"
"443.66900","0.17023","936.69305"
"444.06900","0.17037","937.21347"
"444.46900","0.17049","937.54300"
"444.86900","0.17063","938.32435"
"445.26900","0.17077","938.70942"
"445.66900","0.17089","939.09987"
"446.06900","0.17103","939.68363"
"446.46900","0.17116","940.13467"
"446.86900","0.17130","940.73687"
"447.26900","0.17143","941.07277"
"447.66900","0.17157","941.69791"
"448.06900","0.17169","942.01975"
"448.46900","0.17183","942.47058"
"448.86900","0.17197","943.02568"
"449.26900","0.17209","943.33436"
"449.66900","0.17223","943.86191"
"450.06900","0.17236","944.18079"
"450.46900","0.17250","944.75182"
"450.86900","0.17263","945.13755"
"451.26900","0.17276","945.45182"
"451.66900","0.17290","945.97751"
"452.06900","0.17302","946.21077"
"452.46900","0.17317","946.88399"
"452.86900","0.17330","947.16215"
"453.26900","0.17343","947.47422"
"453.66900","0.17357","947.97466"
"454.06900","0.17369","948.20452"
"454.46900","0.17383","948.74964"
"454.86900","0.17396","948.96918"
"455.26900","0.17410","949.46534"
"455.66900","0.17423","949.77160"
"456.06900","0.17436","949.99465"
"456.46900","0.17450","950.56106"
"456.86900","0.17463","950.75294"
"457.26900","0.17476","951.13000"
"457.66900","0.17490","951.47830"
"458.06900","0.17503","951.76041"
"458.46900","0.17517","952.18478"
"458.86900","0.17529","952.33791"
"459.26900","0.17543","952.84856"
"459.66900","0.17556","952.90893"
"460.06900","0.17570","953.36766"
"460.46900","0.17583","953.68698"
"460.86900","0.17596","953.84835"
"461.26900","0.17610","954.26306"
"461.66900","0.17622","954.35186"
"462.06900","0.17637","954.87030"
"462.46900","0.17650","955.04100"
"462.86900","0.17663","955.28216"
"463.26900","0.17677","955.57217"
"463.66900","0.17689","955.64265"
"464.06900","0.17703","956.19029"
"464.46900","0.17716","956.27657"
"464.86900","0.17730","956.51477"
"465.26900","0.17743","956.78875"
"465.66900","0.17756","956.97547"
"466.06900","0.17770","957.25703"
"466.46900","0.17783","957.34770"
"466.86900","0.17797","957.68777"
"467.26900","0.17809","957.75232"
"467.66900","0.17823","957.99721"
"468.06900","0.17837","958.27833"
"468.46900","0.17849","958.33377"
"468.86900","0.17863","958.61522"
"469.26900","0.17876","958.63410"
"469.66900","0.17890","958.94552"
"470.06900","0.17903","959.06670"
"470.46900","0.17916","959.12071"
"470.86900","0.17930","959.35057"
"471.26900","0.17942","959.30820"
"471.66900","0.17957","959.55639"
"472.06900","0.17970","959.66681"
"472.46900","0.17983","959.65474"
"472.86900","0.17997","959.81610"
"473.26900","0.18009","959.73301"
"473.66900","0.18023","959.92038"
"474.06900","0.18037","959.84124"
"474.46900","0.18050","959.81665"
"474.86900","0.18063","959.72916"
"475.26900","0.18076","959.52313"
"475.66900","0.18090","959.58954"
"476.06900","0.18103","959.23685"
"476.46900","0.18116","958.91017"
"476.86900","0.18130","958.49667"
"477.26900","0.18143","957.93300"
"477.66900","0.18157","957.17306"
"478.06900","0.18169","955.97470"
"478.46900","0.18183","954.66833"
"478.86900","0.18196","952.49861"
"479.26900","0.18209","949.88642"
"479.66900","0.18223","946.44414"
"480.06900","0.18236","941.84171"
"480.46900","0.18250","936.88932"
"480.86900","0.18262","931.08414"
"481.26900","0.18277","925.49707"
"481.66900","0.18290","919.57613"
"482.06900","0.18303","914.12133"
"482.46900","0.18317","909.08541"
"482.86900","0.18329","904.22694"
"483.26900","0.18343","900.20820"
"483.66900","0.18357","896.03667"
"484.06900","0.18370","892.04807"
"484.46900","0.18383","888.28076"
"484.86900","0.18396","884.60648"
"485.26900","0.18410","881.07502"
"485.66900","0.18423","877.30859"
"486.06900","0.18437","873.99540"
"486.46900","0.18450","870.37217"
"486.86900","0.18462","866.99779"
"487.26900","0.18477","863.96715"
"487.66900","0.18490","860.60939"
"488.06900","0.18503","857.48260"
"488.46900","0.18516","854.21288"
"488.86900","0.18530","851.10403"
"489.26900","0.18543","847.85807"
"489.66900","0.18556","844.45131"
"490.06900","0.18570","841.20316"
"490.46900","0.18582","837.61209"
"490.86900","0.18597","834.45982"
"491.26900","0.18610","830.98374"
"491.66900","0.18623","827.40397"
"492.06900","0.18637","823.92608"
"492.46900","0.18649","820.31443"
"492.86900","0.18663","817.02116"
"493.26900","0.18676","813.19184"
"493.66900","0.18690","809.56882"
"494.06900","0.18703","805.70217"
"494.46900","0.18716","801.72493"
"494.86900","0.18730","798.06449"
"495.26900","0.18743","793.76200"
"495.66900","0.18756","789.52131"
"496.06900","0.18769","785.20428"
"496.46900","0.18783","780.71507"
"496.86900","0.18797","776.07860"
"497.26900","0.18809","770.93144"
"497.66900","0.18823","765.80216"
"498.06900","0.18836","760.04324"
"498.46900","0.18850","753.44793"
"498.79300","0.18862","737.56202"
"498.79700","0.18866","700.89171"
"498.80100","0.18871","637.22051"
"498.80500","0.18875","558.92147"
"498.80900","0.18879","474.57625"
"498.81300","0.18882","390.36763"
"498.81700","0.18884","310.71206"
"498.82100","0.18886","238.46856"
"498.82500","0.18887","175.25992"
"498.82900","0.18887","121.71517"
"498.83300","0.18887","77.76267"
"498.83700","0.18887","42.86580"
"498.84100","0.18887","16.16727"
"498.84300","0.18887","5.56880"